Workbook
Name A_ALL_KEYWORDS_TYPE_ScalarContributed_EQTY_200001320: Ticker0024_Annotation_Sheet!$268:$276,Ticker0024_Annotation_Sheet!$318:$318,Ticker0024_Annotation_Sheet!$322:$324,Ticker0024_Annotation_Sheet!$329:$331
Name A_ALL_KEYWORDS_TYPE_ScalarReference_EQTY_200001320: Ticker0024_Annotation_Sheet!$261:$266
Name A_ALL_KEYWORDS_TYPE_ScalarReference_ISSR_208000430: Ticker0024_Annotation_Sheet!$6:$7
Name A_ALL_Ticker0024: Ticker0024_Annotation_Sheet!$A$1:$FT$331
Name A_ALL_PERIODS_Ticker0024: Ticker0024_Annotation_Sheet!$F$1:$FT$1
Name A_ALL_SECTION_KEYWORDS_EQTY_200001320_1314: Ticker0024_Annotation_Sheet!$C$320
Name A_ALL_SECTION_KEYWORDS_EQTY_200001320_1319: Ticker0024_Annotation_Sheet!$C$322:$C$325
Name A_ALL_SECTION_KEYWORDS_EQTY_200001320_131E: Ticker0024_Annotation_Sheet!$C$327
Name A_ALL_SECTION_KEYWORDS_EQTY_200001320_131O: Ticker0024_Annotation_Sheet!$C$329:$C$331
Name A_ALL_SECTION_KEYWORDS_EQTY_200001320_13A: Ticker0024_Annotation_Sheet!$C$268:$C$276
Name A_ALL_SECTION_KEYWORDS_EQTY_200001320_13K: Ticker0024_Annotation_Sheet!$C$278:$C$293
Name A_ALL_SECTION_KEYWORDS_EQTY_200001320_13U: Ticker0024_Annotation_Sheet!$C$295:$C$310
Name A_ALL_SECTION_KEYWORDS_EQTY_200001320_13V: Ticker0024_Annotation_Sheet!$C$312
Name A_ALL_SECTION_KEYWORDS_EQTY_200001320_13W: Ticker0024_Annotation_Sheet!$C$314:$C$318
Name A_ALL_SECTION_KEYWORDS_EQTY_200001320_Reference_Data: Ticker0024_Annotation_Sheet!$C$261:$C$266
Name A_ALL_SECTION_KEYWORDS_ISSR_208000430_1314: Ticker0024_Annotation_Sheet!$C$54:$C$84
Name A_ALL_SECTION_KEYWORDS_ISSR_208000430_13168: Ticker0024_Annotation_Sheet!$C$167:$C$228
Name A_ALL_SECTION_KEYWORDS_ISSR_208000430_1316T: Ticker0024_Annotation_Sheet!$C$230:$C$231
Name A_ALL_SECTION_KEYWORDS_ISSR_208000430_1316U: Ticker0024_Annotation_Sheet!$C$233:$C$247
Name A_ALL_SECTION_KEYWORDS_ISSR_208000430_1319: Ticker0024_Annotation_Sheet!$C$86:$C$104
Name A_ALL_SECTION_KEYWORDS_ISSR_208000430_131E: Ticker0024_Annotation_Sheet!$C$106:$C$122
Name A_ALL_SECTION_KEYWORDS_ISSR_208000430_131J: Ticker0024_Annotation_Sheet!$C$124:$C$137
Name A_ALL_SECTION_KEYWORDS_ISSR_208000430_131O: Ticker0024_Annotation_Sheet!$C$139:$C$165
Name A_ALL_SECTION_KEYWORDS_ISSR_208000430_136E: Ticker0024_Annotation_Sheet!$C$249:$C$258
Name A_ALL_SECTION_KEYWORDS_ISSR_208000430_13A: Ticker0024_Annotation_Sheet!$C$9
Name A_ALL_SECTION_KEYWORDS_ISSR_208000430_13U: Ticker0024_Annotation_Sheet!$C$11:$C$30
Name A_ALL_SECTION_KEYWORDS_ISSR_208000430_13V: Ticker0024_Annotation_Sheet!$C$32:$C$52
Name A_ALL_SECTION_KEYWORDS_ISSR_208000430_Reference_Data: Ticker0024_Annotation_Sheet!$C$6:$C$7
Name A_CURRENCY_EQTY_200001320_PRI: Ticker0024_Annotation_Sheet!$E$265
Name A_CURRENCY_EQTY_200001320_PUB: Ticker0024_Annotation_Sheet!$E$264
Name A_CURRENCY_EQTY_200001320_REP: Ticker0024_Annotation_Sheet!$E$266
Name A_CURRENCY_ISSR_208000430_REP: Ticker0024_Annotation_Sheet!$E$7
Name A_ENTITY_DATA_EQTY_200001320: Ticker0024_Annotation_Sheet!$E$260:$FT$331
Name A_ENTITY_DATA_ISSR_208000430: Ticker0024_Annotation_Sheet!$E$5:$FT$258
Name A_KEYWORD_EQTY_200001320_AMER_LIST: Ticker0024_Annotation_Sheet!$268:$268
Name A_KEYWORD_EQTY_200001320_BETA_ANALYST: Ticker0024_Annotation_Sheet!$329:$329
Name A_KEYWORD_EQTY_200001320_BVPS: Ticker0024_Annotation_Sheet!$320:$320
Name A_KEYWORD_EQTY_200001320_BVPS_PUB: Ticker0024_Annotation_Sheet!$278:$278
Name A_KEYWORD_EQTY_200001320_CEEE_EPS: Ticker0024_Annotation_Sheet!$283:$283
Name A_KEYWORD_EQTY_200001320_CEEE_NDEBT: Ticker0024_Annotation_Sheet!$288:$288
Name A_KEYWORD_EQTY_200001320_CF_NI_PRE_PREF: Ticker0024_Annotation_Sheet!$327:$327
Name A_KEYWORD_EQTY_200001320_COMMON_DIV_PAID: Ticker0024_Annotation_Sheet!$306:$306
Name A_KEYWORD_EQTY_200001320_CURRENCY_ISO: Ticker0024_Annotation_Sheet!$266:$266
Name A_KEYWORD_EQTY_200001320_DILUTE_SHARES: Ticker0024_Annotation_Sheet!$309:$309
Name A_KEYWORD_EQTY_200001320_DPS: Ticker0024_Annotation_Sheet!$307:$307
Name A_KEYWORD_EQTY_200001320_DPS_PUB: Ticker0024_Annotation_Sheet!$279:$279
Name A_KEYWORD_EQTY_200001320_DPS_SPECIAL_PUB: Ticker0024_Annotation_Sheet!$280:$280
Name A_KEYWORD_EQTY_200001320_EBIT_PUB: Ticker0024_Annotation_Sheet!$290:$290
Name A_KEYWORD_EQTY_200001320_EBITDA_PUB: Ticker0024_Annotation_Sheet!$281:$281
Name A_KEYWORD_EQTY_200001320_EPS: Ticker0024_Annotation_Sheet!$302:$302
Name A_KEYWORD_EQTY_200001320_EPS_EX_ESO_B: Ticker0024_Annotation_Sheet!$316:$316
Name A_KEYWORD_EQTY_200001320_EPS_EX_ESO_D: Ticker0024_Annotation_Sheet!$317:$317
Name A_KEYWORD_EQTY_200001320_EPS_FUL_DIL: Ticker0024_Annotation_Sheet!$303:$303
Name A_KEYWORD_EQTY_200001320_EPS_POST_BASIC: Ticker0024_Annotation_Sheet!$304:$304
Name A_KEYWORD_EQTY_200001320_EPS_PUB: Ticker0024_Annotation_Sheet!$282:$282
Name A_KEYWORD_EQTY_200001320_EPS_PUB_EX_ESO: Ticker0024_Annotation_Sheet!$284:$284
Name A_KEYWORD_EQTY_200001320_EQ_PUB: Ticker0024_Annotation_Sheet!$293:$293
Name A_KEYWORD_EQTY_200001320_ESO_POST_TAX: Ticker0024_Annotation_Sheet!$315:$315
Name A_KEYWORD_EQTY_200001320_ESO_YEAR: Ticker0024_Annotation_Sheet!$318:$318
Name A_KEYWORD_EQTY_200001320_EV_ADJ_PUB: Ticker0024_Annotation_Sheet!$285:$285

Sheet __FDSCACHE__
B1: This sheet contains FactSet XML data for use with this workbook's =FDS codes. Modifying the worksheet's contents may damage the workbook's =FDS functionality.

Sheet Cover
C2: Microsoft Analyst Model
C3: Ticker: | D3: Ticker0024
C4: Date: | D4: =TODAY()
B6: Person0591
B7: (415) 249-7318
B8: person@example.com
B10: Person0462
B11: (212) 357-6378
B12: person@example.com
B14: Person0749 Person0744
B15: (212) 902-0695
B16: person@example.com
B18: Person0818
B19: (332) 245-7726
B20: person@example.com
... B24: person@example.com

Sheet Rev. Summary
B2: Microsoft, Inc.
B3: Fiscal Year Ends Jun. 30
B4: ($ millions, except per share amounts) | ER4: Resegmented | EV4: x
C6: =Dates!C3 | H6: =Dates!H3 | M6: =Dates!M3 | R6: =Dates!R3 | W6: =Dates!W3 | AB6: =Dates!AB3 | AG6: =Dates!AG3 | AL6: =Dates!AL3 | AQ6: =Dates!AQ3 | AV6: =Dates!AV3 | BA6: =Dates!BA3 | BF6: =Dates!BF3 | BK6: =Dates!BK3 | BP6: =Dates!BP3 | BU6: =Dates!BU3 | BZ6: =Dates!BZ3 | CE6: =Dates!CE3 | CJ6: =Dates!CJ3 | CO6: =Dates!CO3 | CT6: =Dates!CT3 | CY6: =Dates!CY3 | DD6: =Dates!DD3 | DI6: =Dates!DI3 | DN6: =Dates!DN3 | DS6: =Dates!DS3 | DX6: =Dates!DX3 | EC6: =Dates!EC3 | EH6: =Dates!EH3 | EM6: =Dates!EM3 | ER6: =Dates!ER3 | EW6: =Dates!EW3 | FB6: =Dates!FB3 | FG6: =Dates!FG3 | FL6: =Dates!FL3 | FQ6: =Dates!FQ3 | FV6: =Dates!FV3 | GA6: =Dates!GA3 | GF6: =Dates!GF3
C7: =Dates!C4 | D7: =Dates!D4 | E7: =Dates!E4 | F7: =Dates!F4 | G7: =Dates!G4 | H7: =Dates!H4 | I7: =Dates!I4 | J7: =Dates!J4 | ... GJ7: =Dates!GJ4
C8: =Dates!C5 | D8: =Dates!D5 | E8: =Dates!E5 | F8: =Dates!F5 | G8: =Dates!G5 | H8: =Dates!H5 | I8: =Dates!I5 | J8: =Dates!J5 | ... GJ8: =Dates!GJ5
A10: TREV | B10: Total Revenue | CY10: =CY19+CY44+CY64 | CZ10: =CZ19+CZ44+CZ64 | DA10: =DA19+DA44+DA64 | DB10: =DB19+DB44+DB64 | DC10: =DC19+DC44+DC64 | DD10: =DD19+DD44+DD64 | DE10: =DE19+DE44+DE64 | DF10: =DF19+DF44+DF64 | ... GJ10: =GJ19+GJ44+GJ64
B11: % yoy | DD11: =IFERROR(DD10/CY10-1,"") | DE11: =IFERROR(DE10/CZ10-1,"") | DF11: =IFERROR(DF10/DA10-1,"") | DG11: =IFERROR(DG10/DB10-1,"") | DH11: =IFERROR(DH10/DC10-1,"") | DI11: =IFERROR(DI10/DD10-1,"") | DJ11: =IFERROR(DJ10/DE10-1,"") | DK11: =IFERROR(DK10/DF10-1,"") | ... GJ11: =IFERROR(GJ10/GE10-1,"")
B12: % qoq | CZ12: =IFERROR(CZ10/CY10-1,"") | DA12: =IFERROR(DA10/CZ10-1,"") | DB12: =IFERROR(DB10/DA10-1,"") | DD12: =IFERROR(DD10/DB10-1,"") | DE12: =IFERROR(DE10/DD10-1,"") | DF12: =IFERROR(DF10/DE10-1,"") | DG12: =IFERROR(DG10/DF10-1,"") | DI12: =IFERROR(DI10/DG10-1,"") | DJ12: =IFERROR(DJ10/DI10-1,"") | DK12: =IFERROR(DK10/DJ10-1,"") | DL12: =IFERROR(DL10/DK10-1,"") | DN12: =IFERROR(DN10/DL10-1,"") | DO12: =IFERROR(DO10/DN10-1,"") | DP12: =IFERROR(DP10/DO10-1,"") | DQ12: =IFERROR(DQ10/DP10-1,"") | DS12: =IFERROR(DS10/DQ10-1,"") | DT12: =IFERROR(DT10/DS10-1,"") | DU12: =IFERROR(DU10/DT10-1,"") | DV12: =IFERROR(DV10/DU10-1,"") | DX12: =IFERROR(DX10/DV10-1,"") | DY12: =IFERROR(DY10/DX10-1,"") | DZ12: =IFERROR(DZ10/DY10-1,"") | EA12: =IFERROR(EA10/DZ10-1,"") | EC12: =IFERROR(EC10/EA10-1,"") | ED12: =IFERROR(ED10/EC10-1,"") | EE12: =IFERROR(EE10/ED10-1,"") | EF12: =IFERROR(EF10/EE10-1,"") | EH12: =IFERROR(EH10/EF10-1,"") | EI12: =IFERROR(EI10/EH10-1,"") | EJ12: =IFERROR(EJ10/EI10-1,"") | EK12: =IFERROR(EK10/EJ10-1,"") | EM12: =IFERROR(EM10/EK10-1,"") | EN12: =IFERROR(EN10/EM10-1,"") | EO12: =IFERROR(EO10/EN10-1,"") | EP12: =IFERROR(EP10/EO10-1,"") | ER12: =IFERROR(ER10/EP10-1,"") | ES12: =IFERROR(ES10/ER10-1,"") | ET12: =IFERROR(ET10/ES10-1,"") | EU12: =IFERROR(EU10/ET10-1,"") | EW12: =IFERROR(EW10/EU10-1,"") | EX12: =IFERROR(EX10/EW10-1,"") | EY12: =IFERROR(EY10/EX10-1,"") | EZ12: =IFERROR(EZ10/EY10-1,"") | FB12: =IFERROR(FB10/EZ10-1,"") | FC12: =IFERROR(FC10/FB10-1,"") | FD12: =IFERROR(FD10/FC10-1,"") | FE12: =IFERROR(FE10/FD10-1,"") | FG12: =IFERROR(FG10/FE10-1,"") | FH12: =IFERROR(FH10/FG10-1,"") | FI12: =IFERROR(FI10/FH10-1,"") | FJ12: =IFERROR(FJ10/FI10-1,"") | FL12: =IFERROR(FL10/FJ10-1,"") | FM12: =IFERROR(FM10/FL10-1,"") | FN12: =IFERROR(FN10/FM10-1,"") | FO12: =IFERROR(FO10/FN10-1,"") | FQ12: =IFERROR(FQ10/FO10-1,"") | FR12: =IFERROR(FR10/FQ10-1,"") | FS12: =IFERROR(FS10/FR10-1,"") | FT12: =IFERROR(FT10/FS10-1,"") | FV12: =IFERROR(FV10/FT10-1,"") | FW12: =IFERROR(FW10/FV10-1,"") | FX12: =IFERROR(FX10/FW10-1,"") | FY12: =IFERROR(FY10/FX10-1,"") | GA12: =IFERROR(GA10/FY10-1,"") | GB12: =IFERROR(GB10/GA10-1,"") | GC12: =IFERROR(GC10/GB10-1,"") | GD12: =IFERROR(GD10/GC10-1,"") | GF12: =IFERROR(GF10/GD10-1,"") | GG12: =IFERROR(GG10/GF10-1,"") | GH12: =IFERROR(GH10/GG10-1,"") | GI12: =IFERROR(GI10/GH10-1,"")
B14: Microsoft Cloud Revenue | DG14: ='Ticker0024 Cloud'!DG10 | DH14: ='Ticker0024 Cloud'!DH10 | DI14: ='Ticker0024 Cloud'!DI10 | DJ14: ='Ticker0024 Cloud'!DJ10 | DK14: ='Ticker0024 Cloud'!DK10 | DL14: ='Ticker0024 Cloud'!DL10 | DM14: ='Ticker0024 Cloud'!DM10 | DN14: ='Ticker0024 Cloud'!DN10 | ... GJ14: ='Ticker0024 Cloud'!GJ10
B15: % yoy | DD15: =IFERROR(DD14/CY14-1,"") | DE15: =IFERROR(DE14/CZ14-1,"") | DF15: =IFERROR(DF14/DA14-1,"") | DG15: =IFERROR(DG14/DB14-1,"") | DH15: =IFERROR(DH14/DC14-1,"") | DI15: =IFERROR(DI14/DD14-1,"") | DJ15: =IFERROR(DJ14/DE14-1,"") | DK15: =IFERROR(DK14/DF14-1,"") | ... GJ15: =IFERROR(GJ14/GE14-1,"")
B16: % qoq | CZ16: =IFERROR(CZ14/CY14-1,"") | DA16: =IFERROR(DA14/CZ14-1,"") | DB16: =IFERROR(DB14/DA14-1,"") | DD16: =IFERROR(DD14/DB14-1,"") | DE16: =IFERROR(DE14/DD14-1,"") | DF16: =IFERROR(DF14/DE14-1,"") | DG16: =IFERROR(DG14/DF14-1,"") | DI16: =IFERROR(DI14/DG14-1,"") | DJ16: =IFERROR(DJ14/DI14-1,"") | DK16: =IFERROR(DK14/DJ14-1,"") | DL16: =IFERROR(DL14/DK14-1,"") | DN16: =IFERROR(DN14/DL14-1,"") | DO16: =IFERROR(DO14/DN14-1,"") | DP16: =IFERROR(DP14/DO14-1,"") | DQ16: =IFERROR(DQ14/DP14-1,"") | DS16: =IFERROR(DS14/DQ14-1,"") | DT16: =IFERROR(DT14/DS14-1,"") | DU16: =IFERROR(DU14/DT14-1,"") | DV16: =IFERROR(DV14/DU14-1,"") | DX16: =IFERROR(DX14/DV14-1,"") | DY16: =IFERROR(DY14/DX14-1,"") | DZ16: =IFERROR(DZ14/DY14-1,"") | EA16: =IFERROR(EA14/DZ14-1,"") | EC16: =IFERROR(EC14/EA14-1,"") | ED16: =IFERROR(ED14/EC14-1,"") | EE16: =IFERROR(EE14/ED14-1,"") | EF16: =IFERROR(EF14/EE14-1,"") | EH16: =IFERROR(EH14/EF14-1,"") | EI16: =IFERROR(EI14/EH14-1,"") | EJ16: =IFERROR(EJ14/EI14-1,"") | EK16: =IFERROR(EK14/EJ14-1,"") | EM16: =IFERROR(EM14/EK14-1,"") | EN16: =IFERROR(EN14/EM14-1,"") | EO16: =IFERROR(EO14/EN14-1,"") | EP16: =IFERROR(EP14/EO14-1,"") | ER16: =IFERROR(ER14/EP14-1,"") | ES16: =IFERROR(ES14/ER14-1,"") | ET16: =IFERROR(ET14/ES14-1,"") | EU16: =IFERROR(EU14/ET14-1,"") | EW16: =IFERROR(EW14/EU14-1,"") | EX16: =IFERROR(EX14/EW14-1,"") | EY16: =IFERROR(EY14/EX14-1,"") | EZ16: =IFERROR(EZ14/EY14-1,"") | FB16: =IFERROR(FB14/EZ14-1,"") | FC16: =IFERROR(FC14/FB14-1,"") | FD16: =IFERROR(FD14/FC14-1,"") | FE16: =IFERROR(FE14/FD14-1,"") | FG16: =IFERROR(FG14/FE14-1,"") | FH16: =IFERROR(FH14/FG14-1,"") | FI16: =IFERROR(FI14/FH14-1,"") | FJ16: =IFERROR(FJ14/FI14-1,"") | FL16: =IFERROR(FL14/FJ14-1,"") | FM16: =IFERROR(FM14/FL14-1,"") | FN16: =IFERROR(FN14/FM14-1,"") | FO16: =IFERROR(FO14/FN14-1,"") | FQ16: =IFERROR(FQ14/FO14-1,"") | FR16: =IFERROR(FR14/FQ14-1,"") | FS16: =IFERROR(FS14/FR14-1,"") | FT16: =IFERROR(FT14/FS14-1,"") | FV16: =IFERROR(FV14/FT14-1,"") | FW16: =IFERROR(FW14/FV14-1,"") | FX16: =IFERROR(FX14/FW14-1,"") | FY16: =IFERROR(FY14/FX14-1,"") | GA16: =IFERROR(GA14/FY14-1,"") | GB16: =IFERROR(GB14/GA14-1,"") | GC16: =IFERROR(GC14/GB14-1,"") | GD16: =IFERROR(GD14/GC14-1,"") | GF16: =IFERROR(GF14/GD14-1,"") | GG16: =IFERROR(GG14/GF14-1,"") | GH16: =IFERROR(GH14/GG14-1,"") | GI16: =IFERROR(GI14/GH14-1,"")
B17: % Total Revenue | CY17: =CY14/CY$10 | CZ17: =CZ14/CZ$10 | DA17: =DA14/DA$10 | DB17: =DB14/DB$10 | DC17: =DC14/DC$10 | DD17: =DD14/DD$10 | DE17: =DE14/DE$10 | DF17: =DF14/DF$10 | ... GJ17: =GJ14/GJ$10
EV18: =EV14-EQ14
B19: PBP Revenue | CY19: =IFERROR(PBP!CY50,"") | CZ19: =IFERROR(PBP!CZ50,"") | DA19: =IFERROR(PBP!DA50,"") | DB19: =IFERROR(PBP!DB50,"") | DC19: =IFERROR(PBP!DC50,"") | DD19: =IFERROR(PBP!DD50,"") | DE19: =IFERROR(PBP!DE50,"") | DF19: =IFERROR(PBP!DF50,"") | ... EQ19: =IFERROR(PBP!EQ50,"") | ER19: =PBP!ER10 | ES19: =PBP!ES10 | ET19: =PBP!ET10 | EU19: =PBP!EU10 | EV19: =PBP!EV10 | EW19: =PBP!EW10 | EX19: =PBP!EX10 | EY19: =PBP!EY10 | ... GJ19: =PBP!GJ10
B20: % yoy | DD20: =IFERROR(DD19/CY19-1,"") | DE20: =IFERROR(DE19/CZ19-1,"") | DF20: =IFERROR(DF19/DA19-1,"") | DG20: =IFERROR(DG19/DB19-1,"") | DH20: =IFERROR(DH19/DC19-1,"") | DI20: =IFERROR(DI19/DD19-1,"") | DJ20: =IFERROR(DJ19/DE19-1,"") | DK20: =IFERROR(DK19/DF19-1,"") | ... GJ20: =IFERROR(GJ19/GE19-1,"")
B21: % qoq | CZ21: =IFERROR(CZ19/CY19-1,"") | DA21: =IFERROR(DA19/CZ19-1,"") | DB21: =IFERROR(DB19/DA19-1,"") | DD21: =IFERROR(DD19/DB19-1,"") | DE21: =IFERROR(DE19/DD19-1,"") | DF21: =IFERROR(DF19/DE19-1,"") | DG21: =IFERROR(DG19/DF19-1,"") | DI21: =IFERROR(DI19/DG19-1,"") | DJ21: =IFERROR(DJ19/DI19-1,"") | DK21: =IFERROR(DK19/DJ19-1,"") | DL21: =IFERROR(DL19/DK19-1,"") | DN21: =IFERROR(DN19/DL19-1,"") | DO21: =IFERROR(DO19/DN19-1,"") | DP21: =IFERROR(DP19/DO19-1,"") | DQ21: =IFERROR(DQ19/DP19-1,"") | DS21: =IFERROR(DS19/DQ19-1,"") | DT21: =IFERROR(DT19/DS19-1,"") | DU21: =IFERROR(DU19/DT19-1,"") | DV21: =IFERROR(DV19/DU19-1,"") | DX21: =IFERROR(DX19/DV19-1,"") | DY21: =IFERROR(DY19/DX19-1,"") | DZ21: =IFERROR(DZ19/DY19-1,"") | EA21: =IFERROR(EA19/DZ19-1,"") | EC21: =IFERROR(EC19/EA19-1,"") | ED21: =IFERROR(ED19/EC19-1,"") | EE21: =IFERROR(EE19/ED19-1,"") | EF21: =IFERROR(EF19/EE19-1,"") | EH21: =IFERROR(EH19/EF19-1,"") | EI21: =IFERROR(EI19/EH19-1,"") | EJ21: =IFERROR(EJ19/EI19-1,"") | EK21: =IFERROR(EK19/EJ19-1,"") | EM21: =IFERROR(EM19/EK19-1,"") | EN21: =IFERROR(EN19/EM19-1,"") | EO21: =IFERROR(EO19/EN19-1,"") | EP21: =IFERROR(EP19/EO19-1,"") | ER21: =IFERROR(ER19/EP19-1,"") | ES21: =IFERROR(ES19/ER19-1,"") | ET21: =IFERROR(ET19/ES19-1,"") | EU21: =IFERROR(EU19/ET19-1,"") | EW21: =IFERROR(EW19/EU19-1,"") | EX21: =IFERROR(EX19/EW19-1,"") | EY21: =IFERROR(EY19/EX19-1,"") | EZ21: =IFERROR(EZ19/EY19-1,"") | FB21: =IFERROR(FB19/EZ19-1,"") | FC21: =IFERROR(FC19/FB19-1,"") | FD21: =IFERROR(FD19/FC19-1,"") | FE21: =IFERROR(FE19/FD19-1,"") | FG21: =IFERROR(FG19/FE19-1,"") | FH21: =IFERROR(FH19/FG19-1,"") | FI21: =IFERROR(FI19/FH19-1,"") | FJ21: =IFERROR(FJ19/FI19-1,"") | FL21: =IFERROR(FL19/FJ19-1,"") | FM21: =IFERROR(FM19/FL19-1,"") | FN21: =IFERROR(FN19/FM19-1,"") | FO21: =IFERROR(FO19/FN19-1,"") | FQ21: =IFERROR(FQ19/FO19-1,"") | FR21: =IFERROR(FR19/FQ19-1,"") | FS21: =IFERROR(FS19/FR19-1,"") | FT21: =IFERROR(FT19/FS19-1,"") | FV21: =IFERROR(FV19/FT19-1,"") | FW21: =IFERROR(FW19/FV19-1,"") | FX21: =IFERROR(FX19/FW19-1,"") | FY21: =IFERROR(FY19/FX19-1,"") | GA21: =IFERROR(GA19/FY19-1,"") | GB21: =IFERROR(GB19/GA19-1,"") | GC21: =IFERROR(GC19/GB19-1,"") | GD21: =IFERROR(GD19/GC19-1,"") | GF21: =IFERROR(GF19/GD19-1,"") | GG21: =IFERROR(GG19/GF19-1,"") | GH21: =IFERROR(GH19/GG19-1,"") | GI21: =IFERROR(GI19/GH19-1,"")
B22: % Total Revenue | CY22: =CY19/CY$10 | CZ22: =CZ19/CZ$10 | DA22: =DA19/DA$10 | DB22: =DB19/DB$10 | DC22: =DC19/DC$10 | DD22: =DD19/DD$10 | DE22: =DE19/DE$10 | DF22: =DF19/DF$10 | ... GJ22: =GJ19/GJ$10
B24: Microsoft 365 Commercial Cloud | ER24: =PBP!ER195 | ES24: =PBP!ES195 | ET24: =PBP!ET195 | EU24: =PBP!EU195 | EV24: =PBP!EV195 | EW24: =PBP!EW195 | EX24: =PBP!EX195 | EY24: =PBP!EY195 | ... GJ24: =PBP!GJ195
B25: % yoy | DD25: =IFERROR(DD24/CY24-1,"") | DE25: =IFERROR(DE24/CZ24-1,"") | DF25: =IFERROR(DF24/DA24-1,"") | DG25: =IFERROR(DG24/DB24-1,"") | DH25: =IFERROR(DH24/DC24-1,"") | ER25: =IFERROR(ER24/EM24-1,"") | ES25: =IFERROR(ES24/EN24-1,"") | ET25: =IFERROR(ET24/EO24-1,"") | EU25: =IFERROR(EU24/EP24-1,"") | EV25: =IFERROR(EV24/EQ24-1,"") | EW25: =IFERROR(EW24/ER24-1,"") | EX25: =IFERROR(EX24/ES24-1,"") | EY25: =IFERROR(EY24/ET24-1,"") | ... GJ25: =IFERROR(GJ24/GE24-1,"")
B26: % qoq | CZ26: =IFERROR(CZ24/CY24-1,"") | DA26: =IFERROR(DA24/CZ24-1,"") | DB26: =IFERROR(DB24/DA24-1,"") | DD26: =IFERROR(DD24/DB24-1,"") | DE26: =IFERROR(DE24/DD24-1,"") | DF26: =IFERROR(DF24/DE24-1,"") | DG26: =IFERROR(DG24/DF24-1,"") | ER26: =IFERROR(ER24/EP24-1,"") | ES26: =IFERROR(ES24/ER24-1,"") | ET26: =IFERROR(ET24/ES24-1,"") | EU26: =IFERROR(EU24/ET24-1,"") | EW26: =IFERROR(EW24/EU24-1,"") | EX26: =IFERROR(EX24/EW24-1,"") | EY26: =IFERROR(EY24/EX24-1,"") | EZ26: =IFERROR(EZ24/EY24-1,"") | FB26: =IFERROR(FB24/EZ24-1,"") | FC26: =IFERROR(FC24/FB24-1,"") | FD26: =IFERROR(FD24/FC24-1,"") | FE26: =IFERROR(FE24/FD24-1,"") | FG26: =IFERROR(FG24/FE24-1,"") | FH26: =IFERROR(FH24/FG24-1,"") | FI26: =IFERROR(FI24/FH24-1,"") | FJ26: =IFERROR(FJ24/FI24-1,"") | FL26: =IFERROR(FL24/FJ24-1,"") | FM26: =IFERROR(FM24/FL24-1,"") | FN26: =IFERROR(FN24/FM24-1,"") | FO26: =IFERROR(FO24/FN24-1,"") | FQ26: =IFERROR(FQ24/FO24-1,"") | FR26: =IFERROR(FR24/FQ24-1,"") | FS26: =IFERROR(FS24/FR24-1,"") | FT26: =IFERROR(FT24/FS24-1,"") | FV26: =IFERROR(FV24/FT24-1,"") | FW26: =IFERROR(FW24/FV24-1,"") | FX26: =IFERROR(FX24/FW24-1,"") | FY26: =IFERROR(FY24/FX24-1,"") | GA26: =IFERROR(GA24/FY24-1,"") | GB26: =IFERROR(GB24/GA24-1,"") | GC26: =IFERROR(GC24/GB24-1,"") | GD26: =IFERROR(GD24/GC24-1,"") | GF26: =IFERROR(GF24/GD24-1,"") | GG26: =IFERROR(GG24/GF24-1,"") | GH26: =IFERROR(GH24/GG24-1,"") | GI26: =IFERROR(GI24/GH24-1,"")
B27: % of PBP | ER27: =ER24/ER$19 | ES27: =ES24/ES$19 | ET27: =ET24/ET$19 | EU27: =EU24/EU$19 | EV27: =EV24/EV$19 | EW27: =EW24/EW$19 | EX27: =EX24/EX$19 | EY27: =EY24/EY$19 | ... GJ27: =GJ24/GJ$19
B29: Total Microsoft 365 | ER29: =PBP!ER131 | ES29: =PBP!ES131 | ET29: =PBP!ET131 | EU29: =PBP!EU131 | EV29: =PBP!EV131 | EW29: =PBP!EW131 | EX29: =PBP!EX131 | EY29: =PBP!EY131 | ... GJ29: =PBP!GJ131
B30: % yoy | ER30: =IFERROR(ER29/EM29-1,"") | ES30: =IFERROR(ES29/EN29-1,"") | ET30: =IFERROR(ET29/EO29-1,"") | EU30: =IFERROR(EU29/EP29-1,"") | EV30: =IFERROR(EV29/EQ29-1,"") | EW30: =IFERROR(EW29/ER29-1,"") | EX30: =IFERROR(EX29/ES29-1,"") | EY30: =IFERROR(EY29/ET29-1,"") | ... GJ30: =IFERROR(GJ29/GE29-1,"")
B31: % qoq | ER31: =IFERROR(ER29/EP29-1,"") | ES31: =IFERROR(ES29/ER29-1,"") | ET31: =IFERROR(ET29/ES29-1,"") | EU31: =IFERROR(EU29/ET29-1,"") | EW31: =IFERROR(EW29/EU29-1,"") | EX31: =IFERROR(EX29/EW29-1,"") | EY31: =IFERROR(EY29/EX29-1,"") | EZ31: =IFERROR(EZ29/EY29-1,"") | FB31: =IFERROR(FB29/EZ29-1,"") | FC31: =IFERROR(FC29/FB29-1,"") | FD31: =IFERROR(FD29/FC29-1,"") | FE31: =IFERROR(FE29/FD29-1,"") | FG31: =IFERROR(FG29/FE29-1,"") | FH31: =IFERROR(FH29/FG29-1,"") | FI31: =IFERROR(FI29/FH29-1,"") | FJ31: =IFERROR(FJ29/FI29-1,"") | FL31: =IFERROR(FL29/FJ29-1,"") | FM31: =IFERROR(FM29/FL29-1,"") | FN31: =IFERROR(FN29/FM29-1,"") | FO31: =IFERROR(FO29/FN29-1,"") | FQ31: =IFERROR(FQ29/FO29-1,"") | FR31: =IFERROR(FR29/FQ29-1,"") | FS31: =IFERROR(FS29/FR29-1,"") | FT31: =IFERROR(FT29/FS29-1,"") | FV31: =IFERROR(FV29/FT29-1,"") | FW31: =IFERROR(FW29/FV29-1,"") | FX31: =IFERROR(FX29/FW29-1,"") | FY31: =IFERROR(FY29/FX29-1,"") | GA31: =IFERROR(GA29/FY29-1,"") | GB31: =IFERROR(GB29/GA29-1,"") | GC31: =IFERROR(GC29/GB29-1,"") | GD31: =IFERROR(GD29/GC29-1,"") | GF31: =IFERROR(GF29/GD29-1,"") | GG31: =IFERROR(GG29/GF29-1,"") | GH31: =IFERROR(GH29/GG29-1,"") | GI31: =IFERROR(GI29/GH29-1,"")
B32: % of PBP | ER32: =ER29/ER$19 | ES32: =ES29/ES$19 | ET32: =ET29/ET$19 | EU32: =EU29/EU$19 | EV32: =EV29/EV$19 | EW32: =EW29/EW$19 | EX32: =EX29/EX$19 | EY32: =EY29/EY$19 | ... GJ32: =GJ29/GJ$19
B34: Product0219 | DJ34: =PBP!DJ312 | DK34: =PBP!DK312 | DL34: =PBP!DL312 | DM34: =PBP!DM312 | DN34: =PBP!DN312 | DO34: =PBP!DO312 | DP34: =PBP!DP312 | DQ34: =PBP!DQ312 | ... GJ34: =PBP!GJ312
B35: % yoy | CT35: =IFERROR(CT34/CO34-1,"") | CU35: =IFERROR(CU34/CP34-1,"") | CV35: =IFERROR(CV34/CQ34-1,"") | CW35: =IFERROR(CW34/CR34-1,"") | CX35: =IFERROR(CX34/CS34-1,"") | CY35: =IFERROR(CY34/CT34-1,"") | CZ35: =IFERROR(CZ34/CU34-1,"") | DA35: =IFERROR(DA34/CV34-1,"") | ... GJ35: =IFERROR(GJ34/GE34-1,"")
B36: % qoq | CT36: =IFERROR(CT34/CR34-1,"") | CU36: =IFERROR(CU34/CT34-1,"") | CV36: =IFERROR(CV34/CU34-1,"") | CW36: =IFERROR(CW34/CV34-1,"") | CY36: =IFERROR(CY34/CW34-1,"") | CZ36: =IFERROR(CZ34/CY34-1,"") | DA36: =IFERROR(DA34/CZ34-1,"") | DB36: =IFERROR(DB34/DA34-1,"") | DD36: =IFERROR(DD34/DB34-1,"") | DE36: =IFERROR(DE34/DD34-1,"") | DF36: =IFERROR(DF34/DE34-1,"") | DG36: =IFERROR(DG34/DF34-1,"") | DI36: =IFERROR(DI34/DG34-1,"") | DJ36: =IFERROR(DJ34/DI34-1,"") | DK36: =IFERROR(DK34/DJ34-1,"") | DL36: =IFERROR(DL34/DK34-1,"") | DN36: =IFERROR(DN34/DL34-1,"") | DO36: =IFERROR(DO34/DN34-1,"") | DP36: =IFERROR(DP34/DO34-1,"") | DQ36: =IFERROR(DQ34/DP34-1,"") | DS36: =IFERROR(DS34/DQ34-1,"") | DT36: =IFERROR(DT34/DS34-1,"") | DU36: =IFERROR(DU34/DT34-1,"") | DV36: =IFERROR(DV34/DU34-1,"") | DX36: =IFERROR(DX34/DV34-1,"") | DY36: =IFERROR(DY34/DX34-1,"") | DZ36: =IFERROR(DZ34/DY34-1,"") | EA36: =IFERROR(EA34/DZ34-1,"") | EC36: =IFERROR(EC34/EA34-1,"") | ED36: =IFERROR(ED34/EC34-1,"") | EE36: =IFERROR(EE34/ED34-1,"") | EF36: =IFERROR(EF34/EE34-1,"") | EH36: =IFERROR(EH34/EF34-1,"") | EI36: =IFERROR(EI34/EH34-1,"") | EJ36: =IFERROR(EJ34/EI34-1,"") | EK36: =IFERROR(EK34/EJ34-1,"") | EM36: =IFERROR(EM34/EK34-1,"") | EN36: =IFERROR(EN34/EM34-1,"") | EO36: =IFERROR(EO34/EN34-1,"") | EP36: =IFERROR(EP34/EO34-1,"") | ER36: =IFERROR(ER34/EP34-1,"") | ES36: =IFERROR(ES34/ER34-1,"") | ET36: =IFERROR(ET34/ES34-1,"") | EU36: =IFERROR(EU34/ET34-1,"") | EW36: =IFERROR(EW34/EU34-1,"") | EX36: =IFERROR(EX34/EW34-1,"") | EY36: =IFERROR(EY34/EX34-1,"") | EZ36: =IFERROR(EZ34/EY34-1,"") | FB36: =IFERROR(FB34/EZ34-1,"") | FC36: =IFERROR(FC34/FB34-1,"") | FD36: =IFERROR(FD34/FC34-1,"") | FE36: =IFERROR(FE34/FD34-1,"") | FG36: =IFERROR(FG34/FE34-1,"") | FH36: =IFERROR(FH34/FG34-1,"") | FI36: =IFERROR(FI34/FH34-1,"") | FJ36: =IFERROR(FJ34/FI34-1,"") | FL36: =IFERROR(FL34/FJ34-1,"") | FM36: =IFERROR(FM34/FL34-1,"") | FN36: =IFERROR(FN34/FM34-1,"") | FO36: =IFERROR(FO34/FN34-1,"") | FQ36: =IFERROR(FQ34/FO34-1,"") | FR36: =IFERROR(FR34/FQ34-1,"") | FS36: =IFERROR(FS34/FR34-1,"") | FT36: =IFERROR(FT34/FS34-1,"") | FV36: =IFERROR(FV34/FT34-1,"") | FW36: =IFERROR(FW34/FV34-1,"") | FX36: =IFERROR(FX34/FW34-1,"") | FY36: =IFERROR(FY34/FX34-1,"") | GA36: =IFERROR(GA34/FY34-1,"") | GB36: =IFERROR(GB34/GA34-1,"") | GC36: =IFERROR(GC34/GB34-1,"") | GD36: =IFERROR(GD34/GC34-1,"") | GF36: =IFERROR(GF34/GD34-1,"") | GG36: =IFERROR(GG34/GF34-1,"") | GH36: =IFERROR(GH34/GG34-1,"") | GI36: =IFERROR(GI34/GH34-1,"")
B37: % of PBP | DJ37: =DJ34/DJ$19 | DK37: =DK34/DK$19 | DL37: =DL34/DL$19 | DM37: =DM34/DM$19 | DN37: =DN34/DN$19 | DO37: =DO34/DO$19 | DP37: =DP34/DP$19 | DQ37: =DQ34/DQ$19 | ... GJ37: =GJ34/GJ$19
B39: Dynamics | CT39: =PBP!CT347 | CU39: =PBP!CU347 | CV39: =PBP!CV347 | CW39: =PBP!CW347 | CX39: =PBP!CX347 | CY39: =PBP!CY347 | CZ39: =PBP!CZ347 | DA39: =PBP!DA347 | ... GJ39: =PBP!GJ347
B40: % yoy | CT40: =IFERROR(CT39/CO39-1,"") | CU40: =IFERROR(CU39/CP39-1,"") | CV40: =IFERROR(CV39/CQ39-1,"") | CW40: =IFERROR(CW39/CR39-1,"") | CX40: =IFERROR(CX39/CS39-1,"") | CY40: =IFERROR(CY39/CT39-1,"") | CZ40: =IFERROR(CZ39/CU39-1,"") | DA40: =IFERROR(DA39/CV39-1,"") | ... GJ40: =IFERROR(GJ39/GE39-1,"")
B41: % qoq | CT41: =IFERROR(CT39/CR39-1,"") | CU41: =IFERROR(CU39/CT39-1,"") | CV41: =IFERROR(CV39/CU39-1,"") | CW41: =IFERROR(CW39/CV39-1,"") | CY41: =IFERROR(CY39/CW39-1,"") | CZ41: =IFERROR(CZ39/CY39-1,"") | DA41: =IFERROR(DA39/CZ39-1,"") | DB41: =IFERROR(DB39/DA39-1,"") | DD41: =IFERROR(DD39/DB39-1,"") | DE41: =IFERROR(DE39/DD39-1,"") | DF41: =IFERROR(DF39/DE39-1,"") | DG41: =IFERROR(DG39/DF39-1,"") | DI41: =IFERROR(DI39/DG39-1,"") | DJ41: =IFERROR(DJ39/DI39-1,"") | DK41: =IFERROR(DK39/DJ39-1,"") | DL41: =IFERROR(DL39/DK39-1,"") | DN41: =IFERROR(DN39/DL39-1,"") | DO41: =IFERROR(DO39/DN39-1,"") | DP41: =IFERROR(DP39/DO39-1,"") | DQ41: =IFERROR(DQ39/DP39-1,"") | DS41: =IFERROR(DS39/DQ39-1,"") | DT41: =IFERROR(DT39/DS39-1,"") | DU41: =IFERROR(DU39/DT39-1,"") | DV41: =IFERROR(DV39/DU39-1,"") | DX41: =IFERROR(DX39/DV39-1,"") | DY41: =IFERROR(DY39/DX39-1,"") | DZ41: =IFERROR(DZ39/DY39-1,"") | EA41: =IFERROR(EA39/DZ39-1,"") | EC41: =IFERROR(EC39/EA39-1,"") | ED41: =IFERROR(ED39/EC39-1,"") | EE41: =IFERROR(EE39/ED39-1,"") | EF41: =IFERROR(EF39/EE39-1,"") | EH41: =IFERROR(EH39/EF39-1,"") | EI41: =IFERROR(EI39/EH39-1,"") | EJ41: =IFERROR(EJ39/EI39-1,"") | EK41: =IFERROR(EK39/EJ39-1,"") | EM41: =IFERROR(EM39/EK39-1,"") | EN41: =IFERROR(EN39/EM39-1,"") | EO41: =IFERROR(EO39/EN39-1,"") | EP41: =IFERROR(EP39/EO39-1,"") | ER41: =IFERROR(ER39/EP39-1,"") | ES41: =IFERROR(ES39/ER39-1,"") | ET41: =IFERROR(ET39/ES39-1,"") | EU41: =IFERROR(EU39/ET39-1,"") | EW41: =IFERROR(EW39/EU39-1,"") | EX41: =IFERROR(EX39/EW39-1,"") | EY41: =IFERROR(EY39/EX39-1,"") | EZ41: =IFERROR(EZ39/EY39-1,"") | FB41: =IFERROR(FB39/EZ39-1,"") | FC41: =IFERROR(FC39/FB39-1,"") | FD41: =IFERROR(FD39/FC39-1,"") | FE41: =IFERROR(FE39/FD39-1,"") | FG41: =IFERROR(FG39/FE39-1,"") | FH41: =IFERROR(FH39/FG39-1,"") | FI41: =IFERROR(FI39/FH39-1,"") | FJ41: =IFERROR(FJ39/FI39-1,"") | FL41: =IFERROR(FL39/FJ39-1,"") | FM41: =IFERROR(FM39/FL39-1,"") | FN41: =IFERROR(FN39/FM39-1,"") | FO41: =IFERROR(FO39/FN39-1,"") | FQ41: =IFERROR(FQ39/FO39-1,"") | FR41: =IFERROR(FR39/FQ39-1,"") | FS41: =IFERROR(FS39/FR39-1,"") | FT41: =IFERROR(FT39/FS39-1,"") | FV41: =IFERROR(FV39/FT39-1,"") | FW41: =IFERROR(FW39/FV39-1,"") | FX41: =IFERROR(FX39/FW39-1,"") | FY41: =IFERROR(FY39/FX39-1,"") | GA41: =IFERROR(GA39/FY39-1,"") | GB41: =IFERROR(GB39/GA39-1,"") | GC41: =IFERROR(GC39/GB39-1,"") | GD41: =IFERROR(GD39/GC39-1,"") | GF41: =IFERROR(GF39/GD39-1,"") | GG41: =IFERROR(GG39/GF39-1,"") | GH41: =IFERROR(GH39/GG39-1,"") | GI41: =IFERROR(GI39/GH39-1,"")
B42: % of PBP | DJ42: =DJ39/DJ$19 | DK42: =DK39/DK$19 | DL42: =DL39/DL$19 | DM42: =DM39/DM$19 | DN42: =DN39/DN$19 | DO42: =DO39/DO$19 | DP42: =DP39/DP$19 | DQ42: =DQ39/DQ$19 | ... GJ42: =GJ39/GJ$19
B44: IC Revenue | CY44: =IFERROR(IC!CY50,"") | CZ44: =IFERROR(IC!CZ50,"") | DA44: =IFERROR(IC!DA50,"") | DB44: =IFERROR(IC!DB50,"") | DC44: =IFERROR(IC!DC50,"") | DD44: =IFERROR(IC!DD50,"") | DE44: =IFERROR(IC!DE50,"") | DF44: =IFERROR(IC!DF50,"") | ... EQ44: =IFERROR(IC!EQ50,"") | ER44: =IC!ER10 | ES44: =IC!ES10 | ET44: =IC!ET10 | EU44: =IC!EU10 | EV44: =IC!EV10 | EW44: =IC!EW10 | EX44: =IC!EX10 | EY44: =IC!EY10 | ... GJ44: =IC!GJ10
B45: % yoy | DD45: =IFERROR(DD44/CY44-1,"") | DE45: =IFERROR(DE44/CZ44-1,"") | DF45: =IFERROR(DF44/DA44-1,"") | DG45: =IFERROR(DG44/DB44-1,"") | DH45: =IFERROR(DH44/DC44-1,"") | DI45: =IFERROR(DI44/DD44-1,"") | DJ45: =IFERROR(DJ44/DE44-1,"") | DK45: =IFERROR(DK44/DF44-1,"") | ... GJ45: =IFERROR(GJ44/GE44-1,"")
B46: % qoq | CZ46: =IFERROR(CZ44/CY44-1,"") | DA46: =IFERROR(DA44/CZ44-1,"") | DB46: =IFERROR(DB44/DA44-1,"") | DD46: =IFERROR(DD44/DB44-1,"") | DE46: =IFERROR(DE44/DD44-1,"") | DF46: =IFERROR(DF44/DE44-1,"") | DG46: =IFERROR(DG44/DF44-1,"") | DI46: =IFERROR(DI44/DG44-1,"") | DJ46: =IFERROR(DJ44/DI44-1,"") | DK46: =IFERROR(DK44/DJ44-1,"") | DL46: =IFERROR(DL44/DK44-1,"") | DN46: =IFERROR(DN44/DL44-1,"") | DO46: =IFERROR(DO44/DN44-1,"") | DP46: =IFERROR(DP44/DO44-1,"") | DQ46: =IFERROR(DQ44/DP44-1,"") | DS46: =IFERROR(DS44/DQ44-1,"") | DT46: =IFERROR(DT44/DS44-1,"") | DU46: =IFERROR(DU44/DT44-1,"") | DV46: =IFERROR(DV44/DU44-1,"") | DX46: =IFERROR(DX44/DV44-1,"") | DY46: =IFERROR(DY44/DX44-1,"") | DZ46: =IFERROR(DZ44/DY44-1,"") | EA46: =IFERROR(EA44/DZ44-1,"") | EC46: =IFERROR(EC44/EA44-1,"") | ED46: =IFERROR(ED44/EC44-1,"") | EE46: =IFERROR(EE44/ED44-1,"") | EF46: =IFERROR(EF44/EE44-1,"") | EH46: =IFERROR(EH44/EF44-1,"") | EI46: =IFERROR(EI44/EH44-1,"") | EJ46: =IFERROR(EJ44/EI44-1,"") | EK46: =IFERROR(EK44/EJ44-1,"") | EM46: =IFERROR(EM44/EK44-1,"") | EN46: =IFERROR(EN44/EM44-1,"") | EO46: =IFERROR(EO44/EN44-1,"") | EP46: =IFERROR(EP44/EO44-1,"") | ER46: =IFERROR(ER44/EP44-1,"") | ES46: =IFERROR(ES44/ER44-1,"") | ET46: =IFERROR(ET44/ES44-1,"") | EU46: =IFERROR(EU44/ET44-1,"") | EW46: =IFERROR(EW44/EU44-1,"") | EX46: =IFERROR(EX44/EW44-1,"") | EY46: =IFERROR(EY44/EX44-1,"") | EZ46: =IFERROR(EZ44/EY44-1,"") | FB46: =IFERROR(FB44/EZ44-1,"") | FC46: =IFERROR(FC44/FB44-1,"") | FD46: =IFERROR(FD44/FC44-1,"") | FE46: =IFERROR(FE44/FD44-1,"") | FG46: =IFERROR(FG44/FE44-1,"") | FH46: =IFERROR(FH44/FG44-1,"") | FI46: =IFERROR(FI44/FH44-1,"") | FJ46: =IFERROR(FJ44/FI44-1,"") | FL46: =IFERROR(FL44/FJ44-1,"") | FM46: =IFERROR(FM44/FL44-1,"") | FN46: =IFERROR(FN44/FM44-1,"") | FO46: =IFERROR(FO44/FN44-1,"") | FQ46: =IFERROR(FQ44/FO44-1,"") | FR46: =IFERROR(FR44/FQ44-1,"") | FS46: =IFERROR(FS44/FR44-1,"") | FT46: =IFERROR(FT44/FS44-1,"") | FV46: =IFERROR(FV44/FT44-1,"") | FW46: =IFERROR(FW44/FV44-1,"") | FX46: =IFERROR(FX44/FW44-1,"") | FY46: =IFERROR(FY44/FX44-1,"") | GA46: =IFERROR(GA44/FY44-1,"") | GB46: =IFERROR(GB44/GA44-1,"") | GC46: =IFERROR(GC44/GB44-1,"") | GD46: =IFERROR(GD44/GC44-1,"") | GF46: =IFERROR(GF44/GD44-1,"") | GG46: =IFERROR(GG44/GF44-1,"") | GH46: =IFERROR(GH44/GG44-1,"") | GI46: =IFERROR(GI44/GH44-1,"")
B47: % Total Revenue | CY47: =CY44/CY$10 | CZ47: =CZ44/CZ$10 | DA47: =DA44/DA$10 | DB47: =DB44/DB$10 | DC47: =DC44/DC$10 | DD47: =DD44/DD$10 | DE47: =DE44/DE$10 | DF47: =DF44/DF$10 | ... GJ47: =GJ44/GJ$10
B49: Product0058 | EM49: =IC!EM108 | EN49: =IC!EN108 | EO49: =IC!EO108 | EP49: =IC!EP108 | EQ49: =IC!EQ108 | ER49: =IC!ER108 | ES49: =IC!ES108 | ET49: =IC!ET108 | ... GJ49: =IC!GJ108
B50: % yoy | ER50: =IFERROR(ER49/EM49-1,"") | ES50: =IFERROR(ES49/EN49-1,"") | ET50: =IFERROR(ET49/EO49-1,"") | EU50: =IFERROR(EU49/EP49-1,"") | EV50: =IFERROR(EV49/EQ49-1,"") | EW50: =IFERROR(EW49/ER49-1,"") | EX50: =IFERROR(EX49/ES49-1,"") | EY50: =IFERROR(EY49/ET49-1,"") | ... GJ50: =IFERROR(GJ49/GE49-1,"")
...

Sheet Leading Indicators
B2: Microsoft, Inc.
B3: Fiscal Year Ends Jun. 30
B4: ($ millions, except per share amounts) | ER4: Resegmenting
C6: =Dates!C3 | H6: =Dates!H3 | M6: =Dates!M3 | R6: =Dates!R3 | W6: =Dates!W3 | AB6: =Dates!AB3 | AG6: =Dates!AG3 | AL6: =Dates!AL3 | AQ6: =Dates!AQ3 | AV6: =Dates!AV3 | BA6: =Dates!BA3 | BF6: =Dates!BF3 | BK6: =Dates!BK3 | BP6: =Dates!BP3 | BU6: =Dates!BU3 | BZ6: =Dates!BZ3 | CE6: =Dates!CE3 | CJ6: =Dates!CJ3 | CO6: =Dates!CO3 | CT6: =Dates!CT3 | CY6: =Dates!CY3 | DD6: =Dates!DD3 | DI6: =Dates!DI3 | DN6: =Dates!DN3 | DS6: =Dates!DS3 | DX6: =Dates!DX3 | EC6: =Dates!EC3 | EH6: =Dates!EH3 | EM6: =Dates!EM3 | ER6: =Dates!ER3 | EW6: =Dates!EW3 | FB6: =Dates!FB3 | FG6: =Dates!FG3 | FL6: =Dates!FL3 | FQ6: =Dates!FQ3 | FV6: =Dates!FV3 | GA6: =Dates!GA3 | GF6: =Dates!GF3
C7: =Dates!C4 | D7: =Dates!D4 | E7: =Dates!E4 | F7: =Dates!F4 | G7: =Dates!G4 | H7: =Dates!H4 | I7: =Dates!I4 | J7: =Dates!J4 | ... GJ7: =Dates!GJ4
C8: =Dates!C5 | D8: =Dates!D5 | E8: =Dates!E5 | F8: =Dates!F5 | G8: =Dates!G5 | H8: =Dates!H5 | I8: =Dates!I5 | J8: =Dates!J5 | ... GJ8: =Dates!GJ5
B10: Inputs
B12: PBP Revenue | CY12: =IFERROR(PBP!CY50,"") | CZ12: =IFERROR(PBP!CZ50,"") | DA12: =IFERROR(PBP!DA50,"") | DB12: =IFERROR(PBP!DB50,"") | DC12: =IFERROR(PBP!DC50,"") | DD12: =IFERROR(PBP!DD50,"") | DE12: =IFERROR(PBP!DE50,"") | DF12: =IFERROR(PBP!DF50,"") | ... EQ12: =IFERROR(PBP!EQ50,"") | ER12: =PBP!ER10 | ES12: =PBP!ES10 | ET12: =PBP!ET10 | EU12: =PBP!EU10 | EV12: =PBP!EV10 | EW12: =PBP!EW10 | EX12: =PBP!EX10 | EY12: =PBP!EY10 | ... GJ12: =PBP!GJ10
B13: IC Revenue | CY13: =IFERROR(IC!CY50,"") | CZ13: =IFERROR(IC!CZ50,"") | DA13: =IFERROR(IC!DA50,"") | DB13: =IFERROR(IC!DB50,"") | DC13: =IFERROR(IC!DC50,"") | DD13: =IFERROR(IC!DD50,"") | DE13: =IFERROR(IC!DE50,"") | DF13: =IFERROR(IC!DF50,"") | ... EQ13: =IFERROR(IC!EQ50,"") | ER13: =IC!ER10 | ES13: =IC!ES10 | ET13: =IC!ET10 | EU13: =IC!EU10 | EV13: =IC!EV10 | EW13: =IC!EW10 | EX13: =IC!EX10 | EY13: =IC!EY10 | ... GJ13: =IC!GJ10
B14: Company1738 Revenue | CY14: =IFERROR(Company1738!CY50,"") | CZ14: =IFERROR(Company1738!CZ50,"") | DA14: =IFERROR(Company1738!DA50,"") | DB14: =IFERROR(Company1738!DB50,"") | DC14: =IFERROR(Company1738!DC50,"") | DD14: =IFERROR(Company1738!DD50,"") | DE14: =IFERROR(Company1738!DE50,"") | DF14: =IFERROR(Company1738!DF50,"") | ... EQ14: =IFERROR(Company1738!EQ50,"") | ER14: =Company1738!ER10 | ES14: =Company1738!ES10 | ET14: =Company1738!ET10 | EU14: =Company1738!EU10 | EV14: =Company1738!EV10 | EW14: =Company1738!EW10 | EX14: =Company1738!EX10 | EY14: =Company1738!EY10 | ... GJ14: =Company1738!GJ10
A15: TREV | B15: Total Revenue | CY15: =SUM(CY12:CY14) | CZ15: =SUM(CZ12:CZ14) | DA15: =SUM(DA12:DA14) | DB15: =SUM(DB12:DB14) | DC15: =SUM(DC12:DC14) | DD15: =SUM(DD12:DD14) | DE15: =SUM(DE12:DE14) | DF15: =SUM(DF12:DF14) | ... GJ15: =SUM(GJ12:GJ14)
B17: Microsoft Cloud Revenue | DG17: ='Ticker0024 Cloud'!DG10 | DH17: ='Ticker0024 Cloud'!DH10 | DI17: ='Ticker0024 Cloud'!DI10 | DJ17: ='Ticker0024 Cloud'!DJ10 | DK17: ='Ticker0024 Cloud'!DK10 | DL17: ='Ticker0024 Cloud'!DL10 | DM17: ='Ticker0024 Cloud'!DM10 | DN17: ='Ticker0024 Cloud'!DN10 | ... GJ17: ='Ticker0024 Cloud'!GJ10
B18: % of Total Revenue | DG18: =IFERROR(DG17/DG15,"") | DI18: =IFERROR(DI17/DI15,"") | DJ18: =IFERROR(DJ17/DJ15,"") | DK18: =IFERROR(DK17/DK15,"") | DL18: =IFERROR(DL17/DL15,"") | DM18: =IFERROR(DM17/DM15,"") | DN18: =IFERROR(DN17/DN15,"") | DO18: =IFERROR(DO17/DO15,"") | DP18: =IFERROR(DP17/DP15,"") | ... GJ18: =IFERROR(GJ17/GJ15,"")
B19: Microsoft Cloud NTM Revenue | DF19: =DG17+DI17+DJ17+DK17 | DG19: =DI17+DJ17+DK17+DL17 | DH19: =DM17 | DI19: =DJ17+DK17+DL17+DN17 | DJ19: =DK17+DL17+DN17+DO17 | DK19: =DL17+DN17+DO17+DP17 | DL19: =DN17+DO17+DP17+DQ17 | DM19: =DR17 | DN19: =DO17+DP17+DQ17+DS17 | DO19: =DP17+DQ17+DS17+DT17 | DP19: =DQ17+DS17+DT17+DU17 | DQ19: =DS17+DT17+DU17+DV17 | DR19: =DW17 | DS19: =DT17+DU17+DV17+DX17 | DT19: =DU17+DV17+DX17+DY17 | DU19: =DV17+DX17+DY17+DZ17 | DV19: =DX17+DY17+DZ17+EA17 | DW19: =EB17 | DX19: =DY17+DZ17+EA17+EC17 | DY19: =DZ17+EA17+EC17+ED17 | DZ19: =EA17+EC17+ED17+EE17 | EA19: =EC17+ED17+EE17+EF17 | EB19: =EG17 | EC19: =ED17+EE17+EF17+EH17 | ED19: =EE17+EF17+EH17+EI17 | EE19: =EF17+EH17+EI17+EJ17 | EF19: =EH17+EI17+EJ17+EK17 | EG19: =EL17 | EH19: =EI17+EJ17+EK17+EM17 | EI19: =EJ17+EK17+EM17+EN17 | EJ19: =EK17+EM17+EN17+EO17 | EK19: =EM17+EN17+EO17+EP17 | EL19: =EQ17 | EM19: =EN17+EO17+EP17+ER17 | EN19: =EO17+EP17+ER17+ES17 | EO19: =EP17+ER17+ES17+ET17 | EP19: =ER17+ES17+ET17+EU17 | EQ19: =EV17 | ER19: =ES17+ET17+EU17+EW17 | ES19: =ET17+EU17+EW17+EX17 | ET19: =EU17+EW17+EX17+EY17 | EU19: =EW17+EX17+EY17+EZ17 | EV19: =FA17 | EW19: =EX17+EY17+EZ17+FB17 | EX19: =EY17+EZ17+FA17+FC17 | EY19: =EZ17+FA17+FB17+FD17 | EZ19: =FB17+FC17+FD17+FE17 | FA19: =FF17 | FB19: =FC17+FD17+FE17+FG17 | FC19: =FD17+FE17+FG17+FH17 | FD19: =FE17+FG17+FH17+FI17 | FE19: =FG17+FH17+FI17+FJ17 | FF19: =FK17 | FG19: =FH17+FI17+FJ17+FL17 | FH19: =FI17+FJ17+FL17+FM17 | FI19: =FJ17+FL17+FM17+FN17 | FJ19: =FL17+FM17+FN17+FO17 | FK19: =FP17 | FL19: =FM17+FN17+FO17+FQ17 | FM19: =FN17+FO17+FQ17+FR17 | FN19: =FO17+FQ17+FR17+FS17 | FO19: =FQ17+FR17+FS17+FT17 | FP19: =FU17 | FQ19: =FR17+FS17+FT17+FV17 | FR19: =FS17+FT17+FV17+FW17 | FS19: =FT17+FV17+FW17+FX17 | FT19: =FV17+FW17+FX17+FY17 | FU19: =FZ17 | FV19: =FW17+FX17+FY17+GA17 | FW19: =FX17+FY17+GA17+GB17 | FX19: =FY17+GA17+GB17+GC17 | FY19: =GA17+GB17+GC17+GD17 | FZ19: =GE17
B21: PBP NTM Revenue | CY21: =CZ12+DA12+DB12+DD12 | CZ21: =DA12+DB12+DD12+DE12 | DA21: =DB12+DD12+DE12+DF12 | DB21: =DD12+DE12+DF12+DG12 | DC21: =DH12 | DD21: =DE12+DF12+DG12+DI12 | DE21: =DF12+DG12+DI12+DJ12 | DF21: =DG12+DI12+DJ12+DK12 | DG21: =DI12+DJ12+DK12+DL12 | DH21: =DM12 | DI21: =DJ12+DK12+DL12+DN12 | DJ21: =DK12+DL12+DN12+DO12 | DK21: =DL12+DN12+DO12+DP12 | DL21: =DN12+DO12+DP12+DQ12 | DM21: =DR12 | DN21: =DO12+DP12+DQ12+DS12 | DO21: =DP12+DQ12+DS12+DT12 | DP21: =DQ12+DS12+DT12+DU12 | DQ21: =DS12+DT12+DU12+DV12 | DR21: =DW12 | DS21: =DT12+DU12+DV12+DX12 | DT21: =DU12+DV12+DX12+DY12 | DU21: =DV12+DX12+DY12+DZ12 | DV21: =DX12+DY12+DZ12+EA12 | DW21: =EB12 | DX21: =DY12+DZ12+EA12+EC12 | DY21: =DZ12+EA12+EC12+ED12 | DZ21: =EA12+EC12+ED12+EE12 | EA21: =EC12+ED12+EE12+EF12 | EB21: =EG12 | EC21: =ED12+EE12+EF12+EH12 | ED21: =EE12+EF12+EH12+EI12 | EE21: =EF12+EH12+EI12+EJ12 | EF21: =EH12+EI12+EJ12+EK12 | EG21: =EL12 | EH21: =EI12+EJ12+EK12+EM12 | EI21: =EJ12+EK12+EM12+EN12 | EJ21: =EK12+EM12+EN12+EO12 | EK21: =EM12+EN12+EO12+EP12 | EL21: =EQ12 | EM21: =EN12+EO12+EP12+ER12 | EN21: =EO12+EP12+ER12+ES12 | EO21: =EP12+ER12+ES12+ET12 | EP21: =ER12+ES12+ET12+EU12 | EQ21: =EV12 | ER21: =ES12+ET12+EU12+EW12 | ES21: =ET12+EU12+EW12+EX12 | ET21: =EU12+EW12+EX12+EY12 | EU21: =EW12+EX12+EY12+EZ12 | EV21: =FA12 | EW21: =EX12+EY12+EZ12+FB12 | EX21: =EY12+EZ12+FA12+FC12 | EY21: =EZ12+FA12+FB12+FD12 | EZ21: =FB12+FC12+FD12+FE12 | FA21: =FF12 | FB21: =FC12+FD12+FE12+FG12 | FC21: =FD12+FE12+FG12+FH12 | FD21: =FE12+FG12+FH12+FI12 | FE21: =FG12+FH12+FI12+FJ12 | FF21: =FK12 | FG21: =FH12+FI12+FJ12+FL12 | FH21: =FI12+FJ12+FL12+FM12 | FI21: =FJ12+FL12+FM12+FN12 | FJ21: =FL12+FM12+FN12+FO12 | FK21: =FP12 | FL21: =FM12+FN12+FO12+FQ12 | FM21: =FN12+FO12+FQ12+FR12 | FN21: =FO12+FQ12+FR12+FS12 | FO21: =FQ12+FR12+FS12+FT12 | FP21: =FU12 | FQ21: =FR12+FS12+FT12+FV12 | FR21: =FS12+FT12+FV12+FW12 | FS21: =FT12+FV12+FW12+FX12 | FT21: =FV12+FW12+FX12+FY12 | FU21: =FZ12 | FV21: =FW12+FX12+FY12+GA12 | FW21: =FX12+FY12+GA12+GB12 | FX21: =FY12+GA12+GB12+GC12 | FY21: =GA12+GB12+GC12+GD12 | FZ21: =GE12
B22: IC NTM Revenue | CY22: =CZ13+DA13+DB13+DD13 | CZ22: =DA13+DB13+DD13+DE13 | DA22: =DB13+DD13+DE13+DF13 | DB22: =DD13+DE13+DF13+DG13 | DC22: =DH13 | DD22: =DE13+DF13+DG13+DI13 | DE22: =DF13+DG13+DI13+DJ13 | DF22: =DG13+DI13+DJ13+DK13 | DG22: =DI13+DJ13+DK13+DL13 | DH22: =DM13 | DI22: =DJ13+DK13+DL13+DN13 | DJ22: =DK13+DL13+DN13+DO13 | DK22: =DL13+DN13+DO13+DP13 | DL22: =DN13+DO13+DP13+DQ13 | DM22: =DR13 | DN22: =DO13+DP13+DQ13+DS13 | DO22: =DP13+DQ13+DS13+DT13 | DP22: =DQ13+DS13+DT13+DU13 | DQ22: =DS13+DT13+DU13+DV13 | DR22: =DW13 | DS22: =DT13+DU13+DV13+DX13 | DT22: =DU13+DV13+DX13+DY13 | DU22: =DV13+DX13+DY13+DZ13 | DV22: =DX13+DY13+DZ13+EA13 | DW22: =EB13 | DX22: =DY13+DZ13+EA13+EC13 | DY22: =DZ13+EA13+EC13+ED13 | DZ22: =EA13+EC13+ED13+EE13 | EA22: =EC13+ED13+EE13+EF13 | EB22: =EG13 | EC22: =ED13+EE13+EF13+EH13 | ED22: =EE13+EF13+EH13+EI13 | EE22: =EF13+EH13+EI13+EJ13 | EF22: =EH13+EI13+EJ13+EK13 | EG22: =EL13 | EH22: =EI13+EJ13+EK13+EM13 | EI22: =EJ13+EK13+EM13+EN13 | EJ22: =EK13+EM13+EN13+EO13 | EK22: =EM13+EN13+EO13+EP13 | EL22: =EQ13 | EM22: =EN13+EO13+EP13+ER13 | EN22: =EO13+EP13+ER13+ES13 | EO22: =EP13+ER13+ES13+ET13 | EP22: =ER13+ES13+ET13+EU13 | EQ22: =EV13 | ER22: =ES13+ET13+EU13+EW13 | ES22: =ET13+EU13+EW13+EX13 | ET22: =EU13+EW13+EX13+EY13 | EU22: =EW13+EX13+EY13+EZ13 | EV22: =FA13 | EW22: =EX13+EY13+EZ13+FB13 | EX22: =EY13+EZ13+FA13+FC13 | EY22: =EZ13+FA13+FB13+FD13 | EZ22: =FB13+FC13+FD13+FE13 | FA22: =FF13 | FB22: =FC13+FD13+FE13+FG13 | FC22: =FD13+FE13+FG13+FH13 | FD22: =FE13+FG13+FH13+FI13 | FE22: =FG13+FH13+FI13+FJ13 | FF22: =FK13 | FG22: =FH13+FI13+FJ13+FL13 | FH22: =FI13+FJ13+FL13+FM13 | FI22: =FJ13+FL13+FM13+FN13 | FJ22: =FL13+FM13+FN13+FO13 | FK22: =FP13 | FL22: =FM13+FN13+FO13+FQ13 | FM22: =FN13+FO13+FQ13+FR13 | FN22: =FO13+FQ13+FR13+FS13 | FO22: =FQ13+FR13+FS13+FT13 | FP22: =FU13 | FQ22: =FR13+FS13+FT13+FV13 | FR22: =FS13+FT13+FV13+FW13 | FS22: =FT13+FV13+FW13+FX13 | FT22: =FV13+FW13+FX13+FY13 | FU22: =FZ13 | FV22: =FW13+FX13+FY13+GA13 | FW22: =FX13+FY13+GA13+GB13 | FX22: =FY13+GA13+GB13+GC13 | FY22: =GA13+GB13+GC13+GD13 | FZ22: =GE13
B23: Company1738 NTM Revenue | CY23: =CZ14+DA14+DB14+DD14 | CZ23: =DA14+DB14+DD14+DE14 | DA23: =DB14+DD14+DE14+DF14 | DB23: =DD14+DE14+DF14+DG14 | DC23: =DH14 | DD23: =DE14+DF14+DG14+DI14 | DE23: =DF14+DG14+DI14+DJ14 | DF23: =DG14+DI14+DJ14+DK14 | DG23: =DI14+DJ14+DK14+DL14 | DH23: =DM14 | DI23: =DJ14+DK14+DL14+DN14 | DJ23: =DK14+DL14+DN14+DO14 | DK23: =DL14+DN14+DO14+DP14 | DL23: =DN14+DO14+DP14+DQ14 | DM23: =DR14 | DN23: =DO14+DP14+DQ14+DS14 | DO23: =DP14+DQ14+DS14+DT14 | DP23: =DQ14+DS14+DT14+DU14 | DQ23: =DS14+DT14+DU14+DV14 | DR23: =DW14 | DS23: =DT14+DU14+DV14+DX14 | DT23: =DU14+DV14+DX14+DY14 | DU23: =DV14+DX14+DY14+DZ14 | DV23: =DX14+DY14+DZ14+EA14 | DW23: =EB14 | DX23: =DY14+DZ14+EA14+EC14 | DY23: =DZ14+EA14+EC14+ED14 | DZ23: =EA14+EC14+ED14+EE14 | EA23: =EC14+ED14+EE14+EF14 | EB23: =EG14 | EC23: =ED14+EE14+EF14+EH14 | ED23: =EE14+EF14+EH14+EI14 | EE23: =EF14+EH14+EI14+EJ14 | EF23: =EH14+EI14+EJ14+EK14 | EG23: =EL14 | EH23: =EI14+EJ14+EK14+EM14 | EI23: =EJ14+EK14+EM14+EN14 | EJ23: =EK14+EM14+EN14+EO14 | EK23: =EM14+EN14+EO14+EP14 | EL23: =EQ14 | EM23: =EN14+EO14+EP14+ER14 | EN23: =EO14+EP14+ER14+ES14 | EO23: =EP14+ER14+ES14+ET14 | EP23: =ER14+ES14+ET14+EU14 | EQ23: =EV14 | ER23: =ES14+ET14+EU14+EW14 | ES23: =ET14+EU14+EW14+EX14 | ET23: =EU14+EW14+EX14+EY14 | EU23: =EW14+EX14+EY14+EZ14 | EV23: =FA14 | EW23: =EX14+EY14+EZ14+FB14 | EX23: =EY14+EZ14+FA14+FC14 | EY23: =EZ14+FA14+FB14+FD14 | EZ23: =FB14+FC14+FD14+FE14 | FA23: =FF14 | FB23: =FC14+FD14+FE14+FG14 | FC23: =FD14+FE14+FG14+FH14 | FD23: =FE14+FG14+FH14+FI14 | FE23: =FG14+FH14+FI14+FJ14 | FF23: =FK14 | FG23: =FH14+FI14+FJ14+FL14 | FH23: =FI14+FJ14+FL14+FM14 | FI23: =FJ14+FL14+FM14+FN14 | FJ23: =FL14+FM14+FN14+FO14 | FK23: =FP14 | FL23: =FM14+FN14+FO14+FQ14 | FM23: =FN14+FO14+FQ14+FR14 | FN23: =FO14+FQ14+FR14+FS14 | FO23: =FQ14+FR14+FS14+FT14 | FP23: =FU14 | FQ23: =FR14+FS14+FT14+FV14 | FR23: =FS14+FT14+FV14+FW14 | FS23: =FT14+FV14+FW14+FX14 | FT23: =FV14+FW14+FX14+FY14 | FU23: =FZ14 | FV23: =FW14+FX14+FY14+GA14 | FW23: =FX14+FY14+GA14+GB14 | FX23: =FY14+GA14+GB14+GC14 | FY23: =GA14+GB14+GC14+GD14 | FZ23: =GE14
B24: NTM Revenue | CY24: =CZ15+DA15+DB15+DD15 | CZ24: =DA15+DB15+DD15+DE15 | DA24: =DB15+DD15+DE15+DF15 | DB24: =DD15+DE15+DF15+DG15 | DC24: =DH15 | DD24: =DE15+DF15+DG15+DI15 | DE24: =DF15+DG15+DI15+DJ15 | DF24: =DG15+DI15+DJ15+DK15 | DG24: =DI15+DJ15+DK15+DL15 | DH24: =DM15 | DI24: =DJ15+DK15+DL15+DN15 | DJ24: =DK15+DL15+DN15+DO15 | DK24: =DL15+DN15+DO15+DP15 | DL24: =DN15+DO15+DP15+DQ15 | DM24: =DR15 | DN24: =DO15+DP15+DQ15+DS15 | DO24: =DP15+DQ15+DS15+DT15 | DP24: =DQ15+DS15+DT15+DU15 | DQ24: =DS15+DT15+DU15+DV15 | DR24: =DW15 | DS24: =DT15+DU15+DV15+DX15 | DT24: =DU15+DV15+DX15+DY15 | DU24: =DV15+DX15+DY15+DZ15 | DV24: =DX15+DY15+DZ15+EA15 | DW24: =EB15 | DX24: =DY15+DZ15+EA15+EC15 | DY24: =DZ15+EA15+EC15+ED15 | DZ24: =EA15+EC15+ED15+EE15 | EA24: =EC15+ED15+EE15+EF15 | EB24: =EG15 | EC24: =ED15+EE15+EF15+EH15 | ED24: =EE15+EF15+EH15+EI15 | EE24: =EF15+EH15+EI15+EJ15 | EF24: =EH15+EI15+EJ15+EK15 | EG24: =EL15 | EH24: =EI15+EJ15+EK15+EM15 | EI24: =EJ15+EK15+EM15+EN15 | EJ24: =EK15+EM15+EN15+EO15 | EK24: =EM15+EN15+EO15+EP15 | EL24: =EQ15 | EM24: =EN15+EO15+EP15+ER15 | EN24: =EO15+EP15+ER15+ES15 | EO24: =EP15+ER15+ES15+ET15 | EP24: =ER15+ES15+ET15+EU15 | EQ24: =EV15 | ER24: =ES15+ET15+EU15+EW15 | ES24: =ET15+EU15+EW15+EX15 | ET24: =EU15+EW15+EX15+EY15 | EU24: =EW15+EX15+EY15+EZ15 | EV24: =FA15 | EW24: =EX15+EY15+EZ15+FB15 | EX24: =EY15+EZ15+FB15+FC15 | EY24: =EZ15+FB15+FC15+FD15 | EZ24: =FB15+FC15+FD15+FE15 | FA24: =FF15 | FB24: =FC15+FD15+FE15+FG15 | FC24: =FD15+FE15+FG15+FH15 | FD24: =FE15+FG15+FH15+FI15 | FE24: =FG15+FH15+FI15+FJ15 | FF24: =FK15 | FG24: =FH15+FI15+FJ15+FL15 | FH24: =FI15+FJ15+FL15+FM15 | FI24: =FJ15+FL15+FM15+FN15 | FJ24: =FL15+FM15+FN15+FO15 | FK24: =FP15 | FL24: =FM15+FN15+FO15+FQ15 | FM24: =FN15+FO15+FQ15+FR15 | FN24: =FO15+FQ15+FR15+FS15 | FO24: =FQ15+FR15+FS15+FT15 | FP24: =FU15 | FQ24: =FR15+FS15+FT15+FV15 | FR24: =FS15+FT15+FV15+FW15 | FS24: =FT15+FV15+FW15+FX15 | FT24: =FV15+FW15+FX15+FY15 | FU24: =FZ15 | FV24: =FW15+FX15+FY15+GA15 | FW24: =FX15+FY15+GA15+GB15 | FX24: =FY15+GA15+GB15+GC15 | FY24: =GA15+GB15+GC15+GD15 | FZ24: =GE15
B26: PBP Unearned Revenue | DD26: =PBP!DD80 | DE26: =PBP!DE80 | DF26: =PBP!DF80 | DG26: =PBP!DG80 | DH26: =PBP!DH80 | DI26: =PBP!DI80 | DJ26: =PBP!DJ80 | DK26: =PBP!DK80 | ... ET26: =PBP!ET80 | EU26: =PBP!EU45 | EV26: =PBP!EV45 | EW26: =PBP!EW45 | EX26: =PBP!EX45 | EY26: =PBP!EY45 | EZ26: =PBP!EZ45 | FA26: =PBP!FA80
B27: IC Unearned Revenue | DD27: =IC!DD80 | DE27: =IC!DE80 | DF27: =IC!DF80 | DG27: =IC!DG80 | DH27: =IC!DH80 | DI27: =IC!DI80 | DJ27: =IC!DJ80 | DK27: =IC!DK80 | ... ET27: =IC!ET80 | EU27: =IC!EU45 | EV27: =IC!EV45 | EW27: =IC!EW45 | EX27: =IC!EX45 | EY27: =IC!EY45 | EZ27: =IC!EZ45 | FA27: =IC!FA80
B28: Company1738 Unearned Revenue | DD28: =Company1738!DD80 | DE28: =Company1738!DE80 | DF28: =Company1738!DF80 | DG28: =Company1738!DG80 | DH28: =Company1738!DH80 | DI28: =Company1738!DI80 | DJ28: =Company1738!DJ80 | DK28: =Company1738!DK80 | ... ET28: =Company1738!ET80 | EU28: =Company1738!EU45 | EV28: =Company1738!EV45 | EW28: =Company1738!EW45 | EX28: =Company1738!EX45 | EY28: =Company1738!EY45 | EZ28: =Company1738!EZ45 | FA28: =Company1738!FA80
A29: COGS | B29: Total Unearned Revenue | DD29: =SUM(DD26:DD28) | DE29: =SUM(DE26:DE28) | DF29: =SUM(DF26:DF28) | DG29: =SUM(DG26:DG28) | DH29: =SUM(DH26:DH28) | DI29: =SUM(DI26:DI28) | DJ29: =SUM(DJ26:DJ28) | DK29: =SUM(DK26:DK28) | ... FA29: =SUM(FA26:FA28)
B31: ST Unearned Revenue (B/S) | H31: =BS!H33 | I31: =BS!I33 | J31: =BS!J33 | K31: =BS!K33 | L31: =BS!L33 | M31: =BS!M33 | N31: =BS!N33 | O31: =BS!O33 | ... GJ31: =BS!GJ33
B32: LT Unearned Revenue (B/S) | H32: =BS!H40 | I32: =BS!I40 | J32: =BS!J40 | K32: =BS!K40 | L32: =BS!L40 | M32: =BS!M40 | N32: =BS!N40 | O32: =BS!O40 | ... GJ32: =BS!GJ40
B34: Change in Deferred Revenue (C/F) | DI34: =CF!DI27 | DJ34: =CF!DJ27 | DK34: =CF!DK27 | DL34: =CF!DL27 | DM34: =CF!DM27 | DN34: =CF!DN27 | DO34: =CF!DO27 | DP34: =CF!DP27 | ... GJ34: =CF!GJ27
B35: Total Billings | DI35: =DI34+DI15 | DJ35: =DJ34+DJ15 | DK35: =DK34+DK15 | DL35: =DL34+DL15 | DM35: =DM34+DM15 | DN35: =DN34+DN15 | DO35: =DO34+DO15 | DP35: =DP34+DP15 | ... GJ35: =GJ34+GJ15
A37: GP | B37: Commerical Total RPO | DS37: ='Ticker0024 Cloud'!DS28 | DT37: ='Ticker0024 Cloud'!DT28 | DU37: ='Ticker0024 Cloud'!DU28 | DV37: ='Ticker0024 Cloud'!DV28 | DW37: ='Ticker0024 Cloud'!DW28 | DX37: ='Ticker0024 Cloud'!DX28 | DY37: ='Ticker0024 Cloud'!DY28 | DZ37: ='Ticker0024 Cloud'!DZ28 | ... FA37: ='Ticker0024 Cloud'!FA28
B38: % yoy | DX38: =DX37/DS37-1 | DY38: =DY37/DT37-1 | DZ38: =DZ37/DU37-1 | EA38: =EA37/DV37-1 | EB38: =EB37/DW37-1 | EC38: =EC37/DX37-1 | ED38: =ED37/DY37-1 | EE38: =EE37/DZ37-1 | ... FA38: =FA37/EV37-1
B39: % qoq | DT39: =DT37/DS37-1 | DU39: =DU37/DT37-1 | DV39: =DV37/DU37-1 | DX39: =DX37/DV37-1 | DY39: =DY37/DX37-1 | DZ39: =DZ37/DY37-1 | EA39: =EA37/DZ37-1 | EC39: =EC37/EA37-1 | ED39: =ED37/EC37-1 | EE39: =EE37/ED37-1 | EF39: =EF37/EE37-1 | EH39: =EH37/EF37-1 | EI39: =EI37/EH37-1 | EJ39: =EJ37/EI37-1 | EK39: =EK37/EJ37-1 | EM39: =EM37/EK37-1 | EN39: =EN37/EM37-1 | EO39: =EO37/EN37-1 | EP39: =EP37/EO37-1 | ER39: =ER37/EP37-1 | ES39: =ES37/ER37-1 | ET39: =ET37/ES37-1 | EU39: =EU37/ET37-1 | EW39: =EW37/EU37-1 | EX39: =EX37/EW37-1 | EY39: =EY37/EX37-1 | EZ39: =EZ37/EY37-1
B40: Commercial cRPO | DS40: ='Ticker0024 Cloud'!DS35 | DT40: ='Ticker0024 Cloud'!DT35 | DU40: ='Ticker0024 Cloud'!DU35 | DV40: ='Ticker0024 Cloud'!DV35 | DW40: ='Ticker0024 Cloud'!DW35 | DX40: ='Ticker0024 Cloud'!DX35 | DY40: ='Ticker0024 Cloud'!DY35 | DZ40: ='Ticker0024 Cloud'!DZ35 | ... FA40: ='Ticker0024 Cloud'!FA35
B42: Total RPO | DN42: 59000 | DO42: 61000 | DP42: 61000 | DQ42: 73000 | DR42: =DQ42 | DS42: 71000 | DT42: 72000 | DU42: 75000 | DV42: 91000 | DW42: =DV42 | DX42: 89000 | DY42: 93000 | DZ42: 93000 | EA42: 111000 | EB42: =EA42 | EC42: 111000 | ED42: 117000 | EE42: 121000 | EF42: 146000 | EG42: =EF42 | EH42: 142000 | EI42: 152000 | EJ42: 160000 | EK42: 193000 | EL42: =EK42 | EM42: 183000 | EN42: 193000 | EO42: 201000 | EP42: 229000 | EQ42: =EP42 | ER42: 216000 | ES42: 229000 | ET42: 242000 | EU42: 275000 | EV42: =EU42 | EW42: 266000 | EX42: 304000 | EY42: 321000 | EZ42: 375000 | FA42: =EZ42
B43: % yoy | DS43: =DS42/DN42-1 | DT43: =DT42/DO42-1 | DU43: =DU42/DP42-1 | DV43: =DV42/DQ42-1 | DW43: =DW42/DR42-1 | DX43: =DX42/DS42-1 | DY43: =DY42/DT42-1 | DZ43: =DZ42/DU42-1 | ... FA43: =FA42/EV42-1
B44: % qoq | DO44: =DO42/DN42-1 | DP44: =DP42/DO42-1 | DQ44: =DQ42/DP42-1 | DS44: =DS42/DQ42-1 | DT44: =DT42/DS42-1 | DU44: =DU42/DT42-1 | DV44: =DV42/DU42-1 | DX44: =DX42/DV42-1 | DY44: =DY42/DX42-1 | DZ44: =DZ42/DY42-1 | EA44: =EA42/DZ42-1 | EC44: =EC42/EA42-1 | ED44: =ED42/EC42-1 | EE44: =EE42/ED42-1 | EF44: =EF42/EE42-1 | EH44: =EH42/EF42-1 | EI44: =EI42/EH42-1 | EJ44: =EJ42/EI42-1 | EK44: =EK42/EJ42-1 | EM44: =EM42/EK42-1 | EN44: =EN42/EM42-1 | EO44: =EO42/EN42-1 | EP44: =EP42/EO42-1 | ER44: =ER42/EP42-1 | ES44: =ES42/ER42-1 | ET44: =ET42/ES42-1 | EU44: =EU42/ET42-1 | EW44: =EW42/EU42-1 | EX44: =EX42/EW42-1 | EY44: =EY42/EX42-1 | EZ44: =EZ42/EY42-1
B45: % Recognized in the NTM | DN45: 0.6 | DO45: 0.6 | DP45: 0.6 | DQ45: 0.6 | DR45: =DQ45 | DS45: 0.6 | DT45: 0.6 | DU45: 0.55 | DV45: 0.5 | DW45: =DV45 | DX45: 0.5 | DY45: 0.5 | DZ45: 0.5 | EA45: 0.5 | EB45: =EA45 | EC45: 0.5 | ED45: 0.5 | EE45: 0.5 | EF45: 0.5 | EG45: =EF45 | EH45: 0.5 | EI45: 0.45 | EJ45: 0.5 | EK45: 0.45 | EL45: =EK45 | EM45: 0.45 | EN45: 0.45 | EO45: 0.45 | EP45: 0.45 | EQ45: =EP45 | ER45: 0.45 | ES45: 0.45 | ET45: 0.45 | EU45: 0.45 | EV45: =EU45 | EW45: 0.45 | EX45: 0.4 | EY45: 0.4 | EZ45: 0.4
B46: Total cRPO | DN46: =DN42*DN45 | DO46: =DO42*DO45 | DP46: =DP42*DP45 | DQ46: =DQ42*DQ45 | DR46: =DR42*DR45 | DS46: =DS42*DS45 | DT46: =DT42*DT45 | DU46: =DU42*DU45 | ... FA46: =FA42*FA45
A48: EPSB | B48: Unearned Revenue
A49: EPSBYY | B49: PBP Unearned Revenue | DD49: =DD26 | DE49: =DE26 | DF49: =DF26 | DG49: =DG26 | DH49: =DH26 | DI49: =DI26 | DJ49: =DJ26 | DK49: =DK26 | ... FA49: =FA26
B50: % yoy | DI50: =DI49/DD49-1 | DJ50: =DJ49/DE49-1 | DK50: =DK49/DF49-1 | DL50: =DL49/DG49-1 | DM50: =DM49/DH49-1 | DN50: =DN49/DI49-1 | DO50: =DO49/DJ49-1 | DP50: =DP49/DK49-1 | ... FA50: =FA49/EV49-1
B51: % qoq | DE51: =DE49/DD49-1 | DF51: =DF49/DE49-1 | DG51: =DG49/DF49-1 | DI51: =DI49/DG49-1 | DJ51: =DJ49/DI49-1 | DK51: =DK49/DJ49-1 | DL51: =DL49/DK49-1 | DN51: =DN49/DL49-1 | DO51: =DO49/DN49-1 | DP51: =DP49/DO49-1 | DQ51: =DQ49/DP49-1 | DS51: =DS49/DQ49-1 | DT51: =DT49/DS49-1 | DU51: =DU49/DT49-1 | DV51: =DV49/DU49-1 | DX51: =DX49/DV49-1 | DY51: =DY49/DX49-1 | DZ51: =DZ49/DY49-1 | EA51: =EA49/DZ49-1 | EC51: =EC49/EA49-1 | ED51: =ED49/EC49-1 | EE51: =EE49/ED49-1 | EF51: =EF49/EE49-1 | EH51: =EH49/EF49-1 | EI51: =EI49/EH49-1 | EJ51: =EJ49/EI49-1 | EK51: =EK49/EJ49-1 | EM51: =EM49/EK49-1 | EN51: =EN49/EM49-1 | EO51: =EO49/EN49-1 | EP51: =EP49/EO49-1 | ER51: =ER49/EP49-1 | ES51: =ES49/ER49-1 | ET51: =ET49/ES49-1 | EU51: =EU49/ET49-1 | EW51: =EW49/EU49-1 | EX51: =EX49/EW49-1 | EY51: =EY49/EX49-1 | EZ51: =EZ49/EY49-1
B52: % Total Unearned Revenue | DD52: =DD49/DD$29 | DE52: =DE49/DE$29 | DF52: =DF49/DF$29 | DG52: =DG49/DG$29 | DH52: =DH49/DH$29 | DI52: =DI49/DI$29 | DJ52: =DJ49/DJ$29 | DK52: =DK49/DK$29 | ... FA52: =FA49/FA$29
...

Sheet IS
B2: Microsoft, Inc.
B3: Fiscal Year Ends Jun. 30
B4: ($ millions, except per share amounts) | AI4: Company0935 Merchant Revenue Accounting Change - Restated | AS4: SFAS 123 Adoption - Restated
C6: =Dates!C3 | H6: =Dates!H3 | M6: =Dates!M3 | R6: =Dates!R3 | W6: =Dates!W3 | AB6: =Dates!AB3 | AG6: =Dates!AG3 | AL6: =Dates!AL3 | AQ6: =Dates!AQ3 | AV6: =Dates!AV3 | BA6: =Dates!BA3 | BF6: =Dates!BF3 | BK6: =Dates!BK3 | BP6: =Dates!BP3 | BU6: =Dates!BU3 | BZ6: =Dates!BZ3 | CE6: =Dates!CE3 | CJ6: =Dates!CJ3 | CO6: =Dates!CO3 | CT6: =Dates!CT3 | CY6: =Dates!CY3 | DD6: =Dates!DD3 | DI6: =Dates!DI3 | DN6: =Dates!DN3 | DS6: =Dates!DS3 | DX6: =Dates!DX3 | EC6: =Dates!EC3 | EH6: =Dates!EH3 | EM6: =Dates!EM3 | ER6: =Dates!ER3 | EW6: =Dates!EW3 | FB6: =Dates!FB3 | FG6: =Dates!FG3 | FL6: =Dates!FL3 | FQ6: =Dates!FQ3 | FV6: =Dates!FV3 | GA6: =Dates!GA3 | GF6: =Dates!GF3
C7: =Dates!C4 | D7: =Dates!D4 | E7: =Dates!E4 | F7: =Dates!F4 | G7: =Dates!G4 | H7: =Dates!H4 | I7: =Dates!I4 | J7: =Dates!J4 | ... GJ7: =Dates!GJ4
C8: =Dates!C5 | D8: =Dates!D5 | E8: =Dates!E5 | F8: =Dates!F5 | G8: =Dates!G5 | H8: =Dates!H5 | I8: =Dates!I5 | J8: =Dates!J5 | ... GJ8: =Dates!GJ5
B10: Product Revenue | DI10: 14968 | DJ10: 18273 | DK10: 14513 | DL10: 16057 | DM10: =SUM(DI10:DL10) | DN10: 14298 | DO10: 17926 | DP10: 15114 | DQ10: 17159 | DR10: =SUM(DN10:DQ10) | DS10: 17299 | DT10: 16219 | DU10: 15448 | DV10: 17103 | DW10: =SUM(DS10:DV10) | DX10: 15768 | DY10: 18255 | DZ10: 15871 | EA10: 18147 | EB10: =SUM(DX10:EA10) | EC10: 15803 | ED10: 19460 | EE10: 16873 | EF10: 18938 | EG10: =SUM(EC10:EF10) | EH10: 16631 | EI10: 20779 | EJ10: 17366 | EK10: 17956 | EL10: =SUM(EH10:EK10) | EM10: 15741 | EN10: 16517 | EO10: 15588 | EP10: 16853 | EQ10: =SUM(EM10:EP10) | ER10: 15535 | ES10: 18941 | ET10: 17080 | EU10: 13217 | EV10: =SUM(ER10:EU10) | EW10: 15272 | EX10: 16219 | EY10: 15319 | EZ10: 17136 | FA10: =SUM(EW10:EZ10)
B11: % yoy | H11: =IFERROR(H10/C10-1,"") | I11: =IFERROR(I10/D10-1,"") | J11: =IFERROR(J10/E10-1,"") | K11: =IFERROR(K10/F10-1,"") | L11: =IFERROR(L10/G10-1,"") | M11: =IFERROR(M10/H10-1,"") | N11: =IFERROR(N10/I10-1,"") | O11: =IFERROR(O10/J10-1,"") | ... DC11: =IFERROR(DC10/CX10-1,"") | DI11: =IFERROR(DI10/DD10-1,"") | DJ11: =IFERROR(DJ10/DE10-1,"") | DK11: =IFERROR(DK10/DF10-1,"") | DL11: =IFERROR(DL10/DG10-1,"") | DM11: =IFERROR(DM10/DH10-1,"") | DN11: =IFERROR(DN10/DI10-1,"") | DO11: =IFERROR(DO10/DJ10-1,"") | DP11: =IFERROR(DP10/DK10-1,"") | ... FA11: =IFERROR(FA10/EV10-1,"")
B12: % qoq | H12: =IFERROR(H10/F10-1,"") | I12: =IFERROR(I10/H10-1,"") | J12: =IFERROR(J10/I10-1,"") | K12: =IFERROR(K10/J10-1,"") | M12: =IFERROR(M10/K10-1,"") | N12: =IFERROR(N10/M10-1,"") | O12: =IFERROR(O10/N10-1,"") | P12: =IFERROR(P10/O10-1,"") | R12: =IFERROR(R10/P10-1,"") | S12: =IFERROR(S10/R10-1,"") | T12: =IFERROR(T10/S10-1,"") | U12: =IFERROR(U10/T10-1,"") | W12: =IFERROR(W10/U10-1,"") | X12: =IFERROR(X10/W10-1,"") | Y12: =IFERROR(Y10/X10-1,"") | Z12: =IFERROR(Z10/Y10-1,"") | AB12: =IFERROR(AB10/Z10-1,"") | AC12: =IFERROR(AC10/AB10-1,"") | AD12: =IFERROR(AD10/AC10-1,"") | AE12: =IFERROR(AE10/AD10-1,"") | AG12: =IFERROR(AG10/AE10-1,"") | AH12: =IFERROR(AH10/AG10-1,"") | AI12: =IFERROR(AI10/AH10-1,"") | AJ12: =IFERROR(AJ10/AI10-1,"") | AL12: =IFERROR(AL10/AJ10-1,"") | AM12: =IFERROR(AM10/AL10-1,"") | AN12: =IFERROR(AN10/AM10-1,"") | AO12: =IFERROR(AO10/AN10-1,"") | AQ12: =IFERROR(AQ10/AO10-1,"") | AR12: =IFERROR(AR10/AQ10-1,"") | AS12: =IFERROR(AS10/AR10-1,"") | AT12: =IFERROR(AT10/AS10-1,"") | AV12: =IFERROR(AV10/AT10-1,"") | AW12: =IFERROR(AW10/AV10-1,"") | AX12: =IFERROR(AX10/AW10-1,"") | AY12: =IFERROR(AY10/AX10-1,"") | BA12: =IFERROR(BA10/AY10-1,"") | BB12: =IFERROR(BB10/BA10-1,"") | BC12: =IFERROR(BC10/BB10-1,"") | BD12: =IFERROR(BD10/BC10-1,"") | BF12: =IFERROR(BF10/BD10-1,"") | BG12: =IFERROR(BG10/BF10-1,"") | BH12: =IFERROR(BH10/BG10-1,"") | BI12: =IFERROR(BI10/BH10-1,"") | BK12: =IFERROR(BK10/BI10-1,"") | BL12: =IFERROR(BL10/BK10-1,"") | BM12: =IFERROR(BM10/BL10-1,"") | BN12: =IFERROR(BN10/BM10-1,"") | BP12: =IFERROR(BP10/BN10-1,"") | BQ12: =IFERROR(BQ10/BP10-1,"") | BR12: =IFERROR(BR10/BQ10-1,"") | BS12: =IFERROR(BS10/BR10-1,"") | BU12: =IFERROR(BU10/BS10-1,"") | BV12: =IFERROR(BV10/BU10-1,"") | BW12: =IFERROR(BW10/BV10-1,"") | BX12: =IFERROR(BX10/BW10-1,"") | BZ12: =IFERROR(BZ10/BX10-1,"") | CA12: =IFERROR(CA10/BZ10-1,"") | CB12: =IFERROR(CB10/CA10-1,"") | CC12: =IFERROR(CC10/CB10-1,"") | CE12: =IFERROR(CE10/CC10-1,"") | CF12: =IFERROR(CF10/CE10-1,"") | CG12: =IFERROR(CG10/CF10-1,"") | CH12: =IFERROR(CH10/CG10-1,"") | CJ12: =IFERROR(CJ10/CH10-1,"") | CK12: =IFERROR(CK10/CJ10-1,"") | CL12: =IFERROR(CL10/CK10-1,"") | CM12: =IFERROR(CM10/CL10-1,"") | CO12: =IFERROR(CO10/CM10-1,"") | CP12: =IFERROR(CP10/CO10-1,"") | CQ12: =IFERROR(CQ10/CP10-1,"") | CR12: =IFERROR(CR10/CQ10-1,"") | CT12: =IFERROR(CT10/CR10-1,"") | CU12: =IFERROR(CU10/CT10-1,"") | CV12: =IFERROR(CV10/CU10-1,"") | CW12: =IFERROR(CW10/CV10-1,"") | CY12: =IFERROR(CY10/CW10-1,"") | CZ12: =IFERROR(CZ10/CY10-1,"") | DA12: =IFERROR(DA10/CZ10-1,"") | DB12: =IFERROR(DB10/DA10-1,"") | DI12: =IFERROR(DI10/DG10-1,"") | DJ12: =IFERROR(DJ10/DI10-1,"") | DK12: =IFERROR(DK10/DJ10-1,"") | DL12: =IFERROR(DL10/DK10-1,"") | DN12: =IFERROR(DN10/DL10-1,"") | DO12: =IFERROR(DO10/DN10-1,"") | DP12: =IFERROR(DP10/DO10-1,"") | DQ12: =IFERROR(DQ10/DP10-1,"") | DS12: =IFERROR(DS10/DQ10-1,"") | DT12: =IFERROR(DT10/DS10-1,"") | DU12: =IFERROR(DU10/DT10-1,"") | DV12: =IFERROR(DV10/DU10-1,"") | DX12: =IFERROR(DX10/DV10-1,"") | DY12: =IFERROR(DY10/DX10-1,"") | DZ12: =IFERROR(DZ10/DY10-1,"") | EA12: =IFERROR(EA10/DZ10-1,"") | EC12: =IFERROR(EC10/EA10-1,"") | ED12: =IFERROR(ED10/EC10-1,"") | EE12: =IFERROR(EE10/ED10-1,"") | EF12: =IFERROR(EF10/EE10-1,"") | EH12: =IFERROR(EH10/EF10-1,"") | EI12: =IFERROR(EI10/EH10-1,"") | EJ12: =IFERROR(EJ10/EI10-1,"") | EK12: =IFERROR(EK10/EJ10-1,"") | EM12: =IFERROR(EM10/EK10-1,"") | EN12: =IFERROR(EN10/EM10-1,"") | EO12: =IFERROR(EO10/EN10-1,"") | EP12: =IFERROR(EP10/EO10-1,"") | ER12: =IFERROR(ER10/EP10-1,"") | ES12: =IFERROR(ES10/ER10-1,"") | ET12: =IFERROR(ET10/ES10-1,"") | EU12: =IFERROR(EU10/ET10-1,"") | EW12: =IFERROR(EW10/EU10-1,"") | EX12: =IFERROR(EX10/EW10-1,"") | EY12: =IFERROR(EY10/EX10-1,"") | EZ12: =IFERROR(EZ10/EY10-1,"")
B13: Net New Revenue (yoy) | DN13: =DN10-DI10 | DO13: =DO10-DJ10 | DP13: =DP10-DK10 | DQ13: =DQ10-DL10 | DR13: =DR10-DM10 | DS13: =DS10-DN10 | DT13: =DT10-DO10 | DU13: =DU10-DP10 | ... FA13: =FA10-EV10
B14: Net New Revenue (qoq) | DJ14: =DJ10-DI10 | DK14: =DK10-DJ10 | DL14: =DL10-DK10 | DN14: =DN10-DL10 | DO14: =DO10-DN10 | DP14: =DP10-DO10 | DQ14: =DQ10-DP10 | DS14: =DS10-DQ10 | DT14: =DT10-DS10 | DU14: =DU10-DT10 | DV14: =DV10-DU10 | DX14: =DX10-DV10 | DY14: =DY10-DX10 | DZ14: =DZ10-DY10 | EA14: =EA10-DZ10 | EC14: =EC10-EA10 | ED14: =ED10-EC10 | EE14: =EE10-ED10 | EF14: =EF10-EE10 | EH14: =EH10-EF10 | EI14: =EI10-EH10 | EJ14: =EJ10-EI10 | EK14: =EK10-EJ10 | EM14: =EM10-EK10 | EN14: =EN10-EM10 | EO14: =EO10-EN10 | EP14: =EP10-EO10 | ER14: =ER10-EP10 | ES14: =ES10-ER10 | ET14: =ET10-ES10 | EU14: =EU10-ET10 | EW14: =EW10-EU10 | EX14: =EX10-EW10 | EY14: =EY10-EX10 | EZ14: =EZ10-EY10
B15: % of Total Revenue | DI15: =IFERROR(DI10/DI$24,"") | DJ15: =IFERROR(DJ10/DJ$24,"") | DK15: =IFERROR(DK10/DK$24,"") | DL15: =IFERROR(DL10/DL$24,"") | DM15: =IFERROR(DM10/DM$24,"") | DN15: =IFERROR(DN10/DN$24,"") | DO15: =IFERROR(DO10/DO$24,"") | DP15: =IFERROR(DP10/DP$24,"") | ... FA15: =IFERROR(FA10/FA$24,"")
B17: Service and Other Revenue | DI17: 6960 | DJ17: 7553 | DK17: 8699 | DL17: 9548 | DM17: =SUM(DI17:DL17) | DN17: 10240 | DO17: 10992 | DP17: 11705 | DQ17: 12926 | DR17: =SUM(DN17:DQ17) | DS17: 11785 | DT17: 16252 | DU17: 15123 | DV17: 16614 | DW17: =SUM(DS17:DV17) | DX17: 17287 | DY17: 18651 | DZ17: 19150 | EA17: 19886 | EB17: =SUM(DX17:EA17) | EC17: 21351 | ED17: 23616 | EE17: 24833 | EF17: 27214 | EG17: =SUM(EC17:EF17) | EH17: 28686 | EI17: 30949 | EJ17: 31994 | EK17: 33909 | EL17: =SUM(EH17:EK17) | EM17: 34381 | EN17: 36230 | EO17: 37269 | EP17: 39336 | EQ17: =SUM(EM17:EP17) | ER17: 40982 | ES17: 43079 | ET17: 44778 | EU17: 51510 | EV17: =SUM(ER17:EU17) | EW17: 50313 | EX17: 53413 | EY17: 54747 | EZ17: 59305 | FA17: =SUM(EW17:EZ17)
