Workbook
Name A_ALL_Ticker0009: #REF!
Name A_ALL_KEYWORDS_TYPE_ScalarContributed_EQTY_200001266: #REF!,#REF!,#REF!,#REF!,#REF!
Name A_ALL_KEYWORDS_TYPE_ScalarContributed_ISSR_208000403: #REF!,#REF!
Name A_ALL_KEYWORDS_TYPE_ScalarReference_EQTY_200001266: #REF!
Name A_ALL_KEYWORDS_TYPE_ScalarReference_ISSR_208000403: #REF!
Name A_ALL_KEYWORDS_TYPE_Vector_EQTY_200001266: #REF!,#REF!,#REF!,#REF!,#REF!,#REF!,#REF!
Name A_ALL_KEYWORDS_TYPE_Vector_ISSR_208000403: #REF!,#REF!,#REF!,#REF!,#REF!,#REF!,#REF!,#REF!,#REF!
Name A_ALL_LMT: #REF!
Name A_ALL_LMT_: #REF!
Name A_ALL_SECTION_KEYWORDS_EQTY_200001266_1314: #REF!
Name A_ALL_SECTION_KEYWORDS_EQTY_200001266_1319: #REF!
Name A_ALL_SECTION_KEYWORDS_EQTY_200001266_131E: #REF!
Name A_ALL_SECTION_KEYWORDS_EQTY_200001266_131O: #REF!
Name A_ALL_SECTION_KEYWORDS_EQTY_200001266_13A: #REF!
Name A_ALL_SECTION_KEYWORDS_EQTY_200001266_13K: #REF!
Name A_ALL_SECTION_KEYWORDS_EQTY_200001266_13U: #REF!
Name A_ALL_SECTION_KEYWORDS_EQTY_200001266_13V: #REF!
Name A_ALL_SECTION_KEYWORDS_EQTY_200001266_13W: #REF!
Name A_ALL_SECTION_KEYWORDS_EQTY_200001266_Reference_Data: #REF!
Name A_ALL_SECTION_KEYWORDS_ISSR_208000403_1314: #REF!
Name A_ALL_SECTION_KEYWORDS_ISSR_208000403_13168: #REF!
Name A_ALL_SECTION_KEYWORDS_ISSR_208000403_1316S: #REF!
Name A_ALL_SECTION_KEYWORDS_ISSR_208000403_1316T: #REF!
Name A_ALL_SECTION_KEYWORDS_ISSR_208000403_1316U: #REF!
Name A_ALL_SECTION_KEYWORDS_ISSR_208000403_1319: #REF!
Name A_ALL_SECTION_KEYWORDS_ISSR_208000403_131E: #REF!
Name A_ALL_SECTION_KEYWORDS_ISSR_208000403_131J: #REF!
Name A_ALL_SECTION_KEYWORDS_ISSR_208000403_131O: #REF!
Name A_ALL_SECTION_KEYWORDS_ISSR_208000403_136E: #REF!,#REF!
Name A_ALL_SECTION_KEYWORDS_ISSR_208000403_13A: #REF!
Name A_ALL_SECTION_KEYWORDS_ISSR_208000403_13U: #REF!
Name A_ALL_SECTION_KEYWORDS_ISSR_208000403_13V: #REF!
Name A_ALL_SECTION_KEYWORDS_ISSR_208000403_Reference_Data: #REF!
Name A_ALL_SECTIONS_EQTY_200001266: #REF!,#REF!,#REF!,#REF!,#REF!,#REF!,#REF!,#REF!,#REF!,#REF!
Name A_CURRENCY_EQTY_200001266_PRI: #REF!
Name A_CURRENCY_EQTY_200001266_PUB: #REF!
Name A_CURRENCY_EQTY_200001266_REP: #REF!
Name A_CURRENCY_ISSR_208000403_REP: #REF!
Name A_KEYWORD_EQTY_200001266_AMER_LIST: #REF!
Name A_KEYWORD_EQTY_200001266_BETA_ANALYST: #REF!
Name A_KEYWORD_EQTY_200001266_BVPS: #REF!
Name A_KEYWORD_EQTY_200001266_BVPS_PUB: #REF!
Name A_KEYWORD_EQTY_200001266_CEEE_EPS: #REF!
Name A_KEYWORD_EQTY_200001266_CF_NI_PRE_PREF: #REF!
Name A_KEYWORD_EQTY_200001266_COMMON_DIV_PAID: #REF!
Name A_KEYWORD_EQTY_200001266_CURRENCY_ISO: #REF!
Name A_KEYWORD_EQTY_200001266_DILUTE_SHARES: #REF!
Name A_KEYWORD_EQTY_200001266_DPS: #REF!
Name A_KEYWORD_EQTY_200001266_DPS_PUB: #REF!
Name A_KEYWORD_EQTY_200001266_EBIT_PUB: #REF!
Name A_KEYWORD_EQTY_200001266_EBITDA_PUB: #REF!
Name A_KEYWORD_EQTY_200001266_EPS: #REF!
Name A_KEYWORD_EQTY_200001266_EPS_EX_ESO_B: #REF!
Name A_KEYWORD_EQTY_200001266_EPS_EX_ESO_D: #REF!
Name A_KEYWORD_EQTY_200001266_EPS_FUL_DIL: #REF!
Name A_KEYWORD_EQTY_200001266_EPS_POST_BASIC: #REF!
Name A_KEYWORD_EQTY_200001266_EPS_PUB: #REF!
Name A_KEYWORD_EQTY_200001266_EPS_PUB_EX_ESO: #REF!
Name A_KEYWORD_EQTY_200001266_EQ_PUB: #REF!
Name A_KEYWORD_EQTY_200001266_ESO_POST_TAX: #REF!

Sheet Cover
D7: Company1067 Model
D8: 45936
B16: Person0823, CFA
B17: (212) 357-0954
B18: person@example.com
B20: Person0086, CFA
B21: (212) 934-0385
B22: person@example.com
B24: Person0248
B25: (212) 357-6166
B26: person@example.com
B28: Person1182
B29: (801) 744-0681
B30: person@example.com

Sheet data
B3: Company1067 Raw Data | C3: 1997 | D3: 1998 | E3: 1999 | F3: 2000 | G3: 2001 | H3: 2002 | I3: 2003 | J3: 1Q04 | K3: 2Q04 | L3: 3Q04 | M3: 4Q04 | N3: 2004 | O3: 1Q05 | P3: 2Q05 | Q3: 3Q05 | R3: 4Q05 | S3: 2005 | T3: 1Q06 | U3: 2Q06 | V3: 3Q06 | W3: 4Q06 | X3: 2006 | Y3: 1Q07 | Z3: 2Q07 | AA3: 3Q07 | AB3: 4Q07 | AC3: 2007 | AD3: 1Q08 | AE3: 2Q08 | AF3: 3Q08 | AG3: 4Q08 | AH3: 2008 | AI3: 1Q09 | AJ3: 2Q09 | AK3: 3Q09 | AL3: 4Q09 | AM3: 2009 | AN3: 1Q10 | AO3: 2Q10 | AP3: 3Q10 | AQ3: 4Q10 | AR3: 2010 | AS3: 1Q11 | AT3: 2Q11 | AU3: 3Q11 | AV3: 4Q11 | AW3: 2011 | AX3: 1Q12 | AY3: 2Q12 | AZ3: 3Q12 | BA3: 4Q12 | BB3: 2012 | BC3: 1Q13 | BD3: 2Q13 | BE3: 3Q13 | BF3: 4Q13 | BG3: 2013 | BH3: 1Q14 | BI3: 2Q14 | BJ3: 3Q14 | BK3: 4Q14 | BL3: 2014 | BM3: 1Q15 | BN3: 2Q15 | BO3: 3Q15 | BP3: 4Q15 | BQ3: 2015 | BR3: 1Q16 | BS3: 2Q16 | BT3: 3Q16 | BU3: 4Q16 | BV3: 2016 | BW3: 1Q17 | BX3: 2Q17 | BY3: 3Q17 | BZ3: 4Q17 | CA3: 2017 | CB3: 1Q18 | CC3: 2Q18 | CD3: 3Q18 | CE3: 4Q18 | CF3: 2018 | CG3: 1Q19 | CH3: 2Q19 | CI3: 3Q19 | CJ3: 4Q19 | CK3: 2019 | CL3: 1Q20 | CM3: 2Q20 | CN3: 3Q20 | CO3: 4Q20 | CP3: 2020 | CQ3: 1Q21 | CR3: 2Q21 | CS3: 3Q21 | CT3: 4Q21 | CU3: 2021 | CV3: 1Q22 | CW3: 2Q22 | CX3: 3Q22 | CY3: 4Q22 | CZ3: 2022 | DA3: 1Q23 | DB3: 2Q23 | DC3: 3Q23 | DD3: 4Q23 | DE3: 2023 | DF3: 1Q24 | DG3: 2Q24 | DH3: 3Q24 | DI3: 4Q24 | DJ3: 2024 | DK3: 1Q25 | DL3: 2Q25 | DM3: 3Q25 | DN3: 4Q25 | DO3: 2025 | DP3: 1Q26 | DQ3: 2Q26 | DR3: 3Q26 | DS3: 4Q26 | DT3: 2026 | DU3: 2027 | DV3: 2028
B4: ($ mn) | C4: 35795 | D4: 36160 | E4: 36525 | F4: 36891 | G4: 37256 | H4: 37621 | I4: 37986 | J4: 38077 | K4: 38168 | L4: 38260 | M4: 38352 | N4: 38352 | O4: 38442 | P4: 38533 | Q4: 38625 | R4: 38717 | S4: 38717 | T4: 38807 | U4: 38898 | V4: 38990 | W4: 39082 | X4: 39082 | Y4: 39172 | Z4: 39263 | AA4: 39355 | AB4: 39447 | AC4: 39447 | AD4: 39538 | AE4: 39629 | AF4: 39721 | AG4: 39813 | AH4: 39813 | AI4: 39903 | AJ4: 39994 | AK4: 40086 | AL4: 40178 | AM4: 40178 | AN4: 40268 | AO4: 40359 | AP4: 40451 | AQ4: 40543 | AR4: 40543 | AS4: 40633 | AT4: 40724 | AU4: 40816 | AV4: 40908 | AW4: 40908 | AX4: 40999 | AY4: 41090 | AZ4: 41182 | BA4: 41274 | BB4: 41274 | BC4: 41364 | BD4: 41455 | BE4: 41547 | BF4: 41639 | BG4: 41639 | BH4: 41729 | BI4: 41820 | BJ4: 41912 | BK4: 42004 | BL4: 42004 | BM4: 42094 | BN4: 42185 | BO4: 42277 | BP4: 42369 | BQ4: 42369 | BR4: 42460 | BS4: 42551 | BT4: 42643 | BU4: 42735 | BV4: 42735 | BW4: 42825 | BX4: 42916 | BY4: 43008 | BZ4: 43100 | CA4: 43100 | CB4: 43190 | CC4: 43281 | CD4: 43373 | CE4: 43465 | CF4: 43465 | CG4: 43555 | CH4: 43646 | CI4: 43738 | CJ4: 43830 | CK4: 43830 | CL4: 43921 | CM4: 44012 | CN4: 44104 | CO4: 44196 | CP4: 44196 | CQ4: 44286 | CR4: 44377 | CS4: 44469 | CT4: 44561 | CU4: 44561 | CV4: 44651 | CW4: 44742 | CX4: 44834 | CY4: 44926 | CZ4: 44926 | DA4: 45016 | DB4: 45107 | DC4: 45199 | DD4: 45291 | DE4: 45291 | DF4: 45382 | DG4: 45473 | DH4: 45565 | DI4: 45657 | DJ4: 45657 | DK4: 45747 | DL4: 45838 | DM4: 45930 | DN4: 46022 | DO4: 46022 | DP4: 46112 | DQ4: 46203 | DR4: 46295 | DS4: 46387 | DT4: 46387 | DU4: 46752 | DV4: 47118
B6: Income Statement
B7: Sales of goods | CL7: 12339 | CM7: 10720 | CN7: 12306 | CO7: =CP7-SUM(CL7:CN7) -> 2219 | CP7: 37584 | CQ7: 10349 | CR7: 11105 | CS7: 11530 | CT7: =CU7-SUM(CQ7:CS7) -> 1216 | CU7: 34200 | CV7: 4608 | CW7: 5266 | CX7: 5731 | CY7: =CZ7-SUM(CV7:CX7) -> 6729 | CZ7: 22334 | DA7: 5287 | DB7: 6688 | DC7: 6939 | DD7: =DE7-SUM(DA7:DC7) -> 7879 | DE7: 26793 | DF7: 5935 | DG7: 2175 | DH7: 2448 | DI7: 3230 | DK7: 2653 | DL7: 2842
B8: Sales of services | CL8: 6452 | CM8: 5329 | CN8: 5560 | CO8: =CP8-SUM(CL8:CN8) -> 18044 | CP8: 35385 | CQ8: 5967 | CR8: 6365 | CS8: 6283 | CT8: =CU8-SUM(CQ8:CS8) -> 18275 | CU8: 36890 | CV8: 7302 | CW8: 8096 | CX8: 8095 | CY8: =CZ8-SUM(CV8:CX8) -> 9315 | CZ8: 32808 | DA8: 8407 | DB8: 9163 | DC8: 9565 | DD8: =DE8-SUM(DA8:DC8) -> 10637 | DE8: 37772 | DF8: 9239 | DG8: 6047 | DH8: 6495 | DI8: 6649 | DK8: 6347 | DL8: 7308
B9: Sales of equipment and services | CL9: =SUM(CL7:CL8) -> 18791 | CM9: =SUM(CM7:CM8) -> 16049 | CN9: =SUM(CN7:CN8) -> 17866 | CO9: =SUM(CO7:CO8) -> 20263 | CP9: =SUM(CP7:CP8) -> 72969 | CQ9: =SUM(CQ7:CQ8) -> 16316 | CR9: =SUM(CR7:CR8) -> 17470 | CS9: =SUM(CS7:CS8) -> 17813 | ... DI9: =SUM(DI7:DI8) -> 9879 | DK9: =SUM(DK7:DK8) -> 9000 | DL9: =SUM(DL7:DL8) -> 10150
B10: Insurance revenues | CL10: 699 | CM10: 756 | CN10: 663 | CO10: =CP10-SUM(CL10:CN10) -> 747 | CP10: 2865 | CQ10: 803 | CR10: 810 | CS10: 616 | CT10: =CU10-SUM(CQ10:CS10) -> 877 | CU10: 3106 | CV10: 764 | CW10: 766 | CX10: 645 | CY10: =CZ10-SUM(CV10:CX10) -> 782 | CZ10: 2957 | DA10: 791 | DB10: 847 | DC10: 842 | DD10: =DE10-SUM(DA10:DC10) -> 909 | DE10: 3389 | DF10: 879 | DG10: 871 | DH10: 899 | DI10: 933 | DK10: 934 | DL10: =872+1 -> 873
B11: Net Sales | J11: =SUM(J7:J8) -> 0 | K11: =SUM(K7:K8) -> 0 | L11: =SUM(L7:L8) -> 0 | M11: =SUM(M7:M8) -> 0 | N11: =SUM(N7:N8) -> 0 | O11: =SUM(O7:O8) -> 0 | P11: =SUM(P7:P8) -> 0 | Q11: =SUM(Q7:Q8) -> 0 | ... CK11: =SUM(CK7:CK8) -> 0 | CL11: =SUM(CL9:CL10) -> 19490 | CM11: =SUM(CM9:CM10) -> 16805 | CN11: =SUM(CN9:CN10) -> 18529 | CO11: =SUM(CO9:CO10) -> 21010 | CP11: =SUM(CP9:CP10) -> 75834 | CQ11: =SUM(CQ9:CQ10) -> 17119 | CR11: =SUM(CR9:CR10) -> 18280 | CS11: =SUM(CS9:CS10) -> 18429 | ... DI11: =SUM(DI9:DI10) -> 10812 | DK11: =SUM(DK9:DK10) -> 9934 | DL11: =SUM(DL9:DL10) -> 11023
B12: Cost of goods | CL12: -9930 | CM12: -9787 | CN12: -10555 | CO12: =CP12-SUM(CL12:CN12) -> -4970 | CP12: -35242 | CQ12: -8679 | CR12: -9086 | CS12: -9127 | CT12: =CU12-SUM(CQ12:CS12) -> -4507 | CU12: -31399 | CV12: -5148 | CW12: -5529 | CX12: -6488 | CY12: =CZ12-SUM(CV12:CX12) -> -6578 | CZ12: -23743 | DA12: -5605 | DB12: -6940 | DC12: -7065 | DD12: =DE12-SUM(DA12:DC12) -> -8073 | DE12: -27683 | DF12: -6024 | DG12: -2302 | DH12: -2625 | DI12: -2950 | DK12: -2335 | DL12: -2754
B13: Cost of services | CL13: -4497 | CM13: -3846 | CN13: -3486 | CO13: =CP13-SUM(CL13:CN13) -> -10800 | CP13: -22629 | CQ13: -3859 | CR13: -4532 | CS13: -4275 | CT13: =CU13-SUM(CQ13:CS13) -> -9831 | CU13: -22497 | CV13: -4626 | CW13: -4996 | CX13: -5046 | CY13: =CZ13-SUM(CV13:CX13) -> -5861 | CZ13: -20529 | DA13: -5124 | DB13: -5422 | DC13: -5839 | DD13: =DE13-SUM(DA13:DC13) -> -6324 | DE13: -22709 | DF13: -5596 | DG13: -3273 | DH13: -3601 | DI13: -3811 | DK13: -3660 | DL13: -4092
B14: Unallocated Corporate Costs
B15: Cost of sales | C15: =SUM(C12:C13) -> 0 | D15: =SUM(D12:D13) -> 0 | E15: =SUM(E12:E13) -> 0 | F15: =SUM(F12:F13) -> 0 | G15: =SUM(G12:G13) -> 0 | H15: =SUM(H12:H13) -> 0 | I15: =SUM(I12:I13) -> 0 | J15: =SUM(J12:J13) -> 0 | ... DI15: =SUM(DI12:DI13) -> -6761 | DK15: =SUM(DK12:DK13) -> -5995 | DL15: =SUM(DL12:DL13) -> -6846
B16: Gross Profit | C16: =C11+C15 -> 0 | D16: =D11+D15 -> 0 | E16: =E11+E15 -> 0 | F16: =F11+F15 -> 0 | G16: =G11+G15 -> 0 | H16: =H11+H15 -> 0 | I16: =I11+I15 -> 0 | J16: =J11+J15 -> 0 | ... CK16: =CK11+CK15 -> 0 | CL16: =SUM(CL15,CL11) -> 5063 | CM16: =SUM(CM15,CM11) -> 3172 | CN16: =SUM(CN15,CN11) -> 4488 | CO16: =SUM(CO15,CO11) -> 5240 | CP16: =SUM(CP15,CP11) -> 17963 | CQ16: =SUM(CQ15,CQ11) -> 4581 | CR16: =SUM(CR15,CR11) -> 4662 | CS16: =SUM(CS15,CS11) -> 5027 | ... DI16: =SUM(DI15,DI11) -> 4051 | DK16: =SUM(DK15,DK11) -> 3939 | DL16: =SUM(DL15,DL11) -> 4177
B17: Selling, general and andministrative expenses | CL17: -3061 | CM17: -3068 | CN17: -3215 | CO17: =CP17-SUM(CL17:CN17) -> -3248 | CP17: -12592 | CQ17: -2891 | CR17: -2866 | CS17: -2747 | CT17: =CU17-SUM(CQ17:CS17) -> -3203 | CU17: -11707 | CV17: =-2725-99 -> -2824 | CW17: =-1817-148 -> -1965 | CX17: =-1966-171 -> -2137 | CY17: =CZ17-SUM(CV17:CX17) -> -2962 | CZ17: =-9173-715 -> -9888 | DA17: =-2142-205 -> -2347 | DB17: =-2358-226 -> -2584 | DC17: =-2171-227 -> -2398 | DD17: =DE17-SUM(DA17:DC17) -> -2844 | DE17: =-9195-978 -> -10173 | DF17: -2269 | DG17: -924 | DH17: -1330 | DI17: -1157 | DK17: -876 | DL17: -1020
B18: Research and development expenses | CL18: -723 | CM18: -611 | CN18: -595 | CO18: =CP18-SUM(CL18:CN18) -> -636 | CP18: -2565 | CQ18: -561 | CR18: -604 | CS18: -627 | CT18: =CU18-SUM(CQ18:CS18) -> -705 | CU18: -2497 | CV18: -403 | CW18: -439 | CX18: -426 | CY18: =CZ18-SUM(CV18:CX18) -> -518 | CZ18: -1786 | DA18: -431 | DB18: -455 | DC18: -471 | DD18: =DE18-SUM(DA18:DC18) -> -550 | DE18: -1907 | DF18: -507 | DG18: -300 | DH18: -331 | DI18: -385 | DK18: -359 | DL18: -359
B19: EBIT | C19: =C16+C18 -> 0 | D19: =D16+D18 -> 0 | E19: =E16+E18 -> 0 | F19: =F16+F18 -> 0 | G19: =G16+G18 -> 0 | H19: =H16+H18 -> 0 | I19: =I16+I18 -> 0 | J19: =J18+J16 -> 0 | K19: =K18+K16 -> 0 | L19: =L18+L16 -> 0 | M19: =M18+M16 -> 0 | N19: =N18+N16 -> 0 | O19: =O18+O16 -> 0 | P19: =P18+P16 -> 0 | Q19: =Q18+Q16 -> 0 | ... CK19: =CK18+CK16 -> 0 | CL19: =SUM(CL16:CL18) -> 1279 | CM19: =SUM(CM16:CM18) -> -507 | CN19: =SUM(CN16:CN18) -> 678 | CO19: =SUM(CO16:CO18) -> 1356 | CP19: =SUM(CP16:CP18) -> 2806 | CQ19: =SUM(CQ16:CQ18) -> 1129 | CR19: =SUM(CR16:CR18) -> 1192 | CS19: =SUM(CS16:CS18) -> 1653 | ... DI19: =SUM(DI16:DI18) -> 2509 | DK19: =SUM(DK16:DK18) -> 2704 | DL19: =SUM(DL16:DL18) -> 2798
B20: Interest expense | N20: =SUM(J20:M20) -> 0 | S20: =SUM(O20:R20) -> 0 | X20: =SUM(T20:W20) -> 0 | AC20: =SUM(Y20:AB20) -> 0 | AH20: =SUM(AD20:AG20) -> 0 | AM20: =SUM(AI20:AL20) -> 0 | AR20: =SUM(AN20:AQ20) -> 0 | AW20: =SUM(AS20:AV20) -> 0 | BB20: =SUM(AX20:BA20) -> 0 | BG20: =SUM(BC20:BF20) -> 0 | BL20: =SUM(BH20:BK20) -> 0 | BQ20: =SUM(BM20:BP20) -> 0 | BV20: =SUM(BR20:BU20) -> 0 | CA20: =SUM(BW20:BZ20) -> 0 | CF20: =SUM(CB20:CE20) -> 0 | CK20: =SUM(CG20:CJ20) -> 0 | CL20: -561 | CM20: -561 | CN20: -526 | CO20: =CP20-SUM(CL20:CN20) -> -420 | CP20: -2068 | CQ20: -500 | CR20: -488 | CS20: -462 | CT20: =CU20-SUM(CQ20:CS20) -> -426 | CU20: -1876 | CV20: -387 | CW20: -368 | CX20: -374 | CY20: =CZ20-SUM(CV20:CX20) -> -348 | CZ20: -1477 | DA20: -269 | DB20: -267 | DC20: -286 | DD20: =DE20-SUM(DA20:DC20) -> -296 | DE20: -1118 | DF20: -278 | DG20: -248 | DH20: -251 | DI20: -224 | DK20: -210 | DL20: -158
B21: Non-operating benefit income | N21: =SUM(J21:M21) -> 0 | S21: =SUM(O21:R21) -> 0 | X21: =SUM(T21:W21) -> 0 | AC21: =SUM(Y21:AB21) -> 0 | AH21: =SUM(AD21:AG21) -> 0 | AM21: =SUM(AI21:AL21) -> 0 | AR21: =SUM(AN21:AQ21) -> 0 | AW21: =SUM(AS21:AV21) -> 0 | BB21: =SUM(AX21:BA21) -> 0 | BG21: =SUM(BC21:BF21) -> 0 | BL21: =SUM(BH21:BK21) -> 0 | BQ21: =SUM(BM21:BP21) -> 0 | BV21: =SUM(BR21:BU21) -> 0 | CA21: =SUM(BW21:BZ21) -> 0 | CF21: =SUM(CB21:CE21) -> 0 | CK21: =SUM(CG21:CJ21) -> 0 | CL21: -618 | CM21: -598 | CN21: -605 | CO21: =CP21-SUM(CL21:CN21) -> -609 | CP21: =-2430 -> -2430 | CQ21: -430 | CR21: -517 | CS21: -427 | CT21: =CU21-SUM(CQ21:CS21) -> -408 | CU21: -1782 | CV21: 105 | CW21: 101 | CX21: 96 | CY21: =CZ21-SUM(CV21:CX21) -> 107 | CZ21: 409 | DA21: 385 | DB21: 402 | DC21: 396 | DD21: =DE21-SUM(DA21:DC21) -> 402 | DE21: 1585 | DF21: 362 | DG21: 204 | DH21: 207 | DI21: 213 | DK21: 201 | DL21: 197
B22: Other non-operating income (expense), net | N22: =SUM(J22:M22) -> 0 | S22: =SUM(O22:R22) -> 0 | X22: =SUM(T22:W22) -> 0 | AC22: =SUM(Y22:AB22) -> 0 | AH22: =SUM(AD22:AG22) -> 0 | AM22: =SUM(AI22:AL22) -> 0 | AR22: =SUM(AN22:AQ22) -> 0 | AW22: =SUM(AS22:AV22) -> 0 | BB22: =SUM(AX22:BA22) -> 0 | BG22: =SUM(BC22:BF22) -> 0 | BL22: =SUM(BH22:BK22) -> 0 | BQ22: =SUM(BM22:BP22) -> 0 | BV22: =SUM(BR22:BU22) -> 0 | CA22: =SUM(BW22:BZ22) -> 0 | CF22: =SUM(CB22:CE22) -> 0 | CK22: =SUM(CG22:CJ22) -> 0 | CL22: =-636-25+6869 -> 6208 | CM22: =2078-65-877-205-564 -> 367 | CN22: =-624-25-517 -> -1166 | CO22: =CP22-SUM(CL22:CN22) -> 2253 | CP22: =-159-301-2397+11396-877 -> 7662 | CQ22: =-555-32+626 -> 39 | CR22: =-1416-30+706-483 -> -1223 | CS22: =-643-28+491 -> -180 | CT22: =CU22-SUM(CQ22:CS22) -> -4756 | CU22: =-136-2283-6524+2823 -> -6120 | CV22: =49-620 -> -571 | CW22: =-1227-669 -> -1896 | CX22: =-504+178 -> -326 | CY22: =CZ22-SUM(CV22:CX22) -> 908 | CZ22: =1172-2592-465 -> -1885 | DA22: =-684+6081 -> 5397 | DB22: =692-735 -> -43 | DC22: =-710-673 -> -1383 | DD22: =DE22-SUM(DA22:DC22) -> 272 | DE22: =-2886+7129 -> 4243 | DF22: =-355-627+1109 -> 127 | DG22: =-75-667-63+2 -> -803 | DH22: =-74-714-251+1021 -> -18 | DI22: =-84-421+299+1 -> -205 | DK22: =+-51-701+302 -> -450 | DL22: =+-47-698+298-1 -> -448
B23: EBT | C23: =SUM(C19:C22) -> 0 | D23: =SUM(D19:D22) -> 0 | E23: =SUM(E19:E22) -> 0 | F23: =SUM(F19:F22) -> 0 | G23: =SUM(G19:G22) -> 0 | H23: =SUM(H19:H22) -> 0 | I23: =SUM(I19:I22) -> 0 | J23: =SUM(J19:J22) -> 0 | ... DI23: =SUM(DI19:DI22) -> 2293 | DK23: =SUM(DK19:DK22) -> 2245 | DL23: =SUM(DL19:DL22) -> 2389
B24: Income tax expense | N24: =SUM(J24:M24) -> 0 | S24: =SUM(O24:R24) -> 0 | X24: =SUM(T24:W24) -> 0 | AC24: =SUM(Y24:AB24) -> 0 | AH24: =SUM(AD24:AG24) -> 0 | AM24: =SUM(AI24:AL24) -> 0 | AR24: =SUM(AN24:AQ24) -> 0 | AW24: =SUM(AS24:AV24) -> 0 | BB24: =SUM(AX24:BA24) -> 0 | BG24: =SUM(BC24:BF24) -> 0 | BL24: =SUM(BH24:BK24) -> 0 | BQ24: =SUM(BM24:BP24) -> 0 | BV24: =SUM(BR24:BU24) -> 0 | CA24: =SUM(BW24:BZ24) -> 0 | CF24: =SUM(CB24:CE24) -> 0 | CK24: =SUM(CG24:CJ24) -> 0 | CL24: -54 | CM24: 160 | CN24: 483 | CO24: =CP24-SUM(CL24:CN24) -> -102 | CP24: 487 | CQ24: -142 | CR24: 466 | CS24: -2 | CT24: =CU24-SUM(CQ24:CS24) -> -36 | CU24: 286 | CV24: -29 | CW24: -161 | CX24: -13 | CY24: =CZ24-SUM(CV24:CX24) -> 206 | CZ24: 3 | DA24: -271 | DB24: -333 | DC24: -138 | DD24: =DE24-SUM(DA24:DC24) -> -420 | DE24: -1162 | DF24: -318 | DG24: -125 | DH24: -198 | DI24: -396 | DK24: -283 | DL24: =+-388-1 -> -389
B25: Net income, continuing ops. | C25: =SUM(C23:C24) -> 0 | D25: =SUM(D23:D24) -> 0 | E25: =SUM(E23:E24) -> 0 | F25: =SUM(F23:F24) -> 0 | G25: =SUM(G23:G24) -> 0 | H25: =SUM(H23:H24) -> 0 | I25: =SUM(I23:I24) -> 0 | J25: =SUM(J23:J24) -> 0 | ... DI25: =SUM(DI23:DI24) -> 1897 | DK25: =SUM(DK23:DK24) -> 1962 | DL25: =SUM(DL23:DL24) -> 2000
B26: Earnings (loss) from discontinued ops. | CL26: -21 | CM26: -993 | CN26: -58 | CO26: =CP26-SUM(CL26:CN26) -> 161 | CP26: -911 | CQ26: -2894 | CR26: -564 | CS26: 602 | CT26: =CU26-SUM(CQ26:CS26) -> -339 | CU26: -3195 | CV26: 101 | CW26: 264 | CX26: 409 | CY26: =CZ26-SUM(CV26:CX26) -> 428 | CZ26: 1202 | DA26: 1257 | DB26: -1019 | DC26: 173 | DD26: =DE26-SUM(DA26:DC26) -> 3 | DE26: 414 | DF26: 14 | DG26: -54 | DH26: 147 | DI26: -6 | DK26: 10 | DL26: 21
B27: Net income (loss) | CL27: =SUM(CL25:CL26) -> 6233 | CM27: =SUM(CM25:CM26) -> -2132 | CN27: =SUM(CN25:CN26) -> -1194 | CO27: =SUM(CO25:CO26) -> 2639 | CP27: =SUM(CP25:CP26) -> 5546 | CQ27: =SUM(CQ25:CQ26) -> -2798 | CR27: =SUM(CR25:CR26) -> -1134 | CS27: =SUM(CS25:CS26) -> 1184 | ... DO27: =SUM(DO25:DO26) -> 0 | DT27: =SUM(DT25:DT26) -> 0 | DU27: =SUM(DU25:DU26) -> 0 | DV27: =SUM(DV25:DV26) -> 0
B28: Net income (loss) attributable to noncontrolling interests | CL28: -34 | CM28: 145 | CN28: 51 | CO28: =CP28-SUM(CL28:CN28) -> -4 | CP28: 158 | CQ28: -5 | CR28: 3 | CS28: 73 | CT28: =CU28-SUM(CQ28:CS28) -> 0 | CU28: 71 | CV28: -28 | CW28: -19 | CX28: -4 | CY28: =CZ28-SUM(CV28:CX28) -> -16 | CZ28: -67 | DA28: 27 | DB28: -4 | DC28: 14 | DD28: =DE28-SUM(DA28:DC28) -> 0 | DE28: 37 | DF28: -27 | DG28: -2 | DH28: 10 | DI28: 8 | DK28: 5 | DL28: 7
B29: Net income attributable to the company | C29: =SUM(C25:C28) -> 0 | D29: =SUM(D25:D28) -> 0 | E29: =SUM(E25:E28) -> 0 | F29: =SUM(F25:F28) -> 0 | G29: =SUM(G25:G28) -> 0 | H29: =SUM(H25:H28) -> 0 | I29: =SUM(I25:I28) -> 0 | J29: =SUM(J25:J28) -> 0 | ... CK29: =SUM(CK25:CK28) -> 0 | CL29: =SUM(CL27:CL28) -> 6199 | CM29: =SUM(CM27:CM28) -> -1987 | CN29: =SUM(CN27:CN28) -> -1143 | CO29: =SUM(CO27:CO28) -> 2635 | CP29: =SUM(CP27:CP28) -> 5704 | CQ29: =SUM(CQ27:CQ28) -> -2803 | CR29: =SUM(CR27:CR28) -> -1131 | CS29: =SUM(CS27:CS28) -> 1257 | ... DI29: =SUM(DI27:DI28) -> 1899 | DK29: =SUM(DK27:DK28) -> 1977 | DL29: =SUM(DL27:DL28) -> 2028
B30: Preferred stock dividends | CL30: -43 | CM30: -192 | CN30: -46 | CO30: =CP30-SUM(CL30:CN30) -> -193 | CP30: -474 | CQ30: -72 | CR30: -57 | CS30: -52 | CT30: =CU30-SUM(CQ30:CS30) -> -56 | CU30: -237 | CV30: -52 | CW30: -67 | CX30: -73 | CY30: =CZ30-SUM(CV30:CX30) -> -97 | CZ30: -289 | DA30: -145 | DB30: -58 | DC30: -91 | DD30: =DE30-SUM(DA30:DC30) -> -1 | DE30: -295 | DF30: 0 | DG30: 0 | DH30: 0 | DI30: 0 | DK30: 0 | DL30: 0
B31: Net income (loss) attributable to Ticker0009 common shareholders | CL31: =SUM(CL29:CL30) -> 6156 | CM31: =SUM(CM29:CM30) -> -2179 | CN31: =SUM(CN29:CN30) -> -1189 | CO31: =SUM(CO29:CO30) -> 2442 | CP31: =SUM(CP29:CP30) -> 5230 | CQ31: =SUM(CQ29:CQ30) -> -2875 | CR31: =SUM(CR29:CR30) -> -1188 | CS31: =SUM(CS29:CS30) -> 1205 | ... DI31: =SUM(DI29:DI30) -> 1899 | DK31: =SUM(DK29:DK30) -> 1977 | DL31: =SUM(DL29:DL30) -> 2028
B32: Earnings (loss) from discontinued ops. attributable to Ticker0009 common shareholders | CL32: -21 | CM32: -993 | CN32: -58 | CO32: =CP32-SUM(CL32:CN32) -> 161 | CP32: -911 | CQ32: -2894 | CR32: -564 | CS32: 602 | CT32: =CU32-SUM(CQ32:CS32) -> -339 | CU32: -3195 | CV32: 88 | CW32: 252 | CX32: 403 | CY32: =CZ32-SUM(CV32:CX32) -> 408 | CZ32: 1151 | DA32: 1257 | DB32: -1019 | DC32: 173 | DD32: =DE32-SUM(DA32:DC32) -> 3 | DE32: 414 | DF32: 14 | DG32: -54 | DH32: 147 | DI32: -6 | DK32: -6 | DL32: 0
B33: Net income reported | CL33: =CL31-CL32 -> 6177 | CM33: =CM31-CM32 -> -1186 | CN33: =CN31-CN32 -> -1131 | CO33: =CP33-SUM(CL33:CN33) -> 2281 | CP33: =CP31-CP32 -> 6141 | CQ33: =CQ31-CQ32 -> 19 | CR33: =CR31-CR32 -> -624 | CS33: =CS31-CS32 -> 603 | CT33: =CU33-SUM(CQ33:CS33) -> -3560 | CU33: =CU31-CU32 -> -3562 | CV33: =CV31-CV32 -> -1276 | CW33: =CW31-CW32 -> -1199 | CX33: =CX31-CX32 -> -314 | CY33: =CZ33-SUM(CV33:CX33) -> 1687 | CZ33: =CZ31-CZ32 -> -1102 | DA33: =DA31-DA32 -> 6102 | DB33: =DB31-DB32 -> 994 | DC33: =DC31-DC32 -> 85 | DD33: =DE33-SUM(DA33:DC33) -> 1591 | DE33: =DE31-DE32 -> 8772 | DF33: =DF31-DF32 -> 1523 | DG33: =DG31-DG32 -> 1320 | DH33: =DH31-DH32 -> 1705 | DI33: =DI31-DI32 -> 1905 | DK33: =DK31-DK32 -> 1983 | DL33: =DL31-DL32 -> 2028
B35: Basic EPS, continuing ops. | C35: =C25/C44 -> #DIV/0! | D35: =D25/D44 -> #DIV/0! | E35: =E25/E44 -> #DIV/0! | F35: =F25/F44 -> #DIV/0! | G35: =G25/G44 -> #DIV/0! | H35: =H25/H44 -> #DIV/0! | I35: =I25/I44 -> #DIV/0! | J35: =J25/J44 -> #DIV/0! | ... M35: =M25/M44 -> #DIV/0! | O35: =O25/O44 -> #DIV/0! | P35: =P25/P44 -> #DIV/0! | Q35: =Q25/Q44 -> #DIV/0! | R35: =R25/R44 -> #DIV/0! | T35: =T25/T44 -> #DIV/0! | U35: =U25/U44 -> #DIV/0! | V35: =V25/V44 -> #DIV/0! | W35: =W25/W44 -> #DIV/0! | Y35: =Y25/Y44 -> #DIV/0! | Z35: =Z25/Z44 -> #DIV/0! | AA35: =AA25/AA44 -> #DIV/0! | AB35: =AB25/AB44 -> #DIV/0! | AD35: =AD25/AD44 -> #DIV/0! | AE35: =AE25/AE44 -> #DIV/0! | AF35: =AF25/AF44 -> #DIV/0! | AG35: =AG25/AG44 -> #DIV/0! | AI35: =AI25/AI44 -> #DIV/0! | AJ35: =AJ25/AJ44 -> #DIV/0! | AK35: =AK25/AK44 -> #DIV/0! | AL35: =AL25/AL44 -> #DIV/0! | AN35: =AN25/AN44 -> #DIV/0! | AO35: =AO25/AO44 -> #DIV/0! | AP35: =AP25/AP44 -> #DIV/0! | AQ35: =AQ25/AQ44 -> #DIV/0! | AS35: =AS25/AS44 -> #DIV/0! | AT35: =AT25/AT44 -> #DIV/0! | AU35: =AU25/AU44 -> #DIV/0! | AV35: =AV25/AV44 -> #DIV/0! | AX35: =AX25/AX44 -> #DIV/0! | AY35: =AY25/AY44 -> #DIV/0! | AZ35: =AZ25/AZ44 -> #DIV/0! | BA35: =BA25/BA44 -> #DIV/0! | BC35: =BC25/BC44 -> #DIV/0! | BD35: =BD25/BD44 -> #DIV/0! | BE35: =BE25/BE44 -> #DIV/0! | BF35: =BF25/BF44 -> #DIV/0! | BH35: =BH25/BH44 -> #DIV/0! | BI35: =BI25/BI44 -> #DIV/0! | BJ35: =BJ25/BJ44 -> #DIV/0! | BK35: =BK25/BK44 -> #DIV/0! | BM35: =BM25/BM44 -> #DIV/0! | BN35: =BN25/BN44 -> #DIV/0! | BO35: =BO25/BO44 -> #DIV/0! | BP35: =BP25/BP44 -> #DIV/0! | BR35: =BR25/BR44 -> #DIV/0! | BS35: =BS25/BS44 -> #DIV/0! | BT35: =BT25/BT44 -> #DIV/0! | BU35: =BU25/BU44 -> #DIV/0! | BW35: =BW25/BW44 -> #DIV/0! | BX35: =BX25/BX44 -> #DIV/0! | BY35: =BY25/BY44 -> #DIV/0! | BZ35: =BZ25/BZ44 -> #DIV/0! | CB35: =CB25/CB44 -> #DIV/0! | CC35: =CC25/CC44 -> #DIV/0! | CD35: =CD25/CD44 -> #DIV/0! | CE35: =CE25/CE44 -> #DIV/0! | CG35: =CG25/CG44 -> #DIV/0! | CH35: =CH25/CH44 -> #DIV/0! | CI35: =CI25/CI44 -> #DIV/0! | CJ35: =CJ25/CJ44 -> #DIV/0! | CL35: =CL31/CL44 -> 0.70229935 | CM35: =CM31/CM44 -> -0.24814085 | CN35: =CN31/CN44 -> -0.13573256 | CO35: =CO31/CO44 -> 2.2287395 | CP35: =CP31/CP44 -> 4.7732628 | CQ35: =CQ31/CQ44 -> -0.32749944 | CR35: =CR31/CR44 -> -0.13528744 | CS35: =CS31/CS44 -> 1.0973129 | ... CU35: =CU31/CU44 -> -6.1481644 | CV35: =(CV25+CV30)/CV44 -> -1.145671 | CW35: =(CW25+CW30)/CW44 -> -1.0870427 | CX35: =(CX25+CX30)/CX44 -> -0.28920034 | CY35: =(CY25+CY30)/CY44 -> 1.5453126 | CZ35: =(CZ25+CZ30)/CZ44 -> -0.99715361 | DA35: =(DA25+DA30)/DA44 -> 5.5787172 | DB35: =(DB25+DB30)/DB44 -> 0.91696067 | DC35: =(DC25+DC30)/DC44 -> 0.065234207 | ... DI35: =(DI25+DI30)/DI44 -> 1.7668006 | DK35: =(DK25+DK30)/DK44 -> 1.839858 | DL35: =(DL25+DL30)/DL44 -> 1.8860107
B36: Discontinued ops. & non recurring items | C36: =C28/C44 -> #DIV/0! | D36: =D28/D44 -> #DIV/0! | E36: =E28/E44 -> #DIV/0! | F36: =F28/F44 -> #DIV/0! | G36: =G28/G44 -> #DIV/0! | H36: =H28/H44 -> #DIV/0! | I36: =I28/I44 -> #DIV/0! | J36: =J28/J44 -> #DIV/0! | ... CU36: =CU28/CU44 -> 0.064602586 | CV36: =(CV28+CV26)/CV44 -> 0.066323542 | CW36: =(CW28+CW26)/CW44 -> 0.22342739 | CX36: =(CX28+CX26)/CX44 -> 0.37065234 | CY36: =(CY28+CY26)/CY44 -> 0.378294 | CZ36: =(CZ28+CZ26)/CZ44 -> 1.0421449 | DA36: =(DA28+DA26)/DA44 -> 1.1791066 | DB36: =(DB28+DB26)/DB44 -> -0.93993063 | DC36: =(DC28+DC26)/DC44 -> 0.17181404 | ... DI36: =(DI28+DI26)/DI44 -> 0.0018627313 | DK36: =(DK28+DK26)/DK44 -> 0.014066193 | DL36: =(DL28+DL26)/DL44 -> 0.026404149
B37: Basic EPS, reported | C37: =SUM(C35:C36) -> #DIV/0! | D37: =SUM(D35:D36) -> #DIV/0! | E37: =SUM(E35:E36) -> #DIV/0! | F37: =SUM(F35:F36) -> #DIV/0! | G37: =SUM(G35:G36) -> #DIV/0! | H37: =SUM(H35:H36) -> #DIV/0! | I37: =SUM(I35:I36) -> #DIV/0! | J37: =SUM(J35:J36) -> #DIV/0! | ... DI37: =SUM(DI35:DI36) -> 1.7686633 | DK37: =SUM(DK35:DK36) -> 1.8539242 | DL37: =SUM(DL35:DL36) -> 1.9124148
B39: Diluted EPS, continuing ops. | C39: =C25/C45 -> #DIV/0! | D39: =D25/D45 -> #DIV/0! | E39: =E25/E45 -> #DIV/0! | F39: =F25/F45 -> #DIV/0! | G39: =G25/G45 -> #DIV/0! | H39: =H25/H45 -> #DIV/0! | I39: =I25/I45 -> #DIV/0! | J39: =J25/J45 -> #DIV/0! | ... M39: =M25/M45 -> #DIV/0! | O39: =O25/O45 -> #DIV/0! | P39: =P25/P45 -> #DIV/0! | Q39: =Q25/Q45 -> #DIV/0! | R39: =R25/R45 -> #DIV/0! | T39: =T25/T45 -> #DIV/0! | U39: =U25/U45 -> #DIV/0! | V39: =V25/V45 -> #DIV/0! | W39: =W25/W45 -> #DIV/0! | Y39: =Y25/Y45 -> #DIV/0! | Z39: =Z25/Z45 -> #DIV/0! | AA39: =AA25/AA45 -> #DIV/0! | AB39: =AB25/AB45 -> #DIV/0! | AD39: =AD25/AD45 -> #DIV/0! | AE39: =AE25/AE45 -> #DIV/0! | AF39: =AF25/AF45 -> #DIV/0! | AG39: =AG25/AG45 -> #DIV/0! | AI39: =AI25/AI45 -> #DIV/0! | AJ39: =AJ25/AJ45 -> #DIV/0! | AK39: =AK25/AK45 -> #DIV/0! | AL39: =AL25/AL45 -> #DIV/0! | AN39: =AN25/AN45 -> #DIV/0! | AO39: =AO25/AO45 -> #DIV/0! | AP39: =AP25/AP45 -> #DIV/0! | AQ39: =AQ25/AQ45 -> #DIV/0! | AS39: =AS25/AS45 -> #DIV/0! | AT39: =AT25/AT45 -> #DIV/0! | AU39: =AU25/AU45 -> #DIV/0! | AV39: =AV25/AV45 -> #DIV/0! | AX39: =AX25/AX45 -> #DIV/0! | AY39: =AY25/AY45 -> #DIV/0! | AZ39: =AZ25/AZ45 -> #DIV/0! | BA39: =BA25/BA45 -> #DIV/0! | BC39: =BC25/BC45 -> #DIV/0! | BD39: =BD25/BD45 -> #DIV/0! | BE39: =BE25/BE45 -> #DIV/0! | BF39: =BF25/BF45 -> #DIV/0! | BH39: =BH25/BH45 -> #DIV/0! | BI39: =BI25/BI45 -> #DIV/0! | BJ39: =BJ25/BJ45 -> #DIV/0! | BK39: =BK25/BK45 -> #DIV/0! | BM39: =BM25/BM45 -> #DIV/0! | BN39: =BN25/BN45 -> #DIV/0! | BO39: =BO25/BO45 -> #DIV/0! | BP39: =BP25/BP45 -> #DIV/0! | BR39: =BR25/BR45 -> #DIV/0! | BS39: =BS25/BS45 -> #DIV/0! | BT39: =BT25/BT45 -> #DIV/0! | BU39: =BU25/BU45 -> #DIV/0! | BW39: =BW25/BW45 -> #DIV/0! | BX39: =BX25/BX45 -> #DIV/0! | BY39: =BY25/BY45 -> #DIV/0! | BZ39: =BZ25/BZ45 -> #DIV/0! | CB39: =CB25/CB45 -> #DIV/0! | CC39: =CC25/CC45 -> #DIV/0! | CD39: =CD25/CD45 -> #DIV/0! | CE39: =CE25/CE45 -> #DIV/0! | CG39: =CG25/CG45 -> #DIV/0! | CH39: =CH25/CH45 -> #DIV/0! | CI39: =CI25/CI45 -> #DIV/0! | CJ39: =CJ25/CJ45 -> #DIV/0! | CL39: =CL31/CL45 -> 0.70229935 | CM39: =CM31/CM45 -> -0.24814085 | CN39: =CN31/CN45 -> -0.13573256 | CO39: =CO31/CO45 -> 2.2287395 | CP39: =CP31/CP45 -> 4.7732628 | CQ39: =CQ31/CQ45 -> -0.32749944 | CR39: =CR31/CR45 -> -0.13528744 | CS39: =CS31/CS45 -> 1.0973129 | ... CU39: =CU31/CU45 -> -6.1481644 | CV39: =(CV25+CV30)/CV45 -> -1.145671 | CW39: =(CW25+CW30)/CW45 -> -1.0870427 | CX39: =(CX25+CX30)/CX45 -> -0.28920034 | CY39: =(CY25+CY30)/CY45 -> 1.5453126 | CZ39: =(CZ25+CZ30)/CZ45 -> -0.99715361 | DA39: =(DA25+DA30)/DA45 -> 5.5787172 | DB39: =(DB25+DB30)/DB45 -> 0.91696067 | DC39: =(DC25+DC30)/DC45 -> 0.065234207 | ... DI39: =(DI25+DI30)/DI45 -> 1.7504971 | DK39: =(DK25+DK30)/DK45 -> 1.839858 | DL39: =(DL25+DL30)/DL45 -> 1.8860107
B40: Discontinued ops. & non recurring items | C40: =C28/C45 -> #DIV/0! | D40: =D28/D45 -> #DIV/0! | E40: =E28/E45 -> #DIV/0! | F40: =F28/F45 -> #DIV/0! | G40: =G28/G45 -> #DIV/0! | H40: =H28/H45 -> #DIV/0! | I40: =I28/I45 -> #DIV/0! | J40: =J28/J45 -> #DIV/0! | ... CU40: =CU28/CU45 -> 0.064602586 | CV40: =(CV26+CV28)/CV45 -> 0.066323542 | CW40: =(CW26+CW28)/CW45 -> 0.22342739 | CX40: =(CX26+CX28)/CX45 -> 0.37065234 | CY40: =(CY26+CY28)/CY45 -> 0.378294 | CZ40: =(CZ26+CZ28)/CZ45 -> 1.0421449 | DA40: =(DA26+DA28)/DA45 -> 1.1791066 | DB40: =(DB26+DB28)/DB45 -> -0.93993063 | DC40: =(DC26+DC28)/DC45 -> 0.17181404 | ... DI40: =(DI26+DI28)/DI45 -> 0.0018455425 | DK40: =(DK26+DK28)/DK45 -> 0.014066193 | DL40: =(DL26+DL28)/DL45 -> 0.026404149
B41: Diluted EPS, reported | C41: =SUM(C39:C40) -> #DIV/0! | D41: =SUM(D39:D40) -> #DIV/0! | E41: =SUM(E39:E40) -> #DIV/0! | F41: =SUM(F39:F40) -> #DIV/0! | G41: =SUM(G39:G40) -> #DIV/0! | H41: =SUM(H39:H40) -> #DIV/0! | I41: =SUM(I39:I40) -> #DIV/0! | J41: =SUM(J39:J40) -> #DIV/0! | ... DI41: =SUM(DI39:DI40) -> 1.7523426 | DK41: =SUM(DK39:DK40) -> 1.8539242 | DL41: =SUM(DL39:DL40) -> 1.9124148
B43: Common shares outstanding
B44: Basic | N44: =N29/N35 -> #DIV/0! | S44: =S29/S35 -> #DIV/0! | X44: =X29/X35 -> #DIV/0! | AC44: =AC29/AC35 -> #DIV/0! | AH44: =AH29/AH35 -> #DIV/0! | AM44: =AM29/AM35 -> #DIV/0! | AR44: =AR29/AR35 -> #DIV/0! | AW44: =AW29/AW35 -> #DIV/0! | BB44: =BB29/BB35 -> #DIV/0! | BG44: =BG29/BG35 -> #DIV/0! | BL44: =BL29/BL35 -> #DIV/0! | BQ44: =BQ29/BQ35 -> #DIV/0! | BV44: =BV29/BV35 -> #DIV/0! | CA44: =CA29/CA35 -> #DIV/0! | CF44: =CF29/CF35 -> #DIV/0! | CK44: =CK29/CK35 -> #DIV/0! | CL44: 8765.493 | CM44: 8781.303 | CN44: =8759.873 -> 8759.873 | CO44: 1095.6866 | CP44: 1095.6866 | CQ44: 8778.641 | CR44: 8781.303 | CS44: 1098.1371 | CT44: 1099.0272 | CU44: 1099.0272 | CV44: 1100.665 | CW44: 1096.5531 | CX44: 1092.6681 | CY44: =CZ44 -> 1089.1 | CZ44: 1089.1 | DA44: 1088.96 | DB44: 1088.3782 | DC44: 1088.386 | DD44: =DE44 -> 1088.416 | DE44: 1088.416 | DF44: 1091 | DG44: 1089 | DH44: 1083 | DI44: 1073.6922 | DK44: 1066.3866 | DL44: 1060.4394
B45: Diluted | N45: =N29/N39 -> #DIV/0! | S45: =S29/S39 -> #DIV/0! | X45: =X29/X39 -> #DIV/0! | AC45: =AC29/AC39 -> #DIV/0! | AH45: =AH29/AH39 -> #DIV/0! | AM45: =AM29/AM39 -> #DIV/0! | AR45: =AR29/AR39 -> #DIV/0! | AW45: =AW29/AW39 -> #DIV/0! | BB45: =BB29/BB39 -> #DIV/0! | BG45: =BG29/BG39 -> #DIV/0! | BL45: =BL29/BL39 -> #DIV/0! | BQ45: =BQ29/BQ39 -> #DIV/0! | BV45: =BV29/BV39 -> #DIV/0! | CA45: =CA29/CA39 -> #DIV/0! | CF45: =CF29/CF39 -> #DIV/0! | CK45: =CK29/CK39 -> #DIV/0! | CL45: 8765.493 | CM45: 8781.303 | CN45: 8759.873 | CO45: 1095.6866 | CP45: 1095.6866 | CQ45: 8778.641 | CR45: 8781.303 | CS45: 1098.1371 | CT45: 1099.0272 | CU45: 1099.0272 | CV45: 1100.665 | CW45: 1096.5531 | CX45: 1092.6681 | CY45: =CZ45 -> 1089.1 | CZ45: 1089.1 | DA45: 1088.96 | DB45: 1088.3782 | DC45: 1088.386 | DD45: =DE45 -> 1088.416 | DE45: 1088.416 | DF45: 1103 | DG45: 1100 | DH45: 1093 | DI45: =+DI44+10 -> 1083.6922 | DK45: =+DK44 -> 1066.3866 | DL45: 1060.4394
B47: Check | C47: =IF(ROUND(C25/C44,2)=ROUND(C35,2),"","check") -> #DIV/0! | D47: =IF(ROUND(D25/D44,2)=ROUND(D35,2),"","check") -> #DIV/0! | E47: =IF(ROUND(E25/E44,2)=ROUND(E35,2),"","check") -> #DIV/0! | F47: =IF(ROUND(F25/F44,2)=ROUND(F35,2),"","check") -> #DIV/0! | G47: =IF(ROUND(G25/G44,2)=ROUND(G35,2),"","check") -> #DIV/0! | H47: =IF(ROUND(H25/H44,2)=ROUND(H35,2),"","check") -> #DIV/0! | I47: =IF(ROUND(I25/I44,2)=ROUND(I35,2),"","check") -> #DIV/0! | J47: =IF(ROUND(J25/J44,2)=ROUND(J35,2),"","check") -> #DIV/0! | ... AK47: =IF(ROUND(AK25/AK44,2)=ROUND(AK35,2),"","check") -> #DIV/0!
...

Sheet Aerospace
B3: Ticker0009 Revenue Build | C3: 1997 | D3: 1998 | E3: 1999 | F3: 2000 | G3: 2001 | H3: 2002 | I3: 2003 | J3: 1Q04 | K3: 2Q04 | L3: 3Q04 | M3: 4Q04 | N3: 2004 | O3: 1Q05 | P3: 2Q05 | Q3: 3Q05 | R3: 4Q05 | S3: 2005 | T3: 1Q06 | U3: 2Q06 | V3: 3Q06 | W3: 4Q06 | X3: 2006 | Y3: 1Q07 | Z3: 2Q07 | AA3: 3Q07 | AB3: 4Q07 | AC3: 2007 | AD3: 1Q08 | AE3: 2Q08 | AF3: 3Q08 | AG3: 4Q08 | AH3: 2008 | AI3: 1Q09 | AJ3: 2Q09 | AK3: 3Q09 | AL3: 4Q09 | AM3: 2009 | AN3: 1Q10 | AO3: 2Q10 | AP3: 3Q10 | AQ3: 4Q10 | AR3: 2010 | AS3: 1Q11 | AT3: 2Q11 | AU3: 3Q11 | AV3: 4Q11 | AW3: 2011 | AX3: 1Q12 | AY3: 2Q12 | AZ3: 3Q12 | BA3: 4Q12 | BB3: 2012 | BC3: 1Q13 | BD3: 2Q13 | BE3: 3Q13 | BF3: 4Q13 | BG3: 2013 | BH3: 1Q14 | BI3: 2Q14 | BJ3: 3Q14 | BK3: 4Q14 | BL3: 2014 | BM3: 1Q15 | BN3: 2Q15 | BO3: 3Q15 | BP3: 4Q15 | BQ3: 2015 | BR3: 1Q16 | BS3: 2Q16 | BT3: 3Q16 | BU3: 4Q16 | BV3: 2016 | BW3: 1Q17 | BX3: 2Q17 | BY3: 3Q17 | BZ3: 4Q17 | CA3: 2017 | CB3: 1Q18 | CC3: 2Q18 | CD3: 3Q18 | CE3: 4Q18 | CF3: 2018 | CG3: 1Q19 | CH3: 2Q19 | CI3: 3Q19 | CJ3: 4Q19 | CK3: 2019 | CL3: 1Q20 | CM3: 2Q20 | CN3: 3Q20 | CO3: 4Q20 | CP3: 2020 | CQ3: 1Q21 | CR3: 2Q21 | CS3: 3Q21 | CT3: 4Q21 | CU3: 2021 | CV3: 1Q22 | CW3: 2Q22 | CX3: 3Q22 | CY3: 4Q22 | CZ3: 2022 | DA3: 1Q23 | DB3: 2Q23 | DC3: 3Q23 | DD3: 4Q23 | DE3: 2023 | DF3: 1Q24 | DG3: 2Q24 | DH3: 3Q24 | DI3: 4Q24 | DJ3: 2024 | DK3: 1Q25 | DL3: 2Q25 | DM3: 3Q25E | DN3: 4Q25E | DO3: 2025 | DP3: 1Q26E | DQ3: 2Q26E | DR3: 3Q26E | DS3: 4Q26E | DT3: 2026 | DU3: 2027 | DV3: 2028
B4: ($ mn) | C4: 35795 | D4: 36160 | E4: 36525 | F4: 36891 | G4: 37256 | H4: 37621 | I4: 37986 | J4: 38077 | K4: 38168 | L4: 38260 | M4: 38352 | N4: 38352 | O4: 38442 | P4: 38533 | Q4: 38625 | R4: 38717 | S4: 38717 | T4: 38807 | U4: 38898 | V4: 38990 | W4: 39082 | X4: 39082 | Y4: 39172 | Z4: 39263 | AA4: 39355 | AB4: 39447 | AC4: 39447 | AD4: 39538 | AE4: 39629 | AF4: 39721 | AG4: 39813 | AH4: 39813 | AI4: 39903 | AJ4: 39994 | AK4: 40086 | AL4: 40178 | AM4: 40178 | AN4: 40268 | AO4: 40359 | AP4: 40451 | AQ4: 40543 | AR4: 40543 | AS4: 40633 | AT4: 40724 | AU4: 40816 | AV4: 40908 | AW4: 40908 | AX4: 40999 | AY4: 41090 | AZ4: 41182 | BA4: 41274 | BB4: 41274 | BC4: 41364 | BD4: 41455 | BE4: 41547 | BF4: 41639 | BG4: 41639 | BH4: 41729 | BI4: 41820 | BJ4: 41912 | BK4: 42004 | BL4: 42004 | BM4: 42094 | BN4: 42185 | BO4: 42277 | BP4: 42369 | BQ4: 42369 | BR4: 42460 | BS4: 42551 | BT4: 42643 | BU4: 42735 | BV4: 42735 | BW4: 42825 | BX4: 42916 | BY4: 43008 | BZ4: 43100 | CA4: 43100 | CB4: 43190 | CC4: 43281 | CD4: 43373 | CE4: 43465 | CF4: 43465 | CG4: 43555 | CH4: 43646 | CI4: 43738 | CJ4: 43830 | CK4: 43830 | CL4: 43921 | CM4: 44012 | CN4: 44104 | CO4: 44196 | CP4: 44196 | CQ4: 44286 | CR4: 44377 | CS4: 44469 | CT4: 44561 | CU4: 44561 | CV4: 44651 | CW4: 44742 | CX4: 44834 | CY4: 44926 | CZ4: 44926 | DA4: 45016 | DB4: 45107 | DC4: 45199 | DD4: 45291 | DE4: 45291 | DF4: 45382 | DG4: 45473 | DH4: 45565 | DI4: 45657 | DJ4: 45657 | DK4: 45747 | DL4: 45838 | DM4: 45930 | DN4: 46022 | DO4: 46022 | DP4: 46112 | DQ4: 46203 | DR4: 46295 | DS4: 46387 | DT4: 46387 | DU4: 46752 | DV4: 47118
B6: Segment revenues
B7: Revenues | H7: 11141 | I7: 10509 | N7: 11094 | S7: 11826 | T7: 3010 | U7: 3287 | V7: 3133 | W7: 3587 | X7: =T7+U7+V7+W7 -> 13017 | Y7: 3451 | Z7: 4079 | AA7: 4240 | AB7: 5049 | AC7: =Y7+Z7+AA7+AB7 -> 16819 | AD7: 4320 | AE7: 4923 | AF7: 4841 | AG7: 5155 | AH7: =AD7+AE7+AF7+AG7 -> 19239 | AI7: 4817 | AJ7: 4619 | AK7: 4542 | AL7: 4750 | AM7: =AI7+AJ7+AK7+AL7 -> 18728 | AN7: 4165 | AO7: 4259 | AP7: 4391 | AQ7: 4804 | AR7: =AN7+AO7+AP7+AQ7 -> 17619 | AS7: 4368 | AT7: 4732 | AU7: 4835 | AV7: 4924 | AW7: =AS7+AT7+AU7+AV7 -> 18859 | AX7: 4891 | AY7: 4855 | AZ7: 4781 | BA7: 5467 | BB7: =AX7+AY7+AZ7+BA7 -> 19994 | BC7: 5074 | BD7: 5303 | BE7: 5364 | BF7: 6170 | BG7: =BC7+BD7+BE7+BF7 -> 21911 | BH7: 5778 | BI7: 6090 | BJ7: 5698 | BK7: 6424 | BL7: =BH7+BI7+BJ7+BK7 -> 23990 | BM7: 5674 | BN7: 6252 | BO7: 6001 | BP7: 6734 | BQ7: =BM7+BN7+BO7+BP7 -> 24661 | BR7: 6262 | BS7: 6511 | BT7: 6300 | BU7: 7187 | BV7: =BR7+BS7+BT7+BU7 -> 26260 | BW7: 6673 | BX7: 6634 | BY7: 6696 | BZ7: 7010 | CA7: =BW7+BX7+BY7+BZ7 -> 27013 | CB7: 7112 | CC7: 7519 | CD7: 7480 | CE7: 8456 | CF7: =CB7+CC7+CD7+CE7 -> 30567 | CG7: 7954 | CH7: 7877 | CI7: 8109 | CJ7: 8936 | CK7: =CG7+CH7+CI7+CJ7 -> 32876 | CL7: 6892 | CM7: 4384 | CN7: 4919 | CO7: 5847 | CP7: =CL7+CM7+CN7+CO7 -> 22042 | CQ7: 4992 | CR7: 4840 | CS7: 5398 | CT7: 6080 | CU7: =CQ7+CR7+CS7+CT7 -> 21310 | CV7: 5603 | CW7: 6127 | CX7: 6705 | CY7: 7615 | CZ7: =CV7+CW7+CX7+CY7 -> 26050 | DA7: 6981 | DB7: 7860 | DC7: 8409 | DD7: 8520 | DE7: =DA7+DB7+DC7+DD7 -> 31770 | DF7: =SEG!DF11 -> 8076 | DG7: =SEG!DG11 -> 8223 | DH7: =SEG!DH11 -> 8943 | DI7: =SEG!DI11 -> 9879 | DJ7: =SEG!DJ11 -> 35121 | DK7: =SEG!DK11 -> 9001 | DL7: =SEG!DL11 -> 10151 | DM7: =SEG!DM11 -> 10065.86 | ... DV7: =SEG!DV11 -> 52592.722
B8: Operating expenses | H8: =H7-H9 -> 9081 | I8: =I7-I9 -> 8361 | N8: =N7-N9 -> 8856.1 | S8: =S7-S9 -> 9301 | T8: =T7-T9 -> 2383 | U8: =U7-U9 -> 2559 | V8: =V7-V9 -> 2444 | W8: =W7-W9 -> 2829 | X8: =X7-X9 -> 10215 | Y8: =Y7-Y9 -> 2752 | Z8: =Z7-Z9 -> 3251 | ... DV8: =DV7-DV9 -> 40686.573
B9: EBIT (GAAP) | H9: 2060 | I9: 2148 | N9: 2237.9 | S9: 2525 | T9: 627 | U9: 728 | V9: 689 | W9: 758 | X9: =W9+V9+U9+T9 -> 2802 | Y9: 699 | Z9: 828 | AA9: 736 | AB9: 959 | AC9: =AB9+AA9+Z9+Y9 -> 3222 | AD9: 775 | AE9: 914 | AF9: 834 | AG9: 1161 | AH9: =AD9+AE9+AF9+AG9 -> 3684 | AI9: =1080 -> 1080 | AJ9: 923 | AK9: 970 | AL9: 950 | AM9: =AI9+AJ9+AK9+AL9 -> 3923 | AN9: 799 | AO9: 879 | AP9: 805 | AQ9: 821 | AR9: =AN9+AO9+AP9+AQ9 -> 3304 | AS9: 841 | AT9: 959 | AU9: 862 | AV9: 850 | AW9: =AS9+AT9+AU9+AV9 -> 3512 | AX9: 862 | AY9: 922 | AZ9: 924 | BA9: 1039 | BB9: =AX9+AY9+AZ9+BA9 -> 3747 | BC9: 936 | BD9: =BD11+BD10 -> 1067 | BE9: =BE11+BE10 -> 1091 | BF9: =BF11+BF10 -> 1251 | BG9: =BC9+BD9+BE9+BF9 -> 4345 | BH9: =BH11+BH10 -> 1115 | BI9: =BI11+BI10 -> 1197 | BJ9: =BJ11+BJ10 -> 1264 | BK9: =BK11+BK10 -> 1397 | BL9: =BH9+BI9+BJ9+BK9 -> 4973 | BM9: =BM11+BM10 -> 1314 | BN9: =BN11+BN10 -> 1269 | BO9: =BO11+BO10 -> 1353 | BP9: =BP11+BP10 -> 1571 | BQ9: =BM9+BN9+BO9+BP9 -> 5507 | BR9: =BR11+BR10 -> 1524 | BS9: =BS11+BS10 -> 1348 | BT9: =BT11+BT10 -> 1494 | BU9: =BU11+BU10 -> 1749 | BV9: =BR9+BS9+BT9+BU9 -> 6115 | BW9: =BW11+BW10 -> 1273 | BX9: =BX11+BX10 -> 1374 | BY9: =BY11+BY10 -> 1335 | BZ9: =BZ11+BZ10 -> 1388 | CA9: =BW9+BX9+BY9+BZ9 -> 5370 | CB9: =CB11+CB10 -> 1603 | CC9: =CC11+CC10 -> 1475 | CD9: =CD11+CD10 -> 1665 | CE9: =CE11+CE10 -> 1723 | CF9: =CB9+CC9+CD9+CE9 -> 6466 | CG9: =CG11+CG10 -> 1660 | CH9: =CH11+CH10 -> 1385 | CI9: =CI11+CI10 -> 1718 | CJ9: 2056 | CK9: =CG9+CH9+CI9+CJ9 -> 6819 | CL9: 1002.9277 | CM9: -686.9981 | CN9: 349.55532 | CO9: 563.79383 | CP9: =CL9+CM9+CN9+CO9 -> 1229.2788 | CQ9: 641 | CR9: 176 | CS9: 846 | CT9: 1218 | CU9: =SUM(CQ9:CT9) -> 2881 | CV9: 908 | CW9: 1148 | CX9: 1284 | CY9: 1434 | CZ9: =SUM(CV9:CY9) -> 4774 | DA9: 1326 | DB9: 1479 | DC9: 1712 | DD9: 1598 | DE9: =SUM(DA9:DD9) -> 6115 | DF9: =DF20*DF7 -> 1550 | DG9: =DG20*DG7 -> 1897 | DH9: =DH20*DH7 -> 1818 | DI9: =DI20*DI7 -> 1988 | DJ9: =SUM(DF9:DI9) -> 7253 | DK9: =DK20*DK7 -> 2146 | DL9: =DL20*DL7 -> 2337 | DM9: =DM20*DM7 -> 2141.2269 | DN9: =DN20*DN7 -> 2037.9232 | DO9: =SUM(DK9:DN9) -> 8662.1501 | DP9: =DP20*DP7 -> 2378.8568 | DQ9: =DQ20*DQ7 -> 2595.7158 | DR9: =DR20*DR7 -> 2502.9031 | DS9: =DS20*DS7 -> 2588.8442 | DT9: =SUM(DP9:DS9) -> 10066.32 | DU9: =DU20*DU7 -> 11037.298 | DV9: =DV20*DV7 -> 11906.149
B10: Non-recurring (charges) / gains | BG10: 0 | BH10: 0 | BI10: 0 | BJ10: 0 | BK10: 0 | BL10: 0 | BM10: 0 | BN10: 0 | BO10: 0 | BP10: 0 | BQ10: 0 | BR10: 0 | BS10: 0 | BT10: 0 | BU10: 0 | BV10: =BR10+BS10+BT10+BU10 -> 0 | BW10: 0 | BX10: 0 | BY10: 0 | BZ10: 0 | CA10: =BW10+BX10+BY10+BZ10 -> 0 | CB10: 0 | CC10: 0 | CD10: 0 | CE10: 0 | CF10: =CB10+CC10+CD10+CE10 -> 0 | CG10: 0 | CH10: 0 | CI10: 0 | CJ10: 0 | CK10: =CG10+CH10+CI10+CJ10 -> 0 | CL10: -2.371735 | CM10: -7.0771482 | CN10: -6.2017299 | CO10: -10.008453 | CP10: =SUM(CL10:CO10) -> -25.659066 | CQ10: 0 | CR10: 0 | CS10: 0 | CT10: 0 | CU10: =SUM(CQ10:CT10) -> 0 | CV10: 0 | CW10: 0 | CX10: 0 | CY10: 0 | CZ10: =SUM(CV10:CY10) -> 0 | DA10: 0 | DB10: 0 | DC10: 0 | DD10: 0 | DE10: =SUM(DA10:DD10) -> 0 | DF10: 0 | DG10: 0 | DH10: 0 | DI10: 0 | DJ10: =SUM(DF10:DI10) -> 0 | DK10: 0 | DL10: 0 | DM10: 0 | DN10: 0 | DO10: =SUM(DG10:DJ10) -> 0 | DP10: 0 | DQ10: 0 | DR10: 0 | DS10: 0 | DT10: =SUM(DL10:DO10) -> 0 | DU10: =SUM(DI10:DT10) -> 0 | DV10: =SUM(DJ10:DU10) -> 0
B11: EBIT-adjusted | H11: =H9-H10 -> 2060 | I11: =I9-I10 -> 2148 | N11: =N9-N10 -> 2237.9 | S11: =S9-S10 -> 2525 | T11: =T9-T10 -> 627 | U11: =U9-U10 -> 728 | V11: =V9-V10 -> 689 | W11: =W9-W10 -> 758 | X11: =X9-X10 -> 2802 | Y11: =Y9-Y10 -> 699 | Z11: =Z9-Z10 -> 828 | ... BC11: =BC9-BC10 -> 936 | BD11: 1067 | BE11: 1091 | BF11: 1251 | BG11: =BG9-BG10 -> 4345 | BH11: 1115 | BI11: 1197 | BJ11: 1264 | BK11: 1397 | BL11: =BL9-BL10 -> 4973 | BM11: 1314 | BN11: 1269 | BO11: 1353 | BP11: 1571 | BQ11: =BQ9-BQ10 -> 5507 | BR11: 1524 | BS11: 1348 | BT11: 1494 | BU11: 1749 | BV11: =BR11+BS11+BT11+BU11 -> 6115 | BW11: 1273 | BX11: 1374 | BY11: 1335 | BZ11: 1388 | CA11: =BW11+BX11+BY11+BZ11 -> 5370 | CB11: 1603 | CC11: 1475 | CD11: 1665 | CE11: 1723 | CF11: =CB11+CC11+CD11+CE11 -> 6466 | CG11: 1660 | CH11: 1385 | CI11: 1718 | CJ11: 2056 | CK11: =CG11+CH11+CI11+CJ11 -> 6819 | CL11: 1005.2995 | CM11: -679.92095 | CN11: 355.75705 | CO11: 573.80228 | CP11: =CL11+CM11+CN11+CO11 -> 1254.9379 | CQ11: =CQ9-CQ10 -> 641 | CR11: =CR9-CR10 -> 176 | CS11: =CS9-CS10 -> 846 | CT11: =CT9-CT10 -> 1218 | CU11: =SUM(CQ11:CT11) -> 2881 | CV11: =CV9-CV10 -> 908 | CW11: =CW9-CW10 -> 1148 | CX11: =CX9-CX10 -> 1284 | CY11: =CY9-CY10 -> 1434 | CZ11: =SUM(CV11:CY11) -> 4774 | DA11: =DA9-DA10 -> 1326 | DB11: =DB9-DB10 -> 1479 | DC11: =DC9-DC10 -> 1712 | DD11: =DD9-DD10 -> 1598 | DE11: =SUM(DA11:DD11) -> 6115 | DF11: =DF9-DF10 -> 1550 | DG11: =DG9-DG10 -> 1897 | DH11: =DH9-DH10 -> 1818 | DI11: =DI9-DI10 -> 1988 | DJ11: =SUM(DF11:DI11) -> 7253 | DK11: =DK9-DK10 -> 2146 | DL11: =DL9-DL10 -> 2337 | DM11: =DM9-DM10 -> 2141.2269 | DN11: =DN9-DN10 -> 2037.9232 | DO11: =SUM(DK11:DN11) -> 8662.1501 | DP11: =DP9-DP10 -> 2378.8568 | DQ11: =DQ9-DQ10 -> 2595.7158 | DR11: =DR9-DR10 -> 2502.9031 | DS11: =DS9-DS10 -> 2588.8442 | DT11: =SUM(DP11:DS11) -> 10066.32 | DU11: =DU9+DU10 -> 11037.298 | DV11: =DV9+DV10 -> 11906.149
B13: Revenue growth factors
B14: Organic | AG14: 0.08 | AH14: =Aerospace!AH17-Aerospace!AH16-Aerospace!AH15 -> 0.13307222 | AI14: 0 | AJ14: 0 | AK14: 0 | AL14: 0 | AM14: =Aerospace!AM17-Aerospace!AM16-Aerospace!AM15 -> -0.019700458 | AN14: 0.03 | AO14: 0.03 | AP14: 0.03 | AQ14: 0.03 | AR14: =Aerospace!AR17-Aerospace!AR16-Aerospace!AR15 -> -0.052389967 | AS14: 0 | AT14: 0 | AU14: 0 | AV14: 0 | AW14: =(1100+200-100)/AR7 -> 0.068108292 | BB14: =(800+400)/AW7 -> 0.063630097 | BC14: =BC17 -> 0.037415661 | BD14: =BD17 -> 0.092276004 | BE14: 0.1 | BF14: 0.07 | BG14: =+SUMPRODUCT(BC14:BF14,AX$7:BA$7)/BB$7 -> 0.074611884 | BH14: 0.102 | BI14: 0.1 | BJ14: 0.042 | BK14: 0.05 | BL14: =+SUMPRODUCT(BH14:BK14,BC$7:BF$7)/BG$7 -> 0.072184565 | BM14: -0.01 | BN14: 0.04 | BO14: 0.053 | BP14: 0.05 | BQ14: =+SUMPRODUCT(BM14:BP14,BH$7:BK$7)/BL$7 -> 0.033722968 | BR14: 0.104 | BS14: 0.04 | BT14: 0.05 | BU14: 0.06 | BV14: =+SUMPRODUCT(BR14:BU14,BM$7:BP$7)/BQ$7 -> 0.062619764 | BW14: =6752/BR7-1 -> 0.07824976 | BX14: 0.003 | BY14: 0.08 | BZ14: 0.004 | CA14: =+SUMPRODUCT(BW14:BZ14,BR$7:BU$7)/BV$7 -> 0.039690823 | CB14: 0.06 | CC14: 0.13 | CD14: 0.12 | CE14: 0.21 | CF14: =+SUMPRODUCT(CB14:CE14,BW$7:BZ$7)/CA$7 -> 0.13098952 | CG14: =7961/7112-1 -> 0.1193757 | CH14: =7885/7413-1 -> 0.063671928 | CI14: =8086/7363-1 -> 0.098193671 | CJ14: =8941/8361-1 -> 0.069369693 | CK14: =+SUMPRODUCT(CG14:CJ14,CB$7:CE$7)/CF$7 -> 0.08665646 | CL14: =6882/7774-1 -> -0.11474145 | CM14: =4389/7831-1 -> -0.43953518 | CN14: =4913/8036-1 -> -0.38862618 | CO14: =5848/8866-1 -> -0.34040153 | CP14: =+SUMPRODUCT(CL14:CO14,CG$7:CJ$7)/CK$7 -> -0.32145242 | CQ14: =4992/6892-1 -> -0.27568195 | CR14: =4828/4372-1 -> 0.10430009 | CS14: =5408/4908-1 -> 0.10187449 | CT14: =6072/5847-1 -> 0.038481272 | CU14: =+SUMPRODUCT(CQ14:CT14,CL$7:CO$7)/CP$7 -> -0.032511922 | CV14: =5612/4991-1 -> 0.12442396 | CW14: =6146/4839-1 -> 0.27009713 | CX14: =6726/5398-1 -> 0.24601704 | CY14: =7645/6082-1 -> 0.25698783 | CZ14: =+SUMPRODUCT(CV14:CY14,CQ$7:CT$7)/CU$7 -> 0.22613236 | DA14: =6987/5604-1 -> 0.24678801 | DB14: =7858/6130-1 -> 0.28189233 | DC14: =8401/6710-1 -> 0.25201192 | DD14: =8510/7624-1 -> 0.11621196 | DE14: =+SUMPRODUCT(DA14:DD14,CV$7:CY$7)/CZ$7 -> 0.21821887 | DF14: =DF102 -> 0.1469127 | DG14: =DG102 -> 0.035917541 | DH14: =DH102 -> 0.056967262 | DI14: =DI102 -> 0.15584416 | DJ14: =+SUMPRODUCT(DF14:DI14,DA$7:DD$7)/DE$7 -> 0.09804027 | DK14: =DK102 -> 0.11398515 | DL14: =DL102 -> 0.23928702 | DM14: =DM102 -> 0.12555742 | DN14: =DN102 -> 0.07353882 | DO14: =+SUMPRODUCT(DK14:DN14,DF$7:DI$7)/DJ$7 -> 0.13489227 | DP14: =DP102 -> 0.13802689 | DQ14: =DQ102 -> 0.13040587 | DR14: =DR102 -> 0.12859414 | DS14: =DS102 -> 0.15470856 | DT14: =+SUMPRODUCT(DP14:DS14,DK$7:DN$7)/DO$7 -> 0.13814259 | DU14: =DU102 -> 0.085526392 | DV14: =DV102 -> 0.068933765
B15: Acquisitions/ divestitures | AG15: 0 | AI15: 0 | AJ15: 0 | AK15: 0 | AL15: 0 | AM15: =AVERAGE(AI15:AL15) -> 0 | AN15: 0.0088343379 | AO15: -0.0097138179 | AP15: -0.014711018 | AQ15: -0.011714222 | AS15: 0 | AT15: 0 | AU15: 0 | AV15: 0 | AW15: 0 | AX15: 0 | AY15: 0 | AZ15: 0 | BA15: 0 | BC15: 0 | BD15: 0 | BE15: 0.022 | BF15: =BF17-BF14 -> 0.05858972 | BG15: =+SUMPRODUCT(BC15:BF15,AX$7:BA$7)/BB$7 -> 0.021280984 | BH15: 0.043 | BI15: =((3/12)*1300)/BD7 -> 0.061286064 | BJ15: =((1/12)*1300)/BE7 -> 0.020196371 | BK15: 0 | BL15: =+SUMPRODUCT(BH15:BK15,BC$7:BF$7)/BG$7 -> 0.029734623 | BM15: 0 | BN15: 0 | BO15: 0 | BP15: 0 | BQ15: =+SUMPRODUCT(BM15:BP15,BH$7:BK$7)/BL$7 -> 0 | BR15: 0 | BS15: 0 | BT15: 0 | BU15: 0 | BV15: =+SUMPRODUCT(BR15:BU15,BM$7:BP$7)/BQ$7 -> 0 | BW15: 0 | BX15: 0 | BY15: 0 | BZ15: 0 | CA15: =+SUMPRODUCT(BW15:BZ15,BR$7:BU$7)/BV$7 -> 0 | CB15: 0 | CC15: 0 | CD15: 0 | CE15: 0 | CF15: =+SUMPRODUCT(CB15:CE15,BW$7:BZ$7)/CA$7 -> 0 | CG15: 0 | CH15: =(0-105)/CC7 -> -0.013964623 | CI15: =(25-117)/CD7 -> -0.012299465 | CJ15: =(0-95)/CE7 -> -0.011234626 | CK15: =+SUMPRODUCT(CG15:CJ15,CB$7:CE$7)/CF$7 -> -0.0095527857 | CL15: =(13-180)/CG7 -> -0.020995725 | CM15: =(0-46)/CH7 -> -0.0058397867 | CN15: =(0-73)/CI7 -> -0.0090023431 | CO15: =(0-70)/CJ7 -> -0.0078334825 | CP15: =+SUMPRODUCT(CL15:CO15,CG$7:CJ$7)/CK$7 -> -0.010828568 | CQ15: =(0-25)/CL7 -> -0.0036273941 | CR15: =(0-11)/CM7 -> -0.0025091241 | CS15: =(0-12)/CN7 -> -0.0024395202 | CT15: =(0-0)/CO7 -> 0 | CU15: =+SUMPRODUCT(CQ15:CT15,CL$7:CO$7)/CP$7 -> -0.0021776608 | CV15: =(0-0)/CQ7 -> 0 | CW15: =(0-0)/CR7 -> 0 | CX15: =(0-0)/CS7 -> 0 | CY15: 0 | CZ15: =+SUMPRODUCT(CV15:CY15,CQ$7:CT$7)/CU$7 -> 0 | DA15: =(0-0)/CV7 -> 0 | DB15: 0 | DC15: 0 | DD15: 0 | DE15: =+SUMPRODUCT(DA15:DD15,CV$7:CY$7)/CZ$7 -> 0 | DF15: 0 | DG15: 0 | DH15: 0 | DI15: 0 | DJ15: =+SUMPRODUCT(DF15:DI15,DA$7:DD$7)/DE$7 -> 0 | DK15: 0 | DL15: 0 | DM15: 0 | DN15: 0 | DO15: =+SUMPRODUCT(DK15:DN15,DF$7:DI$7)/DJ$7 -> 0 | DP15: 0 | DQ15: 0 | DR15: 0 | DS15: 0 | DT15: =+SUMPRODUCT(DP15:DS15,DK$7:DN$7)/DO$7 -> 0 | DU15: 0 | DV15: 0
B16: Currency | AG16: -0.013941212 | AH16: 0.01081267 | AI16: -0.019402314 | AJ16: -0.018985538 | AK16: -0.0073645414 | AL16: 0.018311695 | AM16: =AVERAGE(AI16:AL16) -> -0.0068601743 | AN16: 0.0088343379 | AO16: -0.0097138179 | AP16: -0.014711018 | AQ16: -0.011714222 | AR16: =AVERAGE(AN16:AQ16) -> -0.0068261801 | AS16: 0 | AT16: 0 | AU16: 0 | AV16: 0 | AW16: 0 | BG16: =+SUMPRODUCT(BC16:BF16,AX$7:BA$7)/BB$7 -> 0 | BH16: -0.006 | BL16: =+SUMPRODUCT(BH16:BK16,BC$7:BF$7)/BG$7 -> -0.0013894391 | BM16: -0.01 | BN16: -0.01 | BO16: 0 | BP16: 0 | BQ16: =+SUMPRODUCT(BM16:BP16,BH$7:BK$7)/BL$7 -> -0.0049470613 | BR16: 0 | BS16: 0 | BT16: 0 | BU16: 0.01 | BV16: =+SUMPRODUCT(BR16:BU16,BM$7:BP$7)/BQ$7 -> 0.0027306273 | BW16: 0.011 | BX16: 0 | BY16: 0.002 | BZ16: 0 | CA16: =+SUMPRODUCT(BW16:BZ16,BR$7:BU$7)/BV$7 -> 0.0031028941 | CB16: 0.006 | CC16: 0.003 | CD16: 0 | CE16: -0.004 | CF16: =+SUMPRODUCT(CB16:CE16,BW$7:BZ$7)/CA$7 -> 0.0011809129 | CG16: =-7/CB7 -> -0.00098425197 | CH16: =-8/CC7 -> -0.0010639713 | CI16: =-3/CD7 -> -0.00040106952 | CJ16: =-5/CE7 -> -0.00059129612 | CK16: =+SUMPRODUCT(CG16:CJ16,CB$7:CE$7)/CF$7 -> -0.00075244545 | CL16: =-2/CG7 -> -0.00025144581 | CM16: =-5/CH7 -> -0.00063475943 | CN16: =6/CI7 -> 0.00073991861 | CO16: =-1/CJ7 -> -0.00011190689 | CP16: =+SUMPRODUCT(CL16:CO16,CG$7:CJ$7)/CK$7 -> -6.0834651e-05 | CQ16: =10/CL7 -> 0.0014509576 | CR16: =12/CM7 -> 0.0027372263 | CS16: =-9/CN7 -> -0.0018296402 | CT16: =8/CO7 -> 0.001368223 | CU16: =+SUMPRODUCT(CQ16:CT16,CL$7:CO$7)/CP$7 -> 0.00095272661 | CV16: =(-9-1)/CQ7 -> -0.0020032051 | CW16: =-19/CR7 -> -0.0039256198 | CX16: =-22/CS7 -> -0.0040755835 | CY16: =(-29-1)/CT7 -> -0.0049342105 | CZ16: =+SUMPRODUCT(CV16:CY16,CQ$7:CT$7)/CU$7 -> -0.0038010324 | DA16: =(-6-1)/CV7 -> -0.0012493307 | DB16: =(2-3)/CW7 -> -0.00016321201 | DC16: =(8--5)/CX7 -> 0.0019388516 | DD16: =(10--9)/CY7 -> 0.0024950755 | DE16: =+SUMPRODUCT(DA16:DD16,CV$7:CY$7)/CZ$7 -> 0.00092130518 | DF16: 0 | DG16: 0 | DH16: 0 | DI16: 0 | DJ16: =+SUMPRODUCT(DF16:DI16,DA$7:DD$7)/DE$7 -> 0 | DK16: 0 | DL16: 0 | DM16: 0 | DN16: 0 | DO16: =+SUMPRODUCT(DK16:DN16,DF$7:DI$7)/DJ$7 -> 0 | DP16: 0 | DQ16: 0 | DR16: 0 | DS16: 0 | DT16: =+SUMPRODUCT(DP16:DS16,DK$7:DN$7)/DO$7 -> 0 | DU16: 0 | DV16: 0
B17: Total | I17: =I7/H7-1 -> -0.056727403 | N17: =N7/I7-1 -> 0.055666572 | S17: =S7/N7-1 -> 0.065981612 | X17: =X7/S7-1 -> 0.1007103 | Y17: =Y7/T7-1 -> 0.14651163 | Z17: =Z7/U7-1 -> 0.24094919 | AA17: =AA7/V7-1 -> 0.35333546 | AB17: =AB7/W7-1 -> 0.40758294 | AC17: =AC7/X7-1 -> 0.29207959 | AD17: =AD7/Y7-1 -> 0.25181107 | AE17: =AE7/Z7-1 -> 0.20691346 | ... BD17: =BD7/AY7-1 -> 0.092276004 | BE17: =SUM(BE14:BE16) -> 0.122 | BF17: =BF7/BA7-1 -> 0.12858972 | BG17: =SUM(BG14:BG16) -> 0.095892868 | BH17: =SUM(BH14:BH16) -> 0.139 | BI17: =SUM(BI14:BI16) -> 0.16128606 | BJ17: =SUM(BJ14:BJ16) -> 0.062196371 | BK17: =SUM(BK14:BK16) -> 0.05 | BL17: =SUM(BL14:BL16) -> 0.10052975 | BM17: =BM7/BH7-1 -> -0.017999308 | BN17: =SUM(BN14:BN16) -> 0.03 | BO17: =SUM(BO14:BO16) -> 0.053 | BP17: =SUM(BP14:BP16) -> 0.05 | BQ17: =SUM(BQ14:BQ16) -> 0.028775907 | BR17: =SUM(BR14:BR16) -> 0.104 | BS17: =SUM(BS14:BS16) -> 0.04 | BT17: =SUM(BT14:BT16) -> 0.05 | BU17: =SUM(BU14:BU16) -> 0.07 | ... DV17: =SUM(DV14:DV16) -> 0.068933765
B19: Operating income | CL19: Op margin now includes restructuring expense
B20: Operating margin | H20: =Aerospace!H9/Aerospace!H7 -> 0.18490261 | I20: =Aerospace!I9/Aerospace!I7 -> 0.20439623 | N20: =Aerospace!N9/Aerospace!N7 -> 0.20172165 | S20: =Aerospace!S9/Aerospace!S7 -> 0.2135126 | T20: =Aerospace!T9/Aerospace!T7 -> 0.20830565 | U20: =Aerospace!U9/Aerospace!U7 -> 0.22147855 | V20: =Aerospace!V9/Aerospace!V7 -> 0.21991701 | W20: =Aerospace!W9/Aerospace!W7 -> 0.21131865 | X20: =Aerospace!X9/Aerospace!X7 -> 0.21525697 | Y20: =Aerospace!Y9/Aerospace!Y7 -> 0.20254999 | Z20: =Aerospace!Z9/Aerospace!Z7 -> 0.20299093 | ... AW20: =Aerospace!AW9/Aerospace!AW7 -> 0.18622408 | AX20: =Aerospace!AX11/Aerospace!AX7 -> 0.17624208 | AY20: =Aerospace!AY11/Aerospace!AY7 -> 0.18990731 | AZ20: =Aerospace!AZ11/Aerospace!AZ7 -> 0.19326501 | BA20: =Aerospace!BA11/Aerospace!BA7 -> 0.19004939 | BB20: =Aerospace!BB11/Aerospace!BB7 -> 0.18740622 | BC20: =Aerospace!BC11/Aerospace!BC7 -> 0.18446985 | BD20: =Aerospace!BD11/Aerospace!BD7 -> 0.20120686 | BE20: =Aerospace!BE11/Aerospace!BE7 -> 0.20339299 | ... CK20: =Aerospace!CK11/Aerospace!CK7 -> 0.20741574 | CL20: =Aerospace!CL9/Aerospace!CL7 -> 0.14552057 | CM20: =Aerospace!CM9/Aerospace!CM7 -> -0.15670577 | CN20: =Aerospace!CN9/Aerospace!CN7 -> 0.071062272 | CO20: =Aerospace!CO9/Aerospace!CO7 -> 0.096424462 | CP20: =Aerospace!CP9/Aerospace!CP7 -> 0.055769839 | CQ20: =Aerospace!CQ9/Aerospace!CQ7 -> 0.12840545 | CR20: =Aerospace!CR9/Aerospace!CR7 -> 0.036363636 | CS20: =Aerospace!CS9/Aerospace!CS7 -> 0.15672471 | ... DE20: =Aerospace!DE9/Aerospace!DE7 -> 0.19247718 | DF20: =SEG!DF89 -> 0.1919267 | DG20: =SEG!DG89 -> 0.23069439 | DH20: =SEG!DH89 -> 0.20328749 | DI20: =SEG!DI89 -> 0.20123494 | DJ20: =Aerospace!DJ9/Aerospace!DJ7 -> 0.20651462 | DK20: =SEG!DK89 -> 0.23841795 | DL20: =SEG!DL89 -> 0.23022362 | DM20: =SEG!DM89 -> 0.2127217 | DN20: =SEG!DN89 -> 0.19215738 | DO20: =SEG!DO89 -> 0.21751435 | DP20: =SEG!DP89 -> 0.23223358 | DQ20: =SEG!DQ89 -> 0.22621109 | DR20: =SEG!DR89 -> 0.22032073 | ... DV20: =SEG!DV89 -> 0.22638396
B24: Growth rates
B25: Yr/Yr Growth Rates
B26: Revenue | I26: =Aerospace!I7/Aerospace!H7-1 -> -0.056727403 | N26: =Aerospace!N7/Aerospace!I7-1 -> 0.055666572 | S26: =Aerospace!S7/Aerospace!N7-1 -> 0.065981612 | X26: =Aerospace!X7/Aerospace!S7-1 -> 0.1007103 | Y26: =Aerospace!Y7/Aerospace!T7-1 -> 0.14651163 | Z26: =Aerospace!Z7/Aerospace!U7-1 -> 0.24094919 | AA26: =Aerospace!AA7/Aerospace!V7-1 -> 0.35333546 | AB26: =Aerospace!AB7/Aerospace!W7-1 -> 0.40758294 | AC26: =Aerospace!AC7/Aerospace!X7-1 -> 0.29207959 | AD26: =Aerospace!AD7/Aerospace!Y7-1 -> 0.25181107 | AE26: =Aerospace!AE7/Aerospace!Z7-1 -> 0.20691346 | ... DN26: =Aerospace!DN7/Aerospace!DI7-1 -> 0.07353882 | DO26: =Aerospace!DO7/Aerospace!DF7-1 -> 3.9310736 | DP26: =Aerospace!DP7/Aerospace!DK7-1 -> 0.13802689 | DQ26: =Aerospace!DQ7/Aerospace!DL7-1 -> 0.13040587 | DR26: =Aerospace!DR7/Aerospace!DM7-1 -> 0.12859414 | DS26: =Aerospace!DS7/Aerospace!DN7-1 -> 0.15470856 | DT26: =Aerospace!DT7/Aerospace!DK7-1 -> 4.0355128 | DU26: =Aerospace!DU7/Aerospace!DH7-1 -> 4.5016331 | DV26: =Aerospace!DV7/Aerospace!DI7-1 -> 4.3236888
B27: EBIT | I27: =Aerospace!I9/Aerospace!H9-1 -> 0.042718447 | N27: =Aerospace!N9/Aerospace!I9-1 -> 0.041852886 | S27: =Aerospace!S9/Aerospace!N9-1 -> 0.12828991 | X27: =Aerospace!X9/Aerospace!S9-1 -> 0.10970297 | Y27: =Aerospace!Y9/Aerospace!T9-1 -> 0.11483254 | Z27: =Aerospace!Z9/Aerospace!U9-1 -> 0.13736264 | AA27: =Aerospace!AA9/Aerospace!V9-1 -> 0.068214804 | AB27: =Aerospace!AB9/Aerospace!W9-1 -> 0.2651715 | AC27: =Aerospace!AC9/Aerospace!X9-1 -> 0.14989293 | AD27: =Aerospace!AD9/Aerospace!Y9-1 -> 0.10872675 | AE27: =Aerospace!AE9/Aerospace!Z9-1 -> 0.10386473 | ... DN27: =Aerospace!DN9/Aerospace!DI9-1 -> 0.025112274 | DO27: =Aerospace!DO9/Aerospace!DF9-1 -> 4.5884839 | DP27: =Aerospace!DP9/Aerospace!DK9-1 -> 0.10850738 | DQ27: =Aerospace!DQ9/Aerospace!DL9-1 -> 0.11070421 | DR27: =Aerospace!DR9/Aerospace!DM9-1 -> 0.16891075 | DS27: =Aerospace!DS9/Aerospace!DN9-1 -> 0.27033453 | DT27: =Aerospace!DT9/Aerospace!DK9-1 -> 3.6907362 | DU27: =Aerospace!DU9/Aerospace!DH9-1 -> 5.0711211 | DV27: =Aerospace!DV9/Aerospace!DI9-1 -> 4.9890084
B29: Qtr/Qtr Growth Rates
B30: Revenue | U30: =Aerospace!U7/Aerospace!T7-1 -> 0.092026578 | V30: =Aerospace!V7/Aerospace!U7-1 -> -0.046851232 | W30: =Aerospace!W7/Aerospace!V7-1 -> 0.14490903 | Y30: =Aerospace!Y7/Aerospace!W7-1 -> -0.037914692 | Z30: =Aerospace!Z7/Aerospace!Y7-1 -> 0.18197624 | AA30: =Aerospace!AA7/Aerospace!Z7-1 -> 0.039470458 | AB30: =Aerospace!AB7/Aerospace!AA7-1 -> 0.19080189 | AD30: =Aerospace!AD7/Aerospace!AB7-1 -> -0.14438503 | AE30: =Aerospace!AE7/Aerospace!AD7-1 -> 0.13958333 | AF30: =Aerospace!AF7/Aerospace!AE7-1 -> -0.01665651 | AG30: =Aerospace!AG7/Aerospace!AF7-1 -> 0.064862632 | AI30: =Aerospace!AI7/Aerospace!AG7-1 -> -0.06556741 | AJ30: =Aerospace!AJ7/Aerospace!AI7-1 -> -0.041104422 | AK30: =Aerospace!AK7/Aerospace!AJ7-1 -> -0.016670275 | AL30: =Aerospace!AL7/Aerospace!AK7-1 -> 0.045794804 | AN30: =Aerospace!AN7/Aerospace!AL7-1 -> -0.12315789 | AO30: =Aerospace!AO7/Aerospace!AN7-1 -> 0.022569028 | AP30: =Aerospace!AP7/Aerospace!AO7-1 -> 0.030993191 | AQ30: =Aerospace!AQ7/Aerospace!AP7-1 -> 0.094056024 | AS30: =Aerospace!AS7/Aerospace!AQ7-1 -> -0.090757702 | AT30: =Aerospace!AT7/Aerospace!AS7-1 -> 0.083333333 | AU30: =Aerospace!AU7/Aerospace!AT7-1 -> 0.021766695 | AV30: =Aerospace!AV7/Aerospace!AU7-1 -> 0.018407446 | AX30: =Aerospace!AX7/Aerospace!AV7-1 -> -0.0067018684 | AY30: =Aerospace!AY7/Aerospace!AX7-1 -> -0.007360458 | AZ30: =Aerospace!AZ7/Aerospace!AY7-1 -> -0.015242019 | BA30: =Aerospace!BA7/Aerospace!AZ7-1 -> 0.14348463 | BC30: =Aerospace!BC7/Aerospace!BA7-1 -> -0.071885861 | BD30: =Aerospace!BD7/Aerospace!BC7-1 -> 0.045132046 | BE30: =Aerospace!BE7/Aerospace!BD7-1 -> 0.011502923 | BF30: =Aerospace!BF7/Aerospace!BE7-1 -> 0.150261 | BH30: =Aerospace!BH7/Aerospace!BF7-1 -> -0.063533225 | BI30: =Aerospace!BI7/Aerospace!BH7-1 -> 0.053997923 | BJ30: =Aerospace!BJ7/Aerospace!BI7-1 -> -0.064367816 | BK30: =Aerospace!BK7/Aerospace!BJ7-1 -> 0.12741313 | BM30: =Aerospace!BM7/Aerospace!BK7-1 -> -0.11674969 | BN30: =Aerospace!BN7/Aerospace!BM7-1 -> 0.10186817 | BO30: =Aerospace!BO7/Aerospace!BN7-1 -> -0.040147153 | BP30: =Aerospace!BP7/Aerospace!BO7-1 -> 0.12214631 | BR30: =Aerospace!BR7/Aerospace!BP7-1 -> -0.07009207 | BS30: =Aerospace!BS7/Aerospace!BR7-1 -> 0.039763654 | BT30: =Aerospace!BT7/Aerospace!BS7-1 -> -0.032406696 | BU30: =Aerospace!BU7/Aerospace!BT7-1 -> 0.14079365 | BW30: =Aerospace!BW7/Aerospace!BU7-1 -> -0.071518019 | BX30: =Aerospace!BX7/Aerospace!BW7-1 -> -0.0058444478 | BY30: =Aerospace!BY7/Aerospace!BX7-1 -> 0.0093457944 | BZ30: =Aerospace!BZ7/Aerospace!BY7-1 -> 0.046893668 | CB30: =Aerospace!CB7/Aerospace!BZ7-1 -> 0.014550642 | CC30: =Aerospace!CC7/Aerospace!CB7-1 -> 0.057227222 | CD30: =Aerospace!CD7/Aerospace!CC7-1 -> -0.00518686 | CE30: =Aerospace!CE7/Aerospace!CD7-1 -> 0.13048128 | CG30: =Aerospace!CG7/Aerospace!CE7-1 -> -0.059366131 | CH30: =Aerospace!CH7/Aerospace!CG7-1 -> -0.0096806638 | CI30: =Aerospace!CI7/Aerospace!CH7-1 -> 0.029452837 | CJ30: =Aerospace!CJ7/Aerospace!CI7-1 -> 0.10198545 | CL30: =Aerospace!CL7/Aerospace!CJ7-1 -> -0.22873769 | CM30: =Aerospace!CM7/Aerospace!CL7-1 -> -0.36390017 | CN30: =Aerospace!CN7/Aerospace!CM7-1 -> 0.12203467 | CO30: =Aerospace!CO7/Aerospace!CN7-1 -> 0.18865623 | CQ30: =Aerospace!CQ7/Aerospace!CO7-1 -> -0.14622884 | CR30: =Aerospace!CR7/Aerospace!CQ7-1 -> -0.030448718 | CS30: =Aerospace!CS7/Aerospace!CR7-1 -> 0.11528926 | CT30: =Aerospace!CT7/Aerospace!CS7-1 -> 0.12634309 | CV30: =Aerospace!CV7/Aerospace!CT7-1 -> -0.078453947 | CW30: =Aerospace!CW7/Aerospace!CV7-1 -> 0.093521328 | CX30: =Aerospace!CX7/Aerospace!CW7-1 -> 0.094336543 | CY30: =Aerospace!CY7/Aerospace!CX7-1 -> 0.13571961 | DA30: =Aerospace!DA7/Aerospace!CY7-1 -> -0.08325673 | DB30: =Aerospace!DB7/Aerospace!DA7-1 -> 0.12591319 | DC30: =Aerospace!DC7/Aerospace!DB7-1 -> 0.069847328 | DD30: =Aerospace!DD7/Aerospace!DC7-1 -> 0.013200143 | DF30: =Aerospace!DF7/Aerospace!DD7-1 -> -0.052112676 | DG30: =Aerospace!DG7/Aerospace!DE7-1 -> -0.74117092 | DH30: =Aerospace!DH7/Aerospace!DG7-1 -> 0.087559285 | DI30: =Aerospace!DI7/Aerospace!DH7-1 -> 0.10466286 | DK30: =Aerospace!DK7/Aerospace!DI7-1 -> -0.088875392 | DL30: =Aerospace!DL7/Aerospace!DK7-1 -> 0.12776358 | DM30: =Aerospace!DM7/Aerospace!DL7-1 -> -0.008387351 | DN30: =Aerospace!DN7/Aerospace!DM7-1 -> 0.053609925 | DP30: =Aerospace!DP7/Aerospace!DN7-1 -> -0.034143637 | DQ30: =Aerospace!DQ7/Aerospace!DP7-1 -> 0.1202113 | DR30: =Aerospace!DR7/Aerospace!DQ7-1 -> -0.0099766357 | DS30: =Aerospace!DS7/Aerospace!DR7-1 -> 0.077989293
