Workbook
Name AA.AlternatePriceSourceStartPeriod: "Q1-2019"
Name AA.CIK: "1045810"
Name AA.ColorizerVersion: "2.0.4.0"
Name AA.CompareQuarters.LatestMRQ: "Q2-2025"
Name AA.CSIN: "A7FLSL0150"
Name AA.CurationVersion: "2023.11.1.0"
Name AA.DBMacroVersion: "1.0.13.0"
Name AA.FreeCashFlow: "TRUE"
Name AA.GuidanceAnalysisNonGaapGrossProfitVersion: "1.0.0.0"
Name AA.GuidanceAnalysisRevenueVersion: "1.0.0.0"
Name AA.HardcodeChecker.LatestMRQ: "Q3-2020"
Name AA.ModelChecks.LatestMRQ: "Q3-2022"
Name AA.ModelChecks.LatestVersionNumber: "2.38.25.0"
Name AA.ModelColorScheme: "Classic"
Name AA.ModelVersion: "Q1-2027.23"
Name AA.NonLibraryWideCurationVersion: "4"
Name AA.PartialUpdate.BsAvailable: "TRUE"
Name AA.PartialUpdate.CfsAvailable: "TRUE"
Name AA.PartialUpdate.IsAvailable: "TRUE"
Name AA.PeriodLayout: "QFY"
Name AA.PersonalMacro.VersionNumber: ""
Name AA.RowNameEnforcerVersion: "2023.11.1.0"
Name AA.SessionToUploadId: ""
Name AA.StartWorkModelVersion: "Q1-2027.22"
Name AA.StartWorkType: ""
Name AA.SubyearType: "Q"
Name AA.TemplateUpgradeAttempted: "TRUE"
Name AA.TemplateVersion: "7.5.4.0"
Name AA.UpdateType: "Regular"
Name AA.VerifyUnitsAtModelVersion: "Q2-2019.21"
Name AS_KPI_1_Rpos: Model!$224:$224
Name AS_KPI_2_TotalFutureUnconditionalPurchaseCommitments: Model!$268:$268
Name AS_KPI_3_SalesToLargestCustomerAsAPercentOfTotalSales: Model!$271:$271
Name AS_KPI_4_SalesToSecondLargestCustomerAsAPercentOfTotalSales: Model!$272:$272
Name AS_KPI_5_SalesToThirdLargestCustomerAsAPercentOfTotalSales: Model!$273:$273
Name EC_CEO_BasePay: 'Exec Comp'!$7:$7
Name EC_CEO_EquityComp_Percent: 'Exec Comp'!$12:$12
Name EC_CEO_SharesOwned: 'Exec Comp'!$38:$38
Name EC_CEO_TotalComp: 'Exec Comp'!$11:$11
Name EC_CFO_BasePay: 'Exec Comp'!$40:$40
Name EC_CFO_EquityComp_Percent: 'Exec Comp'!$45:$45
Name EC_CFO_SharesOwned: 'Exec Comp'!$49:$49
Name EC_CFO_TotalComp: 'Exec Comp'!$44:$44
Name EC_Director_Compensation_Cash: 'Exec Comp'!$75:$75
Name EC_Director_Compensation_Total: 'Exec Comp'!$106:$106
Name EC_Directors_Current: 'Exec Comp'!$52:$52
Name EC_Directors_Current_Diverse: 'Exec Comp'!$55:$55
Name EC_Directors_Current_Female: 'Exec Comp'!$54:$54
Name EC_Directors_Current_Independent: 'Exec Comp'!$53:$53
Name EC_Directors_Nominees: 'Exec Comp'!$57:$57
Name EC_Directors_Nominees_Independent: 'Exec Comp'!$58:$58
Name EC_OperatingIncome_Target_NONGAAP: 'Exec Comp'!$121:$121
Name EC_Revenue_Target: 'Exec Comp'!$116:$116
Name FP.DataSource: 'Front Page'!$H$16
Name FP.DataSourceName: 'Front Page'!$H$15
Name FP.DataSourceName: 'Front Page'!$H$15
Name FP.Disclaimer: 'Front Page'!$C$22
Name FP.LastPrice: 'Front Page'!$H$20
Name FP.LastPrice: 'Front Page'!$H$20
Name FP.LastPriceDate: 'Front Page'!$F$20

Sheet Front Page
M6: Please contact this email for any model-specific questions:
M7: person@example.com
C9: Company Model: | H9: =Model!A1 -> Company1915 Company0697
C11: Updated: | H11: =OFFSET('Update Log'!$C$10,1,0,1,1) -> 46162
M12: Comments on Model:
C13: For: | H13: =OFFSET('Update Log'!$E$10,1,0,1,1) -> Quarterly (Earnings Report) | M13: On August 26, 2024, the Board of Directors approved an additional $50.0 billion in share repurchase authorization, without expiration. 'On, May 21, 2021, The company announced a 4-for-1 stock split. The model was adjusted for the split on July 20, 2021' 'Starting with the first quarter of fiscal 2021, the company's reportable segments have changed to “Graphics” and “Compute & Networking.” During the third quarter, Company1915 announced a definitive agreement to acquire Arm Limited from Company2574 Capital Limited and SVF Holdco (UK) Limited in a transaction valued at $40 billion. The transaction -- which is expected to be immediately accretive to Company1915’s non-GAAP gross margin and non-GAAP earnings per share -- is expected to close in the first quarter of calendar 2022.
C15: Consensus Data and Real-Time Stock Price: | H15: Bloomberg
H16: =IF(FP.DataSourceName="Bloomberg",1,IF(FP.DataSourceName="Capital IQ",2,IF(FP.DataSourceName="FactSet",3,IF(FP.DataSourceName="Refinitiv",4)))) -> 1
C18: Real-Time Stock Price: | H18: OFF
C20: Stock Price Override: | F20: 46175 | H20: 222.82
C22: DISCLAIMER Access to and use of this model, including the data contained herein (this "Model") is subject to Company2747, Inc.'s (a successor entity to Source Financial Modeling Company0697) ("Company") Terms of Use that you accepted prior to accessing this Model, the applicable Service Agreement between the Company and you (or a corporate entity that has authorized you to access and use this Model on its behalf in accordance with the terms of such Service Agreement) or other similar agreement between you and the Company. BY CONTINUING TO ACCESS OR USE THIS MODEL, YOU EXPRESSLY AGREE TO THE TERMS AND CONDITIONS OF SUCH AGREEMENTS. The Company and certain of its licensors have exclusive proprietary rights in this Model. This Model is being provided for internal use only. Unless prior written consent by the Company and its licensors has been provided to you, you may not distribute or otherwise furnish this Model to any third party, nor use or permit anyone to use this Model for any unlawful or unauthorized purpose. IF YOU HAVE UNLAWFULLY OBTAINED, OR ARE NOT AUTHORIZED TO USE THIS MODEL, YOU ARE OBLIGATED TO PROMPTLY: (I) RETURN THIS MODEL (AND ANY DERIVATIVE WORKS ARISING FROM OR RELATING THERETO) TO THE AUTHORIZED USER OF THIS MODEL; (II) PROVIDE NOTICE TO THE COMPANY AT person@example.com OF SUCH UNLAWFUL OR UNAUTHORIZED ACCESS AND USE; AND, (III) CERTIFY THAT YOU HAVE DESTROYED THIS MODEL (AND ANY DERIVATIVE WORKS ARISING FROM OR RELATING THERETO) AND ANY COPIES FROM YOUR SYSTEMS SO AS TO ENSURE THEY ARE INCAPABLE OF RETRIEVAL. A portion of the data contained in this Model may be powered by third party contributors and their respective licensors, or derived from data provided by such contributors, including (but not limited to): (i) QuoteMedia Inc.: A portion of the market data is powered by Quotemedia.com. All rights reserved. Data delayed 15 minutes unless otherwise indicated; (ii) S&P Global Market Intelligence LLC: Copyright (c) {{YEAR}} S&P Global Market Intelligence LLC (and its affiliates as applicable). All rights reserved. Reproduction of any information, opinions, views, data or material, including ratings ("Content") in any form is prohibited except with the prior written permission of the relevant party. Such party, its affiliates and suppliers ("Content Providers") do not guarantee the accuracy, adequacy, completeness, timeliness or availability of any Content and are not responsible for any errors or omissions (negligent or otherwise), regardless of the cause, or for the results obtained from the use of such Content. In no event shall Content Providers be liable for any damages, costs, expenses, legal fees, or losses (including lost income or lost profit and opportunity costs) in connection with any use of the Content. A reference to a particular investment or security, a rating or any observation concerning an investment that is part of the Content is not a recommendation to buy, sell or hold such investment or security, does not address the suitability of an investment or security and should not be relied on as investment advice. Credit ratings are statements of opinions and are not statements of fact; and, (iii) Refinitiv Canada Holdings Limited: A portion of the information may be provided by or derived from data provided by Refinitiv. By accessing or using this Model (including any portion of the data contained herein) you expressly represent that such access or use does not constitute a violation of any applicable law or regulation to which you or the securities are subject. This Model does not constitute investment advice by the Company or any of its licensors. Reference to a particular investment or security, credit rating or any observation concerning a security or investment in this Model is not a recommendation or solicitation to buy, sell or hold such investment or security or make any other investment decisions. For greater certainty, any forecasts or forward-looking information expressed herein are for illustrative purposes only and do not purport to express any view on what may transpire. Neither the Company nor any of its licensors have performed company-specific research on any projected information, as such, it is your responsibility to express your own views on projected results. This Model does not guarantee future performance and undue reliance should not be placed on such. You are solely responsible for evaluating the merits and risks of any investment based on your own business and financial expertise, the business and financial expertise of professional advisors with whom you have consulted, your financial situation and risk tolerance. Neither the Company, nor any of its licensors, undertake any liability with respect to your reliance on this Model. This Model is a quantitative tool with no investment views. The Company and its respective directors, officers, employees, agents, contractors, and affiliates may hold long or short positions in the security to which this Model relates, based on their personal views, and may initiate or close out any positions in such security at any time without any notice. THIS MODEL IS PROVIDED "AS IS" AND ON AN "AS AVAILABLE" BASIS ONLY, WITHOUT WARRANTIES OR CONDITIONS OF ANY KIND. NEITHER THE COMPANY NOR ANY OF ITS LICENSORS NOR THEIR RESPECTIVE AFFILIATES OR SUPPLIERS HAVE LIABILITY FOR THE ACCURACY, TIMELINESS OR COMPLETENESS OF THIS MODEL, OR FOR DELAYS, INTERRUPTIONS OR OMISSIONS HEREIN, NOR FOR ANY LOST PROFITS, INDIRECT, SPECIAL OR CONSEQUENTIAL DAMAGES. Access to data in this Model that is sourced from third party contributors is subject to termination in the event that any agreement between the Company and such third party contributors terminates for any reason. Copyright 2023 Company2747. All rights reserved.

Sheet Model
A1: Company1915 Company0697
A2: =CHOOSE(MO.DataSourceIndex,MO.Ticker.Bloomberg,MO.Ticker.CapIQ,MO.Ticker.FactSet,MO.Ticker.Thomson) -> Ticker0027 US | C2: =EOMONTH(C4,-12) -> 39478 | AA2: Restated | AB2: Restated | AC2: Restated | AD2: Restated | AE2: Restated
A3: =HP.TradeCurrency -> USD | B3: =IF(MO.RealTime="OFF",MO.LastPriceHardcoded,MO.LastPriceFormula) -> 222.82 | C3: =C4-C2 -> 360 | D3: =D4-C4 -> 371 | E3: =E4-D4 -> 364 | F3: =F4-E4 -> 364 | G3: =G4-F4 -> 91 | H3: =H4-G4 -> 91 | I3: =I4-H4 -> 91 | J3: =J4-I4 -> 91 | K3: =K4-F4 -> 364 | L3: =L4-K4 -> 91 | M3: =M4-L4 -> 91 | N3: =N4-M4 -> 91 | O3: =O4-N4 -> 91 | P3: =P4-K4 -> 364 | Q3: =Q4-P4 -> 91 | R3: =R4-Q4 -> 91 | S3: =S4-R4 -> 91 | T3: =T4-S4 -> 91 | U3: =U4-P4 -> 364 | V3: =V4-U4 -> 91 | W3: =W4-V4 -> 91 | X3: =X4-W4 -> 91 | Y3: =Y4-X4 -> 98 | Z3: =Z4-U4 -> 371 | AA3: =AA4-Z4 -> 91 | AB3: =AB4-AA4 -> 91 | AC3: =AC4-AB4 -> 91 | AD3: =AD4-AC4 -> 91 | AE3: =AE4-Z4 -> 364 | AF3: =AF4-AE4 -> 91 | AG3: =AG4-AF4 -> 91 | AH3: =AH4-AG4 -> 91 | AI3: =AI4-AH4 -> 91 | AJ3: =AJ4-AE4 -> 364 | AK3: =AK4-AJ4 -> 91 | AL3: =AL4-AK4 -> 91 | AM3: =AM4-AL4 -> 91 | AN3: =AN4-AM4 -> 91 | AO3: =AO4-AJ4 -> 364 | AP3: =AP4-AO4 -> 91 | AQ3: =AQ4-AP4 -> 91 | AR3: =AR4-AQ4 -> 91 | AS3: =AS4-AR4 -> 91 | AT3: =AT4-AO4 -> 364 | AU3: =AU4-AT4 -> 91 | AV3: =AV4-AU4 -> 91 | AW3: =AW4-AV4 -> 91 | AX3: =AX4-AW4 -> 98 | AY3: =AY4-AT4 -> 371 | AZ3: =AZ4-AY4 -> 91 | BA3: =BA4-AZ4 -> 91 | BB3: =BB4-BA4 -> 91 | BC3: =BC4-BB4 -> 91 | BD3: =BD4-AY4 -> 364 | BE3: =BE4-BD4 -> 91 | BF3: =BF4-BE4 -> 91 | BG3: =BG4-BF4 -> 91 | BH3: =BH4-BG4 -> 91 | BI3: =BI4-BD4 -> 364 | BJ3: =BJ4-BI4 -> 91 | BK3: =BK4-BJ4 -> 91 | BL3: =BL4-BK4 -> 91 | BM3: =BM4-BL4 -> 91 | BN3: =BN4-BI4 -> 364 | BO3: =BO4-BN4 -> 91 | BP3: =BP4-BO4 -> 91 | BQ3: =BQ4-BP4 -> 91 | BR3: =BR4-BQ4 -> 91 | BS3: =BS4-BN4 -> 364 | BT3: =BT4-BS4 -> 91 | BU3: =BU4-BT4 -> 91 | BV3: =BV4-BU4 -> 91 | BW3: =BW4-BV4 -> 91 | BX3: =BX4-BS4 -> 364 | BY3: =BY4-BX4 -> 91 | BZ3: =BZ4-BY4 -> 91 | CA3: =CA4-BZ4 -> 92 | CB3: =CB4-CA4 -> 97 | CC3: =CC4-BX4 -> 371 | CD3: =CD4-CC4 -> 89 | CE3: =CE4-CD4 -> 91 | CF3: =CF4-CE4 -> 92 | CG3: =CG4-CF4 -> 93 | CH3: =CH4-CC4 -> 365 | CI3: =CI4-CH4 -> 366 | CJ3: =CJ4-CI4 -> 365 | CK3: =CK4-CJ4 -> 365
A4: =FP.DataSourceName -> Bloomberg | B4: =IF(AND(MO.RealTimeStockPriceToggle,MO.LastPriceFormula<>"N/A"),"ON","OFF") -> OFF | C4: 39838 | D4: 40209 | E4: 40573 | F4: 40937 | G4: 41028 | H4: 41119 | I4: 41210 | J4: =K4 -> 41301 | K4: 41301 | L4: 41392 | M4: 41483 | N4: 41574 | O4: =P4 -> 41665 | P4: 41665 | Q4: 41756 | R4: 41847 | S4: 41938 | T4: =U4 -> 42029 | U4: 42029 | V4: 42120 | W4: 42211 | X4: 42302 | Y4: =Z4 -> 42400 | Z4: 42400 | AA4: 42491 | AB4: 42582 | AC4: 42673 | AD4: =AE4 -> 42764 | AE4: 42764 | AF4: 42855 | AG4: 42946 | AH4: 43037 | AI4: =AJ4 -> 43128 | AJ4: 43128 | AK4: 43219 | AL4: 43310 | AM4: 43401 | AN4: =AO4 -> 43492 | AO4: 43492 | AP4: 43583 | AQ4: 43674 | AR4: 43765 | AS4: =AT4 -> 43856 | AT4: 43856 | AU4: 43947 | AV4: 44038 | AW4: 44129 | AX4: =AY4 -> 44227 | AY4: 44227 | AZ4: 44318 | BA4: 44409 | BB4: 44500 | BC4: =BD4 -> 44591 | BD4: 44591 | BE4: 44682 | BF4: 44773 | BG4: 44864 | BH4: =BI4 -> 44955 | BI4: 44955 | BJ4: 45046 | BK4: 45137 | BL4: 45228 | BM4: =BN4 -> 45319 | BN4: 45319 | BO4: 45410 | BP4: 45501 | BQ4: 45592 | BR4: =BS4 -> 45683 | BS4: 45683 | BT4: 45774 | BU4: 45865 | BV4: 45956 | BW4: =BX4 -> 46047 | BX4: 46047 | BY4: 46138 | BZ4: =+EDATE(BY4,3) -> 46229 | CA4: =+EDATE(BZ4,3) -> 46321 | CB4: =DATE(YEAR(CA4)+1,1,31) -> 46418 | CC4: =CB4 -> 46418 | CD4: =+EDATE(CC4,3) -> 46507 | CE4: =+EDATE(CD4,3) -> 46598 | CF4: =+EDATE(CE4,3) -> 46690 | CG4: =DATE(YEAR(CF4)+1,1,31) -> 46783 | CH4: =CG4 -> 46783 | CI4: =EOMONTH(CH4,12) -> 47149 | CJ4: =EOMONTH(CI4,12) -> 47514 | CK4: =EOMONTH(CJ4,12) -> 47879
A5: =MO.ReportCurrency -> USD | C5: FY2009 | D5: =CONCATENATE("FY",RIGHT(C5,4)+1) -> FY2010 | E5: =CONCATENATE("FY",RIGHT(D5,4)+1) -> FY2011 | F5: =CONCATENATE("FY",RIGHT(E5,4)+1) -> FY2012 | G5: =CONCATENATE("Q1","-",RIGHT(F5,4)+1) -> Q1-2013 | H5: =CONCATENATE("Q2","-",RIGHT(G5,4)) -> Q2-2013 | I5: =CONCATENATE("Q3","-",RIGHT(H5,4)) -> Q3-2013 | J5: =CONCATENATE("Q4","-",RIGHT(I5,4)) -> Q4-2013 | K5: =CONCATENATE("FY",RIGHT(F5,4)+1) -> FY2013 | L5: =CONCATENATE("Q1","-",RIGHT(K5,4)+1) -> Q1-2014 | M5: =CONCATENATE("Q2","-",RIGHT(L5,4)) -> Q2-2014 | N5: =CONCATENATE("Q3","-",RIGHT(M5,4)) -> Q3-2014 | O5: =CONCATENATE("Q4","-",RIGHT(N5,4)) -> Q4-2014 | P5: =CONCATENATE("FY",RIGHT(K5,4)+1) -> FY2014 | Q5: =CONCATENATE("Q1","-",RIGHT(P5,4)+1) -> Q1-2015 | R5: =CONCATENATE("Q2","-",RIGHT(Q5,4)) -> Q2-2015 | S5: =CONCATENATE("Q3","-",RIGHT(R5,4)) -> Q3-2015 | T5: =CONCATENATE("Q4","-",RIGHT(S5,4)) -> Q4-2015 | U5: =CONCATENATE("FY",RIGHT(P5,4)+1) -> FY2015 | V5: =CONCATENATE("Q1","-",RIGHT(U5,4)+1) -> Q1-2016 | W5: =CONCATENATE("Q2","-",RIGHT(V5,4)) -> Q2-2016 | X5: =CONCATENATE("Q3","-",RIGHT(W5,4)) -> Q3-2016 | Y5: =CONCATENATE("Q4","-",RIGHT(X5,4)) -> Q4-2016 | Z5: =CONCATENATE("FY",RIGHT(U5,4)+1) -> FY2016 | AA5: =CONCATENATE("Q1","-",RIGHT(Z5,4)+1) -> Q1-2017 | AB5: =CONCATENATE("Q2","-",RIGHT(AA5,4)) -> Q2-2017 | AC5: =CONCATENATE("Q3","-",RIGHT(AB5,4)) -> Q3-2017 | AD5: =CONCATENATE("Q4","-",RIGHT(AC5,4)) -> Q4-2017 | AE5: =CONCATENATE("FY",RIGHT(Z5,4)+1) -> FY2017 | AF5: =CONCATENATE("Q1","-",RIGHT(AE5,4)+1) -> Q1-2018 | AG5: =CONCATENATE("Q2","-",RIGHT(AF5,4)) -> Q2-2018 | AH5: =CONCATENATE("Q3","-",RIGHT(AG5,4)) -> Q3-2018 | AI5: =CONCATENATE("Q4","-",RIGHT(AH5,4)) -> Q4-2018 | AJ5: =CONCATENATE("FY",RIGHT(AE5,4)+1) -> FY2018 | AK5: =CONCATENATE("Q1","-",RIGHT(AJ5,4)+1) -> Q1-2019 | AL5: =CONCATENATE("Q2","-",RIGHT(AK5,4)) -> Q2-2019 | AM5: =CONCATENATE("Q3","-",RIGHT(AL5,4)) -> Q3-2019 | AN5: =CONCATENATE("Q4","-",RIGHT(AM5,4)) -> Q4-2019 | AO5: =CONCATENATE("FY",RIGHT(AJ5,4)+1) -> FY2019 | AP5: =CONCATENATE("Q1","-",RIGHT(AO5,4)+1) -> Q1-2020 | AQ5: =CONCATENATE("Q2","-",RIGHT(AP5,4)) -> Q2-2020 | AR5: =CONCATENATE("Q3","-",RIGHT(AQ5,4)) -> Q3-2020 | AS5: =CONCATENATE("Q4","-",RIGHT(AR5,4)) -> Q4-2020 | AT5: =CONCATENATE("FY",RIGHT(AO5,4)+1) -> FY2020 | AU5: =CONCATENATE("Q1","-",RIGHT(AT5,4)+1) -> Q1-2021 | AV5: =CONCATENATE("Q2","-",RIGHT(AU5,4)) -> Q2-2021 | AW5: =CONCATENATE("Q3","-",RIGHT(AV5,4)) -> Q3-2021 | AX5: =CONCATENATE("Q4","-",RIGHT(AW5,4)) -> Q4-2021 | AY5: =CONCATENATE("FY",RIGHT(AT5,4)+1) -> FY2021 | AZ5: =CONCATENATE("Q1","-",RIGHT(AY5,4)+1) -> Q1-2022 | BA5: =CONCATENATE("Q2","-",RIGHT(AZ5,4)) -> Q2-2022 | BB5: =CONCATENATE("Q3","-",RIGHT(BA5,4)) -> Q3-2022 | BC5: =CONCATENATE("Q4","-",RIGHT(BB5,4)) -> Q4-2022 | BD5: =CONCATENATE("FY",RIGHT(AY5,4)+1) -> FY2022 | BE5: =CONCATENATE("Q1","-",RIGHT(BD5,4)+1) -> Q1-2023 | BF5: =CONCATENATE("Q2","-",RIGHT(BE5,4)) -> Q2-2023 | BG5: =CONCATENATE("Q3","-",RIGHT(BF5,4)) -> Q3-2023 | BH5: =CONCATENATE("Q4","-",RIGHT(BG5,4)) -> Q4-2023 | BI5: =CONCATENATE("FY",RIGHT(BD5,4)+1) -> FY2023 | BJ5: =CONCATENATE("Q1","-",RIGHT(BI5,4)+1) -> Q1-2024 | BK5: =CONCATENATE("Q2","-",RIGHT(BJ5,4)) -> Q2-2024 | BL5: =CONCATENATE("Q3","-",RIGHT(BK5,4)) -> Q3-2024 | BM5: =CONCATENATE("Q4","-",RIGHT(BL5,4)) -> Q4-2024 | BN5: =CONCATENATE("FY",RIGHT(BI5,4)+1) -> FY2024 | BO5: =CONCATENATE("Q1","-",RIGHT(BN5,4)+1) -> Q1-2025 | BP5: =CONCATENATE("Q2","-",RIGHT(BO5,4)) -> Q2-2025 | BQ5: =CONCATENATE("Q3","-",RIGHT(BP5,4)) -> Q3-2025 | BR5: =CONCATENATE("Q4","-",RIGHT(BQ5,4)) -> Q4-2025 | BS5: =CONCATENATE("FY",RIGHT(BN5,4)+1) -> FY2025 | BT5: =CONCATENATE("Q1","-",RIGHT(BS5,4)+1) -> Q1-2026 | BU5: =CONCATENATE("Q2","-",RIGHT(BT5,4)) -> Q2-2026 | BV5: =CONCATENATE("Q3","-",RIGHT(BU5,4)) -> Q3-2026 | BW5: =CONCATENATE("Q4","-",RIGHT(BV5,4)) -> Q4-2026 | BX5: =CONCATENATE("FY",RIGHT(BS5,4)+1) -> FY2026 | BY5: =CONCATENATE("Q1","-",RIGHT(BX5,4)+1) -> Q1-2027 | BZ5: =CONCATENATE("Q2","-",RIGHT(BY5,4)) -> Q2-2027 | CA5: =CONCATENATE("Q3","-",RIGHT(BZ5,4)) -> Q3-2027 | CB5: =CONCATENATE("Q4","-",RIGHT(CA5,4)) -> Q4-2027 | CC5: =CONCATENATE("FY",RIGHT(BX5,4)+1) -> FY2027 | CD5: =CONCATENATE("Q1","-",RIGHT(CC5,4)+1) -> Q1-2028 | CE5: =CONCATENATE("Q2","-",RIGHT(CD5,4)) -> Q2-2028 | CF5: =CONCATENATE("Q3","-",RIGHT(CE5,4)) -> Q3-2028 | CG5: =CONCATENATE("Q4","-",RIGHT(CF5,4)) -> Q4-2028 | CH5: =CONCATENATE("FY",RIGHT(CC5,4)+1) -> FY2028 | CI5: =CONCATENATE("FY",RIGHT(CH5,4)+1) -> FY2029 | CJ5: =CONCATENATE("FY",RIGHT(CI5,4)+1) -> FY2030 | CK5: =CONCATENATE("FY",RIGHT(CJ5,4)+1) -> FY2031
A6: Revenue Build (FS/PR)
A7: Gaming Revenue, mm | P7: 1511 | Q7: 468 | R7: 417 | S7: 527 | T7: =U7-SUM(Q7,R7,S7) -> 646 | U7: 2058 | V7: 587 | W7: 660 | X7: 761 | Y7: =Z7-SUM(V7,W7,X7) -> 810 | Z7: 2818 | AA7: 687 | AB7: 781 | AC7: 1244 | AD7: =AE7-SUM(AA7,AB7,AC7) -> 1348 | AE7: 4060 | AF7: 1027 | AG7: 1186 | AH7: 1561 | AI7: =AJ7-SUM(AF7,AG7,AH7) -> 1739 | AJ7: 5513 | AK7: 1723 | AL7: 1805 | AM7: 1764 | AN7: 954 | AO7: =SUM(AK7,AL7,AM7,AN7) -> 6246 | AP7: 1055 | AQ7: 1313 | AR7: 1659 | AS7: 1491 | AT7: =SUM(AP7,AQ7,AR7,AS7) -> 5518 | AU7: 1339 | AV7: 1654 | AW7: 2271 | AX7: 2495 | AY7: =SUM(AU7,AV7,AW7,AX7) -> 7759 | AZ7: 2760 | BA7: 3061 | BB7: 3221 | BC7: 3420 | BD7: =SUM(AZ7,BA7,BB7,BC7) -> 12462 | BE7: 3620 | BF7: 2042 | BG7: 1574 | BH7: 1831 | BI7: =SUM(BE7,BF7,BG7,BH7) -> 9067 | BJ7: 2240 | BK7: 2486 | BL7: 2856 | BM7: 2865 | BN7: =SUM(BJ7,BK7,BL7,BM7) -> 10447 | BO7: 2647 | BP7: 2880 | BQ7: 3279 | BR7: 2544 | BS7: =SUM(BO7,BP7,BQ7,BR7) -> 11350 | BT7: 3763 | BU7: 4287 | BV7: 4265 | BW7: 3727 | BX7: =SUM(BT7,BU7,BV7,BW7) -> 16042 | BY7: =BY34-BY30-BY26-BY231-BY11-BY22 -> 4219 | BZ7: =+BU7*(1+BZ9) -> 5573.1 | CA7: =+BV7*(1+CA9) -> 5331.25 | CB7: =+BW7*(1+CB9) -> 4472.4 | CC7: =SUM(BY7,BZ7,CA7,CB7) -> 19595.75 | CD7: =+BY7*(1+CD9) -> 5273.75 | CE7: =+BZ7*(1+CE9) -> 6966.375 | CF7: =+CA7*(1+CF9) -> 6664.0625 | CG7: =+CB7*(1+CG9) -> 5366.88 | CH7: =SUM(CD7,CE7,CF7,CG7) -> 24271.067 | CI7: =+CH7*(1+CI9) -> 26698.174 | CJ7: =+CI7*(1+CJ9) -> 29367.992 | CK7: =+CJ7*(1+CK9) -> 32304.791
A8: Q/Q Gaming Revenue growth, % | R8: =R7/Q7-1 -> -0.10897436 | S8: =S7/R7-1 -> 0.26378897 | T8: =T7/S7-1 -> 0.22580645 | V8: =V7/T7-1 -> -0.091331269 | W8: =W7/V7-1 -> 0.12436116 | X8: =X7/W7-1 -> 0.1530303 | Y8: =Y7/X7-1 -> 0.064388962 | AA8: =AA7/Y7-1 -> -0.15185185 | AB8: =AB7/AA7-1 -> 0.13682678 | AC8: =AC7/AB7-1 -> 0.59282971 | AD8: =AD7/AC7-1 -> 0.083601286 | AF8: =AF7/AD7-1 -> -0.23813056 | AG8: =AG7/AF7-1 -> 0.15481986 | AH8: =AH7/AG7-1 -> 0.31618887 | AI8: =AI7/AH7-1 -> 0.11402947 | AK8: =AK7/AI7-1 -> -0.0092006901 | AL8: =AL7/AK7-1 -> 0.04759141 | AM8: =AM7/AL7-1 -> -0.022714681 | AN8: =AN7/AM7-1 -> -0.45918367 | AP8: =AP7/AN7-1 -> 0.10587002 | AQ8: =AQ7/AP7-1 -> 0.24454976 | AR8: =AR7/AQ7-1 -> 0.26351866 | AS8: =AS7/AR7-1 -> -0.10126582 | AU8: =AU7/AS7-1 -> -0.101945 | AV8: =AV7/AU7-1 -> 0.23525019 | AW8: =AW7/AV7-1 -> 0.37303507 | AX8: =AX7/AW7-1 -> 0.098634963 | AZ8: =AZ7/AX7-1 -> 0.10621242 | BA8: =BA7/AZ7-1 -> 0.10905797 | BB8: =BB7/BA7-1 -> 0.0522705 | BC8: =BC7/BB7-1 -> 0.061782055 | BE8: =BE7/BC7-1 -> 0.058479532 | BF8: =BF7/BE7-1 -> -0.4359116 | BG8: =BG7/BF7-1 -> -0.22918707 | BH8: =BH7/BG7-1 -> 0.16327827 | BJ8: =BJ7/BH7-1 -> 0.2233752 | BK8: =BK7/BJ7-1 -> 0.10982143 | BL8: =BL7/BK7-1 -> 0.14883347 | BM8: =BM7/BL7-1 -> 0.0031512605 | BO8: =BO7/BM7-1 -> -0.07609075 | BP8: =BP7/BO7-1 -> 0.088024178 | BQ8: =BQ7/BP7-1 -> 0.13854167 | BR8: =BR7/BQ7-1 -> -0.22415371 | BT8: =BT7/BR7-1 -> 0.47916667 | BU8: =BU7/BT7-1 -> 0.1392506 | BV8: =BV7/BU7-1 -> -0.0051317938 | BW8: =BW7/BV7-1 -> -0.12614302 | BY8: =BY7/BW7-1 -> 0.13200966 | BZ8: =BZ7/BY7-1 -> 0.32095283 | CA8: =CA7/BZ7-1 -> -0.043395956 | CB8: =CB7/CA7-1 -> -0.1610973 | CD8: =CD7/CB7-1 -> 0.17917673 | CE8: =CE7/CD7-1 -> 0.32095283 | CF8: =CF7/CE7-1 -> -0.043395956 | CG8: =CG7/CF7-1 -> -0.19465341
A9: Y/Y Gaming Revenue Growth, % | U9: =+U7/P7-1 -> 0.36201191 | V9: =+V7/Q7-1 -> 0.2542735 | W9: =+W7/R7-1 -> 0.58273381 | X9: =+X7/S7-1 -> 0.44402277 | Y9: =+Y7/T7-1 -> 0.25386997 | Z9: =+Z7/U7-1 -> 0.36929057 | AA9: =+AA7/V7-1 -> 0.17035775 | AB9: =+AB7/W7-1 -> 0.18333333 | ... BY9: =+BY7/BT7-1 -> 0.12117991 | BZ9: 0.3 | CA9: 0.25 | CB9: 0.2 | CC9: =+CC7/BX7-1 -> 0.22152786 | CD9: 0.25 | CE9: 0.25 | CF9: 0.25 | CG9: 0.2 | CH9: =+CH7/CC7-1 -> 0.23858834 | CI9: 0.1 | CJ9: 0.1 | CK9: 0.1
A11: Professional Visualization Revenue, mm | P11: 789 | Q11: 191 | R11: 208 | S11: 206 | T11: =U11-SUM(Q11,R11,S11) -> 190 | U11: 795 | V11: 181 | W11: 176 | X11: 190 | Y11: =Z11-SUM(V11,W11,X11) -> 203 | Z11: 750 | AA11: 189 | AB11: 214 | AC11: 207 | AD11: =AE11-SUM(AA11,AB11,AC11) -> 225 | AE11: 835 | AF11: 205 | AG11: 235 | AH11: 239 | AI11: =AJ11-SUM(AF11,AG11,AH11) -> 255 | AJ11: 934 | AK11: 251 | AL11: 281 | AM11: 305 | AN11: 293 | AO11: =SUM(AK11,AL11,AM11,AN11) -> 1130 | AP11: 266 | AQ11: 291 | AR11: 324 | AS11: 331 | AT11: =SUM(AP11,AQ11,AR11,AS11) -> 1212 | AU11: 307 | AV11: 203 | AW11: 236 | AX11: 307 | AY11: =SUM(AU11,AV11,AW11,AX11) -> 1053 | AZ11: 372 | BA11: 519 | BB11: 577 | BC11: 643 | BD11: =SUM(AZ11,BA11,BB11,BC11) -> 2111 | BE11: 622 | BF11: 496 | BG11: 200 | BH11: 226 | BI11: =SUM(BE11,BF11,BG11,BH11) -> 1544 | BJ11: 295 | BK11: 379 | BL11: 416 | BM11: 463 | BN11: =SUM(BJ11,BK11,BL11,BM11) -> 1553 | BO11: 427 | BP11: 454 | BQ11: 486 | BR11: 511 | BS11: =SUM(BO11,BP11,BQ11,BR11) -> 1878 | BT11: 509 | BU11: 601 | BV11: 760 | BW11: 1321 | BX11: =SUM(BT11,BU11,BV11,BW11) -> 3191 | BY11: 1300 | BZ11: =+BU11*(1+BZ13) -> 631.05 | CA11: =+BV11*(1+CA13) -> 798 | CB11: =+BW11*(1+CB13) -> 1387.05 | CC11: =SUM(BY11,BZ11,CA11,CB11) -> 4116.1 | CD11: =+BY11*(1+CD13) -> 1365 | CE11: =+BZ11*(1+CE13) -> 662.6025 | CF11: =+CA11*(1+CF13) -> 837.9 | CG11: =+CB11*(1+CG13) -> 1456.4025 | CH11: =SUM(CD11,CE11,CF11,CG11) -> 4321.905 | CI11: =+CH11*(1+CI13) -> 4754.0955 | CJ11: =+CI11*(1+CJ13) -> 5229.5051 | CK11: =+CJ11*(1+CK13) -> 5752.4556
A12: Q/Q Professional Visualization Revenue growth, % | R12: =R11/Q11-1 -> 0.089005236 | S12: =S11/R11-1 -> -0.0096153846 | T12: =T11/S11-1 -> -0.077669903 | V12: =V11/T11-1 -> -0.047368421 | W12: =W11/V11-1 -> -0.027624309 | X12: =X11/W11-1 -> 0.079545455 | Y12: =Y11/X11-1 -> 0.068421053 | AA12: =AA11/Y11-1 -> -0.068965517 | AB12: =AB11/AA11-1 -> 0.13227513 | AC12: =AC11/AB11-1 -> -0.03271028 | AD12: =AD11/AC11-1 -> 0.086956522 | AF12: =AF11/AD11-1 -> -0.088888889 | AG12: =AG11/AF11-1 -> 0.14634146 | AH12: =AH11/AG11-1 -> 0.017021277 | AI12: =AI11/AH11-1 -> 0.066945607 | AK12: =AK11/AI11-1 -> -0.015686275 | AL12: =AL11/AK11-1 -> 0.11952191 | AM12: =AM11/AL11-1 -> 0.085409253 | AN12: =AN11/AM11-1 -> -0.039344262 | AP12: =AP11/AN11-1 -> -0.092150171 | AQ12: =AQ11/AP11-1 -> 0.093984962 | AR12: =AR11/AQ11-1 -> 0.11340206 | AS12: =AS11/AR11-1 -> 0.021604938 | AU12: =AU11/AS11-1 -> -0.072507553 | AV12: =AV11/AU11-1 -> -0.33876221 | AW12: =AW11/AV11-1 -> 0.16256158 | AX12: =AX11/AW11-1 -> 0.30084746 | AZ12: =AZ11/AX11-1 -> 0.21172638 | BA12: =BA11/AZ11-1 -> 0.39516129 | BB12: =BB11/BA11-1 -> 0.11175337 | BC12: =BC11/BB11-1 -> 0.11438475 | BE12: =BE11/BC11-1 -> -0.032659409 | BF12: =BF11/BE11-1 -> -0.20257235 | BG12: =BG11/BF11-1 -> -0.59677419 | BH12: =BH11/BG11-1 -> 0.13 | BJ12: =BJ11/BH11-1 -> 0.30530973 | BK12: =BK11/BJ11-1 -> 0.28474576 | BL12: =BL11/BK11-1 -> 0.09762533 | BM12: =BM11/BL11-1 -> 0.11298077 | BO12: =BO11/BM11-1 -> -0.07775378 | BP12: =BP11/BO11-1 -> 0.06323185 | BQ12: =BQ11/BP11-1 -> 0.070484581 | BR12: =BR11/BQ11-1 -> 0.051440329 | BT12: =BT11/BR11-1 -> -0.0039138943 | BU12: =BU11/BT11-1 -> 0.18074656 | BV12: =BV11/BU11-1 -> 0.26455907 | BW12: =BW11/BV11-1 -> 0.73815789 | BY12: =BY11/BW11-1 -> -0.015897048 | BZ12: =BZ11/BY11-1 -> -0.51457692 | CA12: =CA11/BZ11-1 -> 0.26455907 | CB12: =CB11/CA11-1 -> 0.73815789 | CD12: =CD11/CB11-1 -> -0.015897048 | CE12: =CE11/CD11-1 -> -0.51457692 | CF12: =CF11/CE11-1 -> 0.26455907 | CG12: =CG11/CF11-1 -> 0.73815789
A13: Y/Y Professional Visualization Revenue Growth, % | U13: =+U11/P11-1 -> 0.0076045627 | V13: =+V11/Q11-1 -> -0.052356021 | W13: =+W11/R11-1 -> -0.15384615 | X13: =+X11/S11-1 -> -0.077669903 | Y13: =+Y11/T11-1 -> 0.068421053 | Z13: =+Z11/U11-1 -> -0.056603774 | AA13: =+AA11/V11-1 -> 0.044198895 | AB13: =+AB11/W11-1 -> 0.21590909 | ... BY13: =+BY11/BT11-1 -> 1.5540275 | BZ13: 0.05 | CA13: 0.05 | CB13: 0.05 | CC13: =+CC11/BX11-1 -> 0.28990912 | CD13: 0.05 | CE13: 0.05 | CF13: 0.05 | CG13: 0.05 | CH13: =+CH11/CC11-1 -> 0.05 | CI13: 0.1 | CJ13: 0.1 | CK13: 0.1
A15: Compute revenue, mm | BJ15: 3357 | BK15: 8612 | BL15: 11908 | BM15: 15073 | BN15: 38950 | BO15: 19392 | BP15: 22604 | BQ15: 27644 | BR15: =BS15-SUM(BO15,BP15,BQ15) -> 32556 | BS15: 102196 | BT15: 34155 | BU15: 33844 | BV15: 43028 | BW15: =BX15-SUM(BT15,BU15,BV15) -> 51334 | BX15: 162361 | BY15: =BY22-BY19 -> 60446
A16: Q/Q Compute Revenue growth, % | BK16: =BK15/BJ15-1 -> 1.5653858 | BL16: =BL15/BK15-1 -> 0.38272178 | BM16: =BM15/BL15-1 -> 0.26578771 | BO16: =BO15/BM15-1 -> 0.28653884 | BP16: =BP15/BO15-1 -> 0.16563531 | BQ16: =BQ15/BP15-1 -> 0.22296939 | BR16: =BR15/BQ15-1 -> 0.17768774 | BT16: =BT15/BR15-1 -> 0.04911537 | BU16: =BU15/BT15-1 -> -0.0091055482 | BV16: =BV15/BU15-1 -> 0.27136272 | BW16: =BW15/BV15-1 -> 0.19303709 | BY16: =BY15/BW15-1 -> 0.17750419
A17: Y/Y Compute Revenue Growth, % | BO17: =+BO15/BJ15-1 -> 4.7765862 | BP17: =+BP15/BK15-1 -> 1.6247097 | BQ17: =+BQ15/BL15-1 -> 1.3214646 | BR17: =+BR15/BM15-1 -> 1.1598885 | BS17: =+BS15/BN15-1 -> 1.6237741 | BT17: =+BT15/BO15-1 -> 0.76129332 | BU17: =+BU15/BP15-1 -> 0.49725712 | BV17: =+BV15/BQ15-1 -> 0.55650412 | ... BY17: =+BY15/BT15-1 -> 0.76975553
A19: Networking revenue, mm | BJ19: 927 | BK19: 1711 | BL19: 2606 | BM19: 3331 | BN19: 8575 | BO19: 3171 | BP19: 3668 | BQ19: 3127 | BR19: =BS19-SUM(BO19,BP19,BQ19) -> 3024 | BS19: 12990 | BT19: 4957 | BU19: 7252 | BV19: 8187 | BW19: =BX19-SUM(BT19,BU19,BV19) -> 10980 | BX19: 31376 | BY19: 14800
A20: Q/Q Networking Revenue growth, % | BK20: =BK19/BJ19-1 -> 0.84573894 | BL20: =BL19/BK19-1 -> 0.52308591 | BM20: =BM19/BL19-1 -> 0.27820414 | BO20: =BO19/BM19-1 -> -0.048033624 | BP20: =BP19/BO19-1 -> 0.15673289 | BQ20: =BQ19/BP19-1 -> -0.14749182 | BR20: =BR19/BQ19-1 -> -0.032938919 | BT20: =BT19/BR19-1 -> 0.63921958 | BU20: =BU19/BT19-1 -> 0.46298164 | BV20: =BV19/BU19-1 -> 0.12892995 | BW20: =BW19/BV19-1 -> 0.3411506 | BY20: =BY19/BW19-1 -> 0.34790528
A21: Y/Y Networking Revenue Growth, % | BO21: =+BO19/BJ19-1 -> 2.420712 | BP21: =+BP19/BK19-1 -> 1.1437756 | BQ21: =+BQ19/BL19-1 -> 0.19992325 | BR21: =+BR19/BM19-1 -> -0.092164515 | BS21: =+BS19/BN19-1 -> 0.5148688 | BT21: =+BT19/BO19-1 -> 0.56322927 | BU21: =+BU19/BP19-1 -> 0.97709924 | BV21: =+BV19/BQ19-1 -> 1.6181644 | ... BY21: =+BY19/BT19-1 -> 1.9856768
A22: Datacenter Revenue, mm | P22: 199 | Q22: 57 | R22: 83 | S22: 89 | T22: =U22-SUM(Q22,R22,S22) -> 88 | U22: 317 | V22: 88 | W22: 72 | X22: 82 | Y22: =Z22-SUM(V22,W22,X22) -> 97 | Z22: 339 | AA22: 143 | AB22: 151 | AC22: 240 | AD22: =AE22-SUM(AA22,AB22,AC22) -> 296 | AE22: 830 | AF22: 409 | AG22: 416 | AH22: 501 | AI22: =AJ22-SUM(AF22,AG22,AH22) -> 606 | AJ22: 1932 | AK22: 701 | AL22: 760 | AM22: 792 | AN22: 679 | AO22: =SUM(AK22,AL22,AM22,AN22) -> 2932 | AP22: 634 | AQ22: 655 | AR22: 726 | AS22: 968 | AT22: =SUM(AP22,AQ22,AR22,AS22) -> 2983 | AU22: 1141 | AV22: 1752 | AW22: 1900 | AX22: 1903 | AY22: =SUM(AU22,AV22,AW22,AX22) -> 6696 | AZ22: 2048 | BA22: 2366 | BB22: 2936 | BC22: 3263 | BD22: =SUM(AZ22,BA22,BB22,BC22) -> 10613 | BE22: 3750 | BF22: 3806 | BG22: 3833 | BH22: 3616 | BI22: =SUM(BE22,BF22,BG22,BH22) -> 15005 | BJ22: 4284 | BK22: 10323 | BL22: 14514 | BM22: 18404 | BN22: =SUM(BJ22,BK22,BL22,BM22) -> 47525 | BO22: 22563 | BP22: 26272 | BQ22: 30771 | BR22: 35580 | BS22: =SUM(BO22,BP22,BQ22,BR22) -> 115186 | BT22: 39112 | BU22: 41096 | BV22: 51215 | BW22: 62314 | BX22: =SUM(BT22,BU22,BV22,BW22) -> 193737 | BY22: 75246 | BZ22: =+BU22*(1+BZ24) -> 83835.84 | CA22: =+BV22*(1+CA24) -> 84504.75 | CB22: =+BW22*(1+CB24) -> 87239.6 | CC22: =SUM(BY22,BZ22,CA22,CB22) -> 330826.19 | CD22: =+BY22*(1+CD24) -> 97819.8 | CE22: =+BZ22*(1+CE24) -> 108986.59 | CF22: =+CA22*(1+CF24) -> 105630.94 | CG22: =+CB22*(1+CG24) -> 109049.5 | CH22: =SUM(CD22,CE22,CF22,CG22) -> 421486.83 | CI22: =+CH22*(1+CI24) -> 505784.2 | CJ22: =+CI22*(1+CJ24) -> 596825.35 | CK22: =+CJ22*(1+CK24) -> 704253.91
A23: Q/Q Datacenter Revenue growth, % | R23: =R22/Q22-1 -> 0.45614035 | S23: =S22/R22-1 -> 0.072289157 | T23: =T22/S22-1 -> -0.011235955 | V23: =V22/T22-1 -> 0 | W23: =W22/V22-1 -> -0.18181818 | X23: =X22/W22-1 -> 0.13888889 | Y23: =Y22/X22-1 -> 0.18292683 | AA23: =AA22/Y22-1 -> 0.4742268 | AB23: =AB22/AA22-1 -> 0.055944056 | AC23: =AC22/AB22-1 -> 0.58940397 | AD23: =AD22/AC22-1 -> 0.23333333 | AF23: =AF22/AD22-1 -> 0.38175676 | AG23: =AG22/AF22-1 -> 0.017114914 | AH23: =AH22/AG22-1 -> 0.20432692 | AI23: =AI22/AH22-1 -> 0.20958084 | AK23: =AK22/AI22-1 -> 0.15676568 | AL23: =AL22/AK22-1 -> 0.084165478 | AM23: =AM22/AL22-1 -> 0.042105263 | AN23: =AN22/AM22-1 -> -0.14267677 | AP23: =AP22/AN22-1 -> -0.066273932 | AQ23: =AQ22/AP22-1 -> 0.033123028 | AR23: =AR22/AQ22-1 -> 0.10839695 | AS23: =AS22/AR22-1 -> 0.33333333 | AU23: =AU22/AS22-1 -> 0.17871901 | AV23: =AV22/AU22-1 -> 0.53549518 | AW23: =AW22/AV22-1 -> 0.084474886 | AX23: =AX22/AW22-1 -> 0.0015789474 | AZ23: =AZ22/AX22-1 -> 0.076195481 | BA23: =BA22/AZ22-1 -> 0.15527344 | BB23: =BB22/BA22-1 -> 0.24091293 | BC23: =BC22/BB22-1 -> 0.11137602 | BE23: =BE22/BC22-1 -> 0.14924916 | BF23: =BF22/BE22-1 -> 0.014933333 | BG23: =BG22/BF22-1 -> 0.007094062 | BH23: =BH22/BG22-1 -> -0.056613619 | BJ23: =BJ22/BH22-1 -> 0.18473451 | BK23: =BK22/BJ22-1 -> 1.4096639 | BL23: =BL22/BK22-1 -> 0.40598663 | BM23: =BM22/BL22-1 -> 0.26801709 | BO23: =BO22/BM22-1 -> 0.22598348 | BP23: =BP22/BO22-1 -> 0.16438417 | BQ23: =BQ22/BP22-1 -> 0.17124695 | BR23: =BR22/BQ22-1 -> 0.15628351 | BT23: =BT22/BR22-1 -> 0.099269252 | BU23: =BU22/BT22-1 -> 0.05072612 | BV23: =BV22/BU22-1 -> 0.24622834 | BW23: =BW22/BV22-1 -> 0.21671385 | BY23: =BY22/BW22-1 -> 0.20752961 | BZ23: =BZ22/BY22-1 -> 0.11415677 | CA23: =CA22/BZ22-1 -> 0.0079788072 | CB23: =CB22/CA22-1 -> 0.03236327 | CD23: =CD22/CB22-1 -> 0.12127749 | CE23: =CE22/CD22-1 -> 0.11415677 | CF23: =CF22/CE22-1 -> -0.030789609 | CG23: =CG22/CF22-1 -> 0.03236327
A24: Y/Y Datacenter Revenue Growth, % | U24: =+U22/P22-1 -> 0.59296482 | V24: =+V22/Q22-1 -> 0.54385965 | W24: =+W22/R22-1 -> -0.13253012 | X24: =+X22/S22-1 -> -0.078651685 | Y24: =+Y22/T22-1 -> 0.10227273 | Z24: =+Z22/U22-1 -> 0.069400631 | AA24: =+AA22/V22-1 -> 0.625 | AB24: =+AB22/W22-1 -> 1.0972222 | ... BY24: =+BY22/BT22-1 -> 0.92385969 | BZ24: 1.04 | CA24: 0.65 | CB24: 0.4 | CC24: =+CC22/BX22-1 -> 0.70760459 | CD24: 0.3 | CE24: 0.3 | CF24: 0.25 | CG24: 0.25 | CH24: =+CH22/CC22-1 -> 0.27404311 | CI24: 0.2 | CJ24: 0.18 | CK24: 0.18
A26: Automotive Revenue, mm | P26: 99 | Q26: 35 | R26: 40 | S26: 52 | T26: =U26-SUM(Q26,R26,S26) -> 56 | U26: 183 | V26: 77 | W26: 71 | X26: 79 | Y26: =Z26-SUM(V26,W26,X26) -> 93 | Z26: 320 | AA26: 113 | AB26: 119 | AC26: 127 | AD26: =AE26-SUM(AA26,AB26,AC26) -> 128 | AE26: 487 | AF26: 140 | AG26: 142 | AH26: 144 | AI26: =AJ26-SUM(AF26,AG26,AH26) -> 132 | AJ26: 558 | AK26: 145 | AL26: 161 | AM26: 172 | AN26: 163 | AO26: =SUM(AK26,AL26,AM26,AN26) -> 641 | AP26: 166 | AQ26: 209 | AR26: 162 | AS26: 163 | AT26: =SUM(AP26,AQ26,AR26,AS26) -> 700 | AU26: 155 | AV26: 111 | AW26: 125 | AX26: 145 | AY26: =SUM(AU26,AV26,AW26,AX26) -> 536 | AZ26: 154 | BA26: 152 | BB26: 135 | BC26: 125 | BD26: =SUM(AZ26,BA26,BB26,BC26) -> 566 | BE26: 138 | BF26: 220 | BG26: 251 | BH26: 294 | BI26: =SUM(BE26,BF26,BG26,BH26) -> 903 | BJ26: 296 | BK26: 253 | BL26: 261 | BM26: 281 | BN26: =SUM(BJ26,BK26,BL26,BM26) -> 1091 | BO26: 329 | BP26: 346 | BQ26: 449 | BR26: 570 | BS26: =SUM(BO26,BP26,BQ26,BR26) -> 1694 | BT26: 567 | BU26: 586 | BV26: 592 | BW26: 604 | BX26: =SUM(BT26,BU26,BV26,BW26) -> 2349 | BY26: 650 | BZ26: =+BU26*(1+BZ28) -> 703.2 | CA26: =+BV26*(1+CA28) -> 710.4 | CB26: =+BW26*(1+CB28) -> 724.8 | CC26: =SUM(BY26,BZ26,CA26,CB26) -> 2788.4 | CD26: =+BY26*(1+CD28) -> 845 | CE26: =+BZ26*(1+CE28) -> 843.84 | CF26: =+CA26*(1+CF28) -> 852.48 | CG26: =+CB26*(1+CG28) -> 869.76 | CH26: =SUM(CD26,CE26,CF26,CG26) -> 3411.08 | CI26: =+CH26*(1+CI28) -> 3752.188 | CJ26: =+CI26*(1+CJ28) -> 4127.4068 | CK26: =+CJ26*(1+CK28) -> 4540.1475
A27: Q/Q Automotive Revenue growth, % | R27: =R26/Q26-1 -> 0.14285714 | S27: =S26/R26-1 -> 0.3 | T27: =T26/S26-1 -> 0.076923077 | V27: =V26/T26-1 -> 0.375 | W27: =W26/V26-1 -> -0.077922078 | X27: =X26/W26-1 -> 0.11267606 | Y27: =Y26/X26-1 -> 0.17721519 | AA27: =AA26/Y26-1 -> 0.21505376 | AB27: =AB26/AA26-1 -> 0.053097345 | AC27: =AC26/AB26-1 -> 0.067226891 | AD27: =AD26/AC26-1 -> 0.0078740157 | AF27: =AF26/AD26-1 -> 0.09375 | AG27: =AG26/AF26-1 -> 0.014285714 | AH27: =AH26/AG26-1 -> 0.014084507 | AI27: =AI26/AH26-1 -> -0.083333333 | AK27: =AK26/AI26-1 -> 0.098484848 | AL27: =AL26/AK26-1 -> 0.11034483 | AM27: =AM26/AL26-1 -> 0.068322981 | AN27: =AN26/AM26-1 -> -0.052325581 | AP27: =AP26/AN26-1 -> 0.018404908 | AQ27: =AQ26/AP26-1 -> 0.25903614 | AR27: =AR26/AQ26-1 -> -0.22488038 | AS27: =AS26/AR26-1 -> 0.0061728395 | AU27: =AU26/AS26-1 -> -0.049079755 | AV27: =AV26/AU26-1 -> -0.28387097 | AW27: =AW26/AV26-1 -> 0.12612613 | AX27: =AX26/AW26-1 -> 0.16 | AZ27: =AZ26/AX26-1 -> 0.062068966 | BA27: =BA26/AZ26-1 -> -0.012987013 | BB27: =BB26/BA26-1 -> -0.11184211 | BC27: =BC26/BB26-1 -> -0.074074074 | BE27: =BE26/BC26-1 -> 0.104 | BF27: =BF26/BE26-1 -> 0.5942029 | BG27: =BG26/BF26-1 -> 0.14090909 | BH27: =BH26/BG26-1 -> 0.17131474 | BJ27: =BJ26/BH26-1 -> 0.0068027211 | BK27: =BK26/BJ26-1 -> -0.14527027 | BL27: =BL26/BK26-1 -> 0.031620553 | BM27: =BM26/BL26-1 -> 0.076628352 | BO27: =BO26/BM26-1 -> 0.17081851 | BP27: =BP26/BO26-1 -> 0.051671733 | BQ27: =BQ26/BP26-1 -> 0.29768786 | BR27: =BR26/BQ26-1 -> 0.26948775 | BT27: =BT26/BR26-1 -> -0.0052631579 | BU27: =BU26/BT26-1 -> 0.0335097 | BV27: =BV26/BU26-1 -> 0.010238908 | BW27: =BW26/BV26-1 -> 0.02027027 | BY27: =BY26/BW26-1 -> 0.07615894 | BZ27: =BZ26/BY26-1 -> 0.081846154 | CA27: =CA26/BZ26-1 -> 0.010238908 | CB27: =CB26/CA26-1 -> 0.02027027 | CD27: =CD26/CB26-1 -> 0.16583885 | CE27: =CE26/CD26-1 -> -0.0013727811 | CF27: =CF26/CE26-1 -> 0.010238908 | CG27: =CG26/CF26-1 -> 0.02027027
A28: Y/Y Automotive Revenue Growth, % | U28: =+U26/P26-1 -> 0.84848485 | V28: =+V26/Q26-1 -> 1.2 | W28: =+W26/R26-1 -> 0.775 | X28: =+X26/S26-1 -> 0.51923077 | Y28: =+Y26/T26-1 -> 0.66071429 | Z28: =+Z26/U26-1 -> 0.74863388 | AA28: =+AA26/V26-1 -> 0.46753247 | AB28: =+AB26/W26-1 -> 0.67605634 | ... BY28: =+BY26/BT26-1 -> 0.14638448 | BZ28: 0.2 | CA28: 0.2 | CB28: 0.2 | CC28: =+CC26/BX26-1 -> 0.18705832 | CD28: 0.3 | CE28: 0.2 | CF28: 0.2 | CG28: 0.2 | CH28: =+CH26/CC26-1 -> 0.22331086 | CI28: 0.1 | CJ28: 0.1 | CK28: 0.1
A30: OEM & IP Revenue, mm | P30: 1532 | Q30: 352 | R30: 355 | S30: 351 | T30: =U30-SUM(Q30,R30,S30) -> 271 | U30: 1329 | V30: 218 | W30: 174 | X30: 193 | Y30: =Z30-SUM(V30,W30,X30) -> 198 | Z30: 783 | AA30: 173 | AB30: 163 | AC30: 186 | AD30: =AE30-SUM(AA30,AB30,AC30) -> 176 | AE30: 698 | AF30: 156 | AG30: 251 | AH30: 191 | AI30: =AJ30-SUM(AF30,AG30,AH30) -> 179 | AJ30: 777 | AK30: 387 | AL30: 116 | AM30: 148 | AN30: 116 | AO30: =SUM(AK30,AL30,AM30,AN30) -> 767 | AP30: 99 | AQ30: 111 | AR30: 143 | AS30: 152 | AT30: =SUM(AP30,AQ30,AR30,AS30) -> 505 | AU30: 138 | AV30: 146 | AW30: 194 | AX30: 153 | AY30: =SUM(AU30,AV30,AW30,AX30) -> 631 | AZ30: 327 | BA30: 409 | BB30: 234 | BC30: 192 | BD30: =SUM(AZ30,BA30,BB30,BC30) -> 1162 | BE30: 158 | BF30: 140 | BG30: 73 | BH30: 84 | BI30: =SUM(BE30,BF30,BG30,BH30) -> 455 | BJ30: 77 | BK30: 66 | BL30: 73 | BM30: 90 | BN30: =SUM(BJ30,BK30,BL30,BM30) -> 306 | BO30: 78 | BP30: 88 | BQ30: 97 | BR30: 126 | BS30: =SUM(BO30,BP30,BQ30,BR30) -> 389 | BT30: 111 | BU30: 173 | BV30: 174 | BW30: 161 | BX30: =SUM(BT30,BU30,BV30,BW30) -> 619 | BY30: 200 | BZ30: =+BU30*(1+BZ32) -> 190.3 | CA30: =+BV30*(1+CA32) -> 191.4 | CB30: =+BW30*(1+CB32) -> 177.1 | CC30: =SUM(BY30,BZ30,CA30,CB30) -> 758.8 | CD30: =+BY30*(1+CD32) -> 220 | CE30: =+BZ30*(1+CE32) -> 209.33 | CF30: =+CA30*(1+CF32) -> 210.54 | CG30: =+CB30*(1+CG32) -> 194.81 | CH30: =SUM(CD30,CE30,CF30,CG30) -> 834.68 | CI30: =+CH30*(1+CI32) -> 918.148 | CJ30: =+CI30*(1+CJ32) -> 1009.9628 | CK30: =+CJ30*(1+CK32) -> 1110.9591
A31: Q/Q OEM & IP Revenue growth, % | R31: =R30/Q30-1 -> 0.0085227273 | S31: =S30/R30-1 -> -0.011267606 | T31: =T30/S30-1 -> -0.22792023 | V31: =V30/T30-1 -> -0.19557196 | W31: =W30/V30-1 -> -0.20183486 | X31: =X30/W30-1 -> 0.1091954 | Y31: =Y30/X30-1 -> 0.025906736 | AA31: =AA30/Y30-1 -> -0.12626263 | AB31: =AB30/AA30-1 -> -0.057803468 | AC31: =AC30/AB30-1 -> 0.14110429 | AD31: =AD30/AC30-1 -> -0.053763441 | AF31: =AF30/AD30-1 -> -0.11363636 | AG31: =AG30/AF30-1 -> 0.60897436 | AH31: =AH30/AG30-1 -> -0.23904382 | AI31: =AI30/AH30-1 -> -0.062827225 | AK31: =AK30/AI30-1 -> 1.1620112 | AL31: =AL30/AK30-1 -> -0.7002584 | AM31: =AM30/AL30-1 -> 0.27586207 | AN31: =AN30/AM30-1 -> -0.21621622 | AP31: =AP30/AN30-1 -> -0.14655172 | AQ31: =AQ30/AP30-1 -> 0.12121212 | AR31: =AR30/AQ30-1 -> 0.28828829 | AS31: =AS30/AR30-1 -> 0.062937063 | AU31: =AU30/AS30-1 -> -0.092105263 | AV31: =AV30/AU30-1 -> 0.057971014 | AW31: =AW30/AV30-1 -> 0.32876712 | AX31: =AX30/AW30-1 -> -0.21134021 | AZ31: =AZ30/AX30-1 -> 1.1372549 | BA31: =BA30/AZ30-1 -> 0.25076453 | BB31: =BB30/BA30-1 -> -0.42787286 | BC31: =BC30/BB30-1 -> -0.17948718 | BE31: =BE30/BC30-1 -> -0.17708333 | BF31: =BF30/BE30-1 -> -0.11392405 | BG31: =BG30/BF30-1 -> -0.47857143 | BH31: =BH30/BG30-1 -> 0.15068493 | BJ31: =BJ30/BH30-1 -> -0.083333333 | BK31: =BK30/BJ30-1 -> -0.14285714 | BL31: =BL30/BK30-1 -> 0.10606061 | BM31: =BM30/BL30-1 -> 0.23287671 | BO31: =BO30/BM30-1 -> -0.13333333 | BP31: =BP30/BO30-1 -> 0.12820513 | BQ31: =BQ30/BP30-1 -> 0.10227273 | BR31: =BR30/BQ30-1 -> 0.29896907 | BT31: =BT30/BR30-1 -> -0.11904762 | BU31: =BU30/BT30-1 -> 0.55855856 | BV31: =BV30/BU30-1 -> 0.0057803468 | BW31: =BW30/BV30-1 -> -0.074712644 | BY31: =BY30/BW30-1 -> 0.24223602 | BZ31: =BZ30/BY30-1 -> -0.0485 | CA31: =CA30/BZ30-1 -> 0.0057803468 | CB31: =CB30/CA30-1 -> -0.074712644 | CD31: =CD30/CB30-1 -> 0.24223602 | CE31: =CE30/CD30-1 -> -0.0485 | CF31: =CF30/CE30-1 -> 0.0057803468 | CG31: =CG30/CF30-1 -> -0.074712644
A32: Y/Y OEM & IP Revenue Growth, % | U32: =+U30/P30-1 -> -0.13250653 | V32: =+V30/Q30-1 -> -0.38068182 | W32: =+W30/R30-1 -> -0.50985915 | X32: =+X30/S30-1 -> -0.45014245 | Y32: =+Y30/T30-1 -> -0.26937269 | Z32: =+Z30/U30-1 -> -0.41083521 | AA32: =+AA30/V30-1 -> -0.20642202 | AB32: =+AB30/W30-1 -> -0.063218391 | ... BY32: =+BY30/BT30-1 -> 0.8018018 | BZ32: 0.1 | CA32: 0.1 | CB32: 0.1 | CC32: =+CC30/BX30-1 -> 0.22584814 | CD32: 0.1 | CE32: 0.1 | CF32: 0.1 | CG32: 0.1 | CH32: =+CH30/CC30-1 -> 0.1 | CI32: 0.1 | CJ32: 0.1 | CK32: 0.1
A34: Total Revenue, mm | C34: =C300 -> 3424.859 | D34: =D300 -> 3326.445 | E34: =E300 -> 3543.309 | F34: =F300 -> 3997.93 | G34: =G300 -> 924.877 | H34: =H300 -> 1044.27 | I34: =I300 -> 1204.11 | J34: =J300 -> 1106.902 | ... O34: =O300 -> 1144.218 | P34: =P7+P11+P22+P26+P30 -> 4130 | Q34: =Q7+Q11+Q22+Q26+Q30 -> 1103 | R34: =R7+R11+R22+R26+R30 -> 1103 | S34: =S7+S11+S22+S26+S30 -> 1225 | T34: =T7+T11+T22+T26+T30 -> 1251 | U34: =U7+U11+U22+U26+U30 -> 4682 | V34: =V7+V11+V22+V26+V30 -> 1151 | W34: =W7+W11+W22+W26+W30 -> 1153 | ... BX34: =BX7+BX11+BX22+BX26+BX30 -> 215938 | BY34: =BY370 -> 81615 | BZ34: =BZ7+BZ11+BZ22+BZ26+BZ30 -> 90933.49 | CA34: =CA7+CA11+CA22+CA26+CA30 -> 91535.8 | CB34: =CB7+CB11+CB22+CB26+CB30 -> 94000.95 | CC34: =CC7+CC11+CC22+CC26+CC30 -> 358085.24 | CD34: =CD7+CD11+CD22+CD26+CD30 -> 105523.55 | CE34: =CE7+CE11+CE22+CE26+CE30 -> 117668.74 | CF34: =CF7+CF11+CF22+CF26+CF30 -> 114195.92 | CG34: =CG7+CG11+CG22+CG26+CG30 -> 116937.35 | ... CK34: =CK7+CK11+CK22+CK26+CK30 -> 747962.27
A35: =CONCATENATE("Consensus Estimates - ",IFERROR(LEFT(A34,FIND("(",A34)-1),A34)) -> Consensus Estimates - Total Revenue, mm | BZ35: =BZ371 -> N/A | CA35: =CA371 -> N/A | CB35: =CB371 -> N/A | CC35: =CC371 -> N/A | CD35: =CD371 -> N/A | CE35: =CE371 -> N/A | CF35: =CF371 -> N/A | CG35: =CG371 -> N/A | ... CK35: =CK371 -> N/A
A36: Guidance - Total Revenue, mm | BZ36: =BZ580 -> 91000 | CA36: =CA580 | CB36: =CB580 | CC36: =CC580 | CD36: =CD580 | CE36: =CE580 | CF36: =CF580 | CG36: =CG580 | ... CK36: =CK580 -> 0
A37: Q/Q Total Revenue growth, % | H37: =H34/G34-1 -> 0.12909068 | I37: =I34/H34-1 -> 0.15306386 | J37: =J34/I34-1 -> -0.080730166 | L37: =L34/J34-1 -> -0.13746745 | M37: =M34/L34-1 -> 0.023565603 | N37: =N34/M34-1 -> 0.078516185 | O37: =O34/N34-1 -> 0.085629816 | Q37: =Q34/O34-1 -> -0.036022856 | R37: =R34/Q34-1 -> 0 | S37: =S34/R34-1 -> 0.11060743 | T37: =T34/S34-1 -> 0.02122449 | V37: =V34/T34-1 -> -0.079936051 | W37: =W34/V34-1 -> 0.0017376195 | X37: =X34/W34-1 -> 0.13183001 | Y37: =Y34/X34-1 -> 0.073563218 | AA37: =AA34/Y34-1 -> -0.068522484 | AB37: =AB34/AA34-1 -> 0.094252874 | AC37: =AC34/AB34-1 -> 0.40336134 | AD37: =AD34/AC34-1 -> 0.084331337 | AF37: =AF34/AD34-1 -> -0.10860561 | AG37: =AG34/AF34-1 -> 0.15126484 | AH37: =AH34/AG34-1 -> 0.18206278 | AI37: =AI34/AH34-1 -> 0.10432473 | AK37: =AK34/AI34-1 -> 0.10168327 | AL37: =AL34/AK34-1 -> -0.026192703 | AM37: =AM34/AL34-1 -> 0.018571886 | AN37: =AN34/AM34-1 -> -0.30682175 | AP37: =AP34/AN34-1 -> 0.0068027211 | AQ37: =AQ34/AP34-1 -> 0.16171171 | AR37: =AR34/AQ34-1 -> 0.16867003 | AS37: =AS34/AR34-1 -> 0.030192435 | AU37: =AU34/AS34-1 -> -0.0080515298 | AV37: =AV34/AU34-1 -> 0.25519481 | AW37: =AW34/AV34-1 -> 0.22245215 | AX37: =AX34/AW34-1 -> 0.058611934 | AZ37: =AZ34/AX34-1 -> 0.13152109 | BA37: =BA34/AZ34-1 -> 0.14944356 | BB37: =BB34/BA34-1 -> 0.091593668 | BC37: =BC34/BB34-1 -> 0.076024215 | BE37: =BE34/BC34-1 -> 0.084390946 | BF37: =BF34/BE34-1 -> -0.19111969 | BG37: =BG34/BF34-1 -> -0.1153043 | BH37: =BH34/BG34-1 -> 0.020232676 | BJ37: =BJ34/BH34-1 -> 0.18856387 | BK37: =BK34/BJ34-1 -> 0.87805895 | BL37: =BL34/BK34-1 -> 0.34152662 | BM37: =BM34/BL34-1 -> 0.21981236 | BO37: =BO34/BM34-1 -> 0.17830159 | BP37: =BP34/BO34-1 -> 0.15343265 | BQ37: =BQ34/BP34-1 -> 0.16784288 | BR37: =BR34/BQ34-1 -> 0.12111624 | BT37: =BT34/BR34-1 -> 0.1202868 | BU37: =BU34/BT34-1 -> 0.060846081 | BV37: =BV34/BU34-1 -> 0.21956229 | BW37: =BW34/BV34-1 -> 0.19508473 | BY37: =BY34/BW34-1 -> 0.19798318 | BZ37: =BZ34/BY34-1 -> 0.11417619 | CA37: =CA34/BZ34-1 -> 0.0066236323 | CB37: =CB34/CA34-1 -> 0.026930993 | CD37: =CD34/CB34-1 -> 0.12257961 | CE37: =CE34/CD34-1 -> 0.11509459 | CF37: =CF34/CE34-1 -> -0.029513527 | CG37: =CG34/CF34-1 -> 0.024006396
A38: Y/Y Total Revenue Growth, % | D38: =D34/C34-1 -> -0.028735198 | E38: =E34/D34-1 -> 0.065193923 | F38: =F34/E34-1 -> 0.12830408 | K38: =K34/F34-1 -> 0.070593782 | L38: =L34/G34-1 -> 0.032287537 | M38: =M34/H34-1 -> -0.064190296 | N38: =N34/I34-1 -> -0.1246921 | O38: =O34/J34-1 -> 0.033712108 | P38: =P34/K34-1 -> -0.035082575 | Q38: =Q34/L34-1 -> 0.15528956 | R38: =R34/M34-1 -> 0.12869127 | ... CH38: =CH34/CC34-1 -> 0.26876372 | CI38: =CI34/CH34-1 -> 0.19277198 | CJ38: =CJ34/CI34-1 -> 0.17466733 | CK38: =CK34/CJ34-1 -> 0.1750063
A40: Product0075 Revenue, mm | BR40: 11000
A41: CMP Revenue, mm | AF41: 289 | AK41: 0 | AY41: 0 | AZ41: 155 | BA41: 266 | BB41: 105 | BC41: =BD41-SUM(AZ41,BA41,BB41) -> 24 | BD41: 550 | BE41: 0 | BF41: 0 | BG41: 0 | BH41: =BI41-SUM(BE41,BF41,BG41) -> 0 | BI41: 0 | BM41: =BN41-SUM(BJ41,BK41,BL41) -> 0 | BR41: =BS41-SUM(BO41,BP41,BQ41) -> 0
A43: Operating Expense Forecasting
A44: Revenue, mm | C44: =C300 -> 3424.859 | D44: =D300 -> 3326.445 | E44: =E300 -> 3543.309 | F44: =F300 -> 3997.93 | G44: =G300 -> 924.877 | H44: =H300 -> 1044.27 | I44: =I300 -> 1204.11 | J44: =J300 -> 1106.902 | ... O44: =O300 -> 1144.218 | P44: =P34 -> 4130 | Q44: =Q34 -> 1103 | R44: =R34 -> 1103 | S44: =S34 -> 1225 | T44: =T34 -> 1251 | U44: =U34 -> 4682 | V44: =V34 -> 1151 | W44: =W34 -> 1153 | ... CK44: =CK34 -> 747962.27
A45: Cost of revenue, mm | C45: =C301 -> 2250.59 | D45: =D301 -> 2149.522 | E45: =E301 -> 2134.219 | F45: =F301 -> 1941.413 | G45: =G301 -> 461.513 | H45: =H301 -> 503.551 | I45: =I301 -> 567.452 | J45: =J301 -> 521.3 | ... BY45: =BY301 -> 20458 | BZ45: =BZ44-BZ46 -> 22867.418 | CA45: =CA44-CA46 -> 23324.634 | CB45: =CB44-CB46 -> 22497.278 | CC45: =CC44-CC46 -> 89147.33 | CD45: =CD44-CD46 -> 26459.582 | CE45: =CE44-CE46 -> 29590.641 | CF45: =CF44-CF46 -> 29098.757 | CG45: =CG44-CG46 -> 27986.654 | ... CK45: =CK44-CK46 -> 187004.68
A46: GAAP Gross Profit, mm | C46: =C44-C45 -> 1174.269 | D46: =D44-D45 -> 1176.923 | E46: =E44-E45 -> 1409.09 | F46: =F44-F45 -> 2056.517 | G46: =G44-G45 -> 463.364 | H46: =H44-H45 -> 540.719 | I46: =I44-I45 -> 636.658 | J46: =J44-J45 -> 585.602 | ... BY46: =BY44-BY45 -> 61157 | BZ46: =BZ57-BZ55-BZ53-BZ51 -> 68066.072 | CA46: =CA57-CA55-CA53-CA51 -> 68211.166 | CB46: =CB57-CB55-CB53-CB51 -> 71503.672 | CC46: =SUM(BY46,BZ46,CA46,CB46) -> 268937.91 | CD46: =CD57-CD55-CD53-CD51 -> 79063.968 | CE46: =CE57-CE55-CE53-CE51 -> 88078.099 | CF46: =CF57-CF55-CF53-CF51 -> 85097.163 | CG46: =CG57-CG55-CG53-CG51 -> 88950.698 | CH46: =SUM(CD46,CE46,CF46,CG46) -> 341189.93 | CI46: =CI57-CI55-CI53-CI51 -> 406419.88 | CJ46: =CJ57-CJ55-CJ53-CJ51 -> 477408.15 | CK46: =CK57-CK55-CK53-CK51 -> 560957.59
A47: Y/Y growth in Gross Profit, % | D47: =D46/C46-1 -> 0.0022601295 | E47: =E46/D46-1 -> 0.19726609 | F47: =F46/E46-1 -> 0.45946462 | K47: =K46/F46-1 -> 0.082579429 | L47: =L46/G46-1 -> 0.11913744 | M47: =M46/H46-1 -> 0.0089122076 | N47: =N46/I46-1 -> -0.082058185 | O47: =O46/J46-1 -> 0.057445159 | P47: =P46/K46-1 -> 0.018531736 | Q47: =Q46/L46-1 -> 0.16474599 | R47: =R46/M46-1 -> 0.13465973 | ... CH47: =CH46/CC46-1 -> 0.26865687 | CI47: =CI46/CH46-1 -> 0.1911837 | CJ47: =CJ46/CI46-1 -> 0.17466733 | CK47: =CK46/CJ46-1 -> 0.1750063
A48: GAAP Gross Margin, % | C48: =C46/C44 -> 0.34286638 | D48: =D46/D44 -> 0.35380804 | E48: =E46/E44 -> 0.3976763 | F48: =F46/F44 -> 0.51439545 | G48: =G46/G44 -> 0.50100067 | H48: =H46/H44 -> 0.51779616 | I48: =I46/I44 -> 0.52873741 | J48: =J46/J44 -> 0.52904593 | ... CK48: =CK46/CK44 -> 0.74998114
...

Sheet Exec Comp
A1: =MO.CompanyName -> Company1915 Company0697
A2: =MO.Ticker -> Ticker0027 US | C2: =Model!C2 -> 39478 | D2: =Model!D2 -> 0 | E2: =Model!E2 -> 0 | F2: =Model!F2 -> 0 | G2: =Model!G2 -> 0 | H2: =Model!H2 -> 0 | I2: =Model!I2 -> 0 | J2: =Model!J2 -> 0 | ... CK2: =Model!CK2 -> 0
A3: =MO.TradingCurrency -> USD | B3: =MO.LastPrice -> 222.82 | C3: =INDEX(MO_Common_FPDays,0,MATCH(C$5,MO_Common_ColumnHeader,0)) -> 360 | D3: =INDEX(MO_Common_FPDays,0,MATCH(D$5,MO_Common_ColumnHeader,0)) -> 371 | E3: =INDEX(MO_Common_FPDays,0,MATCH(E$5,MO_Common_ColumnHeader,0)) -> 364 | F3: =INDEX(MO_Common_FPDays,0,MATCH(F$5,MO_Common_ColumnHeader,0)) -> 364 | G3: =INDEX(MO_Common_FPDays,0,MATCH(G$5,MO_Common_ColumnHeader,0)) -> 91 | H3: =INDEX(MO_Common_FPDays,0,MATCH(H$5,MO_Common_ColumnHeader,0)) -> 91 | I3: =INDEX(MO_Common_FPDays,0,MATCH(I$5,MO_Common_ColumnHeader,0)) -> 91 | J3: =INDEX(MO_Common_FPDays,0,MATCH(J$5,MO_Common_ColumnHeader,0)) -> 91 | ... CK3: =INDEX(MO_Common_FPDays,0,MATCH(CK$5,MO_Common_ColumnHeader,0)) -> 365
A4: =MO.DataSourceName -> Bloomberg | B4: =MO.RealTime -> OFF | C4: =INDEX(MO_Common_QEndDate,0,MATCH(C$5,MO_Common_ColumnHeader,0)) -> 39838 | D4: =INDEX(MO_Common_QEndDate,0,MATCH(D$5,MO_Common_ColumnHeader,0)) -> 40209 | E4: =INDEX(MO_Common_QEndDate,0,MATCH(E$5,MO_Common_ColumnHeader,0)) -> 40573 | F4: =INDEX(MO_Common_QEndDate,0,MATCH(F$5,MO_Common_ColumnHeader,0)) -> 40937 | G4: =INDEX(MO_Common_QEndDate,0,MATCH(G$5,MO_Common_ColumnHeader,0)) -> 41028 | H4: =INDEX(MO_Common_QEndDate,0,MATCH(H$5,MO_Common_ColumnHeader,0)) -> 41119 | I4: =INDEX(MO_Common_QEndDate,0,MATCH(I$5,MO_Common_ColumnHeader,0)) -> 41210 | J4: =INDEX(MO_Common_QEndDate,0,MATCH(J$5,MO_Common_ColumnHeader,0)) -> 41301 | ... CK4: =INDEX(MO_Common_QEndDate,0,MATCH(CK$5,MO_Common_ColumnHeader,0)) -> 47879
A5: =MO.ReportFX -> USD | C5: =Model!C5 -> FY2009 | D5: =Model!D5 -> FY2010 | E5: =Model!E5 -> FY2011 | F5: =Model!F5 -> FY2012 | G5: =Model!G5 -> Q1-2013 | H5: =Model!H5 -> Q2-2013 | I5: =Model!I5 -> Q3-2013 | J5: =Model!J5 -> Q4-2013 | ... CK5: =Model!CK5 -> FY2031
A6: Executive Compensation
A7: CEO - Base Pay, 000s | AT7: 996.514 | AY7: 1017.355 | BD7: 996.216 | BI7: 996.832 | BN7: 996.514 | BS7: 1486.199
A8: CEO - Stock Awards, 000s | AT8: 9676.92 | AY8: 15279.78 | BD8: 18660.407 | BI8: 19666.382 | BN8: 26676.415 | BS8: 38811.306
A9: CEO - Non-equity incentive plans, 000s | AT9: 805.444 | AY9: 3000 | BD9: 4000 | BI9: 0 | BN9: 4000 | BS9: 6000
A10: CEO - All other compensation, 000s | AT10: 13.402 | AY10: 19.266 | BD10: 81.038 | BI10: 693.71 | BN10: 2494.973 | BS10: 3568.746
A11: CEO - Total Comp, 000s | AT11: =SUM(AT7:AT10) -> 11492.28 | AY11: =SUM(AY7:AY10) -> 19316.401 | BD11: =SUM(BD7:BD10) -> 23737.661 | BI11: =SUM(BI7:BI10) -> 21356.924 | BN11: =SUM(BN7:BN10) -> 34167.902 | BS11: =SUM(BS7:BS10) -> 49866.251
A12: CEO - comp tied to equity, % | AT12: =SUM(AT8)/AT11 -> 0.84203657 | AY12: =SUM(AY8)/AY11 -> 0.79102624 | BD12: =SUM(BD8)/BD11 -> 0.78610976 | BI12: =SUM(BI8)/BI11 -> 0.92084338 | BN12: =SUM(BN8)/BN11 -> 0.78074489 | BS12: =SUM(BS8)/BS11 -> 0.77830808
A13: Market Cap - EoP, mm | AT13: =Model!AT754 -> 152648.01 | AU13: =Model!AU754 -> 185940.58 | AV13: =Model!AV754 -> 266199.12 | AW13: =Model!AW754 -> 316358.16 | AX13: =Model!AX754 -> 328380.88 | AY13: =Model!AY754 -> 327861.29 | AZ13: =Model!AZ754 -> 388635.66 | BA13: =Model!BA754 -> 494299.65 | ... BY13: =Model!BY754 -> 5066376
A15: CEO - Options 09/14/2020 # of unexercised exercisable options, 000s | AT15: 250
A16: CEO - Options 09/14/2020 exercise price, $ | AT16: 10.56
A18: CEO - Options 03/17/2021 # of unexercised exercisable options, 000s | AT18: 250 | AY18: 50
A19: CEO - Options 03/17/2021 exercise price, $ | AT19: 17.62 | AY19: 17.62
A21: CEO - Options 09/20/2021 # of unexercised exercisable options, 000s | AT21: 250 | AY21: 250
A22: CEO - Options 09/20/2021 exercise price, $ | AT22: 14.465 | AY22: 14.465
A24: CEO - Options 03/20/2022 # of unexercised exercisable options, 000s | AT24: 300 | AY24: 300 | BD24: 292.34
A25: CEO - Options 03/20/2022 exercise price, $ | AT25: 14.46 | AY25: 14.46 | BD25: 3.615
A27: CEO - Options 09/18/2022 # of unexercised exercisable options, 000s | AT27: 300 | AY27: 300 | BD27: 1200
A28: CEO - Options 09/18/2022 exercise price, $ | AT28: 13.71 | AY28: 13.71 | BD28: 3.4275
A30: CEO - Options 03/19/2023 # of unexercised exercisable options, 000s | AT30: 237.5 | AY30: 237.5 | BD30: 950
A31: CEO - Options 03/19/2023 exercise price, $ | AT31: 12.62 | AY31: 12.62 | BD31: 3.155
A33: CEO - Options 09/17/2023 # of unexercised excercisable options, 000s | AT33: 237.5 | AY33: 237.5 | BD33: 950 | BI33: 475
A34: CEO - Options 09/17/2023 exercise price, $ | AT34: 16 | AY34: 16 | BD34: 4 | BI34: 4
A36: CEO - EoP shares owned, 000s | AT36: =(21462.889*(10))*(4) -> 858515.56 | AY36: =(21375.455*(10))*(4) -> 855018.2 | BD36: =84421.722*(10) -> 844217.22 | BI36: =86403.193*(10) -> 864031.93 | BN36: =93463.791*(10) -> 934637.91 | BS36: 922922.94
A37: CEO - EoP Shares Issuable Within 60 days, 000s | AT37: =(1825*(10))*(4) -> 73000 | AY37: =(1325*(10))*(4) -> 53000 | BD37: =3100*(10) -> 31000 | BI37: =475*(10) -> 4750
A38: CEO - EoP shares beneficially owned, 000s | AT38: =SUM(AT36:AT37) -> 931515.56 | AY38: =SUM(AY36:AY37) -> 908018.2 | BD38: =SUM(BD36:BD37) -> 875217.22 | BI38: =SUM(BI36:BI37) -> 868781.93 | BN38: =SUM(BN36:BN37) -> 934637.91 | BS38: =SUM(BS36:BS37) -> 922922.94
A40: CFO - Base Pay, 000s | AT40: 896.863 | AY40: 915.62 | BD40: 896.595 | BI40: 897.149 | BN40: 896.863 | BS40: 893.739
A41: CFO - Stock Awards, 000s | AT41: 3307.188 | AY41: 6595.691 | BD41: 8269.02 | BI41: 10004.677 | BN41: 11756.027 | BS41: 19849.891
A42: CFO - Non-equity incentive plans, 000s | AT42: 219.667 | AY42: 600 | BD42: 600 | BI42: 0 | BN42: 600 | BS42: 600
A43: CFO - All other compensation, 000s | AT43: 9.122 | AY43: 9.731 | BD43: 10.312 | BI43: 15.402 | BN43: 13.902 | BS43: 18.902
A44: CFO - Total Comp, 000s | AT44: =SUM(AT40:AT43) -> 4432.84 | AY44: =SUM(AY40:AY43) -> 8121.042 | BD44: =SUM(BD40:BD43) -> 9775.927 | BI44: =SUM(BI40:BI43) -> 10917.228 | BN44: =SUM(BN40:BN43) -> 13266.792 | BS44: =SUM(BS40:BS43) -> 21362.532
A45: CFO - comp tied to equity, % | AT45: =SUM(AT41)/AT44 -> 0.74606528 | AY45: =SUM(AY41)/AY44 -> 0.81217299 | BD45: =SUM(BD41)/BD44 -> 0.84585533 | BI45: =SUM(BI41)/BI44 -> 0.91641184 | BN45: =SUM(BN41)/BN44 -> 0.88612432 | BS45: =SUM(BS41)/BS44 -> 0.92919187
A47: CFO - EoP shares owned, 000s | AT47: 81.792 | AY47: 98.873 | BD47: 447.471 | BI47: 478.297 | BN47: 515.421 | BS47: 4872.485
A48: CFO - EoP Shares Issuable Within 60 days, 000s
A49: CFO - EoP shares beneficially owned, 000s | AT49: =SUM(AT47:AT47) -> 81.792 | AY49: =SUM(AY47:AY47) -> 98.873 | BD49: =SUM(BD47:BD47) -> 447.471 | BI49: =SUM(BI47:BI47) -> 478.297 | BN49: =SUM(BN47:BN48) -> 515.421 | BS49: =SUM(BS47:BS48) -> 4872.485
A51: Board Diversity
...

Sheet Guidance
B1: =MO.CompanyName -> Company1915 Company0697
B2: Most Recent Period: | F2: =UL.MRQ -> Q1-2027
I4: Guidance | M4: Model | P4: Difference vs. Mid | S4: Update Log
B5: Type | D5: Item | E5: Item Name | F5: Fiscal Period | G5: Base Period | I5: Low | J5: High | K5: Mid | M5: Type | N5: Output | P5: Absolute | Q5: Relative | S5: Date | T5: Link
A6: 404 | B6: =IF(INDEX(MO_SNA_IsHistoricalPeriod,,MATCH(F6,MO_Common_ColumnHeader,0)),"Historical","Forward") -> Forward | D6: =INDEX(INDIRECT(E6),0,COLUMN(MO_Common_Column_A)) -> Net Revenue | E6: MO_RIS_REV | F6: Q2-2027 | I6: =91000*0.98 -> 89180 | J6: =91000*1.02 -> 92820 | K6: =AVERAGE(I6:J6) -> 91000 | M6: =IF(INDEX(MO_SNA_IsHistoricalPeriod,,MATCH(F6,MO_Common_ColumnHeader,0)),"Actual","Estimate") -> Estimate | N6: =IFERROR(INDEX(INDIRECT(E6),0,MATCH(F6,MO_Common_ColumnHeader,0)),"N/A") -> 90933.49 | P6: =IF(ISNUMBER(N6),N6-K6,"N/A") -> -66.51 | Q6: =IFERROR(IF(ISNUMBER(N6),(N6-K6)/ABS(K6),"N/A"),"N/A") -> -0.00073087912 | S6: 46162 | T6: CFO Commentary
A7: 403 | B7: =IF(INDEX(MO_SNA_IsHistoricalPeriod,,MATCH(F7,MO_Common_ColumnHeader,0)),"Historical","Forward") -> Forward | D7: =INDEX(INDIRECT(E7),0,COLUMN(MO_Common_Column_A)) -> GAAP Gross Margin, % | E7: MO_MA_GM | F7: Q2-2027 | I7: 0.744 | J7: 0.754 | K7: =AVERAGE(I7:J7) -> 0.749 | M7: =IF(INDEX(MO_SNA_IsHistoricalPeriod,,MATCH(F7,MO_Common_ColumnHeader,0)),"Actual","Estimate") -> Estimate | N7: =IFERROR(INDEX(INDIRECT(E7),0,MATCH(F7,MO_Common_ColumnHeader,0)),"N/A") -> 0.7485259 | P7: =IF(ISNUMBER(N7),N7-K7,"N/A") -> -0.00047410307 | Q7: =IFERROR(IF(ISNUMBER(N7),(N7-K7)/ABS(K7),"N/A"),"N/A") -> -0.00063298141 | S7: 46162 | T7: CFO Commentary
A8: 402 | B8: =IF(INDEX(MO_SNA_IsHistoricalPeriod,,MATCH(F8,MO_Common_ColumnHeader,0)),"Historical","Forward") -> Forward | D8: =INDEX(INDIRECT(E8),0,COLUMN(MO_Common_Column_A)) -> Non-GAAP Gross Margin, % | E8: MO_MA_GM_NONGAAP | F8: Q2-2027 | I8: 0.745 | J8: 0.755 | K8: =AVERAGE(I8:J8) -> 0.75 | M8: =IF(INDEX(MO_SNA_IsHistoricalPeriod,,MATCH(F8,MO_Common_ColumnHeader,0)),"Actual","Estimate") -> Estimate | N8: =IFERROR(INDEX(INDIRECT(E8),0,MATCH(F8,MO_Common_ColumnHeader,0)),"N/A") -> 0.7495259 | P8: =IF(ISNUMBER(N8),N8-K8,"N/A") -> -0.00047410307 | Q8: =IFERROR(IF(ISNUMBER(N8),(N8-K8)/ABS(K8),"N/A"),"N/A") -> -0.00063213743 | S8: 46162 | T8: CFO Commentary
A9: 401 | B9: =IF(INDEX(MO_SNA_IsHistoricalPeriod,,MATCH(F9,MO_Common_ColumnHeader,0)),"Historical","Forward") -> Forward | D9: GAAP Operating Expenses | F9: Q2-2027 | I9: 8500 | J9: 8500 | K9: =AVERAGE(I9:J9) -> 8500 | M9: =IF(INDEX(MO_SNA_IsHistoricalPeriod,,MATCH(F9,MO_Common_ColumnHeader,0)),"Actual","Estimate") -> Estimate | N9: =INDEX(MO_RIS_RD,0,MATCH(F9,MO_Common_ColumnHeader,0))+INDEX(MO_RIS_SGA,0,MATCH(F9,MO_Common_ColumnHeader,0)) -> 8521.3347 | P9: =IF(ISNUMBER(N9),N9-K9,"N/A") -> 21.334685 | Q9: =IFERROR(IF(ISNUMBER(N9),(N9-K9)/ABS(K9),"N/A"),"N/A") -> 0.002509963 | S9: 46162 | T9: CFO Commentary
A10: 400 | B10: =IF(INDEX(MO_SNA_IsHistoricalPeriod,,MATCH(F10,MO_Common_ColumnHeader,0)),"Historical","Forward") -> Forward | D10: =INDEX(INDIRECT(E10),0,COLUMN(MO_Common_Column_A)) -> Total Non-GAAP Operating Expenses, mm | E10: MO_OS_OPEX | F10: Q2-2027 | I10: 8300 | J10: 8300 | K10: =AVERAGE(I10:J10) -> 8300 | M10: =IF(INDEX(MO_SNA_IsHistoricalPeriod,,MATCH(F10,MO_Common_ColumnHeader,0)),"Actual","Estimate") -> Estimate | N10: =IFERROR(INDEX(INDIRECT(E10),0,MATCH(F10,MO_Common_ColumnHeader,0)),"N/A") -> 8321.281 | P10: =IF(ISNUMBER(N10),N10-K10,"N/A") -> 21.281007 | Q10: =IFERROR(IF(ISNUMBER(N10),(N10-K10)/ABS(K10),"N/A"),"N/A") -> 0.0025639768 | S10: 46162 | T10: CFO Commentary
A11: 399 | B11: =IF(INDEX(MO_SNA_IsHistoricalPeriod,,MATCH(F11,MO_Common_ColumnHeader,0)),"Historical","Forward") -> Forward | D11: GAAP Tax Rate | E11: MO_RIS_TaxRate | F11: Q2-2027 | I11: 0.16 | J11: 0.18 | K11: =AVERAGE(I11:J11) -> 0.17 | M11: =IF(INDEX(MO_SNA_IsHistoricalPeriod,,MATCH(F11,MO_Common_ColumnHeader,0)),"Actual","Estimate") -> Estimate | N11: =IFERROR(INDEX(INDIRECT(E11),0,MATCH(F11,MO_Common_ColumnHeader,0)),"N/A") -> 0.17009796 | P11: =IF(ISNUMBER(N11),N11-K11,"N/A") -> 9.7956254e-05 | Q11: =IFERROR(IF(ISNUMBER(N11),(N11-K11)/ABS(K11),"N/A"),"N/A") -> 0.00057621326 | S11: 46162 | T11: CFO Commentary
A12: 398 | B12: =IF(INDEX(MO_SNA_IsHistoricalPeriod,,MATCH(F12,MO_Common_ColumnHeader,0)),"Historical","Forward") -> Forward | D12: =INDEX(INDIRECT(E12),0,COLUMN(MO_Common_Column_A)) -> Non-GAAP Tax Rate | E12: MO_RIS_TaxRate_NONGAAP | F12: Q2-2027 | I12: 0.16 | J12: 0.18 | K12: =AVERAGE(I12:J12) -> 0.17 | M12: =IF(INDEX(MO_SNA_IsHistoricalPeriod,,MATCH(F12,MO_Common_ColumnHeader,0)),"Actual","Estimate") -> Estimate | N12: =IFERROR(INDEX(INDIRECT(E12),0,MATCH(F12,MO_Common_ColumnHeader,0)),"N/A") -> 0.17 | P12: =IF(ISNUMBER(N12),N12-K12,"N/A") -> 2.7755576e-17 | Q12: =IFERROR(IF(ISNUMBER(N12),(N12-K12)/ABS(K12),"N/A"),"N/A") -> 1.6326809e-16 | S12: 46162 | T12: CFO Commentary
A13: 397
