Workbook

Sheet Income Stmnt
B5: Company0786 Consolidated Income Statements with Forecasts
H6: 2021A | I6: 2022A | J6: 2023A | K6: 2024P | L6: 2025P | M6: 2026P | N6: 2027P | O6: 2028P | Q6: Notes/Assumptions
B7: Consolidated Net Sales and Revenues | H7: 44024 | I7: 52577 | J7: 61251 | K7: =J7*(1+K8) -> 72253.44 | L7: =K7*(1+L8) -> 85232.234 | M7: =L7*(1+M8) -> 100542.39 | N7: =M7*(1+N8) -> 118602.7 | O7: =N7*(1+O8) -> 139907.15
D8: Revenue Growth Rate | I8: =I7/H7-1 -> 0.19428039 | J8: =J7/I7-1 -> 0.16497708 | K8: =AVERAGE($I$8:$J$8) -> 0.17962874 | L8: =AVERAGE($I$8:$J$8) -> 0.17962874 | M8: =AVERAGE($I$8:$J$8) -> 0.17962874 | N8: =AVERAGE($I$8:$J$8) -> 0.17962874 | O8: =AVERAGE($I$8:$J$8) -> 0.17962874 | Q8: =AVERAGE(H8:J8) -> 0.17962874 | R8: Revenue growth rate averaged from last three years' growth
B9: Cost of Sales | H9: 29116 | I9: 35338 | J9: 37715 | K9: =K7*K10 -> 46946.204 | L9: =L7*L10 -> 55379.092 | M9: =M7*M10 -> 65326.768 | N9: =N7*N10 -> 77061.333 | O9: =O7*O10 -> 90903.763 | Q9: =AVERAGE(I9/H9-1,J9/I9-1) -> 0.14048082 | R9: Average Cost of Sales growth rate from 3 years historicals
D10: COGS Margin % | H10: =H9/H7 -> 0.66136653 | I10: =I9/I7 -> 0.67211899 | J10: =J9/J7 -> 0.61574505 | K10: =AVERAGE($H$10:$J$10) -> 0.64974352 | L10: =AVERAGE($H$10:$J$10) -> 0.64974352 | M10: =AVERAGE($H$10:$J$10) -> 0.64974352 | N10: =AVERAGE($H$10:$J$10) -> 0.64974352 | O10: =AVERAGE($H$10:$J$10) -> 0.64974352 | Q10: =AVERAGE(H10:J10) -> 0.64974352 | R10: Average Cost of Sales Margin from historicals
B11: Gross Profit | H11: =H7-H9 -> 14908 | I11: =I7-I9 -> 17239 | J11: =J7-J9 -> 23536 | K11: =K7-K9 -> 25307.235 | L11: =L7-L9 -> 29853.142 | M11: =M7-M9 -> 35215.624 | N11: =N7-N9 -> 41541.362 | O11: =O7-O9 -> 49003.385
C12: Research and development expenses | H12: 1587 | I12: 1912 | J12: 2177 | K12: =K7*K13 -> 2600.0763 | L12: =L7*L13 -> 3067.1248 | M12: =M7*M13 -> 3618.0685 | N12: =N7*N13 -> 4267.9776 | O12: =O7*O13 -> 5034.629
D13: R&D Exp Margin % | H13: =H12/H7 -> 0.036048519 | I13: =I12/I7 -> 0.036365711 | J13: =J12/J7 -> 0.035542277 | K13: =AVERAGE($H$13:$J$13) -> 0.035985502 | L13: =AVERAGE($H$13:$J$13) -> 0.035985502 | M13: =AVERAGE($H$13:$J$13) -> 0.035985502 | N13: =AVERAGE($H$13:$J$13) -> 0.035985502 | O13: =AVERAGE($H$13:$J$13) -> 0.035985502 | R13: Margin% assumption from average historical years'
C14: Selling, administrative and general expenses | H14: 3383 | I14: 3863 | J14: 4595 | K14: =K7*K15 -> 5427.1202 | L14: =L7*L15 -> 6401.9869 | M14: =M7*M15 -> 7551.9678 | N14: =N7*N15 -> 8908.5182 | O14: =O7*O15 -> 10508.744
D15: SG&A Exp Margin % | H15: =H14/H7 -> 0.076844448 | I15: =I14/I7 -> 0.073473192 | J15: =J14/J7 -> 0.075019183 | K15: =AVERAGE($H$15:$J$15) -> 0.075112275 | L15: =AVERAGE($H$15:$J$15) -> 0.075112275 | M15: =AVERAGE($H$15:$J$15) -> 0.075112275 | N15: =AVERAGE($H$15:$J$15) -> 0.075112275 | O15: =AVERAGE($H$15:$J$15) -> 0.075112275 | R15: Margin% assumption from average historical years'
C16: Other operating expenses | H16: 1343 | I16: 1275 | J16: 1292 | K16: =K7*K17 -> 1826.8022 | L16: =L7*L17 -> 2154.9484 | M16: =M7*M17 -> 2542.0391 | N16: =N7*N17 -> 2998.6623 | O16: =O7*O17 -> 3537.3082
D17: Margin % | H17: =H16/H7 -> 0.030506088 | I17: =I16/I7 -> 0.024250147 | J17: =J16/J7 -> 0.021093533 | K17: =AVERAGE($H$17:$J$17) -> 0.025283256 | L17: =AVERAGE($H$17:$J$17) -> 0.025283256 | M17: =AVERAGE($H$17:$J$17) -> 0.025283256 | N17: =AVERAGE($H$17:$J$17) -> 0.025283256 | O17: =AVERAGE($H$17:$J$17) -> 0.025283256 | R17: Margin% assumption from average historical years'
B18: Operating Income | H18: =H11-(SUM(H12:H16)) -> 8594.8871 | I18: =I11-(SUM(I12:I16)) -> 10188.89 | J18: =J11-(SUM(J12:J16)) -> 15471.889 | K18: =K11-K12-K14-K16 -> 15453.237 | L18: =L11-L12-L14-L16 -> 18229.082 | M18: =M11-M12-M14-M16 -> 21503.549 | N18: =N11-N12-N14-N16 -> 25366.204 | O18: =O11-O12-O14-O16 -> 29922.704
C19: Interest expense | H19: 993 | I19: 1062 | J19: 2453 | K19: =J19 -> 2453 | L19: =J19 -> 2453 | M19: =J19 -> 2453 | N19: =J19 -> 2453 | O19: =J19 -> 2453
B20: EBT Excl. Unusual Items | H20: =H18-H19 -> 7601.8871 | I20: 9127 | J20: 13019 | K20: =K18-K19 -> 13000.237 | L20: =L18-L19 -> 15776.082 | M20: =M18-M19 -> 19050.549 | N20: =N18-N19 -> 22913.204 | O20: =O18-O19 -> 27469.704
C21: Provision for income taxes | H21: 1658 | I21: 2007 | J21: 2871 | K21: =K20*$Q$22 -> 2853.6585 | L21: =L20*$Q$22 -> 3462.9794 | M21: =M20*$Q$22 -> 4181.7517 | N21: =N20*$Q$22 -> 5029.6362 | O21: =O20*$Q$22 -> 6029.8252
D22: Tax % | H22: =H21/H20 -> 0.21810374 | I22: =I21/I20 -> 0.21989701 | J22: =J21/J20 -> 0.22052385 | K22: =$Q$22 -> 0.2195082 | L22: =$Q$22 -> 0.2195082 | M22: =$Q$22 -> 0.2195082 | N22: =$Q$22 -> 0.2195082 | O22: =$Q$22 -> 0.2195082 | Q22: =AVERAGE(H22:J22) -> 0.2195082 | R22: Average Tax Rate based on average of historical years' tax provision
C23: Equity in income of unconsolidated affiliates | H23: 21 | I23: 10 | J23: 7 | K23: =J23 -> 7 | L23: =K23 -> 7 | M23: =L23 -> 7 | N23: =M23 -> 7 | O23: =N23 -> 7 | R23: Straight-line assumption from previous year
B24: Net Income | H24: =H20-H21+H23 -> 5964.8871 | I24: =I20-I21+I23 -> 7130 | J24: =J20-J21+J23 -> 10155 | K24: =K20-K21+K23 -> 10153.578 | L24: =L20-L21+L23 -> 12320.103 | M24: =M20-M21+M23 -> 14875.797 | N24: =N20-N21+N23 -> 17890.568 | O24: =O20-O21+O23 -> 21446.878

Sheet Cash Flow Stmnt
B3: Company0786 Statements of Consolidated Cash Flows with Forecasts
H4: 2021A | I4: 2022A | J4: 2023A | K4: 2024P | L4: 2025P | M4: 2026P | N4: 2027P | O4: 2028P | Q4: Notes/Assumptions
B5: Cash Flows from Operating Activities
B6: Net income | H6: ='Income Stmnt'!H24 -> 5964.8871 | I6: ='Income Stmnt'!I24 -> 7130 | J6: ='Income Stmnt'!J24 -> 10155 | K6: ='Income Stmnt'!K24 -> 10153.578 | L6: ='Income Stmnt'!L24 -> 12320.103 | M6: ='Income Stmnt'!M24 -> 14875.797 | N6: ='Income Stmnt'!N24 -> 17890.568 | O6: ='Income Stmnt'!O24 -> 21446.878 | Q6: Reference Income Statement
B7: Adjustments to reconcile net income to net cash provided by operating activities:
C8: Provision (credit) for credit losses | H8: -6 | I8: 192 | J8: -16 | K8: =J8 -> -16 | L8: =K8 -> -16 | M8: =L8 -> -16 | N8: =M8 -> -16 | O8: =N8 -> -16 | Q8: Straight-line assumption
C9: Provision for depreciation and amortization | H9: 2050 | I9: 1895 | J9: 2004 | K9: ='Balance Sheet'!J62 -> 2423.8681 | L9: ='Balance Sheet'!K62 -> 2685.1375 | M9: ='Balance Sheet'!L62 -> 3167.4654 | N9: ='Balance Sheet'!M62 -> 3736.4332 | O9: ='Balance Sheet'!N62 -> 4407.6039 | Q9: Refer to D&A Schedule
C10: Impairments and other adjustments | H10: 50 | I10: 88 | J10: 191 | K10: =J10 -> 191 | L10: =K10 -> 191 | M10: =L10 -> 191 | N10: =M10 -> 191 | O10: =N10 -> 191 | Q10: Straight-line assumption
C11: Share-based compensation expense | H11: 82 | I11: 85 | J11: 130 | K11: =J11*(1+'Income Stmnt'!$Q$8) -> 153.35174 | L11: =K11*(1+'Income Stmnt'!$Q$8) -> 180.89811 | M11: =L11*(1+'Income Stmnt'!$Q$8) -> 213.39261 | N11: =M11*(1+'Income Stmnt'!$Q$8) -> 251.72406 | O11: =N11*(1+'Income Stmnt'!$Q$8) -> 296.94093 | Q11: SBC grow in-line with revenue growth rate
C12: Credit for deferred income taxes | H12: -441 | I12: -66 | J12: -790 | K12: =AVERAGE(H12:J12) -> -432.33333 | L12: =K12 -> -432.33333 | M12: =L12 -> -432.33333 | N12: =M12 -> -432.33333 | O12: =N12 -> -432.33333 | Q12: Average from historical years then straight-line assumption from 2024P Forecast
C13: Gain on remeasurement of previously held equity investment | H13: 0 | I13: -326 | J13: 0 | K13: 0 | L13: 0 | M13: 0 | N13: 0 | O13: 0 | Q13: Assume 2022 was unusual
B14: Changes in assets and liabilities:
C15: Receivables related to sales | H15: 969 | I15: -2483 | J15: -4253 | K15: =J15 -> -4253 | L15: =K15 -> -4253 | M15: =L15 -> -4253 | N15: =M15 -> -4253 | O15: =N15 -> -4253 | Q15: =Q18 -> Straight-line assumption
C16: Inventories | H16: -2497 | I16: -2091 | J16: 279 | K16: =('Balance Sheet'!J14-'Balance Sheet'!I14) -> 1146.3235 | L16: =-('Balance Sheet'!K14-'Balance Sheet'!J14) -> -1307.3599 | M16: =-('Balance Sheet'!L14-'Balance Sheet'!K14) -> -1491.0189 | N16: =-('Balance Sheet'!M14-'Balance Sheet'!L14) -> -1700.4785 | O16: =-('Balance Sheet'!N14-'Balance Sheet'!M14) -> -1939.3631 | Q16: Change in B/S Inventories
C17: Accounts payable and accrued expenses | H17: 1884 | I17: 1133 | J17: 830 | K17: ='Balance Sheet'!J26-'Balance Sheet'!I26 -> 2265.9556 | L17: ='Balance Sheet'!K26-'Balance Sheet'!J26 -> 2584.2789 | M17: ='Balance Sheet'!L26-'Balance Sheet'!K26 -> 2947.3205 | N17: ='Balance Sheet'!M26-'Balance Sheet'!L26 -> 3361.3625 | O17: ='Balance Sheet'!N26-'Balance Sheet'!M26 -> 3833.5695 | Q17: Change in B/S Accounts payable and accrued expenses
C18: Accrued income taxes payable/receivable | H18: 11 | I18: 141 | J18: -23 | K18: =J18 -> -23 | L18: =K18 -> -23 | M18: =L18 -> -23 | N18: =M18 -> -23 | O18: =N18 -> -23 | Q18: Straight-line assumption
C19: Retirement benefits | H19: 29 | I19: -1015 | J19: -170 | K19: =J19 -> -170 | L19: =K19 -> -170 | M19: =L19 -> -170 | N19: =M19 -> -170 | O19: =N19 -> -170 | Q19: Straight-line assumption
C20: Other | H20: -370 | I20: 16 | J20: 252 | K20: =J20 -> 252 | L20: =K20 -> 252 | M20: =L20 -> 252 | N20: =M20 -> 252 | O20: =N20 -> 252 | Q20: Straight-line assumption
B21: Net Cash provided by Operating Activities | H21: =SUM(H6:H20) -> 7725.8871 | I21: =SUM(I6:I20) -> 4699 | J21: =SUM(J6:J20) -> 8589 | K21: =SUM(K6:K20) -> 11691.744 | L21: =SUM(L6:L20) -> 12011.724 | M21: =SUM(M6:M20) -> 15261.624 | N21: =SUM(N6:N20) -> 19088.276 | O21: =SUM(O6:O20) -> 23594.296
B24: Cash Flows from Investing Activities
B25: Collections of receivables (excluding receivables related to sales) | H25: 18959 | I25: 20907 | J25: 23051 | K25: =J25*(1+$Q$25) -> 25417.155 | L25: =K25*(1+$Q$25) -> 28026.194 | M25: =L25*(1+$Q$25) -> 30903.046 | N25: =M25*(1+$Q$25) -> 34075.204 | O25: =N25*(1+$Q$25) -> 37572.98 | Q25: =AVERAGE(I25/H25,J25/I25)-1 -> 0.10264871 | R25: Average growth rate
B26: Proceeds from sales of equipment on operating leases | H26: 2094 | I26: 2093 | J26: 1981 | K26: =AVERAGE(I26/H26,J26/I26)*J26 -> 1927.5236 | L26: =K26 -> 1927.5236 | M26: =L26 -> 1927.5236 | N26: =M26 -> 1927.5236 | O26: =N26 -> 1927.5236 | Q26: Straight-line assumption due to variability from historical years
B27: Cost of receivables acquired (excluding receivables related to sales) | H27: -23653 | I27: -26300 | J27: -28772 | K27: =J27*(1+$Q$27) -> -31734.107 | L27: =K27*(1+$Q$27) -> -35001.167 | M27: =L27*(1+$Q$27) -> -38604.574 | N27: =M27*(1+$Q$27) -> -42578.955 | O27: =N27*(1+$Q$27) -> -46962.503 | Q27: =AVERAGE(I27/H27,J27/I27)-1 -> 0.10295104 | R27: Average growth rate
B28: Acquisitions of businesses, net of cash acquired | H28: -244 | I28: -498 | J28: -82 | K28: =J28 -> -82 | L28: =K28 -> -82 | M28: =L28 -> -82 | N28: =M28 -> -82 | O28: =N28 -> -82 | Q28: Straight-line assumption due to variability from historical years
B29: Purchases of property and equipment | H29: -848 | I29: -1134 | J29: -1498 | K29: =-'Balance Sheet'!J53 -> -1900 | L29: =K29*(1+$Q$29) -> -2525.3392 | M29: =L29*(1+$Q$29) -> -3356.4938 | N29: =M29*(1+$Q$29) -> -4461.2028 | O29: =N29*(1+$Q$29) -> -5929.5002 | Q29: =AVERAGE(I29/H29,J29/I29)-1 -> 0.3291259 | R29: Average Growth Rate from historical years; 2024 Forecast as mentioned 2023 10-K MD&A Forecast
B30: Cost of equipment on operating leases acquired | H30: -1732 | I30: -2654 | J30: -2970 | K30: =AVERAGE(I30/H30,J30/I30)*J30 -> -3937.3262 | L30: =K30*(1+$Q$30) -> -5219.7097 | M30: =L30*(1+$Q$30) -> -6919.7642 | N30: =M30*(1+$Q$30) -> -9173.5249 | O30: =N30*(1+$Q$30) -> -12161.333 | Q30: =AVERAGE(I30/H30,J30/I30)-1 -> 0.32569906 | R30: Average growth rate
B31: Collateral on derivatives – net | H31: -281 | I31: -642 | J31: -12 | K31: =J31 -> -12 | L31: =K31 -> -12 | M31: =L31 -> -12 | N31: =M31 -> -12 | O31: =N31 -> -12 | Q31: Straight-line assumption due to variability from historical years
B32: Other | H32: -45 | I32: -257 | J32: -447 | K32: =J32 -> -447 | L32: =K32 -> -447 | M32: =L32 -> -447 | N32: =M32 -> -447 | O32: =N32 -> -447 | Q32: Straight-line assumption due to variability from historical years
B33: Net Cash used for Investing Activities | H33: =SUM(H25:H32) -> -5750 | I33: =SUM(I25:I32) -> -8485 | J33: =SUM(J25:J32) -> -8749 | K33: =SUM(K25:K32) -> -10767.755 | L33: =SUM(L25:L32) -> -13333.499 | M33: =SUM(M25:M32) -> -16591.262 | N33: =SUM(N25:N32) -> -20751.955 | O33: =SUM(O25:O32) -> -26093.833
B36: Cash Flows from Financing Activities
B37: Net proceeds in short-term borrowings (original maturities three months or less) | H37: 818 | I37: 3852 | J37: 4008 | K37: =J37 -> 4008 | L37: =K37 -> 4008 | M37: =L37 -> 4008 | N37: =M37 -> 4008 | O37: =N37 -> 4008 | Q37: Straight-line assumption
B38: Proceeds from borrowings issued (original maturities greater than three months) | H38: 8722 | I38: 10358 | J38: 15429 | K38: =J38 -> 15429 | L38: =K38 -> 15429 | M38: =L38 -> 15429 | N38: =M38 -> 15429 | O38: =N38 -> 15429 | Q38: Straight-line assumption
B39: Payments of borrowings (original maturities greater than three months) | H39: -7090 | I39: -8445 | J39: -7913 | K39: =J39 -> -7913 | L39: =K39 -> -7913 | M39: =L39 -> -7913 | N39: =M39 -> -7913 | O39: =N39 -> -7913 | Q39: Straight-line assumption
B40: Repurchases of common stock | H40: -2538 | I40: -3597 | J40: -7216 | K40: =AVERAGE(H40:J40) -> -4450.3333 | L40: =K40 -> -4450.3333 | M40: =L40 -> -4450.3333 | N40: =M40 -> -4450.3333 | O40: =N40 -> -4450.3333 | Q40: Average Repurchases from historical years
B41: Dividends paid | H41: -1040 | I41: -1313 | J41: -1427 | K41: ='Balance Sheet'!J67 -> -1427 | L41: ='Balance Sheet'!K67 -> -1427 | M41: ='Balance Sheet'!L67 -> -1427 | N41: ='Balance Sheet'!M67 -> -1427 | O41: ='Balance Sheet'!N67 -> -1427 | Q41: Reference Retained Earnings Schedule
B42: Other | H42: 50 | I42: -29 | J42: -73 | K42: =J42 -> -73 | L42: =K42 -> -73 | M42: =L42 -> -73 | N42: =M42 -> -73 | O42: =N42 -> -73 | Q42: Straight-line assumption
B43: Net Cash provided by (used for) Financing Activities | H43: =SUM(H37:H42) -> -1078 | I43: =SUM(I37:I42) -> 826 | J43: =SUM(J37:J42) -> 2808 | K43: =SUM(K37:K42) -> 5573.6667 | L43: =SUM(L37:L42) -> 5573.6667 | M43: =SUM(M37:M42) -> 5573.6667 | N43: =SUM(N37:N42) -> 5573.6667 | O43: =SUM(O37:O42) -> 5573.6667
B45: Effect of Exchange Rate Changes on Cash, Cash Equivalents, and Restricted Cash | H45: 55 | I45: -224 | J45: 31 | K45: =J45 -> 31 | L45: =K45 -> 31 | M45: =L45 -> 31 | N45: =M45 -> 31 | O45: =N45 -> 31 | Q45: Straight-line assumption
B47: Net Increase (Decrease) in Cash, Cash Equivalents, and Restricted Cash | H47: 953 | I47: -3184 | J47: 2679 | K47: =K49-J49 -> -1122.3442 | L47: =L49-K49 -> -2245.7638 | M47: =M49-L49 -> -7.8635706 | N47: =N49-M49 -> -334.0406 | O47: =O49-N49 -> -835.85772
B48: Cash, Cash Equivalents, and Restricted Cash at Beginning of Year | H48: 7172 | I48: 8125 | J48: 4941 | K48: =J49 -> 7620 | L48: =K49 -> 6497.6558 | M48: =L49 -> 4251.892 | N48: =M49 -> 4244.0284 | O48: =N49 -> 3909.9878
...

Sheet Balance Sheet
B5: Company0786 Consolidated Balance Sheets with Forecast
B6: Assets | H6: 2022A | I6: 2023A | J6: 2024P | K6: 2025P | L6: 2026P | M6: 2027P | N6: 2028P | P6: Notes/Assumptions
B7: Cash and Cash Equivalents | H7: 4774 | I7: 7458 | J7: ='Cash Flow Stmnt'!K49 -> 6497.6558 | K7: ='Cash Flow Stmnt'!L49 -> 4251.892 | L7: ='Cash Flow Stmnt'!M49 -> 4244.0284 | M7: ='Cash Flow Stmnt'!N49 -> 3909.9878 | N7: ='Cash Flow Stmnt'!O49 -> 3074.1301 | P7: Refer to CFS Total Cash & Cash Equivalents
B8: Marketable Securities | H8: 734 | I8: 946 | J8: =I8 -> 946 | K8: =J8 -> 946 | L8: =K8 -> 946 | M8: =L8 -> 946 | N8: =M8 -> 946 | P8: Straight-line assumption
B9: Trade accounts and notes receivable - net | H9: 6410 | I9: 7739 | J9: =I9*(1+'Income Stmnt'!$Q$8) -> 9129.1468 | K9: =J9*(1+'Income Stmnt'!$Q$8) -> 10769.004 | L9: =K9*(1+'Income Stmnt'!$Q$8) -> 12703.426 | M9: =L9*(1+'Income Stmnt'!$Q$8) -> 14985.327 | N9: =M9*(1+'Income Stmnt'!$Q$8) -> 17677.122 | P9: Grow in-line with revenue growth
B10: Financing receivables - net | H10: 36634 | I10: 43673 | J10: =I10*(1+'Income Stmnt'!$Q$8) -> 51517.926 | K10: =J10*(1+'Income Stmnt'!$Q$8) -> 60772.026 | L10: =K10*(1+'Income Stmnt'!$Q$8) -> 71688.428 | M10: =L10*(1+'Income Stmnt'!$Q$8) -> 84565.73 | N10: =M10*(1+'Income Stmnt'!$Q$8) -> 99756.165 | P10: Grow in-line with revenue growth
B11: Financing receivables securitized - net | H11: 5936 | I11: 7335 | J11: =I11*(1+'Income Stmnt'!$Q$8) -> 8652.5768 | K11: =J11*(1+'Income Stmnt'!$Q$8) -> 10206.828 | L11: =K11*(1+'Income Stmnt'!$Q$8) -> 12040.268 | M11: =L11*(1+'Income Stmnt'!$Q$8) -> 14203.046 | N11: =M11*(1+'Income Stmnt'!$Q$8) -> 16754.321 | P11: Grow in-line with revenue growth
B12: Other receivables | H12: 2492 | I12: 2623 | J12: =I12*(1+'Income Stmnt'!$Q$8) -> 3094.1662 | K12: =J12*(1+'Income Stmnt'!$Q$8) -> 3649.9673 | L12: =K12*(1+'Income Stmnt'!$Q$8) -> 4305.6064 | M12: =L12*(1+'Income Stmnt'!$Q$8) -> 5079.017 | N12: =M12*(1+'Income Stmnt'!$Q$8) -> 5991.3544 | P12: Grow in-line with revenue growth
B13: Equipment on operating leases - net | H13: 6623 | I13: 6917 | J13: =I13 -> 6917 | K13: =J13 -> 6917 | L13: =K13 -> 6917 | M13: =L13 -> 6917 | N13: =M13 -> 6917 | P13: Straight-line assumption
B14: Inventories | H14: 8495 | I14: 8160 | J14: =I14*(1+'Income Stmnt'!$Q$9) -> 9306.3235 | K14: =J14*(1+'Income Stmnt'!$Q$9) -> 10613.683 | L14: =K14*(1+'Income Stmnt'!$Q$9) -> 12104.702 | M14: =L14*(1+'Income Stmnt'!$Q$9) -> 13805.181 | N14: =M14*(1+'Income Stmnt'!$Q$9) -> 15744.544 | P14: Grow in-line with Cost of Sales average growth
B15: Property and equipment - net | H15: 6056 | I15: 6879 | J15: =J57 -> 7922.8585 | K15: =K57 -> 8941.918 | L15: =L57 -> 10144.03 | M15: =M57 -> 11562.076 | N15: =N57 -> 13234.843 | P15: Reference PP&E Schedule
B16: Goodwill | H16: 3687 | I16: 3900 | J16: =I16 -> 3900 | K16: =J16 -> 3900 | L16: =K16 -> 3900 | M16: =L16 -> 3900 | N16: =M16 -> 3900 | P16: 2023A Goodwill
B17: Other intangible assets - net | H17: 1218 | I17: 1133 | J17: =I17 -> 1133 | K17: =I17 -> 1133 | L17: =K17 -> 1133 | M17: =L17 -> 1133 | N17: =M17 -> 1133 | P17: Straight-line assumption
B18: Retirement benefits | H18: 3730 | I18: 3007 | J18: =I18 -> 3007 | K18: =J18 -> 3007 | L18: =K18 -> 3007 | M18: =L18 -> 3007 | N18: =M18 -> 3007 | P18: Straight-line assumption
B19: Deferred income taxes | H19: 824 | I19: 1814 | J19: =I19 -> 1814 | K19: =J19 -> 1814 | L19: =K19 -> 1814 | M19: =L19 -> 1814 | N19: =M19 -> 1814 | P19: Straight-line assumption
B20: Other assets | H20: 2417 | I20: 2503 | J20: =I20 -> 2503 | K20: =J20 -> 2503 | L20: =K20 -> 2503 | M20: =L20 -> 2503 | N20: =M20 -> 2503 | P20: Straight-line assumption
B21: TOTAL ASSETS | H21: =90030 -> 90030 | I21: =104087 -> 104087 | J21: =SUM(J7:J20) -> 116340.65 | K21: =SUM(K7:K20) -> 129425.32 | L21: =SUM(L7:L20) -> 147450.49 | M21: =SUM(M7:M20) -> 168330.36 | N21: =SUM(N7:N20) -> 192452.48
B23: Liabilities
B24: Short-term borrowings | H24: 12592 | I24: 17939 | J24: =I24 -> 17939 | K24: =J24 -> 17939 | L24: =K24 -> 17939 | M24: =L24 -> 17939 | N24: =M24 -> 17939 | P24: Straight-line assumption
B25: Short-term securitizations borrowings | H25: 5711 | I25: 6995 | J25: =I25 -> 6995 | K25: =J25 -> 6995 | L25: =K25 -> 6995 | M25: =L25 -> 6995 | N25: =M25 -> 6995 | P25: Straight-line assumption
B26: Accounts payable and accrued expenses | H26: 14822 | I26: 16130 | J26: =I26*(1+'Income Stmnt'!$Q$9) -> 18395.956 | K26: =J26*(1+'Income Stmnt'!$Q$9) -> 20980.235 | L26: =K26*(1+'Income Stmnt'!$Q$9) -> 23927.555 | M26: =L26*(1+'Income Stmnt'!$Q$9) -> 27288.918 | N26: =M26*(1+'Income Stmnt'!$Q$9) -> 31122.487 | P26: Grow in-line with Cost of Sales average growth
B27: Deferred income taxes | H27: 495 | I27: 520 | J27: 520 | K27: 520 | L27: 520 | M27: 520 | N27: 520 | P27: Straight-line assumption
B28: Long-term borrowings | H28: 33596 | I28: 38477 | J28: =J21-SUM(J24:J27,J29,J35:J40,J31) -> 43650.696 | K28: =K21-SUM(K24:K27,K29,K35:K40,K31) -> 47073.959 | L28: =L21-SUM(L24:L27,L29,L35:L40,L31) -> 52405.043 | M28: =M21-SUM(M24:M27,M29,M35:M40,M31) -> 57027.602 | N28: =N21-SUM(N24:N27,N29,N35:N40,N31) -> 60705.323 | P28: Levered-up to balance
B29: Retirement benefits and other liabilities | H29: 2457 | I29: 2140 | J29: =I29*(1+'Income Stmnt'!$Q$8) -> 2524.4055 | K29: =J29*(1+'Income Stmnt'!$Q$8) -> 2977.8613 | L29: =K29*(1+'Income Stmnt'!$Q$8) -> 3512.7707 | M29: =L29*(1+'Income Stmnt'!$Q$8) -> 4143.7653 | N29: =M29*(1+'Income Stmnt'!$Q$8) -> 4888.1046 | P29: Grow in-line with revenue growth
B30: TOTAL LIABILITIES | H30: 69673 | I30: =82201 -> 82201 | J30: =SUM(J24:J29) -> 90025.057 | K30: =SUM(K24:K29) -> 96486.055 | L30: =SUM(L24:L29) -> 105299.37 | M30: =SUM(M24:M29) -> 113914.28 | N30: =SUM(N24:N29) -> 122169.91
C31: Redeemable noncontrolling interest | H31: 92 | I31: 97 | J31: =I31 -> 97 | K31: =J31 -> 97 | L31: =K31 -> 97 | M31: =L31 -> 97 | N31: =M31 -> 97 | P31: Straight-line assumption
B33: Stockholders' Equity
B34: Common stock, $1 par value (authorized – 1,200,000,000 shares;
B35: issued – 536,431,204 shares in 2023 and 2022), at paid-in amount | H35: 5165 | I35: 5303 | J35: =I35+'Cash Flow Stmnt'!K11 -> 5456.3517 | K35: =J35+'Cash Flow Stmnt'!L11 -> 5637.2499 | L35: =K35+'Cash Flow Stmnt'!M11 -> 5850.6425 | M35: =L35+'Cash Flow Stmnt'!N11 -> 6102.3665 | N35: =M35+'Cash Flow Stmnt'!O11 -> 6399.3075 | P35: Increase by stock-based compensation forecasted in Cash Flow Statement
B36: Common stock in treasury, 254,846,927 shares in 2023
B37: and 237,659,289 shares in 2022, at cost | H37: -24094 | I37: -31335 | J37: =I37+'Cash Flow Stmnt'!K40 -> -35785.333 | K37: =J37+'Cash Flow Stmnt'!L40 -> -40235.667 | L37: =K37+'Cash Flow Stmnt'!M40 -> -44686 | M37: =L37+'Cash Flow Stmnt'!N40 -> -49136.333 | N37: =M37+'Cash Flow Stmnt'!O40 -> -53586.667 | P37: 2023 Treasury added by Repurchases from Cash Flow Statement
B38: Retained Earnings | H38: 42247 | I38: 50931 | J38: =J68 -> 59657.578 | K38: =K68 -> 70550.681 | L38: =L68 -> 83999.478 | M38: =M68 -> 100463.05 | N38: =N68 -> 120482.92 | P38: Reference Retained Earnings Schedule
B39: Accumulated other comprehensive income (loss) | H39: -3056 | I39: -3114 | J39: =I39 -> -3114 | K39: =J39 -> -3114 | L39: =K39 -> -3114 | M39: =L39 -> -3114 | N39: =M39 -> -3114 | P39: Straight-line assumption
B40: Noncontroliing interests | H40: 3 | I40: 4 | J40: 4 | K40: 4 | L40: 4 | M40: 4 | N40: 4 | P40: =P39 -> Straight-line assumption
B41: TOTAL STOCKHOLDERS' EQUITY | H41: =20265 -> 20265 | I41: =21789 -> 21789 | J41: =SUM(J35:J40) -> 26218.597 | K41: =SUM(K35:K40) -> 32842.264 | L41: =SUM(L35:L40) -> 42054.121 | M41: =SUM(M35:M40) -> 54319.079 | N41: =SUM(N35:N40) -> 70185.565
B43: TOTAL LIABILITIES + STOCKHOLDERS' EQUITY | H43: 90030 | I43: 104087 | J43: =J30+J41+J31 -> 116340.65 | K43: =K30+K41+K31 -> 129425.32 | L43: =L30+L41+L31 -> 147450.49 | M43: =M30+M41+M31 -> 168330.36 | N43: =N30+N41+N31 -> 192452.48
B44: Balance | H44: =H43=H21 -> TRUE | I44: =I43=I21 -> TRUE | J44: =IF(J43-J21<1,TRUE) -> TRUE | K44: =IF(K43-K21<1,TRUE) -> TRUE | L44: =IF(L43-L21<1,TRUE) -> TRUE | M44: =IF(M43-M21<1,TRUE) -> TRUE | N44: =IF(N43-N21<1,TRUE) -> TRUE
B45: Difference | H45: =H43-H21 -> 0 | I45: =I43-I21 -> 0 | J45: =IF(J43-J21<1,0) -> 0 | K45: =IF(K43-K21<1,0) -> 0 | L45: =IF(L43-L21<1,0) -> 0 | M45: =IF(M43-M21<1,0) -> 0 | N45: =IF(N43-N21<1,0) -> 0
B51: Property, Plant & Equipment Schedule | G51: 2021A | H51: 2022A | I51: 2023A | J51: 2024P | K51: 2025P | L51: 2026P | M51: 2027P | N51: 2028P
C52: Beginning of Period | G52: 5817 | H52: 5820 | I52: 6056 | J52: 6879 | K52: =J57 -> 7922.8585 | L52: =K57 -> 8941.918 | M52: =L57 -> 10144.03 | N52: =M57 -> 11562.076
...

Sheet FCF Forecast with WACC
C4: UFCF/LFCF
C5: Fiscal Year | G5: 2021A | H5: 2022A | I5: 2023A | J5: 2024P | L5: Notes/Assumptions
C6: Net Cash provided by Operating Activities | G6: ='Cash Flow Stmnt'!H21 -> 7725.8871 | H6: ='Cash Flow Stmnt'!I21 -> 4699 | I6: ='Cash Flow Stmnt'!J21 -> 8589 | J6: ='Cash Flow Stmnt'!K21 -> 11691.744 | L6: Reference Operating Activities section of CF Statement
D7: Less: Capital Expenditures | G7: ='Cash Flow Stmnt'!H29 -> -848 | H7: ='Cash Flow Stmnt'!I29 -> -1134 | I7: ='Cash Flow Stmnt'!J29 -> -1498 | J7: ='Cash Flow Stmnt'!K29 -> -1900 | L7: Reference Cash Flow Statement's Purchases of Property and Equipment
C8: Levered Free Cash Flow | G8: =G6+G7 -> 6877.8871 | H8: =H6+H7 -> 3565 | I8: =I6+I7 -> 7091 | J8: =J6+J7 -> 9791.7437
C9: FCF Growth Rate | H9: =(H8-G8)/G8 -> -0.48167221 | I9: =(I8-H8)/H8 -> 0.98906031 | J9: =(J8-I8)/I8 -> 0.38086923
C10: Operating Income | G10: ='Income Stmnt'!H18 -> 8594.8871 | H10: ='Income Stmnt'!I18 -> 10188.89 | I10: ='Income Stmnt'!J18 -> 15471.889 | J10: ='Income Stmnt'!K18 -> 15453.237
D11: Less: Tax Expense | G11: =-'Income Stmnt'!H21 -> -1658 | H11: =-'Income Stmnt'!I21 -> -2007 | I11: =-'Income Stmnt'!J21 -> -2871 | J11: =-'Income Stmnt'!K21 -> -2853.6585 | L11: Reference Income Statement's Provision from Income Tax
D12: Plus: Operating Activities Adjustments | G12: ='Cash Flow Stmnt'!H21-'Cash Flow Stmnt'!H6 -> 1761 | H12: ='Cash Flow Stmnt'!I21-'Cash Flow Stmnt'!I6 -> -2431 | I12: ='Cash Flow Stmnt'!J21-'Cash Flow Stmnt'!J6 -> -1566 | J12: ='Cash Flow Stmnt'!K21-'Cash Flow Stmnt'!K6 -> 1538.1656 | L12: Value derived from Cash Flow Statement's Net Cash provided by Operating Activities less Net Income
D13: Less: Capital Expenditures | G13: =G7 -> -848 | H13: =H7 -> -1134 | I13: =I7 -> -1498 | J13: =J7 -> -1900
C14: Unlevered Free Cash Flow | G14: =SUM(G10:G13) -> 7849.8871 | H14: =SUM(H10:H13) -> 4616.8902 | I14: =SUM(I10:I13) -> 9536.8894 | J14: =SUM(J10:J13) -> 12237.744
C15: FCF Growth Rate | H15: =(H14-G14)/G14 -> -0.41185267 | I15: =(I14-H14)/H14 -> 1.0656522 | J15: =(J14-I14)/I14 -> 0.28320075
I18: Growth Rate | J18: 0.031 | L18: Inflation Rate as of January 2024
I19: Share Price (as of 10/30/23) | J19: 367.8 | L19: Referenced from Yahoo Finance
I20: Diluted Shares Outstanding | J20: 293.6 | L20: Reference 2023 10-K
I22: NPV of UFCF | J22: =NPV(J43,G8:J8) -> 20916.923 | L22: UFCF used for calculations to arrive at Enterprise Value
I23: Terminal Value | J23: =(J14*(1+J18))/(J37-J18) -> 280937.43
I24: PV of Terminal Value | J24: =J23/(1+J37)+ (I14/(1+J37)) -> 269979.93
I25: Enterprise Value | J25: =J24+J22 -> 290896.86 | L25: NPV of FCF + PV of Terminal Value
I26: Net Debt | J26: =J33-'Balance Sheet'!J7-'Balance Sheet'!J8 -> 61141.04 | L26: Total Debt less Cash & Cash Equivalents and Marketable Securities
I27: Equity Value | J27: =J25-J26 -> 229755.82
I28: Equity Value per Share | J28: =J27/J20 -> 782.54706
I31: Weighted Average Cost of Capital
I32: Cost of Debt | J32: 0.0365 | L32: Average Interest Rate from current issuance of Long-Term Borrowings in LT Debt Schedule
I33: Total Debt | J33: ='Balance Sheet'!J24+'Balance Sheet'!J25+'Balance Sheet'!J28 -> 68584.696 | L33: Aggregate of Short-term borrowings, Short-term securitizations borrowings, and Long-term borrowings
I34: Cost of Equity | J34: =J43 -> 0.10603 | L34: From CAPM
I35: Equity Value | J35: =J19*J20 -> 107986.08 | L35: Share Price multiplied by Diluted Shares Outstanding
I36: Debt + Equity | J36: =J35+J33 -> 176570.78
I37: WACC | J37: =J34*(J35/J36)+J32*(J33/J36)*(1-21.95%) -> 0.075910761
P38: =J33/J35 -> 0.63512534
I39: Capital Asset Pricing Model (CAPM)
I40: Risk-free Rate | J40: 0.04561 | L40: 10-Yr US Treasury Rate as of 10/30/23
I41: Beta | J41: 1.06 | L41: From Capital IQ company profile
I42: Market Risk Premium | J42: 0.057 | L42: From Company2593 Historical Data of 10/30/23
I43: Cost of Equity | J43: =J40+J41*J42 -> 0.10603

Sheet ST Debt Schedule
B6: Short-Term Debt Payment and Interest Expense Schedule
G7: 2023A | H7: 2024P | I7: 2025P | J7: 2026P
B8: Short-Term Debt
C9: Commercial Paper
D10: Beginning of Period | G10: 4703 | H10: 4703 | I10: 4703 | J10: 4703
D11: Draw/(paydown) | G11: -4703 | H11: -4703 | I11: -4703 | J11: -4703
D12: Discretionary borrowing/(paydown) | G12: 9100 | H12: =G12 -> 9100 | I12: =H12 -> 9100 | J12: =I12 -> 9100
D13: End of Period | G13: 9100 | H13: =SUM(H10:H12) -> 9100 | I13: =SUM(I10:I12) -> 9100 | J13: =SUM(J10:J12) -> 9100
C14: Notes payable to banks
D15: Beginning of Period | G15: 402 | H15: 402 | I15: 402 | J15: 402
D16: Draw/(paydown) | G16: =-G15 -> -402 | H16: =-H15 -> -402 | I16: =-I15 -> -402 | J16: =-J15 -> -402
D17: Discretionary borrowing/(paydown) | G17: 483 | H17: =H18 -> 483 | I17: =I18 -> 483 | J17: =J18 -> 483
D18: End of Period | G18: 483 | H18: 483 | I18: 483 | J18: 483
C19: Finance lease obligations
D20: Beginning of Period | G20: 21 | H20: 21 | I20: 21 | J20: 21
D21: Draw/(paydown) | G21: =-G20 -> -21 | H21: =-H20 -> -21 | I21: =-I20 -> -21 | J21: =-J20 -> -21
D22: Discretionary borrowing/(paydown) | G22: 25 | H22: 25 | I22: 25 | J22: 25
D23: End of Period | G23: 25 | H23: 25 | I23: 25 | J23: 25
C24: Current Portion of Long-term Debt
D25: Beginning of Period | G25: 7446 | H25: 7446 | I25: 7446 | J25: 7446
D26: Draw/(paydown) | G26: =-G25 -> -7446 | H26: =-H25 -> -7446 | I26: =-I25 -> -7446 | J26: =-J25 -> -7446
D27: Continuing obligations/(paydown) | G27: 8331 | H27: 8331 | I27: 8331 | J27: 8331
D28: End of Period | G28: 8331 | H28: 8331 | I28: 8331 | J28: 8331
C29: Short-Term Debt, net | G29: 17939 | H29: =H13+H18+H23+H28 -> 17939 | I29: =I13+I18+I23+I28 -> 17939 | J29: =J13+J18+J23+J28 -> 17939
B31: Short-term Borrowings, Interest Expense
C32: Commercial Paper
D33: =D13 -> End of Period | G33: =G13 -> 9100 | H33: =H13 -> 9100 | I33: =I13 -> 9100 | J33: =J13 -> 9100
D34: Weighted Average Interest Rate | G34: 0.053 | H34: 0.053 | I34: 0.053 | J34: 0.053
D35: Interest Expense | G35: =G33*G34 -> 482.3 | H35: =H33*H34 -> 482.3 | I35: =I33*I34 -> 482.3 | J35: =J33*J34 -> 482.3
C36: Notes payable to banks
D37: End of Period | G37: =G15 -> 402 | H37: =H15 -> 402 | I37: =I15 -> 402 | J37: =J15 -> 402
D38: Weighted Average Interest Rate | G38: 0.316 | H38: 0.316 | I38: 0.316 | J38: 0.316
D39: Interest Expense | G39: =G37*G38 -> 127.032 | H39: =H37*H38 -> 127.032 | I39: =I37*I38 -> 127.032 | J39: =J37*J38 -> 127.032
C40: Finance lease obligations
D41: End of Period | G41: =G23 -> 25 | H41: =H23 -> 25 | I41: =I23 -> 25 | J41: =J23 -> 25
D42: Weighted Average Interest Rate | G42: 0.036 | H42: 0.036 | I42: 0.036 | J42: 0.036
D43: Interest Expense | G43: =G41*G42 -> 0.9 | H43: =H41*H42 -> 0.9 | I43: =I41*I42 -> 0.9 | J43: =J41*J42 -> 0.9
C44: Current Portion of Long-term Debt
D45: End of Period | G45: =G28 -> 8331 | H45: =H28 -> 8331 | I45: =I28 -> 8331 | J45: =J28 -> 8331
D46: Weighted Average Interest Rate | G46: 0.01375 | H46: 0.01375 | I46: 0.01375 | J46: 0.01375
...

Sheet LT Debt Schedule
B6: Calculation & Forecast of LT Borrowings Interest Expense
B7: 2024 | D7: 2.75% notes due 2025 | E7: 6.55% debuntures due 2028 | F7: 5.375% notes due 2029 | G7: 3.10% notes due 2030 | H7: 8.10% debuntures due 2030 | I7: 7.125% notes due 2031 | J7: 3.90% notes due 2042 | K7: 2.875% notes due 2049 | L7: 3.75% notes due 2050 | M7: 1.85% notes due 2028 | N7: 2.20% notes due 2032 | O7: 1.65% notes due 2039 | P7: Interest Expense Calculation
B8: 1 | C8: January
B9: 2 | C9: February
B10: 3 | C10: March
B11: 4 | C11: April | D11: =-('Loan & Bond Data'!$D$12*'Loan & Bond Data'!$D$13/'Loan & Bond Data'!$D$14)*4/6 -> -6.4166667 | E11: =-('Loan & Bond Data'!$G$12*'Loan & Bond Data'!$G$13/'Loan & Bond Data'!$G$14)*4/6 -> -4.3666667 | F11: =-('Loan & Bond Data'!$J$12*'Loan & Bond Data'!$J$13/'Loan & Bond Data'!$J$14)*4/6 -> -8.9583333 | G11: =-('Loan & Bond Data'!$M$12*'Loan & Bond Data'!$M$13/'Loan & Bond Data'!$M$14)*4/6 -> -7.2333333 | H11: =-('Loan & Bond Data'!$D$19*'Loan & Bond Data'!$D$20/'Loan & Bond Data'!$D$21)*4/6 -> -2.5833333 | I11: =-('Loan & Bond Data'!$G$19*'Loan & Bond Data'!$G$20/'Loan & Bond Data'!$G$21)*4/6 -> -7.125 | J11: =-('Loan & Bond Data'!$J$19*'Loan & Bond Data'!$J$20/'Loan & Bond Data'!$J$21)*4/6 -> -16.25 | K11: =-('Loan & Bond Data'!$M$19*'Loan & Bond Data'!$M$20/'Loan & Bond Data'!$M$21)*4/6 -> -4.7916667 | L11: =-('Loan & Bond Data'!$G$26*'Loan & Bond Data'!$G$27/'Loan & Bond Data'!$G$28)*4/6 -> -3.9096667 | M11: =-('Loan & Bond Data'!$D$26*'Loan & Bond Data'!$D$27/'Loan & Bond Data'!$D$28)*4/6 -> -10.625 | N11: =-('Loan & Bond Data'!$J$26*'Loan & Bond Data'!$J$27/'Loan & Bond Data'!$J$28)*4/6 -> -4.6493333 | O11: =-('Loan & Bond Data'!$M$26*'Loan & Bond Data'!$M$27/'Loan & Bond Data'!$M$28)*4/6 -> -3.7785 | P11: =SUM(D11:O11) -> -80.6875
B12: 5 | C12: May
B13: 6 | C13: June
B14: 7 | C14: July
B15: 8 | C15: August
B16: 9 | C16: September
B17: 10 | C17: October | D17: =-('Loan & Bond Data'!$D$12*'Loan & Bond Data'!$D$13/'Loan & Bond Data'!$D$14) -> -9.625 | E17: =-('Loan & Bond Data'!$G$12*'Loan & Bond Data'!$G$13/'Loan & Bond Data'!$G$14)/6*6 -> -6.55 | F17: =-('Loan & Bond Data'!$J$12*'Loan & Bond Data'!$J$13/'Loan & Bond Data'!$J$14)/6*6 -> -13.4375 | G17: =-('Loan & Bond Data'!$M$12*'Loan & Bond Data'!$M$13/'Loan & Bond Data'!$M$14)/6*6 -> -10.85 | H17: =-('Loan & Bond Data'!$D$19*'Loan & Bond Data'!$D$20/'Loan & Bond Data'!$D$21)/6*6 -> -3.875 | I17: =-('Loan & Bond Data'!$G$19*'Loan & Bond Data'!$G$20/'Loan & Bond Data'!$G$21)/6*6 -> -10.6875 | J17: =-('Loan & Bond Data'!$J$19*'Loan & Bond Data'!$J$20/'Loan & Bond Data'!$J$21)/6*6 -> -24.375 | K17: =-('Loan & Bond Data'!$M$19*'Loan & Bond Data'!$M$20/'Loan & Bond Data'!$M$21)/6*6 -> -7.1875 | L17: =-('Loan & Bond Data'!$G$26*'Loan & Bond Data'!$G$27/'Loan & Bond Data'!$G$28)/6*6 -> -5.8645 | M17: =-('Loan & Bond Data'!$D$26*'Loan & Bond Data'!$D$27/'Loan & Bond Data'!$D$28)/6*6 -> -15.9375 | N17: =-('Loan & Bond Data'!$J$26*'Loan & Bond Data'!$J$27/'Loan & Bond Data'!$J$28)/6*6 -> -6.974 | O17: =-('Loan & Bond Data'!$M$26*'Loan & Bond Data'!$M$27/'Loan & Bond Data'!$M$28)/6*6 -> -5.66775 | P17: =SUM(D17:O17) -> -121.03125
B18: 11 | C18: November
B19: 12 | C19: December
C20: Totals | D20: =SUM(D8:D19) -> -16.041667 | E20: =SUM(E8:E19) -> -10.916667 | F20: =SUM(F8:F19) -> -22.395833 | G20: =SUM(G8:G19) -> -18.083333 | H20: =SUM(H8:H19) -> -6.4583333 | I20: =SUM(I8:I19) -> -17.8125 | J20: =SUM(J8:J19) -> -40.625 | K20: =SUM(K8:K19) -> -11.979167 | ... O20: =SUM(O8:O19) -> -9.44625 | P20: =SUM(D20:O20) -> -201.71875
B23: 2025 | D23: 2.75% notes due 2025 | E23: 6.55% debuntures due 2028 | F23: 5.375% notes due 2029 | G23: 3.10% notes due 2030 | H23: 8.10% debuntures due 2030 | I23: 7.125% notes due 2031 | J23: 3.90% notes due 2042 | K23: 2.875% notes due 2049 | L23: 3.75% notes due 2050 | M23: 1.85% notes due 2028 | N23: 2.20% notes due 2032 | O23: 1.65% notes due 2039 | P23: Interest Expense Calculation
B24: 1 | C24: January
B25: 2 | C25: February
B26: 3 | C26: March
B27: 4 | C27: April | D27: =-('Loan & Bond Data'!$D$12*'Loan & Bond Data'!$D$13/'Loan & Bond Data'!$D$14)*4/6 -> -6.4166667 | E27: =-('Loan & Bond Data'!$G$12*'Loan & Bond Data'!$G$13/'Loan & Bond Data'!$G$14)*4/6 -> -4.3666667 | F27: =-('Loan & Bond Data'!$J$12*'Loan & Bond Data'!$J$13/'Loan & Bond Data'!$J$14)*4/6 -> -8.9583333 | G27: =-('Loan & Bond Data'!$M$12*'Loan & Bond Data'!$M$13/'Loan & Bond Data'!$M$14)*4/6 -> -7.2333333 | H27: =-('Loan & Bond Data'!$D$19*'Loan & Bond Data'!$D$20/'Loan & Bond Data'!$D$21)*4/6 -> -2.5833333 | I27: =-('Loan & Bond Data'!$G$19*'Loan & Bond Data'!$G$20/'Loan & Bond Data'!$G$21)*4/6 -> -7.125 | J27: =-('Loan & Bond Data'!$J$19*'Loan & Bond Data'!$J$20/'Loan & Bond Data'!$J$21)*4/6 -> -16.25 | K27: =-('Loan & Bond Data'!$M$19*'Loan & Bond Data'!$M$20/'Loan & Bond Data'!$M$21)*4/6 -> -4.7916667 | L27: =-('Loan & Bond Data'!$G$26*'Loan & Bond Data'!$G$27/'Loan & Bond Data'!$G$28)*4/6 -> -3.9096667 | M27: =-('Loan & Bond Data'!$D$26*'Loan & Bond Data'!$D$27/'Loan & Bond Data'!$D$28)*4/6 -> -10.625 | N27: =-('Loan & Bond Data'!$J$26*'Loan & Bond Data'!$J$27/'Loan & Bond Data'!$J$28)*4/6 -> -4.6493333 | O27: =-('Loan & Bond Data'!$M$26*'Loan & Bond Data'!$M$27/'Loan & Bond Data'!$M$28)*4/6 -> -3.7785 | P27: =SUM(D27:O27) -> -80.6875
B28: 5 | C28: May
B29: 6 | C29: June
B30: 7 | C30: July
B31: 8 | C31: August
B32: 9 | C32: September
B33: 10 | C33: October | D33: =-('Loan & Bond Data'!$D$12*'Loan & Bond Data'!$D$13/'Loan & Bond Data'!$D$14)/6*6 -> -9.625 | E33: =-('Loan & Bond Data'!$G$12*'Loan & Bond Data'!$G$13/'Loan & Bond Data'!$G$14)/6*6 -> -6.55 | F33: =-('Loan & Bond Data'!$J$12*'Loan & Bond Data'!$J$13/'Loan & Bond Data'!$J$14)/6*6 -> -13.4375 | G33: =-('Loan & Bond Data'!$M$12*'Loan & Bond Data'!$M$13/'Loan & Bond Data'!$M$14)/6*6 -> -10.85 | H33: =-('Loan & Bond Data'!$D$19*'Loan & Bond Data'!$D$20/'Loan & Bond Data'!$D$21)/6*6 -> -3.875 | I33: =-('Loan & Bond Data'!$G$19*'Loan & Bond Data'!$G$20/'Loan & Bond Data'!$G$21)/6*6 -> -10.6875 | J33: =-('Loan & Bond Data'!$J$19*'Loan & Bond Data'!$J$20/'Loan & Bond Data'!$J$21)/6*6 -> -24.375 | K33: =-('Loan & Bond Data'!$M$19*'Loan & Bond Data'!$M$20/'Loan & Bond Data'!$M$21)/6*6 -> -7.1875 | L33: =-('Loan & Bond Data'!$G$26*'Loan & Bond Data'!$G$27/'Loan & Bond Data'!$G$28)/6*6 -> -5.8645 | M33: =-('Loan & Bond Data'!$D$26*'Loan & Bond Data'!$D$27/'Loan & Bond Data'!$D$28)/6*6 -> -15.9375 | N33: =-('Loan & Bond Data'!$J$26*'Loan & Bond Data'!$J$27/'Loan & Bond Data'!$J$28)/6*6 -> -6.974 | O33: =-('Loan & Bond Data'!$M$26*'Loan & Bond Data'!$M$27/'Loan & Bond Data'!$M$28)/6*6 -> -5.66775 | P33: =SUM(D33:O33) -> -121.03125
B34: 11 | C34: November
B35: 12 | C35: December
C36: Totals | D36: =SUM(D24:D35) -> -16.041667 | E36: =SUM(E24:E35) -> -10.916667 | F36: =SUM(F24:F35) -> -22.395833 | G36: =SUM(G24:G35) -> -18.083333 | H36: =SUM(H24:H35) -> -6.4583333 | I36: =SUM(I24:I35) -> -17.8125 | J36: =SUM(J24:J35) -> -40.625 | K36: =SUM(K24:K35) -> -11.979167 | ... P36: =SUM(P24:P35) -> -201.71875
B39: 2026 | D39: 2.75% notes due 2025 | E39: 6.55% debuntures due 2028 | F39: 5.375% notes due 2029 | G39: 3.10% notes due 2030 | H39: 8.10% debuntures due 2030 | I39: 7.125% notes due 2031 | J39: 3.90% notes due 2042 | K39: 2.875% notes due 2049 | L39: 3.75% notes due 2050 | M39: 1.85% notes due 2028 | N39: 2.20% notes due 2032 | O39: 1.65% notes due 2039 | P39: Interest Expense Calculation
B40: 1 | C40: January
B41: 2 | C41: February
B42: 3 | C42: March
B43: 4 | C43: April | E43: =-('Loan & Bond Data'!$G$12*'Loan & Bond Data'!$G$13/'Loan & Bond Data'!$G$14)*4/6 -> -4.3666667 | F43: =-('Loan & Bond Data'!$J$12*'Loan & Bond Data'!$J$13/'Loan & Bond Data'!$J$14)*4/6 -> -8.9583333 | G43: =-('Loan & Bond Data'!$M$12*'Loan & Bond Data'!$M$13/'Loan & Bond Data'!$M$14)*4/6 -> -7.2333333 | H43: =-('Loan & Bond Data'!$D$19*'Loan & Bond Data'!$D$20/'Loan & Bond Data'!$D$21)*4/6 -> -2.5833333 | I43: =-('Loan & Bond Data'!$G$19*'Loan & Bond Data'!$G$20/'Loan & Bond Data'!$G$21)*4/6 -> -7.125 | J43: =-('Loan & Bond Data'!$J$19*'Loan & Bond Data'!$J$20/'Loan & Bond Data'!$J$21)*4/6 -> -16.25 | K43: =-('Loan & Bond Data'!$M$19*'Loan & Bond Data'!$M$20/'Loan & Bond Data'!$M$21)*4/6 -> -4.7916667 | L43: =-('Loan & Bond Data'!$G$26*'Loan & Bond Data'!$G$27/'Loan & Bond Data'!$G$28)*4/6 -> -3.9096667 | M43: =-('Loan & Bond Data'!$D$26*'Loan & Bond Data'!$D$27/'Loan & Bond Data'!$D$28)*4/6 -> -10.625 | N43: =-('Loan & Bond Data'!$J$26*'Loan & Bond Data'!$J$27/'Loan & Bond Data'!$J$28)*4/6 -> -4.6493333 | O43: =-('Loan & Bond Data'!$M$26*'Loan & Bond Data'!$M$27/'Loan & Bond Data'!$M$28)*4/6 -> -3.7785 | P43: =SUM(D43:O43) -> -74.270833
B44: 5 | C44: May
B45: 6 | C45: June
B46: 7 | C46: July
B47: 8 | C47: August
B48: 9 | C48: September
B49: 10 | C49: October | E49: =-('Loan & Bond Data'!$G$12*'Loan & Bond Data'!$G$13/'Loan & Bond Data'!$G$14)/6*6 -> -6.55 | F49: =-('Loan & Bond Data'!$J$12*'Loan & Bond Data'!$J$13/'Loan & Bond Data'!$J$14)/6*6 -> -13.4375 | G49: =-('Loan & Bond Data'!$M$12*'Loan & Bond Data'!$M$13/'Loan & Bond Data'!$M$14)/6*6 -> -10.85 | H49: =-('Loan & Bond Data'!$D$19*'Loan & Bond Data'!$D$20/'Loan & Bond Data'!$D$21)/6*6 -> -3.875 | I49: =-('Loan & Bond Data'!$G$19*'Loan & Bond Data'!$G$20/'Loan & Bond Data'!$G$21)/6*6 -> -10.6875 | J49: =-('Loan & Bond Data'!$J$19*'Loan & Bond Data'!$J$20/'Loan & Bond Data'!$J$21)/6*6 -> -24.375 | K49: =-('Loan & Bond Data'!$M$19*'Loan & Bond Data'!$M$20/'Loan & Bond Data'!$M$21)/6*6 -> -7.1875 | L49: =-('Loan & Bond Data'!$G$26*'Loan & Bond Data'!$G$27/'Loan & Bond Data'!$G$28)/6*6 -> -5.8645 | M49: =-('Loan & Bond Data'!$D$26*'Loan & Bond Data'!$D$27/'Loan & Bond Data'!$D$28)/6*6 -> -15.9375 | N49: =-('Loan & Bond Data'!$J$26*'Loan & Bond Data'!$J$27/'Loan & Bond Data'!$J$28)/6*6 -> -6.974 | O49: =-('Loan & Bond Data'!$M$26*'Loan & Bond Data'!$M$27/'Loan & Bond Data'!$M$28)/6*6 -> -5.66775 | P49: =SUM(D49:O49) -> -111.40625
...

Sheet Loan & Bond Data
H2: Calculation of Interest Expense for F/S Purposes
H3: Company0786
H4: (for the fiscal year ended 10/29/23)
C7: Calculation Date: | D7: 45228
C9: 2.75% notes due 2025 | F9: 6.55% debuntures due 2028 | I9: 5.375% notes due 2029 | L9: 3.10% notes due 2030
C10: Remaining Loan Term (Yrs): | D10: 2 | F10: Remaining Loan Term (Yrs: | G10: 5 | I10: Remaining Loan Term (Yrs): | J10: 6 | L10: Remaining Loan Term (Yrs): | M10: 7
C11: Settlement: | D11: =EOMONTH(D7,24) -> 45961 | F11: Settlement: | G11: =EOMONTH($D$7,60) -> 47057 | I11: Settlement: | J11: =EOMONTH(D7,72) -> 47422 | L11: Settlement: | M11: =EOMONTH(D7,84) -> 47787
C12: Loan Outstanding: | D12: 700 | F12: Loan Outstanding: | G12: 200 | I12: Loan Outstanding: | J12: 500 | L12: Loan Outstanding: | M12: 700
C13: Interest Rate: | D13: 0.0275 | F13: Interest Rate: | G13: 0.0655 | I13: Interest Rate: | J13: 0.05375 | L13: Interest Rate: | M13: 0.031
C14: Pmts/Yr: | D14: 2 | F14: Pmts/Yr: | G14: 2 | I14: Pmts/Yr: | J14: 2 | L14: Pmts/Yr: | M14: 2
C16: 8.10% debuntures due 2030 | F16: 7.125% notes due 2031 | I16: 3.90% notes due 2042 | L16: 2.875% notes due 2049
C17: Remaining Loan Term (Yrs): | D17: 7 | F17: Remaining Loan Term (Yrs): | G17: 8 | I17: Remaining Loan Term (Yrs): | J17: 19 | L17: Remaining Loan Term (Yrs): | M17: 26
C18: Settlement: | D18: =EOMONTH($D$7,84) -> 47787 | F18: Settlement: | G18: =EOMONTH($D$7,96) -> 48152 | I18: Settlement: | J18: =EOMONTH($D$7,19*12) -> 52170 | L18: Settlement: | M18: =EOMONTH($D$7,26*12) -> 54727
C19: Loan Outstanding: | D19: 250 | F19: Loan Outstanding: | G19: 300 | I19: Loan Outstanding: | J19: 1250 | L19: Loan Outstanding: | M19: 500
C20: Interest Rate: | D20: 0.031 | F20: Interest Rate: | G20: 0.07125 | I20: Interest Rate: | J20: 0.039 | L20: Interest Rate: | M20: 0.02875
C21: Pmts/Yr: | D21: 2 | F21: Pmts/Yr: | G21: 2 | I21: Pmts/Yr: | J21: 2 | L21: Pmts/Yr: | M21: 2
C23: 3.75% notes due 2050 | F23: 1.85% notes due 2028 | I23: 2.20% notes due 2032 | L23: 1.65% notes due 2039
C24: Remaining Loan Term (Yrs): | D24: 27 | F24: Remaining Loan Term (Yrs): | G24: 5 | I24: Remaining Loan Term (Yrs): | J24: 9 | L24: Remaining Loan Term (Yrs): | M24: 16
C25: Settlement: | D25: =EOMONTH($D$7,27*12) -> 55092 | F25: Settlement: | G25: =EOMONTH($D$7,60) -> 47057 | I25: Settlement: | J25: =EOMONTH($D$7,9*12) -> 48518 | L25: Settlement: | M25: =EOMONTH($D$7,16*12) -> 51074
C26: Loan Outstanding: | D26: 850 | F26: Loan Outstanding: | G26: 634 | I26: Loan Outstanding: | J26: 634 | L26: Loan Outstanding: | M26: 687
C27: Interest Rate: | D27: 0.0375 | F27: Interest Rate: | G27: 0.0185 | I27: Interest Rate: | J27: 0.022 | L27: Interest Rate: | M27: 0.0165
C28: Pmts/Yr: | D28: 2 | F28: Pmts/Yr: | G28: 2 | I28: Pmts/Yr: | J28: 2 | L28: Pmts/Yr: | M28: 2
