Workbook
Name EC_CCMO_BasePay: 'Exec Comp'!$1503:$1503
Name EC_CCMO_EquityComp_Percent: 'Exec Comp'!$1507:$1507
Name EC_CCMO_SharesOwned: 'Exec Comp'!$1692:$1692
Name EC_CCMO_TotalComp: 'Exec Comp'!$1506:$1506
Name EC_CEO_BasePay: 'Exec Comp'!$7:$7
Name EC_CEO_EquityComp_Percent: 'Exec Comp'!$13:$13
Name EC_CEO_SharesOwned: 'Exec Comp'!$456:$456
Name EC_CEO_TotalComp: 'Exec Comp'!$12:$12
Name EC_CFO_BasePay: 'Exec Comp'!$976:$976
Name EC_CFO_EquityComp_Percent: 'Exec Comp'!$982:$982
Name EC_CFO_SharesOwned: 'Exec Comp'!$1164:$1164
Name EC_CFO_TotalComp: 'Exec Comp'!$981:$981
Name EC_CLO_BasePay: 'Exec Comp'!$1166:$1166
Name EC_CLO_EquityComp_Percent: 'Exec Comp'!$1172:$1172
Name EC_CLO_SharesOwned: 'Exec Comp'!$1501:$1501
Name EC_CLO_TotalComp: 'Exec Comp'!$1171:$1171
Name EC_CoCEOCCO_BasePay: 'Exec Comp'!$458:$458
Name EC_CoCEOCCO_EquityComp_Percent: 'Exec Comp'!$464:$464
Name EC_CoCEOCCO_SharesOwned: 'Exec Comp'!$720:$720
Name EC_CoCEOCCO_TotalComp: 'Exec Comp'!$463:$463
Name EC_Person0187_BasePay: 'Exec Comp'!$722:$722
Name EC_Person0187_EquityComp_Percent: 'Exec Comp'!$726:$726
Name EC_Person0187_SharesOwned: 'Exec Comp'!$974:$974
Name EC_Person0187_TotalComp: 'Exec Comp'!$725:$725
Name EC_CTO_BasePay: 'Exec Comp'!$1694:$1694
Name EC_CTO_EquityComp_Percent: 'Exec Comp'!$1698:$1698
Name EC_CTO_OptionsAwards: 'Exec Comp'!$1695:$1695
Name EC_CTO_SharesOwned: 'Exec Comp'!$A$1733
Name EC_CTO_TotalComp: 'Exec Comp'!$1697:$1697
Name EC_Director_Compensation_Cash: 'Exec Comp'!$1755:$1755
Name EC_Director_Compensation_Total: 'Exec Comp'!$1780:$1780
Name EC_Directors_Current: 'Exec Comp'!$1736:$1736
Name EC_Directors_Current_Diverse: 'Exec Comp'!$1739:$1739
Name EC_Directors_Current_Female: 'Exec Comp'!$1738:$1738
Name EC_Directors_Current_Independent: 'Exec Comp'!$1737:$1737
Name EC_Directors_Nominees: 'Exec Comp'!$1741:$1741
Name GD.CompanyName: Guidance!$B$1
Name GD.MRQ: Guidance!$F$2
Name GD_Difference_Mid_Absolute: Guidance!$P:$P
Name GD_Difference_Mid_Relative: Guidance!$Q:$Q
Name GD_Guidance_High: Guidance!$J:$J
Name GD_Guidance_Low: Guidance!$I:$I
Name GD_Guidance_Mid: Guidance!$K:$K
Name GD_Header_Column: Guidance!$5:$5
Name GD_Header_Section: Guidance!$4:$4
Name GD_Index: Guidance!$A:$A
Name GD_Item: Guidance!$D:$D
Name GD_Item_BasePeriod: Guidance!$G:$G
Name GD_Item_FiscalPeriod: Guidance!$F:$F
Name GD_Item_Name: Guidance!$E:$E
Name GD_Model_Output: Guidance!$N:$N
Name GD_Model_Type: Guidance!$M:$M
Name GD_Type: Guidance!$B:$B
Name GD_Update_Date: Guidance!$S:$S
Name GD_Update_Link: Guidance!$T:$T
Name HP.MRFX: Model!$B$1411
Name HP.ReportCurrency: Model!$B$1410
Name HP.Ticker: Model!$A$2
Name HP.TradeCurrency: Model!$B$1408
Name HP.TradeCurrency.HardCoded: Model!$B$1409

Sheet Model
A1: Company1933, Inc.
A2: =CHOOSE(MO.DataSourceIndex,MO.Ticker.Bloomberg,MO.Ticker.CapIQ,MO.Ticker.FactSet,MO.Ticker.Thomson) | C2: =EOMONTH(C4,-12)
A3: =HP.TradeCurrency | B3: =IF(MO.RealTime="OFF",MO.LastPriceHardcoded,MO.LastPriceFormula) | C3: =C4-C2 | D3: =D4-C4 | E3: =E4-D4 | F3: =F4-E4 | G3: =G4-F4 | H3: =H4-G4 | I3: =I4-H4 | J3: =J4-I4 | K3: =K4-F4 | L3: =L4-K4 | M3: =M4-L4 | N3: =N4-M4 | O3: =O4-N4 | P3: =P4-K4 | Q3: =Q4-P4 | R3: =R4-Q4 | S3: =S4-R4 | T3: =T4-S4 | U3: =U4-P4 | V3: =V4-U4 | W3: =W4-V4 | X3: =X4-W4 | Y3: =Y4-X4 | Z3: =Z4-U4 | AA3: =AA4-Z4 | AB3: =AB4-AA4 | AC3: =AC4-AB4 | AD3: =AD4-AC4 | AE3: =AE4-Z4 | AF3: =AF4-AE4 | AG3: =AG4-AF4 | AH3: =AH4-AG4 | AI3: =AI4-AH4 | AJ3: =AJ4-AE4 | AK3: =AK4-AJ4 | AL3: =AL4-AK4 | AM3: =AM4-AL4 | AN3: =AN4-AM4 | AO3: =AO4-AJ4 | AP3: =AP4-AO4 | AQ3: =AQ4-AP4 | AR3: =AR4-AQ4 | AS3: =AS4-AR4 | AT3: =AT4-AO4 | AU3: =AU4-AT4 | AV3: =AV4-AU4 | AW3: =AW4-AV4 | AX3: =AX4-AW4 | AY3: =AY4-AT4 | AZ3: =AZ4-AY4 | BA3: =BA4-AZ4 | BB3: =BB4-BA4 | BC3: =BC4-BB4 | BD3: =BD4-AY4 | BE3: =BE4-BD4 | BF3: =BF4-BE4 | BG3: =BG4-BF4 | BH3: =BH4-BG4 | BI3: =BI4-BD4 | BJ3: =BJ4-BI4 | BK3: =BK4-BJ4 | BL3: =BL4-BK4 | BM3: =BM4-BL4 | BN3: =BN4-BI4 | BO3: =BO4-BN4 | BP3: =BP4-BO4 | BQ3: =BQ4-BP4 | BR3: =BR4-BQ4 | BS3: =BS4-BN4 | BT3: =BT4-BS4 | BU3: =BU4-BT4 | BV3: =BV4-BU4 | BW3: =BW4-BV4 | BX3: =BX4-BS4 | BY3: =BY4-BX4 | BZ3: =BZ4-BY4 | CA3: =CA4-BZ4 | CB3: =CB4-CA4 | CC3: =CC4-BX4 | CD3: =CD4-CC4 | CE3: =CE4-CD4 | CF3: =CF4-CE4
A4: Bloomberg | B4: =IF(AND(MO.RealTimeStockPriceToggle,MO.LastPriceFormula<>"N/A"),"ON","OFF") | C4: 40178 | D4: =EOMONTH(C4,12) | E4: =EOMONTH(D4,12) | F4: =EOMONTH(E4,12) | G4: =EOMONTH(F4,3) | H4: =EOMONTH(G4,3) | I4: =EOMONTH(H4,3) | J4: =EOMONTH(I4,3) | K4: =J4 | L4: =EOMONTH(K4,3) | M4: =EOMONTH(L4,3) | N4: =EOMONTH(M4,3) | O4: =EOMONTH(N4,3) | P4: =O4 | Q4: =EOMONTH(P4,3) | R4: =EOMONTH(Q4,3) | S4: =EOMONTH(R4,3) | T4: =EOMONTH(S4,3) | U4: =T4 | V4: =EOMONTH(U4,3) | W4: =EOMONTH(V4,3) | X4: =EOMONTH(W4,3) | Y4: =EOMONTH(X4,3) | Z4: =Y4 | AA4: =EOMONTH(Z4,3) | AB4: =EOMONTH(AA4,3) | AC4: =EOMONTH(AB4,3) | AD4: =EOMONTH(AC4,3) | AE4: =AD4 | AF4: =EOMONTH(AE4,3) | AG4: =EOMONTH(AF4,3) | AH4: =EOMONTH(AG4,3) | AI4: =EOMONTH(AH4,3) | AJ4: =AI4 | AK4: =EOMONTH(AJ4,3) | AL4: =EOMONTH(AK4,3) | AM4: =EOMONTH(AL4,3) | AN4: =EOMONTH(AM4,3) | AO4: =AN4 | AP4: =EOMONTH(AO4,3) | AQ4: =EOMONTH(AP4,3) | AR4: =EOMONTH(AQ4,3) | AS4: =EOMONTH(AR4,3) | AT4: =AS4 | AU4: =EOMONTH(AT4,3) | AV4: =EOMONTH(AU4,3) | AW4: =EOMONTH(AV4,3) | AX4: =EOMONTH(AW4,3) | AY4: =AX4 | AZ4: =EOMONTH(AY4,3) | BA4: =EOMONTH(AZ4,3) | BB4: =EOMONTH(BA4,3) | BC4: =EOMONTH(BB4,3) | BD4: =BC4 | BE4: =EOMONTH(BD4,3) | BF4: =EOMONTH(BE4,3) | BG4: =EOMONTH(BF4,3) | BH4: =EOMONTH(BG4,3) | BI4: =BH4 | BJ4: =EOMONTH(BI4,3) | BK4: =EOMONTH(BJ4,3) | BL4: =EOMONTH(BK4,3) | BM4: =EOMONTH(BL4,3) | BN4: =BM4 | BO4: =EOMONTH(BN4,3) | BP4: =EOMONTH(BO4,3) | BQ4: =EOMONTH(BP4,3) | BR4: =EOMONTH(BQ4,3) | BS4: =BR4 | BT4: =EOMONTH(BS4,3) | BU4: =EOMONTH(BT4,3) | BV4: =EOMONTH(BU4,3) | BW4: =EOMONTH(BV4,3) | BX4: =BW4 | BY4: =EOMONTH(BX4,3) | BZ4: =EOMONTH(BY4,3) | CA4: =EOMONTH(BZ4,3) | CB4: =EOMONTH(CA4,3) | CC4: =CB4 | CD4: =EOMONTH(CC4,12) | CE4: =EOMONTH(CD4,12) | CF4: =EOMONTH(CE4,12)
A5: =MO.ReportCurrency | C5: FY2009 | D5: =CONCATENATE("FY",RIGHT(C5,4)+1) | E5: =CONCATENATE("FY",RIGHT(D5,4)+1) | F5: =CONCATENATE("FY",RIGHT(E5,4)+1) | G5: =CONCATENATE("Q1","-",RIGHT(F5,4)+1) | H5: =CONCATENATE("Q2","-",RIGHT(G5,4)) | I5: =CONCATENATE("Q3","-",RIGHT(H5,4)) | J5: =CONCATENATE("Q4","-",RIGHT(I5,4)) | K5: =CONCATENATE("FY",RIGHT(F5,4)+1) | L5: =CONCATENATE("Q1","-",RIGHT(K5,4)+1) | M5: =CONCATENATE("Q2","-",RIGHT(L5,4)) | N5: =CONCATENATE("Q3","-",RIGHT(M5,4)) | O5: =CONCATENATE("Q4","-",RIGHT(N5,4)) | P5: =CONCATENATE("FY",RIGHT(K5,4)+1) | Q5: =CONCATENATE("Q1","-",RIGHT(P5,4)+1) | R5: =CONCATENATE("Q2","-",RIGHT(Q5,4)) | S5: =CONCATENATE("Q3","-",RIGHT(R5,4)) | T5: =CONCATENATE("Q4","-",RIGHT(S5,4)) | U5: =CONCATENATE("FY",RIGHT(P5,4)+1) | V5: =CONCATENATE("Q1","-",RIGHT(U5,4)+1) | W5: =CONCATENATE("Q2","-",RIGHT(V5,4)) | X5: =CONCATENATE("Q3","-",RIGHT(W5,4)) | Y5: =CONCATENATE("Q4","-",RIGHT(X5,4)) | Z5: =CONCATENATE("FY",RIGHT(U5,4)+1) | AA5: =CONCATENATE("Q1","-",RIGHT(Z5,4)+1) | AB5: =CONCATENATE("Q2","-",RIGHT(AA5,4)) | AC5: =CONCATENATE("Q3","-",RIGHT(AB5,4)) | AD5: =CONCATENATE("Q4","-",RIGHT(AC5,4)) | AE5: =CONCATENATE("FY",RIGHT(Z5,4)+1) | AF5: =CONCATENATE("Q1","-",RIGHT(AE5,4)+1) | AG5: =CONCATENATE("Q2","-",RIGHT(AF5,4)) | AH5: =CONCATENATE("Q3","-",RIGHT(AG5,4)) | AI5: =CONCATENATE("Q4","-",RIGHT(AH5,4)) | AJ5: =CONCATENATE("FY",RIGHT(AE5,4)+1) | AK5: =CONCATENATE("Q1","-",RIGHT(AJ5,4)+1) | AL5: =CONCATENATE("Q2","-",RIGHT(AK5,4)) | AM5: =CONCATENATE("Q3","-",RIGHT(AL5,4)) | AN5: =CONCATENATE("Q4","-",RIGHT(AM5,4)) | AO5: =CONCATENATE("FY",RIGHT(AJ5,4)+1) | AP5: =CONCATENATE("Q1","-",RIGHT(AO5,4)+1) | AQ5: =CONCATENATE("Q2","-",RIGHT(AP5,4)) | AR5: =CONCATENATE("Q3","-",RIGHT(AQ5,4)) | AS5: =CONCATENATE("Q4","-",RIGHT(AR5,4)) | AT5: =CONCATENATE("FY",RIGHT(AO5,4)+1) | AU5: =CONCATENATE("Q1","-",RIGHT(AT5,4)+1) | AV5: =CONCATENATE("Q2","-",RIGHT(AU5,4)) | AW5: =CONCATENATE("Q3","-",RIGHT(AV5,4)) | AX5: =CONCATENATE("Q4","-",RIGHT(AW5,4)) | AY5: =CONCATENATE("FY",RIGHT(AT5,4)+1) | AZ5: =CONCATENATE("Q1","-",RIGHT(AY5,4)+1) | BA5: =CONCATENATE("Q2","-",RIGHT(AZ5,4)) | BB5: =CONCATENATE("Q3","-",RIGHT(BA5,4)) | BC5: =CONCATENATE("Q4","-",RIGHT(BB5,4)) | BD5: =CONCATENATE("FY",RIGHT(AY5,4)+1) | BE5: =CONCATENATE("Q1","-",RIGHT(BD5,4)+1) | BF5: =CONCATENATE("Q2","-",RIGHT(BE5,4)) | BG5: =CONCATENATE("Q3","-",RIGHT(BF5,4)) | BH5: =CONCATENATE("Q4","-",RIGHT(BG5,4)) | BI5: =CONCATENATE("FY",RIGHT(BD5,4)+1) | BJ5: =CONCATENATE("Q1","-",RIGHT(BI5,4)+1) | BK5: =CONCATENATE("Q2","-",RIGHT(BJ5,4)) | BL5: =CONCATENATE("Q3","-",RIGHT(BK5,4)) | BM5: =CONCATENATE("Q4","-",RIGHT(BL5,4)) | BN5: =CONCATENATE("FY",RIGHT(BI5,4)+1) | BO5: =CONCATENATE("Q1","-",RIGHT(BN5,4)+1) | BP5: =CONCATENATE("Q2","-",RIGHT(BO5,4)) | BQ5: =CONCATENATE("Q3","-",RIGHT(BP5,4)) | BR5: =CONCATENATE("Q4","-",RIGHT(BQ5,4)) | BS5: =CONCATENATE("FY",RIGHT(BN5,4)+1) | BT5: =CONCATENATE("Q1","-",RIGHT(BS5,4)+1) | BU5: =CONCATENATE("Q2","-",RIGHT(BT5,4)) | BV5: =CONCATENATE("Q3","-",RIGHT(BU5,4)) | BW5: =CONCATENATE("Q4","-",RIGHT(BV5,4)) | BX5: =CONCATENATE("FY",RIGHT(BS5,4)+1) | BY5: =CONCATENATE("Q1","-",RIGHT(BX5,4)+1) | BZ5: =CONCATENATE("Q2","-",RIGHT(BY5,4)) | CA5: =CONCATENATE("Q3","-",RIGHT(BZ5,4)) | CB5: =CONCATENATE("Q4","-",RIGHT(CA5,4)) | CC5: =CONCATENATE("FY",RIGHT(BX5,4)+1) | CD5: =CONCATENATE("FY",RIGHT(CC5,4)+1) | CE5: =CONCATENATE("FY",RIGHT(CD5,4)+1) | CF5: =CONCATENATE("FY",RIGHT(CE5,4)+1)
A6: Consolidated Summary
A7: BoP Total Global Paid Streaming Memberships, 000s | G7: =F9 | H7: =G9 | I7: =H9 | J7: =I9 | K7: =F9 | L7: =K9 | M7: =L9 | N7: =M9 | O7: =N9 | P7: =K9 | Q7: =P9 | R7: =Q9 | S7: =R9 | T7: =S9 | U7: =P9 | V7: =U9 | W7: =V9 | X7: =W9 | Y7: =X9 | Z7: =U9 | AA7: =Z9 | AB7: =AA9 | AC7: =AB9 | AD7: =AC9 | AE7: =Z9 | AF7: =AE9 | AG7: =AF9 | AH7: =AG9 | AI7: =AH9 | AJ7: =AE9 | AK7: =AJ9 | AL7: =AK9 | AM7: =AL9 | AN7: =AM9 | AO7: =AJ9 | AP7: =AO9 | AQ7: =AP9 | AR7: =AQ9 | AS7: =AR9 | AT7: =AO9 | AU7: =AT9 | AV7: =AU9 | AW7: =AV9 | AX7: =AW9 | AY7: =AT9 | AZ7: =AY9 | BA7: =AZ9 | BB7: =BA9 | BC7: =BB9 | BD7: =AY9 | BE7: =BD9 | BF7: =BE9 | BG7: =BF9 | BH7: =BG9 | BI7: =BD9 | BJ7: =BI9 | BK7: =BJ9 | BL7: =BK9 | BM7: =BL9 | BN7: =BI9 | BO7: =BN9 | BP7: =BO9 | BQ7: =BP9 | BR7: =BQ9 | BS7: =BN9 | BT7: =BS9 | BU7: =BT9 | BV7: =BU9 | BW7: =BV9 | BX7: =BS9 | BY7: =BX9 | BZ7: =BY9 | CA7: =BZ9 | CB7: =CA9 | CC7: =BX9 | CD7: =CC9 | CE7: =CD9 | CF7: =CE9
A8: Total paid streaming memberships net additions, 000s | G8: =G9-G7 | H8: =H9-H7 | I8: =I9-I7 | J8: =J9-J7 | K8: =K9-K7 | L8: =L9-L7 | M8: =M9-M7 | N8: =N9-N7 | ... CF8: =CF9-CF7
A9: EoP Total Global Paid Streaming Memberships, 000s | F9: =F150 | G9: =G150 | H9: =H150 | I9: =I150 | J9: =J150 | K9: =K150 | L9: =L150 | M9: =M150 | ... BQ9: =BQ150 | BR9: 325000 | BS9: =BR9 | BT9: =BT150 | BU9: =BU150 | BV9: =BV150 | BW9: =BW150 | BX9: =BX150 | BY9: =BY150 | BZ9: =BZ150 | CA9: =CA150 | ... CF9: =CF150
A10: Q/Q Global EOP paid streaming memberships growth, % | H10: =H9/G9-1 | I10: =I9/H9-1 | J10: =J9/I9-1 | L10: =L9/J9-1 | M10: =M9/L9-1 | N10: =N9/M9-1 | O10: =O9/N9-1 | Q10: =Q9/O9-1 | R10: =R9/Q9-1 | S10: =S9/R9-1 | T10: =T9/S9-1 | V10: =V9/T9-1 | W10: =W9/V9-1 | X10: =X9/W9-1 | Y10: =Y9/X9-1 | AA10: =AA9/Y9-1 | AB10: =AB9/AA9-1 | AC10: =AC9/AB9-1 | AD10: =AD9/AC9-1 | AF10: =AF9/AD9-1 | AG10: =AG9/AF9-1 | AH10: =AH9/AG9-1 | AI10: =AI9/AH9-1 | AK10: =AK9/AI9-1 | AL10: =AL9/AK9-1 | AM10: =AM9/AL9-1 | AN10: =AN9/AM9-1 | AP10: =AP9/AN9-1 | AQ10: =AQ9/AP9-1 | AR10: =AR9/AQ9-1 | AS10: =AS9/AR9-1 | AU10: =AU9/AS9-1 | AV10: =AV9/AU9-1 | AW10: =AW9/AV9-1 | AX10: =AX9/AW9-1 | AZ10: =AZ9/AX9-1 | BA10: =BA9/AZ9-1 | BB10: =BB9/BA9-1 | BC10: =BC9/BB9-1 | BE10: =BE9/BC9-1 | BF10: =BF9/BE9-1 | BG10: =BG9/BF9-1 | BH10: =BH9/BG9-1 | BJ10: =BJ9/BH9-1 | BK10: =BK9/BJ9-1 | BL10: =BL9/BK9-1 | BM10: =BM9/BL9-1 | BO10: =BO9/BM9-1 | BP10: =BP9/BO9-1 | BQ10: =BQ9/BP9-1 | BR10: =BR9/BQ9-1 | BT10: =BT9/BR9-1 | BU10: =BU9/BT9-1 | BV10: =BV9/BU9-1 | BW10: =BW9/BV9-1 | BY10: =BY9/BW9-1 | BZ10: =BZ9/BY9-1 | CA10: =CA9/BZ9-1 | CB10: =CB9/CA9-1
A11: Y/Y Global EOP paid streaming memberships growth, % | K11: =K9/F9-1 | L11: =L9/G9-1 | M11: =M9/H9-1 | N11: =N9/I9-1 | O11: =O9/J9-1 | P11: =P9/K9-1 | Q11: =Q9/L9-1 | R11: =R9/M9-1 | ... CC11: =CC9/BX9-1 | CD11: =CD9/CC9-1 | CE11: =CE9/CD9-1 | CF11: =CF9/CE9-1
A12: Total Average Paying Memberships, 000s | G12: =AVERAGE(G9,G7) | H12: =AVERAGE(H9,H7) | I12: =AVERAGE(I9,I7) | J12: =AVERAGE(J9,J7) | K12: =AVERAGE(G12,H12,I12,J12) | L12: =AVERAGE(L9,L7) | M12: =AVERAGE(M9,M7) | N12: =AVERAGE(N9,N7) | O12: =AVERAGE(O9,O7) | P12: =AVERAGE(L12,M12,N12,O12) | Q12: =AVERAGE(Q9,Q7) | R12: =AVERAGE(R9,R7) | S12: =AVERAGE(S9,S7) | T12: =AVERAGE(T9,T7) | U12: =AVERAGE(Q12,R12,S12,T12) | V12: =AVERAGE(V9,V7) | W12: =AVERAGE(W9,W7) | X12: =AVERAGE(X9,X7) | Y12: =AVERAGE(Y9,Y7) | Z12: =AVERAGE(V12,W12,X12,Y12) | AA12: =AVERAGE(AA9,AA7) | AB12: =AVERAGE(AB9,AB7) | AC12: =AVERAGE(AC9,AC7) | AD12: =AVERAGE(AD9,AD7) | AE12: =AVERAGE(AA12,AB12,AC12,AD12) | AF12: =AVERAGE(AF9,AF7) | AG12: =AVERAGE(AG9,AG7) | AH12: =AVERAGE(AH9,AH7) | AI12: =AVERAGE(AI9,AI7) | AJ12: =AVERAGE(AF12,AG12,AH12,AI12) | AK12: =AVERAGE(AK9,AK7) | AL12: =AVERAGE(AL9,AL7) | AM12: =AVERAGE(AM9,AM7) | AN12: =AVERAGE(AN9,AN7) | AO12: =AVERAGE(AK12,AL12,AM12,AN12) | AP12: =AVERAGE(AP9,AP7) | AQ12: =AVERAGE(AQ9,AQ7) | AR12: =AVERAGE(AR9,AR7) | AS12: =AVERAGE(AS9,AS7) | AT12: =AVERAGE(AP12,AQ12,AR12,AS12) | AU12: =AVERAGE(AU9,AU7) | AV12: =AVERAGE(AV9,AV7) | AW12: =AVERAGE(AW9,AW7) | AX12: =AVERAGE(AX9,AX7) | AY12: =AVERAGE(AU12,AV12,AW12,AX12) | AZ12: =AVERAGE(AZ9,AZ7) | BA12: =AVERAGE(BA9,BA7) | BB12: =AVERAGE(BB9,BB7) | BC12: =AVERAGE(BC9,BC7) | BD12: =AVERAGE(AZ12,BA12,BB12,BC12) | BE12: =AVERAGE(BE9,BE7) | BF12: =AVERAGE(BF9,BF7) | BG12: =AVERAGE(BG9,BG7) | BH12: =AVERAGE(BH9,BH7) | BI12: =AVERAGE(BE12,BF12,BG12,BH12) | BJ12: =AVERAGE(BJ9,BJ7) | BK12: =AVERAGE(BK9,BK7) | BL12: =AVERAGE(BL9,BL7) | BM12: =AVERAGE(BM9,BM7) | BN12: =AVERAGE(BJ12,BK12,BL12,BM12) | BO12: =AVERAGE(BO9,BO7) | BP12: =AVERAGE(BP9,BP7) | BQ12: =AVERAGE(BQ9,BQ7) | BR12: =AVERAGE(BR9,BR7) | BS12: =AVERAGE(BO12,BP12,BQ12,BR12) | BT12: =AVERAGE(BT9,BT7) | BU12: =AVERAGE(BU9,BU7) | BV12: =AVERAGE(BV9,BV7) | BW12: =AVERAGE(BW9,BW7) | BX12: =AVERAGE(BT12,BU12,BV12,BW12) | BY12: =AVERAGE(BY9,BY7) | BZ12: =AVERAGE(BZ9,BZ7) | CA12: =AVERAGE(CA9,CA7) | CB12: =AVERAGE(CB9,CB7) | CC12: =AVERAGE(BY12,BZ12,CA12,CB12) | CD12: =AVERAGE(CD9,CD7) | CE12: =AVERAGE(CE9,CE7) | CF12: =AVERAGE(CF9,CF7)
A13: Q/Q Total average paying memberships growth, % | H13: =H12/G12-1 | I13: =I12/H12-1 | J13: =J12/I12-1 | L13: =L12/J12-1 | M13: =M12/L12-1 | N13: =N12/M12-1 | O13: =O12/N12-1 | Q13: =Q12/O12-1 | R13: =R12/Q12-1 | S13: =S12/R12-1 | T13: =T12/S12-1 | V13: =V12/T12-1 | W13: =W12/V12-1 | X13: =X12/W12-1 | Y13: =Y12/X12-1 | AA13: =AA12/Y12-1 | AB13: =AB12/AA12-1 | AC13: =AC12/AB12-1 | AD13: =AD12/AC12-1 | AF13: =AF12/AD12-1 | AG13: =AG12/AF12-1 | AH13: =AH12/AG12-1 | AI13: =AI12/AH12-1 | AK13: =AK12/AI12-1 | AL13: =AL12/AK12-1 | AM13: =AM12/AL12-1 | AN13: =AN12/AM12-1 | AP13: =AP12/AN12-1 | AQ13: =AQ12/AP12-1 | AR13: =AR12/AQ12-1 | AS13: =AS12/AR12-1 | AU13: =AU12/AS12-1 | AV13: =AV12/AU12-1 | AW13: =AW12/AV12-1 | AX13: =AX12/AW12-1 | AZ13: =AZ12/AX12-1 | BA13: =BA12/AZ12-1 | BB13: =BB12/BA12-1 | BC13: =BC12/BB12-1 | BE13: =BE12/BC12-1 | BF13: =BF12/BE12-1 | BG13: =BG12/BF12-1 | BH13: =BH12/BG12-1 | BJ13: =BJ12/BH12-1 | BK13: =BK12/BJ12-1 | BL13: =BL12/BK12-1 | BM13: =BM12/BL12-1 | BO13: =BO12/BM12-1 | BP13: =BP12/BO12-1 | BQ13: =BQ12/BP12-1 | BR13: =BR12/BQ12-1 | BT13: =BT12/BR12-1 | BU13: =BU12/BT12-1 | BV13: =BV12/BU12-1 | BW13: =BW12/BV12-1 | BY13: =BY12/BW12-1 | BZ13: =BZ12/BY12-1 | CA13: =CA12/BZ12-1 | CB13: =CB12/CA12-1
A14: Y/Y Total average paying memberships growth, % | L14: =L12/G12-1 | M14: =M12/H12-1 | N14: =N12/I12-1 | O14: =O12/J12-1 | P14: =P12/K12-1 | Q14: =Q12/L12-1 | R14: =R12/M12-1 | S14: =S12/N12-1 | ... CC14: =CC12/BX12-1 | CD14: =CD12/CC12-1 | CE14: =CE12/CD12-1 | CF14: =CF12/CE12-1
A16: Total Global Streaming ARPU, $/Member | AA16: =AA183 | AB16: =AB183 | AC16: =AC183 | AD16: =AD183 | AE16: =AE183 | AF16: =AF183 | AG16: =AG183 | AH16: =AH183 | ... CF16: =CF183
A17: Q/Q Global streaming ARPU growth, % | AB17: =AB16/AA16-1 | AC17: =AC16/AB16-1 | AD17: =AD16/AC16-1 | AF17: =AF16/AD16-1 | AG17: =AG16/AF16-1 | AH17: =AH16/AG16-1 | AI17: =AI16/AH16-1 | AK17: =AK16/AI16-1 | AL17: =AL16/AK16-1 | AM17: =AM16/AL16-1 | AN17: =AN16/AM16-1 | AP17: =AP16/AN16-1 | AQ17: =AQ16/AP16-1 | AR17: =AR16/AQ16-1 | AS17: =AS16/AR16-1 | AU17: =AU16/AS16-1 | AV17: =AV16/AU16-1 | AW17: =AW16/AV16-1 | AX17: =AX16/AW16-1 | AZ17: =AZ16/AX16-1 | BA17: =BA16/AZ16-1 | BB17: =BB16/BA16-1 | BC17: =BC16/BB16-1 | BE17: =BE16/BC16-1 | BF17: =BF16/BE16-1 | BG17: =BG16/BF16-1 | BH17: =BH16/BG16-1 | BJ17: =BJ16/BH16-1 | BK17: =BK16/BJ16-1 | BL17: =BL16/BK16-1 | BM17: =BM16/BL16-1 | BO17: =BO16/BM16-1 | BP17: =BP16/BO16-1 | BQ17: =BQ16/BP16-1 | BR17: =BR16/BQ16-1 | BT17: =BT16/BR16-1 | BU17: =BU16/BT16-1 | BV17: =BV16/BU16-1 | BW17: =BW16/BV16-1 | BY17: =BY16/BW16-1 | BZ17: =BZ16/BY16-1 | CA17: =CA16/BZ16-1 | CB17: =CB16/CA16-1
A18: Y/Y Global streaming constant currency ARPU growth, % | AK18: 0.03 | AL18: 0.09 | AM18: 0.12 | AN18: 0.12 | AP18: 0.08 | AQ18: 0.05 | AR18: 0.01 | AS18: 0 | AU18: 0.05 | AV18: 0.04 | AW18: 0.05 | AX18: 0.07 | AZ18: 0.06 | BA18: 0.07 | BB18: 0.08 | BC18: 0.05 | BE18: 0.04 | BF18: -0.01 | BG18: -0.01 | BH18: 0.01 | BJ18: 0.04 | BK18: 0.05 | BL18: 0.05 | BM18: 0.03
A19: Y/Y Global streaming ARPU growth, % | AF19: =AF16/AA16-1 | AG19: =AG16/AB16-1 | AH19: =AH16/AC16-1 | AI19: =AI16/AD16-1 | AJ19: =AJ16/AE16-1 | AK19: =AK16/AF16-1 | AL19: =AL16/AG16-1 | AM19: =AM16/AH16-1 | ... CC19: =CC16/BX16-1 | CD19: =CD16/CC16-1 | CE19: =CE16/CD16-1 | CF19: =CF16/CE16-1
A21: Total Streaming Revenue, mm | F21: =F192 | G21: =G192 | H21: =H192 | I21: =I192 | J21: =J192 | K21: =K192 | L21: =L192 | M21: =M192 | ... CF21: =CF192
A22: Q/Q Streaming revenue growth, % | H22: =H21/G21-1 | I22: =I21/H21-1 | J22: =J21/I21-1 | L22: =L21/J21-1 | M22: =M21/L21-1 | N22: =N21/M21-1 | O22: =O21/N21-1 | Q22: =Q21/O21-1 | R22: =R21/Q21-1 | S22: =S21/R21-1 | T22: =T21/S21-1 | V22: =V21/T21-1 | W22: =W21/V21-1 | X22: =X21/W21-1 | Y22: =Y21/X21-1 | AA22: =AA21/Y21-1 | AB22: =AB21/AA21-1 | AC22: =AC21/AB21-1 | AD22: =AD21/AC21-1 | AF22: =AF21/AD21-1 | AG22: =AG21/AF21-1 | AH22: =AH21/AG21-1 | AI22: =AI21/AH21-1 | AK22: =AK21/AI21-1 | AL22: =AL21/AK21-1 | AM22: =AM21/AL21-1 | AN22: =AN21/AM21-1 | AP22: =AP21/AN21-1 | AQ22: =AQ21/AP21-1 | AR22: =AR21/AQ21-1 | AS22: =AS21/AR21-1 | AU22: =AU21/AS21-1 | AV22: =AV21/AU21-1 | AW22: =AW21/AV21-1 | AX22: =AX21/AW21-1 | AZ22: =AZ21/AX21-1 | BA22: =BA21/AZ21-1 | BB22: =BB21/BA21-1 | BC22: =BC21/BB21-1 | BE22: =BE21/BC21-1 | BF22: =BF21/BE21-1 | BG22: =BG21/BF21-1 | BH22: =BH21/BG21-1 | BJ22: =BJ21/BH21-1 | BK22: =BK21/BJ21-1 | BL22: =BL21/BK21-1 | BM22: =BM21/BL21-1 | BO22: =BO21/BM21-1 | BP22: =BP21/BO21-1 | BQ22: =BQ21/BP21-1 | BR22: =BR21/BQ21-1 | BT22: =BT21/BR21-1 | BU22: =BU21/BT21-1 | BV22: =BV21/BU21-1 | BW22: =BW21/BV21-1 | BY22: =BY21/BW21-1 | BZ22: =BZ21/BY21-1 | CA22: =CA21/BZ21-1 | CB22: =CB21/CA21-1
A23: Y/Y Streaming revenue growth, % | K23: =K21/F21-1 | L23: =L21/G21-1 | M23: =M21/H21-1 | N23: =N21/I21-1 | O23: =O21/J21-1 | P23: =P21/K21-1 | Q23: =Q21/L21-1 | R23: =R21/M21-1 | ... CC23: =CC21/BX21-1 | CD23: =CD21/CC21-1 | CE23: =CE21/CD21-1 | CF23: =CF21/CE21-1
A24: United States DVD Revenue, mm | F24: =F193 | G24: =G193 | H24: =H193 | I24: =I193 | J24: =J193 | K24: =K193 | L24: =L193 | M24: =M193 | ... BI24: =BI193
A25: Q/Q United States DVD revenue growth, % | H25: =H24/G24-1 | I25: =I24/H24-1 | J25: =J24/I24-1 | L25: =L24/J24-1 | M25: =M24/L24-1 | N25: =N24/M24-1 | O25: =O24/N24-1 | Q25: =Q24/O24-1 | R25: =R24/Q24-1 | S25: =S24/R24-1 | T25: =T24/S24-1 | V25: =V24/T24-1 | W25: =W24/V24-1 | X25: =X24/W24-1 | Y25: =Y24/X24-1 | AA25: =AA24/Y24-1 | AB25: =AB24/AA24-1 | AC25: =AC24/AB24-1 | AD25: =AD24/AC24-1 | AF25: =AF24/AD24-1 | AG25: =AG24/AF24-1 | AH25: =AH24/AG24-1 | AI25: =AI24/AH24-1 | AK25: =AK24/AI24-1 | AL25: =AL24/AK24-1 | AM25: =AM24/AL24-1 | AN25: =AN24/AM24-1 | AP25: =AP24/AN24-1 | AQ25: =AQ24/AP24-1 | AR25: =AR24/AQ24-1 | AS25: =AS24/AR24-1 | AU25: =AU24/AS24-1 | AV25: =AV24/AU24-1 | AW25: =AW24/AV24-1 | AX25: =AX24/AW24-1 | AZ25: =AZ24/AX24-1 | BA25: =BA24/AZ24-1 | BB25: =BB24/BA24-1 | BC25: =BC24/BB24-1 | BE25: =BE24/BC24-1 | BF25: =BF24/BE24-1 | BG25: =BG24/BF24-1
A26: Y/Y United States DVD revenue growth, % | K26: =K24/F24-1 | L26: =L24/G24-1 | M26: =M24/H24-1 | N26: =N24/I24-1 | O26: =O24/J24-1 | P26: =P24/K24-1 | Q26: =Q24/L24-1 | R26: =R24/M24-1 | ... BG26: =BG24/BB24-1 | BI26: =BI24/BD24-1
A28: Total Revenue, mm | C28: =C462 | D28: =D462 | E28: =E462 | F28: =F21+F24 | G28: =G21+G24 | H28: =H21+H24 | I28: =I21+I24 | J28: =J21+J24 | K28: =K21+K24 | L28: =L21+L24 | M28: =M21+M24 | ... CF28: =CF21+CF24
A29: =A463 | BU29: =BU463 | BV29: =BV463 | BW29: =BW463 | BX29: =BX463 | BY29: =BY463 | BZ29: =BZ463 | CA29: =CA463 | CB29: =CB463 | ... CF29: =CF463
A30: =A464 | AD30: =AD464 | AE30: =AE464 | AF30: =AF464 | AG30: =AG464 | AH30: =AH464 | AI30: =AI464 | AJ30: =AJ464 | AK30: =AK464 | ... CF30: =CF464
A31: Q/Q Total revenue growth, % | H31: =H28/G28-1 | I31: =I28/H28-1 | J31: =J28/I28-1 | L31: =L28/J28-1 | M31: =M28/L28-1 | N31: =N28/M28-1 | O31: =O28/N28-1 | Q31: =Q28/O28-1 | R31: =R28/Q28-1 | S31: =S28/R28-1 | T31: =T28/S28-1 | V31: =V28/T28-1 | W31: =W28/V28-1 | X31: =X28/W28-1 | Y31: =Y28/X28-1 | AA31: =AA28/Y28-1 | AB31: =AB28/AA28-1 | AC31: =AC28/AB28-1 | AD31: =AD28/AC28-1 | AF31: =AF28/AD28-1 | AG31: =AG28/AF28-1 | AH31: =AH28/AG28-1 | AI31: =AI28/AH28-1 | AK31: =AK28/AI28-1 | AL31: =AL28/AK28-1 | AM31: =AM28/AL28-1 | AN31: =AN28/AM28-1 | AP31: =AP28/AN28-1 | AQ31: =AQ28/AP28-1 | AR31: =AR28/AQ28-1 | AS31: =AS28/AR28-1 | AU31: =AU28/AS28-1 | AV31: =AV28/AU28-1 | AW31: =AW28/AV28-1 | AX31: =AX28/AW28-1 | AZ31: =AZ28/AX28-1 | BA31: =BA28/AZ28-1 | BB31: =BB28/BA28-1 | BC31: =BC28/BB28-1 | BE31: =BE28/BC28-1 | BF31: =BF28/BE28-1 | BG31: =BG28/BF28-1 | BH31: =BH28/BG28-1 | BJ31: =BJ28/BH28-1 | BK31: =BK28/BJ28-1 | BL31: =BL28/BK28-1 | BM31: =BM28/BL28-1 | BO31: =BO28/BM28-1 | BP31: =BP28/BO28-1 | BQ31: =BQ28/BP28-1 | BR31: =BR28/BQ28-1 | BT31: =BT28/BR28-1 | BU31: =BU28/BT28-1 | BV31: =BV28/BU28-1 | BW31: =BW28/BV28-1 | BY31: =BY28/BW28-1 | BZ31: =BZ28/BY28-1 | CA31: =CA28/BZ28-1 | CB31: =CB28/CA28-1
A32: Y/Y Total constant currency revenue growth (calculated), % | AK32: =AK35/AF28-1 | AL32: =AL35/AG28-1 | AM32: =AM35/AH28-1 | AN32: =AN35/AI28-1 | AO32: =AO35/AJ28-1 | AP32: =AP35/AK28-1 | AQ32: =AQ35/AL28-1 | AR32: =AR35/AM28-1 | ... BI32: =BI35/BD28-1 | BJ32: =BJ312 | BK32: =BK312 | BL32: =BL312 | BM32: =BM312 | BN32: =BN312 | BO32: =BO312 | BP32: =BP312 | BQ32: =BQ312 | ... BT32: =BT312
A33: Y/Y Total revenue growth, % | D33: =D28/C28-1 | E33: =E28/D28-1 | F33: =F28/E28-1 | K33: =K28/F28-1 | L33: =L28/G28-1 | M33: =M28/H28-1 | N33: =N28/I28-1 | O33: =O28/J28-1 | P33: =P28/K28-1 | Q33: =Q28/L28-1 | R33: =R28/M28-1 | ... CC33: =CC28/BX28-1 | CD33: =CD28/CC28-1 | CE33: =CE28/CD28-1 | CF33: =CF28/CE28-1
A35: Constant currency revenue, mm | AK35: =AK38-AK36 | AL35: =AL38-AL36 | AM35: =AM38-AM36 | AN35: =AN38-AN36 | AO35: =AO38-AO36 | AP35: =AP38-AP36 | AQ35: =AQ38-AQ36 | AR35: =AR38-AR36 | ... BI35: =BI38-BI36 | BJ35: =BJ38-SUM(BJ36:BJ37) | BK35: =BK38-SUM(BK36:BK37) | BL35: =BL38-SUM(BL36:BL37) | BM35: =BM38-SUM(BM36:BM37) | BN35: =BN38-SUM(BN36:BN37) | BO35: =BO38-SUM(BO36:BO37) | BP35: =BP38-SUM(BP36:BP37) | BQ35: =BQ38-SUM(BQ36:BQ37) | ... BT35: =BT38-SUM(BT36:BT37)
A36: FX impact, mm | AK36: -228 | AL36: -265 | AM36: -137 | AN36: -133 | AO36: -762 | AP36: -115 | AQ36: -289 | AR36: -158 | AS36: =AT36-SUM(AP36,AQ36,AR36) | AT36: -596 | AU36: 80 | AV36: 277 | AW36: 128 | AX36: =AY36-SUM(AU36,AV36,AW36) | AY36: 443 | AZ36: -280 | BA36: -339 | BB36: -548 | BC36: =BD36-SUM(AZ36,BA36,BB36) | BD36: -1773 | BE36: -345.859 | BF36: -231.144 | BG36: 8.548 | BH36: -28.294 | BI36: =SUM(BE36,BF36,BG36,BH36) | BJ36: =-BJ308 | BK36: =-BK308 | BL36: =-BL308 | BM36: =-BM308 | BN36: =-BN308 | BO36: =-BO308 | BP36: =-BP308 | BQ36: =-BQ308 | ... BT36: =-BT308
A37: Hedging (gains) losses included in revenue, mm | BJ37: =-BJ309 | BK37: =-BK309 | BL37: =-BL309 | BM37: =-BM309 | BN37: =-BN309 | BO37: =-BO309 | BP37: =-BP309 | BQ37: =-BQ309 | ... BT37: =-BT309
A38: Total Revenue, mm | AK38: =AK28 | AL38: =AL28 | AM38: =AM28 | AN38: =AN28 | AO38: =AO28 | AP38: =AP28 | AQ38: =AQ28 | AR38: =AR28 | ... BT38: =BT28
A40: Segmented Results - US and Canada Streaming (FS)
A41: United States EOP paid streaming memberships, 000s | F41: 25471 | G41: 27913 | H41: 28624 | I41: 29925 | J41: 31712 | K41: 31712 | L41: 34377 | M41: 35085 | N41: 36265 | O41: 37698 | P41: 37698 | Q41: 40315 | R41: 41057 | S41: 42068 | T41: 43401 | U41: 43401 | V41: 45714 | W41: 46004 | X41: 46479 | Y41: 47905 | Z41: 47905 | AA41: 49375 | AB41: 50323 | AC41: 51345 | AD41: 52810 | AE41: 52810 | AF41: 55087 | AG41: 55959 | AH41: 56957 | AI41: 58486 | AJ41: 58486 | AK41: 60229 | AL41: 60103 | AM41: 60620 | AN41: 61043 | AO41: 61043
A42: Q/Q United States EOP paid streaming membership growth, % | H42: =H41/G41-1 | I42: =I41/H41-1 | J42: =J41/I41-1 | L42: =L41/J41-1 | M42: =M41/L41-1 | N42: =N41/M41-1 | O42: =O41/N41-1 | Q42: =Q41/O41-1 | R42: =R41/Q41-1 | S42: =S41/R41-1 | T42: =T41/S41-1 | V42: =V41/T41-1 | W42: =W41/V41-1 | X42: =X41/W41-1 | Y42: =Y41/X41-1 | AA42: =AA41/Y41-1 | AB42: =AB41/AA41-1 | AC42: =AC41/AB41-1 | AD42: =AD41/AC41-1 | AF42: =AF41/AD41-1 | AG42: =AG41/AF41-1 | AH42: =AH41/AG41-1 | AI42: =AI41/AH41-1 | AK42: =AK41/AI41-1 | AL42: =AL41/AK41-1 | AM42: =AM41/AL41-1 | AN42: =AN41/AM41-1
A43: Y/Y United States EOP paid streaming membership growth, % | K43: =+K41/F41-1 | L43: =+L41/G41-1 | M43: =+M41/H41-1 | N43: =+N41/I41-1 | O43: =+O41/J41-1 | P43: =+P41/K41-1 | Q43: =+Q41/L41-1 | R43: =+R41/M41-1 | ... AO43: =+AO41/AJ41-1
A44: United States paid streaming memberships net additions, 000s | G44: =+G41-F41 | H44: =+H41-G41 | I44: =+I41-H41 | J44: =+J41-I41 | K44: =SUM(G44,H44,I44,J44) | L44: =+L41-K41 | M44: =+M41-L41 | N44: =+N41-M41 | O44: =+O41-N41 | P44: =SUM(L44,M44,N44,O44) | Q44: =+Q41-P41 | R44: =+R41-Q41 | S44: =+S41-R41 | T44: =+T41-S41 | U44: =SUM(Q44,R44,S44,T44) | V44: =+V41-U41 | W44: =+W41-V41 | X44: =+X41-W41 | Y44: =+Y41-X41 | Z44: =SUM(V44,W44,X44,Y44) | AA44: =+AA41-Z41 | AB44: =+AB41-AA41 | AC44: =+AC41-AB41 | AD44: =+AD41-AC41 | AE44: =SUM(AA44,AB44,AC44,AD44) | AF44: =+AF41-AE41 | AG44: =+AG41-AF41 | AH44: =+AH41-AG41 | AI44: =+AI41-AH41 | AJ44: =SUM(AF44,AG44,AH44,AI44) | AK44: =+AK41-AJ41 | AL44: =+AL41-AK41 | AM44: =+AM41-AL41 | AN44: =+AN41-AM41 | AO44: =SUM(AK44,AL44,AM44,AN44)
A45: Calculated Canada EOP paid streaming memberships, 000s | AA45: =+AA52-AA41 | AB45: =+AB52-AB41 | AC45: =+AC52-AC41 | AD45: =+AD52-AD41 | AE45: =+AE52-AE41 | AF45: =+AF52-AF41 | AG45: =+AG52-AG41 | AH45: =+AH52-AH41 | ... AO45: =+AO52-AO41
...

Sheet Exec Comp
A1: =MO.CompanyName
A2: =MO.Ticker | C2: =Model!C2 | D2: =Model!D2 | E2: =Model!E2 | F2: =Model!F2 | G2: =Model!G2 | H2: =Model!H2 | I2: =Model!I2 | J2: =Model!J2 | ... CF2: =Model!CF2
A3: =MO.TradingCurrency | B3: =MO.LastPrice | C3: =INDEX(MO_Common_FPDays,0,MATCH(C$5,MO_Common_ColumnHeader,0)) | D3: =INDEX(MO_Common_FPDays,0,MATCH(D$5,MO_Common_ColumnHeader,0)) | E3: =INDEX(MO_Common_FPDays,0,MATCH(E$5,MO_Common_ColumnHeader,0)) | F3: =INDEX(MO_Common_FPDays,0,MATCH(F$5,MO_Common_ColumnHeader,0)) | G3: =INDEX(MO_Common_FPDays,0,MATCH(G$5,MO_Common_ColumnHeader,0)) | H3: =INDEX(MO_Common_FPDays,0,MATCH(H$5,MO_Common_ColumnHeader,0)) | I3: =INDEX(MO_Common_FPDays,0,MATCH(I$5,MO_Common_ColumnHeader,0)) | J3: =INDEX(MO_Common_FPDays,0,MATCH(J$5,MO_Common_ColumnHeader,0)) | ... CF3: =INDEX(MO_Common_FPDays,0,MATCH(CF$5,MO_Common_ColumnHeader,0))
A4: =MO.DataSourceName | B4: =MO.RealTime | C4: =INDEX(MO_Common_QEndDate,0,MATCH(C$5,MO_Common_ColumnHeader,0)) | D4: =INDEX(MO_Common_QEndDate,0,MATCH(D$5,MO_Common_ColumnHeader,0)) | E4: =INDEX(MO_Common_QEndDate,0,MATCH(E$5,MO_Common_ColumnHeader,0)) | F4: =INDEX(MO_Common_QEndDate,0,MATCH(F$5,MO_Common_ColumnHeader,0)) | G4: =INDEX(MO_Common_QEndDate,0,MATCH(G$5,MO_Common_ColumnHeader,0)) | H4: =INDEX(MO_Common_QEndDate,0,MATCH(H$5,MO_Common_ColumnHeader,0)) | I4: =INDEX(MO_Common_QEndDate,0,MATCH(I$5,MO_Common_ColumnHeader,0)) | J4: =INDEX(MO_Common_QEndDate,0,MATCH(J$5,MO_Common_ColumnHeader,0)) | ... CF4: =INDEX(MO_Common_QEndDate,0,MATCH(CF$5,MO_Common_ColumnHeader,0))
A5: =MO.ReportFX | C5: =Model!C5 | D5: =Model!D5 | E5: =Model!E5 | F5: =Model!F5 | G5: =Model!G5 | H5: =Model!H5 | I5: =Model!I5 | J5: =Model!J5 | ... CF5: =Model!CF5
A6: Executive Compensation
A7: Co-CEO - Base Pay, 000s | AT7: 650 | AY7: 650 | BD7: 650 | BI7: 2890.385 | BN7: 3000
A8: Co-CEO - Stock Awards, 000s | BN8: 42707.872
A9: Co-CEO - Option Awards, 000s | AT9: 42428.878 | AY9: 39731.118 | BD9: 49408.182 | BI9: 22667.588 | BN9: 1951.611
A10: Co-CEO - Non-Equity Incentive Plan, 000s | BI10: 13938.549 | BN10: 12000
A11: Co-CEO - All other compensation, 000s | AT11: 147.146 | AY11: 442.607 | BD11: 1015.055 | BI11: 620.602 | BN11: 613.091
A12: Co-CEO - Total Comp, 000s | AT12: =SUM(AT7:AT11) | AY12: =SUM(AY7:AY11) | BD12: =SUM(BD7:BD11) | BI12: =SUM(BI7:BI11) | BN12: =SUM(BN7:BN11)
A13: Co-CEO - comp tied to equity, % | AT13: =SUM(AT9)/AT12 | AY13: =SUM(AY9)/AY12 | BD13: =SUM(BD9)/BD12 | BI13: =SUM(BI9)/BI12 | BN13: =SUM(BN9)/BN12
A14: Market Cap - EoP, mm | AT14: =Model!AT1008 | AU14: =Model!AU1008 | AV14: =Model!AV1008 | AW14: =Model!AW1008 | AX14: =Model!AX1008 | AY14: =Model!AY1008 | AZ14: =Model!AZ1008 | BA14: =Model!BA1008 | ... BT14: =Model!BT1008
A16: Co-CEO - Options 03/01/2022 # of unexercised exercisable options, 000s | AT16: 38.801
A17: Co-CEO - Options 03/01/2022 exercise price, $ | AT17: 16.11
A19: Co-CEO - Options 04/02/2022 # of unexercised exercisable options, 000s | AT19: 38.388
A20: Co-CEO - Options 04/02/2022 exercise price, $ | AT20: 16.28
A22: Co-CEO - Options 05/01/2022 # of unexercised exercisable options, 000s | AT22: 53.774
A23: Co-CEO - Options 05/01/2022 exercise price, $ | AT23: 11.62
A25: Co-CEO - Options 06/01/2022 # of unexercised exercisable options, 000s | AT25: 69.503
A26: Co-CEO - Options 06/01/2022 exercise price, $ | AT26: 8.99
A28: Co-CEO - Options 07/02/2022 # of unexercised exercisable options, 000s | AT28: 64.477
A29: Co-CEO - Options 07/02/2022 exercise price, $ | AT29: 9.69
A31: Co-CEO - Options 08/01/2022 # of unexercised exercisable options, 000s | AT31: 80.276
A32: Co-CEO - Options 08/01/2022 exercise price, $ | AT32: 7.79
... A59: Co-CEO - Options 05/01/2023 exercise price, $ | AT59: 30.42
A61: Co-CEO - Options 06/03/2023 # of unexercised exercisable options, 000s | AT61: 26.278 | AY61: 26.278 | BD61: 26.278
A62: Co-CEO - Options 06/03/2023 exercise price, $ | AT62: 31.71 | AY62: 31.71 | BD62: 31.71
A64: Co-CEO - Options 07/01/2023 # of unexercised exercisable options, 000s | AT64: 26.012 | AY64: 26.012 | BD64: 26.012
A65: Co-CEO - Options 07/01/2023 exercise price, $ | AT65: 32.04 | AY65: 32.04 | BD65: 32.04
A67: Co-CEO - Options 08/01/2023 # of unexercised exercisable options, 000s | AT67: 23.415 | AY67: 23.415 | BD67: 23.415
A68: Co-CEO - Options 08/01/2023 exercise price, $ | AT68: 35.59 | AY68: 35.59 | BD68: 35.59
A70: Co-CEO - Options 09/03/2023 # of unexercised exercisable options, 000s | AT70: 20.188 | AY70: 20.188 | BD70: 20.188
A71: Co-CEO - Options 09/03/2023 exercise price, $ | AT71: 41.29 | AY71: 41.29 | BD71: 41.29
A73: Co-CEO - Options 10/01/2023 # of unexercised exercisable options, 000s | AT73: 17.969 | AY73: 17.969 | BD73: 17.969
A74: Co-CEO - Options 10/01/2023 exercise price, $ | AT74: 46.37 | AY74: 46.37 | BD74: 46.37
A76: Co-CEO - Options 11/01/2023 # of unexercised exercisable options, 000s | AT76: 17.717 | AY76: 17.717 | BD76: 17.717
A77: Co-CEO - Options 11/01/2023 exercise price, $ | AT77: 47.04 | AY77: 47.04 | BD77: 47.04
... A176: Co-CEO - Options 08/01/2026 exercise price, $ | AT176: 94.37 | AY176: 94.37 | BD176: 94.37
...

Sheet Supplemental Data
A1: =MO.CompanyName
A2: =MO.Ticker | C2: =Model!C2 | D2: =Model!D2 | E2: =Model!E2 | F2: =Model!F2 | G2: =Model!G2 | H2: =Model!H2 | I2: =Model!I2 | J2: =Model!J2 | ... CF2: =Model!CF2
A3: =MO.TradingCurrency | B3: =MO.LastPrice | C3: =INDEX(MO_Common_FPDays,0,MATCH(C$5,MO_Common_ColumnHeader,0)) | D3: =INDEX(MO_Common_FPDays,0,MATCH(D$5,MO_Common_ColumnHeader,0)) | E3: =INDEX(MO_Common_FPDays,0,MATCH(E$5,MO_Common_ColumnHeader,0)) | F3: =INDEX(MO_Common_FPDays,0,MATCH(F$5,MO_Common_ColumnHeader,0)) | G3: =INDEX(MO_Common_FPDays,0,MATCH(G$5,MO_Common_ColumnHeader,0)) | H3: =INDEX(MO_Common_FPDays,0,MATCH(H$5,MO_Common_ColumnHeader,0)) | I3: =INDEX(MO_Common_FPDays,0,MATCH(I$5,MO_Common_ColumnHeader,0)) | J3: =INDEX(MO_Common_FPDays,0,MATCH(J$5,MO_Common_ColumnHeader,0)) | ... CF3: =INDEX(MO_Common_FPDays,0,MATCH(CF$5,MO_Common_ColumnHeader,0))
A4: =MO.DataSourceName | B4: =MO.RealTime | C4: =INDEX(MO_Common_QEndDate,0,MATCH(C$5,MO_Common_ColumnHeader,0)) | D4: =INDEX(MO_Common_QEndDate,0,MATCH(D$5,MO_Common_ColumnHeader,0)) | E4: =INDEX(MO_Common_QEndDate,0,MATCH(E$5,MO_Common_ColumnHeader,0)) | F4: =INDEX(MO_Common_QEndDate,0,MATCH(F$5,MO_Common_ColumnHeader,0)) | G4: =INDEX(MO_Common_QEndDate,0,MATCH(G$5,MO_Common_ColumnHeader,0)) | H4: =INDEX(MO_Common_QEndDate,0,MATCH(H$5,MO_Common_ColumnHeader,0)) | I4: =INDEX(MO_Common_QEndDate,0,MATCH(I$5,MO_Common_ColumnHeader,0)) | J4: =INDEX(MO_Common_QEndDate,0,MATCH(J$5,MO_Common_ColumnHeader,0)) | ... CF4: =INDEX(MO_Common_QEndDate,0,MATCH(CF$5,MO_Common_ColumnHeader,0))
A5: =MO.ReportFX | C5: =Model!C5 | D5: =Model!D5 | E5: =Model!E5 | F5: =Model!F5 | G5: =Model!G5 | H5: =Model!H5 | I5: =Model!I5 | J5: =Model!J5 | ... CF5: =Model!CF5
A6: Key Metrics - Content Obligations (FS)
A7: Current content liabilities, mm | D7: =Model!D1226 | E7: =Model!E1226 | F7: =Model!F1226 | G7: =Model!G1226 | H7: =Model!H1226 | I7: =Model!I1226 | J7: =K7 | K7: =Model!K1226 | L7: =Model!L1226 | M7: =Model!M1226 | N7: =Model!N1226 | O7: =P7 | P7: =Model!P1226 | Q7: =Model!Q1226 | R7: =Model!R1226 | S7: =Model!S1226 | T7: =U7 | U7: =Model!U1226 | V7: =Model!V1226 | W7: =Model!W1226 | X7: =Model!X1226 | Y7: =Z7 | Z7: =Model!Z1226 | AA7: =Model!AA1226 | AB7: =Model!AB1226 | AC7: =Model!AC1226 | AD7: =AE7 | AE7: =Model!AE1226 | AF7: =Model!AF1226 | AG7: =Model!AG1226 | AH7: =Model!AH1226 | AI7: =AJ7 | AJ7: =Model!AJ1226 | AK7: =Model!AK1226 | AL7: =Model!AL1226 | AM7: =Model!AM1226 | AN7: =AO7 | AO7: =Model!AO1226 | AP7: =Model!AP1226 | AQ7: =Model!AQ1226 | AR7: =Model!AR1226 | AS7: =AT7 | AT7: =Model!AT1226 | AU7: =Model!AU1226 | AV7: =Model!AV1226 | AW7: 4110.962 | AX7: =AY7 | AY7: =Model!AY1226 | AZ7: =Model!AZ1226 | BA7: =Model!BA1226 | BB7: =Model!BB1226 | BC7: =BD7 | BD7: =Model!BD1226 | BE7: =Model!BE1226 | BF7: =Model!BF1226 | BG7: =Model!BG1226 | BH7: =BI7 | BI7: =Model!BI1226 | BJ7: =Model!BJ1226 | BK7: =Model!BK1226 | BL7: =Model!BL1226 | BM7: =BN7 | BN7: =Model!BN1226 | BO7: =Model!BO1226 | BP7: =Model!BP1226 | BQ7: =Model!BQ1226 | BR7: =BS7 | BS7: =Model!BS1226 | BT7: =Model!BT1226
A8: Non-current content liabilities, mm | D8: =Model!D1237 | E8: =Model!E1237 | F8: =Model!F1237 | G8: =Model!G1237 | H8: =Model!H1237 | I8: =Model!I1237 | J8: =K8 | K8: =Model!K1237 | L8: =Model!L1237 | M8: =Model!M1237 | N8: =Model!N1237 | O8: =P8 | P8: =Model!P1237 | Q8: =Model!Q1237 | R8: =Model!R1237 | S8: =Model!S1237 | T8: =U8 | U8: =Model!U1237 | V8: =Model!V1237 | W8: =Model!W1237 | X8: =Model!X1237 | Y8: =Z8 | Z8: =Model!Z1237 | AA8: =Model!AA1237 | AB8: =Model!AB1237 | AC8: =Model!AC1237 | AD8: =AE8 | AE8: =Model!AE1237 | AF8: =Model!AF1237 | AG8: =Model!AG1237 | AH8: =Model!AH1237 | AI8: =AJ8 | AJ8: =Model!AJ1237 | AK8: =Model!AK1237 | AL8: =Model!AL1237 | AM8: =Model!AM1237 | AN8: =AO8 | AO8: =Model!AO1237 | AP8: =Model!AP1237 | AQ8: =Model!AQ1237 | AR8: =Model!AR1237 | AS8: =AT8 | AT8: =Model!AT1237 | AU8: =Model!AU1237 | AV8: =Model!AV1237 | AW8: 2301.026 | AX8: =AY8 | AY8: =Model!AY1237 | AZ8: =Model!AZ1237 | BA8: =Model!BA1237 | BB8: =Model!BB1237 | BC8: =BD8 | BD8: =Model!BD1237 | BE8: =Model!BE1237 | BF8: =Model!BF1237 | BG8: =Model!BG1237 | BH8: =BI8 | BI8: =Model!BI1237 | BJ8: =Model!BJ1237 | BK8: =Model!BK1237 | BL8: =Model!BL1237 | BM8: =BN8 | BN8: =Model!BN1237 | BO8: =Model!BO1237 | BP8: =Model!BP1237 | BQ8: =Model!BQ1237 | BR8: =BS8 | BS8: =Model!BS1237 | BT8: =Model!BT1237
A9: Other obligations not reflected in Balance sheet, mm | D9: =D10-D7-D8 | E9: =E10-E7-E8 | F9: =F10-F7-F8 | G9: =G10-G7-G8 | H9: =H10-H7-H8 | I9: =I10-I7-I8 | J9: =K9 | K9: =K10-K7-K8 | L9: =L10-L7-L8 | M9: =M10-M7-M8 | N9: =N10-N7-N8 | O9: =P9 | P9: =P10-P7-P8 | Q9: =Q10-Q7-Q8 | R9: =R10-R7-R8 | S9: =S10-S7-S8 | T9: =U9 | U9: =U10-U7-U8 | V9: =V10-V7-V8 | W9: =W10-W7-W8 | X9: =X10-X7-X8 | Y9: =Z9 | Z9: =Z10-Z7-Z8 | AA9: =AA10-AA7-AA8 | AB9: =AB10-AB7-AB8 | AC9: =AC10-AC7-AC8 | AD9: =AE9 | AE9: =AE10-AE7-AE8 | AF9: =AF10-AF7-AF8 | AG9: =AG10-AG7-AG8 | AH9: =AH10-AH7-AH8 | AI9: =AJ9 | AJ9: =AJ10-AJ7-AJ8 | AK9: =AK10-AK7-AK8 | AL9: =AL10-AL7-AL8 | AM9: =AM10-AM7-AM8 | AN9: =AO9 | AO9: =AO10-AO7-AO8 | AP9: =AP10-AP7-AP8 | AQ9: =AQ10-AQ7-AQ8 | AR9: =AR10-AR7-AR8 | AS9: =AT9 | AT9: =AT10-AT7-AT8 | AU9: =AU10-AU7-AU8 | AV9: =AV10-AV7-AV8 | AW9: =AW10-AW7-AW8 | AX9: =AY9 | AY9: =AY10-AY7-AY8 | AZ9: =AZ10-AZ7-AZ8 | BA9: =BA10-BA7-BA8 | BB9: =BB10-BB7-BB8 | BC9: =BD9 | BD9: =BD10-BD7-BD8 | BE9: =BE10-BE7-BE8 | BF9: =BF10-BF7-BF8 | BG9: =BG10-BG7-BG8 | BH9: =BI9 | BI9: =BI10-BI7-BI8 | BJ9: =BJ10-BJ7-BJ8 | BK9: =BK10-BK7-BK8 | BL9: =BL10-BL7-BL8 | BM9: =BN9 | BN9: =BN10-BN7-BN8 | BO9: =BO10-BO7-BO8 | BP9: =BP10-BP7-BP8 | BQ9: =BQ10-BQ7-BQ8 | BR9: =BS9 | BS9: =BS10-BS7-BS8 | BT9: =BT10-BT7-BT8
A10: Total Content Obligations, mm | D10: 1299.176 | E10: 3907.198 | F10: 5633.685 | G10: 5672.486 | H10: 6368.105 | I10: 6505.351 | J10: =K10 | K10: 7252.161 | L10: 7123.209 | M10: 7728.05 | N10: 8857.227 | O10: =P10 | P10: 9451.112 | Q10: 9780.262 | R10: 10073.409 | S10: 10378.218 | T10: =U10 | U10: 10902.231 | V10: 12318.233 | W10: 13194.009 | X10: 14353.045 | Y10: =Z10 | Z10: 14479.487 | AA10: 15290.134 | AB10: 15699.387 | AC10: 16991.93 | AD10: =AE10 | AE10: 17694.642 | AF10: 17937.682 | AG10: 18398.766 | AH10: 18645.758 | AI10: =AJ10 | AJ10: 19285.875 | AK10: 18922.789 | AL10: 18502.817 | AM10: 19141.543 | AN10: =AO10 | AO10: 19490.082 | AP10: 19174.038 | AQ10: 19133.34 | AR10: 19072.254 | AS10: =AT10 | AT10: 19218.83 | AU10: 20725.165 | AV10: 21863.144 | AW10: 22465.54 | AX10: =AY10 | AY10: 23161.36 | AZ10: 22365.56 | BA10: 22769.606 | BB10: 21572.745 | BC10: =BD10 | BD10: 21831.947 | BE10: 21525.871 | BF10: =BF16 | BG10: =BG16 | BH10: =BI10 | BI10: 21713.349 | BJ10: 24195 | BK10: =BK16 | BL10: 22698.295 | BM10: =BN10 | BN10: 23248.931 | BO10: 21790.643 | BP10: 20967.27 | BQ10: 20940.9 | BR10: =BS10 | BS10: 24039.228 | BT10: 24139.431
A12: Content obligations due in less than one year, mm | D12: 530.878 | E12: 797.649 | F12: 2299.562 | G12: 2376.26 | H12: 2533.061 | I12: 2766.597 | J12: =K12 | K12: 2972.325 | L12: 3055.127 | M12: 3304.367 | N12: 3574.129 | O12: =P12 | P12: 3747.648 | Q12: 4016.95 | R12: 4271.285 | S12: 4535.209 | T12: =U12 | U12: 4703.172 | V12: 5161.279 | W12: 5544.875 | X12: 5895.205 | Y12: =Z12 | Z12: 6200.611 | AA12: 6599.754 | AB12: 6592.517 | AC12: 6984.36 | AD12: =AE12 | AE12: 7446.947 | AF12: 7949.544 | AG12: 8212.614 | AH12: 8407.156 | AI12: =AJ12 | AJ12: 8611.398 | AK12: 8888.491 | AL12: 8741.623 | AM12: 8993.612 | AN12: =AO12 | AO12: 8477.367 | AP12: 8618.185 | AQ12: 8415.792 | AR12: 8668.296 | AS12: =AT12 | AT12: 8980.868 | AU12: 9456.342 | AV12: 9885.589 | AW12: 10017.405 | AX12: =AY12 | AY12: 10019.306 | AZ12: 9861.979 | BA12: 10208.609 | BB12: 9667.326 | BC12: =BD12 | BD12: 10038.483 | BE12: 9771.665 | BF12: 9818.37 | BG12: 9512.081 | BH12: =BI12 | BI12: 10328.923 | BJ12: 11066.048 | BK12: 11456.834 | BL12: 11810.836 | BM12: =BN12 | BN12: 11424.696 | BO12: 10977.295 | BP12: 10842.959 | BQ12: 11267.688 | BR12: =BS12 | BS12: 11528.03 | BT12: 11779.222
A13: Content obligations due after one year and through three years, mm | D13: 531.698 | E13: 2384.373 | F13: 2715.294 | G13: 2696.896 | H13: 2864.331 | I13: 2829.201 | J13: =K13 | K13: 3266.907 | L13: 3393.761 | M13: 3732.38 | N13: 4176.621 | O13: =P13 | P13: 4495.103 | Q13: 4634.792 | R13: 4791.033 | S13: 4888.13 | T13: =U13 | U13: 5249.147 | V13: 5745.041 | W13: 6305.936 | X13: 6770.007 | Y13: =Z13 | Z13: 6731.336 | AA13: 6939.847 | AB13: 7461.47 | AC13: 7918.009 | AD13: =AE13 | AE13: 8210.159 | AF13: 8015.837 | AG13: 8374.64 | AH13: 8557.396 | AI13: =AJ13 | AJ13: 8841.561 | AK13: 8416.736 | AL13: 8282.265 | AM13: 8082.44 | AN13: =AO13 | AO13: 8352.731 | AP13: 8064.206 | AQ13: 8315.449 | AR13: 8004.624 | AS13: =AT13 | AT13: 7819.563 | AU13: 8241.022 | AV13: 8548.463 | AW13: 8991.781 | AX13: =AY13 | AY13: 9238.315 | AZ13: 9089.537 | BA13: 9286.478 | BB13: 8961.147 | BC13: =BD13 | BD13: 9425.551 | BE13: 9536.111 | BF13: 9131.131 | BG13: 8470.469 | BH13: =BI13 | BI13: 8784.302 | BJ13: 9378.186 | BK13: 8592.237 | BL13: 8062.166 | BM13: =BN13 | BN13: 8113.91 | BO13: 7552.902 | BP13: 7179.966 | BQ13: 6981.849 | BR13: =BS13 | BS13: 8376.16 | BT13: 8611.852
A14: Content obligations due after three years and through five years, mm | D14: 236.6 | E14: 650.48 | F14: 540.346 | G14: 535.617 | H14: 830.536 | I14: 803.942 | J14: =K14 | K14: 929.645 | L14: 630.518 | M14: 653.408 | N14: 1071.238 | O14: =P14 | P14: 1164.308 | Q14: 1071.291 | R14: 961.784 | S14: 908.111 | T14: =U14 | U14: 891.864 | V14: 1256.041 | W14: 1220.827 | X14: 1489.933 | Y14: =Z14 | Z14: 1386.934 | AA14: 1562.941 | AB14: 1488.76 | AC14: 1918.123 | AD14: =AE14 | AE14: 1894.001 | AF14: 1849.029 | AG14: 1718.511 | AH14: 1590.976 | AI14: =AJ14 | AJ14: 1684.582 | AK14: 1480.67 | AL14: 1341.448 | AM14: 1586.731 | AN14: =AO14 | AO14: 2041.34 | AP14: 1974.855 | AQ14: 1941.731 | AR14: 1956.565 | AS14: =AT14 | AT14: 1973.091 | AU14: 2259.821 | AV14: 2688.616 | AW14: 2860.871 | AX14: =AY14 | AY14: 3238.977 | AZ14: 3072.216 | BA14: 2904.226 | BB14: 2639.608 | BC14: =BD14 | BD14: 2124.307 | BE14: 1964.812 | BF14: 1662.733 | BG14: 1449.676 | BH14: =BI14 | BI14: 2016.358 | BJ14: 2820.168 | BK14: 2528.545 | BL14: 2277.918 | BM14: =BN14 | BN14: 2809.834 | BO14: 2520.879 | BP14: 2273.025 | BQ14: 2110.536 | BR14: =BS14 | BS14: 3041.538 | BT14: 2825.509
A15: Content obligations due after five years, mm | D15: 0 | E15: 74.696 | F15: 78.483 | G15: 63.713 | H15: 140.177 | I15: 105.611 | J15: =K15 | K15: 83.284 | L15: 43.803 | M15: 37.895 | N15: 35.239 | O15: =P15 | P15: 44.053 | Q15: 57.229 | R15: 49.307 | S15: 46.768 | T15: =U15 | U15: 58.048 | V15: 155.872 | W15: 122.371 | X15: 197.9 | Y15: =Z15 | Z15: 160.606 | AA15: 187.592 | AB15: 156.64 | AC15: 171.438 | AD15: =AE15 | AE15: 143.535 | AF15: 123.272 | AG15: 93.001 | AH15: 90.23 | AI15: =AJ15 | AJ15: 148.334 | AK15: 136.892 | AL15: 137.481 | AM15: 478.76 | AN15: =AO15 | AO15: 618.644 | AP15: 516.792 | AQ15: 460.368 | AR15: 442.769 | AS15: =AT15 | AT15: 445.308 | AU15: 767.98 | AV15: 740.476 | AW15: 595.483 | AX15: =AY15 | AY15: 664.762 | AZ15: 341.828 | BA15: 370.293 | BB15: 304.664 | BC15: =BD15 | BD15: 243.606 | BE15: 253.283 | BF15: 288.054 | BG15: 217.823 | BH15: =BI15 | BI15: 583.766 | BJ15: 930.598 | BK15: 731.986 | BL15: 547.375 | BM15: =BN15 | BN15: 900.491 | BO15: 739.567 | BP15: 671.32 | BQ15: 580.827 | BR15: =BS15 | BS15: 1093.5 | BT15: 922.848
A16: Total Content Obligations, mm | D16: =SUM(D12:D15) | E16: =SUM(E12:E15) | F16: =SUM(F12:F15) | G16: =SUM(G12:G15) | H16: =SUM(H12:H15) | I16: =SUM(I12:I15) | J16: =SUM(J12:J15) | K16: =SUM(K12:K15) | ... BT16: =SUM(BT12:BT15)
A18: Key Metrics - Headcount (FS)
A19: United States & Canada employees, # of employees | AT19: 7600 | AY19: 8600 | BD19: 9000 | BI19: 9000 | BN19: 9600 | BS19: 10900
A20: EMEA employees, # of employees | AT20: 1000 | AY20: 1400 | BD20: 2000 | BI20: 2000 | BN20: 2200 | BS20: 2500
A21: Latin America employees, # of employees | AT21: 200 | AY21: 400 | BD21: 400 | BI21: 500 | BN21: 600 | BS21: 700
A22: Asia Pacific employees, # of employees | AT22: 600 | AY22: 900 | BD22: 1400 | BI22: 1500 | BN22: 1600 | BS22: 1900
A23: Total Full-time Employees, # of employees | C23: 1883 | D23: 2180 | E23: 2348 | F23: 2045 | K23: 2022 | P23: 2189 | U23: 3500 | Z23: 4500 | AE23: 5400 | AJ23: 7100 | AO23: 8600 | AT23: =SUM(AT19:AT22) | AY23: =SUM(AY19:AY22) | BD23: =SUM(BD19:BD22) | BI23: =SUM(BI19:BI22) | BN23: =SUM(BN19:BN22) | BS23: =SUM(BS19:BS22)
A25: Segmented Results - Revenue Breakdown Based On Old Segmentation (FS) (Historical)
A26: Domestic Streaming Revenue, mm | F26: 2184.868 | G26: 638.649 | H26: 671.089 | I26: 701.083 | J26: =K26-I26-H26-G26 | K26: 2751.375 | L26: 798.617 | M26: 838.225 | N26: 877.15 | O26: =P26-N26-M26-L26 | P26: 3431.434 | Q26: 984.532 | R26: 1025.913 | S26: 1063.961 | T26: =U26-Q26-R26-S26 | U26: 4180.339 | V26: 1161.241 | W26: 1208.271 | X26: 1304.333 | Y26: =Z26-V26-W26-X26 | Z26: 5077.307 | AA26: 1470.042 | AB26: 1505.499 | AC26: 1547.21 | AD26: =AE26-AA26-AB26-AC26 | AE26: 6153.025 | AF26: 1820.019 | AG26: 1893.222 | AH26: 1937.314 | AI26: =AJ26-AF26-AG26-AH26 | AJ26: 7646.647 | AK26: 2073.555 | AL26: 2299.189 | AM26: 2412.598 | AN26: =AO26-AK26-AL26-AM26 | AO26: 9243.005
A27: Y/Y Domestic streaming revenue growth, % | K27: ='Supplemental Data'!K26/'Supplemental Data'!F26-1 | L27: ='Supplemental Data'!L26/'Supplemental Data'!G26-1 | M27: ='Supplemental Data'!M26/'Supplemental Data'!H26-1 | N27: ='Supplemental Data'!N26/'Supplemental Data'!I26-1 | O27: ='Supplemental Data'!O26/'Supplemental Data'!J26-1 | P27: ='Supplemental Data'!P26/'Supplemental Data'!K26-1 | Q27: ='Supplemental Data'!Q26/'Supplemental Data'!L26-1 | R27: ='Supplemental Data'!R26/'Supplemental Data'!M26-1 | ... AO27: ='Supplemental Data'!AO26/'Supplemental Data'!AJ26-1
A28: International Streaming Revenue, mm | F28: 287.542 | G28: 142.019 | H28: 165.902 | I28: 183.051 | J28: =K28-I28-H28-G28 | K28: 712.39 | L28: 267.118 | M28: 307.461 | N28: 345.685 | O28: =P28-N28-M28-L28 | P28: 1308.061 | Q28: 415.397 | R28: 454.763 | S28: 516.87 | T28: =U28-Q28-R28-S28 | U28: 1953.435 | V28: 651.748 | W28: 758.201 | X28: 853.48 | Y28: =Z28-V28-W28-X28 | Z28: 3211.095 | AA28: 1046.199 | AB28: 1165.228 | AC28: 1327.435 | AD28: =AE28-AA28-AB28-AC28 | AE28: 5089.191 | AF28: 1782.086 | AG28: 1921.144 | AH28: 1973.283 | AI28: =AJ28-AF28-AG28-AH28 | AJ28: 7782.105 | AK28: 2366.749 | AL28: 2547.727 | AM28: 2760.43 | AN28: =AO28-AK28-AL28-AM28 | AO28: 10616.225
A29: Y/Y International streaming revenue growth, % | K29: ='Supplemental Data'!K28/'Supplemental Data'!F28-1 | L29: ='Supplemental Data'!L28/'Supplemental Data'!G28-1 | M29: ='Supplemental Data'!M28/'Supplemental Data'!H28-1 | N29: ='Supplemental Data'!N28/'Supplemental Data'!I28-1 | O29: ='Supplemental Data'!O28/'Supplemental Data'!J28-1 | P29: ='Supplemental Data'!P28/'Supplemental Data'!K28-1 | Q29: ='Supplemental Data'!Q28/'Supplemental Data'!L28-1 | R29: ='Supplemental Data'!R28/'Supplemental Data'!M28-1 | ... AO29: ='Supplemental Data'!AO28/'Supplemental Data'!AJ28-1
A30: Domestic DVD Revenue, mm | F30: 1136.872 | G30: 243.293 | H30: 232.381 | I30: 221.865 | J30: =K30-I30-H30-G30 | K30: 910.797 | L30: 204.354 | M30: 194.721 | N30: 186.597 | O30: =P30-N30-M30-L30 | P30: 765.161 | Q30: 173.2 | R30: 164.018 | S30: 157.524 | T30: =U30-Q30-R30-S30 | U30: 645.737 | V30: 144.747 | W30: 138.732 | X30: 132.375 | Y30: =Z30-V30-W30-X30 | Z30: 542.267 | AA30: 120.394 | AB30: 114.737 | AC30: 110.214 | AD30: =AE30-AA30-AB30-AC30 | AE30: 450.497 | AF30: 98.751 | AG30: 92.904 | AH30: 88.777 | AI30: =AJ30-AF30-AG30-AH30 | AJ30: 365.589 | AK30: 80.688 | AL30: 76.2 | AM30: 71.877 | AN30: =AO30-AK30-AL30-AM30 | AO30: 297.217
A31: Y/Y Domestic DVD Revenue Growth, % | K31: ='Supplemental Data'!K30/'Supplemental Data'!F30-1 | L31: ='Supplemental Data'!L30/'Supplemental Data'!G30-1 | M31: ='Supplemental Data'!M30/'Supplemental Data'!H30-1 | N31: ='Supplemental Data'!N30/'Supplemental Data'!I30-1 | O31: ='Supplemental Data'!O30/'Supplemental Data'!J30-1 | P31: ='Supplemental Data'!P30/'Supplemental Data'!K30-1 | Q31: ='Supplemental Data'!Q30/'Supplemental Data'!L30-1 | R31: ='Supplemental Data'!R30/'Supplemental Data'!M30-1 | ... AO31: ='Supplemental Data'!AO30/'Supplemental Data'!AJ30-1
A32: Total Revenue, mm | F32: =F26+F28+F30 | G32: =G26+G28+G30 | H32: =H26+H28+H30 | I32: =I26+I28+I30 | J32: =J26+J28+J30 | K32: =K26+K28+K30 | L32: =L26+L28+L30 | M32: =M26+M28+M30 | ... AO32: =AO26+AO28+AO30
A34: Segmented Results - Costs Breakdown Based On Old Segmentation (FS) (Historical)
A35: Domestic Streaming COGS, mm | F35: 1570.6 | G35: 440.334 | H35: 452.598 | I35: 473.965 | J35: =K35-I35-H35-G35 | K35: 1863.376 | L35: 517.094 | M35: 546.223 | N35: 565.251 | O35: =P35-N35-M35-L35 | P35: 2201.761 | Q35: 582.529 | R35: 612.691 | S35: 644.914 | T35: =U35-Q35-R35-S35 | U35: 2487.193 | V35: 687.756 | W35: 729.399 | X35: 746.22 | Y35: 788.598 | Z35: 2951.973 | AA35: 783.954 | AB35: 868.53 | AC35: 902.275 | AD35: 916.1 | AE35: 3470.859 | AF35: 936.48 | AG35: 969.995 | AH35: 1038.473 | AI35: 1093.446 | AJ35: =SUM(AF35,AG35,AH35,AI35) | AK35: 1139.535 | AL35: 1196.42 | AM35: 1210.105 | AN35: 1321.283 | AO35: =SUM(AK35,AL35,AM35,AN35)
A36: International Streaming COGS, mm | F36: 483.295 | G36: 166.892 | H36: 184.4 | I36: 209.811 | J36: =K36-I36-H36-G36 | K36: 782.304 | L36: 245.267 | M36: 266.697 | N36: 291.942 | O36: =P36-N36-M36-L36 | P36: 1154.117 | Q36: 375.278 | R36: 422.966 | S36: 451.251 | T36: =U36-Q36-R36-S36 | U36: 1780.375 | V36: 657.73 | W36: 728.168 | X36: 783.877 | Y36: 872.972 | Z36: 3042.747 | AA36: 896.558 | AB36: 1070.432 | AC36: 1136.877 | AD36: 1255.749 | AE36: 4359.616 | AF36: 1321.706 | AG36: 1392.512 | AH36: 1455.554 | AI36: 1606.275 | AJ36: =SUM(AF36,AG36,AH36,AI36) | AK36: 1697.121 | AL36: 1778.89 | AM36: 1860.021 | AN36: 2113.631 | AO36: =SUM(AK36,AL36,AM36,AN36)
A37: Domestic DVD COGS, mm | F37: 598.163 | G37: 129.726 | H37: 123.676 | I37: 115.124 | J37: =K37-I37-H37-G37 | K37: 471.523 | L37: 106.825 | M37: 101.928 | N37: 97.201 | O37: =P37-N37-M37-L37 | P37: 396.882 | Q37: 88.594 | R37: 86.095 | S37: 77.793 | T37: =U37-Q37-R37-S37 | U37: 323.908 | V37: 73.095 | W37: 67.83 | X37: 63.671 | Y37: =Z37-V37-W37-X37 | Z37: 262.742 | AA37: 60.219 | AB37: 52.734 | AC37: 47.087 | AD37: =AE37-AA37-AB37-AC37 | AE37: 202.525 | AF37: 42.393 | AG37: 39.924 | AH37: 37.101 | AI37: 33.679 | AJ37: 153.097 | AK37: 33.958 | AL37: 30.347 | AM37: 27.793 | AN37: 31.109 | AO37: =SUM(AK37,AL37,AM37,AN37)
A38: Total COGS, mm | F38: =SUM(F35:F37) | G38: =SUM(G35:G37) | H38: =SUM(H35:H37) | I38: =SUM(I35:I37) | J38: =SUM(J35:J37) | K38: =SUM(K35:K37) | L38: =SUM(L35:L37) | M38: =SUM(M35:M37) | ... AO38: =SUM(AO35:AO37)
A40: Domestic Streaming Marketing Expense, mm | F40: 245.259 | G40: 66.965 | H40: 67.177 | I40: 60.637 | J40: =K40-I40-H40-G40 | K40: 265.232 | L40: 80.258 | M40: 64.727 | N40: 61.045 | O40: =P40-N40-M40-L40 | P40: 293.453 | Q40: 89.551 | R40: 73.427 | S40: 74.835 | T40: =U40-Q40-R40-S40 | U40: 317.646 | V40: 88.574 | W40: 93.751 | X40: 116.687 | Y40: 113.916 | Z40: 412.928 | AA40: 126.253 | AB40: 124.903 | AC40: 141.533 | AD40: 211.057 | AE40: 603.746 | AF40: 250.719 | AG40: 251.298 | AH40: 210.595 | AI40: 312.739 | AJ40: 1025.351 | AK40: 221.046 | AL40: 250.606 | AM40: 211.793 | AN40: 379.597 | AO40: =SUM(AK40,AL40,AM40,AN40)
A41: International Streaming Marketing Expense, mm | F41: 193.39 | G41: 52.047 | H41: 47.335 | I41: 47.537 | J41: =K41-I41-H41-G41 | K41: 204.418 | L41: 56.84 | M41: 56.036 | N41: 84.609 | O41: =P41-N41-M41-L41 | P41: 313.733 | Q41: 105.126 | R41: 123.713 | S41: 133.267 | T41: =U41-Q41-R41-S41 | U41: 506.446 | V41: 142.891 | W41: 146.839 | X41: 194.33 | Y41: 200.531 | Z41: 684.591 | AA41: 179.895 | AB41: 186.257 | AC41: 210.913 | AD41: 255.47 | AE41: 832.535 | AF41: 286.058 | AG41: 340.709 | AH41: 299.735 | AI41: 417.616 | AJ41: 1344.118 | AK41: 395.532 | AL41: 352.544 | AM41: 342.004 | AN41: 499.34 | AO41: =SUM(AK41,AL41,AM41,AN41)
A42: Domestic DVD Marketing Expense, mm | F42: 0.559 | G42: 0.074 | H42: 0.099 | I42: 0.054 | J42: =K42-I42-H42-G42 | K42: 0.292 | L42: 0 | M42: 0 | N42: 0 | O42: =P42-N42-M42-L42 | P42: 0 | Q42: 0 | R42: 0 | S42: 0 | T42: =U42-Q42-R42-S42 | U42: 0 | V42: 0 | W42: 0 | X42: 0 | Y42: =Z42-V42-W42-X42 | Z42: 0 | AA42: 0 | AB42: 0 | AC42: 0 | AD42: =AE42-AA42-AB42-AC42 | AE42: 0 | AF42: 0 | AG42: 0 | AH42: 0 | AI42: 0 | AJ42: 0 | AK42: 0 | AL42: 0 | AM42: 0 | AN42: 0
A43: Total Marketing Expense, mm | F43: =SUM(F40:F42) | G43: =SUM(G40:G42) | H43: =SUM(H40:H42) | I43: =SUM(I40:I42) | J43: =SUM(J40:J42) | K43: =SUM(K40:K42) | L43: =SUM(L40:L42) | M43: =SUM(M40:M42) | ... AO43: =SUM(AO40:AO42)
A45: Domestic Streaming Net Contribution, mm | F45: ='Supplemental Data'!F26-F35-F40 | G45: ='Supplemental Data'!G26-G35-G40 | H45: ='Supplemental Data'!H26-H35-H40 | I45: ='Supplemental Data'!I26-I35-I40 | J45: ='Supplemental Data'!J26-J35-J40 | K45: ='Supplemental Data'!K26-K35-K40 | L45: ='Supplemental Data'!L26-L35-L40 | M45: ='Supplemental Data'!M26-M35-M40 | ... AO45: ='Supplemental Data'!AO26-AO35-AO40
A46: International Streaming Net Contribution, mm | F46: ='Supplemental Data'!F28-F36-F41 | G46: ='Supplemental Data'!G28-G36-G41 | H46: ='Supplemental Data'!H28-H36-H41 | I46: ='Supplemental Data'!I28-I36-I41 | J46: ='Supplemental Data'!J28-J36-J41 | K46: ='Supplemental Data'!K28-K36-K41 | L46: ='Supplemental Data'!L28-L36-L41 | M46: ='Supplemental Data'!M28-M36-M41 | ... AO46: ='Supplemental Data'!AO28-AO36-AO41
...

Sheet Guidance
B1: =MO.CompanyName
B2: Most Recent Period: | F2: =MO.MRFP
I4: Guidance | M4: Model | P4: Difference vs. Mid | S4: Update Log
B5: Type | D5: Item | E5: Item Name | F5: Fiscal Period | G5: Base Period | I5: Low | J5: High | K5: Mid | M5: Type | N5: Output | P5: Absolute | Q5: Relative | S5: Date | T5: Link
A6: 427 | B6: =IF(INDEX(MO_SNA_IsHistoricalPeriod,,MATCH(F6,MO_Common_ColumnHeader,0)),"Historical","Forward") | D6: =INDEX(INDIRECT(E6),0,COLUMN(MO_Common_Column_A)) | E6: MO_RIS_REV | F6: FY2026 | I6: 50700 | J6: 51700 | K6: =AVERAGE(I6:J6) | M6: =IF(INDEX(MO_SNA_IsHistoricalPeriod,,MATCH(F6,MO_Common_ColumnHeader,0)),"Actual","Estimate") | N6: =IFERROR(INDEX(INDIRECT(E6),0,MATCH(F6,MO_Common_ColumnHeader,0)),"N/A") | P6: =IF(ISNUMBER(N6),N6-K6,"N/A") | Q6: =IFERROR(IF(ISNUMBER(N6),(N6-K6)/ABS(K6),"N/A"),"N/A") | S6: 46128 | T6: Letter to Shareholders
A7: 426 | B7: =IF(INDEX(MO_SNA_IsHistoricalPeriod,,MATCH(F7,MO_Common_ColumnHeader,0)),"Historical","Forward") | D7: =INDEX(INDIRECT(E7),0,COLUMN(MO_Common_Column_A)) | E7: MO_GA_TotalRevenue | F7: FY2026 | I7: 0.12 | J7: 0.14 | K7: =AVERAGE(I7:J7) | M7: =IF(INDEX(MO_SNA_IsHistoricalPeriod,,MATCH(F7,MO_Common_ColumnHeader,0)),"Actual","Estimate") | N7: =IFERROR(INDEX(INDIRECT(E7),0,MATCH(F7,MO_Common_ColumnHeader,0)),"N/A") | P7: =IF(ISNUMBER(N7),N7-K7,"N/A") | Q7: =IFERROR(IF(ISNUMBER(N7),(N7-K7)/ABS(K7),"N/A"),"N/A") | S7: 46128 | T7: Letter to Shareholders
A8: 425 | B8: =IF(INDEX(MO_SNA_IsHistoricalPeriod,,MATCH(F8,MO_Common_ColumnHeader,0)),"Historical","Forward") | D8: =INDEX(INDIRECT(E8),0,COLUMN(MO_Common_Column_A)) | E8: MO_GA_REV_ConstantCurrency | F8: FY2026 | I8: 0.11 | J8: 0.13 | K8: =AVERAGE(I8:J8) | M8: =IF(INDEX(MO_SNA_IsHistoricalPeriod,,MATCH(F8,MO_Common_ColumnHeader,0)),"Actual","Estimate") | N8: =IF(B8="Historical",IFERROR(INDEX(INDIRECT(E8),0,MATCH(F8,MO_Common_ColumnHeader,0)),"N/A"),"N/A") | P8: =IF(ISNUMBER(N8),N8-K8,"N/A") | Q8: =IFERROR(IF(ISNUMBER(N8),(N8-K8)/ABS(K8),"N/A"),"N/A") | S8: 46128 | T8: Letter to Shareholders
A9: 424 | B9: =IF(INDEX(MO_SNA_IsHistoricalPeriod,,MATCH(F9,MO_Common_ColumnHeader,0)),"Historical","Forward") | D9: Operating Margin | E9: MO_MA_EBIT | F9: FY2026 | I9: 0.315 | J9: 0.315 | K9: =AVERAGE(I9:J9) | M9: =IF(INDEX(MO_SNA_IsHistoricalPeriod,,MATCH(F9,MO_Common_ColumnHeader,0)),"Actual","Estimate") | N9: =IFERROR(INDEX(INDIRECT(E9),0,MATCH(F9,MO_Common_ColumnHeader,0)),"N/A") | P9: =IF(ISNUMBER(N9),N9-K9,"N/A") | Q9: =IFERROR(IF(ISNUMBER(N9),(N9-K9)/ABS(K9),"N/A"),"N/A") | S9: 46128 | T9: Letter to Shareholders
A10: 423
A11: 422 | B11: =IF(INDEX(MO_SNA_IsHistoricalPeriod,,MATCH(F11,MO_Common_ColumnHeader,0)),"Historical","Forward") | D11: =INDEX(INDIRECT(E11),0,COLUMN(MO_Common_Column_A)) | E11: MO_RIS_REV | F11: Q2-2026 | I11: 12574 | J11: 12574 | K11: =AVERAGE(I11:J11) | M11: =IF(INDEX(MO_SNA_IsHistoricalPeriod,,MATCH(F11,MO_Common_ColumnHeader,0)),"Actual","Estimate") | N11: =IFERROR(INDEX(INDIRECT(E11),0,MATCH(F11,MO_Common_ColumnHeader,0)),"N/A") | P11: =IF(ISNUMBER(N11),N11-K11,"N/A") | Q11: =IFERROR(IF(ISNUMBER(N11),(N11-K11)/ABS(K11),"N/A"),"N/A") | S11: 46128 | T11: Letter to Shareholders
A12: 421 | B12: =IF(INDEX(MO_SNA_IsHistoricalPeriod,,MATCH(F12,MO_Common_ColumnHeader,0)),"Historical","Forward") | D12: =INDEX(INDIRECT(E12),0,COLUMN(MO_Common_Column_A)) | E12: MO_GA_TotalRevenue | F12: Q2-2026 | I12: 0.135 | J12: 0.135 | K12: =AVERAGE(I12:J12) | M12: =IF(INDEX(MO_SNA_IsHistoricalPeriod,,MATCH(F12,MO_Common_ColumnHeader,0)),"Actual","Estimate") | N12: =IFERROR(INDEX(INDIRECT(E12),0,MATCH(F12,MO_Common_ColumnHeader,0)),"N/A") | P12: =IF(ISNUMBER(N12),N12-K12,"N/A") | Q12: =IFERROR(IF(ISNUMBER(N12),(N12-K12)/ABS(K12),"N/A"),"N/A") | S12: 46128 | T12: Letter to Shareholders
A13: 420 | B13: =IF(INDEX(MO_SNA_IsHistoricalPeriod,,MATCH(F13,MO_Common_ColumnHeader,0)),"Historical","Forward") | D13: =INDEX(INDIRECT(E13),0,COLUMN(MO_Common_Column_A)) | E13: MO_GA_REV_ConstantCurrency | F13: Q2-2026 | I13: 0.12 | J13: 0.12 | K13: =AVERAGE(I13:J13) | M13: =IF(INDEX(MO_SNA_IsHistoricalPeriod,,MATCH(F13,MO_Common_ColumnHeader,0)),"Actual","Estimate") | N13: =IF(B13="Historical",IFERROR(INDEX(INDIRECT(E13),0,MATCH(F13,MO_Common_ColumnHeader,0)),"N/A"),"N/A") | P13: =IF(ISNUMBER(N13),N13-K13,"N/A") | Q13: =IFERROR(IF(ISNUMBER(N13),(N13-K13)/ABS(K13),"N/A"),"N/A") | S13: 46128 | T13: Letter to Shareholders
A14: 419 | B14: =IF(INDEX(MO_SNA_IsHistoricalPeriod,,MATCH(F14,MO_Common_ColumnHeader,0)),"Historical","Forward") | D14: =INDEX(INDIRECT(E14),0,COLUMN(MO_Common_Column_A)) | E14: MO_RIS_EBIT | F14: Q2-2026 | I14: 4105 | J14: 4105 | K14: =AVERAGE(I14:J14) | M14: =IF(INDEX(MO_SNA_IsHistoricalPeriod,,MATCH(F14,MO_Common_ColumnHeader,0)),"Actual","Estimate") | N14: =IFERROR(INDEX(INDIRECT(E14),0,MATCH(F14,MO_Common_ColumnHeader,0)),"N/A") | P14: =IF(ISNUMBER(N14),N14-K14,"N/A") | Q14: =IFERROR(IF(ISNUMBER(N14),(N14-K14)/ABS(K14),"N/A"),"N/A") | S14: 46128 | T14: Letter to Shareholders
A15: 418 | B15: =IF(INDEX(MO_SNA_IsHistoricalPeriod,,MATCH(F15,MO_Common_ColumnHeader,0)),"Historical","Forward") | D15: Operating Margin | E15: MO_MA_EBIT | F15: Q2-2026 | I15: 0.326 | J15: 0.326 | K15: =AVERAGE(I15:J15) | M15: =IF(INDEX(MO_SNA_IsHistoricalPeriod,,MATCH(F15,MO_Common_ColumnHeader,0)),"Actual","Estimate") | N15: =IFERROR(INDEX(INDIRECT(E15),0,MATCH(F15,MO_Common_ColumnHeader,0)),"N/A") | P15: =IF(ISNUMBER(N15),N15-K15,"N/A") | Q15: =IFERROR(IF(ISNUMBER(N15),(N15-K15)/ABS(K15),"N/A"),"N/A") | S15: 46128 | T15: Letter to Shareholders
A16: 417 | B16: =IF(INDEX(MO_SNA_IsHistoricalPeriod,,MATCH(F16,MO_Common_ColumnHeader,0)),"Historical","Forward") | D16: =INDEX(INDIRECT(E16),0,COLUMN(MO_Common_Column_A)) | E16: MO_RIS_NI_GAAP_Basic | F16: Q2-2026 | I16: 3327 | J16: 3327 | K16: =AVERAGE(I16:J16) | M16: =IF(INDEX(MO_SNA_IsHistoricalPeriod,,MATCH(F16,MO_Common_ColumnHeader,0)),"Actual","Estimate") | N16: =IFERROR(INDEX(INDIRECT(E16),0,MATCH(F16,MO_Common_ColumnHeader,0)),"N/A") | P16: =IF(ISNUMBER(N16),N16-K16,"N/A") | Q16: =IFERROR(IF(ISNUMBER(N16),(N16-K16)/ABS(K16),"N/A"),"N/A") | S16: 46128 | T16: Letter to Shareholders
