Workbook
Name CIRCULARITY: 'Model Summary'!$D$11
Name CRT: 'Model Summary'!$D$6
Name GrowthCase: 'Model Summary'!$D$7
Name Mergers: 'Model Summary'!$D$4
Name MultipleExpansion: 'Model Summary'!$D$8
Name SOFR: 'Model Summary'!$D$9
Name XSell: 'Model Summary'!$D$5

Sheet Model Summary
C3: Toggles:
C4: M&A | D4: No
C5: Cross-Sell | D5: Base
C6: Cost Reduction | D6: Base
C7: Growth Case | D7: Base
C8: Multiple Expansion | D8: Yes
C9: SOFR Curve | D9: Forward Curve
C11: CIRC | D11: 1
C12: INPUT: EBITDA and Annual Debt Paydown | M12: INPUT: Purchase Price / Capitalization | U12: Returns by Year
E13: Est. Dec | F13: Projected | Q13: PF
E14: 2024 | F14: =E14+1 -> 2025 | G14: =F14+1 -> 2026 | H14: =G14+1 -> 2027 | I14: =H14+1 -> 2028 | J14: =I14+1 -> 2029 | K14: CAGR | P14: pre fee | Q14: w/ fee | V14: Exit Year | W14: IRR | X14: MOIC
A15: A | C15: Organic Revenue | E15: ='Operating Build'!Q23 -> 1288.3681 | F15: =E15*(1+F16) -> 1349.2524 | G15: =F15*(1+G16) -> 1420.6578 | H15: =G15*(1+H16) -> 1512.1049 | I15: =H15*(1+I16) -> 1621.2493 | J15: =I15*(1+J16) -> 1742.3495 | K15: =(J15/E15)^(1/5)-1 -> 0.062231217 | M15: TEV / Price Paid | P15: =H100 -> 715 | Q15: =H102 -> 715 | V15: 1 | W15: =INDEX($F$216:$J$216, MATCH($V15, $F$215:$J$215, 0)) -> 0.56661787 | X15: =INDEX($F$214:$J$214, MATCH($V15, $F$215:$J$215, 0)) -> 1.5666179
C16: % growth | F16: =F52 -> 0.047256875 | G16: =G52 -> 0.052922166 | H16: =H52 -> 0.064369549 | I16: =I52 -> 0.072180494 | J16: =J52 -> 0.074695598 | M16: FY EBITDA | N16: =E29 -> 81.607343 | P16: =P$15/N16 -> 8.7614665 | Q16: =Q$15/N16 -> 8.7614665 | S16: H | V16: 2 | W16: =INDEX($F$216:$J$216, MATCH($V16, $F$215:$J$215, 0)) -> 0.44556915 | X16: =INDEX($F$214:$J$214, MATCH($V16, $F$215:$J$215, 0)) -> 2.0896702
V17: 3 | W17: =INDEX($F$216:$J$216, MATCH($V17, $F$215:$J$215, 0)) -> 0.35886934 | X17: =INDEX($F$214:$J$214, MATCH($V17, $F$215:$J$215, 0)) -> 2.5091874
A18: B | C18: Gross Profit | E18: ='Operating Build'!Q45 -> 256.991 | F18: =F19*F15 -> 270.18162 | G18: =G19*G15 -> 284.70873 | H18: =H19*H15 -> 302.8315 | I18: =I19*I15 -> 324.2819 | J18: =J19*J15 -> 348.06719 | K18: =(J18/E18)^(1/5)-1 -> 0.06254917 | M18: Revolver / (Cash) | Q18: =SUM(O$17:O18)/N16 -> 0 | V18: 4 | W18: =INDEX($F$216:$J$216, MATCH($V18, $F$215:$J$215, 0)) -> 0.31571157 | X18: =INDEX($F$214:$J$214, MATCH($V18, $F$215:$J$215, 0)) -> 2.9966966
C19: % margin | E19: =E18/E15 -> 0.19947016 | F19: =F53 -> 0.20024543 | G19: =G53 -> 0.20040628 | H19: =H53 -> 0.2002715 | I19: =I53 -> 0.20001976 | J19: =J53 -> 0.19976887 | M19: 1st Lien / Senior Debt | O19: =G105 -> 118.6 | Q19: =SUM(O$17:O19)/N16 -> 1.4533006 | V19: 5 | W19: =INDEX($F$216:$J$216, MATCH($V19, $F$215:$J$215, 0)) -> 0.28839736 | X19: =INDEX($F$214:$J$214, MATCH($V19, $F$215:$J$215, 0)) -> 3.5501699
M20: 2nd Lien / Sub Debt | O20: =G106 -> 200 | Q20: =SUM(O$17:O20)/N16 -> 3.9040604
A21: C | C21: SG&A | E21: =-('Operating Build'!Q49+'Operating Build'!Q52) -> 179.21915 | F21: =F22*F15 -> 175.2079 | G21: =G22*G15 -> 171.3392 | H21: =H22*H15 -> 176.57182 | I21: =I22*I15 -> 183.10207 | J21: =J22*J15 -> 190.09999 | K21: =(J21/E21)^(1/5)-1 -> 0.011857921 | M21: Total Debt | N21: =O21/O26 -> 0.44559441 | O21: =SUM(O17:O20) -> 318.6 | Q21: =Q20 -> 3.9040604
C22: % margin | E22: =E21/E15 -> 0.13910554 | F22: =F54 -> 0.12985554 | G22: =G54 -> 0.12060554 | H22: =H54 -> 0.11677221 | I22: =I54 -> 0.11293887 | J22: =J54 -> 0.10910554 | M22: Rollover Equity | O22: 0 | S22: I
C24: Adjustments | E24: 3.8354945 | F24: 0 | G24: 0 | H24: 0 | I24: 0 | J24: 0 | M24: PE Sponsor | O24: =H108-O22 -> 396.4
C25: Organic EBITDA | E25: =E18-E21+E24 -> 81.607343 | F25: =F18-F21+F24 -> 94.973724 | G25: =G18-G21+G24 -> 113.36954 | H25: =H18-H21+H24 -> 126.25968 | I25: =I18-I21+I24 -> 141.17982 | J25: =J18-J21+J24 -> 157.96721 | K25: =(J25/E25)^(1/5)-1 -> 0.14121518 | M25: Total Equity | N25: =O25/O26 -> 0.55440559 | O25: =O22+O24 -> 396.4 | Q25: =(O25+O21)/N16 -> 8.7614665
C26: % margin | E26: =E25/E15 -> 0.063341634 | F26: =F25/F15 -> 0.070389887 | G26: =G25/G15 -> 0.079800738 | H26: =H25/H15 -> 0.083499289 | I26: =I25/I15 -> 0.087080882 | J26: =J25/J15 -> 0.090663328 | M26: Total Sources | O26: =O25+O21 -> 715 | Q26: =Q25 -> 8.7614665
A28: Acq | C28: Add-on Acq EBITDA | E28: 0 | F28: =F153 -> 0 | G28: =G153 -> 0 | H28: =H153 -> 0 | I28: =I153 -> 0 | J28: =J153 -> 0
C29: Total EBITDA | E29: =E25+E28 -> 81.607343 | F29: =F25+F28 -> 94.973724 | G29: =G25+G28 -> 113.36954 | H29: =H25+H28 -> 126.25968 | I29: =I25+I28 -> 141.17982 | J29: =J25+J28 -> 157.96721 | K29: =(J29/E29)^(1/5)-1 -> 0.14121518
C30: % margin | E30: =E29/E15 -> 0.063341634 | F30: =F29/F15 -> 0.070389887 | G30: =G29/G15 -> 0.079800738 | H30: =H29/H15 -> 0.083499289 | I30: =I29/I15 -> 0.087080882 | J30: =J29/J15 -> 0.090663328 | M30: Downside Return | P30: =J214 -> 3.5501699 | Q30: =J216 -> 0.28839736 | S30: J
O31: Exit Multiple
A32: D | C32: Capex | E32: ='Operating Build'!L112 -> -25.391958 | F32: =F60+F61 -> -22.114506 | G32: =G60+G61 -> -23.284853 | H32: =H60+H61 -> -24.783689 | I32: =I60+I61 -> -26.572588 | J32: =J60+J61 -> -28.557443 | N32: =J216 -> 0.28839736 | O32: =P32-0.5 -> 9.2614665 | P32: =H116 -> 9.7614665 | Q32: =P32+0.5 -> 10.261466
A33: Acq | C33: Add-on Acq Price (if debt) | F33: =-F145 -> 0 | G33: =-G145 -> 0 | H33: =-H145 -> 0 | I33: =-I145 -> 0 | J33: =-J145 -> 0 | N33: =N34*0.9 -> 142.17048 | O33: 0.24752186 | P33: 0.26099854 | Q33: 0.27392258
A34: E | C34: Change in NWC | F34: =F66+F67 -> -6.3843508 | G34: =G66+G67 -> -7.0861113 | H34: =H66+H67 -> -8.1493559 | I34: =I66+I67 -> -9.6407084 | J34: =J66+J67 -> -10.709711 | M34: Exit EBITDA | N34: =J29 -> 157.96721 | O34: 0.27465759 | P34: 0.28839736 | Q34: 0.30157487
A35: F | C35: Interest | F35: =IF(CIRCULARITY=1,-F83,-0.69) -> -30.833899 | G35: =IF(CIRCULARITY=1,-G83,-0.69) -> -25.801878 | H35: =IF(CIRCULARITY=1,-H83,-0.69) -> -22.738482 | I35: =IF(CIRCULARITY=1,-I83,-0.69) -> -21.515024 | J35: =IF(CIRCULARITY=1,-J83,-0.69) -> -21.592168 | N35: =N34*1.1 -> 173.76393 | O35: 0.29966186 | P35: 0.31364619 | Q35: 0.32705921
A36: G | C36: Cash taxes | F36: =-F91 -> -8.456303 | G36: =-G91 -> -13.822785 | H36: =-H91 -> -17.60127 | I36: =-I91 -> -21.299727 | J36: =-J91 -> -25.066828 | K36: cum
C37: Annual Debt Paydown | F37: =SUM(F32:F36)+F29 -> 27.184665 | G37: =SUM(G32:G36)+G29 -> 43.373909 | H37: =SUM(H32:H36)+H29 -> 52.986885 | I37: =SUM(I32:I36)+I29 -> 62.151775 | J37: =SUM(J32:J36)+J29 -> 72.041055 | K37: =SUM(F37:J37) -> 257.73829 | M37: Value Creation: | O37: At Acq. | P37: Exit | Q37: Change
C38: Ending Net Debt | E38: =H107 -> 318.6 | F38: =E38-F37 -> 291.41533 | G38: =F38-G37 -> 248.04143 | H38: =G38-H37 -> 195.05454 | I38: =H38-I37 -> 132.90277 | J38: =I38-J37 -> 60.861711 | K38: =SUM(E38-J38) -> 257.73829 | M38: EBITDA | O38: =E29 -> 81.607343 | P38: =J29 -> 157.96721 | Q38: =(P38-O38)*O39 -> 669.02437
C39: Debt / EBITDA | E39: =E38/E29 -> 3.9040604 | F39: =F38/F29 -> 3.0683785 | G39: =G38/G29 -> 2.1879019 | H39: =H38/H29 -> 1.544868 | I39: =I38/I29 -> 0.94137224 | J39: =J38/J29 -> 0.38528067 | M39: TEV mult | O39: =P16 -> 8.7614665 | P39: =H116 -> 9.7614665 | Q39: =(P39-O39)*P38 -> 157.96721
C40: EBITDA-Capex / Interest | E40: =(E29+E32)/-F35 -> 1.8231682 | F40: =(F29+F32)/-F35 -> 2.3629583 | G40: =(G29+G32)/-G35 -> 3.4914003 | H40: =(H29+H32)/-H35 -> 4.4627426 | I40: =(I29+I32)/-I35 -> 5.3268467 | J40: =(J29+J32)/-J35 -> 5.9933658 | M40: TEV | O40: =O38*O39 -> 715 | P40: =P38*P39 -> 1541.9916 | Q40: =Q38+Q39 -> 826.99158
M41: less: Debt | O41: =O21 -> 318.6 | P41: =J38 -> 60.861711 | Q41: =O41-P41 -> 257.73829
C42: Debt- 1st Lien / (cash) | E42: =E185 -> 118.6 | F42: =F185 -> 93.415335 | G42: =G185 -> 52.041426 | H42: =H185 -> 1.0545413 | I42: =I185 -> -59.097234 | J42: =J185 -> -129.13829 | M42: less: options | P42: =J208 -> 73.842531 | Q42: =-P42 -> -73.842531
C43: Debt - 2nd Lien/Sub | E43: =E191 -> 200 | F43: =F191 -> 198 | G43: =G191 -> 196 | H43: =H191 -> 194 | I43: =I191 -> 192 | J43: =J191 -> 190 | M43: Equity value | O43: =O40-O41-O42 -> 396.4 | P43: =P40-P41-P42 -> 1407.2873 | Q43: =Q40+Q41+Q42 -> 1010.8873
C44: Total Debt (Net) | E44: =E42+E43 -> 318.6 | F44: =F42+F43 -> 291.41533 | G44: =G42+G43 -> 248.04143 | H44: =H42+H43 -> 195.05454 | I44: =I42+I43 -> 132.90277 | J44: =J42+J43 -> 60.861711 | K44: =E44-J44 -> 257.73829 | M44: MOIC | P44: =P43/O43 -> 3.5501699
B49: INPUT: EBITDA and DEBT PAYDOWN
...

Sheet Operating Build
B4: LBO-audit
H6: Q1 | I6: Q2 | J6: Q3 | K6: Q4 | L6: FY | M6: Q1 | N6: Q2 | O6: Q3 | P6: Q4 | Q6: FY | R6: FY | S6: FY | T6: FY | U6: FY | V6: FY
B7: ($ in millions) | D7: 43830 | E7: =EOMONTH(D7,12) -> 44196 | F7: =EOMONTH(E7,12) -> 44561 | G7: =EOMONTH(F7,12) -> 44926 | H7: =EOMONTH(G7,3) -> 45016 | I7: =EOMONTH(H7,3) -> 45107 | J7: =EOMONTH(I7,3) -> 45199 | K7: =EOMONTH(J7,3) -> 45291 | L7: =EOMONTH(G7,12) -> 45291 | M7: 45382 | N7: =EOMONTH(M7,3) -> 45473 | O7: =EOMONTH(N7,3) -> 45565 | P7: =EOMONTH(O7,3) -> 45657 | Q7: =P7 -> 45657 | R7: =EOMONTH(Q7,12) -> 46022 | S7: =EOMONTH(R7,12) -> 46387 | T7: =EOMONTH(S7,12) -> 46752 | U7: =EOMONTH(T7,12) -> 47118 | V7: =EOMONTH(U7,12) -> 47483
A9: x | B9: P&L Summary
B11: Infrastructure | D11: 557.20315 | E11: 519.12937 | F11: 619.67696 | G11: 651.93614 | H11: 140.03735 | I11: 177.34492 | J11: 137.62342 | K11: 200.15326 | L11: 655.15895 | M11: =Q11*$D$74 -> 154.04097 | N11: =Q11*$E$74 -> 158.88755 | O11: =Q11*$F$74 -> 163.82991 | P11: =Q11*$G$74 -> 193.90228 | Q11: =L11*(1+Q12) -> 670.66071 | R11: =Q11*(1+R12) -> 694.82258 | S11: =R11*(1+S12) -> 719.92129 | T11: =S11*(1+T12) -> 745.99523 | U11: =T11*(1+U12) -> 773.08443 | V11: =U11*(1+V12) -> 801.23063
B12: % Growth | D12: -- | E12: =IFERROR(+E11/D11-1,0) -> -0.068330156 | F12: =IFERROR(+F11/E11-1,0) -> 0.19368504 | G12: =IFERROR(+G11/F11-1,0) -> 0.052058055 | L12: =IFERROR(+L11/G11-1,0) -> 0.0049434423 | M12: =M11/H11-1 -> 0.09999913 | N12: =N11/I11-1 -> -0.10407607 | O12: =O11/J11-1 -> 0.19042178 | P12: =P11/K11-1 -> -0.031230977 | Q12: ='Top Customer Data'!I31 -> 0.023661077 | R12: =IF(GrowthCase="Recession",0.5%,'Revenue Build'!J43) -> 0.036026963 | S12: =IF(GrowthCase="Recession",0.5%,'Revenue Build'!K43) -> 0.036122467 | T12: =IF(GrowthCase="Recession",0.5%,'Revenue Build'!L43) -> 0.036217765 | U12: =IF(GrowthCase="Recession",0.5%,'Revenue Build'!M43) -> 0.036312839 | V12: =IF(GrowthCase="Recession",0.5%,'Revenue Build'!N43) -> 0.036407671
B14: Cloud | D14: 81.869709 | E14: 75.624607 | F14: 85.547617 | G14: 89.989896 | H14: 23.256295 | I14: 25.626924 | J14: 26.64538 | K14: 27.020934 | L14: 102.54953 | M14: =Q14*$D$74 -> 26.20416 | N14: =Q14*$E$74 -> 27.028621 | O14: =Q14*$F$74 -> 27.869373 | P14: =Q14*$G$74 -> 32.985032 | Q14: =L14*(1+Q15) -> 114.08719 | R14: =Q14*(1+R15) -> 125.86906 | S14: =R14*(1+S15) -> 137.82897 | T14: =S14*(1+T15) -> 149.77183 | U14: =T14*(1+U15) -> 162.98588 | V14: =U14*(1+V15) -> 177.58612
B15: % Growth | D15: -- | E15: =IFERROR(+E14/D14-1,0) -> -0.076280987 | F15: =IFERROR(+F14/E14-1,0) -> 0.13121404 | G15: =IFERROR(+G14/F14-1,0) -> 0.051927569 | L15: =IFERROR(+L14/G14-1,0) -> 0.13956719 | M15: =M14/H14-1 -> 0.12675557 | N15: =N14/I14-1 -> 0.054696232 | O15: =O14/J14-1 -> 0.045936413 | P15: =P14/K14-1 -> 0.22072137 | Q15: ='Top Customer Data'!I56 -> 0.11250809 | R15: =IF(GrowthCase="Recession",0.5%,'Revenue Build'!J77) -> 0.10327083 | S15: =IF(GrowthCase="Recession",0.5%,'Revenue Build'!K77) -> 0.095018616 | T15: =IF(GrowthCase="Recession",0.5%,'Revenue Build'!L77) -> 0.086649882 | U15: =IF(GrowthCase="Recession",0.5%,'Revenue Build'!M77) -> 0.088227865 | V15: =IF(GrowthCase="Recession",0.5%,'Revenue Build'!N77) -> 0.089579756
B17: Consulting | D17: 152.63324 | E17: 196.02662 | F17: 299.11454 | G17: 339.4398 | H17: 84.723232 | I17: 88.954097 | J17: 85.144657 | K17: 81.836048 | L17: 340.65803 | M17: =Q17*$D$74 -> 80.341593 | N17: =Q17*$E$74 -> 82.869379 | O17: =Q17*$F$74 -> 85.447115 | P17: =Q17*$G$74 -> 101.13165 | Q17: =L17*(1+Q18) -> 349.78974 | R17: =Q17*(1+R18) -> 369.723 | S17: =R17*(1+S18) -> 398.53211 | T17: =S17*(1+T18) -> 445.85529 | U17: =T17*(1+U18) -> 507.97847 | V17: =U17*(1+V18) -> 578.95925
B18: % Growth | D18: -- | E18: =IFERROR(+E17/D17-1,0) -> 0.28429837 | F18: =IFERROR(+F17/E17-1,0) -> 0.52588734 | G18: =IFERROR(+G17/F17-1,0) -> 0.13481544 | L18: =IFERROR(+L17/G17-1,0) -> 0.0035889671 | M18: =M17/H17-1 -> -0.05171709 | N18: =N17/I17-1 -> -0.068402892 | O18: =O17/J17-1 -> 0.0035522844 | P18: =P17/K17-1 -> 0.23578369 | Q18: ='Top Customer Data'!I81 -> 0.026806083 | R18: =IF(GrowthCase="Recession",0.5%,'Revenue Build'!J92) -> 0.056986401 | S18: =IF(GrowthCase="Recession",0.5%,'Revenue Build'!K92) -> 0.077920786 | T18: =IF(GrowthCase="Recession",0.5%,'Revenue Build'!L92) -> 0.11874371 | U18: =IF(GrowthCase="Recession",0.5%,'Revenue Build'!M92) -> 0.13933484 | V18: =IF(GrowthCase="Recession",0.5%,'Revenue Build'!N92) -> 0.13973188
B20: Comms | D20: 100.79152 | E20: 114.68729 | F20: 121.81334 | G20: 133.65576 | H20: 35.557871 | I20: 34.269577 | J20: 36.824528 | K20: 38.681066 | L20: 145.33304 | M20: =Q20*$D$74 -> 35.33262 | N20: =Q20*$E$74 -> 36.44429 | O20: =Q20*$F$74 -> 37.577926 | P20: =Q20*$G$74 -> 44.475672 | Q20: =L20*(1+Q21) -> 153.83051 | R20: =Q20*(1+R21) -> 158.83775 | S20: =R20*(1+S21) -> 164.3754 | T20: =S20*(1+T21) -> 170.48251 | U20: =T20*(1+U21) -> 177.20056 | V20: =U20*(1+V21) -> 184.57352
B21: % Growth | D21: -- | E21: =IFERROR(+E20/D20-1,0) -> 0.1378664 | F21: =IFERROR(+F20/E20-1,0) -> 0.062134672 | G21: =IFERROR(+G20/F20-1,0) -> 0.097217754 | L21: =IFERROR(+L20/G20-1,0) -> 0.087368314 | M21: =M20/H20-1 -> -0.0063347802 | N21: =N20/I20-1 -> 0.063458978 | O21: =O20/J20-1 -> 0.020459143 | P21: =P20/K20-1 -> 0.14980471 | Q21: ='Top Customer Data'!I106 -> 0.058468914 | R21: =IF(GrowthCase="Recession",0.5%,'Revenue Build'!J113) -> 0.032550418 | S21: =IF(GrowthCase="Recession",0.5%,'Revenue Build'!K113) -> 0.034863511 | T21: =IF(GrowthCase="Recession",0.5%,'Revenue Build'!L113) -> 0.037153452 | U21: =IF(GrowthCase="Recession",0.5%,'Revenue Build'!M113) -> 0.039406081 | V21: =IF(GrowthCase="Recession",0.5%,'Revenue Build'!N113) -> 0.041608017
B23: Total Organic Revenue | D23: =SUM(D20,D17,D14,D11) -> 892.49762 | E23: =SUM(E20,E17,E14,E11) -> 905.46788 | F23: =SUM(F20,F17,F14,F11) -> 1126.1525 | G23: =SUM(G20,G17,G14,G11) -> 1215.0216 | H23: =SUM(H20,H17,H14,H11) -> 283.57475 | I23: =SUM(I20,I17,I14,I11) -> 326.19551 | J23: =SUM(J20,J17,J14,J11) -> 286.23798 | K23: =SUM(K20,K17,K14,K11) -> 347.69131 | ... V23: =SUM(V20,V17,V14,V11) -> 1742.3495
B24: % Growth | D24: -- | E24: =+E23/D23-1 -> 0.01453255 | F24: =+F23/E23-1 -> 0.24372436 | G24: =+G23/F23-1 -> 0.078913945 | L24: =+L23/G23-1 -> 0.023602842 | M24: =M23/H23-1 -> 0.043532042 | N24: =N23/I23-1 -> -0.064273327 | O24: =O23/J23-1 -> 0.099519796 | P24: =P23/K23-1 -> 0.07133721 | Q24: =+Q23/L23-1 -> 0.035915901 | R24: =R23/Q23-1 -> 0.047256875 | S24: =S23/R23-1 -> 0.052922166 | T24: =T23/S23-1 -> 0.064369549 | U24: =U23/T23-1 -> 0.072180494 | V24: =V23/U23-1 -> 0.074695598
B26: Acquired Revenue | C26: 1
B28: Total Revenue | D28: =SUM(D20,D17,D14,D11,D26) -> 892.49762 | E28: =SUM(E20,E17,E14,E11,E26) -> 905.46788 | F28: =SUM(F20,F17,F14,F11,F26) -> 1126.1525 | G28: =SUM(G20,G17,G14,G11,G26) -> 1215.0216 | H28: =SUM(H20,H17,H14,H11,H26) -> 283.57475 | I28: =SUM(I20,I17,I14,I11,I26) -> 326.19551 | J28: =SUM(J20,J17,J14,J11,J26) -> 286.23798 | K28: =SUM(K20,K17,K14,K11,K26) -> 347.69131 | ... V28: =SUM(V20,V17,V14,V11,V26) -> 1742.3495
B29: % Growth | D29: -- | E29: =+E28/D28-1 -> 0.01453255 | F29: =+F28/E28-1 -> 0.24372436 | G29: =+G28/F28-1 -> 0.078913945 | L29: =+L28/G28-1 -> 0.023602842 | M29: =M28/H28-1 -> 0.043532042 | N29: =N28/I28-1 -> -0.064273327 | O29: =O28/J28-1 -> 0.099519796 | P29: =P28/K28-1 -> 0.07133721 | Q29: =+Q28/L28-1 -> 0.035915901 | R29: =+R28/Q28-1 -> 0.047256875 | S29: =+S28/R28-1 -> 0.052922166 | T29: =+T28/S28-1 -> 0.064369549 | U29: =+U28/T28-1 -> 0.072180494 | V29: =+V28/U28-1 -> 0.074695598
B31: Memo: Organic COGS | D31: =D23-D45 -> 720.80984 | E31: =E23-E45 -> 726.01931 | F31: =F23-F45 -> 915.37287 | G31: =G23-G45 -> 982.01218 | H31: =H23-H45 -> 228.26864 | I31: =I23-I45 -> 261.7457 | J31: =J23-J45 -> 230.92556 | K31: =K23-K45 -> 280.48725 | ... V31: =V23-V45 -> 1394.2823
B33: =B11&" Gross Profit" -> Infrastructure Gross Profit | D33: 99.677349 | E33: 93.404027 | F33: 108.73486 | G33: 117.02704 | H33: 25.775385 | I33: 30.989439 | J33: 22.664984 | K33: 33.734926 | L33: 113.1648 | M33: =M34*M11 -> 26.819423 | N33: =N34*N11 -> 27.663242 | O33: =O34*O11 -> 28.523735 | P33: =P34*P11 -> 33.759508 | Q33: =Q34*Q11 -> 116.76591 | R33: =R34*R11 -> 121.59395 | S33: =S34*S11 -> 125.98623 | T33: =T34*T11 -> 130.54916 | ... V33: =V34*V11 -> 140.21536
B34: % Margin | D34: =D33/D11 -> 0.1788887 | E34: =E33/E11 -> 0.17992437 | F34: =F33/F11 -> 0.17547023 | G34: =G33/G11 -> 0.1795069 | H34: =H33/H11 -> 0.18406078 | I34: =I33/I11 -> 0.17474106 | J34: =J33/J11 -> 0.16468842 | K34: =K33/K11 -> 0.16854548 | L34: =L33/L11 -> 0.17272878 | M34: =Q34 -> 0.17410578 | N34: =Q34 -> 0.17410578 | O34: =Q34 -> 0.17410578 | P34: =Q34 -> 0.17410578 | Q34: ='Top Customer Data'!W30 -> 0.17410578 | R34: 0.175 | S34: =R34 -> 0.175 | T34: =S34 -> 0.175 | U34: =T34 -> 0.175 | V34: =U34 -> 0.175
B36: =B14&" Gross Profit" -> Cloud Gross Profit | D36: 20.758924 | E36: 21.237845 | F36: 27.480422 | G36: 26.24656 | H36: 6.4647798 | I36: 7.5819124 | J36: 7.0411578 | K36: 7.2790346 | L36: 28.367191 | M36: =M37*M14 -> 7.4495808 | N36: =N37*N14 -> 7.6839668 | O36: =O37*O14 -> 7.9229844 | P36: =P37*P14 -> 9.377315 | Q36: =Q37*Q14 -> 32.433847 | R36: =R37*R14 -> 35.783317 | S36: =S37*S14 -> 39.183399 | T36: =T37*T14 -> 42.578635 | ... V36: =V37*V14 -> 50.485959
B37: % Margin | D37: =D36/D14 -> 0.25356049 | E37: =E36/E14 -> 0.28083247 | F37: =F36/F14 -> 0.32122955 | G37: =G36/G14 -> 0.29166118 | H37: =H36/H14 -> 0.27797978 | I37: =I36/I14 -> 0.29585729 | J37: =J36/J14 -> 0.26425436 | K37: =K36/K14 -> 0.26938501 | L37: =L36/L14 -> 0.27661941 | M37: =Q37 -> 0.28429001 | N37: =Q37 -> 0.28429001 | O37: =Q37 -> 0.28429001 | P37: =Q37 -> 0.28429001 | Q37: ='Top Customer Data'!W55 -> 0.28429001 | R37: =Q37 -> 0.28429001 | S37: =R37 -> 0.28429001 | T37: =S37 -> 0.28429001 | U37: =T37 -> 0.28429001 | V37: =U37 -> 0.28429001
B39: =B17&" Gross Profit" -> Consulting Gross Profit | D39: 24.828103 | E39: 31.566227 | F39: 42.440442 | G39: 52.600549 | H39: 13.343253 | I39: 16.048453 | J39: 14.36389 | K39: 14.182058 | L39: 57.937289 | M39: =M40*M17 -> 14.141173 | N39: =N40*N17 -> 14.586097 | O39: =O40*O17 -> 15.039812 | P39: =P40*P17 -> 17.800496 | Q39: =Q40*Q17 -> 61.567578 | R39: =R40*R17 -> 65.076093 | S39: =S40*S17 -> 70.146873 | T39: =T40*T17 -> 78.476373 | ... V39: =V40*V17 -> 101.90441
B40: % Margin | D40: =D39/D17 -> 0.16266511 | E40: =E39/E17 -> 0.16103031 | F40: =F39/F17 -> 0.14188692 | G40: =G39/G17 -> 0.15496282 | H40: =H39/H17 -> 0.15749225 | I40: =I39/I17 -> 0.18041275 | J40: =J39/J17 -> 0.16869984 | K40: =K39/K17 -> 0.17329842 | L40: =L39/L17 -> 0.17007463 | M40: =Q40 -> 0.1760131 | N40: =Q40 -> 0.1760131 | O40: =Q40 -> 0.1760131 | P40: =Q40 -> 0.1760131 | Q40: ='Top Customer Data'!W80 -> 0.1760131 | R40: =Q40 -> 0.1760131 | S40: =R40 -> 0.1760131 | T40: =S40 -> 0.1760131 | U40: =T40 -> 0.1760131 | V40: =U40 -> 0.1760131
B42: =B20&" Gross Profit" -> Comms Gross Profit | D42: 26.4234 | E42: 33.240477 | F42: 32.12387 | G42: 37.135265 | H42: 9.7226968 | I42: 9.8300064 | J42: 11.242391 | K42: 12.00804 | L42: 42.803597 | M42: =M43*M20 -> 10.6169 | N42: =N43*N20 -> 10.950939 | O42: =O43*O20 -> 11.29158 | P42: =P43*P20 -> 13.364244 | Q42: =Q43*Q20 -> 46.223663 | R42: =R43*R20 -> 47.728263 | S42: =S43*S20 -> 49.392238 | T42: =T43*T20 -> 51.22733 | ... V42: =V43*V20 -> 55.461458
B43: % Margin | D43: =D42/D20 -> 0.26215895 | E43: =E42/E20 -> 0.28983576 | F43: =F42/F20 -> 0.26371388 | G43: =G42/G20 -> 0.2778426 | H43: =H42/H20 -> 0.27343304 | I43: =I42/I20 -> 0.28684353 | J43: =J42/J20 -> 0.30529628 | K43: =K42/K20 -> 0.31043716 | L43: =L42/L20 -> 0.29452075 | M43: =Q43 -> 0.30048437 | N43: =Q43 -> 0.30048437 | O43: =Q43 -> 0.30048437 | P43: =Q43 -> 0.30048437 | Q43: ='Top Customer Data'!W105 -> 0.30048437 | R43: =Q43 -> 0.30048437 | S43: =R43 -> 0.30048437 | T43: =S43 -> 0.30048437 | U43: =T43 -> 0.30048437 | V43: =U43 -> 0.30048437
B45: Total Organic Gross Profit | D45: =SUM(D42,D39,D36,D33) -> 171.68778 | E45: =SUM(E42,E39,E36,E33) -> 179.44858 | F45: =SUM(F42,F39,F36,F33) -> 210.77959 | G45: =SUM(G42,G39,G36,G33) -> 233.00941 | H45: =SUM(H42,H39,H36,H33) -> 55.306114 | I45: =SUM(I42,I39,I36,I33) -> 64.449811 | J45: =SUM(J42,J39,J36,J33) -> 55.312423 | K45: =SUM(K42,K39,K36,K33) -> 67.204059 | ... V45: =SUM(V42,V39,V36,V33) -> 348.06719
B46: % Margin | D46: =+D45/D$23 -> 0.19236777 | E46: =+E45/E$23 -> 0.19818326 | F46: =+F45/F$23 -> 0.1871679 | G46: =+G45/G$23 -> 0.19177388 | H46: =+H45/H$23 -> 0.19503187 | I46: =+I45/I$23 -> 0.19758031 | J46: =+J45/J$23 -> 0.19323928 | K46: =+K45/K$23 -> 0.19328657 | ... V46: =+V45/V$23 -> 0.19976887
B47: Memo: Organic OPEX | D47: =-D49-D52 -> 142.23412 | E47: =-E49-E52 -> 137.28448 | F47: =-F49-F52 -> 144.33604 | G47: =-G49-G52 -> 155.50079 | H47: =H45-H64 -> 41.045456 | I47: =I45-I64 -> 41.290687 | J47: =J45-J64 -> 41.572599 | K47: =K45-K64 -> 40.688888 | L47: =-L49-L52 -> 163.48517 | M47: =-M49-M52-M57 -> 41.16402 | N47: =-N49-N52-N57 -> 42.459163 | O47: =-O49-O52-O57 -> 43.779898 | P47: =-P49-P52-P57 -> 51.816068 | Q47: =-Q49-Q52-Q57 -> 179.21915 | R47: =-R49-R52-R57 -> 175.2079 | S47: =-S49-S52-S57 -> 171.3392 | T47: =-T49-T52-T57 -> 176.57182 | ... V47: =-V49-V52-V57 -> 190.09999
B49: Selling Expense | D49: -102.00389 | E49: -102.91753 | F49: -105.6066 | G49: -109.65123 | H49: -28.312927 | I49: -28.017868 | J49: -27.35567 | K49: -30.650395 | L49: -114.33686 | M49: =-M$23*M50 -> -26.23302 | N49: =-N$23*N50 -> -27.058389 | O49: =-O$23*O50 -> -27.900068 | P49: =-P$23*P50 -> -33.021361 | Q49: =-Q$23*Q50 -> -114.21284 | R49: =-R$23*R50 -> -119.61018 | S49: =-S$23*S50 -> -125.94021 | T49: =-T$23*T50 -> -134.04692 | ... V49: =-V$23*V50 -> -154.45793
B50: % Margin | D50: =-D49/D$23 -> 0.11429038 | E50: =-E49/E$23 -> 0.11366226 | F50: =-F49/F$23 -> 0.093776471 | G50: =-G49/G$23 -> 0.090246322 | H50: =-H49/H$23 -> 0.099842907 | I50: =-I49/I$23 -> 0.085892866 | J50: =-J49/J$23 -> 0.095569672 | K50: =-K49/K$23 -> 0.088154043 | L50: =-L49/L$23 -> 0.091932862 | M50: =Q50 -> 0.088649225 | N50: =Q50 -> 0.088649225 | O50: =Q50 -> 0.088649225 | P50: =Q50 -> 0.088649225 | Q50: 0.088649225 | R50: =Q50 -> 0.088649225 | S50: =R50 -> 0.088649225 | T50: =S50 -> 0.088649225 | U50: =T50 -> 0.088649225 | V50: =U50 -> 0.088649225
B52: Operating Expenses | D52: -40.230226 | E52: -34.366957 | F52: -38.729434 | G52: -45.849561 | H52: -12.454294 | I52: -12.994585 | J52: -13.938694 | K52: -9.7602589 | L52: -49.148305 | M52: =-M$23*M53 -> -14.931 | N52: =-N$23*N53 -> -15.400774 | O52: =-O$23*O53 -> -15.87983 | P52: =-P$23*P53 -> -18.794707 | Q52: =-Q$23*Q53 -> -65.006311 | R52: =-R$23*R53 -> -55.597721 | S52: =-S$23*S53 -> -45.398989 | T52: =-T$23*T53 -> -42.524899 | ... V52: =-V$23*V53 -> -35.642053
B53: % Margin | D53: =-D52/D$23 -> 0.045076004 | E53: =-E52/E$23 -> 0.037954915 | F53: =-F52/F$23 -> 0.034390933 | G53: =-G52/G$23 -> 0.037735593 | H53: =-H52/H$23 -> 0.043918911 | I53: =-I52/I$23 -> 0.039836799 | J53: =-J52/J$23 -> 0.048696173 | K53: =-K52/K$23 -> 0.028071622 | L53: =-L52/L$23 -> 0.039517828 | M53: =Q53 -> 0.050456316 | N53: =Q53 -> 0.050456316 | O53: =Q53 -> 0.050456316 | P53: =Q53 -> 0.050456316 | Q53: 0.050456316 | R53: =Q53-'Margin Build vF'!J19/10000 -> 0.041206316 | S53: =R53-'Margin Build vF'!K19/10000 -> 0.031956316 | T53: =S53-'Margin Build vF'!L19/10000 -> 0.028122983 | U53: =T53-'Margin Build vF'!M19/10000 -> 0.02428965 | V53: =U53-'Margin Build vF'!N19/10000 -> 0.020456316
B55: Adjustments | D55: -12.816102 | E55: -12.816102 | F55: -21.650103 | G55: -17.626647 | H55: =$L55/4 -> -0.27823445 | I55: =$L55/4 -> -0.27823445 | J55: =$L55/4 -> -0.27823445 | K55: =$L55/4 -> -0.27823445 | L55: -1.1129378 | M55: =Q55*$D$74 -> 0.88095704 | N55: =Q55*$E$74 -> 0.90867458 | O55: =Q55*$F$74 -> 0.93693982 | P55: =Q55*$G$74 -> 1.108923 | Q55: 3.8354945 | R55: 0 | S55: 0 | T55: 0 | U55: 0 | V55: 0
B57: Run-Rate Impact of Cost Initiatives | M57: =Q57*25% -> 0 | N57: =Q57*25% -> 0 | O57: =Q57*25% -> 0 | P57: =Q57*25% -> 0 | Q57: 0 | R57: 0 | S57: 0 | T57: 0 | U57: 0 | V57: 0
B59: Organic PF Adj. EBITDA | D59: =D45+D49+D52+D55+D57 -> 16.637554 | E59: =E45+E49+E52+E55+E57 -> 29.347991 | F59: =F45+F49+F52+F55+F57 -> 44.79345 | G59: =G45+G49+G52+G55+G57 -> 59.881973 | H59: =H45+H49+H52+H55+H57 -> 14.260658 | I59: =I45+I49+I52+I55+I57 -> 23.159124 | J59: =J45+J49+J52+J55+J57 -> 13.739824 | K59: =K45+K49+K52+K55+K57 -> 26.515171 | ... V59: =V45+V49+V52+V55+V57 -> 157.96721
B60: % Margin | D60: =+D59/D$23 -> 0.018641567 | E60: =+E59/E$23 -> 0.032411962 | F60: =+F59/F$23 -> 0.039775653 | G60: =+G59/G$23 -> 0.049284698 | H60: =+H59/H$23 -> 0.050288883 | I60: =+I59/I$23 -> 0.070997676 | J60: =+J59/J$23 -> 0.048001401 | K60: =+K59/K$23 -> 0.076260667 | ... V60: =+V59/V$23 -> 0.090663328
B62: Acquired EBITDA | C62: =C26 -> 1
B64: Total PF Adj. EBITDA | D64: =D59+D62 -> 16.637554 | E64: =E59+E62 -> 29.347991 | F64: =F59+F62 -> 44.79345 | G64: =G59+G62 -> 59.881973 | H64: =H59+H62 -> 14.260658 | I64: =I59+I62 -> 23.159124 | J64: =J59+J62 -> 13.739824 | K64: =K59+K62 -> 26.515171 | ... V64: =V59+V62 -> 157.96721
B65: % Margin | D65: =+D64/D$28 -> 0.018641567 | E65: =+E64/E$28 -> 0.032411962 | F65: =+F64/F$28 -> 0.039775653 | G65: =+G64/G$28 -> 0.049284698 | H65: =+H64/H$28 -> 0.050288883 | I65: =+I64/I$28 -> 0.070997676 | J65: =+J64/J$28 -> 0.048001401 | K65: =+K64/K$28 -> 0.076260667 | ... V65: =+V64/V$28 -> 0.090663328
...

Sheet Revenue Build
B2: Cross-Sell | C2: =XSell -> Base
D5: 43830 | E5: =EOMONTH(D5,12) -> 44196 | F5: =EOMONTH(E5,12) -> 44561 | G5: =EOMONTH(F5,12) -> 44926 | H5: =EOMONTH(G5,12) -> 45291 | I5: =EOMONTH(H5,12) -> 45657 | J5: =EOMONTH(I5,12) -> 46022 | K5: =EOMONTH(J5,12) -> 46387 | L5: =EOMONTH(K5,12) -> 46752 | ... N5: =EOMONTH(M5,12) -> 47483
D6: 2019 | E6: =D6+1 -> 2020 | F6: =E6+1 -> 2021 | G6: =F6+1 -> 2022 | H6: =G6+1 -> 2023 | I6: =H6+1 -> 2024 | J6: =I6+1 -> 2025 | K6: =J6+1 -> 2026 | L6: =K6+1 -> 2027 | ... N6: =M6+1 -> 2029
A7: x | B7: Industry Data
B9: Forecasted Industry Growth
B10: Communications | J10: 0.014 | K10: 0.014 | L10: 0.014 | M10: 0.014 | N10: 0.014
B11: Consulting | J11: 0.135 | K11: 0.135 | L11: 0.135 | M11: 0.135 | N11: 0.135
B12: Cloud | J12: 0.145 | K12: 0.145 | L12: 0.145 | M12: 0.145 | N12: 0.145
B13: Infrastructure | J13: 0.045 | K13: 0.045 | L13: 0.045 | M13: 0.045 | N13: 0.045
A15: x | B15: Infrastructure
B17: Customer A | D17: 133.87019 | E17: 119.36184 | F17: 216.554 | G17: 184.38929 | H17: 161.06997 | I17: 162.68067
B18: Customer B | D18: 0 | E18: 0 | F18: 0 | G18: 0 | H18: 0 | I18: 0
B19: Customer C | D19: 0 | E19: 1.211 | F19: 0.737 | G19: 0.852 | H19: 1.0747681 | I19: 1.1257698
B20: Customer D | D20: 35.109 | E20: 29.821 | F20: 34.501 | G20: 34.163 | H20: 37.897286 | I20: 40.171123
B21: Customer E | D21: 6.209 | E21: 5.610572 | F21: 2.475 | G21: 5.859 | H21: 21.205057 | I21: 19.296602
B22: Customer F | D22: 7.1745 | E22: 11.310568 | F22: 20.824025 | G22: 22.216846 | H22: 14.45348 | I22: 14.887084
B23: Customer G | D23: 16.3534 | E23: 5.359 | F23: 2.671 | G23: 4.548 | H23: 1.1347891 | I23: 1.3730948
B24: Customer H | D24: 1.2815 | E24: 0.843 | F24: 1.636 | G24: 1.524 | H24: 2.888449 | I24: 3.0617559
B25: Customer I | D25: 1.83786 | E25: 5.971 | F25: 8.911 | G25: 11.724 | H25: 10.591103 | I25: 11.014747
B26: Customer J | D26: 9.20245 | E26: 10.149942 | F26: 15.27686 | G26: 13.014011 | H26: 13.950893 | I26: 12.695313
B27: Customer K | D27: 1.593 | E27: 0.661 | F27: 0.266 | G27: 0.502 | H27: 2.069129 | I27: 7.9868379
B28: Customer L | D28: 7.267305 | E28: 2.052507 | F28: 2.779591 | G28: 3.606554 | H28: 5.20156 | I28: 5.5136536
... B31: Customer O | D31: 0 | E31: 0 | F31: 0.035 | G31: 0.202 | H31: 0.620261 | I31: 0.620261
B32: Top 15 Customers | D32: =SUM(D17:D31) -> 227.5977 | E32: =SUM(E17:E31) -> 202.94023 | F32: =SUM(F17:F31) -> 314.58472 | G32: =SUM(G17:G31) -> 295.44871 | H32: =SUM(H17:H31) -> 291.33648 | I32: =SUM(I17:I31) -> 300.89318 | J32: =I32*(1+J33) -> 308.41551 | K32: =J32*(1+K33) -> 316.1259 | L32: =K32*(1+L33) -> 324.02905 | M32: =L32*(1+M33) -> 332.12978 | N32: =M32*(1+N33) -> 340.43302
B33: % growth | E33: =E32/D32-1 -> -0.10833796 | F33: =F32/E32-1 -> 0.55013483 | G33: =G32/F32-1 -> -0.060829435 | H33: =H32/G32-1 -> -0.013918584 | I33: =I32/H32-1 -> 0.032802967 | J33: =SUM(J34,J35) -> 0.025 | K33: =SUM(K34,K35) -> 0.025 | L33: =SUM(L34,L35) -> 0.025 | M33: =SUM(M34,M35) -> 0.025 | N33: =SUM(N34,N35) -> 0.025
B34: industry growth | J34: =J13 -> 0.045 | K34: =K13 -> 0.045 | L34: =L13 -> 0.045 | M34: =M13 -> 0.045 | N34: =N13 -> 0.045
B35: size impact | J35: -0.02 | K35: -0.02 | L35: -0.02 | M35: -0.02 | N35: -0.02
B37: Remaining Customers | D37: ='Top Customer Data'!D27 -> 329.60544 | E37: ='Top Customer Data'!E27 -> 316.18914 | F37: ='Top Customer Data'!F27 -> 305.09224 | G37: ='Top Customer Data'!G27 -> 356.48743 | H37: ='Top Customer Data'!H27 -> 363.82246 | I37: ='Top Customer Data'!I27 -> 369.76753 | J37: =I37*(1+J38) -> 386.40707 | K37: =J37*(1+K38) -> 403.79538 | L37: =K37*(1+L38) -> 421.96618 | M37: =L37*(1+M38) -> 440.95465 | N37: =M37*(1+N38) -> 460.79761
B38: % growth | E38: =E37/D37-1 -> -0.040704144 | F38: =F37/E37-1 -> -0.035095762 | G38: =G37/F37-1 -> 0.16845787 | H38: =H37/G37-1 -> 0.020575863 | I38: =I37/H37-1 -> 0.016340566 | J38: =SUM(J39,J40) -> 0.045 | K38: =SUM(K39,K40) -> 0.045 | L38: =SUM(L39,L40) -> 0.045 | M38: =SUM(M39,M40) -> 0.045 | N38: =SUM(N39,N40) -> 0.045
B39: industry growth | J39: =J13 -> 0.045 | K39: =K13 -> 0.045 | L39: =L13 -> 0.045 | M39: =M13 -> 0.045 | N39: =N13 -> 0.045
B40: share taking | J40: 0 | K40: 0 | L40: 0 | M40: 0 | N40: 0
B42: Total Revenue | D42: =D37+D32 -> 557.20315 | E42: =E37+E32 -> 519.12937 | F42: =F37+F32 -> 619.67696 | G42: =G37+G32 -> 651.93614 | H42: =H37+H32 -> 655.15895 | I42: =I37+I32 -> 670.66071 | J42: =J37+J32 -> 694.82258 | K42: =K37+K32 -> 719.92129 | ... N42: =N37+N32 -> 801.23063
B43: % growth | E43: =E42/D42-1 -> -0.068330156 | F43: =F42/E42-1 -> 0.19368504 | G43: =G42/F42-1 -> 0.052058055 | H43: =H42/G42-1 -> 0.0049434423 | I43: =I42/H42-1 -> 0.023661077 | J43: =J42/I42-1 -> 0.036026963 | K43: =K42/J42-1 -> 0.036122467 | L43: =L42/K42-1 -> 0.036217765 | ... N43: =N42/M42-1 -> 0.036407671
B45: Top 15 Customer Outgrowth | E45: =E33-E38 -> -0.067633814 | F45: =F33-F38 -> 0.58523059 | G45: =G33-G38 -> -0.2292873 | H45: =H33-H38 -> -0.034494447 | I45: =I33-I38 -> 0.016462401 | J45: =J33-J38 -> -0.02 | K45: =K33-K38 -> -0.02 | L45: =L33-L38 -> -0.02 | ... N45: =N33-N38 -> -0.02
B47: Mix:
B48: Top 15 | D48: =D32/D$42 -> 0.4084645 | E48: =E32/E$42 -> 0.3909242 | F48: =F32/F$42 -> 0.50765922 | G48: =G32/G$42 -> 0.45318658 | H48: =H32/H$42 -> 0.44468062 | I48: =I32/I$42 -> 0.44865187 | J48: =J32/J$42 -> 0.44387664 | K48: =K32/K$42 -> 0.43911176 | ... N48: =N32/N$42 -> 0.42488767
B49: Other | D49: =D37/D42 -> 0.5915355 | E49: =E37/E42 -> 0.6090758 | F49: =F37/F42 -> 0.49234078 | G49: =G37/G42 -> 0.54681342 | H49: =H37/H42 -> 0.55531938 | I49: =I37/I42 -> 0.55134813 | J49: =J37/J42 -> 0.55612336 | K49: =K37/K42 -> 0.56088824 | ... N49: =N37/N42 -> 0.57511233
A52: x | B52: Cloud
B54: Customer A | D54: ='Top Customer Data'!D34 -> 0 | E54: ='Top Customer Data'!E34 -> 0 | F54: ='Top Customer Data'!F34 -> 0 | G54: ='Top Customer Data'!G34 -> 0 | H54: ='Top Customer Data'!H34 -> 0 | I54: ='Top Customer Data'!I34 -> 0
B55: Customer B | D55: ='Top Customer Data'!D35 -> 0 | E55: ='Top Customer Data'!E35 -> 0 | F55: ='Top Customer Data'!F35 -> 0 | G55: ='Top Customer Data'!G35 -> 0 | H55: ='Top Customer Data'!H35 -> 0 | I55: ='Top Customer Data'!I35 -> 0
...

Sheet Margin Build vF
B2: Cost Reduction Toggle | C2: =CRT -> Base | J2: 1 | K2: 2 | L2: 3 | M2: 4 | N2: 5
A4: x | B4: EBITDA Margin Build (Cost Savings)
D5: 43830 | E5: =EOMONTH(D5,12) -> 44196 | F5: =EOMONTH(E5,12) -> 44561 | G5: =EOMONTH(F5,12) -> 44926 | H5: =EOMONTH(G5,12) -> 45291 | I5: =EOMONTH(H5,12) -> 45657 | J5: 2025E | K5: 2026E | L5: 2027E | M5: 2028E | N5: 2029E | R5: Cost Savings By Year Summary
B6: EBITDA Margins BoP | E6: 0.018641567 | F6: 0.032411962 | G6: 0.039775653 | H6: 0.049284698 | I6: 0.062454615 | J6: =I20 -> 0.062454615 | K6: =J20 -> 0.071704615 | L6: =K20 -> 0.080954615 | M6: =L20 -> 0.084787949 | N6: =M20 -> 0.088621282
B7: (+) Near-term Offshoring (bps impact) | J7: {=_xlfn.IFS($E$35=0,0,$E$35=1,$D$35,$E$35=2,$D$36)} -> 40 | K7: {=_xlfn.IFS($E$35=0,0,$E$35=1,$D$35,$E$35=2,$D$36)} -> 40 | Q7: Year | R7: Bps | S7: EoP EBITDA Margin
B8: (+) Managed Services Utilization Improvement (bps impact) | J8: {=_xlfn.IFS($E$39=0,0,$E$39=1,$D$39,$E$39=2,$D$40)} -> 17.5 | K8: {=_xlfn.IFS($E$39=0,0,$E$39=1,$D$39,$E$39=2,$D$40)} -> 17.5 | Q8: 1 | R8: =INDEX($J$19:$N$19,MATCH($Q8,$J$2:$N$2,0)) -> 92.5 | S8: =INDEX($J$20:$N$20,MATCH($Q8,$J$2:$N$2,0)) -> 0.071704615
B9: (+) Sales Commission Change (bps impact) | J9: {=_xlfn.IFS($E$43=0,0,$E$43=1,$D$43,$E$43=2,$D$44)} -> 15 | K9: {=_xlfn.IFS($E$43=0,0,$E$43=1,$D$43,$E$43=2,$D$44)} -> 15 | Q9: 2 | R9: =INDEX($J$19:$N$19,MATCH($Q9,$J$2:$N$2,0)) -> 92.5 | S9: =INDEX($J$20:$N$20,MATCH($Q9,$J$2:$N$2,0)) -> 0.080954615
B10: (+) In-Process SG&A Reduction (bps impact) | J10: {=_xlfn.IFS($E$47=0,0,$E$47=1,$D$47,$E$47=2,$D$48)} -> 10 | K10: {=_xlfn.IFS($E$47=0,0,$E$47=1,$D$47,$E$47=2,$D$48)} -> 10 | Q10: 3 | R10: =INDEX($J$19:$N$19,MATCH($Q10,$J$2:$N$2,0)) -> 38.333333 | S10: =INDEX($J$20:$N$20,MATCH($Q10,$J$2:$N$2,0)) -> 0.084787949
B11: (+) Back Office IT Spend Reduction (bps impact) | J11: {=_xlfn.IFS($E$51=0,0,$E$51=1,$D$51,$E$51=2,$D$52)} -> 10 | K11: {=_xlfn.IFS($E$51=0,0,$E$51=1,$D$51,$E$51=2,$D$52)} -> 10 | Q11: 4 | R11: =INDEX($J$19:$N$19,MATCH($Q11,$J$2:$N$2,0)) -> 38.333333 | S11: =INDEX($J$20:$N$20,MATCH($Q11,$J$2:$N$2,0)) -> 0.088621282
B12: (+) Pricing Increase (bps impact) | L12: {=_xlfn.IFS($E$23=0,0,$E$23=1,$D$23,$E$23=2,$D$24)} -> 25 | M12: {=_xlfn.IFS($E$23=0,0,$E$23=1,$D$23,$E$23=2,$D$24)} -> 25 | N12: {=_xlfn.IFS($E$23=0,0,$E$23=1,$D$23,$E$23=2,$D$24)} -> 25 | Q12: 5 | R12: =INDEX($J$19:$N$19,MATCH($Q12,$J$2:$N$2,0)) -> 38.333333 | S12: =INDEX($J$20:$N$20,MATCH($Q12,$J$2:$N$2,0)) -> 0.092454615
B13: (+) Span and Layer Reduction (bps impact) | L13: {=_xlfn.IFS($E$31=0,0,$E$31=1,$D$31,$E$31=2,$D$32)} -> 0 | M13: {=_xlfn.IFS($E$31=0,0,$E$31=1,$D$31,$E$31=2,$D$32)} -> 0 | N13: {=_xlfn.IFS($E$31=0,0,$E$31=1,$D$31,$E$31=2,$D$32)} -> 0
B14: (+) Offshoring / Nearshoring / Outsourcing (bps impact) | L14: {=_xlfn.IFS($E$27=0,0,$E$27=1,$D$27,$E$27=2,$D$28)} -> 13.333333 | M14: {=_xlfn.IFS($E$27=0,0,$E$27=1,$D$27,$E$27=2,$D$28)} -> 13.333333 | N14: {=_xlfn.IFS($E$27=0,0,$E$27=1,$D$27,$E$27=2,$D$28)} -> 13.333333
B15: (+) Resale Margin Expansion | J15: 0 | K15: 0 | L15: 0 | M15: 0 | N15: 0
B16: (+) Time/Materials Margin Expansion | J16: 0 | K16: 0 | L16: 0 | M16: 0 | N16: 0
B17: (+) Consulting Margin Expansion | J17: 0 | K17: 0 | L17: 0 | M17: 0 | N17: 0
B18: (+) Cloud Margin Expansion | J18: 0 | K18: 0 | L18: 0 | M18: 0 | N18: 0
B19: Total bps impact | I19: =SUM(I7:I18) -> 0 | J19: =SUM(J7:J18) -> 92.5 | K19: =SUM(K7:K18) -> 92.5 | L19: =SUM(L7:L18) -> 38.333333 | M19: =SUM(M7:M18) -> 38.333333 | N19: =SUM(N7:N18) -> 38.333333
B20: EoP EBITDA Margin | D20: 0.018641567 | E20: 0.032411962 | F20: 0.039775653 | G20: 0.049284698 | H20: 0.062454615 | I20: =H20 -> 0.062454615 | J20: =J6+J19/10000 -> 0.071704615 | K20: =K6+K19/10000 -> 0.080954615 | L20: =L6+L19/10000 -> 0.084787949 | M20: =M6+M19/10000 -> 0.088621282 | N20: =N6+N19/10000 -> 0.092454615
B22: Pricing Increase (bps impact) cases | C22: Total Cost Savings | D22: Per Year Savings | E22: Case Manager
B23: Low Cost Savings | C23: 75 | D23: =C23/3 -> 25 | E23: =IF(CRT="Base",1,IF(CRT="None",0,IF(CRT="High",2))) -> 1 | G23: Case Manager
B24: High Cost Savings | C24: 110 | D24: =C24/3 -> 36.666667 | G24: No Cost Savings: 0
G25: Low Cost Savings: 1
B26: Offshoring / Nearshoring / Outsourcing (bps impact) cases | E26: Case Manager | G26: High Cost Savings: 2
B27: Low Cost Savings | C27: 40 | D27: =C27/3 -> 13.333333 | E27: =IF(CRT="Base",1,IF(CRT="None",0,IF(CRT="High",2))) -> 1
B28: High Cost Savings | C28: 255 | D28: =C28/3 -> 85
B30: Span and Layer Reduction (bps impact) cases | E30: Case Manager
B31: Low Cost Savings | C31: 5 | D31: =C31/3 -> 1.6666667 | E31: =IF(CRT="Base",0,IF(CRT="None",0,IF(CRT="High",2))) -> 0
B32: High Cost Savings | C32: 10 | D32: =C32/3 -> 3.3333333
B34: Near-term Offshoring (bps impact) cases | E34: Case Manager
B35: Low Cost Savings | C35: 50 | D35: =C35/2 -> 25 | E35: =IF(CRT="Base",2,IF(CRT="None",0,IF(CRT="High",2))) -> 2
B36: High Cost Savings | C36: 80 | D36: =C36/2 -> 40
B38: Near-term Managed Services Utilization Improvement (bps impact) cases | E38: Case Manager
B39: Low Cost Savings | C39: 15 | D39: =C39/2 -> 7.5 | E39: =IF(CRT="Base",2,IF(CRT="None",0,IF(CRT="High",2))) -> 2
B40: High Cost Savings | C40: 35 | D40: =C40/2 -> 17.5
B42: Near-term Sales Commission Change (bps impact) cases | E42: Case Manager
B43: Low Cost Savings | C43: 10 | D43: =C43/2 -> 5 | E43: =IF(CRT="Base",2,IF(CRT="None",0,IF(CRT="High",2))) -> 2
B44: High Cost Savings | C44: 30 | D44: =C44/2 -> 15
B46: Near-term In-Process SG&A Reduction (bps impact) cases | E46: Case Manager
B47: Low Cost Savings | C47: 10 | D47: =C47/2 -> 5 | E47: =IF(CRT="Base",2,IF(CRT="None",0,IF(CRT="High",2))) -> 2
B48: High Cost Savings | C48: 20 | D48: =C48/2 -> 10
...

Sheet Top Customer Data
A1: Strictly private & confidential
A2: There can be no assurance this investment will achieve its objectives or avoid losses.
B4: Top Customer Financials
B6: $m | D6: 2019A | E6: 2020A | F6: 2021A | G6: 2022A | H6: 2023E | I6: 2024E | K6: 2019A | L6: 2020A | M6: 2021A | N6: 2022A | O6: 2023E | P6: 2024E | R6: 2019A | S6: 2020A | T6: 2021A | U6: 2022A | V6: 2023E | W6: 2024E | Y6: 2019A | Z6: 2020A | AA6: 2021A | AB6: 2022A | AC6: 2023E | AD6: 2024E
A8: x | B8: Rank | C8: Infrastructure Revenue | D8: Revenue | K8: Gross Profit | R8: Gross Margin | Y8: Revenue Growth
B9: 1 | C9: Customer A | D9: 133.87019 | E9: 119.36184 | F9: 216.554 | G9: 184.38929 | H9: 161.06997 | I9: =IFERROR(H9*(1+AD9),0) -> 162.68067 | K9: 18.454073 | L9: 15.035522 | M9: 24.717 | N9: 22.248266 | O9: 16.782791 | P9: =IFERROR(I9*W9,0) -> 19.613077 | R9: =IFERROR(K9/D9,0) -> 0.1378505 | S9: =IFERROR(L9/E9,0) -> 0.1259659 | T9: =IFERROR(M9/F9,0) -> 0.11413781 | U9: =IFERROR(N9/G9,0) -> 0.12065921 | V9: =IFERROR(O9/H9,0) -> 0.10419566 | W9: =AVERAGE(R9:V9) -> 0.12056182 | Z9: =IFERROR(E9/D9-1,0) -> -0.10837626 | AA9: =IFERROR(F9/E9-1,0) -> 0.81426488 | AB9: =IFERROR(G9/F9-1,0) -> -0.14852975 | AC9: =IFERROR(H9/G9-1,0) -> -0.12646787 | AD9: 0.01
B10: =B9+1 -> 2 | C10: Customer B | D10: 0 | E10: 0 | F10: 0 | G10: 0 | H10: 0 | I10: =IFERROR(H10*(1+AD10),0) -> 0 | K10: 0 | L10: 0 | M10: 0 | N10: 0 | O10: 0 | P10: =IFERROR(I10*W10,0) -> 0 | R10: =IFERROR(K10/D10,0) -> 0 | S10: =IFERROR(L10/E10,0) -> 0 | T10: =IFERROR(M10/F10,0) -> 0 | U10: =IFERROR(N10/G10,0) -> 0 | V10: =IFERROR(O10/H10,0) -> 0 | W10: =IFERROR(P10/I10,0) -> 0 | Z10: =IFERROR(E10/D10-1,0) -> 0 | AA10: =IFERROR(F10/E10-1,0) -> 0 | AB10: =IFERROR(G10/F10-1,0) -> 0 | AC10: =IFERROR(H10/G10-1,0) -> 0 | AD10: 0.01
B11: =B10+1 -> 3 | C11: Customer C | D11: 0 | E11: 1.211 | F11: 0.737 | G11: 0.852 | H11: 1.0747681 | I11: =IFERROR(H11*(1+AD11),0) -> 1.1257698 | K11: 0 | L11: 0.268 | M11: 0.186 | N11: 0.283 | O11: 0.22094828 | P11: =IFERROR(I11*W11,0) -> 0.33019731 | R11: =IFERROR(K11/D11,0) -> 0 | S11: =IFERROR(L11/E11,0) -> 0.22130471 | T11: =IFERROR(M11/F11,0) -> 0.25237449 | U11: =IFERROR(N11/G11,0) -> 0.33215962 | V11: =IFERROR(O11/H11,0) -> 0.20557763 | W11: 0.29330801 | Z11: =IFERROR(E11/D11-1,0) -> 0 | AA11: =IFERROR(F11/E11-1,0) -> -0.39141206 | AB11: =IFERROR(G11/F11-1,0) -> 0.15603799 | AC11: =IFERROR(H11/G11-1,0) -> 0.26146492 | AD11: 0.047453709
B12: =B11+1 -> 4 | C12: Customer D | D12: 35.109 | E12: 29.821 | F12: 34.501 | G12: 34.163 | H12: 37.897286 | I12: =IFERROR(H12*(1+AD12),0) -> 40.171123 | K12: 4.91526 | L12: 3.955 | M12: 3.459 | N12: 3.395 | O12: 2.5137979 | P12: =IFERROR(I12*W12,0) -> 4.1777968 | R12: =IFERROR(K12/D12,0) -> 0.14 | S12: =IFERROR(L12/E12,0) -> 0.13262466 | T12: =IFERROR(M12/F12,0) -> 0.10025796 | U12: =IFERROR(N12/G12,0) -> 0.099376518 | V12: =IFERROR(O12/H12,0) -> 0.066331871 | W12: 0.104 | Z12: =IFERROR(E12/D12-1,0) -> -0.15061665 | AA12: =IFERROR(F12/E12-1,0) -> 0.15693639 | AB12: =IFERROR(G12/F12-1,0) -> -0.0097968175 | AC12: =IFERROR(H12/G12-1,0) -> 0.1093079 | AD12: 0.06
B13: =B12+1 -> 5 | C13: Customer E | D13: 6.209 | E13: 5.610572 | F13: 2.475 | G13: 5.859 | H13: 21.205057 | I13: =IFERROR(H13*(1+AD13),0) -> 19.296602 | K13: 0.707 | L13: 0.776753 | M13: 0.428 | N13: 1.386773 | O13: 2.788593 | P13: =IFERROR(I13*W13,0) -> 1.3507621 | R13: =IFERROR(K13/D13,0) -> 0.11386697 | S13: =IFERROR(L13/E13,0) -> 0.13844453 | T13: =IFERROR(M13/F13,0) -> 0.17292929 | U13: =IFERROR(N13/G13,0) -> 0.23669107 | V13: =IFERROR(O13/H13,0) -> 0.13150603 | W13: 0.07 | Z13: =IFERROR(E13/D13-1,0) -> -0.096380738 | AA13: =IFERROR(F13/E13-1,0) -> -0.55886851 | AB13: =IFERROR(G13/F13-1,0) -> 1.3672727 | AC13: =IFERROR(H13/G13-1,0) -> 2.6192281 | AD13: -0.09
B14: =B13+1 -> 6 | C14: Customer F | D14: 7.1745 | E14: 11.310568 | F14: 20.824025 | G14: 22.216846 | H14: 14.45348 | I14: =IFERROR(H14*(1+AD14),0) -> 14.887084 | K14: 1.00443 | L14: 1.6283201 | M14: 3.9251758 | N14: 5.9095803 | O14: 3.3876 | P14: =IFERROR(I14*W14,0) -> 3.5729003 | R14: =IFERROR(K14/D14,0) -> 0.14 | S14: =IFERROR(L14/E14,0) -> 0.14396448 | T14: =IFERROR(M14/F14,0) -> 0.18849266 | U14: =IFERROR(N14/G14,0) -> 0.26599546 | V14: =IFERROR(O14/H14,0) -> 0.23437954 | W14: 0.24 | Z14: =IFERROR(E14/D14-1,0) -> 0.57649568 | AA14: =IFERROR(F14/E14-1,0) -> 0.84111219 | AB14: =IFERROR(G14/F14-1,0) -> 0.066885293 | AC14: =IFERROR(H14/G14-1,0) -> -0.34943601 | AD14: 0.03
B15: =B14+1 -> 7 | C15: Customer G | D15: 16.3534 | E15: 5.359 | F15: 2.671 | G15: 4.548 | H15: 1.1347891 | I15: =IFERROR(H15*(1+AD15),0) -> 1.3730948 | K15: 2.0318 | L15: 0.475 | M15: 0.504 | N15: 0.77593 | O15: 0.46706554 | P15: =IFERROR(I15*W15,0) -> 0.37542846 | R15: =IFERROR(K15/D15,0) -> 0.12424328 | S15: =IFERROR(L15/E15,0) -> 0.08863594 | T15: =IFERROR(M15/F15,0) -> 0.18869337 | U15: =IFERROR(N15/G15,0) -> 0.17060906 | V15: =IFERROR(O15/H15,0) -> 0.41158796 | W15: 0.27341772 | Z15: =IFERROR(E15/D15-1,0) -> -0.67230056 | AA15: =IFERROR(F15/E15-1,0) -> -0.50158612 | AB15: =IFERROR(G15/F15-1,0) -> 0.70273306 | AC15: =IFERROR(H15/G15-1,0) -> -0.75048612 | AD15: 0.21
B16: =B15+1 -> 8 | C16: Customer H | D16: 1.2815 | E16: 0.843 | F16: 1.636 | G16: 1.524 | H16: 2.888449 | I16: =IFERROR(H16*(1+AD16),0) -> 3.0617559 | K16: 0.138 | L16: 0.09 | M16: 0.201 | N16: 0.133 | O16: 0.208296 | P16: =IFERROR(I16*W16,0) -> 0.28321242 | R16: =IFERROR(K16/D16,0) -> 0.10768631 | S16: =IFERROR(L16/E16,0) -> 0.10676157 | T16: =IFERROR(M16/F16,0) -> 0.12286064 | U16: =IFERROR(N16/G16,0) -> 0.087270341 | V16: =IFERROR(O16/H16,0) -> 0.072113442 | W16: 0.0925 | Z16: =IFERROR(E16/D16-1,0) -> -0.34217714 | AA16: =IFERROR(F16/E16-1,0) -> 0.94068802 | AB16: =IFERROR(G16/F16-1,0) -> -0.068459658 | AC16: =IFERROR(H16/G16-1,0) -> 0.89530774 | AD16: 0.06
B17: =B16+1 -> 9 | C17: Customer I | D17: 1.83786 | E17: 5.971 | F17: 8.911 | G17: 11.724 | H17: 10.591103 | I17: =IFERROR(H17*(1+AD17),0) -> 11.014747 | K17: 0.1654074 | L17: 0.708 | M17: 1.19 | N17: 1.435 | O17: 1.2218628 | P17: =IFERROR(I17*W17,0) -> 1.2362688 | R17: =IFERROR(K17/D17,0) -> 0.09 | S17: =IFERROR(L17/E17,0) -> 0.1185731 | T17: =IFERROR(M17/F17,0) -> 0.13354281 | U17: =IFERROR(N17/G17,0) -> 0.1223985 | V17: =IFERROR(O17/H17,0) -> 0.11536691 | W17: 0.11223761 | Z17: =IFERROR(E17/D17-1,0) -> 2.2488873 | AA17: =IFERROR(F17/E17-1,0) -> 0.49237984 | AB17: =IFERROR(G17/F17-1,0) -> 0.31567725 | AC17: =IFERROR(H17/G17-1,0) -> -0.096630618 | AD17: 0.04
B18: =B17+1 -> 10 | C18: Customer J | D18: 9.20245 | E18: 10.149942 | F18: 15.27686 | G18: 13.014011 | H18: 13.950893 | I18: =IFERROR(H18*(1+AD18),0) -> 12.695313 | K18: 2.618 | L18: 1.4717416 | M18: 2.2151447 | N18: 1.8870316 | O18: 2.7839651 | P18: =IFERROR(I18*W18,0) -> 1.8408203 | R18: =IFERROR(K18/D18,0) -> 0.28448946 | S18: =IFERROR(L18/E18,0) -> 0.145 | T18: =IFERROR(M18/F18,0) -> 0.145 | U18: =IFERROR(N18/G18,0) -> 0.145 | V18: =IFERROR(O18/H18,0) -> 0.19955461 | W18: 0.145 | Z18: =IFERROR(E18/D18-1,0) -> 0.10296081 | AA18: =IFERROR(F18/E18-1,0) -> 0.50511798 | AB18: =IFERROR(G18/F18-1,0) -> -0.14812262 | AC18: =IFERROR(H18/G18-1,0) -> 0.071990235 | AD18: -0.09
B19: =B18+1 -> 11 | C19: Customer K | D19: 1.593 | E19: 0.661 | F19: 0.266 | G19: 0.502 | H19: 2.069129 | I19: =IFERROR(H19*(1+AD19),0) -> 7.9868379 | K19: 0.307562 | L19: 0.155 | M19: 0.056 | N19: 0.109 | O19: 0.1755247 | P19: =IFERROR(I19*W19,0) -> 1.2778941 | R19: =IFERROR(K19/D19,0) -> 0.19307094 | S19: =IFERROR(L19/E19,0) -> 0.23449319 | T19: =IFERROR(M19/F19,0) -> 0.21052632 | U19: =IFERROR(N19/G19,0) -> 0.21713147 | V19: =IFERROR(O19/H19,0) -> 0.084830235 | W19: 0.16 | Z19: =IFERROR(E19/D19-1,0) -> -0.58505964 | AA19: =IFERROR(F19/E19-1,0) -> -0.59757943 | AB19: =IFERROR(G19/F19-1,0) -> 0.88721805 | AC19: =IFERROR(H19/G19-1,0) -> 3.1217709 | AD19: 2.86
B20: =B19+1 -> 12 | C20: Customer L | D20: 7.267305 | E20: 2.052507 | F20: 2.779591 | G20: 3.606554 | H20: 5.20156 | I20: =IFERROR(H20*(1+AD20),0) -> 5.5136536 | K20: 1.0667982 | L20: -0.22941456 | M20: 0.67538628 | N20: 0.83532836 | O20: 0.68344 | P20: =IFERROR(I20*W20,0) -> 0.99245765 | R20: =IFERROR(K20/D20,0) -> 0.14679419 | S20: =IFERROR(L20/E20,0) -> -0.11177285 | T20: =IFERROR(M20/F20,0) -> 0.24298045 | U20: =IFERROR(N20/G20,0) -> 0.23161399 | V20: =IFERROR(O20/H20,0) -> 0.13139135 | W20: 0.18 | Z20: =IFERROR(E20/D20-1,0) -> -0.71756972 | AA20: =IFERROR(F20/E20-1,0) -> 0.35424191 | AB20: =IFERROR(G20/F20-1,0) -> 0.29751248 | AC20: =IFERROR(H20/G20-1,0) -> 0.44225208 | AD20: 0.06
B21: =B20+1 -> 13 | C21: Customer M | D21: 0.2706165 | E21: 0.55575 | F21: 1.438634 | G21: 6.652186 | H21: 2.715 | I21: =IFERROR(H21*(1+AD21),0) -> 3.01365 | K21: 0.040592475 | L21: 0.0833625 | M21: 0.248625 | N21: 1.2463875 | O21: 0.5973 | P21: =IFERROR(I21*W21,0) -> 0.663003 | R21: =IFERROR(K21/D21,0) -> 0.15 | S21: =IFERROR(L21/E21,0) -> 0.15 | T21: =IFERROR(M21/F21,0) -> 0.17282019 | U21: =IFERROR(N21/G21,0) -> 0.1873651 | V21: =IFERROR(O21/H21,0) -> 0.22 | W21: 0.22 | Z21: =IFERROR(E21/D21-1,0) -> 1.0536442 | AA21: =IFERROR(F21/E21-1,0) -> 1.5886352 | AB21: =IFERROR(G21/F21-1,0) -> 3.62396 | AC21: =IFERROR(H21/G21-1,0) -> -0.59186349 | AD21: 0.11
B22: =B21+1 -> 14 | C22: Customer N | D22: 7.4288768 | E22: 10.03305 | F22: 6.4796125 | G22: 6.195825 | H22: 16.46474 | I22: =IFERROR(H22*(1+AD22),0) -> 17.452624 | K22: 1.154883 | L22: 1.169358 | M22: 0.88124215 | N22: 0.90957975 | O22: 3.292948 | P22: =IFERROR(I22*W22,0) -> 3.4905249 | R22: =IFERROR(K22/D22,0) -> 0.15545862 | S22: =IFERROR(L22/E22,0) -> 0.1165506 | T22: =IFERROR(M22/F22,0) -> 0.13600229 | U22: =IFERROR(N22/G22,0) -> 0.14680527 | V22: =IFERROR(O22/H22,0) -> 0.2 | W22: 0.2 | Z22: =IFERROR(E22/D22-1,0) -> 0.35054738 | AA22: =IFERROR(F22/E22-1,0) -> -0.35417321 | AB22: =IFERROR(G22/F22-1,0) -> -0.043796986 | AC22: =IFERROR(H22/G22-1,0) -> 1.6573927 | AD22: 0.06
B23: =B22+1 -> 15 | C23: Customer O | D23: 0 | E23: 0 | F23: 0.035 | G23: 0.202 | H23: 0.620261 | I23: =IFERROR(H23*(1+AD23),0) -> 0.620261 | K23: 0 | L23: 0 | M23: 0.496 | N23: 0.028 | O23: 0.10905051 | P23: =IFERROR(I23*W23,0) -> 0.09924176 | R23: =IFERROR(K23/D23,0) -> 0 | S23: =IFERROR(L23/E23,0) -> 0 | T23: =IFERROR(M23/F23,0) -> 14.171429 | U23: =IFERROR(N23/G23,0) -> 0.13861386 | V23: =IFERROR(O23/H23,0) -> 0.17581391 | W23: 0.16 | Z23: =IFERROR(E23/D23-1,0) -> 0 | AA23: =IFERROR(F23/E23-1,0) -> 0 | AB23: =IFERROR(G23/F23-1,0) -> 4.7714286 | AC23: =IFERROR(H23/G23-1,0) -> 2.070599
C24: Top 15 Total | D24: =SUM(D9:D23) -> 227.5977 | E24: =SUM(E9:E23) -> 202.94023 | F24: =SUM(F9:F23) -> 314.58472 | G24: =SUM(G9:G23) -> 295.44871 | H24: =SUM(H9:H23) -> 291.33648 | I24: =SUM(I9:I23) -> 300.89318 | K24: =SUM(K9:K23) -> 32.603806 | L24: =SUM(L9:L23) -> 25.586643 | M24: =SUM(M9:M23) -> 39.182574 | N24: =SUM(N9:N23) -> 40.581877 | O24: =SUM(O9:O23) -> 35.233183 | P24: =SUM(P9:P23) -> 39.303585 | R24: =IFERROR(K24/D24,0) -> 0.14325191 | S24: =IFERROR(L24/E24,0) -> 0.1260797 | T24: =IFERROR(M24/F24,0) -> 0.12455333 | U24: =IFERROR(N24/G24,0) -> 0.13735676 | V24: =IFERROR(O24/H24,0) -> 0.12093639 | W24: =IFERROR(P24/I24,0) -> 0.13062305 | Z24: =IFERROR(E24/D24-1,"--") -> -0.10833796 | AA24: =IFERROR(F24/E24-1,"--") -> 0.55013483 | AB24: =IFERROR(G24/F24-1,"--") -> -0.060829435 | AC24: =IFERROR(H24/G24-1,"--") -> -0.013918584 | AD24: =IFERROR(I24/H24-1,"--") -> 0.032802967
C25: Growth | E25: =E24/D24-1 -> -0.10833796 | F25: =F24/E24-1 -> 0.55013483 | G25: =G24/F24-1 -> -0.060829435 | H25: =H24/G24-1 -> -0.013918584 | I25: =I24/H24-1 -> 0.032802967 | L25: =L24/K24-1 -> -0.21522528 | M25: =M24/L24-1 -> 0.53136832 | N25: =N24/M24-1 -> 0.035712371 | O25: =O24/N24-1 -> -0.13180006 | P25: =P24/O24-1 -> 0.11552751
C27: Rest of Customers | D27: =D30-D24 -> 329.60544 | E27: =E30-E24 -> 316.18914 | F27: =F30-F24 -> 305.09224 | G27: =G30-G24 -> 356.48743 | H27: =H30-H24 -> 363.82246 | I27: =I30-I24 -> 369.76753 | K27: =K30-K24 -> 67.073543 | L27: =L30-L24 -> 67.817384 | M27: =M30-M24 -> 69.552282 | N27: =N30-N24 -> 76.44516 | O27: =O30-O24 -> 77.93162 | P27: =P30-P24 -> 77.462324 | R27: =IFERROR(K27/D27,"--") -> 0.20349647 | S27: =IFERROR(L27/E27,"--") -> 0.2144836 | T27: =IFERROR(M27/F27,"--") -> 0.22797133 | U27: =IFERROR(N27/G27,"--") -> 0.21443999 | V27: =IFERROR(O27/H27,"--") -> 0.21420233 | W27: =IFERROR(P27/I27,"--") -> 0.20948926 | Z27: =IFERROR(E27/D27-1,"--") -> -0.040704144 | AA27: =IFERROR(F27/E27-1,"--") -> -0.035095762 | AB27: =IFERROR(G27/F27-1,"--") -> 0.16845787 | AC27: =IFERROR(H27/G27-1,"--") -> 0.020575863 | AD27: =IFERROR(I27/H27-1,"--") -> 0.016340566
C28: Growth | E28: =E27/D27-1 -> -0.040704144 | F28: =F27/E27-1 -> -0.035095762 | G28: =G27/F27-1 -> 0.16845787 | H28: =H27/G27-1 -> 0.020575863 | I28: =I27/H27-1 -> 0.016340566 | L28: =L27/K27-1 -> 0.011089931 | M28: =M27/L27-1 -> 0.025581903 | N28: =N27/M27-1 -> 0.099103559 | O28: =O27/N27-1 -> 0.019444788 | P28: =P27/O27-1 -> -0.0060219017
C30: Total infrastructure | D30: 557.20315 | E30: 519.12937 | F30: 619.67696 | G30: 651.93614 | H30: 655.15895 | I30: 670.66071 | K30: 99.677349 | L30: 93.404027 | M30: 108.73486 | N30: 117.02704 | O30: 113.1648 | P30: 116.76591 | R30: =IFERROR(K30/D30,"--") -> 0.1788887 | S30: =IFERROR(L30/E30,"--") -> 0.17992437 | T30: =IFERROR(M30/F30,"--") -> 0.17547023 | U30: =IFERROR(N30/G30,"--") -> 0.1795069 | V30: =IFERROR(O30/H30,"--") -> 0.17272878 | W30: =IFERROR(P30/I30,"--") -> 0.17410578 | Z30: =IFERROR(E30/D30-1,"--") -> -0.068330156 | AA30: =IFERROR(F30/E30-1,"--") -> 0.19368504 | AB30: =IFERROR(G30/F30-1,"--") -> 0.052058055 | AC30: =IFERROR(H30/G30-1,"--") -> 0.0049434423 | AD30: =IFERROR(I30/H30-1,"--") -> 0.023661077
C31: Growth | E31: =E30/D30-1 -> -0.068330156 | F31: =F30/E30-1 -> 0.19368504 | G31: =G30/F30-1 -> 0.052058055 | H31: =H30/G30-1 -> 0.0049434423 | I31: =I30/H30-1 -> 0.023661077 | L31: =L30/K30-1 -> -0.062936289 | M31: =M30/L30-1 -> 0.16413456 | N31: =N30/M30-1 -> 0.076260562 | O31: =O30/N30-1 -> -0.033002918 | P31: =P30/O30-1 -> 0.031821777
A33: x | B33: Rank | C33: Cloud Revenue | D33: Revenue | K33: Gross Profit | R33: Gross Margin | Y33: Revenue Growth
B34: 1 | C34: Customer A | D34: 0 | E34: 0 | F34: 0 | G34: 0 | H34: 0 | I34: =IFERROR(H34*(1+AD34),0) -> 0 | K34: 0 | L34: 0 | M34: 0 | N34: 0 | O34: 0 | P34: =IFERROR(I34*W34,0) -> 0 | R34: =IFERROR(K34/D34,"--") -> -- | S34: =IFERROR(L34/E34,"--") -> -- | T34: =IFERROR(M34/F34,"--") -> -- | U34: =IFERROR(N34/G34,"--") -> -- | V34: =IFERROR(O34/H34,"--") -> -- | Z34: =IFERROR(E34/D34-1,"--") -> -- | AA34: =IFERROR(F34/E34-1,"--") -> -- | AB34: =IFERROR(G34/F34-1,"--") -> -- | AC34: =IFERROR(H34/G34-1,"--") -> -- | AD34: 0.01 | AM34: =IFERROR(AL34/AK34-1,"")
B35: =B34+1 -> 2 | C35: Customer B | D35: 0 | E35: 0 | F35: 0 | G35: 0 | H35: 0 | I35: =IFERROR(H35*(1+AD35),0) -> 0 | K35: 0 | L35: 0 | M35: 0 | N35: 0 | O35: 0 | P35: =IFERROR(I35*W35,0) -> 0 | R35: =IFERROR(K35/D35,"--") -> -- | S35: =IFERROR(L35/E35,"--") -> -- | T35: =IFERROR(M35/F35,"--") -> -- | U35: =IFERROR(N35/G35,"--") -> -- | V35: =IFERROR(O35/H35,"--") -> -- | Z35: =IFERROR(E35/D35-1,"--") -> -- | AA35: =IFERROR(F35/E35-1,"--") -> -- | AB35: =IFERROR(G35/F35-1,"--") -> -- | AC35: =IFERROR(H35/G35-1,"--") -> -- | AD35: 0.01 | AM35: =IFERROR(AL35/AK35-1,"")
B36: =B35+1 -> 3 | C36: Customer C | D36: 0 | E36: 0 | F36: 0 | G36: 0 | H36: 0 | I36: =IFERROR(H36*(1+AD36),0) -> 0 | K36: 0 | L36: 0 | M36: 0 | N36: 0 | O36: 0 | P36: =IFERROR(I36*W36,0) -> 0 | R36: =IFERROR(K36/D36,"--") -> -- | S36: =IFERROR(L36/E36,"--") -> -- | T36: =IFERROR(M36/F36,"--") -> -- | U36: =IFERROR(N36/G36,"--") -> -- | V36: =IFERROR(O36/H36,"--") -> -- | Z36: =IFERROR(E36/D36-1,"--") -> -- | AA36: =IFERROR(F36/E36-1,"--") -> -- | AB36: =IFERROR(G36/F36-1,"--") -> -- | AC36: =IFERROR(H36/G36-1,"--") -> -- | AD36: 0.01 | AM36: =IFERROR(AL36/AK36-1,"")
B37: =B36+1 -> 4 | C37: Customer D | D37: 0.575 | E37: 0.566 | F37: 0.167 | G37: 0.021 | H37: 0.091266 | I37: =IFERROR(H37*(1+AD37),0) -> 0.09217866 | K37: 0.253 | L37: 0.255 | M37: 0.075 | N37: 0.01 | O37: 0.0273798 | P37: =IFERROR(I37*W37,0) -> 0.044245757 | R37: =IFERROR(K37/D37,"--") -> 0.44 | S37: =IFERROR(L37/E37,"--") -> 0.45053004 | T37: =IFERROR(M37/F37,"--") -> 0.4491018 | U37: =IFERROR(N37/G37,"--") -> 0.47619048 | V37: =IFERROR(O37/H37,"--") -> 0.3 | W37: 0.48 | Z37: =IFERROR(E37/D37-1,"--") -> -0.015652174 | AA37: =IFERROR(F37/E37-1,"--") -> -0.704947 | AB37: =IFERROR(G37/F37-1,"--") -> -0.8742515 | AC37: =IFERROR(H37/G37-1,"--") -> 3.346 | AD37: 0.01
B38: =B37+1 -> 5 | C38: Customer E | D38: 12.8567 | E38: 5.684 | F38: 5.391 | G38: 6.813 | H38: 9.146 | I38: =IFERROR(H38*(1+AD38),0) -> 10.15206 | K38: 5.8278 | L38: 3.305 | M38: 3.261 | N38: 4.131 | O38: 5.62 | P38: =IFERROR(I38*W38,0) -> 5.8223308 | R38: =IFERROR(K38/D38,"--") -> 0.45328895 | S38: =IFERROR(L38/E38,"--") -> 0.58145672 | T38: =IFERROR(M38/F38,"--") -> 0.60489705 | U38: =IFERROR(N38/G38,"--") -> 0.60634082 | V38: =IFERROR(O38/H38,"--") -> 0.61447627 | W38: 0.57351225 | Z38: =IFERROR(E38/D38-1,"--") -> -0.55789588 | AA38: =IFERROR(F38/E38-1,"--") -> -0.051548205 | AB38: =IFERROR(G38/F38-1,"--") -> 0.26377295 | AC38: =IFERROR(H38/G38-1,"--") -> 0.34243358 | AD38: 0.11
B39: =B38+1 -> 6 | C39: Customer F | D39: 0 | E39: 0 | F39: 0 | G39: 0 | H39: 0 | I39: =IFERROR(H39*(1+AD39),0) -> 0 | K39: 0 | L39: 0 | M39: 0 | N39: 0 | O39: 0 | P39: =IFERROR(I39*W39,0) -> 0 | R39: =IFERROR(K39/D39,"--") -> -- | S39: =IFERROR(L39/E39,"--") -> -- | T39: =IFERROR(M39/F39,"--") -> -- | U39: =IFERROR(N39/G39,"--") -> -- | V39: =IFERROR(O39/H39,"--") -> -- | W39: -- | Z39: =IFERROR(E39/D39-1,"--") -> -- | AA39: =IFERROR(F39/E39-1,"--") -> -- | AB39: =IFERROR(G39/F39-1,"--") -> -- | AC39: =IFERROR(H39/G39-1,"--") -> -- | AD39: 0.01
B40: =B39+1 -> 7 | C40: Customer G | D40: 10.8393 | E40: 10.647 | F40: 10.125 | G40: 10.425 | H40: 10.2854 | I40: =IFERROR(H40*(1+AD40),0) -> 10.593962 | K40: 2.3178 | L40: 2.479 | M40: 2.593 | N40: 2.341 | O40: 2.316 | P40: =IFERROR(I40*W40,0) -> 2.4969271 | R40: =IFERROR(K40/D40,"--") -> 0.213833 | S40: =IFERROR(L40/E40,"--") -> 0.23283554 | T40: =IFERROR(M40/F40,"--") -> 0.25609877 | U40: =IFERROR(N40/G40,"--") -> 0.22455635 | V40: =IFERROR(O40/H40,"--") -> 0.22517355 | W40: 0.23569342 | Z40: =IFERROR(E40/D40-1,"--") -> -0.017740998 | AA40: =IFERROR(F40/E40-1,"--") -> -0.049027895 | AB40: =IFERROR(G40/F40-1,"--") -> 0.02962963 | AC40: =IFERROR(H40/G40-1,"--") -> -0.013390887 | AD40: 0.03
B41: =B40+1 -> 8 | C41: Customer H | D41: 0 | E41: 0 | F41: 0 | G41: 0 | H41: 0 | I41: =IFERROR(H41*(1+AD41),0) -> 0 | K41: 0 | L41: 0 | M41: 0 | N41: 0 | O41: 0 | P41: =IFERROR(I41*W41,0) -> 0 | R41: =IFERROR(K41/D41,"--") -> -- | S41: =IFERROR(L41/E41,"--") -> -- | T41: =IFERROR(M41/F41,"--") -> -- | U41: =IFERROR(N41/G41,"--") -> -- | V41: =IFERROR(O41/H41,"--") -> -- | W41: -- | Z41: =IFERROR(E41/D41-1,"--") -> -- | AA41: =IFERROR(F41/E41-1,"--") -> -- | AB41: =IFERROR(G41/F41-1,"--") -> -- | AC41: =IFERROR(H41/G41-1,"--") -> -- | AD41: 0.01
B42: =B41+1 -> 9 | C42: Customer I | D42: 0 | E42: 0 | F42: 0 | G42: 0 | H42: 0 | I42: =IFERROR(H42*(1+AD42),0) -> 0 | K42: 0 | L42: 0 | M42: 0 | N42: 0 | O42: 0 | P42: =IFERROR(I42*W42,0) -> 0 | R42: =IFERROR(K42/D42,"--") -> -- | S42: =IFERROR(L42/E42,"--") -> -- | T42: =IFERROR(M42/F42,"--") -> -- | U42: =IFERROR(N42/G42,"--") -> -- | V42: =IFERROR(O42/H42,"--") -> -- | W42: -- | Z42: =IFERROR(E42/D42-1,"--") -> -- | AA42: =IFERROR(F42/E42-1,"--") -> -- | AB42: =IFERROR(G42/F42-1,"--") -> -- | AC42: =IFERROR(H42/G42-1,"--") -> -- | AD42: 0.01
B43: =B42+1 -> 10 | C43: Customer J | D43: 0.0144 | E43: 0.10215 | F43: 0.0939 | G43: 0.0144 | H43: 0.0144 | I43: =IFERROR(H43*(1+AD43),0) -> 0.014544 | K43: 0.006048 | L43: 0.042903 | M43: 0.039438 | N43: 0.00432 | O43: 0.00432 | P43: =IFERROR(I43*W43,0) -> 0.0043632 | R43: =IFERROR(K43/D43,"--") -> 0.42 | S43: =IFERROR(L43/E43,"--") -> 0.42 | T43: =IFERROR(M43/F43,"--") -> 0.42 | U43: =IFERROR(N43/G43,"--") -> 0.3 | V43: =IFERROR(O43/H43,"--") -> 0.3 | W43: 0.3 | Z43: =IFERROR(E43/D43-1,"--") -> 6.09375 | AA43: =IFERROR(F43/E43-1,"--") -> -0.080763583 | AB43: =IFERROR(G43/F43-1,"--") -> -0.84664537 | AC43: =IFERROR(H43/G43-1,"--") -> 0 | AD43: 0.01
B44: =B43+1 -> 11 | C44: Customer K | D44: 0 | E44: 0.876954 | F44: 3.954 | G44: 5.143 | H44: 9.031 | I44: =IFERROR(H44*(1+AD44),0) -> 10.47596 | K44: 0 | L44: 0.297 | M44: 1.347 | N44: 1.677 | O44: 2.7093 | P44: =IFERROR(I44*W44,0) -> 3.4570668 | R44: =IFERROR(K44/D44,"--") -> -- | S44: =IFERROR(L44/E44,"--") -> 0.33867227 | T44: =IFERROR(M44/F44,"--") -> 0.34066768 | U44: =IFERROR(N44/G44,"--") -> 0.32607428 | V44: =IFERROR(O44/H44,"--") -> 0.3 | W44: 0.33 | Z44: =IFERROR(E44/D44-1,"--") -> -- | AA44: =IFERROR(F44/E44-1,"--") -> 3.5087884 | AB44: =IFERROR(G44/F44-1,"--") -> 0.30070814 | AC44: =IFERROR(H44/G44-1,"--") -> 0.755979 | AD44: 0.16
B45: =B44+1 -> 12 | C45: Customer L | D45: 0.04687275 | E45: 1.852743 | F45: 5.311784 | G45: 6.165946 | H45: 6.08 | I45: =IFERROR(H45*(1+AD45),0) -> 6.1408 | K45: 0.0187491 | L45: 0.77815206 | M45: 1.7528887 | N45: 2.0964216 | O45: 2.303535 | P45: =IFERROR(I45*W45,0) -> 2.087872 | R45: =IFERROR(K45/D45,"--") -> 0.4 | S45: =IFERROR(L45/E45,"--") -> 0.42 | T45: =IFERROR(M45/F45,"--") -> 0.33 | U45: =IFERROR(N45/G45,"--") -> 0.34 | V45: =IFERROR(O45/H45,"--") -> 0.37887089 | W45: 0.34 | Z45: =IFERROR(E45/D45-1,"--") -> 38.527081 | AA45: =IFERROR(F45/E45-1,"--") -> 1.8669837 | AB45: =IFERROR(G45/F45-1,"--") -> 0.16080511 | AC45: =IFERROR(H45/G45-1,"--") -> -0.013938818 | AD45: 0.01
B46: =B45+1 -> 13 | C46: Customer M | D46: 0 | E46: 0 | F46: 0.218866 | G46: 1.657064 | H46: 3.2 | I46: =IFERROR(H46*(1+AD46),0) -> 4.832 | K46: 0 | L46: 0 | M46: 0 | N46: 0 | O46: 0.096 | P46: =IFERROR(I46*W46,0) -> 0.14496 | R46: =IFERROR(K46/D46,"--") -> -- | S46: =IFERROR(L46/E46,"--") -> -- | T46: =IFERROR(M46/F46,"--") -> 0 | U46: =IFERROR(N46/G46,"--") -> 0 | V46: =IFERROR(O46/H46,"--") -> 0.03 | W46: 0.03 | Z46: =IFERROR(E46/D46-1,"--") -> -- | AA46: =IFERROR(F46/E46-1,"--") -> -- | AB46: =IFERROR(G46/F46-1,"--") -> 6.5711348 | AC46: =IFERROR(H46/G46-1,"--") -> 0.93112638 | AD46: 0.51
...

Sheet SOFR
