Workbook
Name Buyer_Diversification: WACC!$F$11
Name CapEx_Pct_Revenue: DCF!$J$16
Name Company_Name: 'Company0462-GAAP'!$F$8
Name Cost_of_Debt: WACC!$F$8
Name Cost_of_Preferred: WACC!$F$9
Name DA_Pct_Revenue: DCF!$J$15
Name Equity_Risk_Premium: WACC!$F$7
Name FCF_Decline_Rate: DCF!$T$21
Name Market_Correlation: WACC!$F$10
Name Min_Op_Margin: DCF!$J$13
Name Min_Rev_Growth: DCF!$J$10
Name Op_Margin_Change: DCF!$J$12
Name PrivCo_Discount: 'Company0462-GAAP'!$F$10
Name Rev_Growth_Decline: DCF!$J$9
Name Risk_Free_Rate: WACC!$F$6
Name Tax_Rate: 'Company0462-GAAP'!$F$7
Name Terminal_Growth_Rate: DCF!$J$21
Name Terminal_Multiple: DCF!$E$21
Name TV_Discount: DCF!$E$11
Name TV_Liquidation_Discount: DCF!$E$13
Name WACC: WACC!$L$35
Name WC_Pct_Change_in_Rev: DCF!$J$17

Sheet Company0462-Internal
B2: ="Sample Private Company Financial Statements - "&Company_Name
B3: ($ USD as Stated)
G5: Historical | L5: Projected
B6: Revenue and Expense Drivers: | F6: Units: | G6: Year 1 | H6: Year 2 | I6: Year 3 | J6: Year 4 | K6: Year 5 | L6: Year 6 | M6: Year 7 | N6: Year 8 | O6: Year 9 | P6: Year 10
C8: Course Sign-Ups: | F8: # Customers | G8: 1011 | H8: 2051 | I8: 2978 | J8: 4000 | K8: 4500 | L8: 4800 | M8: 5200 | N8: 5600 | O8: 6000 | P8: 6500
C9: Average Customer Value: | F9: $ / Customer | G9: =+G79/G8 | H9: =+H79/H8 | I9: =+I79/I8 | J9: =+J79/J8 | K9: =+K79/K8 | L9: 175 | M9: 190 | N9: 210 | O9: 225 | P9: 240
C11: Revenue Growth Rates:
C12: Product Sales Referred by Affiliates: | F12: % | G12: =IFERROR(+G80/F80-1,"N/A") | H12: =IFERROR(+H80/G80-1,"N/A") | I12: =IFERROR(+I80/H80-1,"N/A") | J12: =IFERROR(+J80/I80-1,"N/A") | K12: =IFERROR(+K80/J80-1,"N/A") | L12: 0.25 | M12: 0.2 | N12: 0.15 | O12: 0.1 | P12: 0.1
C13: Coaching & Resume Editing Services: | F13: % | G13: =IFERROR(+G81/F81-1,"N/A") | H13: =IFERROR(+H81/G81-1,"N/A") | I13: =IFERROR(+I81/H81-1,"N/A") | J13: =IFERROR(+J81/I81-1,"N/A") | K13: =IFERROR(+K81/J81-1,"N/A") | L13: 0.1 | M13: 0.1 | N13: 0.08 | O13: 0.08 | P13: 0.06
C14: Sales to Institutions: | F14: % | G14: =IFERROR(+G82/F82-1,"N/A") | H14: =IFERROR(+H82/G82-1,"N/A") | I14: =IFERROR(+I82/H82-1,"N/A") | J14: =IFERROR(+J82/I82-1,"N/A") | K14: =IFERROR(+K82/J82-1,"N/A") | L14: 0.4 | M14: 0.35 | N14: 0.3 | O14: 0.3 | P14: 0.25
C15: Commissions from Other Products: | F15: % | G15: =IFERROR(+G83/F83-1,"N/A") | H15: =IFERROR(+H83/G83-1,"N/A") | I15: =IFERROR(+I83/H83-1,"N/A") | J15: =IFERROR(+J83/I83-1,"N/A") | K15: =IFERROR(+K83/J83-1,"N/A") | L15: 0.15 | M15: 0.1 | N15: 0.1 | O15: 0.08 | P15: 0.08
C17: Expense Percentages:
C18: Commission Rate - Affiliates: | F18: % | G18: =IFERROR(-G87/G80,"N/A") | H18: =IFERROR(-H87/H80,"N/A") | I18: =IFERROR(-I87/I80,"N/A") | J18: =IFERROR(-J87/J80,"N/A") | K18: =IFERROR(-K87/K80,"N/A") | L18: 0.5 | M18: 0.5 | N18: 0.5 | O18: 0.5 | P18: 0.5
C19: Commission Rate - Coaches: | F19: % | G19: =IFERROR(-G88/G81,"N/A") | H19: =IFERROR(-H88/H81,"N/A") | I19: =IFERROR(-I88/I81,"N/A") | J19: =IFERROR(-J88/J81,"N/A") | K19: =IFERROR(-K88/K81,"N/A") | L19: 0.5 | M19: 0.5 | N19: 0.5 | O19: 0.5 | P19: 0.5
C20: Commission Rate - Sales Reps: | F20: % | G20: =IFERROR(-G89/G82,"N/A") | H20: =IFERROR(-H89/H82,"N/A") | I20: =IFERROR(-I89/I82,"N/A") | J20: =IFERROR(-J89/J82,"N/A") | K20: =IFERROR(-K89/K82,"N/A") | L20: 0.4 | M20: 0.4 | N20: 0.4 | O20: 0.4 | P20: 0.4
C22: Payment Fees % Gross Sales: | F22: % | G22: =IFERROR(-G95/G$84,"N/A") | H22: =IFERROR(-H95/H$84,"N/A") | I22: =IFERROR(-I95/I$84,"N/A") | J22: =IFERROR(-J95/J$84,"N/A") | K22: =IFERROR(-K95/K$84,"N/A") | L22: 0.028 | M22: 0.028 | N22: 0.029 | O22: 0.029 | P22: 0.03
C23: Refunds % Gross Sales: | F23: % | G23: =IFERROR(-G96/G$84,"N/A") | H23: =IFERROR(-H96/H$84,"N/A") | I23: =IFERROR(-I96/I$84,"N/A") | J23: =IFERROR(-J96/J$84,"N/A") | K23: =IFERROR(-K96/K$84,"N/A") | L23: 0.045 | M23: 0.045 | N23: 0.05 | O23: 0.05 | P23: 0.06
C25: Tax & Legal Fees % Gross Sales: | F25: % | G25: =IFERROR(-G102/G$84,"N/A") | H25: =IFERROR(-H102/H$84,"N/A") | I25: =IFERROR(-I102/I$84,"N/A") | J25: =IFERROR(-J102/J$84,"N/A") | K25: =IFERROR(-K102/K$84,"N/A") | L25: 0.002 | M25: 0.002 | N25: 0.003 | O25: 0.003 | P25: 0.003
C26: Online Advertising % Gross Sales: | F26: % | G26: =IFERROR(-G104/G$84,"N/A") | H26: =IFERROR(-H104/H$84,"N/A") | I26: =IFERROR(-I104/I$84,"N/A") | J26: =IFERROR(-J104/J$84,"N/A") | K26: =IFERROR(-K104/K$84,"N/A") | L26: 0.031 | M26: 0.033 | N26: 0.035 | O26: 0.035 | P26: 0.037
C27: IT Infrastructure % Gross Sales: | F27: % | G27: =IFERROR(-G108/G$84,"N/A") | H27: =IFERROR(-H108/H$84,"N/A") | I27: =IFERROR(-I108/I$84,"N/A") | J27: =IFERROR(-J108/J$84,"N/A") | K27: =IFERROR(-K108/K$84,"N/A") | L27: 0.022 | M27: 0.024 | N27: 0.024 | O27: 0.026 | P27: 0.026
C28: Travel & Moving % Gross Sales: | F28: % | G28: =IFERROR(-G109/G$84,"N/A") | H28: =IFERROR(-H109/H$84,"N/A") | I28: =IFERROR(-I109/I$84,"N/A") | J28: =IFERROR(-J109/J$84,"N/A") | K28: =IFERROR(-K109/K$84,"N/A") | L28: 0.007 | M28: 0.006 | N28: 0.005 | O28: 0.004 | P28: 0.004
C29: Depr. & Amort. % Gross Sales: | F29: % | G29: =IFERROR(-G110/G$84,"N/A") | H29: =IFERROR(-H110/H$84,"N/A") | I29: =IFERROR(-I110/I$84,"N/A") | J29: =IFERROR(-J110/J$84,"N/A") | K29: =IFERROR(-K110/K$84,"N/A") | L29: 0.002 | M29: 0.002 | N29: 0.003 | O29: 0.004 | P29: 0.004
C31: Effective Tax Rate: | F31: % | G31: =IFERROR(-G117/G115,"N/A") | H31: =IFERROR(-H117/H115,"N/A") | I31: =IFERROR(-I117/I115,"N/A") | J31: =IFERROR(-J117/J115,"N/A") | K31: =IFERROR(-K117/K115,"N/A") | L31: 0.3 | M31: 0.3 | N31: 0.3 | O31: 0.3 | P31: 0.3
C33: Full-Time Equivalents (FTEs):
C34: Customer Support: | F34: # FTEs | G34: 0 | H34: 0 | I34: 0.5 | J34: 0.75 | K34: 1 | L34: 1 | M34: 1.5 | N34: 1.5 | O34: 2 | P34: 2
C35: Web Design & Development: | F35: # FTEs | G35: 0 | H35: 0.5 | I35: 1 | J35: 1 | K35: 1 | L35: 1.5 | M35: 1.5 | N35: 2 | O35: 2 | P35: 2
C36: Sales Reps: | F36: # FTEs | G36: 0 | H36: 0.5 | I36: 0.5 | J36: 0.5 | K36: 0.5 | L36: 0.5 | M36: 1 | N36: 1 | O36: 1 | P36: 1
C37: Marketing Staff: | F37: # FTEs | G37: 0 | H37: 0 | I37: 0.5 | J37: 0.75 | K37: 1 | L37: 1 | M37: 1 | N37: 1 | O37: 1.25 | P37: 1.5
C38: Product Creation: | F38: # FTEs | G38: 0 | H38: 0 | I38: 0.5 | J38: 0.5 | K38: 1 | L38: 1 | M38: 1 | N38: 2 | O38: 2 | P38: 2
C39: Content Creation: | F39: # FTEs | G39: 0 | H39: 0 | I39: 0.5 | J39: 0.5 | K39: 0.5 | L39: 0.5 | M39: 0.75 | N39: 0.75 | O39: 1 | P39: 1
C40: Total FTEs: | G40: =SUM(G34:G39) | H40: =SUM(H34:H39) | I40: =SUM(I34:I39) | J40: =SUM(J34:J39) | K40: =SUM(K34:K39) | L40: =SUM(L34:L39) | M40: =SUM(M34:M39) | N40: =SUM(N34:N39) | ... P40: =SUM(P34:P39)
C42: Average Expense per FTE:
C43: =+C34 | F43: $ / FTE | G43: =IFERROR(-G103/G34,"N/A") | H43: =IFERROR(-H103/H34,"N/A") | I43: =IFERROR(-I103/I34,"N/A") | J43: =IFERROR(-J103/J34,"N/A") | K43: =IFERROR(-K103/K34,"N/A") | L43: =+K43*(1+L$50) | M43: =+L43*(1+M$50) | N43: =+M43*(1+N$50) | O43: =+N43*(1+O$50) | P43: =+O43*(1+P$50)
C44: =+C35 | F44: $ / FTE | G44: =IFERROR(-G105/G35,"N/A") | H44: =IFERROR(-H105/H35,"N/A") | I44: =IFERROR(-I105/I35,"N/A") | J44: =IFERROR(-J105/J35,"N/A") | K44: =IFERROR(-K105/K35,"N/A") | L44: =+K44*(1+L$50) | M44: =+L44*(1+M$50) | N44: =+M44*(1+N$50) | O44: =+N44*(1+O$50) | P44: =+O44*(1+P$50)
C45: =+C36 | F45: $ / FTE | G45: =IFERROR(-G106/G36,"N/A") | H45: =IFERROR(-H106/H36,"N/A") | I45: =IFERROR(-I106/I36,"N/A") | J45: =IFERROR(-J106/J36,"N/A") | K45: =IFERROR(-K106/K36,"N/A") | L45: =+K45*(1+L$50) | M45: =+L45*(1+M$50) | N45: =+M45*(1+N$50) | O45: =+N45*(1+O$50) | P45: =+O45*(1+P$50)
C46: =+C37 | F46: $ / FTE | G46: =IFERROR(-G107/G37,"N/A") | H46: =IFERROR(-H107/H37,"N/A") | I46: =IFERROR(-I107/I37,"N/A") | J46: =IFERROR(-J107/J37,"N/A") | K46: =IFERROR(-K107/K37,"N/A") | L46: =+K46*(1+L$50) | M46: =+L46*(1+M$50) | N46: =+M46*(1+N$50) | O46: =+N46*(1+O$50) | P46: =+O46*(1+P$50)
C47: =+C38 | F47: $ / FTE | G47: =IFERROR(-G111/G38,"N/A") | H47: =IFERROR(-H111/H38,"N/A") | I47: =IFERROR(-I111/I38,"N/A") | J47: =IFERROR(-J111/J38,"N/A") | K47: =IFERROR(-K111/K38,"N/A") | L47: =+K47*(1+L$50) | M47: =+L47*(1+M$50) | N47: =+M47*(1+N$50) | O47: =+N47*(1+O$50) | P47: =+O47*(1+P$50)
C48: =+C39 | F48: $ / FTE | G48: =IFERROR(-G112/G39,"N/A") | H48: =IFERROR(-H112/H39,"N/A") | I48: =IFERROR(-I112/I39,"N/A") | J48: =IFERROR(-J112/J39,"N/A") | K48: =IFERROR(-K112/K39,"N/A") | L48: =+K48*(1+L$50) | M48: =+L48*(1+M$50) | N48: =+M48*(1+N$50) | O48: =+N48*(1+O$50) | P48: =+O48*(1+P$50)
C50: Salary Growth Rate: | F50: % | L50: 0.04 | M50: 0.04 | N50: 0.04 | O50: 0.04 | P50: 0.04
G52: =+$G$5 | L52: =+$L$5
...

Sheet Company0462-GAAP
B2: ="Sample Private Company Financial Statements - "&Company_Name&" - U.S. GAAP / IFRS-Compliant"
B3: ($ USD as Stated)
B5: Assumptions:
C7: Potential Buyer's Tax Rate: | F7: 0.35
C8: Company Name: | F8: Capital Capable Media LLC
C10: Private Company Discount: | F10: 0.3
G12: Historical | L12: Projected
B13: Income Statement: | F13: Units: | G13: Year 1 | H13: Year 2 | I13: Year 3 | J13: Year 4 | K13: Year 5 | L13: Year 6 | M13: Year 7 | N13: Year 8 | O13: Year 9 | P13: Year 10
C15: Gross Sales: | F15: $
C16: (-) Allowances & Refunds: | F16: $
C17: Net Sales: | F17: $
C19: Operating Expenses:
C20: (+) General & Administrative: | F20: $
C21: (+) Sales & Marketing: | F21: $
C22: (+) Research & Development: | F22: $
C23: (+) Depreciation & Amortization: | F23: $
C24: Total Operating Expenses: | F24: $
C26: Operating Income: | F26: $
C27: (+) Net Interest Income / (-) Expense: | F27: $
C28: Pre-Tax Income: | F28: $
C30: Income Taxes: | F30: $
C32: Net Income: | F32: $
G34: =+$G$12 | L34: =+$L$12
B35: Key Metrics and Ratios: | F35: =+$F$13 | G35: =+$G$13 | H35: =+$H$13 | I35: =+$I$13 | J35: =+$J$13 | K35: =+$K$13 | L35: =+$L$13 | M35: =+$M$13 | N35: =+$N$13 | O35: =+$O$13 | P35: =+$P$13
C37: (+) Operating Income: | F37: $
C38: (+) Depreciation & Amortization: | F38: $
C39: EBITDA: | F39: $
C41: Revenue Growth: | F41: %
C42: Operating Margin: | F42: %
C43: EBITDA Margin: | F43: %
C44: Net Margin: | F44: %
C46: Effective Tax Rate: | F46: %
G48: =+$G$12 | L48: =+$L$12
B49: Balance Sheet: | F49: =+$F$13 | G49: =+$G$13 | H49: =+$H$13 | I49: =+$I$13 | J49: =+$J$13 | K49: =+$K$13 | L49: =+$L$13 | M49: =+$M$13 | N49: =+$N$13 | O49: =+$O$13 | P49: =+$P$13
B50: ASSETS:
C51: Current Assets:
C52: Cash & Cash Equivalents: | F52: $
C53: Accounts Receivable: | F53: $
C54: Total Current Assets: | F54: $
C56: Long-Term Assets:
...

Sheet DCF
B2: ="Private Company DCF Analysis - "&Company_Name
B3: ($ USD as Stated)
B5: ="DCF Assumptions - "&Company_Name&":"
B7: Financial Assumptions for DCF: | G7: Operating Assumptions for Extended Projection Period:
B9: Discount Rate: | E9: =+WACC | G9: Annual Change in Revenue Growth: | J9: -0.02
G10: Minimum Revenue Growth: | J10: 0.04
B11: "Going Concern" Discount to Terminal Value: | E11: 0.25
G12: Annual Change in EBIT Margin: | J12: -0.005
B13: Discount to Liquidation Value Terminal Value: | E13: 0 | G13: Minimum EBIT Margin: | J13: 0.15
G15: Depreciation & Amortization % Revenue: | J15: 0.005
G16: CapEx % Revenue: | J16: 0.01
G17: Change in WC % Change in Revenue: | J17: 0.03
B19: Terminal Value - Multiples Method: | G19: Terminal Value - Perpetuity Growth Method: | L19: Terminal Value - Liquidation Value Method: | Q19: Terminal Value - "Cease Operations" Method:
B21: Baseline Terminal EBITDA Multiple: | E21: 5.6970458 | G21: Baseline Terminal FCF Growth Rate: | J21: 0.03 | L21: Final Projection Year Liquidation Value: | Q21: FCF Growth / (Decline) Rate: | T21: -0.1
B22: Baseline Terminal Value: | G22: Baseline Terminal Value: | L22: Cumulative FCF Beyond Final Year:
B23: Terminal Value After "Going Concern" Discount: | G23: Terminal Value After "Going Concern" Discount: | L23: Terminal Value Based on Asset Liquidation:
B24: Implied Terminal FCF Growth Rate: | G24: Implied Terminal EBITDA Multiple: | L24: Terminal Value After Discount:
B26: (+) PV of Terminal Value: | G26: =+$B$26 | L26: =+$B$26 | Q26: =+$B$26
B27: (+) Sum of PV of Free Cash Flows: | G27: =+$B$27 | L27: =+$B$27 | Q27: =+$B$27
B28: Implied Enterprise Value: | E28: =SUM(E26:E27) | G28: =+$B$28 | L28: =+$B$28 | Q28: =+$B$28
B30: % of Implied EV from Terminal Value: | G30: =+$B$30 | L30: =+$B$30 | Q30: =+$B$30
B32: (+) Cash & Cash-Equivalents: | G32: =+$B$32 | L32: =+$B$32 | Q32: =+$B$32
B33: (+) Equity Investments: | G33: =+$B$33 | L33: =+$B$33 | Q33: =+$B$33
B34: (+) Other Non-Core Assets, Net: | G34: =+$B$34 | L34: =+$B$34 | Q34: =+$B$34
B35: (-) Total Debt: | G35: =+$B$35 | L35: =+$B$35 | Q35: =+$B$35
B36: (-) Noncontrolling Interests: | G36: =+$B$36 | L36: =+$B$36 | Q36: =+$B$36
B37: Implied Equity Value: | G37: =+$B$37 | L37: =+$B$37 | Q37: =+$B$37
C39: Unlevered Free Cash Flow Projections:
B40: FCF Projections: | C40: =+'Company0462-GAAP'!L13 | D40: =+'Company0462-GAAP'!M13 | E40: =+'Company0462-GAAP'!N13 | F40: =+'Company0462-GAAP'!O13 | G40: =+'Company0462-GAAP'!P13 | H40: Year 11 | I40: Year 12 | J40: Year 13 | K40: Year 14 | L40: Year 15 | M40: Year 16 | N40: Year 17 | O40: Year 18 | P40: Year 19 | Q40: Year 20 | R40: Year 21 | S40: Year 22 | T40: Year 23 | U40: Year 24 | V40: Year 25
B42: Revenue:
B43: Growth Rate:
B45: Operating Income (EBIT):
B46: Operating Margin:
B48: (-) Taxes:
B50: NOPAT:
B52: (+) Depreciation & Amortization:
B53: (+/-) Change in WC:
B54: (-) CapEx:
B56: Unlevered FCF:
B57: Growth Rate:
...

Sheet WACC
B2: ="Private Company WACC Analysis - "&Company_Name
B3: =+'Company0462-GAAP'!$B$3
B5: Discount Rate Calculations - Assumptions
B6: Risk-Free Rate: | F6: 0.0205
B7: Equity Risk Premium: | F7: 0.07
B8: Pre-Tax Cost of Debt: | F8: =+Risk_Free_Rate+0.4%
B9: Cost of Preferred Stock: | F9: 0
B10: Market Correlation (R^2) for Education Companies: | F10: 0.1988
B11: Adjustment for Portfolio Diversification of Potential Buyer: | F11: 0.25
B13: Comparable Companies - Unlevered Beta Calculation
D14: Levered | G14: Preferred | I14: Equity | L14: Unlevered
B15: Name | C15: Ticker | D15: Beta | E15: Debt | F15: % Debt | G15: Stock | H15: % Preferred | I15: Value | J15: % Equity | K15: Tax Rate | L15: Beta
B16: =+'Public Comps'!B8 | C16: =+'Public Comps'!C8 | K16: 0.4
B17: =+'Public Comps'!B9 | C17: =+'Public Comps'!C9 | K17: 0.4
B18: =+'Public Comps'!B10 | C18: =+'Public Comps'!C10 | K18: 0.4
B19: =+'Public Comps'!B11 | C19: =+'Public Comps'!C11 | K19: 0.4
B20: =+'Public Comps'!B12 | C20: =+'Public Comps'!C12 | K20: 0.4
B21: =+'Public Comps'!B13 | C21: =+'Public Comps'!C13 | K21: 0.4
B23: Median:
B24: Median "Total" Unlevered Beta:
B26: =TEXT(Company_Name,"")&" - Levered Beta & WACC Calculation"
D27: Unlevered | G27: Preferred | I27: Equity | L27: Levered
C28: Ticker | D28: Beta | E28: Debt | F28: % Debt | G28: Stock | H28: % Preferred | I28: Value | J28: % Equity | K28: Tax Rate | L28: Beta
B29: "Optimal" Capital Structure: | C29: N/A
B31: Cost of Equity Based on Comparables and "Optimal" Capital Structure:
B35: WACC, "Optimal" Capital Structure:

Sheet Public Comps
B2: Comparable Public Companies - U.S.-Based, For-Profit Education Companies with Less Than $500 Million USD in LTM Revenue
B3: ($ USD in Millions Except Per Share Amounts in USD as Stated)
B5: Operating Statistics | E5: Capitalization
D6: Share | E6: Equity | G6: Preferred | H6: Enterprise | I6: Revenue | L6: EBITDA | O6: EBITDA Margin | R6: Net Income
B7: Company Name | C7: Ticker | D7: Price | E7: Value | F7: Debt | G7: Stock | H7: Value | I7: LTM | J7: Forward Year 1 | K7: Forward Year 2 | L7: =+$I$7 | M7: =+$J$7 | N7: =+$K$7 | O7: =+$I$7 | P7: =+$J$7 | Q7: =+$K$7 | R7: =+$I$7 | S7: =+$J$7 | T7: =+$K$7 | U7: Beta
B8: Nord Anglia Education Inc | C8: NYSE:Company1891 | D8: 19.69 | E8: 1924.6975 | F8: 522.4 | G8: 0 | H8: 2280.3975 | I8: 474.6 | J8: 542.5 | K8: 616.1 | L8: 127.4 | M8: 143.6 | N8: 169.6 | R8: 26.3925 | S8: 61.5825 | T8: 78.2 | U8: 0.32
B9: Company2600 Education Inc | C9: NASDAQ:Company2494 | D9: 62.14 | E9: 671.112 | F9: 118.75 | G9: 0 | H9: 627.582 | I9: 446.041 | J9: 431.62 | K9: 443.6 | L9: 102.377 | M9: 95.6 | N9: 104.3 | R9: 46.36 | S9: 36.828 | T9: 41.472 | U9: 1.55
B10: Capella Education Company | C10: NASDAQ:Company0593 | D10: 65.4 | E10: 800.496 | F10: 0 | G10: 0 | H10: 633.444 | I10: 421.967 | J10: 440.8 | K10: 463.93 | L10: 90.583 | M10: 95 | N10: 99.1 | R10: 37.943 | S10: 42.228 | T10: 46.512 | U10: 1.11
B11: American Public Education, Inc. | C11: NASDAQ:Company0117 | D11: 34.48 | E11: 595.1248 | F11: 0 | G11: 0 | H11: 474.2958 | I11: 348.72 | J11: 368.86 | K11: 385.2 | L11: 74.1 | M11: 75.3 | N11: 80.1 | R11: 37.7994 | S11: 40.9062 | T11: 43.4952 | U11: 1.15
B12: Lincoln Educational Services Corp | C12: NASDAQ:Company1557 | D12: 2.2 | E12: 52.91 | F12: 43.904 | G12: 0 | H12: 77.802 | I12: 330.249 | J12: 320 | K12: 339.06 | L12: -34.301 | M12: -45 | N12: -15.6 | R12: -75.39 | S12: -18.759 | T12: -3.367 | U12: 2.11
B13: National American University Holdings Inc | C13: NASDAQ:Company1849 | D13: 3.26 | E13: 82.0868 | F13: 12.303 | G13: 0 | H13: 74.6548 | I13: 127.753 | J13: 119.63 | K13: 124.21 | L13: 12.723 | M13: 11.1 | N13: 15.2 | R13: 3.468 | S13: 6.0432 | T13: 6.7986 | U13: 1.25
B15: Maximum
B16: 75th Percentile
B17: Median
B18: 25th Percentile
B19: Minimum
B21: Valuation Statistics | E21: Capitalization | I21: Enterprise Value / | L21: Enterprise Value /
D22: =+$D$6 | E22: =+$E$6 | G22: =+$G$6 | H22: =+$H$6 | I22: Revenue | L22: EBITDA | O22: Price / Earnings Multiple
B23: =+$B$7 | C23: =+$C$7 | D23: =+$D$7 | E23: =+$E$7 | F23: =+$F$7 | G23: =+$G$7 | H23: =+$H$7 | I23: =+$I$7 | J23: =+$J$7 | K23: =+$K$7 | L23: =+$I$7 | M23: =+$J$7 | N23: =+$K$7 | O23: =+$I$7 | P23: =+$J$7 | Q23: =+$K$7
B24: =+B8 | C24: =+C8
B25: =+B9 | C25: =+C9
B26: =+B10 | C26: =+C10
B27: =+B11 | C27: =+C11
B28: =+B12 | C28: =+C12
B29: =+B13 | C29: =+C13
B31: Maximum
B32: 75th Percentile
B33: Median
B34: 25th Percentile
B35: Minimum

Sheet ValSum
B2: ="Valuation Summary - "&Company_Name
B3: =+'Company0462-GAAP'!$B$3
B5: ="Valuation Statistics - "&TEXT(Company_Name,"") | C5: =TEXT(Company_Name,"")&" - Range of Valuation Multiples" | J5: =TEXT(Company_Name,"")&" - Range of Implied Equity Values"
D7: 75th | F7: 25th | H7: Applicable | I7: Private | K7: 25th | M7: 75th
C8: Maximum | D8: Percentile | E8: Median | F8: Percentile | G8: Minimum | H8: Company | I8: Company | J8: Minimum | K8: Percentile | L8: Median | M8: Percentile | N8: Maximum
B9: Methodology Name | C9: Multiple | D9: Multiple | E9: Multiple | F9: Multiple | G9: Multiple | H9: Figure | I9: Discount | J9: Multiple | K9: Multiple | L9: Multiple | M9: Multiple | N9: Multiple
B11: Public Company Comparables:
B12: LTM EV / Revenue:
B13: =TEXT('Public Comps'!$J$7,"yyyy-mm-dd")&" EV / Revenue:"
B14: =TEXT('Public Comps'!$K$7,"yyyy-mm-dd")&" EV / Revenue:"
B15: LTM EV / EBITDA:
B16: =TEXT('Public Comps'!$J$7,"yyyy-mm-dd")&" EV / EBITDA:"
B17: =TEXT('Public Comps'!$K$7,"yyyy-mm-dd")&" EV / EBITDA:"
B18: LTM Price / Earnings:
B19: =TEXT('Public Comps'!$J$7,"yyyy-mm-dd")&" Price / Earnings:"
B20: =TEXT('Public Comps'!$K$7,"yyyy-mm-dd")&" Price / Earnings:"
B22: Precedent Transactions:
B23: LTM EV / Revenue: | C23: 2.5 | D23: 1.7 | E23: 1.5 | F23: 1.4 | G23: 0.9
B24: LTM EV / EBITDA: | C24: 13.5 | D24: 12.1 | E24: 11.1 | F24: 10.1 | G24: 8
B26: Discounted Cash Flow Analysis:
B27: 13.5% - 15.5% Discount Rate, 2.0% - 4.0% Terminal FCF Growth Rate:
H29: Implied Enterprise Value or Equity Value at a Range of Multiples:
G31: Enterprise Value -->
G32: Enterprise Value -->
G33: Enterprise Value -->
G34: Enterprise Value -->
G35: Enterprise Value -->
G36: Enterprise Value -->
G38: Equity Value -->
G39: Equity Value -->
G40: Equity Value -->
G41: Equity Value -->
G42: Equity Value -->
G43: Equity Value -->
... G52: Equity Value -->

Sheet ValGraph
I25: Min | J25: 25th | K25: Median | L25: 75th | M25: Max | N25: Min Point | O25: 25th Point | P25: Median Point | Q25: 75th Point | R25: Max Point
B27: =+ValSum!B27
B29: =+ValSum!B24
B30: =+ValSum!B23
B32: =+ValSum!B20
B33: =+ValSum!B19
B34: =+ValSum!B18
B35: =+ValSum!B17
B36: =+ValSum!B16
B37: =+ValSum!B15
B38: =+ValSum!B14
B39: =+ValSum!B13
B40: =+ValSum!B12
