Workbook
Name AP: WORKCAP!$C$31:$G$31
Name AP_CHANGE: WORKCAP!$C$32:$G$32
Name AR: WORKCAP!$C$12:$G$12
Name AR_CHANGE: WORKCAP!$C$13:$G$13
Name ARdata: WORKCAP!$A$67:$G$78
Name ARMonths: WORKCAP!$A$67:$A$78
Name CAP_EXPEND: 'PROP & EQUIP'!$C$13:$G$13
Name Cash_Begin: #REF!
Name Cash_Begin: 'CASHFLOW-MOS'!#REF!
Name DEPRECIATION: 'PROP & EQUIP'!$C$34:$G$34
Name EARNINGS_BEFORE_INTEREST___TAXES: 'CASHFLOW-MOS'!#REF!
Name EARNINGS_BEFORE_INTEREST___TAXES: 'INCOME-MOS'!$B$27
Name EXTR_INC_EXCL_INT_INCOME: EXTRA!$C$21:$G$21
Name FUNDINGf14: #REF!
Name INC_TAX_CHANGE: WORKCAP!$C$38:$G$38
Name INC_TAX_LIAB: WORKCAP!$C$37:$G$37
Name INC_TAX_RATE: TAXES!$C$9:$G$9
Name INV: WORKCAP!$C$19:$G$19
Name INV_CHANGE: WORKCAP!$C$20:$G$20
Name investment: 'VAL-2'!$B$8
Name Name: REVENUE!$A$1
Name Name: REVENUE!$A$1
Name NET_EARNINGS: 'INCOME-MOS'!$B$35
Name NET_PL_EQUIP: 'PROP & EQUIP'!$C$53:$G$53
Name OTHER_CA: WORKCAP!$C$25:$G$25
Name OTHER_CA_CHANGE: WORKCAP!$C$26:$G$26
Name PE: 'VAL-2'!$B$7
Name Rate: 'VAL-2'!$B$6
Name TAXES: 'INCOME-MOS'!$B$33
Name TOT_EXTR_INC_EXP: EXTRA!$C$16:$G$16
Name TOTAL_COG: WORKCAP!$C$28:$G$28
Name WORK_CAP_CHANGE: WORKCAP!$C$40:$G$40

Sheet COMPS
A1: XYZ Company
A2: Peer Company Comparisons
E5: Select Best
B6: Company A | C6: Company B | D6: Company C | E6: Comparison | F6: Projections
A7: Ratios | F7: Year 1 | G7: Year 2 | H7: Year 3 | I7: Year 4 | J7: Year 5
A8: Accounts Receivable % of Rev | B8: 0.098 | C8: 0.074 | D8: 0.116 | E8: 0.1 | F8: =WORKCAP!C10 -> 0.083 | G8: =WORKCAP!D10 -> 0.083 | H8: =WORKCAP!E10 -> 0.083 | I8: =WORKCAP!F10 -> 0.083 | J8: =WORKCAP!G10 -> 0.083
A9: Inventory % of Rev | B9: 0.135 | C9: 0.112 | D9: 0.169 | E9: 0.15 | F9: =WORKCAP!C16 -> 0.083 | G9: =WORKCAP!D16 -> 0.083 | H9: =WORKCAP!E16 -> 0.067 | I9: =WORKCAP!F16 -> 0.067 | J9: =WORKCAP!G16 -> 0.067
A10: Accounts Payable % of Rev | B10: 0.079 | C10: 0.086 | D10: 0.094 | E10: 0.08 | F10: =WORKCAP!C29 -> 0.087 | G10: =WORKCAP!D29 -> 0.087 | H10: =WORKCAP!E29 -> 0.087 | I10: =WORKCAP!F29 -> 0.087 | J10: =WORKCAP!G29 -> 0.087
A11: Working Capital % of Rev | B11: 0.154 | C11: 0.123 | D11: 0.187 | E11: 0.16 | F11: =WORKCAP!C10+WORKCAP!C16+WORKCAP!C23-WORKCAP!C29-WORKCAP!C35 -> 0.079 | G11: =WORKCAP!D10+WORKCAP!D16+WORKCAP!D23-WORKCAP!D29-WORKCAP!D35 -> 0.079 | H11: =WORKCAP!E10+WORKCAP!E16+WORKCAP!E23-WORKCAP!E29-WORKCAP!E35 -> 0.063 | I11: =WORKCAP!F10+WORKCAP!F16+WORKCAP!F23-WORKCAP!F29-WORKCAP!F35 -> 0.063 | J11: =WORKCAP!G10+WORKCAP!G16+WORKCAP!G23-WORKCAP!G29-WORKCAP!G35 -> 0.063
A12: Net Fixed Assets % of Rev | B12: 0.087 | C12: 0.095 | D12: 0.108 | E12: 0.09 | F12: ='PROP & EQUIP'!C54 -> 0.088862338 | G12: ='PROP & EQUIP'!D54 -> 0.15725818 | H12: ='PROP & EQUIP'!E54 -> 0.15396402 | I12: ='PROP & EQUIP'!F54 -> 0.14838025 | J12: ='PROP & EQUIP'!G54 -> 0.11863822
A13: Current Ratio | B13: 2.1 | C13: 3.2 | D13: 1.9 | E13: 2.3 | F13: =BALANCE!C13/BALANCE!C23 -> 3.8692769 | G13: =BALANCE!D13/BALANCE!D23 -> 4.0806633 | H13: =BALANCE!E13/BALANCE!E23 -> 2.6366848 | I13: =BALANCE!F13/BALANCE!F23 -> 3.8422343 | J13: =BALANCE!G13/BALANCE!G23 -> 4.0882108
A14: Debt to Capital (LT Debt + Equity) | B14: 1.25 | C14: 1.08 | D14: 1.36 | E14: 1.2 | F14: =(BALANCE!C22+BALANCE!C25)/(BALANCE!C22+BALANCE!C25+BALANCE!C31) -> 0.67143449 | G14: =(BALANCE!D22+BALANCE!D25)/(BALANCE!D22+BALANCE!D25+BALANCE!D31) -> 0.57204498 | H14: =(BALANCE!E22+BALANCE!E25)/(BALANCE!E22+BALANCE!E25+BALANCE!E31) -> 0.50297904 | I14: =(BALANCE!F22+BALANCE!F25)/(BALANCE!F22+BALANCE!F25+BALANCE!F31) -> 0.33323967 | J14: =(BALANCE!G22+BALANCE!G25)/(BALANCE!G22+BALANCE!G25+BALANCE!G31) -> 0.20151079
A16: Profitability
A17: Gross Profit % of Rev | B17: 0.317 | C17: 0.462 | D17: 0.541 | E17: 0.3 | F17: =INCOME!C13 -> 0.51798961 | G17: =INCOME!D13 -> 0.50104167 | H17: =INCOME!E13 -> 0.58064101 | I17: =INCOME!F13 -> 0.61641626 | J17: =INCOME!G13 -> 0.66470002
A18: Sales & Marketing % of Rev | B18: 0.294 | C18: 0.246 | D18: 0.213 | E18: 0.294 | F18: ='OPER EXP'!C17 -> 0.23981818 | G18: ='OPER EXP'!D17 -> 0.21598958 | H18: ='OPER EXP'!E17 -> 0.18700417 | I18: ='OPER EXP'!F17 -> 0.17463054 | J18: ='OPER EXP'!G17 -> 0.15778878
A19: Research & Development % of Rev | B19: 0.281 | C19: 0.148 | D19: 0.112 | E19: 0.281 | F19: ='OPER EXP'!C26 -> 0.10454545 | G19: ='OPER EXP'!D26 -> 0.14621094 | H19: ='OPER EXP'!E26 -> 0.12905922 | I19: ='OPER EXP'!F26 -> 0.11933498 | J19: ='OPER EXP'!G26 -> 0.10023102
A20: General & Administration % of Rev | B20: 0.307 | C20: 0.195 | D20: 0.146 | E20: 0.3 | F20: ='OPER EXP'!C39 -> 0.22545455 | G20: ='OPER EXP'!D39 -> 0.22641927 | H20: ='OPER EXP'!E39 -> 0.17651209 | I20: ='OPER EXP'!F39 -> 0.16178161 | J20: ='OPER EXP'!G39 -> 0.13134213
A21: Operating Expenses % of Rev | B21: 0.405 | C21: 0.342 | D21: 0.316 | E21: 0.17 | F21: ='OPER EXP'!C42 -> 0.56981818 | G21: ='OPER EXP'!D42 -> 0.58861979 | H21: ='OPER EXP'!E42 -> 0.49257548 | I21: ='OPER EXP'!F42 -> 0.45574713 | J21: ='OPER EXP'!G42 -> 0.38936194
A22: Earnings from Operations % of Rev | B22: 0.112 | C22: 0.161 | D22: 0.225 | E22: 0.12 | F22: =INCOME!C22/INCOME!C7 -> -0.051828571 | G22: =INCOME!D22/INCOME!D7 -> -0.087578125 | H22: =INCOME!E22/INCOME!E7 -> 0.088065531 | I22: =INCOME!F22/INCOME!F7 -> 0.16066913 | J22: =INCOME!G22/INCOME!G7 -> 0.27533809
A23: EBIT % of Rev | B23: 0.112 | C23: 0.161 | D23: 0.225 | E23: 0.12 | F23: =INCOME!C26/INCOME!C7 -> -0.095464935 | G23: =INCOME!D26/INCOME!D7 -> -0.057630208 | H23: =INCOME!E26/INCOME!E7 -> 0.11809055 | I23: =INCOME!F26/INCOME!F7 -> 0.19268883 | J23: =INCOME!G26/INCOME!G7 -> 0.30256581
A24: Depreciation % of Rev | B24: 0.028 | C24: 0.037 | D24: 0.049 | E24: 0.03 | F24: ='PROP & EQUIP'!C48 -> 0.01641039 | G24: ='PROP & EQUIP'!D48 -> 0.034765625 | H24: ='PROP & EQUIP'!E48 -> 0.041844394 | I24: ='PROP & EQUIP'!F48 -> 0.047188013 | J24: ='PROP & EQUIP'!G48 -> 0.042652837
A25: EBITDA % of Rev | B25: 0.14 | C25: 0.198 | D25: 0.274 | E25: 0.14 | F25: =(INCOME!C26+'PROP & EQUIP'!C47)/INCOME!C7 -> -0.079054545 | G25: =(INCOME!D26+'PROP & EQUIP'!D47)/INCOME!D7 -> -0.022864583 | H25: =(INCOME!E26+'PROP & EQUIP'!E47)/INCOME!E7 -> 0.15993495 | I25: =(INCOME!F26+'PROP & EQUIP'!F47)/INCOME!F7 -> 0.23987685 | J25: =(INCOME!G26+'PROP & EQUIP'!G47)/INCOME!G7 -> 0.34521865
A26: Net Earnings % of Rev | B26: 0.051 | C26: 0.096 | D26: 0.143 | E26: 0.05 | F26: =INCOME!C35 -> -0.17331948 | G26: =INCOME!D35 -> -0.10848958 | H26: =INCOME!E35 -> 0.081460026 | I26: =INCOME!F35 -> 0.12639536 | J26: =INCOME!G35 -> 0.17722265
A28: Returns
A29: Return on Assets | B29: 0.115 | C29: 0.158 | D29: 0.179 | E29: 0.12 | F29: =INCOME!C34/BALANCE!C15 -> -0.11010034 | G29: =INCOME!D34/BALANCE!D15 -> -0.089126571 | H29: =INCOME!E34/BALANCE!E15 -> 0.09116777 | I29: =INCOME!F34/BALANCE!F15 -> 0.1750194 | J29: =INCOME!G34/BALANCE!G15 -> 0.27986049
A30: Return on Equity | B30: 0.144 | C30: 0.196 | D30: 0.247 | E30: 0.15 | F30: =INCOME!C34/BALANCE!C31 -> -0.3896025 | G30: =INCOME!D34/BALANCE!D31 -> -0.23447023 | H30: =INCOME!E34/BALANCE!E31 -> 0.23533668 | I30: =INCOME!F34/BALANCE!F31 -> 0.29736167 | J30: =INCOME!G34/BALANCE!G31 -> 0.40152939
A31: Return on Capital (LT Debt + Equity) | B31: 0.148 | C31: 0.183 | D31: 0.219 | E31: 0.15 | F31: =INCOME!C34/(BALANCE!C22+BALANCE!C25+BALANCE!C31) -> -0.12800994 | G31: =INCOME!D34/(BALANCE!D22+BALANCE!D25+BALANCE!D31) -> -0.10034271 | H31: =INCOME!E34/(BALANCE!E22+BALANCE!E25+BALANCE!E31) -> 0.11696726 | I31: =INCOME!F34/(BALANCE!F22+BALANCE!F25+BALANCE!F31) -> 0.19826896 | J31: =INCOME!G34/(BALANCE!G22+BALANCE!G25+BALANCE!G31) -> 0.32061689
A33: Growth
A34: Revenue Growth Rate - CAGR: | B34: 0.142 | C34: 0.195 | D34: 0.248 | E34: 0.15 | G34: =INCOME!D7/INCOME!C7-1 -> 0.39636364 | H34: =INCOME!E7/INCOME!D7-1 -> 0.56119792 | I34: =INCOME!F7/INCOME!E7-1 -> 0.35446205 | J34: =(INCOME!G7/INCOME!F7-1) -> 0.49261084
A35: Net Earnings Growth Rate - CAGR: | B35: 0.116 | C35: 0.179 | D35: 0.215 | E35: 0.12 | G35: =IF((INCOME!D34/INCOME!C34-1)>0,(INCOME!D34/INCOME!C34-1),"Negative") -> Negative | H35: =IF((INCOME!E34/INCOME!D34-1)>0,(INCOME!E34/INCOME!D34-1),"Negative") -> Negative | I35: =IF((INCOME!F34/INCOME!E34-1)>0,(INCOME!F34/INCOME!E34-1),"Negative") -> 1.1016162 | J35: =IF((INCOME!G34/INCOME!F34-1)>0,(INCOME!G34/INCOME!F34-1),"Negative") -> 1.0928337

Sheet REVENUE
A1: XYZ Company | M1: checksum | N1: =SUM(C16:G16,C38:G38,C41:G42,'COST OF REV'!C32:G33,'COST OF REV'!C38:G38,'COST OF REV'!C59:G59,'OPER EXP'!C16:G17,'OPER EXP'!C25:G26,'OPER EXP'!C38:G39,'OPER EXP'!C41:G42,'OPER EXP'!C47:G47,'OPER EXP'!C69:G69,'OPER EXP'!C91:G91,'OPER EXP'!C113:G113) -> 1.7619413e+08
A2: Revenue Projections
A3: Years 1 to 5
A4: ($)
C5: Year 1 | D5: Year 2 | E5: Year 3 | F5: Year 4 | G5: Year 5
A6: Product A
A7: Number of Units | C7: 9000 | D7: 12000 | E7: 17000 | F7: 22000 | G7: 30000
A8: Price per unit | C8: 250 | D8: 250 | E8: 275 | F8: 275 | G8: 300
A9: Total | C9: =C7*C8 -> 2250000 | D9: =D7*D8 -> 3000000 | E9: =E7*E8 -> 4675000 | F9: =F7*F8 -> 6050000 | G9: =G7*G8 -> 9000000
A10: Service B
A11: Number of Customers | C11: 500 | D11: 800 | E11: 1200 | F11: 1800 | G11: 2600
A12: Fee per Customer | C12: 1000 | D12: 1050 | E12: 1100 | F12: 1150 | G12: 1200
A13: Total | C13: =C11*C12 -> 500000 | D13: =D11*D12 -> 840000 | E13: =E11*E12 -> 1320000 | F13: =F11*F12 -> 2070000 | G13: =G11*G12 -> 3120000
A16: Net Revenue | C16: =C9+C13 -> 2750000 | D16: =D9+D13 -> 3840000 | E16: =E9+E13 -> 5995000 | F16: =F9+F13 -> 8120000 | G16: =G9+G13 -> 12120000
D19: Revenues by Months & Quarters
D20: ($)
A21: Months | C21: Year 1 | D21: Year 2 | E21: Year 3 | F21: Year 4 | G21: Year 5
A22: Month 1 | C22: 0 | D22: =D$16/12 -> 320000 | E22: =E$16/12 -> 499583.33 | F22: =F$16/12 -> 676666.67 | G22: =G$16/12 -> 1010000
A23: Month 2 | C23: 0 | D23: =D$16/12 -> 320000 | E23: =E$16/12 -> 499583.33 | F23: =F$16/12 -> 676666.67 | G23: =G$16/12 -> 1010000
A24: Month 3 | C24: 0 | D24: =D$16/12 -> 320000 | E24: =E$16/12 -> 499583.33 | F24: =F$16/12 -> 676666.67 | G24: =G$16/12 -> 1010000
A25: Total 1st Quarter | C25: =SUM(C22:C24) -> 0 | D25: =SUM(D22:D24) -> 960000 | E25: =SUM(E22:E24) -> 1498750 | F25: =SUM(F22:F24) -> 2030000 | G25: =SUM(G22:G24) -> 3030000
A26: Month 4 | C26: =C$16/9 -> 305555.56 | D26: =D$16/12 -> 320000 | E26: =E$16/12 -> 499583.33 | F26: =F$16/12 -> 676666.67 | G26: =G$16/12 -> 1010000
A27: Month 5 | C27: =C$16/9 -> 305555.56 | D27: =D$16/12 -> 320000 | E27: =E$16/12 -> 499583.33 | F27: =F$16/12 -> 676666.67 | G27: =G$16/12 -> 1010000
A28: Month 6 | C28: =C$16/9 -> 305555.56 | D28: =D$16/12 -> 320000 | E28: =E$16/12 -> 499583.33 | F28: =F$16/12 -> 676666.67 | G28: =G$16/12 -> 1010000
A29: Total 2nd Quarter | C29: =SUM(C26:C28) -> 916666.67 | D29: =SUM(D26:D28) -> 960000 | E29: =SUM(E26:E28) -> 1498750 | F29: =SUM(F26:F28) -> 2030000 | G29: =SUM(G26:G28) -> 3030000
A30: Month 7 | C30: =C$16/9 -> 305555.56 | D30: =D$16/12 -> 320000 | E30: =E$16/12 -> 499583.33 | F30: =F$16/12 -> 676666.67 | G30: =G$16/12 -> 1010000
A31: Month 8 | C31: =C$16/9 -> 305555.56 | D31: =D$16/12 -> 320000 | E31: =E$16/12 -> 499583.33 | F31: =F$16/12 -> 676666.67 | G31: =G$16/12 -> 1010000
A32: Month 9 | C32: =C$16/9 -> 305555.56 | D32: =D$16/12 -> 320000 | E32: =E$16/12 -> 499583.33 | F32: =F$16/12 -> 676666.67 | G32: =G$16/12 -> 1010000
A33: Total 3rd Quarter | C33: =SUM(C30:C32) -> 916666.67 | D33: =SUM(D30:D32) -> 960000 | E33: =SUM(E30:E32) -> 1498750 | F33: =SUM(F30:F32) -> 2030000 | G33: =SUM(G30:G32) -> 3030000
A34: Month 10 | C34: =C$16/9 -> 305555.56 | D34: =D$16/12 -> 320000 | E34: =E$16/12 -> 499583.33 | F34: =F$16/12 -> 676666.67 | G34: =G$16/12 -> 1010000
A35: Month 11 | C35: =C$16/9 -> 305555.56 | D35: =D$16/12 -> 320000 | E35: =E$16/12 -> 499583.33 | F35: =F$16/12 -> 676666.67 | G35: =G$16/12 -> 1010000
A36: Month 12 | C36: =C$16/9 -> 305555.56 | D36: =D$16/12 -> 320000 | E36: =E$16/12 -> 499583.33 | F36: =F$16/12 -> 676666.67 | G36: =G$16/12 -> 1010000
A37: Total 4th Quarter | C37: =SUM(C34:C36) -> 916666.67 | D37: =SUM(D34:D36) -> 960000 | E37: =SUM(E34:E36) -> 1498750 | F37: =SUM(F34:F36) -> 2030000 | G37: =SUM(G34:G36) -> 3030000
A38: Total for year | C38: =C25+C29+C33+C37 -> 2750000 | D38: =D25+D29+D33+D37 -> 3840000 | E38: =E25+E29+E33+E37 -> 5995000 | F38: =F25+F29+F33+F37 -> 8120000 | G38: =G25+G29+G33+G37 -> 12120000
A40: Average Revenue
A41: by Month | C41: =C16/12 -> 229166.67 | D41: =D16/12 -> 320000 | E41: =E16/12 -> 499583.33 | F41: =F16/12 -> 676666.67 | G41: =G16/12 -> 1010000
A42: by Quarter | C42: =C16/4 -> 687500 | D42: =D16/4 -> 960000 | E42: =E16/4 -> 1498750 | F42: =F16/4 -> 2030000 | G42: =G16/4 -> 3030000

Sheet COST OF REV
A1: XYZ Company
A2: Cost of Revenues
A3: Years 1 to 5
A4: ($)
C5: Year 1 | D5: Year 2 | E5: Year 3 | F5: Year 4 | G5: Year 5
A7: Revenue | C7: =REVENUE!C16 -> 2750000 | D7: =REVENUE!D16 -> 3840000 | E7: =REVENUE!E16 -> 5995000 | F7: =REVENUE!F16 -> 8120000 | G7: =REVENUE!G16 -> 12120000
A9: Cost of Revenue
A11: Product A
A12: Material Costs per Unit | C12: 18.7 | D12: 18.2 | E12: 17.5 | F12: 16.8 | G12: 16.2
A13: Subcontract Costs per Unit | C13: 12.4 | D13: 11.8 | E13: 11.2 | F13: 10.7 | G13: 10.2
A14: Total Direct Costs per Unit | C14: =SUM(C12:C13) -> 31.1 | D14: =SUM(D12:D13) -> 30 | E14: =SUM(E12:E13) -> 28.7 | F14: =SUM(F12:F13) -> 27.5 | G14: =SUM(G12:G13) -> 26.4
A15: Unit Sales | C15: =REVENUE!C7 -> 9000 | D15: =REVENUE!D7 -> 12000 | E15: =REVENUE!E7 -> 17000 | F15: =REVENUE!F7 -> 22000 | G15: =REVENUE!G7 -> 30000
A16: Total Direct Costs | C16: =C14*C15 -> 279900 | D16: =D14*D15 -> 360000 | E16: =E14*E15 -> 487900 | F16: =F14*F15 -> 605000 | G16: =G14*G15 -> 792000
A17: Labor Costs | C17: =PERSONNEL!C65 -> 66000 | D17: =PERSONNEL!D65 -> 227700 | E17: =PERSONNEL!E65 -> 358800 | F17: =PERSONNEL!F65 -> 489600 | G17: =PERSONNEL!G65 -> 600000
A18: Total Direct Costs | C18: =C16+C17 -> 345900 | D18: =D16+D17 -> 587700 | E18: =E16+E17 -> 846700 | F18: =F16+F17 -> 1094600 | G18: =G16+G17 -> 1392000
A20: Service B
A21: Service Personnel Costs | C21: =PERSONNEL!C73 -> 115500 | D21: =PERSONNEL!D73 -> 212750 | E21: =PERSONNEL!E73 -> 336000 | F21: =PERSONNEL!F73 -> 480000 | G21: =PERSONNEL!G73 -> 825000
A23: Other Expenses
A24: Salary Expenses | C24: =PERSONNEL!C57 -> 181500 | D24: =PERSONNEL!D57 -> 290950 | E24: =PERSONNEL!E57 -> 325200 | F24: =PERSONNEL!F57 -> 346800 | G24: =PERSONNEL!G57 -> 383750
A25: Depreciation | C25: ='PROP & EQUIP'!C34+'PROP & EQUIP'!C44 -> 37628.571 | D25: ='PROP & EQUIP'!D34+'PROP & EQUIP'!D44 -> 91000 | E25: ='PROP & EQUIP'!E34+'PROP & EQUIP'!E44 -> 138357.14 | F25: ='PROP & EQUIP'!F34+'PROP & EQUIP'!F44 -> 191500 | G25: ='PROP & EQUIP'!G34+'PROP & EQUIP'!G44 -> 245285.71
A26: Facility costs (rent, energy) | C26: 325000 | D26: 345000 | E26: 368000 | F26: 392000 | G26: 418000
A27: System Costs | C27: 210000 | D27: 235000 | E27: 260000 | F27: 285000 | G27: 315000
A31: All other costs % of Revenue | B31: 0.04 | C31: =$B31*C7 -> 110000 | D31: =$B31*D7 -> 153600 | E31: =$B31*E7 -> 239800 | F31: =$B31*F7 -> 324800 | G31: =$B31*G7 -> 484800
A32: Total Cost of Revenues | C32: =C18+C21+C24+C25+C26+C27+C31 -> 1325528.6 | D32: =D18+D21+D24+D25+D26+D27+D31 -> 1916000 | E32: =E18+E21+E24+E25+E26+E27+E31 -> 2514057.1 | F32: =F18+F21+F24+F25+F26+F27+F31 -> 3114700 | G32: =G18+G21+G24+G25+G26+G27+G31 -> 4063835.7
A33: % of Revenue | C33: =C32/C7 -> 0.48201039 | D33: =D32/D7 -> 0.49895833 | E33: =E32/E7 -> 0.41935899 | F33: =F32/F7 -> 0.38358374 | G33: =G32/G7 -> 0.33529998
A35: Allocation of Cost of Revenue between:
A36: Variable | C36: =C18+C21+C31 -> 571400 | D36: =D18+D21+D31 -> 954050 | E36: =E18+E21+E31 -> 1422500 | F36: =F18+F21+F31 -> 1899400 | G36: =G18+G21+G31 -> 2701800
A37: Fixed | C37: =C24+C25+C26+C27 -> 754128.57 | D37: =D24+D25+D26+D27 -> 961950 | E37: =E24+E25+E26+E27 -> 1091557.1 | F37: =F24+F25+F26+F27 -> 1215300 | G37: =G24+G25+G26+G27 -> 1362035.7
A38: Total | C38: =SUM(C36:C37) -> 1325528.6 | D38: =SUM(D36:D37) -> 1916000 | E38: =SUM(E36:E37) -> 2514057.1 | F38: =SUM(F36:F37) -> 3114700 | G38: =SUM(G36:G37) -> 4063835.7
D40: Cost of Revenues by Months & Quarters
D41: ($)
C42: Year 1 | D42: Year 2 | E42: Year 3 | F42: Year 4 | G42: Year 5
A43: Month 1 | C43: =REVENUE!C22*'COST OF REV'!C$33 -> 0 | D43: =REVENUE!D22*'COST OF REV'!D$33 -> 159666.67 | E43: =REVENUE!E22*'COST OF REV'!E$33 -> 209504.76 | F43: =REVENUE!F22*'COST OF REV'!F$33 -> 259558.33 | G43: =REVENUE!G22*'COST OF REV'!G$33 -> 338652.98
A44: Month 2 | C44: =REVENUE!C23*'COST OF REV'!C$33 -> 0 | D44: =REVENUE!D23*'COST OF REV'!D$33 -> 159666.67 | E44: =REVENUE!E23*'COST OF REV'!E$33 -> 209504.76 | F44: =REVENUE!F23*'COST OF REV'!F$33 -> 259558.33 | G44: =REVENUE!G23*'COST OF REV'!G$33 -> 338652.98
A45: Month 3 | C45: =REVENUE!C24*'COST OF REV'!C$33 -> 0 | D45: =REVENUE!D24*'COST OF REV'!D$33 -> 159666.67 | E45: =REVENUE!E24*'COST OF REV'!E$33 -> 209504.76 | F45: =REVENUE!F24*'COST OF REV'!F$33 -> 259558.33 | G45: =REVENUE!G24*'COST OF REV'!G$33 -> 338652.98
A46: Total 1st Quarter | C46: =REVENUE!C25*'COST OF REV'!C$33 -> 0 | D46: =REVENUE!D25*'COST OF REV'!D$33 -> 479000 | E46: =REVENUE!E25*'COST OF REV'!E$33 -> 628514.29 | F46: =REVENUE!F25*'COST OF REV'!F$33 -> 778675 | G46: =REVENUE!G25*'COST OF REV'!G$33 -> 1015958.9
A47: Month 4 | C47: =REVENUE!C26*'COST OF REV'!C$33 -> 147280.95 | D47: =REVENUE!D26*'COST OF REV'!D$33 -> 159666.67 | E47: =REVENUE!E26*'COST OF REV'!E$33 -> 209504.76 | F47: =REVENUE!F26*'COST OF REV'!F$33 -> 259558.33 | G47: =REVENUE!G26*'COST OF REV'!G$33 -> 338652.98
A48: Month 5 | C48: =REVENUE!C27*'COST OF REV'!C$33 -> 147280.95 | D48: =REVENUE!D27*'COST OF REV'!D$33 -> 159666.67 | E48: =REVENUE!E27*'COST OF REV'!E$33 -> 209504.76 | F48: =REVENUE!F27*'COST OF REV'!F$33 -> 259558.33 | G48: =REVENUE!G27*'COST OF REV'!G$33 -> 338652.98
A49: Month 6 | C49: =REVENUE!C28*'COST OF REV'!C$33 -> 147280.95 | D49: =REVENUE!D28*'COST OF REV'!D$33 -> 159666.67 | E49: =REVENUE!E28*'COST OF REV'!E$33 -> 209504.76 | F49: =REVENUE!F28*'COST OF REV'!F$33 -> 259558.33 | G49: =REVENUE!G28*'COST OF REV'!G$33 -> 338652.98
A50: Total 2nd Quarter | C50: =REVENUE!C29*'COST OF REV'!C$33 -> 441842.86 | D50: =REVENUE!D29*'COST OF REV'!D$33 -> 479000 | E50: =REVENUE!E29*'COST OF REV'!E$33 -> 628514.29 | F50: =REVENUE!F29*'COST OF REV'!F$33 -> 778675 | G50: =REVENUE!G29*'COST OF REV'!G$33 -> 1015958.9
...

Sheet OPER EXP
A1: XYZ Company
A2: Operating Expenses
A3: Years 1 to 5
A4: ($)
C5: Year 1 | D5: Year 2 | E5: Year 3 | F5: Year 4 | G5: Year 5
A7: Net Revenues | C7: =REVENUE!C16 -> 2750000 | D7: =REVENUE!D16 -> 3840000 | E7: =REVENUE!E16 -> 5995000 | F7: =REVENUE!F16 -> 8120000 | G7: =REVENUE!G16 -> 12120000
A9: Sales & Marketing
A10: Drivers
A11: Salaries and Benefits | C11: =PERSONNEL!C18 -> 297000 | D11: =PERSONNEL!D18 -> 322000 | E11: =PERSONNEL!E18 -> 341640 | F11: =PERSONNEL!F18 -> 364800 | G11: =PERSONNEL!G18 -> 379200
A12: Commissions % of Revenue | B12: 0.05 | C12: =$B12*C7 -> 137500 | D12: =$B12*D7 -> 192000 | E12: =$B12*E7 -> 299750 | F12: =$B12*F7 -> 406000 | G12: =$B12*G7 -> 606000
A13: Direct Mail Campaign | C13: 60000 | D13: 85000 | E13: 120000 | F13: 160000 | G13: 200000
A15: All other expenses % of Revenue | B15: 0.06 | C15: =$B15*C7 -> 165000 | D15: =$B15*D7 -> 230400 | E15: =$B15*E7 -> 359700 | F15: =$B15*F7 -> 487200 | G15: =$B15*G7 -> 727200
A16: Total Sales and Marketing | C16: =SUM(C11:C15) -> 659500 | D16: =SUM(D11:D15) -> 829400 | E16: =SUM(E11:E15) -> 1121090 | F16: =SUM(F11:F15) -> 1418000 | G16: =SUM(G11:G15) -> 1912400
A17: % of Revenue | C17: =C16/C7 -> 0.23981818 | D17: =D16/D7 -> 0.21598958 | E17: =E16/E7 -> 0.18700417 | F17: =F16/F7 -> 0.17463054 | G17: =G16/G7 -> 0.15778878
A19: Research & Development
A20: Drivers
A21: Salaries and Benefits | C21: =PERSONNEL!C31 -> 110000 | D21: =PERSONNEL!D31 -> 316250 | E21: =PERSONNEL!E31 -> 418860 | F21: =PERSONNEL!F31 -> 500400 | G21: =PERSONNEL!G31 -> 571200
A22: Testing | C22: 95000 | D22: 130000 | E22: 175000 | F22: 225000 | G22: 280000
A24: All other expenses % of Revenue | B24: 0.03 | C24: =$B24*C7 -> 82500 | D24: =$B24*D7 -> 115200 | E24: =$B24*E7 -> 179850 | F24: =$B24*F7 -> 243600 | G24: =$B24*G7 -> 363600
A25: Total Research & Development | C25: =SUM(C21:C24) -> 287500 | D25: =SUM(D21:D24) -> 561450 | E25: =SUM(E21:E24) -> 773710 | F25: =SUM(F21:F24) -> 969000 | G25: =SUM(G21:G24) -> 1214800
A26: % of Revenue | C26: =C25/C7 -> 0.10454545 | D26: =D25/D7 -> 0.14621094 | E26: =E25/E7 -> 0.12905922 | F26: =F25/F7 -> 0.11933498 | G26: =G25/G7 -> 0.10023102
A28: General & Administration
A29: Drivers
A30: Salaries and Benefits | C30: =PERSONNEL!C44 -> 137500 | D30: =PERSONNEL!D44 -> 300150 | E30: =PERSONNEL!E44 -> 335790 | F30: =PERSONNEL!F44 -> 429600 | G30: =PERSONNEL!G44 -> 502800
A31: Depreciation | C31: ='PROP & EQUIP'!C24 -> 7500 | D31: ='PROP & EQUIP'!D24 -> 42500 | E31: ='PROP & EQUIP'!E24 -> 112500 | F31: ='PROP & EQUIP'!F24 -> 191666.67 | G31: ='PROP & EQUIP'!G24 -> 271666.67
A32: Rent and Utilities | C32: 420000 | D32: 450000 | E32: 490000 | F32: 530000 | G32: 575000
A36: All other expenses % of Revenue | B36: 0.02 | C36: =$B36*C7 -> 55000 | D36: =$B36*D7 -> 76800 | E36: =$B36*E7 -> 119900 | F36: =$B36*F7 -> 162400 | G36: =$B36*G7 -> 242400
A38: Total General & Administration | C38: =SUM(C30:C36) -> 620000 | D38: =SUM(D30:D36) -> 869450 | E38: =SUM(E30:E36) -> 1058190 | F38: =SUM(F30:F36) -> 1313666.7 | G38: =SUM(G30:G36) -> 1591866.7
A39: % of Revenue | C39: =C38/C7 -> 0.22545455 | D39: =D38/D7 -> 0.22641927 | E39: =E38/E7 -> 0.17651209 | F39: =F38/F7 -> 0.16178161 | G39: =G38/G7 -> 0.13134213
A41: Total Operating Expenses | C41: =C16+C25+C38 -> 1567000 | D41: =D16+D25+D38 -> 2260300 | E41: =E16+E25+E38 -> 2952990 | F41: =F16+F25+F38 -> 3700666.7 | G41: =G16+G25+G38 -> 4719066.7
A42: % of Revenue | C42: =C41/C7 -> 0.56981818 | D42: =D41/D7 -> 0.58861979 | E42: =E41/E7 -> 0.49257548 | F42: =F41/F7 -> 0.45574713 | G42: =G41/G7 -> 0.38936194
A44: Allocation of Operating Expenses between:
A45: Variable | C45: =C12+C15+C24+C36 -> 440000 | D45: =D12+D15+D24+D36 -> 614400 | E45: =E12+E15+E24+E36 -> 959200 | F45: =F12+F15+F24+F36 -> 1299200 | G45: =G12+G15+G24+G36 -> 1939200
A46: Fixed | C46: =C11+C13+C21+C22+C30+C31+C32 -> 1127000 | D46: =D11+D13+D21+D22+D30+D31+D32 -> 1645900 | E46: =E11+E13+E21+E22+E30+E31+E32 -> 1993790 | F46: =F11+F13+F21+F22+F30+F31+F32 -> 2401466.7 | G46: =G11+G13+G21+G22+G30+G31+G32 -> 2779866.7
A47: Total | C47: =C45+C46 -> 1567000 | D47: =D45+D46 -> 2260300 | E47: =E45+E46 -> 2952990 | F47: =F45+F46 -> 3700666.7 | G47: =G45+G46 -> 4719066.7
D50: Sales & Marketing by Months & Quarters
D51: ($)
C52: Year 1 | D52: Year 2 | E52: Year 3 | F52: Year 4 | G52: Year 5
A53: Month 1 | C53: =REVENUE!C22*'OPER EXP'!C$17 -> 0 | D53: =REVENUE!D22*'OPER EXP'!D$17 -> 69116.667 | E53: =REVENUE!E22*'OPER EXP'!E$42 -> 246082.5 | F53: =REVENUE!F22*'OPER EXP'!F$42 -> 308388.89 | G53: =REVENUE!G22*'OPER EXP'!G$42 -> 393255.56
A54: Month 2 | C54: =REVENUE!C23*'OPER EXP'!C$17 -> 0 | D54: =REVENUE!D23*'OPER EXP'!D$17 -> 69116.667 | E54: =REVENUE!E23*'OPER EXP'!E$42 -> 246082.5 | F54: =REVENUE!F23*'OPER EXP'!F$42 -> 308388.89 | G54: =REVENUE!G23*'OPER EXP'!G$42 -> 393255.56
...

Sheet PERSONNEL
A1: XYZ Company | M1: checksum | N1: =SUM(C18:G19,C31:G32,C44:G45,C75:G81,EXTRA!C15:G16,EXTRA!C39:G39,TAXES!C14:G15,'PROP & EQUIP'!B13:G14,'PROP & EQUIP'!C47:G48,'PROP & EQUIP'!B53:G54,'PROP & EQUIP'!C77:G77,WORKCAP!C61:G61,WORKCAP!C6:G6,FUNDING!C9:G9,FUNDING!C14:G14,FUNDING!B15:G15,FUNDING!C19:G19,FUNDING!C24:G24,FUNDING!C27:G29,FUNDING!C41:G41,FUNDING!C50:G52) -> 1.3795575e+08
A2: Personnel
A3: Years 1 to 5
A4: ($)
C5: Year 1 | D5: Year 2 | E5: Year 3 | F5: Year 4 | G5: Year 5
A7: Net Revenues | C7: =REVENUE!C16 -> 2750000 | D7: =REVENUE!D16 -> 3840000 | E7: =REVENUE!E16 -> 5995000 | F7: =REVENUE!F16 -> 8120000 | G7: =REVENUE!G16 -> 12120000
A9: Sales & Marketing
A10: Sales Manager | C10: 85000 | D10: 88000 | E10: 92000 | F10: 96000 | G10: 100000
A11: Marketing Manager | C11: 80000 | D11: 83000 | E11: 87000 | F11: 91000 | G11: 95000
A12: Customer Service Rep 1 | C12: 45000 | D12: 47000 | E12: 49000 | F12: 51000 | G12: 53000
A13: Operations Coordinator | C13: 60000 | D13: 62000 | E13: 64000 | F13: 66000 | G13: 68000
A14: Total Salary | C14: =SUM(C10:C13) -> 270000 | D14: =SUM(D10:D13) -> 280000 | E14: =SUM(E10:E13) -> 292000 | F14: =SUM(F10:F13) -> 304000 | G14: =SUM(G10:G13) -> 316000
A15: Benefits
A16: Percent (%) | C16: 0.1 | D16: 0.15 | E16: 0.17 | F16: 0.2 | G16: 0.2
A17: Total benefit costs | C17: =C16*C14 -> 27000 | D17: =D16*D14 -> 42000 | E17: =E16*E14 -> 49640 | F17: =F16*F14 -> 60800 | G17: =G16*G14 -> 63200
A18: Total S & M Compensation | C18: =C14+C17 -> 297000 | D18: =D14+D17 -> 322000 | E18: =E14+E17 -> 341640 | F18: =F14+F17 -> 364800 | G18: =G14+G17 -> 379200
A19: % of Revenue | C19: =C18/C$7 -> 0.108 | D19: =D18/D$7 -> 0.083854167 | E19: =E18/E$7 -> 0.05698749 | F19: =F18/F$7 -> 0.044926108 | G19: =G18/G$7 -> 0.031287129
A21: Research and Development
A22: R&D Manager | D22: 80000 | E22: 100000 | F22: 125000 | G22: 130000
A23: Engineer | C23: 60000 | D23: 60000 | E23: 90000 | F23: 95000 | G23: 110000
A24: Technician | D24: 50000 | E24: 55000 | F24: 65000 | G24: 70000
A25: Subcontract (Contract R&D) | C25: 40000 | D25: 50000 | E25: 75000 | F25: 90000 | G25: 120000
A26: Other 1: Lab Assistant | D26: 35000 | E26: 38000 | F26: 42000 | G26: 46000
A27: Total Salary | C27: =SUM(C22:C26) -> 100000 | D27: =SUM(D22:D26) -> 275000 | E27: =SUM(E22:E26) -> 358000 | F27: =SUM(F22:F26) -> 417000 | G27: =SUM(G22:G26) -> 476000
A28: Benefits
A29: Percent (%) | C29: 0.1 | D29: 0.15 | E29: 0.17 | F29: 0.2 | G29: 0.2
A30: Total benefit costs | C30: =C29*C27 -> 10000 | D30: =D29*D27 -> 41250 | E30: =E29*E27 -> 60860 | F30: =F29*F27 -> 83400 | G30: =G29*G27 -> 95200
A31: Total R & D Compensation | C31: =C27+C30 -> 110000 | D31: =D27+D30 -> 316250 | E31: =E27+E30 -> 418860 | F31: =F27+F30 -> 500400 | G31: =G27+G30 -> 571200
A32: % of Revenue | C32: =C31/C$7 -> 0.04 | D32: =D31/D$7 -> 0.082356771 | E32: =E31/E$7 -> 0.069868224 | F32: =F31/F$7 -> 0.061625616 | G32: =G31/G$7 -> 0.047128713
A34: General & Administration
A35: CEO | C35: 60000 | D35: 80000 | E35: 100000 | F35: 125000 | G35: 130000
A36: CFO | D36: 50000 | E36: 60000 | F36: 75000 | G36: 100000
A37: Accounting | C37: 40000 | D37: 45000 | E37: 25000 | F37: 50000 | G37: 75000
A38: Secretarial | C38: 25000 | D38: 26000 | E38: 27000 | F38: 28000 | G38: 29000
A39: Clerks/Admin Personnel | D39: 60000 | E39: 75000 | F39: 80000 | G39: 85000
A40: Total Salary | C40: =SUM(C35:C39) -> 125000 | D40: =SUM(D35:D39) -> 261000 | E40: =SUM(E35:E39) -> 287000 | F40: =SUM(F35:F39) -> 358000 | G40: =SUM(G35:G39) -> 419000
A41: Benefits
A42: Percent (%) | C42: 0.1 | D42: 0.15 | E42: 0.17 | F42: 0.2 | G42: 0.2
A43: Total benefit costs | C43: =C42*C40 -> 12500 | D43: =D42*D40 -> 39150 | E43: =E42*E40 -> 48790 | F43: =F42*F40 -> 71600 | G43: =G42*G40 -> 83800
A44: Total G & A Compensation | C44: =C40+C43 -> 137500 | D44: =D40+D43 -> 300150 | E44: =E40+E43 -> 335790 | F44: =F40+F43 -> 429600 | G44: =G40+G43 -> 502800
...

Sheet EXTRA
A1: XYZ Company
A2: Extraordinary Income & Expense
A3: Years 1 to 5
A4: ($)
C5: Year 1 | D5: Year 2 | E5: Year 3 | F5: Year 4 | G5: Year 5
A7: Income
A8: Training Services (B2B workshops) | C8: 0 | D8: 50000 | E8: 80000 | F8: 120000 | G8: 150000
A9: Equipment Leasing (spare capacity) | C9: 0 | D9: 40000 | E9: 60000 | F9: 80000 | G9: 100000
A10: Consulting Add-ons | C10: 0 | D10: 25000 | E10: 40000 | F10: 60000 | G10: 80000
A11: Total | C11: =SUM(C8:C10) -> 0 | D11: =SUM(D8:D10) -> 115000 | E11: =SUM(E8:E10) -> 180000 | F11: =SUM(F8:F10) -> 260000 | G11: =SUM(G8:G10) -> 330000
A12: Start-up expenses
A13: Legal | C13: 50000 | D13: 0 | E13: 0 | F13: 0 | G13: 0
A14: Relocation | C14: 70000 | D14: 0 | E14: 0 | F14: 0 | G14: 0
A15: Total | C15: =SUM(C13:C14) -> 120000 | D15: =SUM(D13:D14) -> 0 | E15: =SUM(E13:E14) -> 0 | F15: =SUM(F13:F14) -> 0 | G15: =SUM(G13:G14) -> 0
A16: Total Extraordinary Income/(Expense) | C16: =C11-C15 -> -120000 | D16: =D11-D15 -> 115000 | E16: =E11-E15 -> 180000 | F16: =F11-F15 -> 260000 | G16: =G11-G15 -> 330000
D20: Extraordinary Income and Expense by Months & Quarters
D21: ($)
C22: Year 1 | D22: Year 2 | E22: Year 3 | F22: Year 4 | G22: Year 5
A23: Month 1 | C23: -50000 | D23: =D8 -> 50000 | E23: 0 | F23: 0 | G23: 0
A24: Month 2 | C24: -70000 | D24: 0 | E24: 80000 | F24: 120000 | G24: 150000
A25: Month 3 | C25: 0 | D25: 0 | E25: 0 | F25: 0 | G25: 0
A26: Total 1st Quarter | C26: =SUM(C23:C25) -> -120000 | D26: =SUM(D23:D25) -> 50000 | E26: =SUM(E23:E25) -> 80000 | F26: =SUM(F23:F25) -> 120000 | G26: =SUM(G23:G25) -> 150000
A27: Month 4 | C27: 0 | D27: 0 | E27: 0 | F27: 0 | G27: 100000
A28: Month 5 | C28: 0 | D28: 40000 | E28: 0 | F28: 80000 | G28: 0
A29: Month 6 | C29: 0 | D29: 0 | E29: 0 | F29: 0 | G29: 0
A30: Total 2nd Quarter | C30: =SUM(C27:C29) -> 0 | D30: =SUM(D27:D29) -> 40000 | E30: =SUM(E27:E29) -> 0 | F30: =SUM(F27:F29) -> 80000 | G30: =SUM(G27:G29) -> 100000
A31: Month 7 | C31: 0 | D31: 0 | E31: 0 | F31: 0 | G31: 80000
A32: Month 8 | C32: 0 | D32: 0 | E32: 60000 | F32: 0 | G32: 0
A33: Month 9 | C33: 0 | D33: 0 | E33: 0 | F33: 0 | G33: 0
A34: Total 3rd Quarter | C34: =SUM(C31:C33) -> 0 | D34: =SUM(D31:D33) -> 0 | E34: =SUM(E31:E33) -> 60000 | F34: =SUM(F31:F33) -> 0 | G34: =SUM(G31:G33) -> 80000
A35: Month 10 | C35: 0 | D35: 25000 | E35: 0 | F35: 60000 | G35: 0
A36: Month 11 | C36: 0 | D36: 0 | E36: 40000 | F36: 0 | G36: 0
A37: Month 12 | C37: 0 | D37: 0 | E37: 0 | F37: 0 | G37: 0
A38: Total 4th Quarter | C38: =SUM(C35:C37) -> 0 | D38: =SUM(D35:D37) -> 25000 | E38: =SUM(E35:E37) -> 40000 | F38: =SUM(F35:F37) -> 60000 | G38: =SUM(G35:G37) -> 0
A39: Total for year | C39: =SUM(C38,C34,C30,C26) -> -120000 | D39: =SUM(D38,D34,D30,D26) -> 115000 | E39: =SUM(E38,E34,E30,E26) -> 180000 | F39: =SUM(F38,F34,F30,F26) -> 260000 | G39: =SUM(G38,G34,G30,G26) -> 330000

Sheet TAXES
A1: XYZ Company
A2: Taxes
A3: Years 1 to 5
A4: ($)
C5: Year 1 | D5: Year 2 | E5: Year 3 | F5: Year 4 | G5: Year 5
A7: Net Revenues | C7: =REVENUE!C16 -> 2750000 | D7: =REVENUE!D16 -> 3840000 | E7: =REVENUE!E16 -> 5995000 | F7: =REVENUE!F16 -> 8120000 | G7: =REVENUE!G16 -> 12120000
A9: Income Tax (Rate Federal & State) | C9: 0.4 | D9: 0.4 | E9: 0.4 | F9: 0.4 | G9: 0.4
A11: Net Earnings Before Taxes | C11: =INCOME!C30 -> -476628.57 | D11: =INCOME!D30 -> -416600 | E11: =INCOME!E30 -> 488352.86 | F11: =INCOME!F30 -> 1440633.3 | G11: =INCOME!G30 -> 3579897.6
A12: Cumulative | C12: =C11 -> -476628.57 | D12: =D11+C12 -> -893228.57 | E12: =E11+D12 -> -404875.71 | F12: =F11+E12 -> 1035757.6 | G12: =G11+F12 -> 4615655.2
A14: Taxes | C14: =-IF(C12>=0,TAXES!$C$9*MIN(C11,C12),0) -> 0 | D14: =-IF(D12>=0,TAXES!$D$9*MIN(D11,D12),0) -> 0 | E14: =-IF(E12>=0,TAXES!$E$9*MIN(E11,E12),0) -> 0 | F14: =-IF(F12>=0,TAXES!$F$9*MIN(F11,F12),0) -> -414303.05 | G14: =-IF(G12>=0,TAXES!$G$9*MIN(G11,G12),0) -> -1431959
A15: Percent of Revenues | C15: =C14/C7 -> 0 | D15: =D14/D7 -> 0 | E15: =E14/E7 -> 0 | F15: =F14/F7 -> -0.051022543 | G15: =G14/G7 -> -0.11814844

Sheet PROP & EQUIP
A1: XYZ Company
A2: Property and Equipment
A3: Years 1 to 5
A4: ($)
B5: Year 0 | C5: Year 1 | D5: Year 2 | E5: Year 3 | F5: Year 4 | G5: Year 5
B6: Purchased
A7: Net Revenues | B7: Assets | C7: =REVENUE!C16 -> 2750000 | D7: =REVENUE!D16 -> 3840000 | E7: =REVENUE!E16 -> 5995000 | F7: =REVENUE!F16 -> 8120000 | G7: =REVENUE!G16 -> 12120000
A9: Capital Expenditures
A10: Computers, Software & Office Equipment | C10: 22500 | D10: 105000 | E10: 210000 | F10: 260000 | G10: 345000
A11: Plant & Equipment | C11: 255000 | D11: 340000 | E11: 265000 | F11: 295000 | G11: 310000
A12: Other | C12: 12000 | D12: 48000 | E12: 95000 | F12: 110000 | G12: 95000
A13: Total Capital Expenditures | B13: =SUM(B10:B12) -> 0 | C13: =SUM(C10:C12) -> 289500 | D13: =SUM(D10:D12) -> 493000 | E13: =SUM(E10:E12) -> 570000 | F13: =SUM(F10:F12) -> 665000 | G13: =SUM(G10:G12) -> 750000
A14: % of Revenue | C14: =C13/C7 -> 0.10527273 | D14: =D13/D7 -> 0.12838542 | E14: =E13/E7 -> 0.095079233 | F14: =F13/F7 -> 0.081896552 | G14: =G13/G7 -> 0.061881188
A16: Depreciation Computers, Sofware & Office Equipment (allocated to General & Administrative Expenses)
A17: Depreciation Rate: Years | B17: 1 | C17: 3 | D17: 3 | E17: 3 | F17: 3 | G17: 3
A18: Year 0 | C18: =$B10*1/$B17 -> 0 | D18: =IF(C18<$B10,($B10*1/$B$17),0) -> 0 | E18: =IF(SUM(C18:D18)<$B10,($B10*1/$B$17),0) -> 0 | F18: =IF(SUM(C18:E18)<$B10,($B10*1/$B$17),0) -> 0 | G18: =IF(SUM(C18:F18)<$B10,($B10*1/$B$17),0) -> 0
A19: Year 1 | C19: =$C10*1/$C17 -> 7500 | D19: =IF(C19<$C10,($C10*1/$C$17),0) -> 7500 | E19: =IF(SUM(C19:D19)<$C10,($C10*1/$C$17),0) -> 7500 | F19: =IF(SUM(C19:E19)<$C10,($C10*1/$C$17),0) -> 0 | G19: =IF(SUM(C19:F19)<$C10,($C10*1/$C$17),0) -> 0
A20: Year 2 | D20: =$D10*1/$D$17 -> 35000 | E20: =IF(D20<$D10,($D10*1/$D$17),0) -> 35000 | F20: =IF(SUM(D20:E20)<$D10,($D10*1/$D$17),0) -> 35000 | G20: =IF(SUM(D20:F20)<$D10,($D10*1/$D$17),0) -> 0
A21: Year 3 | E21: =$E10*1/$E$17 -> 70000 | F21: =IF(E21<$E10,($E10*1/$E$17),0) -> 70000 | G21: =IF(SUM(E21:F21)<$E10,($E10*1/$E$17),0) -> 70000
A22: Year 4 | F22: =$F10*1/$F$17 -> 86666.667 | G22: =IF(F22<$F10,($F10*1/$F$17),0) -> 86666.667
A23: Year 5 | G23: =$G10*1/G$17 -> 115000
A24: Total Depreciation | C24: =SUM(C18:C23) -> 7500 | D24: =SUM(D18:D23) -> 42500 | E24: =SUM(E18:E23) -> 112500 | F24: =SUM(F18:F23) -> 191666.67 | G24: =SUM(G18:G23) -> 271666.67
A26: Depreciation on Plant and Equipment (allocated to Cost of Revenue)
A27: Depreciation Rate: Years | B27: 1 | C27: 7 | D27: 7 | E27: 7 | F27: 7 | G27: 7
A28: Year 0 | C28: =$B11*1/$B27 -> 0 | D28: =IF(C28<$B11,($B11*1/$B$27),0) -> 0 | E28: =IF(SUM(C28:D28)<$B11,($B11*1/$B$27),0) -> 0 | F28: =IF(SUM(C28:E28)<$B11,($B11*1/$B$27),0) -> 0 | G28: =IF(SUM(C28:F28)<$B11,($B11*1/$B$27),0) -> 0
A29: Year 1 | C29: =$C11*1/$C27 -> 36428.571 | D29: =IF(C29<$C11,($C11*1/$C$27),0) -> 36428.571 | E29: =IF(SUM(C29:D29)<$C11,($C11*1/$C$27),0) -> 36428.571 | F29: =IF(SUM(C29:E29)<$C11,($C11*1/$C$27),0) -> 36428.571 | G29: =IF(SUM(C29:F29)<$C11,($C11*1/$C$27),0) -> 36428.571
A30: Year 2 | D30: =$D11*1/$D$27 -> 48571.429 | E30: =IF(D30<$D11,($D11*1/$D$27),0) -> 48571.429 | F30: =IF(SUM(D30:E30)<$D11,($D11*1/$D$27),0) -> 48571.429 | G30: =IF(SUM(D30:F30)<$D11,($D11*1/$D$27),0) -> 48571.429
A31: Year 3 | E31: =$E11*1/$E$27 -> 37857.143 | F31: =IF(E31<$E11,($E11*1/$E$27),0) -> 37857.143 | G31: =IF(SUM(E31:F31)<$E11,($E11*1/$E$27),0) -> 37857.143
A32: Year 4 | F32: =$F11*1/$F$27 -> 42142.857 | G32: =IF(F32<$F11,($F11*1/$F$27),0) -> 42142.857
A33: Year 5 | G33: =$G11*1/G$27 -> 44285.714
A34: Total Depreciation | C34: =SUM(C28:C33) -> 36428.571 | D34: =SUM(D28:D33) -> 85000 | E34: =SUM(E28:E33) -> 122857.14 | F34: =SUM(F28:F33) -> 165000 | G34: =SUM(G28:G33) -> 209285.71
A36: Depreciation Other (allocated to Cost of Revenue)
A37: Depreciation Rate: Years | B37: 1 | C37: 10 | D37: 10 | E37: 10 | F37: 10 | G37: 10
A38: Year 0 | C38: =$B12*1/$B37 -> 0 | D38: =IF(C38<$B12,($B12*1/$B$37),0) -> 0 | E38: =IF(SUM(C38:D38)<$B12,($B12*1/$B$37),0) -> 0 | F38: =IF(SUM(C38:E38)<$B12,($B12*1/$B$37),0) -> 0 | G38: =IF(SUM(C38:F38)<$B12,($B12*1/$B$37),0) -> 0
A39: Year 1 | C39: =$C12*1/$C37 -> 1200 | D39: =IF(C39<$C12,($C12*1/$C$37),0) -> 1200 | E39: =IF(SUM(C39:D39)<$C12,($C12*1/$C$37),0) -> 1200 | F39: =IF(SUM(C39:E39)<$C12,($C12*1/$C$37),0) -> 1200 | G39: =IF(SUM(C39:F39)<$C12,($C12*1/$C$37),0) -> 1200
A40: Year 2 | D40: =$D12*1/$D$37 -> 4800 | E40: =IF(D40<D12,($D12*1/$D$37),0) -> 4800 | F40: =IF(SUM(D40:E40)<$D12,($D12*1/$D$37),0) -> 4800 | G40: =IF(SUM(D40:F40)<$D12,($D12*1/$D$37),0) -> 4800
A41: Year 3 | E41: =$E12*1/$E$37 -> 9500 | F41: =IF(E41<$E12,($E12*1/$E$37),0) -> 9500 | G41: =IF(SUM(E41:F41)<$E12,($E12*1/$E$37),0) -> 9500
A42: Year 4 | F42: =$F12*1/$F$37 -> 11000 | G42: =IF(F42<$F12,($F12*1/$F$37),0) -> 11000
A43: Year 5 | G43: =$G12*1/G$37 -> 9500
A44: Total Depreciation | C44: =SUM(C38:C43) -> 1200 | D44: =SUM(D38:D43) -> 6000 | E44: =SUM(E38:E43) -> 15500 | F44: =SUM(F38:F43) -> 26500 | G44: =SUM(G38:G43) -> 36000
...

Sheet WORKCAP
A1: XYZ Company
A2: Working Capital
A3: Years 1 to 5
A4: ($)
C5: Year 1 | D5: Year 2 | E5: Year 3 | F5: Year 4 | G5: Year 5
A6: Net Revenues | C6: =REVENUE!C16 -> 2750000 | D6: =REVENUE!D16 -> 3840000 | E6: =REVENUE!E16 -> 5995000 | F6: =REVENUE!F16 -> 8120000 | G6: =REVENUE!G16 -> 12120000
A9: Accounts Receivable
A10: % of Revenue | C10: 0.083 | D10: 0.083 | E10: 0.083 | F10: 0.083 | G10: 0.083
A11: Days Outstanding | C11: =C10*360 -> 29.88 | D11: =D10*360 -> 29.88 | E11: =E10*360 -> 29.88 | F11: =F10*360 -> 29.88 | G11: =G10*360 -> 29.88
A12: Accounts Receivable | C12: =C78 -> 304333.33 | D12: =D78 -> 318720 | E12: =E78 -> 497585 | F12: =F78 -> 673960 | G12: =G78 -> 1005960
A13: (Increase)/Decrease from Prev. Period | C13: =-C12 -> -304333.33 | D13: =-(D12-C12) -> -14386.667 | E13: =-(E12-D12) -> -178865 | F13: =-(F12-E12) -> -176375 | G13: =-(G12-F12) -> -332000
A15: Inventory
A16: % of Revenue | C16: 0.083 | D16: 0.083 | E16: 0.067 | F16: 0.067 | G16: 0.067
A17: Inventory Turns | C17: =IF(C18<=0,0,ROUND(360/C18,0)) -> 12 | D17: =IF(D18<=0,0,ROUND(360/D18,0)) -> 12 | E17: =IF(E18<=0,0,ROUND(360/E18,0)) -> 15 | F17: =IF(F18<=0,0,ROUND(360/F18,0)) -> 15 | G17: =IF(G18<=0,0,ROUND(360/G18,0)) -> 15
A18: Inventory Days | C18: =C16*360 -> 29.88 | D18: =D16*360 -> 29.88 | E18: =E16*360 -> 24.12 | F18: =F16*360 -> 24.12 | G18: =G16*360 -> 24.12
A19: Inventory | C19: =C95 -> 304333.33 | D19: =D95 -> 318720 | E19: =E95 -> 401665 | F19: =F95 -> 544040 | G19: =G95 -> 812040
A20: (Increase)/Decrease from Prev. Period | C20: =-C19 -> -304333.33 | D20: =-(D19-C19) -> -14386.667 | E20: =-(E19-D19) -> -82945 | F20: =-(F19-E19) -> -142375 | G20: =-(G19-F19) -> -268000
A22: Other Current Assets
A23: % of Revenue | C23: 0.01 | D23: 0.01 | E23: 0.01 | F23: 0.01 | G23: 0.01
A24: Days | C24: =C23*360 -> 3.6 | D24: =D23*360 -> 3.6 | E24: =E23*360 -> 3.6 | F24: =F23*360 -> 3.6 | G24: =G23*360 -> 3.6
A25: Other CA Value | C25: =C112 -> 36666.667 | D25: =D112 -> 38400 | E25: =E112 -> 59950 | F25: =F112 -> 81200 | G25: =G112 -> 121200
A26: (Increase)/Decrease from Prev. Period | C26: =-C25 -> -36666.667 | D26: =-(D25-C25) -> -1733.3333 | E26: =-(E25-D25) -> -21550 | F26: =-(F25-E25) -> -21250 | G26: =-(G25-F25) -> -40000
A28: Accounts Payable & Accrued Expenses
A29: % of Revenue | C29: 0.087 | D29: 0.087 | E29: 0.087 | F29: 0.087 | G29: 0.087
A30: Days | C30: =C29*360 -> 31.32 | D30: =D29*360 -> 31.32 | E30: =E29*360 -> 31.32 | F30: =F29*360 -> 31.32 | G30: =G29*360 -> 31.32
A31: AP & Accrued Value | C31: =C129 -> 319000 | D31: =D129 -> 334080 | E31: =E129 -> 521565 | F31: =F129 -> 706440 | G31: =G129 -> 1054440
A32: Increase/(Decrease) from Prev. Period | C32: =C31 -> 319000 | D32: =(D31-C31) -> 15080 | E32: =(E31-D31) -> 187485 | F32: =(F31-E31) -> 184875 | G32: =(G31-F31) -> 348000
A34: Other Current Liabilites
A35: % of Revenue | C35: 0.01 | D35: 0.01 | E35: 0.01 | F35: 0.01 | G35: 0.01
A36: Days | C36: =C35*360 -> 3.6 | D36: =D35*360 -> 3.6 | E36: =E35*360 -> 3.6 | F36: =F35*360 -> 3.6 | G36: =G35*360 -> 3.6
A37: Other Current Liabilities | C37: =C146 -> 36666.667 | D37: =D146 -> 38400 | E37: =E146 -> 59950 | F37: =F146 -> 81200 | G37: =G146 -> 121200
A38: Increase/(Decrease) from Prev. Period | C38: =C37 -> 36666.667 | D38: =D37-C37 -> 1733.3333 | E38: =E37-D37 -> 21550 | F38: =F37-E37 -> 21250 | G38: =G37-F37 -> 40000
A42: Revenues by Months & Quarters
D43: ($)
C44: Year 1 | D44: Year 2 | E44: Year 3 | F44: Year 4 | G44: Year 5
A45: Month 1 | C45: =REVENUE!C22 -> 0 | D45: =REVENUE!D22 -> 320000 | E45: =REVENUE!E22 -> 499583.33 | F45: =REVENUE!F22 -> 676666.67 | G45: =REVENUE!G22 -> 1010000
A46: Month 2 | C46: =REVENUE!C23 -> 0 | D46: =REVENUE!D23 -> 320000 | E46: =REVENUE!E23 -> 499583.33 | F46: =REVENUE!F23 -> 676666.67 | G46: =REVENUE!G23 -> 1010000
A47: Month 3 | C47: =REVENUE!C24 -> 0 | D47: =REVENUE!D24 -> 320000 | E47: =REVENUE!E24 -> 499583.33 | F47: =REVENUE!F24 -> 676666.67 | G47: =REVENUE!G24 -> 1010000
A48: Total 1st Quarter | C48: =REVENUE!C25 -> 0 | D48: =REVENUE!D25 -> 960000 | E48: =REVENUE!E25 -> 1498750 | F48: =REVENUE!F25 -> 2030000 | G48: =REVENUE!G25 -> 3030000
A49: Month 4 | C49: =REVENUE!C26 -> 305555.56 | D49: =REVENUE!D26 -> 320000 | E49: =REVENUE!E26 -> 499583.33 | F49: =REVENUE!F26 -> 676666.67 | G49: =REVENUE!G26 -> 1010000
...

Sheet FUNDING
A1: XYZ Company
A2: Funding Projections
A3: Years 1 to 5
A4: ($)
B5: Begin | C5: Year 1 | D5: Year 2 | E5: Year 3 | F5: Year 4 | G5: Year 5
A6: Beginning Cash | B6: 2500000
A7: Equity
A8: Common | B8: 1500000 | C8: 500000 | D8: 750000 | E8: 600000 | F8: 1000000 | G8: 800000
A9: Increase / (Decrease) Previous Period | C9: =C8-B8 -> -1000000 | D9: =D8-C8 -> 250000 | E9: =E8-D8 -> -150000 | F9: =F8-E8 -> 400000 | G9: =G8-F8 -> -200000
A10: Preferred
A11: A Round | B11: 1200000 | C11: 1200000 | D11: 1200000 | E11: 1200000 | F11: 1200000 | G11: 1200000
A12: B Round | D12: 750000 | E12: 750000 | F12: 750000 | G12: 750000
A13: Total Preferred | B13: =SUM(B11:B12) -> 1200000 | C13: =SUM(C11:C12) -> 1200000 | D13: =SUM(D11:D12) -> 1950000 | E13: =SUM(E11:E12) -> 1950000 | F13: =SUM(F11:F12) -> 1950000 | G13: =SUM(G11:G12) -> 1950000
A14: Increase / (Decrease) Previous Period | C14: =C13-B13 -> 0 | D14: =D13-C13 -> 750000 | E14: =E13-D13 -> 0 | F14: =F13-E13 -> 0 | G14: =G13-F13 -> 0
A15: Total Equity | B15: =B8+B13 -> 2700000 | C15: =C8+C13 -> 1700000 | D15: =D8+D13 -> 2700000 | E15: =E8+E13 -> 2550000 | F15: =F8+F13 -> 2950000 | G15: =G8+G13 -> 2750000
A17: Debt
A18: Short Term Debt | C18: 450000 | D18: 350000 | E18: 800000 | F18: 100000
A19: Increase / (Decrease) Previous Period | C19: =C18-B18 -> 450000 | D19: =D18-C18 -> -100000 | E19: =E18-D18 -> 450000 | F19: =F18-E18 -> -700000 | G19: =G18-F18 -> -100000
A21: Long Term Debt
A22: Current Portion | C22: 250000 | D22: 275000 | E22: 300000 | F22: 325000 | G22: 350000
A23: Long Term Portion | C23: 2250000 | D23: 2100000 | E23: 1800000 | F23: 1400000 | G23: 1000000
A24: Total Long Term Debt | C24: =C22+C23 -> 2500000 | D24: =D22+D23 -> 2375000 | E24: =E22+E23 -> 2100000 | F24: =F22+F23 -> 1725000 | G24: =G22+G23 -> 1350000
A26: Increase / (Decrease) Previous Period
A27: Current Portion | C27: =C22-B22 -> 250000 | D27: =D22-C22 -> 25000 | E27: =E22-D22 -> 25000 | F27: =F22-E22 -> 25000 | G27: =G22-F22 -> 25000
A28: Long Term Protion | C28: =C23-B23 -> 2250000 | D28: =D23-C23 -> -150000 | E28: =E23-D23 -> -300000 | F28: =F23-E23 -> -400000 | G28: =G23-F23 -> -400000
A29: Total Long Term Debt | C29: =SUM(C27:C28) -> 2500000 | D29: =SUM(D27:D28) -> -125000 | E29: =SUM(E27:E28) -> -275000 | F29: =SUM(F27:F28) -> -375000 | G29: =SUM(G27:G28) -> -375000
A31: Total Equity & Debt | B31: =B15+B18+B24 -> 2700000 | C31: =C15+C18+C24 -> 4650000 | D31: =D15+D18+D24 -> 5425000 | E31: =E15+E18+E24 -> 5450000 | F31: =F15+F18+F24 -> 4775000 | G31: =G15+G18+G24 -> 4100000
A33: Interest
A34: Interest Rate
A35: Short Term Debt | C35: 0.098 | D35: 0.098 | E35: 0.098 | F35: 0.098 | G35: 0.098
A36: Long Term Debt | C36: 0.072 | D36: 0.072 | E36: 0.072 | F36: 0.072 | G36: 0.072
A38: Interest Expense
A39: Short Term Debt | C39: =C35*C18 -> 44100 | D39: =D35*D18 -> 34300 | E39: =E35*E18 -> 78400 | F39: =F35*F18 -> 9800 | G39: =G35*G18 -> 0
A40: Long Term Debt | C40: =C36*C24 -> 180000 | D40: =D36*D24 -> 171000 | E40: =E36*E24 -> 151200 | F40: =F36*F24 -> 124200 | G40: =G36*G24 -> 97200
A41: Total Interest | C41: =SUM(C39:C40) -> 224100 | D41: =SUM(D39:D40) -> 205300 | E41: =SUM(E39:E40) -> 229600 | F41: =SUM(F39:F40) -> 134000 | G41: =SUM(G39:G40) -> 97200
A43: Interest Income
A44: Interest Rate | C44: 0.032 | D44: 0.032 | E44: 0.032 | F44: 0.032 | G44: 0.032
A45: Interest Income | C45: 10000 | D45: 10000 | E45: 10000 | F45: 10000 | G45: 10000
A47: Retained Earnings
A48: Net Income | C48: =INCOME!C34 -> -476628.57 | D48: =INCOME!D34 -> -416600 | E48: =INCOME!E34 -> 488352.86 | F48: =INCOME!F34 -> 1026330.3 | G48: =INCOME!G34 -> 2147938.6
...

Sheet INCOME
A1: XYZ Company | M1: Checksum | N1: =SUM(C19:G20,C34:G35,BALANCE!B15:G15,BALANCE!B23:G23,BALANCE!B31:G32,CASHFLOW!C15:G15,CASHFLOW!C20:G20,CASHFLOW!C29:G29,CASHFLOW!C31:G31,CASHFLOW!C33:G34,BREAKEVEN!C21:G21,BREAKEVEN!C19:G20,BREAKEVEN!C23:G23,BREAKEVEN!C25:G25,'INCOME-MOS'!C35:P35,'INCOME-MOS'!C68:P68,'INCOME-MOS'!C102:T102,'CASHFLOW-MOS'!B20:O20,'CASHFLOW-MOS'!B25:O25,'CASHFLOW-MOS'!B34:O34,'CASHFLOW-MOS'!B36:O36,'CASHFLOW-MOS'!B38:O39,'CASHFLOW-MOS'!B56:O56,'CASHFLOW-MOS'!B61:O61,'CASHFLOW-MOS'!B70:O70,'CASHFLOW-MOS'!B72:O72,'CASHFLOW-MOS'!B74:O75,'CASHFLOW-MOS'!B92:S92,'CASHFLOW-MOS'!B97:S97,'CASHFLOW-MOS'!B106:S106,'CASHFLOW-MOS'!B108:S108,'CASHFLOW-MOS'!B110:S111,SUMMARY!C18:G18,SUMMARY!C34:G36) -> 5.8459393e+08
A2: Income Statement
A3: Years 1 to 5
A4: ($)
C5: Year 1 | D5: Year 2 | E5: Year 3 | F5: Year 4 | G5: Year 5
A7: NET REVENUES | C7: =REVENUE!C16 -> 2750000 | D7: =REVENUE!D16 -> 3840000 | E7: =REVENUE!E16 -> 5995000 | F7: =REVENUE!F16 -> 8120000 | G7: =REVENUE!G16 -> 12120000
A9: COST OF REVENUE | C9: ='COST OF REV'!C32 -> 1325528.6 | D9: ='COST OF REV'!D32 -> 1916000 | E9: ='COST OF REV'!E32 -> 2514057.1 | F9: ='COST OF REV'!F32 -> 3114700 | G9: ='COST OF REV'!G32 -> 4063835.7
A10: % of Revenues | C10: =C9/C7 -> 0.48201039 | D10: =D9/D7 -> 0.49895833 | E10: =E9/E7 -> 0.41935899 | F10: =F9/F7 -> 0.38358374 | G10: =G9/G7 -> 0.33529998
A12: GROSS PROFIT | C12: =C7-C9 -> 1424471.4 | D12: =D7-D9 -> 1924000 | E12: =E7-E9 -> 3480942.9 | F12: =F7-F9 -> 5005300 | G12: =G7-G9 -> 8056164.3
A13: % of Revenues | C13: =C12/C7 -> 0.51798961 | D13: =D12/D7 -> 0.50104167 | E13: =E12/E7 -> 0.58064101 | F13: =F12/F7 -> 0.61641626 | G13: =G12/G7 -> 0.66470002
A15: OPERATING EXPENSES
A16: Sales & Marketing | C16: ='OPER EXP'!C16 -> 659500 | D16: ='OPER EXP'!D16 -> 829400 | E16: ='OPER EXP'!E16 -> 1121090 | F16: ='OPER EXP'!F16 -> 1418000 | G16: ='OPER EXP'!G16 -> 1912400
A17: Research & Development | C17: ='OPER EXP'!C25 -> 287500 | D17: ='OPER EXP'!D25 -> 561450 | E17: ='OPER EXP'!E25 -> 773710 | F17: ='OPER EXP'!F25 -> 969000 | G17: ='OPER EXP'!G25 -> 1214800
A18: General and Administration | C18: ='OPER EXP'!C38 -> 620000 | D18: ='OPER EXP'!D38 -> 869450 | E18: ='OPER EXP'!E38 -> 1058190 | F18: ='OPER EXP'!F38 -> 1313666.7 | G18: ='OPER EXP'!G38 -> 1591866.7
A19: Total Operating Expenses | C19: ='OPER EXP'!C41 -> 1567000 | D19: ='OPER EXP'!D41 -> 2260300 | E19: ='OPER EXP'!E41 -> 2952990 | F19: ='OPER EXP'!F41 -> 3700666.7 | G19: ='OPER EXP'!G41 -> 4719066.7
A20: % of Revenues | C20: ='OPER EXP'!C42 -> 0.56981818 | D20: ='OPER EXP'!D42 -> 0.58861979 | E20: ='OPER EXP'!E42 -> 0.49257548 | F20: ='OPER EXP'!F42 -> 0.45574713 | G20: ='OPER EXP'!G42 -> 0.38936194
A22: EARNINGS FROM OPERATIONS | C22: =C12-C19 -> -142528.57 | D22: =D12-D19 -> -336300 | E22: =E12-E19 -> 527952.86 | F22: =F12-F19 -> 1304633.3 | G22: =G12-G19 -> 3337097.6
A24: EXTRAORDINARY INCOME / (EXPENSE) | C24: =EXTRA!C16 -> -120000 | D24: =EXTRA!D16 -> 115000 | E24: =EXTRA!E16 -> 180000 | F24: =EXTRA!F16 -> 260000 | G24: =EXTRA!G16 -> 330000
A26: EARNINGS BEFORE INTEREST & TAXES | C26: =C22+C24 -> -262528.57 | D26: =D22+D24 -> -221300 | E26: =E22+E24 -> 707952.86 | F26: =F22+F24 -> 1564633.3 | G26: =G22+G24 -> 3667097.6
A28: INTEREST INCOME / (EXPENSE) | C28: =-FUNDING!C41+FUNDING!C45 -> -214100 | D28: =-FUNDING!D41+FUNDING!D45 -> -195300 | E28: =-FUNDING!E41+FUNDING!E45 -> -219600 | F28: =-FUNDING!F41+FUNDING!F45 -> -124000 | G28: =-FUNDING!G41+FUNDING!G45 -> -87200
A30: NET EARNINGS BEFORE TAXES | C30: =C26+C28 -> -476628.57 | D30: =D26+D28 -> -416600 | E30: =E26+E28 -> 488352.86 | F30: =F26+F28 -> 1440633.3 | G30: =G26+G28 -> 3579897.6
A32: TAXES | C32: =TAXES!C14 -> 0 | D32: =TAXES!D14 -> 0 | E32: =TAXES!E14 -> 0 | F32: =TAXES!F14 -> -414303.05 | G32: =TAXES!G14 -> -1431959
A34: NET EARNINGS | C34: =C30+C32 -> -476628.57 | D34: =D30+D32 -> -416600 | E34: =E30+E32 -> 488352.86 | F34: =F30+F32 -> 1026330.3 | G34: =G30+G32 -> 2147938.6
A35: % of Revenues | C35: =C34/C7 -> -0.17331948 | D35: =D34/D7 -> -0.10848958 | E35: =E34/E7 -> 0.081460026 | F35: =F34/F7 -> 0.12639536 | G35: =G34/G7 -> 0.17722265

Sheet BALANCE
A1: XYZ Company | M1: Checksum | N1: =SUM(B9:G9,C10:G14,B13:B14,B15:G15,C19:G23,B22:B23,B19,B25:G25,C28:G32,B31:B32,B28:B29) -> 1.7303034e+08
A2: Balance Sheet
A3: Years 1 to 5
A4: ($)
B5: Begin | C5: Year 1 | D5: Year 2 | E5: Year 3 | F5: Year 4 | G5: Year 5
A7: ASSETS
A8: CURRENT ASSETS
A9: Cash | B9: =FUNDING!B6 -> 2500000 | C9: =CASHFLOW!C34 -> 3439333.3 | D9: =CASHFLOW!D34 -> 3394540 | E9: =CASHFLOW!E34 -> 3474425 | F9: =CASHFLOW!F34 -> 3360047 | G9: =CASHFLOW!G34 -> 4297937.9
A10: Accounts Receivable | C10: =WORKCAP!C12 -> 304333.33 | D10: =WORKCAP!D12 -> 318720 | E10: =WORKCAP!E12 -> 497585 | F10: =WORKCAP!F12 -> 673960 | G10: =WORKCAP!G12 -> 1005960
A11: Inventories | C11: =WORKCAP!C19 -> 304333.33 | D11: =WORKCAP!D19 -> 318720 | E11: =WORKCAP!E19 -> 401665 | F11: =WORKCAP!F19 -> 544040 | G11: =WORKCAP!G19 -> 812040
A12: Other Current Assets | C12: =WORKCAP!C25 -> 36666.667 | D12: =WORKCAP!D25 -> 38400 | E12: =WORKCAP!E25 -> 59950 | F12: =WORKCAP!F25 -> 81200 | G12: =WORKCAP!G25 -> 121200
A13: Total Current Assets | B13: =SUM(B9:B12) -> 2500000 | C13: =SUM(C9:C12) -> 4084666.7 | D13: =SUM(D9:D12) -> 4070380 | E13: =SUM(E9:E12) -> 4433625 | F13: =SUM(F9:F12) -> 4659247 | G13: =SUM(G9:G12) -> 6237137.9
A14: PROPERTY & EQUIPMENT | B14: ='PROP & EQUIP'!B53 -> 0 | C14: ='PROP & EQUIP'!C53 -> 244371.43 | D14: ='PROP & EQUIP'!D53 -> 603871.43 | E14: ='PROP & EQUIP'!E53 -> 923014.29 | F14: ='PROP & EQUIP'!F53 -> 1204847.6 | G14: ='PROP & EQUIP'!G53 -> 1437895.2
A15: TOTAL ASSETS | B15: =B13+B14 -> 2500000 | C15: =C13+C14 -> 4329038.1 | D15: =D13+D14 -> 4674251.4 | E15: =E13+E14 -> 5356639.3 | F15: =F13+F14 -> 5864094.6 | G15: =G13+G14 -> 7675033.1
A17: LIABILITIES & SHAREHOLDERS' EQUITY
A18: CURRENT LIABILITIES
A19: Short Term Debt | B19: =FUNDING!B18 -> 0 | C19: =FUNDING!C18 -> 450000 | D19: =FUNDING!D18 -> 350000 | E19: =FUNDING!E18 -> 800000 | F19: =FUNDING!F18 -> 100000 | G19: =FUNDING!G18 -> 0
A20: Accounts Payable & Accrued Expen | C20: =WORKCAP!C31 -> 319000 | D20: =WORKCAP!D31 -> 334080 | E20: =WORKCAP!E31 -> 521565 | F20: =WORKCAP!F31 -> 706440 | G20: =WORKCAP!G31 -> 1054440
A21: Other Current Liab | C21: =WORKCAP!C37 -> 36666.667 | D21: =WORKCAP!D37 -> 38400 | E21: =WORKCAP!E37 -> 59950 | F21: =WORKCAP!F37 -> 81200 | G21: =WORKCAP!G37 -> 121200
A22: Current portion of long term debt | B22: =FUNDING!B22 -> 0 | C22: =FUNDING!C22 -> 250000 | D22: =FUNDING!D22 -> 275000 | E22: =FUNDING!E22 -> 300000 | F22: =FUNDING!F22 -> 325000 | G22: =FUNDING!G22 -> 350000
A23: Total Current Liabilities | B23: =SUM(B19:B22) -> 0 | C23: =SUM(C19:C22) -> 1055666.7 | D23: =SUM(D19:D22) -> 997480 | E23: =SUM(E19:E22) -> 1681515 | F23: =SUM(F19:F22) -> 1212640 | G23: =SUM(G19:G22) -> 1525640
A25: LONG TERM DEBT (less current portion) | B25: =FUNDING!B23 -> 0 | C25: =FUNDING!C23 -> 2250000 | D25: =FUNDING!D23 -> 2100000 | E25: =FUNDING!E23 -> 1800000 | F25: =FUNDING!F23 -> 1400000 | G25: =FUNDING!G23 -> 1000000
A27: STOCKHOLDERS' EQUITY
A28: CommonStock | B28: =FUNDING!B8 -> 1500000 | C28: =FUNDING!C8 -> 500000 | D28: =FUNDING!D8 -> 750000 | E28: =FUNDING!E8 -> 600000 | F28: =FUNDING!F8 -> 1000000 | G28: =FUNDING!G8 -> 800000
A29: Preferred Stock | B29: =FUNDING!B13 -> 1200000 | C29: =FUNDING!C13 -> 1200000 | D29: =FUNDING!D13 -> 1950000 | E29: =FUNDING!E13 -> 1950000 | F29: =FUNDING!F13 -> 1950000 | G29: =FUNDING!G13 -> 1950000
A30: Retained Earnings | C30: =FUNDING!C52 -> -476628.57 | D30: =FUNDING!D52 -> -923228.57 | E30: =FUNDING!E52 -> -474875.71 | F30: =FUNDING!F52 -> 501454.57 | G30: =FUNDING!G52 -> 2599393.1
A31: Total Equity | B31: =SUM(B28:B30) -> 2700000 | C31: =SUM(C28:C30) -> 1223371.4 | D31: =SUM(D28:D30) -> 1776771.4 | E31: =SUM(E28:E30) -> 2075124.3 | F31: =SUM(F28:F30) -> 3451454.6 | G31: =SUM(G28:G30) -> 5349393.1
A32: TOTAL LIABILITIES & EQUITY | B32: =B23+B25+B31 -> 2700000 | C32: =C23+C25+C31 -> 4529038.1 | D32: =D23+D25+D31 -> 4874251.4 | E32: =E23+E25+E31 -> 5556639.3 | F32: =F23+F25+F31 -> 6064094.6 | G32: =G23+G25+G31 -> 7875033.1

Sheet CASHFLOW
A1: XYZ Company
A2: Cash Flow Statememt
A3: Years 1 to 5
A4: ($)
C5: Year 1 | D5: Year 2 | E5: Year 3 | F5: Year 4 | G5: Year 5
A6: OPERATING ACTIVITIES
A7: Net Earnings | C7: =INCOME!C34 -> -476628.57 | D7: =INCOME!D34 -> -416600 | E7: =INCOME!E34 -> 488352.86 | F7: =INCOME!F34 -> 1026330.3 | G7: =INCOME!G34 -> 2147938.6
A8: Depreciation | C8: ='PROP & EQUIP'!C47 -> 45128.571 | D8: ='PROP & EQUIP'!D47 -> 133500 | E8: ='PROP & EQUIP'!E47 -> 250857.14 | F8: ='PROP & EQUIP'!F47 -> 383166.67 | G8: ='PROP & EQUIP'!G47 -> 516952.38
A9: Working Capital Changes
A10: (Increase)/Decrease Accounts Receivable | C10: =WORKCAP!C13 -> -304333.33 | D10: =WORKCAP!D13 -> -14386.667 | E10: =WORKCAP!E13 -> -178865 | F10: =WORKCAP!F13 -> -176375 | G10: =WORKCAP!G13 -> -332000
A11: (Increase)/Decrease Inventories | C11: =WORKCAP!C20 -> -304333.33 | D11: =WORKCAP!D20 -> -14386.667 | E11: =WORKCAP!E20 -> -82945 | F11: =WORKCAP!F20 -> -142375 | G11: =WORKCAP!G20 -> -268000
A12: (Increase)/Decrease Other Current Assets | C12: =WORKCAP!C26 -> -36666.667 | D12: =WORKCAP!D26 -> -1733.3333 | E12: =WORKCAP!E26 -> -21550 | F12: =WORKCAP!F26 -> -21250 | G12: =WORKCAP!G26 -> -40000
A13: Increase/(Decrease) Accts Pay & Accrd Expenses | C13: =WORKCAP!C32 -> 319000 | D13: =WORKCAP!D32 -> 15080 | E13: =WORKCAP!E32 -> 187485 | F13: =WORKCAP!F32 -> 184875 | G13: =WORKCAP!G32 -> 348000
A14: Increase/(Decrease) Other Current Liab | C14: =WORKCAP!C38 -> 36666.667 | D14: =WORKCAP!D38 -> 1733.3333 | E14: =WORKCAP!E38 -> 21550 | F14: =WORKCAP!F38 -> 21250 | G14: =WORKCAP!G38 -> 40000
A15: Net Cash Provided/(Used) by Operating Activities | C15: =SUM(C7:C14) -> -721166.67 | D15: =SUM(D7:D14) -> -296793.33 | E15: =SUM(E7:E14) -> 664885 | F15: =SUM(F7:F14) -> 1275622 | G15: =SUM(G7:G14) -> 2412891
A17: INVESTING ACTIVITIES
A18: Property & Equipment | C18: =-'PROP & EQUIP'!C13 -> -289500 | D18: =-'PROP & EQUIP'!D13 -> -493000 | E18: =-'PROP & EQUIP'!E13 -> -570000 | F18: =-'PROP & EQUIP'!F13 -> -665000 | G18: =-'PROP & EQUIP'!G13 -> -750000
A19: Other
A20: Net Cash Used in Investing Activities | C20: =SUM(C18:C19) -> -289500 | D20: =SUM(D18:D19) -> -493000 | E20: =SUM(E18:E19) -> -570000 | F20: =SUM(F18:F19) -> -665000 | G20: =SUM(G18:G19) -> -750000
A22: FINANCING ACTIVITIES
A23: Increase/(Decrease) Short Term Debt | C23: =FUNDING!C19 -> 450000 | D23: =FUNDING!D19 -> -100000 | E23: =FUNDING!E19 -> 450000 | F23: =FUNDING!F19 -> -700000 | G23: =FUNDING!G19 -> -100000
A24: Increase/(Decrease) Curr. Portion LTD | C24: =FUNDING!C27 -> 250000 | D24: =FUNDING!D27 -> 25000 | E24: =FUNDING!E27 -> 25000 | F24: =FUNDING!F27 -> 25000 | G24: =FUNDING!G27 -> 25000
A25: Increase/(Decrease) Long Term Debt | C25: =FUNDING!C28 -> 2250000 | D25: =FUNDING!D28 -> -150000 | E25: =FUNDING!E28 -> -300000 | F25: =FUNDING!F28 -> -400000 | G25: =FUNDING!G28 -> -400000
A26: Increase/(Decrease) Common Stock | C26: =FUNDING!C9 -> -1000000 | D26: =FUNDING!D9 -> 250000 | E26: =FUNDING!E9 -> -150000 | F26: =FUNDING!F9 -> 400000 | G26: =FUNDING!G9 -> -200000
A27: Increase/(Decrease) Preferred Stock | C27: =FUNDING!C14 -> 0 | D27: =FUNDING!D14 -> 750000 | E27: =FUNDING!E14 -> 0 | F27: =FUNDING!F14 -> 0 | G27: =FUNDING!G14 -> 0
A28: Dividends Declared | C28: =-FUNDING!C49 -> 0 | D28: =-FUNDING!D49 -> -30000 | E28: =-FUNDING!E49 -> -40000 | F28: =-FUNDING!F49 -> -50000 | G28: =-FUNDING!G49 -> -50000
A29: Net Cash Provided / (Used) by Financing | C29: =SUM(C23:C28) -> 1950000 | D29: =SUM(D23:D28) -> 745000 | E29: =SUM(E23:E28) -> -15000 | F29: =SUM(F23:F28) -> -725000 | G29: =SUM(G23:G28) -> -725000
A31: INCREASE/(DECREASE) IN CASH | C31: =C15+C20+C29 -> 939333.33 | D31: =D15+D20+D29 -> -44793.333 | E31: =E15+E20+E29 -> 79885 | F31: =F15+F20+F29 -> -114378.05 | G31: =G15+G20+G29 -> 937890.95
A33: CASH AT BEGINNING OF YEAR | C33: =B34 -> 2500000 | D33: =C34 -> 3439333.3 | E33: =D34 -> 3394540 | F33: =E34 -> 3474425 | G33: =F34 -> 3360047
A34: CASH AT END OF YEAR | B34: =BALANCE!B9 -> 2500000 | C34: =C33+C31 -> 3439333.3 | D34: =D33+D31 -> 3394540 | E34: =E33+E31 -> 3474425 | F34: =F33+F31 -> 3360047 | G34: =G33+G31 -> 4297937.9

Sheet BREAKEVEN
A1: XYZ Company
A2: Break-Even Analysis
A3: Years 1 to 5
A4: ($)
C5: Year 1 | D5: Year 2 | E5: Year 3 | F5: Year 4 | G5: Year 5
A6: Revenue | C6: =REVENUE!C16 -> 2750000 | D6: =REVENUE!D16 -> 3840000 | E6: =REVENUE!E16 -> 5995000 | F6: =REVENUE!F16 -> 8120000 | G6: =REVENUE!G16 -> 12120000
A8: ='COST OF REV'!A9 -> Cost of Revenue | B8: ='COST OF REV'!B9 -> 0
A9: Variable | C9: ='COST OF REV'!C36 -> 571400 | D9: ='COST OF REV'!D36 -> 954050 | E9: ='COST OF REV'!E36 -> 1422500 | F9: ='COST OF REV'!F36 -> 1899400 | G9: ='COST OF REV'!G36 -> 2701800
A10: Fixed | C10: ='COST OF REV'!C37 -> 754128.57 | D10: ='COST OF REV'!D37 -> 961950 | E10: ='COST OF REV'!E37 -> 1091557.1 | F10: ='COST OF REV'!F37 -> 1215300 | G10: ='COST OF REV'!G37 -> 1362035.7
A11: Total | C11: ='COST OF REV'!C38 -> 1325528.6 | D11: ='COST OF REV'!D38 -> 1916000 | E11: ='COST OF REV'!E38 -> 2514057.1 | F11: ='COST OF REV'!F38 -> 3114700 | G11: ='COST OF REV'!G38 -> 4063835.7
A13: Operating Expenses
A14: Variable | C14: ='OPER EXP'!C45 -> 440000 | D14: ='OPER EXP'!D45 -> 614400 | E14: ='OPER EXP'!E45 -> 959200 | F14: ='OPER EXP'!F45 -> 1299200 | G14: ='OPER EXP'!G45 -> 1939200
A15: Fixed | C15: ='OPER EXP'!C46 -> 1127000 | D15: ='OPER EXP'!D46 -> 1645900 | E15: ='OPER EXP'!E46 -> 1993790 | F15: ='OPER EXP'!F46 -> 2401466.7 | G15: ='OPER EXP'!G46 -> 2779866.7
A16: Total | C16: ='OPER EXP'!C47 -> 1567000 | D16: ='OPER EXP'!D47 -> 2260300 | E16: ='OPER EXP'!E47 -> 2952990 | F16: ='OPER EXP'!F47 -> 3700666.7 | G16: ='OPER EXP'!G47 -> 4719066.7
A18: Total Costs & Expenses
A19: Variable | C19: =C9+C14 -> 1011400 | D19: =D9+D14 -> 1568450 | E19: =E9+E14 -> 2381700 | F19: =F9+F14 -> 3198600 | G19: =G9+G14 -> 4641000
A20: Fixed | C20: =C10+C15 -> 1881128.6 | D20: =D10+D15 -> 2607850 | E20: =E10+E15 -> 3085347.1 | F20: =F10+F15 -> 3616766.7 | G20: =G10+G15 -> 4141902.4
A21: Total | C21: =C19+C20 -> 2892528.6 | D21: =D19+D20 -> 4176300 | E21: =E19+E20 -> 5467047.1 | F21: =F19+F20 -> 6815366.7 | G21: =G19+G20 -> 8782902.4
A23: Variable Costs/Revenue Ratio | C23: =C19/C6 -> 0.36778182 | D23: =D19/D6 -> 0.40845052 | E23: =E19/E6 -> 0.39728107 | F23: =F19/F6 -> 0.39391626 | G23: =G19/G6 -> 0.38292079
A25: Break-Even Point Revenues | C25: =C20/(1-C19/C6) -> 2975442.1 | D25: =D20/(1-D19/D6) -> 4408507 | E25: =E20/(1-E19/E6) -> 5119048 | F25: =F20/(1-F19/F6) -> 5967437.2 | G25: =G20/(1-G19/G6) -> 6712108.2

Sheet INCOME-MOS
A1: XYZ Company
A2: Income Statements
A3: 5 Years by Months & Quarters
A4: ($)
A6: =A1 -> XYZ Company
A7: Income Statement | P7: Year 1
A8: Year 1 by Months | O8: Total | P8: Annual
C9: Month 1 | D9: Month 2 | E9: Month 3 | F9: Month 4 | G9: Month 5 | H9: Month 6 | I9: Month 7 | J9: Month 8 | K9: Month 9 | L9: Month 10 | M9: Month 11 | N9: Month 12 | O9: 12 Months | P9: Projection
A11: NET REVENUES | C11: =REVENUE!C22 -> 0 | D11: =REVENUE!C23 -> 0 | E11: =REVENUE!C24 -> 0 | F11: =REVENUE!C26 -> 305555.56 | G11: =REVENUE!C27 -> 305555.56 | H11: =REVENUE!C28 -> 305555.56 | I11: =REVENUE!C30 -> 305555.56 | J11: =REVENUE!C31 -> 305555.56 | K11: =REVENUE!C32 -> 305555.56 | L11: =REVENUE!C34 -> 305555.56 | M11: =REVENUE!C35 -> 305555.56 | N11: =REVENUE!C36 -> 305555.56 | O11: =SUM(C11:N11) -> 2750000 | P11: =INCOME!C7 -> 2750000
