Workbook

Sheet T-12
A1: Income Statement (Date Range)
A2: Exported On: 03/05/2025 12:09 PM
A4: Company1804 Living, LLC
A5: Properties: Active
A6: Date Range: 01/01/2024 to 12/31/2024
A7: Accounting Basis: Accrual
A8: GL Account Map: None - use master chart of accounts
A9: Level of Detail: Detail View
A10: Include Zero Balance GL Accounts: No
A12: Account Name | B12: Selected Period
A13: Operating Income & Expense
A14: Income | E14: Purchase Price | F14: 75000000
A15: Gross Potential Rent | B15: 5616927.7 | C15: =SUM(B15:B23) -> 4992407.2 | E15: Mortgage in place | F15: 55300000
A16: Gain/Loss to Lease | B16: -165399.58
A17: Vacancy | B17: -409793.39
A18: CONCESSIONS
A19: One-Time Concessions | B19: -7676 | E19: Case Study
A20: Hometown Hero Discount | B20: -2474.19 | E20: 1. Create financial model including NOI pro-forma, rent sensitivities, value sensitivities, sales comps
A21: Employee Units | B21: -12647.58 | E21: 2. What changed between projections (See OM) and outcome.
A22: Other Concession | B22: -1866 | E22: 2. Estimate refinance options with bank, Company1219 and agency
A23: Total CONCESSIONS | B23: -24663.77 | E23: 3. Provide recommendation for refinance / sale
A24: Interest Income | B24: 16653.78
A25: OTHER INCOME
A26: Application Fee Income | B26: 33120
A27: CO Inspection Fee | B27: 3290
A28: Monthly Amenity Fee | B28: 117883.55
A29: Annual Amenity Fee | B29: 600
A30: Transfer Fee | B30: 3000
A31: Company0240 Insurance Services | B31: 5893.5
A32: Company0240 Insurance Admin Fees | B32: 1063
A33: One-Time Pet Fee | B33: 7150
A34: Pet Rent | B34: 8826.58
A35: Resident Parking | B35: 213565.33
A36: NSF Fees Collected | B36: 1275
A37: Late Fee | B37: 9300
... A46: Total Operating Income | B46: 5516477.5
A47: Expense
A48: PAYROLL COSTS
A49: Property Manager | B49: 23999.21
A50: Assistant Property Manager | B50: 61573.69
...

Sheet Rent Roll
A1: Rent Roll
A2: Exported On: 03/05/2025 12:10 PM
A4: Properties: Transit Plaza (New) - 1 West Dickerson Street Dover, NJ 07801
A5: Units: Active
A6: As of: 03/01/2025
A7: Include Non-Revenue Units: No
A9: Unit | B9: Tenant | C9: Status | D9: Market Rent | E9: Rent | F9: Lease From | G9: Lease To | H9: Move-in | I9: Past Due
A10: Transit Plaza (New) - 1 West Dickerson Street Dover, NJ 07801
A11: 338 | B11: Person1214 Person0154 | C11: Current | D11: 2060 | E11: 1945 | F11: 44434 | G11: 45747 | H11: 44434 | I11: 0
A12: 223 | B12: Person1210 S. Person0622 | C12: Current | D12: 2095 | E12: 2095 | F12: 44974 | G12: 46081 | H12: 44974 | I12: 61.5
A13: 102 | B13: Person1210 A. Person0666 | C13: Current | D13: 2550 | E13: 2440 | F13: 45564 | G13: 45930 | H13: 45564 | I13: 0
A14: 130 | B14: Person1197 A. Person0718 | C14: Current | D14: 2455 | E14: 2350 | F14: 45381 | G14: 46112 | H14: 45381 | I14: 0
A15: 317 | B15: Person1275 G. Person1112 | C15: Current | D15: 2275 | E15: 2195 | F15: 45658 | G15: 46022 | H15: 45658 | I15: 0
A16: 354 | B16: Person1275 A. Person1148 Person0325 | C16: Notice-Unrented | D16: 2160 | E16: 2040 | F16: 45383 | G16: 45747 | H16: 45383 | I16: 0
A17: 417 | B17: Person1275 A. Person0531 | C17: Current | D17: 2080 | E17: 2080 | F17: 45627 | G17: 45991 | H17: 45627 | I17: 0
A18: 201 | B18: Person1161 D. Person0030 Person1091 | C18: Current | D18: 2450 | E18: 2350 | F18: 45505 | G18: 45869 | H18: 45505 | I18: 0
A19: 208 | B19: Person1159 B. Person0147 | C19: Current | D19: 2055 | E19: 1975 | F19: 45564 | G19: 45838 | H19: 45564 | I19: 0
A20: 346 | B20: Person1272 Person1082 | C20: Current | D20: 2100 | E20: 1975 | F20: 44440 | G20: 45930 | H20: 44440 | I20: 0
A21: 150 | B21: Person1272 I. Person0846 | C21: Current | D21: 2180 | E21: 2025 | F21: 44925 | G21: 45838 | H21: 44925 | I21: 2178
A22: 415 | B22: Person1155 Person0212 | C22: Current | D22: 2195 | E22: 2095 | F22: 45536 | G22: 45900 | H22: 45536 | I22: 2248
... A42: 327 | B42: Person1261 Person0377 | C42: Current | D42: 2185 | E42: 2045 | F42: 44317 | G42: 45838 | H42: 44317 | I42: 0
A43: 436 | B43: Person1028 V. Person1157 | C43: Current | D43: 2450 | E43: 2350 | F43: 44870 | H43: 44870 | I43: 2766.5
A44: 133 | B44: Person1026 S. Person0304 | C44: Current | D44: 2350 | E44: 2295 | F44: 45535 | G44: 45900 | H44: 45535 | I44: 0
A45: 347 | B45: Person1025 Person0417 | C45: Current | D45: 2160 | E45: 2025 | F45: 44470 | G45: 45777 | H45: 44470 | I45: 0
A46: 410 | B46: Person0975 Person0374 | C46: Current | D46: 2240 | E46: 1995 | F46: 44501 | G46: 46022 | H46: 44501 | I46: 2258.5
A47: 220 | B47: Person0968 Person1167 | C47: Notice-Unrented | D47: 3100 | E47: 2800 | F47: 45139 | G47: 45838 | H47: 45139 | I47: 3100
A48: 122 | B48: Person0963 C. Person1128 | C48: Current | D48: 2095 | E48: 1995 | F48: 45019 | G48: 46112 | H48: 45019 | I48: 0
A49: 153 | B49: Person1259 Person1031 Person0209 | C49: Current | D49: 2180 | E49: 2050 | F49: 44926 | G49: 46022 | H49: 44926 | I49: 0
A50: 245 | B50: Person1259 Person0877 | C50: Current | D50: 2100 | E50: 2000 | F50: 44401 | G50: 45900 | H50: 44401 | I50: 0
A51: 205 | B51: Person1259 F. Person0634 | C51: Current | D51: 2550 | E51: 2465 | F51: 45156 | G51: 45869 | H51: 45156 | I51: 0
A52: 111 | B52: Person0956 A. Person1082 | C52: Current | D52: 2175 | E52: 2175 | F52: 45647 | G52: 46022 | H52: 45647 | I52: 0
A53: 443 | B53: Person0951 G. Person0233 | C53: Current | D53: 2100 | E53: 1970 | F53: 44407 | G53: 46053 | H53: 44407 | I53: 0
A54: 237 | B54: Person0948 N. Person0324 | C54: Current | D54: 2195 | E54: 2170 | F54: 45245 | G54: 46053 | H54: 45245 | I54: 0
A55: 241 | B55: Person0947 A. Person0624 | C55: Current | D55: 2060 | E55: 1945 | F55: 45465 | G55: 45838 | H55: 45465 | I55: 0
... A84: 304 | B84: Person0738 Person0214 | C84: Current | D84: 2350 | E84: 2050 | F84: 44575 | G84: 45716 | H84: 44575 | I84: 2116.5
A85: 152 | B85: Person0735 Person0783 | C85: Current | D85: 2165 | E85: 2040 | F85: 45031 | H85: 45031 | I85: 0
A86: 441 | B86: Person0729 M. Person0043 | C86: Current | D86: 2060 | E86: 1970 | F86: 44926 | G86: 46022 | H86: 44926 | I86: 0
A87: 209 | B87: Person0684 Person0762 | C87: Current | D87: 2475 | E87: 2220 | F87: 44455 | G87: 45930 | H87: 44455 | I87: 0
A88: 240 | B88: Person0683 M. Person1241 Person1254 | C88: Current | D88: 2185 | E88: 2100 | F88: 45296 | G88: 45838 | H88: 45296 | I88: 0
A89: 407 | B89: Person0680 Person0125 | C89: Current | D89: 2290 | E89: 2130 | F89: 44618 | G89: 45747 | H89: 44618 | I89: 0
...

Sheet Summary
A2: Propert Address | C2: 1 W Dickerson St | E2: Unit Mix | L2: Pro Forma
A3: City | C3: Dover | E3: ='Unit Mix'!A2 -> Unit Type | F3: ='Unit Mix'!B2 -> # of Units | G3: ='Unit Mix'!C2 -> SF | H3: ='Unit Mix'!D2 -> Monthly Avg Rent | I3: ='Unit Mix'!E2 -> Annual Rent | J3: ='Unit Mix'!F2 -> Annual $/SF | L3: ='Pro Forma'!A3 -> Resi Gross Potential Rent | M3: ='Pro Forma'!B3 -> 5894124.1
A4: State | C4: NJ | E4: ='Unit Mix'!A3 -> 1BD | F4: ='Unit Mix'!B3 -> 53 | G4: ='Unit Mix'!C3 -> 650 | H4: ='Unit Mix'!D3 -> 2050 | I4: ='Unit Mix'!E3 -> 1303800 | J4: ='Unit Mix'!F3 -> 37.846154 | L4: ='Pro Forma'!A4 -> Vacancy | M4: ='Pro Forma'!B4 -> -294706.2
A5: Zip Code | C5: 7801 | E5: ='Unit Mix'!A4 -> 1 BD + Den | F5: ='Unit Mix'!B4 -> 70 | G5: ='Unit Mix'!C4 -> 725 | H5: ='Unit Mix'!D4 -> 2150 | I5: ='Unit Mix'!E4 -> 1806000 | J5: ='Unit Mix'!F4 -> 35.586207 | L5: ='Pro Forma'!A5 -> Bed Debt | M5: ='Pro Forma'!B5 -> -353647.44
A6: Year Built | C6: 2021 | E6: ='Unit Mix'!A5 -> 2 BD | F6: ='Unit Mix'!B5 -> 84 | G6: ='Unit Mix'!C5 -> 850 | H6: ='Unit Mix'!D5 -> 2450 | I6: ='Unit Mix'!E5 -> 2469600 | J6: ='Unit Mix'!F5 -> 34.588235 | L6: ='Pro Forma'!A6 -> Net Rental Income | M6: =SUM(M3:M5) -> 5245770.4
E7: ='Unit Mix'!A6 -> 2BD + 2 BA | F7: ='Unit Mix'!B6 -> 7 | G7: ='Unit Mix'!C6 -> 1100 | H7: ='Unit Mix'!D6 -> 2800 | I7: ='Unit Mix'!E6 -> 235200 | J7: ='Unit Mix'!F6 -> 30.545455 | L7: ='Pro Forma'!A7 -> Other Income | M7: ='Pro Forma'!B7 -> 438229.2
A8: Property Details | E8: ='Unit Mix'!A7 -> Total | F8: ='Unit Mix'!B7 -> 214 | G8: ='Unit Mix'!C7 -> 767.75701 | H8: ='Unit Mix'!D7 -> 2264.2523 | I8: ='Unit Mix'!E7 -> 5814600 | J8: ='Unit Mix'!F7 -> 35.39014 | L8: ='Pro Forma'!A8 -> Net Revenue | M8: =SUM(M6:M7) -> 5683999.6
A9: # of Units | C9: ='Unit Mix'!B7 -> 214
A10: Gross SF | C10: 0 | L10: ='Pro Forma'!A9 -> Expenses
A11: NSF | C11: ='Unit Mix'!C7*'Unit Mix'!B7 -> 164300 | E11: Sources and Uses | L11: ='Pro Forma'!A10 -> Taxes | M11: ='Pro Forma'!B10 -> -563378.61
A12: # of Parking Spaces Covered | C12: 283 | E12: Sources | G12: $/Unit | H12: % of Total | L12: ='Pro Forma'!A11 -> Insurance | M12: ='Pro Forma'!B11 -> -195015.67
A13: # of Parking Spaces uncovered | C13: 0 | E13: Equity | F13: =F15-F14 -> 22450000 | G13: =F13/$C$9 -> 104906.54 | H13: =F13/$F$15 -> 0.29636964 | L13: ='Pro Forma'!A12 -> Payroll | M13: ='Pro Forma'!B12 -> -292523.51
E14: Debt | F14: =C32 -> 53300000 | G14: =F14/$C$9 -> 249065.42 | H14: =F14/$F$15 -> 0.70363036 | L14: ='Pro Forma'!A13 -> Repairs & Maintnence | M14: ='Pro Forma'!B13 -> -97507.836
A15: Acquisition Info | E15: Total | F15: =F19 -> 75750000 | G15: =F15/$C$9 -> 353971.96 | H15: =F15/$F$15 -> 1 | L15: ='Pro Forma'!A14 -> Contract Services | M15: ='Pro Forma'!B14 -> -164679.9
A16: Purchase Price | C16: 75000000 | E16: Uses | L16: ='Pro Forma'!A15 -> Marketing | M16: ='Pro Forma'!B15 -> -108342.04
A17: Acquisition Date | C17: 45778 | E17: Purchase Price | F17: =C16 -> 75000000 | G17: =F17/$C$9 -> 350467.29 | H17: =F17/$F$19 -> 0.99009901 | L17: ='Pro Forma'!A16 -> General & Administrative | M17: ='Pro Forma'!B16 -> -67172.065
A18: T-12 NOI | C18: ='T-12'!B149 -> 1892128.2 | E18: Closing Cost | F18: =C16*C23 -> 750000 | G18: =F18/$C$9 -> 3504.6729 | H18: =F18/$F$19 -> 0.0099009901 | L18: ='Pro Forma'!A17 -> Utilities | M18: ='Pro Forma'!B17 -> -132177.29
A19: Going In Cap Rate | C19: =C18/C16 -> 0.025228375 | E19: Total | F19: =SUM(F17:F18) -> 75750000 | G19: =F19/$C$9 -> 353971.96 | H19: =F19/$F$19 -> 1 | L19: ='Pro Forma'!A18 -> Reserves | M19: ='Pro Forma'!B18 -> -235501.17
A20: Price/Unit | C20: =C16/C9 -> 350467.29 | L20: ='Pro Forma'!A19 -> Management | M20: ='Pro Forma'!B19 -> -176625.88
A21: Price/GSF | C21: =IFERROR(C16/C10,0) -> 0 | E21: Returns | L21: ='Pro Forma'!A20 -> Total Expenses | M21: =SUM(M11:M20) -> -2032924
A22: Price/NSF | C22: =IFERROR(C16/C11,0) -> 456.48205 | E22: Unlevered IRR | F22: =XIRR('Monthly Cash Flow Statement'!E34:BY34,'Monthly Cash Flow Statement'!E4:BY4) -> 0.00048516095 | L22: ='Pro Forma'!A21 -> Net Operating Income | M22: =M21+M8 -> 3651075.7
A23: Closing Cost | C23: 0.01 | E23: Levered IRR | F23: =XIRR('Monthly Cash Flow Statement'!E38:BY38,'Monthly Cash Flow Statement'!E4:BY4,) -> 0.11376533
E24: Unlevered Equity Multiple | F24: =SUMIF('Monthly Cash Flow Statement'!E34:BY34,">0",'Monthly Cash Flow Statement'!E34:BY34)/ABS(SUMIF('Monthly Cash Flow Statement'!E34:BY34,"<0",'Monthly Cash Flow Statement'!E34:BY34)) -> 1.0013952 | L24: Projected Value | M24: =M22/C27 -> 60851261
A25: Exit Assumptions | E25: Levered Equity Multiple | F25: =SUMIF('Monthly Cash Flow Statement'!E38:BY38,">0",'Monthly Cash Flow Statement'!E38:BY38)/ABS(SUMIF('Monthly Cash Flow Statement'!E38:BY38,"<0",'Monthly Cash Flow Statement'!E38:BY38)) -> 1.2671392
A26: Month | C26: 36
A27: Exit Cap Rate | C27: 0.06
A28: Cost of Sale | C28: 0.02
A31: Exisiting Loan Info
A32: Exisiting Mortgage | C32: 53300000
A33: Lender | C33: Company1921
A34: Floating/Fixed | C34: Fixed
A35: Term | C35: 5+5
A36: Rate | C36: 0.0335
A37: I/O Period (MTHs) | C37: 24
A38: Amortization | C38: 30
A40: Bank Refinance Loan Info | D40: Company1219 Refinance Loan Info | G40: Agency Refinance Loan Info
A41: LTV Constraint | C41: 0.65 | D41: LTV Constraint | F41: 0.85 | G41: LTV Constraint | I41: 0.75
A42: DSCR Constraint | C42: 1.25 | D42: DSCR Constraint | F42: 1.15 | G42: DSCR Constraint | I42: 1.2
A43: Debt Yield Constraint | C43: 0.08 | D43: Debt Yield Constraint | G43: Debt Yield Constraint
A44: Cap Rate | C44: =$C$27 -> 0.06 | D44: Cap Rate | F44: =$C$27 -> 0.06 | G44: Cap Rate | I44: =$C$27 -> 0.06
...

Sheet Unit Mix
A1: Unit Mix
A2: Unit Type | B2: # of Units | C2: SF | D2: Monthly Avg Rent | E2: Annual Rent | F2: Annual $/SF
A3: 1BD | B3: 53 | C3: 650 | D3: 2050 | E3: =D3*B3*12 -> 1303800 | F3: =E3/(C3*B3) -> 37.846154
A4: 1 BD + Den | B4: 70 | C4: 725 | D4: 2150 | E4: =D4*B4*12 -> 1806000 | F4: =E4/(C4*B4) -> 35.586207
A5: 2 BD | B5: 84 | C5: 850 | D5: 2450 | E5: =D5*B5*12 -> 2469600 | F5: =E5/(C5*B5) -> 34.588235
A6: 2BD + 2 BA | B6: 7 | C6: 1100 | D6: 2800 | E6: =D6*B6*12 -> 235200 | F6: =E6/(C6*B6) -> 30.545455
A7: Total | B7: =SUM(B3:B6) -> 214 | C7: =SUMPRODUCT(B3:B6,C3:C6)/B7 -> 767.75701 | D7: =SUMPRODUCT(D3:D6,$B$3:$B$6)/B7 -> 2264.2523 | E7: =SUM(E3:E6) -> 5814600 | F7: =E7/(C7*B7) -> 35.39014
A10: Other Income
A11: Item | B11: $/Unit/MTH | C11: Monthly Income | D11: Annual Income
A12: Pet Fees & Rent | B12: 6 | C12: =B12*$B$7 -> 1284 | D12: =C12*12 -> 15408
A13: Application Fee | B13: 12.5 | C13: =B13*$B$7 -> 2675 | D13: =C13*12 -> 32100
A14: Ammenity Fees | B14: 45 | C14: =B14*$B$7 -> 9630 | D14: =C14*12 -> 115560
A15: Parking | B15: 83 | C15: =B15*$B$7 -> 17762 | D15: =C15*12 -> 213144
A16: Tranfer Fee | B16: 1.15 | C16: =B16*$B$7 -> 246.1 | D16: =C16*12 -> 2953.2
A17: Late Fee | B17: 3.5 | C17: =B17*$B$7 -> 749 | D17: =C17*12 -> 8988
A18: Lockout Fee | B18: 0.5 | C18: =B18*$B$7 -> 107 | D18: =C18*12 -> 1284
A19: Move-Out Charges | B19: 2.5 | C19: =B19*$B$7 -> 535 | D19: =C19*12 -> 6420
A20: Termination Fees | B20: 14 | C20: =B20*$B$7 -> 2996 | D20: =C20*12 -> 35952
A21: Company0241 Insurance & Fees | B21: 2.5 | C21: =B21*$B$7 -> 535 | D21: =C21*12 -> 6420
A22: Total | B22: =SUM(B12:B21) -> 170.65 | C22: =B22*$B$7 -> 36519.1 | D22: =C22*12 -> 438229.2

Sheet Expenses
A1: Annual Expenses T-12 | F1: Pro Forma Annual Expenses
A2: Item | B2: Annual Expense | C2: $/Unit | F2: Item | G2: Annual Expense | H2: $/Unit
A3: Taxes | B3: ='T-12'!B137 -> 548581.38 | C3: =B3/Summary!$C$9 -> 2563.4644 | F3: Taxes | G3: =H3*Summary!$C$9 -> 556400 | H3: 2600
A4: Insurance | B4: ='T-12'!B134 -> 188164.07 | C4: =B4/Summary!$C$9 -> 879.27136 | F4: Insurance | G4: =H4*Summary!$C$9 -> 192600 | H4: 900
A5: Payroll | B5: ='T-12'!B60 -> 292281.22 | C5: =B5/Summary!$C$9 -> 1365.8001 | F5: Payroll | G5: =H5*Summary!$C$9 -> 288900 | H5: 1350
A6: Repairs & Maintnence | B6: ='T-12'!B77 -> 92128.74 | C6: =B6/Summary!$C$9 -> 430.50813 | F6: Repairs & Maintnence | G6: =H6*Summary!$C$9 -> 96300 | H6: 450
A7: Contract Services | B7: ='T-12'!B87 -> 161902.5 | C7: =B7/Summary!$C$9 -> 756.55374 | F7: Contract Services | G7: =H7*Summary!$C$9 -> 162640 | H7: 760
A8: Marketing | B8: ='T-12'!B102 -> 132627.59 | C8: =B8/Summary!$C$9 -> 619.75509 | F8: Marketing | G8: =H8*Summary!$C$9 -> 107000 | H8: 500
A9: General & Administrative | B9: ='T-12'!B119 -> 66145.92 | C9: =B9/Summary!$C$9 -> 309.09308 | F9: General & Administrative | G9: =H9*Summary!$C$9 -> 66340 | H9: 310
A10: Utilities | B10: ='T-12'!B125 -> 129975.04 | C10: =B10/Summary!$C$9 -> 607.36 | F10: Utilities | G10: =H10*Summary!$C$9 -> 130540 | H10: 610
A11: Management | B11: ='T-12'!B128 -> 168000 | C11: =B11/Summary!$C$9 -> 785.04673 | E11: 0.04 | F11: Reserves | G11: =E11*'Unit Mix'!$E$7 -> 232584 | H11: =G11/Summary!$C$9 -> 1086.8411
A12: Total | B12: =SUM(B3:B11) -> 1779806.5 | C12: =B12/Summary!$C$9 -> 8316.8526 | E12: 0.03 | F12: Management | G12: =E12*'Unit Mix'!$E$7 -> 174438 | H12: =G12/Summary!$C$9 -> 815.13084
F13: Total | G13: =SUM(G3:G12) -> 2007742 | H13: =G13/Summary!$C$9 -> 9381.972

Sheet Pro Forma
A1: 5-Yr Pro Forma
A2: Year | B2: 1 | C2: =B2+1 -> 2 | D2: =C2+1 -> 3 | E2: =D2+1 -> 4 | F2: =E2+1 -> 5
A3: Resi Gross Potential Rent | B3: =SUMIF('Monthly Cash Flow Statement'!$F$2:$BY$2,'Pro Forma'!B2,'Monthly Cash Flow Statement'!$F$5:$BY$5) -> 5894124.1 | C3: =SUMIF('Monthly Cash Flow Statement'!$F$2:$BY$2,'Pro Forma'!C2,'Monthly Cash Flow Statement'!$F$5:$BY$5) -> 6070947.8 | D3: =SUMIF('Monthly Cash Flow Statement'!$F$2:$BY$2,'Pro Forma'!D2,'Monthly Cash Flow Statement'!$F$5:$BY$5) -> 6253076.2 | E3: =SUMIF('Monthly Cash Flow Statement'!$F$2:$BY$2,'Pro Forma'!E2,'Monthly Cash Flow Statement'!$F$5:$BY$5) -> 6440668.5 | F3: =SUMIF('Monthly Cash Flow Statement'!$F$2:$BY$2,'Pro Forma'!F2,'Monthly Cash Flow Statement'!$F$5:$BY$5) -> 6633888.6
A4: Vacancy | B4: =SUMIF('Monthly Cash Flow Statement'!$F$2:$BY$2,'Pro Forma'!B2,'Monthly Cash Flow Statement'!$F$6:$BY$6) -> -294706.2 | C4: =SUMIF('Monthly Cash Flow Statement'!$F$2:$BY$2,'Pro Forma'!C2,'Monthly Cash Flow Statement'!$F6:$BY6) -> -303547.39 | D4: =SUMIF('Monthly Cash Flow Statement'!$F$2:$BY$2,'Pro Forma'!D2,'Monthly Cash Flow Statement'!$F6:$BY6) -> -312653.81 | E4: =SUMIF('Monthly Cash Flow Statement'!$F$2:$BY$2,'Pro Forma'!E2,'Monthly Cash Flow Statement'!$F6:$BY6) -> -322033.43 | F4: =SUMIF('Monthly Cash Flow Statement'!$F$2:$BY$2,'Pro Forma'!F2,'Monthly Cash Flow Statement'!$F6:$BY6) -> -331694.43
A5: Bed Debt | B5: =SUMIF('Monthly Cash Flow Statement'!$F$2:$BY$2,'Pro Forma'!B2,'Monthly Cash Flow Statement'!$F$7:$BY$7) -> -353647.44 | C5: =SUMIF('Monthly Cash Flow Statement'!$F$2:$BY$2,'Pro Forma'!C2,'Monthly Cash Flow Statement'!$F$7:$BY$7) -> -364256.87 | D5: =SUMIF('Monthly Cash Flow Statement'!$F$2:$BY$2,'Pro Forma'!D2,'Monthly Cash Flow Statement'!$F$7:$BY$7) -> -375184.57 | E5: =SUMIF('Monthly Cash Flow Statement'!$F$2:$BY$2,'Pro Forma'!E2,'Monthly Cash Flow Statement'!$F$7:$BY$7) -> -386440.11 | F5: =SUMIF('Monthly Cash Flow Statement'!$F$2:$BY$2,'Pro Forma'!F2,'Monthly Cash Flow Statement'!$F$7:$BY$7) -> -398033.31
A6: Net Rental Income | B6: =SUM(B3:B5) -> 5245770.4 | C6: =SUM(C3:C5) -> 5403143.5 | D6: =SUM(D3:D5) -> 5565237.8 | E6: =SUM(E3:E5) -> 5732195 | F6: =SUM(F3:F5) -> 5904160.8
A7: Other Income | B7: =SUMIF('Monthly Cash Flow Statement'!$F$2:$BY$2,'Pro Forma'!B2,'Monthly Cash Flow Statement'!$F$9:$BY$9) -> 438229.2 | C7: =SUMIF('Monthly Cash Flow Statement'!$F$2:$BY$2,'Pro Forma'!C2,'Monthly Cash Flow Statement'!$F$9:$BY$9) -> 438229.2 | D7: =SUMIF('Monthly Cash Flow Statement'!$F$2:$BY$2,'Pro Forma'!D2,'Monthly Cash Flow Statement'!$F$9:$BY$9) -> 438229.2 | E7: =SUMIF('Monthly Cash Flow Statement'!$F$2:$BY$2,'Pro Forma'!E2,'Monthly Cash Flow Statement'!$F$9:$BY$9) -> 438229.2 | F7: =SUMIF('Monthly Cash Flow Statement'!$F$2:$BY$2,'Pro Forma'!F2,'Monthly Cash Flow Statement'!$F$9:$BY$9) -> 438229.2
A8: Net Revenue | B8: =SUM(B6:B7) -> 5683999.6 | C8: =SUM(C6:C7) -> 5841372.7 | D8: =SUM(D6:D7) -> 6003467 | E8: =SUM(E6:E7) -> 6170424.2 | F8: =SUM(F6:F7) -> 6342390
A9: Expenses
A10: =Expenses!F3 -> Taxes | B10: =SUMIF('Monthly Cash Flow Statement'!$F$2:$BY$2,'Pro Forma'!B$2,'Monthly Cash Flow Statement'!$F12:$BY12) -> -563378.61 | C10: =SUMIF('Monthly Cash Flow Statement'!$F$2:$BY$2,'Pro Forma'!C$2,'Monthly Cash Flow Statement'!$F12:$BY12) -> -578871.52 | D10: =SUMIF('Monthly Cash Flow Statement'!$F$2:$BY$2,'Pro Forma'!D$2,'Monthly Cash Flow Statement'!$F12:$BY12) -> -594790.49 | E10: =SUMIF('Monthly Cash Flow Statement'!$F$2:$BY$2,'Pro Forma'!E$2,'Monthly Cash Flow Statement'!$F12:$BY12) -> -611147.22 | F10: =SUMIF('Monthly Cash Flow Statement'!$F$2:$BY$2,'Pro Forma'!F$2,'Monthly Cash Flow Statement'!$F12:$BY12) -> -627953.77
A11: =Expenses!F4 -> Insurance | B11: =SUMIF('Monthly Cash Flow Statement'!$F$2:$BY$2,'Pro Forma'!B$2,'Monthly Cash Flow Statement'!$F13:$BY13) -> -195015.67 | C11: =SUMIF('Monthly Cash Flow Statement'!$F$2:$BY$2,'Pro Forma'!C$2,'Monthly Cash Flow Statement'!$F13:$BY13) -> -200378.6 | D11: =SUMIF('Monthly Cash Flow Statement'!$F$2:$BY$2,'Pro Forma'!D$2,'Monthly Cash Flow Statement'!$F13:$BY13) -> -205889.01 | E11: =SUMIF('Monthly Cash Flow Statement'!$F$2:$BY$2,'Pro Forma'!E$2,'Monthly Cash Flow Statement'!$F13:$BY13) -> -211550.96 | F11: =SUMIF('Monthly Cash Flow Statement'!$F$2:$BY$2,'Pro Forma'!F$2,'Monthly Cash Flow Statement'!$F13:$BY13) -> -217368.61
A12: =Expenses!F5 -> Payroll | B12: =SUMIF('Monthly Cash Flow Statement'!$F$2:$BY$2,'Pro Forma'!B$2,'Monthly Cash Flow Statement'!$F14:$BY14) -> -292523.51 | C12: =SUMIF('Monthly Cash Flow Statement'!$F$2:$BY$2,'Pro Forma'!C$2,'Monthly Cash Flow Statement'!$F14:$BY14) -> -300567.9 | D12: =SUMIF('Monthly Cash Flow Statement'!$F$2:$BY$2,'Pro Forma'!D$2,'Monthly Cash Flow Statement'!$F14:$BY14) -> -308833.52 | E12: =SUMIF('Monthly Cash Flow Statement'!$F$2:$BY$2,'Pro Forma'!E$2,'Monthly Cash Flow Statement'!$F14:$BY14) -> -317326.44 | F12: =SUMIF('Monthly Cash Flow Statement'!$F$2:$BY$2,'Pro Forma'!F$2,'Monthly Cash Flow Statement'!$F14:$BY14) -> -326052.92
A13: =Expenses!F6 -> Repairs & Maintnence | B13: =SUMIF('Monthly Cash Flow Statement'!$F$2:$BY$2,'Pro Forma'!B$2,'Monthly Cash Flow Statement'!$F15:$BY15) -> -97507.836 | C13: =SUMIF('Monthly Cash Flow Statement'!$F$2:$BY$2,'Pro Forma'!C$2,'Monthly Cash Flow Statement'!$F15:$BY15) -> -100189.3 | D13: =SUMIF('Monthly Cash Flow Statement'!$F$2:$BY$2,'Pro Forma'!D$2,'Monthly Cash Flow Statement'!$F15:$BY15) -> -102944.51 | E13: =SUMIF('Monthly Cash Flow Statement'!$F$2:$BY$2,'Pro Forma'!E$2,'Monthly Cash Flow Statement'!$F15:$BY15) -> -105775.48 | F13: =SUMIF('Monthly Cash Flow Statement'!$F$2:$BY$2,'Pro Forma'!F$2,'Monthly Cash Flow Statement'!$F15:$BY15) -> -108684.31
A14: =Expenses!F7 -> Contract Services | B14: =SUMIF('Monthly Cash Flow Statement'!$F$2:$BY$2,'Pro Forma'!B$2,'Monthly Cash Flow Statement'!$F16:$BY16) -> -164679.9 | C14: =SUMIF('Monthly Cash Flow Statement'!$F$2:$BY$2,'Pro Forma'!C$2,'Monthly Cash Flow Statement'!$F16:$BY16) -> -169208.6 | D14: =SUMIF('Monthly Cash Flow Statement'!$F$2:$BY$2,'Pro Forma'!D$2,'Monthly Cash Flow Statement'!$F16:$BY16) -> -173861.83 | E14: =SUMIF('Monthly Cash Flow Statement'!$F$2:$BY$2,'Pro Forma'!E$2,'Monthly Cash Flow Statement'!$F16:$BY16) -> -178643.03 | F14: =SUMIF('Monthly Cash Flow Statement'!$F$2:$BY$2,'Pro Forma'!F$2,'Monthly Cash Flow Statement'!$F16:$BY16) -> -183555.72
A15: =Expenses!F8 -> Marketing | B15: =SUMIF('Monthly Cash Flow Statement'!$F$2:$BY$2,'Pro Forma'!B$2,'Monthly Cash Flow Statement'!$F17:$BY17) -> -108342.04 | C15: =SUMIF('Monthly Cash Flow Statement'!$F$2:$BY$2,'Pro Forma'!C$2,'Monthly Cash Flow Statement'!$F17:$BY17) -> -111321.45 | D15: =SUMIF('Monthly Cash Flow Statement'!$F$2:$BY$2,'Pro Forma'!D$2,'Monthly Cash Flow Statement'!$F17:$BY17) -> -114382.79 | E15: =SUMIF('Monthly Cash Flow Statement'!$F$2:$BY$2,'Pro Forma'!E$2,'Monthly Cash Flow Statement'!$F17:$BY17) -> -117528.31 | F15: =SUMIF('Monthly Cash Flow Statement'!$F$2:$BY$2,'Pro Forma'!F$2,'Monthly Cash Flow Statement'!$F17:$BY17) -> -120760.34
A16: =Expenses!F9 -> General & Administrative | B16: =SUMIF('Monthly Cash Flow Statement'!$F$2:$BY$2,'Pro Forma'!B$2,'Monthly Cash Flow Statement'!$F18:$BY18) -> -67172.065 | C16: =SUMIF('Monthly Cash Flow Statement'!$F$2:$BY$2,'Pro Forma'!C$2,'Monthly Cash Flow Statement'!$F18:$BY18) -> -69019.297 | D16: =SUMIF('Monthly Cash Flow Statement'!$F$2:$BY$2,'Pro Forma'!D$2,'Monthly Cash Flow Statement'!$F18:$BY18) -> -70917.327 | E16: =SUMIF('Monthly Cash Flow Statement'!$F$2:$BY$2,'Pro Forma'!E$2,'Monthly Cash Flow Statement'!$F18:$BY18) -> -72867.554 | F16: =SUMIF('Monthly Cash Flow Statement'!$F$2:$BY$2,'Pro Forma'!F$2,'Monthly Cash Flow Statement'!$F18:$BY18) -> -74871.411
A17: =Expenses!F10 -> Utilities | B17: =SUMIF('Monthly Cash Flow Statement'!$F$2:$BY$2,'Pro Forma'!B$2,'Monthly Cash Flow Statement'!$F19:$BY19) -> -132177.29 | C17: =SUMIF('Monthly Cash Flow Statement'!$F$2:$BY$2,'Pro Forma'!C$2,'Monthly Cash Flow Statement'!$F19:$BY19) -> -135812.16 | D17: =SUMIF('Monthly Cash Flow Statement'!$F$2:$BY$2,'Pro Forma'!D$2,'Monthly Cash Flow Statement'!$F19:$BY19) -> -139547 | E17: =SUMIF('Monthly Cash Flow Statement'!$F$2:$BY$2,'Pro Forma'!E$2,'Monthly Cash Flow Statement'!$F19:$BY19) -> -143384.54 | F17: =SUMIF('Monthly Cash Flow Statement'!$F$2:$BY$2,'Pro Forma'!F$2,'Monthly Cash Flow Statement'!$F19:$BY19) -> -147327.62
A18: =Expenses!F11 -> Reserves | B18: =SUMIF('Monthly Cash Flow Statement'!$F$2:$BY$2,'Pro Forma'!B$2,'Monthly Cash Flow Statement'!$F20:$BY20) -> -235501.17 | C18: =SUMIF('Monthly Cash Flow Statement'!$F$2:$BY$2,'Pro Forma'!C$2,'Monthly Cash Flow Statement'!$F20:$BY20) -> -241977.45 | D18: =SUMIF('Monthly Cash Flow Statement'!$F$2:$BY$2,'Pro Forma'!D$2,'Monthly Cash Flow Statement'!$F20:$BY20) -> -248631.83 | E18: =SUMIF('Monthly Cash Flow Statement'!$F$2:$BY$2,'Pro Forma'!E$2,'Monthly Cash Flow Statement'!$F20:$BY20) -> -255469.21 | F18: =SUMIF('Monthly Cash Flow Statement'!$F$2:$BY$2,'Pro Forma'!F$2,'Monthly Cash Flow Statement'!$F20:$BY20) -> -262494.61
A19: =Expenses!F12 -> Management | B19: =SUMIF('Monthly Cash Flow Statement'!$F$2:$BY$2,'Pro Forma'!B$2,'Monthly Cash Flow Statement'!$F21:$BY21) -> -176625.88 | C19: =SUMIF('Monthly Cash Flow Statement'!$F$2:$BY$2,'Pro Forma'!C$2,'Monthly Cash Flow Statement'!$F21:$BY21) -> -181483.09 | D19: =SUMIF('Monthly Cash Flow Statement'!$F$2:$BY$2,'Pro Forma'!D$2,'Monthly Cash Flow Statement'!$F21:$BY21) -> -186473.87 | E19: =SUMIF('Monthly Cash Flow Statement'!$F$2:$BY$2,'Pro Forma'!E$2,'Monthly Cash Flow Statement'!$F21:$BY21) -> -191601.9 | F19: =SUMIF('Monthly Cash Flow Statement'!$F$2:$BY$2,'Pro Forma'!F$2,'Monthly Cash Flow Statement'!$F21:$BY21) -> -196870.96
A20: Total Expenses | B20: =SUM(B10:B19) -> -2032924 | C20: =SUM(C10:C19) -> -2088829.4 | D20: =SUM(D10:D19) -> -2146272.2 | E20: =SUM(E10:E19) -> -2205294.7 | F20: =SUM(F10:F19) -> -2265940.3
A21: Net Operating Income | B21: =B20+B8 -> 3651075.7 | C21: =C20+C8 -> 3752543.4 | D21: =D20+D8 -> 3857194.9 | E21: =E20+E8 -> 3965129.5 | F21: =F20+F8 -> 4076449.7
A23: Exp Ratio | B23: =-B20/B8 -> 0.3576573 | C23: =-C20/C8 -> 0.35759221 | D23: =-D20/D8 -> 0.35750545 | E23: =-E20/E8 -> 0.35739758 | F23: =-F20/F8 -> 0.35726915
A24: NOI/Unit | B24: =B21/Summary!$C$9 -> 17061.101 | C24: =C21/Summary!$C$9 -> 17535.249 | D24: =D21/Summary!$C$9 -> 18024.275 | E24: =E21/Summary!$C$9 -> 18528.643 | F24: =F21/Summary!$C$9 -> 19048.831
A26: Projected Value | B26: =B21/Summary!$C$27 -> 60851261 | C26: =C21/Summary!$C$27 -> 62542389 | D26: =D21/Summary!$C$27 -> 64286581 | E26: =E21/Summary!$C$27 -> 66085492 | F26: =F21/Summary!$C$27 -> 67940829
A27: /Unit | B27: =B26/Summary!$C$9 -> 284351.69 | C27: =C26/Summary!$C$9 -> 292254.16 | D27: =D26/Summary!$C$9 -> 300404.58 | E27: =E26/Summary!$C$9 -> 308810.71 | F27: =F26/Summary!$C$9 -> 317480.51

Sheet Monthly Cash Flow Statement
A1: Rental Growth | B1: 0.03 | D1: Pro Forma 5 - Year Analysis | BM1: 0
A2: Other Income Growth | B2: 0 | D2: Year | F2: 1 | G2: 1 | H2: 1 | I2: 1 | J2: 1 | K2: 1 | L2: 1 | M2: 1 | N2: 1 | O2: 1 | P2: 1 | Q2: 1 | R2: =F2+1 -> 2 | S2: =G2+1 -> 2 | T2: =H2+1 -> 2 | U2: =I2+1 -> 2 | V2: =J2+1 -> 2 | W2: =K2+1 -> 2 | X2: =L2+1 -> 2 | Y2: =M2+1 -> 2 | ... BY2: =BM2+1 -> 6
A3: Expense Growth | B3: 0.0275 | D3: Month | E3: 0 | F3: =E3+1 -> 1 | G3: =F3+1 -> 2 | H3: =G3+1 -> 3 | I3: =H3+1 -> 4 | J3: =I3+1 -> 5 | K3: =J3+1 -> 6 | L3: =K3+1 -> 7 | M3: =L3+1 -> 8 | ... BY3: =BX3+1 -> 72
A4: Vacancy | B4: 0.05 | D4: Month Ending | E4: =Summary!C17 -> 45778 | F4: =EOMONTH(E4,1) -> 45838 | G4: =EOMONTH(F4,1) -> 45869 | H4: =EOMONTH(G4,1) -> 45900 | I4: =EOMONTH(H4,1) -> 45930 | J4: =EOMONTH(I4,1) -> 45961 | K4: =EOMONTH(J4,1) -> 45991 | L4: =EOMONTH(K4,1) -> 46022 | M4: =EOMONTH(L4,1) -> 46053 | ... BY4: =EOMONTH(BX4,1) -> 47999
A5: Bad Debt | B5: 0.06 | D5: Gross Potential Rent | F5: ='Unit Mix'!D7*'Unit Mix'!B7 -> 484550 | G5: =F5*(1+$B$1)^(1/12) -> 485745.03 | H5: =G5*(1+$B$1)^(1/12) -> 486943.01 | I5: =H5*(1+$B$1)^(1/12) -> 488143.94 | J5: =I5*(1+$B$1)^(1/12) -> 489347.84 | K5: =J5*(1+$B$1)^(1/12) -> 490554.7 | L5: =K5*(1+$B$1)^(1/12) -> 491764.54 | M5: =L5*(1+$B$1)^(1/12) -> 492977.36 | N5: =M5*(1+$B$1)^(1/12) -> 494193.18 | ... BY5: =BX5*(1+$B$1)^(1/12) -> 577154.62
A6: Capital Improvements | B6: 0.015 | D6: Vacancy | F6: =F5*-$B$4 -> -24227.5 | G6: =G5*-$B$4 -> -24287.252 | H6: =H5*-$B$4 -> -24347.15 | I6: =I5*-$B$4 -> -24407.197 | J6: =J5*-$B$4 -> -24467.392 | K6: =K5*-$B$4 -> -24527.735 | L6: =L5*-$B$4 -> -24588.227 | M6: =M5*-$B$4 -> -24648.868 | ... BY6: =BY5*-$B$4 -> -28857.731
D7: Bad Debt | F7: =F5*-$B$5 -> -29073 | G7: =G5*-$B$5 -> -29144.702 | H7: =H5*-$B$5 -> -29216.581 | I7: =I5*-$B$5 -> -29288.637 | J7: =J5*-$B$5 -> -29360.87 | K7: =K5*-$B$5 -> -29433.282 | L7: =L5*-$B$5 -> -29505.872 | M7: =M5*-$B$5 -> -29578.642 | ... BY7: =BY5*-$B$5 -> -34629.277
D8: Net Rental Income | F8: =SUM(F5:F7) -> 431249.5 | G8: =SUM(G5:G7) -> 432313.08 | H8: =SUM(H5:H7) -> 433379.28 | I8: =SUM(I5:I7) -> 434448.11 | J8: =SUM(J5:J7) -> 435519.57 | K8: =SUM(K5:K7) -> 436593.68 | L8: =SUM(L5:L7) -> 437670.44 | M8: =SUM(M5:M7) -> 438749.85 | ... BY8: =SUM(BY5:BY7) -> 513667.61
D9: Other Income | F9: ='Unit Mix'!C22 -> 36519.1 | G9: =F9*(1+$B$2)^(1/12) -> 36519.1 | H9: =G9*(1+$B$2)^(1/12) -> 36519.1 | I9: =H9*(1+$B$2)^(1/12) -> 36519.1 | J9: =I9*(1+$B$2)^(1/12) -> 36519.1 | K9: =J9*(1+$B$2)^(1/12) -> 36519.1 | L9: =K9*(1+$B$2)^(1/12) -> 36519.1 | M9: =L9*(1+$B$2)^(1/12) -> 36519.1 | N9: =M9*(1+$B$2)^(1/12) -> 36519.1 | ... BY9: =BX9*(1+$B$2)^(1/12) -> 36519.1
D10: Net Revenue | F10: =F9+F8 -> 467768.6 | G10: =G9+G8 -> 468832.18 | H10: =H9+H8 -> 469898.38 | I10: =I9+I8 -> 470967.21 | J10: =J9+J8 -> 472038.67 | K10: =K9+K8 -> 473112.78 | L10: =L9+L8 -> 474189.54 | M10: =M9+M8 -> 475268.95 | ... BY10: =BY9+BY8 -> 550186.71
D11: Expenses | BM11: 0 | BN11: 0 | BO11: 0 | BP11: 0 | BQ11: 0 | BR11: 0 | BS11: 0 | BT11: 0 | BU11: 0 | BV11: 0 | BW11: 0 | BX11: 0 | BY11: 0
D12: =Expenses!F3 -> Taxes | F12: =-Expenses!$H3/12*'Unit Mix'!$B$7 -> -46366.667 | G12: =F12*(1+$B$3)^(1/12) -> -46471.607 | H12: =G12*(1+$B$3)^(1/12) -> -46576.786 | I12: =H12*(1+$B$3)^(1/12) -> -46682.202 | J12: =I12*(1+$B$3)^(1/12) -> -46787.857 | K12: =J12*(1+$B$3)^(1/12) -> -46893.751 | L12: =K12*(1+$B$3)^(1/12) -> -46999.884 | M12: =L12*(1+$B$3)^(1/12) -> -47106.258 | N12: =M12*(1+$B$3)^(1/12) -> -47212.873 | ... BY12: =BX12*(1+$B$3)^(1/12) -> -54439.614
D13: =Expenses!F4 -> Insurance | F13: =-Expenses!$H4/12*'Unit Mix'!$B$7 -> -16050 | G13: =F13*(1+$B$3)^(1/12) -> -16086.326 | H13: =G13*(1+$B$3)^(1/12) -> -16122.733 | I13: =H13*(1+$B$3)^(1/12) -> -16159.224 | J13: =I13*(1+$B$3)^(1/12) -> -16195.797 | K13: =J13*(1+$B$3)^(1/12) -> -16232.452 | L13: =K13*(1+$B$3)^(1/12) -> -16269.191 | M13: =L13*(1+$B$3)^(1/12) -> -16306.013 | N13: =M13*(1+$B$3)^(1/12) -> -16342.918 | ... BY13: =BX13*(1+$B$3)^(1/12) -> -18844.482
D14: =Expenses!F5 -> Payroll | F14: =-Expenses!$H5/12*'Unit Mix'!$B$7 -> -24075 | G14: =F14*(1+$B$3)^(1/12) -> -24129.488 | H14: =G14*(1+$B$3)^(1/12) -> -24184.1 | I14: =H14*(1+$B$3)^(1/12) -> -24238.836 | J14: =I14*(1+$B$3)^(1/12) -> -24293.695 | K14: =J14*(1+$B$3)^(1/12) -> -24348.678 | L14: =K14*(1+$B$3)^(1/12) -> -24403.786 | M14: =L14*(1+$B$3)^(1/12) -> -24459.019 | N14: =M14*(1+$B$3)^(1/12) -> -24514.376 | ... BY14: =BX14*(1+$B$3)^(1/12) -> -28266.723
D15: =Expenses!F6 -> Repairs & Maintnence | F15: =-Expenses!$H6/12*'Unit Mix'!$B$7 -> -8025 | G15: =F15*(1+$B$3)^(1/12) -> -8043.1628 | H15: =G15*(1+$B$3)^(1/12) -> -8061.3667 | I15: =H15*(1+$B$3)^(1/12) -> -8079.6119 | J15: =I15*(1+$B$3)^(1/12) -> -8097.8983 | K15: =J15*(1+$B$3)^(1/12) -> -8116.2261 | L15: =K15*(1+$B$3)^(1/12) -> -8134.5954 | M15: =L15*(1+$B$3)^(1/12) -> -8153.0063 | N15: =M15*(1+$B$3)^(1/12) -> -8171.4588 | ... BY15: =BX15*(1+$B$3)^(1/12) -> -9422.2409
D16: =Expenses!F7 -> Contract Services | F16: =-Expenses!$H7/12*'Unit Mix'!$B$7 -> -13553.333 | G16: =F16*(1+$B$3)^(1/12) -> -13584.008 | H16: =G16*(1+$B$3)^(1/12) -> -13614.753 | I16: =H16*(1+$B$3)^(1/12) -> -13645.567 | J16: =I16*(1+$B$3)^(1/12) -> -13676.45 | K16: =J16*(1+$B$3)^(1/12) -> -13707.404 | L16: =K16*(1+$B$3)^(1/12) -> -13738.428 | M16: =L16*(1+$B$3)^(1/12) -> -13769.522 | N16: =M16*(1+$B$3)^(1/12) -> -13800.686 | ... BY16: =BX16*(1+$B$3)^(1/12) -> -15913.118
D17: =Expenses!F8 -> Marketing | F17: =-Expenses!$H8/12*'Unit Mix'!$B$7 -> -8916.6667 | G17: =F17*(1+$B$3)^(1/12) -> -8936.8476 | H17: =G17*(1+$B$3)^(1/12) -> -8957.0742 | I17: =H17*(1+$B$3)^(1/12) -> -8977.3465 | J17: =I17*(1+$B$3)^(1/12) -> -8997.6648 | K17: =J17*(1+$B$3)^(1/12) -> -9018.029 | L17: =K17*(1+$B$3)^(1/12) -> -9038.4393 | M17: =L17*(1+$B$3)^(1/12) -> -9058.8958 | N17: =M17*(1+$B$3)^(1/12) -> -9079.3987 | ... BY17: =BX17*(1+$B$3)^(1/12) -> -10469.157
D18: =Expenses!F9 -> General & Administrative | F18: =-Expenses!$H9/12*'Unit Mix'!$B$7 -> -5528.3333 | G18: =F18*(1+$B$3)^(1/12) -> -5540.8455 | H18: =G18*(1+$B$3)^(1/12) -> -5553.386 | I18: =H18*(1+$B$3)^(1/12) -> -5565.9548 | J18: =I18*(1+$B$3)^(1/12) -> -5578.5522 | K18: =J18*(1+$B$3)^(1/12) -> -5591.178 | L18: =K18*(1+$B$3)^(1/12) -> -5603.8324 | M18: =L18*(1+$B$3)^(1/12) -> -5616.5154 | N18: =M18*(1+$B$3)^(1/12) -> -5629.2272 | ... BY18: =BX18*(1+$B$3)^(1/12) -> -6490.8771
D19: =Expenses!F10 -> Utilities | F19: =-Expenses!$H10/12*'Unit Mix'!$B$7 -> -10878.333 | G19: =F19*(1+$B$3)^(1/12) -> -10902.954 | H19: =G19*(1+$B$3)^(1/12) -> -10927.63 | I19: =H19*(1+$B$3)^(1/12) -> -10952.363 | J19: =I19*(1+$B$3)^(1/12) -> -10977.151 | K19: =J19*(1+$B$3)^(1/12) -> -11001.995 | L19: =K19*(1+$B$3)^(1/12) -> -11026.896 | M19: =L19*(1+$B$3)^(1/12) -> -11051.853 | N19: =M19*(1+$B$3)^(1/12) -> -11076.866 | ... BY19: =BX19*(1+$B$3)^(1/12) -> -12772.371
D20: =Expenses!F11 -> Reserves | F20: =-Expenses!$H11/12*'Unit Mix'!$B$7 -> -19382 | G20: =F20*(1+$B$3)^(1/12) -> -19425.867 | H20: =G20*(1+$B$3)^(1/12) -> -19469.833 | I20: =H20*(1+$B$3)^(1/12) -> -19513.899 | J20: =I20*(1+$B$3)^(1/12) -> -19558.064 | K20: =J20*(1+$B$3)^(1/12) -> -19602.33 | L20: =K20*(1+$B$3)^(1/12) -> -19646.695 | M20: =L20*(1+$B$3)^(1/12) -> -19691.161 | N20: =M20*(1+$B$3)^(1/12) -> -19735.728 | ... BY20: =BX20*(1+$B$3)^(1/12) -> -22756.62
D21: =Expenses!F12 -> Management | F21: =-Expenses!$H12/12*'Unit Mix'!$B$7 -> -14536.5 | G21: =F21*(1+$B$3)^(1/12) -> -14569.4 | H21: =G21*(1+$B$3)^(1/12) -> -14602.375 | I21: =H21*(1+$B$3)^(1/12) -> -14635.424 | J21: =I21*(1+$B$3)^(1/12) -> -14668.548 | K21: =J21*(1+$B$3)^(1/12) -> -14701.747 | L21: =K21*(1+$B$3)^(1/12) -> -14735.021 | M21: =L21*(1+$B$3)^(1/12) -> -14768.371 | N21: =M21*(1+$B$3)^(1/12) -> -14801.796 | ... BY21: =BX21*(1+$B$3)^(1/12) -> -17067.465
D22: Total Expenses | F22: =SUM(F12:F21) -> -167311.83 | G22: =SUM(G12:G21) -> -167690.51 | H22: =SUM(H12:H21) -> -168070.04 | I22: =SUM(I12:I21) -> -168450.43 | J22: =SUM(J12:J21) -> -168831.68 | K22: =SUM(K12:K21) -> -169213.79 | L22: =SUM(L12:L21) -> -169596.77 | M22: =SUM(M12:M21) -> -169980.61 | ... BY22: =SUM(BY12:BY21) -> -196442.67
D23: Exp Ratio | F23: =-F22/F10 -> 0.35768077 | G23: =-G22/G10 -> 0.35767704 | H23: =-H22/H10 -> 0.35767316 | I23: =-I22/I10 -> 0.35766912 | J23: =-J22/J10 -> 0.35766493 | K23: =-K22/K10 -> 0.35766058 | L23: =-L22/L10 -> 0.35765607 | M23: =-M22/M10 -> 0.35765141 | ... BY23: =-BY22/BY10 -> 0.35704728
D24: Net Operating Income | F24: =F10+F22 -> 300456.77 | G24: =G10+G22 -> 301141.67 | H24: =H10+H22 -> 301828.34 | I24: =I10+I22 -> 302516.78 | J24: =J10+J22 -> 303207 | K24: =K10+K22 -> 303898.99 | L24: =L10+L22 -> 304592.77 | M24: =M10+M22 -> 305288.34 | ... BY24: =BY10+BY22 -> 353744.05
D25: Capital Improvements | F25: =F24*-$B$6 -> -4506.8515 | G25: =G24*-$B$6 -> -4517.1251 | H25: =H24*-$B$6 -> -4527.4251 | I25: =I24*-$B$6 -> -4537.7517 | J25: =J24*-$B$6 -> -4548.105 | K25: =K24*-$B$6 -> -4558.4849 | L25: =L24*-$B$6 -> -4568.8916 | M25: =M24*-$B$6 -> -4579.3251 | ... BY25: =BY24*-$B$6 -> -5306.1607
D26: Cash Flow Before Debt Service | F26: =SUM(F24:F25) -> 295949.92 | G26: =SUM(G24:G25) -> 296624.55 | H26: =SUM(H24:H25) -> 297300.92 | I26: =SUM(I24:I25) -> 297979.03 | J26: =SUM(J24:J25) -> 298658.89 | K26: =SUM(K24:K25) -> 299340.51 | L26: =SUM(L24:L25) -> 300023.88 | M26: =SUM(M24:M25) -> 300709.02 | ... BY26: =SUM(BY24:BY25) -> 348437.89
D27: Principal Payment | F27: =IF(F3<=Summary!$C$37,0,PPMT(Summary!$C$36/12,'Monthly Cash Flow Statement'!F3,Summary!$C$38*12,Summary!$C$32,0,)) -> 0 | G27: =IF(G3<=Summary!$C$37,0,PPMT(Summary!$C$36/12,'Monthly Cash Flow Statement'!G3,Summary!$C$38*12,Summary!$C$32,0,)) -> 0 | H27: =IF(H3<=Summary!$C$37,0,PPMT(Summary!$C$36/12,'Monthly Cash Flow Statement'!H3,Summary!$C$38*12,Summary!$C$32,0,)) -> 0 | I27: =IF(I3<=Summary!$C$37,0,PPMT(Summary!$C$36/12,'Monthly Cash Flow Statement'!I3,Summary!$C$38*12,Summary!$C$32,0,)) -> 0 | J27: =IF(J3<=Summary!$C$37,0,PPMT(Summary!$C$36/12,'Monthly Cash Flow Statement'!J3,Summary!$C$38*12,Summary!$C$32,0,)) -> 0 | K27: =IF(K3<=Summary!$C$37,0,PPMT(Summary!$C$36/12,'Monthly Cash Flow Statement'!K3,Summary!$C$38*12,Summary!$C$32,0,)) -> 0 | L27: =IF(L3<=Summary!$C$37,0,PPMT(Summary!$C$36/12,'Monthly Cash Flow Statement'!L3,Summary!$C$38*12,Summary!$C$32,0,)) -> 0 | M27: =IF(M3<=Summary!$C$37,0,PPMT(Summary!$C$36/12,'Monthly Cash Flow Statement'!M3,Summary!$C$38*12,Summary!$C$32,0,)) -> 0 | ... BY27: =IF(BY3<=Summary!$C$37,0,PPMT(Summary!$C$36/12,'Monthly Cash Flow Statement'!BY3,Summary!$C$38*12,Summary!$C$32,0,)) -> -104951
D28: Interest Payments | F28: =IPMT(Summary!$C$36/12,'Monthly Cash Flow Statement'!F3,Summary!$C$38*12,Summary!$C$32,0,) -> -148795.83 | G28: =IPMT(Summary!$C$36/12,'Monthly Cash Flow Statement'!G3,Summary!$C$38*12,Summary!$C$32,0,0) -> -148555.46 | H28: =IPMT(Summary!$C$36/12,'Monthly Cash Flow Statement'!H3,Summary!$C$38*12,Summary!$C$32,0,0) -> -148314.41 | I28: =IPMT(Summary!$C$36/12,'Monthly Cash Flow Statement'!I3,Summary!$C$38*12,Summary!$C$32,0,0) -> -148072.69 | J28: =IPMT(Summary!$C$36/12,'Monthly Cash Flow Statement'!J3,Summary!$C$38*12,Summary!$C$32,0,0) -> -147830.3 | K28: =IPMT(Summary!$C$36/12,'Monthly Cash Flow Statement'!K3,Summary!$C$38*12,Summary!$C$32,0,0) -> -147587.23 | L28: =IPMT(Summary!$C$36/12,'Monthly Cash Flow Statement'!L3,Summary!$C$38*12,Summary!$C$32,0,0) -> -147343.48 | M28: =IPMT(Summary!$C$36/12,'Monthly Cash Flow Statement'!M3,Summary!$C$38*12,Summary!$C$32,0,0) -> -147099.05 | N28: =IPMT(Summary!$C$36/12,'Monthly Cash Flow Statement'!N3,Summary!$C$38*12,Summary!$C$32,0,0) -> -146853.94 | ... BY28: =IPMT(Summary!$C$36/12,'Monthly Cash Flow Statement'!BY3,Summary!$C$38*12,Summary!$C$32,0,0) -> -129949.31
D29: Cash Flow After Debt Service | F29: =SUM(F24:F28) -> 443104 | G29: =SUM(G24:G28) -> 444693.63 | H29: =SUM(H24:H28) -> 446287.42 | I29: =SUM(I24:I28) -> 447885.37 | J29: =SUM(J24:J28) -> 449487.49 | K29: =SUM(K24:K28) -> 451093.79 | L29: =SUM(L24:L28) -> 452704.28 | M29: =SUM(M24:M28) -> 454318.98 | ... BY29: =SUM(BY24:BY28) -> 461975.46
D30: Acquisition Price | E30: =-Summary!C16 -> -75000000 | BM30: 0
D31: Closing Cost | E31: =-Summary!F18 -> -750000 | BM31: 0
D32: Sale Proceeds | E32: =IF(E3=Summary!$C$26,((SUM(F24:Q24)/Summary!$C$27)),0) -> 0 | F32: =IF(F3=Summary!$C$26,((SUM(G24:R24)/Summary!$C$27)),0) -> 0 | G32: =IF(G3=Summary!$C$26,((SUM(H24:S24)/Summary!$C$27)),0) -> 0 | H32: =IF(H3=Summary!$C$26,((SUM(I24:T24)/Summary!$C$27)),0) -> 0 | I32: =IF(I3=Summary!$C$26,((SUM(J24:U24)/Summary!$C$27)),0) -> 0 | J32: =IF(J3=Summary!$C$26,((SUM(K24:V24)/Summary!$C$27)),0) -> 0 | K32: =IF(K3=Summary!$C$26,((SUM(L24:W24)/Summary!$C$27)),0) -> 0 | L32: =IF(L3=Summary!$C$26,((SUM(M24:X24)/Summary!$C$27)),0) -> 0 | ... BM32: =IF(BM3=Summary!$C$26,((SUM(BN24:BY24)/Summary!$C$27)),0) -> 0 | BN32: =IF(BN3=Summary!$C$26,((SUM(BO29:BZ29)/Summary!$C$27)),0) -> 0 | BO32: =IF(BO3=Summary!$C$26,((SUM(BP29:CA29)/Summary!$C$27)),0) -> 0 | BP32: =IF(BP3=Summary!$C$26,((SUM(BQ29:CB29)/Summary!$C$27)),0) -> 0 | BQ32: =IF(BQ3=Summary!$C$26,((SUM(BR29:CC29)/Summary!$C$27)),0) -> 0 | BR32: =IF(BR3=Summary!$C$26,((SUM(BS29:CD29)/Summary!$C$27)),0) -> 0 | BS32: =IF(BS3=Summary!$C$26,((SUM(BT29:CE29)/Summary!$C$27)),0) -> 0 | BT32: =IF(BT3=Summary!$C$26,((SUM(BU29:CF29)/Summary!$C$27)),0) -> 0 | BU32: =IF(BU3=Summary!$C$26,((SUM(BV29:CG29)/Summary!$C$27)),0) -> 0 | ... BY32: =IF(BY3=Summary!$C$26,((SUM(BZ29:CK29)/Summary!$C$27)),0) -> 0
D33: Cost Of Sale | E33: =E32*-Summary!$C$28 -> 0 | F33: =F32*-Summary!$C$28 -> 0 | G33: =G32*-Summary!$C$28 -> 0 | H33: =H32*-Summary!$C$28 -> 0 | I33: =I32*-Summary!$C$28 -> 0 | J33: =J32*-Summary!$C$28 -> 0 | K33: =K32*-Summary!$C$28 -> 0 | L33: =L32*-Summary!$C$28 -> 0 | ... BY33: =BY32*-Summary!$C$28 -> 0
D34: Unlevered Cash Flows | E34: =SUM(E30:E33) -> -75750000 | F34: =IF(F3>Summary!$C$26,0,SUM(F26,F30:F33)) -> 295949.92 | G34: =IF(G3>Summary!$C$26,0,SUM(G26,G30:G33)) -> 296624.55 | H34: =IF(H3>Summary!$C$26,0,SUM(H26,H30:H33)) -> 297300.92 | I34: =IF(I3>Summary!$C$26,0,SUM(I26,I30:I33)) -> 297979.03 | J34: =IF(J3>Summary!$C$26,0,SUM(J26,J30:J33)) -> 298658.89 | K34: =IF(K3>Summary!$C$26,0,SUM(K26,K30:K33)) -> 299340.51 | L34: =IF(L3>Summary!$C$26,0,SUM(L26,L30:L33)) -> 300023.88 | M34: =IF(M3>Summary!$C$26,0,SUM(M26,M30:M33)) -> 300709.02 | ... BY34: =IF(BY3>Summary!$C$26,0,SUM(BY26,BY30:BY33)) -> 0
D35: Loan Proceeds | E35: =Summary!C32 -> 53300000 | BM35: 0
D36: Loan Origination Fee | E36: 0 | BM36: 0
D37: Loan Payoff | E37: 0 | F37: =IF(F3=Summary!$C$26,-($E$35+SUM($F$27:F27)),0) -> 0 | G37: =IF(G3=Summary!$C$26,-($E$35+SUM($F$27:G27)),0) -> 0 | H37: =IF(H3=Summary!$C$26,-($E$35+SUM($F$27:H27)),0) -> 0 | I37: =IF(I3=Summary!$C$26,-($E$35+SUM($F$27:I27)),0) -> 0 | J37: =IF(J3=Summary!$C$26,-($E$35+SUM($F$27:J27)),0) -> 0 | K37: =IF(K3=Summary!$C$26,-($E$35+SUM($F$27:K27)),0) -> 0 | L37: =IF(L3=Summary!$C$26,-($E$35+SUM($F$27:L27)),0) -> 0 | M37: =IF(M3=Summary!$C$26,-($E$35+SUM($F$27:M27)),0) -> 0 | ... BY37: =IF(BY3=Summary!$C$26,-($E$35+SUM($F$27:BY27)),0) -> 0
D38: Total Levered Cash Flows | E38: =IF(E3>Summary!$C$26,0,SUM(E29:E33,E35:E37)) -> -22450000 | F38: =IF(F3>Summary!$C$26,0,SUM(F29:F33,F35:F37)) -> 443104 | G38: =IF(G3>Summary!$C$26,0,SUM(G29:G33,G35:G37)) -> 444693.63 | H38: =IF(H3>Summary!$C$26,0,SUM(H29:H33,H35:H37)) -> 446287.42 | I38: =IF(I3>Summary!$C$26,0,SUM(I29:I33,I35:I37)) -> 447885.37 | J38: =IF(J3>Summary!$C$26,0,SUM(J29:J33,J35:J37)) -> 449487.49 | K38: =IF(K3>Summary!$C$26,0,SUM(K29:K33,K35:K37)) -> 451093.79 | L38: =IF(L3>Summary!$C$26,0,SUM(L29:L33,L35:L37)) -> 452704.28 | ... BY38: =IF(BY3>Summary!$C$26,0,SUM(BY29:BY33,BY35:BY37)) -> 0
A84: 1
A85: =A84+1 -> 2
...

Sheet Rent Comps
A1: 1BD
A2: Name | B2: Address | C2: Yr Built | D2: SF | E2: Monthly Rent | F2: Notes
A3: Clinton Manor Apartments | B3: 275-281 W Clinton St Dover, NJ | D3: 610 | E3: 2095 | F3: Inferior
A4: Person0097 Person1178 | B4: 111 East Dewey Ave Dover, NJ | C4: 2015 | D4: 823 | E4: 2165 | F4: comparable
A5: Person0097 Person1178 | B5: 111 East Dewey Ave Dover, NJ | C5: 2015 | D5: 847 | E5: 2171 | F5: comparable
A6: Person0097 Person1178 | B6: 111 East Dewey Ave Dover, NJ | C6: 2015 | D6: 934 | E6: 2255 | F6: comparable
C7: Avg | D7: =AVERAGE(D3:D6) -> 803.5 | E7: =AVERAGE(E3:E6) -> 2171.5
A9: 2BD
A10: Name | B10: Address | C10: Yr Built | D10: SF | E10: Monthly Rent | F10: Notes
A11: Boulder at Rockaway | B11: 10 Mount Pleasant Ave, Dover, NJ | D11: 1077 | E11: 2800 | F11: older / 2BA
A12: Person0097 Person1178 | B12: 111 East Dewey Ave Dover, NJ | C12: 2015 | D12: 1100 | E12: 2625 | F12: comparable / 2BA
A13: Person0097 Person1178 | B13: 111 East Dewey Ave Dover, NJ | C13: 2015 | D13: 1089 | E13: 2720 | F13: comparable / 2BA
A14: Person0097 Person1178 | B14: 111 East Dewey Ave Dover, NJ | C14: 2015 | D14: 1404 | E14: 2815 | F14: comparable / 2BA
C15: Avg | D15: =AVERAGE(D11:D14) -> 1167.5 | E15: =AVERAGE(E11:E14) -> 2740
