Workbook
Name AA.AlternatePriceSourceStartPeriod: "Q1-2018"
Name AA.CIK: "93410"
Name AA.ColorizerVersion: "2.0.4.0"
Name AA.CompareQuarters.LatestMRQ: "Q2-2018"
Name AA.CSIN: "Z99BO00122"
Name AA.CurationVersion: "2023.11.1.0"
Name AA.DBMacroVersion: "1.0.13.0"
Name AA.FreeCashFlow: "TRUE"
Name AA.HardcodeChecker.LatestMRQ: "Q3-2019"
Name AA.ModelChecks.LatestMRQ: "Q3-2021"
Name AA.ModelChecks.LatestVersionNumber: "2.38.12.0"
Name AA.ModelColorScheme: "Classic"
Name AA.ModelVersion: "Q1-2026.23"
Name AA.NonLibraryWideCurationVersion: "D"
Name AA.PartialUpdate.BsAvailable: "FALSE"
Name AA.PartialUpdate.CfsAvailable: "FALSE"
Name AA.PartialUpdate.IsAvailable: "TRUE"
Name AA.PeriodLayout: "QFY"
Name AA.PersonalMacro.VersionNumber: "1.6.1.0"
Name AA.RowNameEnforcerVersion: "2023.11.1.0"
Name AA.SessionToUploadId: ""
Name AA.StartWorkModelVersion: "Q1-2026.21"
Name AA.StartWorkType: ""
Name AA.SubyearType: "Q"
Name AA.TemplateUpgradeAttempted: "TRUE"
Name AA.TemplateVersion: "7.5.4.0"
Name AA.UpdateType: "Regular"
Name AA.VerifyUnitsAtModelVersion: "Q1-2018.22"
Name CR.42.Gal.Per.Boe: 42
Name CR.6Mcf.Per.Boe: 6
Name FP.DataSource: 'Front Page'!$H$16
Name FP.DataSourceName: 'Front Page'!$H$15
Name FP.Disclaimer: 'Front Page'!$C$22
Name FP.LastPrice: 'Front Page'!$H$20
Name FP.LastPriceDate: 'Front Page'!$F$20
Name FP.RealTimeToggle: 'Front Page'!$H$18
Name FP.UpdateDate: 'Front Page'!$H$11
Name FP.UpdateEvent: 'Front Page'!$H$13
Name FP_Comment: 'Front Page'!$M$13:$P$20
Name FP_StockPriceOverride: 'Front Page'!$C$20:$H$20
Name GD.CompanyName: Guidance!$B$1
Name GD.MRQ: Guidance!$F$2
Name GD_Difference_Mid_Absolute: Guidance!$P:$P
Name GD_Difference_Mid_Relative: Guidance!$Q:$Q
Name GD_Guidance_High: Guidance!$J:$J
Name GD_Guidance_Low: Guidance!$I:$I
Name GD_Guidance_Mid: Guidance!$K:$K
Name GD_Header_Column: Guidance!$5:$5
Name GD_Header_Section: Guidance!$4:$4
Name GD_Index: Guidance!$A:$A
Name GD_Item: Guidance!$D:$D
Name GD_Item_BasePeriod: Guidance!$G:$G
Name GD_Item_FiscalPeriod: Guidance!$F:$F
Name GD_Item_Name: Guidance!$E:$E
Name GD_Model_Output: Guidance!$N:$N
Name GD_Model_Type: Guidance!$M:$M
Name GD_Type: Guidance!$B:$B
Name GD_Update_Date: Guidance!$S:$S
Name GD_Update_Link: Guidance!$T:$T
Name HP.MRFX: Model!$B$914

Sheet Front Page
M6: Please contact this email for any model-specific questions:
M7: person@example.com
C9: Company Model: | H9: =Model!A1 -> Company0670 Company0697
C11: Updated: | H11: =OFFSET('Update Log'!$C$10,1,0,1,1) -> 46149
M12: Comments on Model:
C13: For: | H13: =OFFSET('Update Log'!$E$10,1,0,1,1) -> Quarterly (Earnings Report) | M13: On October 23, 2023, the company announced the definitive agreement to acquire all outstanding shares of Company1245 Company0697 in an all-stock transaction valued at $53 billion. Company1245 shareholders will receive 1.025 shares of Company0670 for each Company1245 share. The acquisition is expected to close in the first half of 2024. The acquisition is subject to Company1245 shareholder approval and has not been modelled.
C15: Consensus Data and Real-Time Stock Price: | H15: Bloomberg
H16: =IF(FP.DataSourceName="Bloomberg",1,IF(FP.DataSourceName="Capital IQ",2,IF(FP.DataSourceName="FactSet",3,IF(FP.DataSourceName="Refinitiv",4)))) -> 1
C18: Real-Time Stock Price: | H18: OFF
C20: Stock Price Override: | F20: 46148 | H20: 185.16
C22: DISCLAIMER Access to and use of this model, including the data contained herein (this "Model") is subject to Company2747, Inc.'s (a successor entity to Source Financial Modeling Company0697) ("Company") Terms of Use that you accepted prior to accessing this Model, the applicable Service Agreement between the Company and you (or a corporate entity that has authorized you to access and use this Model on its behalf in accordance with the terms of such Service Agreement) or other similar agreement between you and the Company. BY CONTINUING TO ACCESS OR USE THIS MODEL, YOU EXPRESSLY AGREE TO THE TERMS AND CONDITIONS OF SUCH AGREEMENTS. The Company and certain of its licensors have exclusive proprietary rights in this Model. This Model is being provided for internal use only. Unless prior written consent by the Company and its licensors has been provided to you, you may not distribute or otherwise furnish this Model to any third party, nor use or permit anyone to use this Model for any unlawful or unauthorized purpose. IF YOU HAVE UNLAWFULLY OBTAINED, OR ARE NOT AUTHORIZED TO USE THIS MODEL, YOU ARE OBLIGATED TO PROMPTLY: (I) RETURN THIS MODEL (AND ANY DERIVATIVE WORKS ARISING FROM OR RELATING THERETO) TO THE AUTHORIZED USER OF THIS MODEL; (II) PROVIDE NOTICE TO THE COMPANY AT person@example.com OF SUCH UNLAWFUL OR UNAUTHORIZED ACCESS AND USE; AND, (III) CERTIFY THAT YOU HAVE DESTROYED THIS MODEL (AND ANY DERIVATIVE WORKS ARISING FROM OR RELATING THERETO) AND ANY COPIES FROM YOUR SYSTEMS SO AS TO ENSURE THEY ARE INCAPABLE OF RETRIEVAL. A portion of the data contained in this Model may be powered by third party contributors and their respective licensors, or derived from data provided by such contributors, including (but not limited to): (i) QuoteMedia Inc.: A portion of the market data is powered by Quotemedia.com. All rights reserved. Data delayed 15 minutes unless otherwise indicated; (ii) S&P Global Market Intelligence LLC: Copyright (c) {{YEAR}} S&P Global Market Intelligence LLC (and its affiliates as applicable). All rights reserved. Reproduction of any information, opinions, views, data or material, including ratings ("Content") in any form is prohibited except with the prior written permission of the relevant party. Such party, its affiliates and suppliers ("Content Providers") do not guarantee the accuracy, adequacy, completeness, timeliness or availability of any Content and are not responsible for any errors or omissions (negligent or otherwise), regardless of the cause, or for the results obtained from the use of such Content. In no event shall Content Providers be liable for any damages, costs, expenses, legal fees, or losses (including lost income or lost profit and opportunity costs) in connection with any use of the Content. A reference to a particular investment or security, a rating or any observation concerning an investment that is part of the Content is not a recommendation to buy, sell or hold such investment or security, does not address the suitability of an investment or security and should not be relied on as investment advice. Credit ratings are statements of opinions and are not statements of fact; and, (iii) Refinitiv Canada Holdings Limited: A portion of the information may be provided by or derived from data provided by Refinitiv. By accessing or using this Model (including any portion of the data contained herein) you expressly represent that such access or use does not constitute a violation of any applicable law or regulation to which you or the securities are subject. This Model does not constitute investment advice by the Company or any of its licensors. Reference to a particular investment or security, credit rating or any observation concerning a security or investment in this Model is not a recommendation or solicitation to buy, sell or hold such investment or security or make any other investment decisions. For greater certainty, any forecasts or forward-looking information expressed herein are for illustrative purposes only and do not purport to express any view on what may transpire. Neither the Company nor any of its licensors have performed company-specific research on any projected information, as such, it is your responsibility to express your own views on projected results. This Model does not guarantee future performance and undue reliance should not be placed on such. You are solely responsible for evaluating the merits and risks of any investment based on your own business and financial expertise, the business and financial expertise of professional advisors with whom you have consulted, your financial situation and risk tolerance. Neither the Company, nor any of its licensors, undertake any liability with respect to your reliance on this Model. This Model is a quantitative tool with no investment views. The Company and its respective directors, officers, employees, agents, contractors, and affiliates may hold long or short positions in the security to which this Model relates, based on their personal views, and may initiate or close out any positions in such security at any time without any notice. THIS MODEL IS PROVIDED "AS IS" AND ON AN "AS AVAILABLE" BASIS ONLY, WITHOUT WARRANTIES OR CONDITIONS OF ANY KIND. NEITHER THE COMPANY NOR ANY OF ITS LICENSORS NOR THEIR RESPECTIVE AFFILIATES OR SUPPLIERS HAVE LIABILITY FOR THE ACCURACY, TIMELINESS OR COMPLETENESS OF THIS MODEL, OR FOR DELAYS, INTERRUPTIONS OR OMISSIONS HEREIN, NOR FOR ANY LOST PROFITS, INDIRECT, SPECIAL OR CONSEQUENTIAL DAMAGES. Access to data in this Model that is sourced from third party contributors is subject to termination in the event that any agreement between the Company and such third party contributors terminates for any reason. Copyright 2023 Company2747. All rights reserved.

Sheet Model
A1: Company0670 Company0697
A2: =CHOOSE(MO.DataSourceIndex,MO.Ticker.Bloomberg,MO.Ticker.CapIQ,MO.Ticker.FactSet,MO.Ticker.Thomson) -> Ticker0006 US | C2: =EOMONTH(C4,-12) -> 39813
A3: =HP.TradeCurrency -> USD | B3: =IF(MO.RealTime="OFF",MO.LastPriceHardcoded,MO.LastPriceFormula) -> 185.16 | C3: =C4-C2 -> 365 | D3: =D4-C4 -> 365 | E3: =E4-D4 -> 365 | F3: =F4-E4 -> 366 | G3: =G4-F4 -> 90 | H3: =H4-G4 -> 91 | I3: =I4-H4 -> 92 | J3: =J4-I4 -> 92 | K3: =K4-F4 -> 365 | L3: =L4-K4 -> 90 | M3: =M4-L4 -> 91 | N3: =N4-M4 -> 92 | O3: =O4-N4 -> 92 | P3: =P4-K4 -> 365 | Q3: =Q4-P4 -> 90 | R3: =R4-Q4 -> 91 | S3: =S4-R4 -> 92 | T3: =T4-S4 -> 92 | U3: =U4-P4 -> 365 | V3: =V4-U4 -> 91 | W3: =W4-V4 -> 91 | X3: =X4-W4 -> 92 | Y3: =Y4-X4 -> 92 | Z3: =Z4-U4 -> 366 | AA3: =AA4-Z4 -> 90 | AB3: =AB4-AA4 -> 91 | AC3: =AC4-AB4 -> 92 | AD3: =AD4-AC4 -> 92 | AE3: =AE4-Z4 -> 365 | AF3: =AF4-AE4 -> 90 | AG3: =AG4-AF4 -> 91 | AH3: =AH4-AG4 -> 92 | AI3: =AI4-AH4 -> 92 | AJ3: =AJ4-AE4 -> 365 | AK3: =AK4-AJ4 -> 90 | AL3: =AL4-AK4 -> 91 | AM3: =AM4-AL4 -> 92 | AN3: =AN4-AM4 -> 92 | AO3: =AO4-AJ4 -> 365 | AP3: =AP4-AO4 -> 91 | AQ3: =AQ4-AP4 -> 91 | AR3: =AR4-AQ4 -> 92 | AS3: =AS4-AR4 -> 92 | AT3: =AT4-AO4 -> 366 | AU3: =AU4-AT4 -> 90 | AV3: =AV4-AU4 -> 91 | AW3: =AW4-AV4 -> 92 | AX3: =AX4-AW4 -> 92 | AY3: =AY4-AT4 -> 365 | AZ3: =AZ4-AY4 -> 90 | BA3: =BA4-AZ4 -> 91 | BB3: =BB4-BA4 -> 92 | BC3: =BC4-BB4 -> 92 | BD3: =BD4-AY4 -> 365 | BE3: =BE4-BD4 -> 90 | BF3: =BF4-BE4 -> 91 | BG3: =BG4-BF4 -> 92 | BH3: =BH4-BG4 -> 92 | BI3: =BI4-BD4 -> 365 | BJ3: =BJ4-BI4 -> 91 | BK3: =BK4-BJ4 -> 91 | BL3: =BL4-BK4 -> 92 | BM3: =BM4-BL4 -> 92 | BN3: =BN4-BI4 -> 366 | BO3: =BO4-BN4 -> 90 | BP3: =BP4-BO4 -> 91 | BQ3: =BQ4-BP4 -> 92 | BR3: =BR4-BQ4 -> 92 | BS3: =BS4-BN4 -> 365 | BT3: =BT4-BS4 -> 90 | BU3: =BU4-BT4 -> 91 | BV3: =BV4-BU4 -> 92 | BW3: =BW4-BV4 -> 92 | BX3: =BX4-BS4 -> 365 | BY3: =BY4-BX4 -> 90 | BZ3: =BZ4-BY4 -> 91 | CA3: =CA4-BZ4 -> 92 | CB3: =CB4-CA4 -> 92 | CC3: =CC4-BX4 -> 365 | CD3: =CD4-CC4 -> 366 | CE3: =CE4-CD4 -> 365 | CF3: =CF4-CE4 -> 365
A4: =FP.DataSourceName -> Bloomberg | B4: =IF(AND(MO.RealTimeStockPriceToggle,MO.LastPriceFormula<>"N/A"),"ON","OFF") -> OFF | C4: 40178 | D4: =EOMONTH(C4,12) -> 40543 | E4: =EOMONTH(D4,12) -> 40908 | F4: =EOMONTH(E4,12) -> 41274 | G4: =EOMONTH(F4,3) -> 41364 | H4: =EOMONTH(G4,3) -> 41455 | I4: =EOMONTH(H4,3) -> 41547 | J4: =EOMONTH(I4,3) -> 41639 | K4: =J4 -> 41639 | L4: =EOMONTH(K4,3) -> 41729 | M4: =EOMONTH(L4,3) -> 41820 | N4: =EOMONTH(M4,3) -> 41912 | O4: =EOMONTH(N4,3) -> 42004 | P4: =O4 -> 42004 | Q4: =EOMONTH(P4,3) -> 42094 | R4: =EOMONTH(Q4,3) -> 42185 | S4: =EOMONTH(R4,3) -> 42277 | T4: =EOMONTH(S4,3) -> 42369 | U4: =T4 -> 42369 | V4: =EOMONTH(U4,3) -> 42460 | W4: =EOMONTH(V4,3) -> 42551 | X4: =EOMONTH(W4,3) -> 42643 | Y4: =EOMONTH(X4,3) -> 42735 | Z4: =Y4 -> 42735 | AA4: =EOMONTH(Z4,3) -> 42825 | AB4: =EOMONTH(AA4,3) -> 42916 | AC4: =EOMONTH(AB4,3) -> 43008 | AD4: =EOMONTH(AC4,3) -> 43100 | AE4: =AD4 -> 43100 | AF4: =EOMONTH(AE4,3) -> 43190 | AG4: =EOMONTH(AF4,3) -> 43281 | AH4: =EOMONTH(AG4,3) -> 43373 | AI4: =EOMONTH(AH4,3) -> 43465 | AJ4: =AI4 -> 43465 | AK4: =EOMONTH(AJ4,3) -> 43555 | AL4: =EOMONTH(AK4,3) -> 43646 | AM4: =EOMONTH(AL4,3) -> 43738 | AN4: =EOMONTH(AM4,3) -> 43830 | AO4: =AN4 -> 43830 | AP4: =EOMONTH(AO4,3) -> 43921 | AQ4: =EOMONTH(AP4,3) -> 44012 | AR4: =EOMONTH(AQ4,3) -> 44104 | AS4: =EOMONTH(AR4,3) -> 44196 | AT4: =AS4 -> 44196 | AU4: =EOMONTH(AT4,3) -> 44286 | AV4: =EOMONTH(AU4,3) -> 44377 | AW4: =EOMONTH(AV4,3) -> 44469 | AX4: =EOMONTH(AW4,3) -> 44561 | AY4: =AX4 -> 44561 | AZ4: =EOMONTH(AY4,3) -> 44651 | BA4: =EOMONTH(AZ4,3) -> 44742 | BB4: =EOMONTH(BA4,3) -> 44834 | BC4: =EOMONTH(BB4,3) -> 44926 | BD4: =BC4 -> 44926 | BE4: =EOMONTH(BD4,3) -> 45016 | BF4: =EOMONTH(BE4,3) -> 45107 | BG4: =EOMONTH(BF4,3) -> 45199 | BH4: =EOMONTH(BG4,3) -> 45291 | BI4: =BH4 -> 45291 | BJ4: =EOMONTH(BI4,3) -> 45382 | BK4: =EOMONTH(BJ4,3) -> 45473 | BL4: =EOMONTH(BK4,3) -> 45565 | BM4: =EOMONTH(BL4,3) -> 45657 | BN4: =BM4 -> 45657 | BO4: =EOMONTH(BN4,3) -> 45747 | BP4: =EOMONTH(BO4,3) -> 45838 | BQ4: =EOMONTH(BP4,3) -> 45930 | BR4: =EOMONTH(BQ4,3) -> 46022 | BS4: =BR4 -> 46022 | BT4: =EOMONTH(BS4,3) -> 46112 | BU4: =EOMONTH(BT4,3) -> 46203 | BV4: =EOMONTH(BU4,3) -> 46295 | BW4: =EOMONTH(BV4,3) -> 46387 | BX4: =BW4 -> 46387 | BY4: =EOMONTH(BX4,3) -> 46477 | BZ4: =EOMONTH(BY4,3) -> 46568 | CA4: =EOMONTH(BZ4,3) -> 46660 | CB4: =EOMONTH(CA4,3) -> 46752 | CC4: =CB4 -> 46752 | CD4: =EOMONTH(CC4,12) -> 47118 | CE4: =EOMONTH(CD4,12) -> 47483 | CF4: =EOMONTH(CE4,12) -> 47848
A5: =MO.ReportCurrency -> USD | C5: FY2009 | D5: =CONCATENATE("FY",RIGHT(C5,4)+1) -> FY2010 | E5: =CONCATENATE("FY",RIGHT(D5,4)+1) -> FY2011 | F5: =CONCATENATE("FY",RIGHT(E5,4)+1) -> FY2012 | G5: =CONCATENATE("Q1","-",RIGHT(F5,4)+1) -> Q1-2013 | H5: =CONCATENATE("Q2","-",RIGHT(G5,4)) -> Q2-2013 | I5: =CONCATENATE("Q3","-",RIGHT(H5,4)) -> Q3-2013 | J5: =CONCATENATE("Q4","-",RIGHT(I5,4)) -> Q4-2013 | K5: =CONCATENATE("FY",RIGHT(F5,4)+1) -> FY2013 | L5: =CONCATENATE("Q1","-",RIGHT(K5,4)+1) -> Q1-2014 | M5: =CONCATENATE("Q2","-",RIGHT(L5,4)) -> Q2-2014 | N5: =CONCATENATE("Q3","-",RIGHT(M5,4)) -> Q3-2014 | O5: =CONCATENATE("Q4","-",RIGHT(N5,4)) -> Q4-2014 | P5: =CONCATENATE("FY",RIGHT(K5,4)+1) -> FY2014 | Q5: =CONCATENATE("Q1","-",RIGHT(P5,4)+1) -> Q1-2015 | R5: =CONCATENATE("Q2","-",RIGHT(Q5,4)) -> Q2-2015 | S5: =CONCATENATE("Q3","-",RIGHT(R5,4)) -> Q3-2015 | T5: =CONCATENATE("Q4","-",RIGHT(S5,4)) -> Q4-2015 | U5: =CONCATENATE("FY",RIGHT(P5,4)+1) -> FY2015 | V5: =CONCATENATE("Q1","-",RIGHT(U5,4)+1) -> Q1-2016 | W5: =CONCATENATE("Q2","-",RIGHT(V5,4)) -> Q2-2016 | X5: =CONCATENATE("Q3","-",RIGHT(W5,4)) -> Q3-2016 | Y5: =CONCATENATE("Q4","-",RIGHT(X5,4)) -> Q4-2016 | Z5: =CONCATENATE("FY",RIGHT(U5,4)+1) -> FY2016 | AA5: =CONCATENATE("Q1","-",RIGHT(Z5,4)+1) -> Q1-2017 | AB5: =CONCATENATE("Q2","-",RIGHT(AA5,4)) -> Q2-2017 | AC5: =CONCATENATE("Q3","-",RIGHT(AB5,4)) -> Q3-2017 | AD5: =CONCATENATE("Q4","-",RIGHT(AC5,4)) -> Q4-2017 | AE5: =CONCATENATE("FY",RIGHT(Z5,4)+1) -> FY2017 | AF5: =CONCATENATE("Q1","-",RIGHT(AE5,4)+1) -> Q1-2018 | AG5: =CONCATENATE("Q2","-",RIGHT(AF5,4)) -> Q2-2018 | AH5: =CONCATENATE("Q3","-",RIGHT(AG5,4)) -> Q3-2018 | AI5: =CONCATENATE("Q4","-",RIGHT(AH5,4)) -> Q4-2018 | AJ5: =CONCATENATE("FY",RIGHT(AE5,4)+1) -> FY2018 | AK5: =CONCATENATE("Q1","-",RIGHT(AJ5,4)+1) -> Q1-2019 | AL5: =CONCATENATE("Q2","-",RIGHT(AK5,4)) -> Q2-2019 | AM5: =CONCATENATE("Q3","-",RIGHT(AL5,4)) -> Q3-2019 | AN5: =CONCATENATE("Q4","-",RIGHT(AM5,4)) -> Q4-2019 | AO5: =CONCATENATE("FY",RIGHT(AJ5,4)+1) -> FY2019 | AP5: =CONCATENATE("Q1","-",RIGHT(AO5,4)+1) -> Q1-2020 | AQ5: =CONCATENATE("Q2","-",RIGHT(AP5,4)) -> Q2-2020 | AR5: =CONCATENATE("Q3","-",RIGHT(AQ5,4)) -> Q3-2020 | AS5: =CONCATENATE("Q4","-",RIGHT(AR5,4)) -> Q4-2020 | AT5: =CONCATENATE("FY",RIGHT(AO5,4)+1) -> FY2020 | AU5: =CONCATENATE("Q1","-",RIGHT(AT5,4)+1) -> Q1-2021 | AV5: =CONCATENATE("Q2","-",RIGHT(AU5,4)) -> Q2-2021 | AW5: =CONCATENATE("Q3","-",RIGHT(AV5,4)) -> Q3-2021 | AX5: =CONCATENATE("Q4","-",RIGHT(AW5,4)) -> Q4-2021 | AY5: =CONCATENATE("FY",RIGHT(AT5,4)+1) -> FY2021 | AZ5: =CONCATENATE("Q1","-",RIGHT(AY5,4)+1) -> Q1-2022 | BA5: =CONCATENATE("Q2","-",RIGHT(AZ5,4)) -> Q2-2022 | BB5: =CONCATENATE("Q3","-",RIGHT(BA5,4)) -> Q3-2022 | BC5: =CONCATENATE("Q4","-",RIGHT(BB5,4)) -> Q4-2022 | BD5: =CONCATENATE("FY",RIGHT(AY5,4)+1) -> FY2022 | BE5: =CONCATENATE("Q1","-",RIGHT(BD5,4)+1) -> Q1-2023 | BF5: =CONCATENATE("Q2","-",RIGHT(BE5,4)) -> Q2-2023 | BG5: =CONCATENATE("Q3","-",RIGHT(BF5,4)) -> Q3-2023 | BH5: =CONCATENATE("Q4","-",RIGHT(BG5,4)) -> Q4-2023 | BI5: =CONCATENATE("FY",RIGHT(BD5,4)+1) -> FY2023 | BJ5: =CONCATENATE("Q1","-",RIGHT(BI5,4)+1) -> Q1-2024 | BK5: =CONCATENATE("Q2","-",RIGHT(BJ5,4)) -> Q2-2024 | BL5: =CONCATENATE("Q3","-",RIGHT(BK5,4)) -> Q3-2024 | BM5: =CONCATENATE("Q4","-",RIGHT(BL5,4)) -> Q4-2024 | BN5: =CONCATENATE("FY",RIGHT(BI5,4)+1) -> FY2024 | BO5: =CONCATENATE("Q1","-",RIGHT(BN5,4)+1) -> Q1-2025 | BP5: =CONCATENATE("Q2","-",RIGHT(BO5,4)) -> Q2-2025 | BQ5: =CONCATENATE("Q3","-",RIGHT(BP5,4)) -> Q3-2025 | BR5: =CONCATENATE("Q4","-",RIGHT(BQ5,4)) -> Q4-2025 | BS5: =CONCATENATE("FY",RIGHT(BN5,4)+1) -> FY2025 | BT5: =CONCATENATE("Q1","-",RIGHT(BS5,4)+1) -> Q1-2026 | BU5: =CONCATENATE("Q2","-",RIGHT(BT5,4)) -> Q2-2026 | BV5: =CONCATENATE("Q3","-",RIGHT(BU5,4)) -> Q3-2026 | BW5: =CONCATENATE("Q4","-",RIGHT(BV5,4)) -> Q4-2026 | BX5: =CONCATENATE("FY",RIGHT(BS5,4)+1) -> FY2026 | BY5: =CONCATENATE("Q1","-",RIGHT(BX5,4)+1) -> Q1-2027 | BZ5: =CONCATENATE("Q2","-",RIGHT(BY5,4)) -> Q2-2027 | CA5: =CONCATENATE("Q3","-",RIGHT(BZ5,4)) -> Q3-2027 | CB5: =CONCATENATE("Q4","-",RIGHT(CA5,4)) -> Q4-2027 | CC5: =CONCATENATE("FY",RIGHT(BX5,4)+1) -> FY2027 | CD5: =CONCATENATE("FY",RIGHT(CC5,4)+1) -> FY2028 | CE5: =CONCATENATE("FY",RIGHT(CD5,4)+1) -> FY2029 | CF5: =CONCATENATE("FY",RIGHT(CE5,4)+1) -> FY2030
A6: Revenue and Volume Summary
A7: Upstream revenues, mm | C7: =C95 -> 22688 | D7: =D95 -> 27616 | E7: =E95 -> 29709 | F7: =F95 -> 25875 | G7: =G95 -> 6628 | H7: =H95 -> 6493 | I7: =I95 -> 6275 | J7: =J95 -> 6263 | ... CF7: =CF95 -> 47954.92
A8: Downstream revenues, mm | C8: =C236 -> 144010 | D8: =D236 -> 169949 | E8: =E236 -> 214132 | F8: =F236 -> 204333 | G8: =G236 -> 47581 | H8: =H236 -> 48740 | I8: =I236 -> 50233 | J8: =J236 -> 47582 | ... CF8: =CF236 -> 140985.56
A9: Other revenues, mm | C9: =C255 -> 704 | D9: =D255 -> 633 | E9: =E255 -> 530 | F9: =F255 -> 382 | G9: =G255 -> 87 | H9: =H255 -> 74 | I9: =I255 -> 95 | J9: =J255 -> 105 | ... AO9: =AO255 -> 246 | AP9: =AP10-SUM(AP7:AP8) -> 65 | AQ9: =AQ10-SUM(AQ7:AQ8) -> 33 | AR9: =AR10-SUM(AR7:AR8) -> 37 | AS9: =AS10-SUM(AS7:AS8) -> -58 | AT9: =SUM(AP9,AQ9,AR9,AS9) -> 77 | AU9: =AU10-SUM(AU7:AU8) -> 24 | AV9: =AV10-SUM(AV7:AV8) -> 25 | AW9: =AW10-SUM(AW7:AW8) -> 39 | AX9: =AX10-SUM(AX7:AX8) -> 36 | AY9: =AY10-SUM(AY7:AY8) -> 124 | AZ9: =AZ10-SUM(AZ7:AZ8) -> 16 | BA9: =BA10-SUM(BA7:BA8) -> 38 | BB9: =BB10-SUM(BB7:BB8) -> 32 | ... BT9: =BT10-SUM(BT7:BT8) -> 14 | BU9: =BU255 -> 130 | BV9: =BV255 -> 130 | BW9: =BW255 -> 130 | BX9: =BX255 -> 404 | BY9: =BY255 -> 130 | BZ9: =BZ255 -> 130 | CA9: =CA255 -> 130 | CB9: =CB255 -> 130 | ... CF9: =CF255 -> 520
A10: Total Sales and other operating revenue, mm | C10: =SUM(C7:C9) -> 167402 | D10: =SUM(D7:D9) -> 198198 | E10: =SUM(E7:E9) -> 244371 | F10: =SUM(F7:F9) -> 230590 | G10: =SUM(G7:G9) -> 54296 | H10: =SUM(H7:H9) -> 55307 | I10: =SUM(I7:I9) -> 56603 | J10: =SUM(J7:J9) -> 53950 | ... AH10: =SUM(AH7:AH9) -> 42105 | AI10: =AI495 -> 40338 | AJ10: =AJ495 -> 158902 | AK10: =SUM(AK7:AK9) -> 34189 | AL10: =SUM(AL7:AL9) -> 36323 | AM10: =SUM(AM7:AM9) -> 34779 | AN10: =AN495 -> 34574 | AO10: =AO495 -> 139865 | AP10: =AP495 -> 29705 | AQ10: =AQ495 -> 15926 | AR10: =AR495 -> 23997 | AS10: =AS495 -> 24843 | AT10: =AT495 -> 94471 | AU10: =AU495 -> 31076 | ... BT10: =BT495 -> 47556 | BU10: =SUM(BU7:BU9) -> 58939.442 | BV10: =SUM(BV7:BV9) -> 54894.09 | BW10: =SUM(BW7:BW9) -> 54052.44 | BX10: =SUM(BX7:BX9) -> 215441.97 | BY10: =SUM(BY7:BY9) -> 51942.325 | BZ10: =SUM(BZ7:BZ9) -> 51909.601 | CA10: =SUM(CA7:CA9) -> 52751.602 | CB10: =SUM(CB7:CB9) -> 52295.674 | ... CF10: =SUM(CF7:CF9) -> 189460.48
A12: Upstream earnings, mm | C12: =C99 -> 10932 | D12: =D99 -> 17677 | E12: =E99 -> 24786 | F12: =F99 -> 23788 | G12: =G99 -> 5916 | H12: =H99 -> 4949 | I12: =I99 -> 5092 | J12: =J99 -> 4852 | ... BT12: =BT99 -> 3909
A13: Downstream earnings, mm | C13: =C243 -> 473 | D13: =D243 -> 2478 | E13: =E243 -> 3591 | F13: =F243 -> 4299 | G13: =G243 -> 701 | H13: =H243 -> 766 | I13: =I243 -> 380 | J13: =J243 -> 390 | ... BT13: =BT243 -> -817
A14: Other earnings, mm | C14: =C260 -> -922 | D14: =D260 -> -1131 | E14: =E260 -> -1482 | F14: =F260 -> -1908 | G14: =G260 -> -439 | H14: =H260 -> -350 | I14: =I260 -> -522 | J14: =J260 -> -312 | ... BT14: =BT260 -> -882
A15: Total earnings, mm | C15: =SUM(C12:C14) -> 10483 | D15: =SUM(D12:D14) -> 19024 | E15: =SUM(E12:E14) -> 26895 | F15: =SUM(F12:F14) -> 26179 | G15: =SUM(G12:G14) -> 6178 | H15: =SUM(H12:H14) -> 5365 | I15: =SUM(I12:I14) -> 4950 | J15: =SUM(J12:J14) -> 4930 | ... BT15: =SUM(BT12:BT14) -> 2210 | BU15: =MO_RIS_NI_GAAP_Basic -> 9898.3571 | BV15: =MO_RIS_NI_GAAP_Basic -> 7375.6397 | BW15: =MO_RIS_NI_GAAP_Basic -> 6589.1303 | BX15: =MO_RIS_NI_GAAP_Basic -> 26073.127 | BY15: =MO_RIS_NI_GAAP_Basic -> 5996.1876 | BZ15: =MO_RIS_NI_GAAP_Basic -> 6012.9055 | CA15: =MO_RIS_NI_GAAP_Basic -> 6177.51 | CB15: =MO_RIS_NI_GAAP_Basic -> 6087.3183 | ... CF15: =MO_RIS_NI_GAAP_Basic -> 16219.818
A17: Upstream total production volumes, kBOE/d | C17: =C53 -> 2348.5 | D17: =D53 -> 2396.5 | E17: =E53 -> 2312 | F17: =F53 -> 2255 | G17: =G53 -> 2644.8333 | H17: =H53 -> 2582 | I17: =I53 -> 2585.6667 | J17: =J53 -> 2575.5 | ... CF17: =CF53 -> 3650
A18: Downstream total refinery input, kbbl/d | C18: =C169+C185 -> 1878 | D18: =D169+D185 -> 1894 | E18: =E169+E185 -> 1787 | F18: =F169+F185 -> 1702 | G18: =G169+G185 -> 1394 | H18: =H169+H185 -> 1686 | I18: =I169+I185 -> 1716 | J18: =J169+J185 -> 1749 | ... CF18: =CF169+CF185 -> 1675
A19: Downstream total refined products sold, kbbl/d | C19: =C190+C173 -> 3254 | D19: =D190+D173 -> 3113 | E19: =E190+E173 -> 2949 | F19: =F190+F173 -> 2765 | G19: =G190+G173 -> 2547 | H19: =H190+H173 -> 2761 | I19: =I190+I173 -> 2756 | J19: =J190+J173 -> 1220.5109 | ... CF19: =CF190+CF173 -> 3007.5
A21: Upstream Operating Stats - Production Volumes (Company1282)
A22: Angola, k bbl/d | C22: 141 | D22: 152 | E22: 139 | F22: 128 | G22: 120 | H22: 122 | I22: 120 | J22: 116 | K22: =SUM(G22*G$3,H22*H$3,I22*I$3,J22*J$3)/K$3 -> 119.49041 | L22: 118 | M22: 113 | N22: 110 | O22: 114 | P22: =SUM(L22*L$3,M22*M$3,N22*N$3,O22*O$3)/P$3 -> 113.72877 | Q22: 113 | R22: 111 | S22: 106 | T22: 110 | U22: =SUM(Q22*Q$3,R22*R$3,S22*S$3,T22*T$3)/U$3 -> 109.98082 | V22: 111 | W22: 107 | X22: 105 | Y22: 107 | Z22: 108 | AA22: 105 | AB22: 116 | AC22: 117 | AD22: 113 | AE22: 113 | AF22: 111 | AG22: 108 | AH22: 105 | AI22: 104 | AJ22: 107 | AK22: 105 | AL22: 102 | AM22: 94 | AN22: 88 | AO22: 97 | AP22: 97 | AQ22: 89 | AR22: 88 | AS22: 81 | AT22: 89 | AU22: 83 | AV22: 77 | AW22: 76 | AX22: 78 | AY22: 79 | AZ22: 75 | BA22: 71 | BB22: 71 | BC22: 62 | BD22: 70 | BE22: 67 | BF22: 70 | BG22: 66 | BH22: 69 | BI22: 68 | BJ22: 67 | BK22: 66 | BL22: 63 | BM22: 64 | BN22: 64 | BO22: 59 | BP22: 55 | BQ22: 59 | BR22: 59 | BS22: 58 | BT22: 57
A23: Canada, k bbl/d | AP23: 141 | AQ23: 152 | AR23: 117 | AS23: 141 | AT23: 138 | AU23: 143 | AV23: 138 | AW23: 131 | AX23: 131 | AY23: 136 | AZ23: 113 | BA23: 112 | BB23: 118 | BC23: 120 | BD23: 116 | BE23: 118 | BF23: 106 | BG23: 107 | BH23: 122 | BI23: 114 | BJ23: 110 | BK23: 117 | BL23: 115 | BM23: 98 | BN23: 110 | BO23: 43 | BP23: 47 | BQ23: 48 | BR23: 47 | BS23: 46 | BT23: 55
A24: Guyana, k bbl/d | BQ24: 210 | BR24: 261 | BS24: 119 | BT24: 284
A25: Europe, k bbl/d | C25: 115 | D25: 101 | E25: 93 | F25: 75 | G25: 71 | H25: 66 | I25: 56 | J25: 57 | K25: =SUM(G25*G$3,H25*H$3,I25*I$3,J25*J$3)/K$3 -> 62.443836 | L25: 59 | M25: 52 | N25: 43 | O25: 53 | P25: =SUM(L25*L$3,M25*M$3,N25*N$3,O25*O$3)/P$3 -> 51.709589 | Q25: 47 | R25: 55 | S25: 58 | T25: 62 | U25: =SUM(Q25*Q$3,R25*R$3,S25*S$3,T25*T$3)/U$3 -> 55.547945 | V25: 58 | W25: 49 | X25: 56 | Y25: 65 | Z25: 57 | AA25: 69 | AB25: 68 | AC25: 59 | AD25: 59 | AE25: 64 | AF25: 57 | AG25: 46 | AH25: 50 | AI25: 66 | AJ25: 55 | AK25: 65 | AL25: 49 | AM25: 44 | AN25: 29 | AO25: 47 | AP25: 13 | AQ25: 13 | AR25: 12 | AS25: 12 | AT25: 13 | AU25: 13 | AV25: 11 | AW25: 13 | AX25: 16 | AY25: 13
A26: Indonesia, k bbl/d | C26: 199 | D26: 187 | E26: 166 | F26: 158 | G26: 150 | H26: 154 | I26: 159 | J26: 160 | K26: =SUM(G26*G$3,H26*H$3,I26*I$3,J26*J$3)/K$3 -> 155.7863 | L26: 149 | M26: 145 | N26: 149 | O26: 156 | P26: =SUM(L26*L$3,M26*M$3,N26*N$3,O26*O$3)/P$3 -> 149.76712 | Q26: 173 | R26: 161 | S26: 176 | T26: 196 | U26: =SUM(Q26*Q$3,R26*R$3,S26*S$3,T26*T$3)/U$3 -> 176.56164 | V26: 198 | W26: 158 | X26: 147 | Y26: 189 | Z26: 173 | AA26: 135 | AB26: 137 | AC26: 140 | AD26: 135 | AE26: 137 | AF26: 114 | AG26: 112 | AH26: 114 | AI26: 114 | AJ26: 113 | AK26: 98 | AL26: 99 | AM26: 102 | AN26: 103 | AO26: 101 | AP26: 106 | AQ26: 122 | AR26: 109 | AS26: 186 | AT26: 131 | AU26: 84 | AV26: 76 | AW26: 86 | AX26: 2 | AY26: 62
A27: Kazakhstan/Eurasia, k bbl/d | C27: 70 | D27: 67 | E27: 64 | F27: 63 | G27: 335 | H27: 315 | I27: 313 | J27: 333 | K27: =SUM(G27*G$3,H27*H$3,I27*I$3,J27*J$3)/K$3 -> 323.96438 | L27: 326 | M27: 294 | N27: 310 | O27: 333 | P27: =SUM(L27*L$3,M27*M$3,N27*N$3,O27*O$3)/P$3 -> 315.75342 | Q27: 361 | R27: 350 | S27: 308 | T27: 354 | U27: =SUM(Q27*Q$3,R27*R$3,S27*S$3,T27*T$3)/U$3 -> 343.13425 | V27: 381 | W27: 357 | X27: 298 | Y27: 373 | Z27: 352 | AA27: 363 | AB27: 352 | AC27: 334 | AD27: 347 | AE27: 349 | AF27: 342 | AG27: 337 | AH27: 312 | AI27: 343 | AJ27: 333 | AK27: 361 | AL27: 348 | AM27: 344 | AN27: 377 | AO27: 357 | AP27: 388 | AQ27: 351 | AR27: 309 | AS27: 327 | AT27: 344 | AU27: 309 | AV27: 314 | AW27: 246 | AX27: 329 | AY27: 299 | AZ27: 310 | BA27: 291 | BB27: 297 | BC27: 342 | BD27: 310 | BE27: 324 | BF27: 333 | BG27: 302 | BH27: 334 | BI27: 323 | BJ27: 343 | BK27: 326 | BL27: 330 | BM27: 317 | BN27: 329 | BO27: 431 | BP27: 458 | BQ27: 483 | BR27: 408 | BS27: 445 | BT27: 285
A28: Partitioned zone, k bbl/d | C28: 101 | D28: 94 | E28: 88 | F28: 86 | G28: 86 | H28: 84 | I28: 84 | J28: 83 | K28: =SUM(G28*G$3,H28*H$3,I28*I$3,J28*J$3)/K$3 -> 84.241096 | L28: 80 | M28: 80 | N28: 77 | O28: 76 | P28: =SUM(L28*L$3,M28*M$3,N28*N$3,O28*O$3)/P$3 -> 78.235616 | Q28: 74 | R28: 35 | S28: 0 | T28: 0 | U28: =SUM(Q28*Q$3,R28*R$3,S28*S$3,T28*T$3)/U$3 -> 26.972603 | V28: 0 | W28: 1 | X28: 0 | Y28: 0 | Z28: 0 | AA28: 0 | AB28: 0 | AC28: 0 | AD28: 0 | AE28: 0 | AF28: 0 | AG28: 0 | AH28: 0 | AK28: 0 | AL28: 0 | AM28: 0 | AN28: 0 | AO28: 0 | AR28: 29 | AS28: 39 | AT28: 17 | AU28: 57 | AV28: 57 | AW28: 55 | AX28: 56 | AY28: 56 | AZ28: 57 | BA28: 58 | BB28: 59 | BC28: 59 | BD28: 58 | BE28: 59 | BF28: 61 | BG28: 60 | BH28: 60 | BI28: 60 | BJ28: 60 | BK28: 60 | BL28: 60 | BM28: 60 | BN28: 60 | BO28: 62 | BP28: 63 | BQ28: 66 | BR28: 69 | BS28: 65 | BT28: 59
A29: Nigeria, k bbl/d | C29: 225 | D29: 239 | E29: 236 | F29: 242 | G29: 239 | H29: 223 | I29: 247 | J29: 242 | K29: =SUM(G29*G$3,H29*H$3,I29*I$3,J29*J$3)/K$3 -> 237.78356 | L29: 248 | M29: 245 | N29: 248 | O29: 247 | P29: =SUM(L29*L$3,M29*M$3,N29*N$3,O29*O$3)/P$3 -> 247 | Q29: 235 | R29: 231 | S29: 228 | T29: 225 | U29: =SUM(Q29*Q$3,R29*R$3,S29*S$3,T29*T$3)/U$3 -> 229.71781 | V29: 226 | W29: 214 | X29: 209 | Y29: 186 | Z29: 208 | AA29: 214 | AB29: 220 | AC29: 209 | AD29: 210 | AE29: 213 | AF29: 210 | AG29: 203 | AH29: 198 | AI29: 189 | AJ29: 200 | AK29: 188 | AL29: 184 | AM29: 170 | AN29: 150 | AO29: 173 | AP29: 176 | AQ29: 140 | AR29: 126 | AS29: 119 | AT29: 140 | AU29: 136 | AV29: 120 | AW29: 124 | AX29: 117 | AY29: 124 | AZ29: 115 | BA29: 107 | BB29: 104 | BC29: 104 | BD29: 107 | BE29: 110 | BF29: 98 | BG29: 119 | BH29: 110 | BI29: 109 | BJ29: 96 | BK29: 95 | BL29: 106 | BM29: 98 | BN29: 99 | BO29: 101 | BP29: 103 | BQ29: 102 | BR29: 83 | BS29: 97 | BT29: 94
A30: South America, k bbl/d | C30: 36 | D30: 55 | E30: 59 | F30: 27 | G30: 80 | H30: 84 | I30: 85 | J30: 88 | K30: =SUM(G30*G$3,H30*H$3,I30*I$3,J30*J$3)/K$3 -> 84.273973 | L30: 92 | M30: 101 | N30: 103 | O30: 102 | P30: =SUM(L30*L$3,M30*M$3,N30*N$3,O30*O$3)/P$3 -> 99.536986 | Q30: 101 | R30: 96 | S30: 96 | T30: 95 | U30: =SUM(Q30*Q$3,R30*R$3,S30*S$3,T30*T$3)/U$3 -> 96.980822 | V30: 94 | W30: 90 | X30: 91 | Y30: 92 | Z30: 92 | AA30: 91 | AB30: 88 | AC30: 82 | AD30: 72 | AE30: 83 | AF30: 69 | AG30: 68 | AH30: 74 | AI30: 79 | AJ30: 72 | AK30: 74 | AL30: 61 | AM30: 61 | AN30: 63 | AO30: 65 | AP30: 68 | AQ30: 48 | AR30: 31 | AS30: 27 | AT30: 42 | AU30: 32 | AV30: 34 | AW30: 28 | AX30: 30 | AY30: 31 | AZ30: 32 | BA30: 32 | BB30: 35 | BC30: 39 | BD30: 35 | BE30: 37 | BF30: 37 | BG30: 36 | BH30: 39 | BI30: 37 | BJ30: 41 | BK30: 40 | BL30: 44 | BM30: 48 | BN30: 43 | BO30: 48 | BP30: 48 | BQ30: 53 | BR30: 61 | BS30: 52 | BT30: 61
A31: Other, k bbl/d | C31: 198 | D31: 233 | E31: 235 | F31: 230 | G31: 224 | H31: 210 | I31: 215 | J31: 207 | K31: =SUM(G31*G$3,H31*H$3,I31*I$3,J31*J$3)/K$3 -> 213.95616 | L31: 203 | M31: 204 | N31: 195 | O31: 189 | P31: =SUM(L31*L$3,M31*M$3,N31*N$3,O31*O$3)/P$3 -> 197.70411 | Q31: 208 | R31: 172 | S31: 201 | T31: 234 | U31: =SUM(Q31*Q$3,R31*R$3,S31*S$3,T31*T$3)/U$3 -> 203.8137 | V31: 223 | W31: 212 | X31: 236 | Y31: 225 | Z31: 225 | AA31: 227 | AB31: 240 | AC31: 253 | AD31: 259 | AE31: 245 | AF31: 283 | AG31: 274 | AH31: 280 | AI31: 293 | AJ31: 284 | AK31: 294 | AL31: 310 | AM31: 289 | AN31: 312 | AO31: 301 | AP31: 174 | AQ31: 162 | AR31: 155 | AS31: 166 | AT31: 164 | AU31: 167 | AV31: 163 | AW31: 156 | AX31: 140 | AY31: 156 | AZ31: 154 | BA31: 128 | BB31: 132 | BC31: 126 | BD31: 136 | BE31: 134 | BF31: 122 | BG31: 113 | BH31: 117 | BI31: 122 | BJ31: 121 | BK31: 119 | BL31: 116 | BM31: 112 | BN31: 118 | BO31: 78 | BP31: 76 | BQ31: 78 | BR31: 83 | BS31: 80 | BT31: 79
A32: International net liquids production, k bbl/d | C32: =SUM(C22:C31) -> 1085 | D32: =SUM(D22:D31) -> 1128 | E32: =SUM(E22:E31) -> 1080 | F32: =SUM(F22:F31) -> 1009 | G32: =SUM(G22:G31) -> 1305 | H32: =SUM(H22:H31) -> 1258 | I32: =SUM(I22:I31) -> 1279 | J32: =SUM(J22:J31) -> 1286 | ... BT32: =SUM(BT22:BT31) -> 974 | BU32: 1000 | BV32: 1250 | BW32: 1000 | BX32: =SUM(BT32*BT$3,BU32*BU$3,BV32*BV$3,BW32*BW$3)/BX$3 -> 1056.6027 | BY32: 1000 | BZ32: 1000 | CA32: 1000 | CB32: 1000 | CC32: =SUM(BY32*BY$3,BZ32*BZ$3,CA32*CA$3,CB32*CB$3)/CC$3 -> 1000 | CD32: 925 | CE32: 925 | CF32: 925
A33: US net liquids production, k bbl/d | C33: 484 | D33: 489 | E33: 465 | F33: 455 | G33: 455 | H33: 455 | I33: 448 | J33: 440 | K33: =SUM(G33*G$3,H33*H$3,I33*I$3,J33*J$3)/K$3 -> 449.45479 | L33: 438 | M33: 460 | N33: 464 | O33: 462 | P33: =SUM(L33*L$3,M33*M$3,N33*N$3,O33*O$3)/P$3 -> 456.08767 | Q33: 489 | R33: 511 | S33: 505 | T33: 499 | U33: =SUM(Q33*Q$3,R33*R$3,S33*S$3,T33*T$3)/U$3 -> 501.03836 | V33: 490 | W33: 501 | X33: 519 | Y33: 508 | Z33: 504 | AA33: 504 | AB33: 530 | AC33: 525 | AD33: 518 | AE33: 519 | AF33: 567 | AG33: 575 | AH33: 654 | AI33: 674 | AJ33: 618 | AK33: 690 | AL33: 710 | AM33: 726 | AN33: 771 | AO33: 724 | AP33: 803 | AQ33: 747 | AR33: 731 | AS33: 880 | AT33: 790 | AU33: 802 | AV33: 857 | AW33: 842 | AX33: 929 | AY33: 858 | AZ33: 880 | BA33: 888 | BB33: 891 | BC33: 895 | BD33: 888 | BE33: 877 | BF33: 916 | BG33: 1028 | BH33: 1164 | BI33: 997 | BJ33: 1130 | BK33: 1132 | BL33: 1156 | BM33: 1189 | BN33: 1152 | BO33: 1159 | BP33: 1218 | BQ33: 1496 | BR33: 1488 | BS33: 1341 | BT33: 1461 | BU33: 1500 | BV33: 1500 | BW33: 1500 | BX33: =SUM(BT33*BT$3,BU33*BU$3,BV33*BV$3,BW33*BW$3)/BX$3 -> 1490.3836 | BY33: 1500 | BZ33: 1500 | CA33: 1500 | CB33: 1500 | CC33: =SUM(BY33*BY$3,BZ33*BZ$3,CA33*CA$3,CB33*CB$3)/CC$3 -> 1500 | CD33: 1325 | CE33: 1325 | CF33: 1325
A34: Liquids, k bbl/d | C34: =SUM(C32:C33) -> 1569 | D34: =SUM(D32:D33) -> 1617 | E34: =SUM(E32:E33) -> 1545 | F34: =SUM(F32:F33) -> 1464 | G34: =SUM(G32:G33) -> 1760 | H34: =SUM(H32:H33) -> 1713 | I34: =SUM(I32:I33) -> 1727 | J34: =SUM(J32:J33) -> 1726 | ... CF34: =SUM(CF32:CF33) -> 2250
A35: Angola, MMcf/d | AZ35: 281 | BA35: 224 | BB35: 271 | BC35: 260 | BD35: 259 | BE35: 300 | BF35: 290 | BG35: 284 | BH35: 261 | BI35: 284 | BJ35: 247 | BK35: 293 | BL35: 310 | BM35: 296 | BN35: 287 | BO35: 315 | BP35: 315 | BQ35: 397 | BR35: 377 | BS35: 351 | BT35: 362
A36: Australia, MMcf/d | C36: 434 | D36: 458 | E36: 448 | F36: 428 | G36: 433 | H36: 391 | I36: 450 | J36: 410 | K36: =SUM(G36*G$3,H36*H$3,I36*I$3,J36*J$3)/K$3 -> 421.01644 | L36: 434 | M36: 423 | N36: 479 | O36: 430 | P36: =SUM(L36*L$3,M36*M$3,N36*N$3,O36*O$3)/P$3 -> 441.59178 | Q36: 457 | R36: 396 | S36: 446 | T36: 457 | U36: =SUM(Q36*Q$3,R36*R$3,S36*S$3,T36*T$3)/U$3 -> 439.01918 | V36: 474 | W36: 409 | X36: 721 | Y36: 854 | Z36: 615 | AA36: 1061 | AB36: 1316 | AC36: 1551 | AD36: 1552 | AE36: 1372 | AF36: 1973 | AG36: 2012 | AH36: 2578 | AI36: 2643 | AJ36: 2304 | AK36: 2202 | AL36: 2661 | AM36: 2644 | AN36: 2331 | AO36: 2460 | AP36: 2588 | AQ36: 2470 | AR36: 2239 | AS36: 2276 | AT36: 2392 | AU36: 2344 | AV36: 2240 | AW36: 2614 | AX36: 2534 | AY36: 2434 | AZ36: 2560 | BA36: 2411 | BB36: 2849 | BC36: 2748 | BD36: 2643 | BE36: 2697 | BF36: 2632 | BG36: 2676 | BH36: 2709 | BI36: 2678 | BJ36: 2715 | BK36: 2542 | BL36: 2607 | BM36: 2635 | BN36: 2625 | BO36: 2562 | BP36: 2510 | BQ36: 2650 | BR36: 2697 | BS36: 2605 | BT36: 2523
A37: Bangladesh, MMcf/d | C37: 387 | D37: 404 | E37: 434 | F37: 550 | G37: 658 | H37: 684 | I37: 675 | J37: 634 | K37: =SUM(G37*G$3,H37*H$3,I37*I$3,J37*J$3)/K$3 -> 662.71781 | L37: 649 | M37: 593 | N37: 651 | O37: 679 | P37: =SUM(L37*L$3,M37*M$3,N37*N$3,O37*O$3)/P$3 -> 643.10411 | Q37: 742 | R37: 738 | S37: 660 | T37: 742 | U37: =SUM(Q37*Q$3,R37*R$3,S37*S$3,T37*T$3)/U$3 -> 720.33425 | V37: 694 | W37: 647 | X37: 620 | Y37: 673 | Z37: 658 | AA37: 660 | AB37: 623 | AC37: 639 | AD37: 644 | AE37: 642 | AF37: 646 | AG37: 641 | AH37: 649 | AI37: 657 | AJ37: 648 | AK37: 637 | AL37: 634 | AM37: 636 | AN37: 646 | AO37: 638 | AP37: 644 | AQ37: 543 | AR37: 631 | AS37: 670 | AT37: 622 | AU37: 678 | AV37: 667 | AW37: 583 | AX37: 691 | AY37: 655 | AZ37: 675 | BA37: 635 | BB37: 841 | BC37: 633 | BD37: 696 | BE37: 598 | BF37: 580 | BG37: 624 | BH37: 640 | BI37: 610 | BJ37: 612 | BK37: 575 | BL37: 592 | BM37: 529 | BN37: 577 | BO37: 510 | BP37: 476 | BQ37: 519 | BR37: 471 | BS37: 494 | BT37: 424
A38: Canada, MMcf/d | AP38: 115 | AQ38: 127 | AR38: 126 | AS38: 135 | AT38: 126 | AU38: 149 | AV38: 149 | AW38: 149 | AX38: 152 | AY38: 150 | AZ38: 141 | BA38: 135 | BB38: 137 | BC38: 126 | BD38: 135 | BE38: 125 | BF38: 72 | BG38: 109 | BH38: 132 | BI38: 110 | BJ38: 127 | BK38: 134 | BL38: 147 | BM38: 115 | BN38: 131 | BO38: 10 | BP38: 10 | BQ38: 10 | BR38: 9 | BS38: 10 | BT38: 10
A39: Guyana, MMcf/d | BQ39: 18 | BR39: 21 | BS39: 10 | BT39: 24
A40: Europe, MMcf/d | C40: 383 | D40: 346 | E40: 278 | F40: 239 | G40: 218 | H40: 207 | I40: 157 | J40: 185 | K40: =SUM(G40*G$3,H40*H$3,I40*I$3,J40*J$3)/K$3 -> 191.56438 | L40: 199 | M40: 168 | N40: 157 | O40: 170 | P40: =SUM(L40*L$3,M40*M$3,N40*N$3,O40*O$3)/P$3 -> 173.37534 | Q40: 146 | R40: 166 | S40: 163 | T40: 184 | U40: =SUM(Q40*Q$3,R40*R$3,S40*S$3,T40*T$3)/U$3 -> 164.84932 | V40: 161 | W40: 152 | X40: 140 | Y40: 229 | Z40: 170 | AA40: 247 | AB40: 234 | AC40: 157 | AD40: 193 | AE40: 208 | AF40: 190 | AG40: 176 | AH40: 157 | AI40: 188 | AJ40: 178 | AK40: 184 | AL40: 126 | AM40: 107 | AN40: 56 | AO40: 119 | AP40: 5 | AQ40: 5 | AR40: 5 | AS40: 5 | AT40: 5 | AU40: 5 | AV40: 5 | AW40: 7 | AX40: 9 | AY40: 6
A41: Indonesia, MMcf/d | C41: 268 | D41: 236 | E41: 253 | F41: 236 | G41: 225 | H41: 225 | I41: 226 | J41: 227 | K41: =SUM(G41*G$3,H41*H$3,I41*I$3,J41*J$3)/K$3 -> 225.75616 | L41: 219 | M41: 216 | N41: 213 | O41: 207 | P41: =SUM(L41*L$3,M41*M$3,N41*N$3,O41*O$3)/P$3 -> 213.71507 | Q41: 193 | R41: 188 | S41: 169 | T41: 191 | U41: =SUM(Q41*Q$3,R41*R$3,S41*S$3,T41*T$3)/U$3 -> 185.2 | V41: 174 | W41: 196 | X41: 168 | Y41: 188 | Z41: 182 | AA41: 197 | AB41: 188 | AC41: 128 | AD41: 139 | AE41: 163 | AF41: 136 | AG41: 111 | AH41: 120 | AI41: 85 | AJ41: 113 | AK41: 46 | AL41: 60 | AM41: 34 | AN41: 69 | AO41: 52 | AP41: 36 | AQ41: 46 | AR41: 56 | AS41: 35 | AT41: 43 | AU41: 39 | AV41: 33 | AW41: 23 | AX41: 23 | AY41: 29
A42: Israel, MMcf/d | AS42: 462 | AT42: 116 | AU42: 515 | AV42: 520 | AW42: 597 | AX42: 530 | AY42: 541 | AZ42: 600 | BA42: 597 | BB42: 635 | BC42: 575 | BD42: 602 | BE42: 598 | BF42: 549 | BG42: 615 | BH42: 502 | BI42: 566 | BJ42: 578 | BK42: 574 | BL42: 640 | BM42: 577 | BN42: 592 | BO42: 630 | BP42: 496 | BQ42: 642 | BR42: 557 | BS42: 581 | BT42: 492
A43: Kazakhstan/Eurasia, MMcf/d | C43: 171 | D43: 160 | E43: 154 | F43: 149 | G43: 499 | H43: 469 | I43: 486 | J43: 513 | K43: =SUM(G43*G$3,H43*H$3,I43*I$3,J43*J$3)/K$3 -> 491.7726 | L43: 488 | M43: 437 | N43: 461 | O43: 501 | P43: =SUM(L43*L$3,M43*M$3,N43*N$3,O43*O$3)/P$3 -> 471.75616 | Q43: 527 | R43: 516 | S43: 439 | T43: 512 | U43: =SUM(Q43*Q$3,R43*R$3,S43*S$3,T43*T$3)/U$3 -> 498.29589 | V43: 552 | W43: 543 | X43: 479 | Y43: 594 | Z43: 542 | AA43: 595 | AB43: 535 | AC43: 497 | AD43: 552 | AE43: 544 | AF43: 543 | AG43: 537 | AH43: 482 | AI43: 506 | AJ43: 517 | AK43: 565 | AL43: 544 | AM43: 530 | AN43: 591 | AO43: 558 | AP43: 595 | AQ43: 562 | AR43: 484 | AS43: 534 | AT43: 544 | AU43: 515 | AV43: 508 | AW43: 349 | AX43: 550 | AY43: 480 | AZ43: 557 | BA43: 510 | BB43: 513 | BC43: 483 | BD43: 516 | BE43: 512 | BF43: 487 | BG43: 422 | BH43: 501 | BI43: 480 | BJ43: 515 | BK43: 478 | BL43: 483 | BM43: 465 | BN43: 485 | BO43: 500 | BP43: 458 | BQ43: 465 | BR43: 485 | BS43: 477 | BT43: 392
...

Sheet Guidance
B1: =MO.CompanyName -> Company0670 Company0697
B2: Most Recent Period: | F2: =UL.MRQ -> Q1-2026
I4: Guidance | M4: Model | P4: Difference vs. Mid | S4: Update Log
B5: Type | D5: Item | E5: Item Name | F5: Fiscal Period | G5: Base Period | I5: Low | J5: High | K5: Mid | M5: Type | N5: Output | P5: Absolute | Q5: Relative | S5: Date | T5: Link
A6: 221 | B6: =IF(INDEX(MO_SNA_IsHistoricalPeriod,,MATCH(F6,MO_Common_ColumnHeader,0)),"Historical","Forward") -> Forward | D6: =INDEX(INDIRECT(E6),0,COLUMN(MO_Common_Column_A)) -> Total average daily production volumes, kBOE/d | E6: MO_OS_Energy_AverageDailyProduction_Total | F6: FY2026 | G6: FY2025 | I6: 0.07 | J6: 0.1 | K6: =AVERAGE(I6:J6) -> 0.085 | M6: =IF(INDEX(MO_SNA_IsHistoricalPeriod,,MATCH(F6,MO_Common_ColumnHeader,0)),"Actual","Estimate") -> Estimate | N6: =INDEX(MO_OS_Energy_AverageDailyProduction_Total,0,MATCH(F6,MO_Common_ColumnHeader,0))/INDEX(MO_OS_Energy_AverageDailyProduction_Total,0,MATCH(G6,MO_Common_ColumnHeader,0))-1 -> 0.085572122 | P6: =IF(ISNUMBER(N6),N6-K6,"N/A") -> 0.0005721216 | Q6: =IFERROR(IF(ISNUMBER(N6),(N6-K6)/ABS(K6),"N/A"),"N/A") -> 0.0067308424 | S6: 46143 | T6: Investor Presentation
A7: 220 | B7: =IF(INDEX(MO_SNA_IsHistoricalPeriod,,MATCH(F7,MO_Common_ColumnHeader,0)),"Historical","Forward") -> Forward | D7: =INDEX(INDIRECT(E7),0,COLUMN(MO_Common_Column_A)) -> Capex | E7: MO_CFSum_Capex | F7: FY2026 | I7: -19000 | J7: -18000 | K7: =AVERAGE(I7:J7) -> -18500 | M7: =IF(INDEX(MO_SNA_IsHistoricalPeriod,,MATCH(F7,MO_Common_ColumnHeader,0)),"Actual","Estimate") -> Estimate | N7: =IFERROR(INDEX(INDIRECT(E7),0,MATCH(F7,MO_Common_ColumnHeader,0)),"N/A") -> -18563 | P7: =IF(ISNUMBER(N7),N7-K7,"N/A") -> -63 | Q7: =IFERROR(IF(ISNUMBER(N7),(N7-K7)/ABS(K7),"N/A"),"N/A") -> -0.0034054054 | S7: 46143 | T7: Investor Presentation
A8: 219
A9: 218 | B9: =IF(INDEX(MO_SNA_IsHistoricalPeriod,,MATCH(F9,MO_Common_ColumnHeader,0)),"Historical","Forward") -> Forward | D9: Turnarounds & downtime, MBOE/d | F9: Q2-2026 | I9: -100 | J9: -150 | K9: =AVERAGE(I9:J9) -> -125 | M9: =IF(INDEX(MO_SNA_IsHistoricalPeriod,,MATCH(F9,MO_Common_ColumnHeader,0)),"Actual","Estimate") -> Estimate | S9: 46143 | T9: Investor Presentation
A10: 217 | B10: =IF(INDEX(MO_SNA_IsHistoricalPeriod,,MATCH(F10,MO_Common_ColumnHeader,0)),"Historical","Forward") -> Forward | D10: Turnarounds (A/T earnings), mm | F10: Q2-2026 | I10: -275 | J10: -325 | K10: =AVERAGE(I10:J10) -> -300 | M10: =IF(INDEX(MO_SNA_IsHistoricalPeriod,,MATCH(F10,MO_Common_ColumnHeader,0)),"Actual","Estimate") -> Estimate | S10: 46143 | T10: Investor Presentation
A11: 216 | B11: =IF(INDEX(MO_SNA_IsHistoricalPeriod,,MATCH(F11,MO_Common_ColumnHeader,0)),"Historical","Forward") -> Forward | D11: Share repurchase, mm | E11: MO_CFSum_NetShares | F11: Q2-2026 | I11: -2500 | J11: -3000 | K11: =AVERAGE(I11:J11) -> -2750 | M11: =IF(INDEX(MO_SNA_IsHistoricalPeriod,,MATCH(F11,MO_Common_ColumnHeader,0)),"Actual","Estimate") -> Estimate | N11: =IFERROR(INDEX(INDIRECT(E11),0,MATCH(F11,MO_Common_ColumnHeader,0)),"N/A") -> -2800 | P11: =IF(ISNUMBER(N11),N11-K11,"N/A") -> -50 | Q11: =IFERROR(IF(ISNUMBER(N11),(N11-K11)/ABS(K11),"N/A"),"N/A") -> -0.018181818 | S11: 46143 | T11: Investor Presentation
A12: 215 | B12: =IF(INDEX(MO_SNA_IsHistoricalPeriod,,MATCH(F12,MO_Common_ColumnHeader,0)),"Historical","Forward") -> Forward | D12: Affiliate dividends | E12: MO_CFSum_Dividend | F12: Q2-2026 | I12: -2500 | J12: -2500 | K12: =AVERAGE(I12:J12) -> -2500 | M12: =IF(INDEX(MO_SNA_IsHistoricalPeriod,,MATCH(F12,MO_Common_ColumnHeader,0)),"Actual","Estimate") -> Estimate | S12: 46143 | T12: Investor Presentation
A13: 214
A14: 213 | B14: =IF(INDEX(MO_SNA_IsHistoricalPeriod,,MATCH(F14,MO_Common_ColumnHeader,0)),"Historical","Forward") -> Forward | D14: Total average daily production volumes growth, % | E14: MO_OS_Energy_AverageDailyProduction_Total | F14: FY2026 | G14: FY2025 | I14: 0.07 | J14: 0.1 | K14: =AVERAGE(I14:J14) -> 0.085 | M14: =IF(INDEX(MO_SNA_IsHistoricalPeriod,,MATCH(F14,MO_Common_ColumnHeader,0)),"Actual","Estimate") -> Estimate | N14: =INDEX(MO_OS_Energy_AverageDailyProduction_Total,0,MATCH(F14,MO_Common_ColumnHeader,0))/INDEX(MO_OS_Energy_AverageDailyProduction_Total,0,MATCH(G14,MO_Common_ColumnHeader,0))-1 -> 0.085572122 | P14: =IF(ISNUMBER(N14),N14-K14,"N/A") -> 0.0005721216 | Q14: =IFERROR(IF(ISNUMBER(N14),(N14-K14)/ABS(K14),"N/A"),"N/A") -> 0.0067308424 | S14: 46052 | T14: Investor Presentation
A15: 212 | B15: =IF(INDEX(MO_SNA_IsHistoricalPeriod,,MATCH(F15,MO_Common_ColumnHeader,0)),"Historical","Forward") -> Forward | D15: =INDEX(INDIRECT(E15),0,COLUMN(MO_Common_Column_A)) -> Total average daily production volumes, kBOE/d | E15: MO_KPI_Energy_AverageDailyProduction_Total | F15: FY2026 | I15: 3980 | J15: 4100 | K15: =AVERAGE(I15:J15) -> 4040 | M15: =IF(INDEX(MO_SNA_IsHistoricalPeriod,,MATCH(F15,MO_Common_ColumnHeader,0)),"Actual","Estimate") -> Estimate | N15: =IFERROR(INDEX(INDIRECT(E15),0,MATCH(F15,MO_Common_ColumnHeader,0)),"N/A") -> 4040.6804 | P15: =IF(ISNUMBER(N15),N15-K15,"N/A") -> 0.6803653 | Q15: =IFERROR(IF(ISNUMBER(N15),(N15-K15)/ABS(K15),"N/A"),"N/A") -> 0.00016840725 | S15: 46052 | T15: Investor Presentation
A16: 211 | B16: =IF(INDEX(MO_SNA_IsHistoricalPeriod,,MATCH(F16,MO_Common_ColumnHeader,0)),"Historical","Forward") -> Forward | D16: =INDEX(INDIRECT(E16),0,COLUMN(MO_Common_Column_A)) -> All other adjusted earnings, mm | E16: z_Z99BO00122_MO_OS_Allotheradjustedearnings | F16: FY2026 | I16: -3600 | J16: -4000 | K16: =AVERAGE(I16:J16) -> -3800 | M16: =IF(INDEX(MO_SNA_IsHistoricalPeriod,,MATCH(F16,MO_Common_ColumnHeader,0)),"Actual","Estimate") -> Estimate | S16: 46052 | T16: Investor Presentation
A17: 210 | B17: =IF(INDEX(MO_SNA_IsHistoricalPeriod,,MATCH(F17,MO_Common_ColumnHeader,0)),"Historical","Forward") -> Forward | D17: Affiliate dividends | E17: MO_CFSum_Dividend | F17: FY2026 | I17: -4500 | J17: -4500 | K17: =AVERAGE(I17:J17) -> -4500 | M17: =IF(INDEX(MO_SNA_IsHistoricalPeriod,,MATCH(F17,MO_Common_ColumnHeader,0)),"Actual","Estimate") -> Estimate | S17: 46052 | T17: Investor Presentation
A18: 209 | B18: =IF(INDEX(MO_SNA_IsHistoricalPeriod,,MATCH(F18,MO_Common_ColumnHeader,0)),"Historical","Forward") -> Forward | D18: Distributions more (less) affiliate income, mm | F18: FY2026 | I18: -2500 | J18: -2400 | K18: =AVERAGE(I18:J18) -> -2450 | M18: =IF(INDEX(MO_SNA_IsHistoricalPeriod,,MATCH(F18,MO_Common_ColumnHeader,0)),"Actual","Estimate") -> Estimate | S18: 46052 | T18: Investor Presentation
A19: 208 | B19: =IF(INDEX(MO_SNA_IsHistoricalPeriod,,MATCH(F19,MO_Common_ColumnHeader,0)),"Historical","Forward") -> Forward | D19: B/T asset sales proceeds, mm | E19: MO_CFSum_Divestiture | F19: FY2026 | I19: 1000 | J19: 3000 | K19: =AVERAGE(I19:J19) -> 2000 | M19: =IF(INDEX(MO_SNA_IsHistoricalPeriod,,MATCH(F19,MO_Common_ColumnHeader,0)),"Actual","Estimate") -> Estimate | N19: =IFERROR(INDEX(INDIRECT(E19),0,MATCH(F19,MO_Common_ColumnHeader,0)),"N/A") -> 1572 | P19: =IF(ISNUMBER(N19),N19-K19,"N/A") -> -428 | Q19: =IFERROR(IF(ISNUMBER(N19),(N19-K19)/ABS(K19),"N/A"),"N/A") -> -0.214 | S19: 46052 | T19: Investor Presentation
A20: 207 | B20: =IF(INDEX(MO_SNA_IsHistoricalPeriod,,MATCH(F20,MO_Common_ColumnHeader,0)),"Historical","Forward") -> Forward | D20: Organic C&E, mm | F20: FY2026 | I20: -19000 | J20: -18000 | K20: =AVERAGE(I20:J20) -> -18500 | M20: =IF(INDEX(MO_SNA_IsHistoricalPeriod,,MATCH(F20,MO_Common_ColumnHeader,0)),"Actual","Estimate") -> Estimate | S20: 46052 | T20: Investor Presentation
A21: 206 | B21: =IF(INDEX(MO_SNA_IsHistoricalPeriod,,MATCH(F21,MO_Common_ColumnHeader,0)),"Historical","Forward") -> Forward | D21: Capex by Affiliated Companies, mm | F21: FY2026 | I21: -2000 | J21: -1000 | K21: =AVERAGE(I21:J21) -> -1500 | M21: =IF(INDEX(MO_SNA_IsHistoricalPeriod,,MATCH(F21,MO_Common_ColumnHeader,0)),"Actual","Estimate") -> Estimate | S21: 46052 | T21: Investor Presentation
A22: 205 | B22: =IF(INDEX(MO_SNA_IsHistoricalPeriod,,MATCH(F22,MO_Common_ColumnHeader,0)),"Historical","Forward") -> Forward | D22: DD&A | F22: FY2026 | I22: 23000 | J22: 24000 | K22: =AVERAGE(I22:J22) -> 23500 | M22: =IF(INDEX(MO_SNA_IsHistoricalPeriod,,MATCH(F22,MO_Common_ColumnHeader,0)),"Actual","Estimate") -> Estimate | S22: 46052 | T22: Investor Presentation
A23: 204 | B23: =IF(INDEX(MO_SNA_IsHistoricalPeriod,,MATCH(F23,MO_Common_ColumnHeader,0)),"Historical","Forward") -> Forward | D23: TCO loan repayment, mm | F23: FY2026 | I23: 2000 | J23: 2000 | K23: =AVERAGE(I23:J23) -> 2000 | M23: =IF(INDEX(MO_SNA_IsHistoricalPeriod,,MATCH(F23,MO_Common_ColumnHeader,0)),"Actual","Estimate") -> Estimate | S23: 46052 | T23: Investor Presentation
A24: 203
A25: 202 | B25: =IF(INDEX(MO_SNA_IsHistoricalPeriod,,MATCH(F25,MO_Common_ColumnHeader,0)),"Historical","Forward") -> Historical | D25: Turnarounds & downtime, MBOE/d | F25: Q1-2026 | I25: -185 | J25: -225 | K25: =AVERAGE(I25:J25) -> -205 | M25: =IF(INDEX(MO_SNA_IsHistoricalPeriod,,MATCH(F25,MO_Common_ColumnHeader,0)),"Actual","Estimate") -> Actual | S25: 46052 | T25: Investor Presentation
A26: 201 | B26: =IF(INDEX(MO_SNA_IsHistoricalPeriod,,MATCH(F26,MO_Common_ColumnHeader,0)),"Historical","Forward") -> Historical | D26: Turnarounds (A/T earnings), mm | F26: Q1-2026 | I26: -275 | J26: -325 | K26: =AVERAGE(I26:J26) -> -300 | M26: =IF(INDEX(MO_SNA_IsHistoricalPeriod,,MATCH(F26,MO_Common_ColumnHeader,0)),"Actual","Estimate") -> Actual | S26: 46052 | T26: Investor Presentation
A27: 200 | B27: =IF(INDEX(MO_SNA_IsHistoricalPeriod,,MATCH(F27,MO_Common_ColumnHeader,0)),"Historical","Forward") -> Historical | D27: Share repurchase, mm | E27: MO_CFSum_NetShares | F27: Q1-2026 | I27: -2500 | J27: -3000 | K27: =AVERAGE(I27:J27) -> -2750 | M27: =IF(INDEX(MO_SNA_IsHistoricalPeriod,,MATCH(F27,MO_Common_ColumnHeader,0)),"Actual","Estimate") -> Actual | N27: =IFERROR(INDEX(INDIRECT(E27),0,MATCH(F27,MO_Common_ColumnHeader,0)),"N/A") -> -1412 | P27: =IF(ISNUMBER(N27),N27-K27,"N/A") -> 1338 | Q27: =IFERROR(IF(ISNUMBER(N27),(N27-K27)/ABS(K27),"N/A"),"N/A") -> 0.48654545 | S27: 46052 | T27: Investor Presentation
A28: 199 | B28: =IF(INDEX(MO_SNA_IsHistoricalPeriod,,MATCH(F28,MO_Common_ColumnHeader,0)),"Historical","Forward") -> Historical | D28: Affiliate dividends | E28: MO_CFSum_Dividend | F28: Q1-2026 | I28: -300 | J28: -400 | K28: =AVERAGE(I28:J28) -> -350 | M28: =IF(INDEX(MO_SNA_IsHistoricalPeriod,,MATCH(F28,MO_Common_ColumnHeader,0)),"Actual","Estimate") -> Actual | S28: 46052 | T28: Investor Presentation
A29: 198 | B29: =IF(INDEX(MO_SNA_IsHistoricalPeriod,,MATCH(F29,MO_Common_ColumnHeader,0)),"Historical","Forward") -> Historical | D29: TCO loan repayment, mm | F29: Q1-2026 | I29: 1000 | J29: 1000 | K29: =AVERAGE(I29:J29) -> 1000 | M29: =IF(INDEX(MO_SNA_IsHistoricalPeriod,,MATCH(F29,MO_Common_ColumnHeader,0)),"Actual","Estimate") -> Actual | S29: 46052 | T29: Investor Presentation
A30: 197
A31: 196 | B31: =IF(INDEX(MO_SNA_IsHistoricalPeriod,,MATCH(F31,MO_Common_ColumnHeader,0)),"Historical","Forward") -> Historical | D31: Upstream Turnarounds & downtime, MBOE/d | F31: Q4-2025 | I31: -125 | J31: -125 | K31: =AVERAGE(I31:J31) -> -125 | M31: =IF(INDEX(MO_SNA_IsHistoricalPeriod,,MATCH(F31,MO_Common_ColumnHeader,0)),"Actual","Estimate") -> Actual | S31: 45961 | T31: Investor Presentation
A32: 195 | B32: =IF(INDEX(MO_SNA_IsHistoricalPeriod,,MATCH(F32,MO_Common_ColumnHeader,0)),"Historical","Forward") -> Historical | D32: Downstream Turnarounds (A/T earnings), mm | F32: Q4-2025 | I32: -400 | J32: -500 | K32: =AVERAGE(I32:J32) -> -450 | M32: =IF(INDEX(MO_SNA_IsHistoricalPeriod,,MATCH(F32,MO_Common_ColumnHeader,0)),"Actual","Estimate") -> Actual | S32: 45961 | T32: Investor Presentation
A33: 194 | B33: =IF(INDEX(MO_SNA_IsHistoricalPeriod,,MATCH(F33,MO_Common_ColumnHeader,0)),"Historical","Forward") -> Historical | D33: Share repurchase, mm | E33: MO_CFSum_NetShares | F33: Q4-2025 | I33: -2500 | J33: -3000 | K33: =AVERAGE(I33:J33) -> -2750 | M33: =IF(INDEX(MO_SNA_IsHistoricalPeriod,,MATCH(F33,MO_Common_ColumnHeader,0)),"Actual","Estimate") -> Actual | N33: =IFERROR(INDEX(INDIRECT(E33),0,MATCH(F33,MO_Common_ColumnHeader,0)),"N/A") -> -2941 | P33: =IF(ISNUMBER(N33),N33-K33,"N/A") -> -191 | Q33: =IFERROR(IF(ISNUMBER(N33),(N33-K33)/ABS(K33),"N/A"),"N/A") -> -0.069454545 | S33: 45961 | T33: Investor Presentation
A34: 193 | B34: =IF(INDEX(MO_SNA_IsHistoricalPeriod,,MATCH(F34,MO_Common_ColumnHeader,0)),"Historical","Forward") -> Historical | D34: Affiliate dividends | F34: Q4-2025 | I34: -800 | J34: -900 | K34: =AVERAGE(I34:J34) -> -850 | M34: =IF(INDEX(MO_SNA_IsHistoricalPeriod,,MATCH(F34,MO_Common_ColumnHeader,0)),"Actual","Estimate") -> Actual | S34: 45961 | T34: Investor Presentation
A35: 192 | B35: =IF(INDEX(MO_SNA_IsHistoricalPeriod,,MATCH(F35,MO_Common_ColumnHeader,0)),"Historical","Forward") -> Historical | D35: All Other segment earnings, mm | F35: Q4-2025 | I35: -900 | J35: -1100 | K35: =AVERAGE(I35:J35) -> -1000 | M35: =IF(INDEX(MO_SNA_IsHistoricalPeriod,,MATCH(F35,MO_Common_ColumnHeader,0)),"Actual","Estimate") -> Actual | S35: 45961 | T35: Investor Presentation
A36: 191
A37: 190 | B37: =IF(INDEX(MO_SNA_IsHistoricalPeriod,,MATCH(F37,MO_Common_ColumnHeader,0)),"Historical","Forward") -> Historical | D37: Upstream Turnarounds & downtime, MBOE/d | F37: Q3-2025 | I37: -60 | J37: -60 | K37: =AVERAGE(I37:J37) -> -60 | M37: =IF(INDEX(MO_SNA_IsHistoricalPeriod,,MATCH(F37,MO_Common_ColumnHeader,0)),"Actual","Estimate") -> Actual | S37: 45870 | T37: Investor Presentation
A38: 189 | B38: =IF(INDEX(MO_SNA_IsHistoricalPeriod,,MATCH(F38,MO_Common_ColumnHeader,0)),"Historical","Forward") -> Historical | D38: Downstream Turnarounds (A/T earnings), mm | F38: Q3-2025 | I38: -200 | J38: -250 | K38: =AVERAGE(I38:J38) -> -225 | M38: =IF(INDEX(MO_SNA_IsHistoricalPeriod,,MATCH(F38,MO_Common_ColumnHeader,0)),"Actual","Estimate") -> Actual | S38: 45870 | T38: Investor Presentation
A39: 188 | B39: =IF(INDEX(MO_SNA_IsHistoricalPeriod,,MATCH(F39,MO_Common_ColumnHeader,0)),"Historical","Forward") -> Historical | D39: Share repurchase, mm | E39: MO_CFSum_NetShares | F39: Q3-2025 | I39: -2500 | J39: -3000 | K39: =AVERAGE(I39:J39) -> -2750 | M39: =IF(INDEX(MO_SNA_IsHistoricalPeriod,,MATCH(F39,MO_Common_ColumnHeader,0)),"Actual","Estimate") -> Actual | N39: =IFERROR(INDEX(INDIRECT(E39),0,MATCH(F39,MO_Common_ColumnHeader,0)),"N/A") -> -2482 | P39: =IF(ISNUMBER(N39),N39-K39,"N/A") -> 268 | Q39: =IFERROR(IF(ISNUMBER(N39),(N39-K39)/ABS(K39),"N/A"),"N/A") -> 0.097454545 | S39: 45870 | T39: Investor Presentation
A40: 187 | B40: =IF(INDEX(MO_SNA_IsHistoricalPeriod,,MATCH(F40,MO_Common_ColumnHeader,0)),"Historical","Forward") -> Historical | D40: Affiliate dividends | F40: Q3-2025 | I40: -700 | J40: -800 | K40: =AVERAGE(I40:J40) -> -750 | M40: =IF(INDEX(MO_SNA_IsHistoricalPeriod,,MATCH(F40,MO_Common_ColumnHeader,0)),"Actual","Estimate") -> Actual | S40: 45870 | T40: Investor Presentation
A41: 186 | B41: =IF(INDEX(MO_SNA_IsHistoricalPeriod,,MATCH(F41,MO_Common_ColumnHeader,0)),"Historical","Forward") -> Historical | D41: TCO loan repayment, mm | F41: Q3-2025 | I41: 1000 | J41: 1000 | K41: =AVERAGE(I41:J41) -> 1000 | M41: =IF(INDEX(MO_SNA_IsHistoricalPeriod,,MATCH(F41,MO_Common_ColumnHeader,0)),"Actual","Estimate") -> Actual | S41: 45870 | T41: Investor Presentation
...

Sheet Supplemental
A1: =MO.CompanyName -> Company0670 Company0697
A2: =MO.Ticker -> Ticker0006 US | C2: =Model!C2 -> 39813 | D2: =Model!D2 -> 0 | E2: =Model!E2 -> 0 | F2: =Model!F2 -> 0 | G2: =Model!G2 -> 0 | H2: =Model!H2 -> 0 | I2: =Model!I2 -> 0 | J2: =Model!J2 -> 0 | ... CF2: =Model!CF2 -> 0
A3: =MO.TradingCurrency -> USD | B3: =MO.LastPrice -> 185.16 | C3: =INDEX(MO_Common_FPDays,0,MATCH(C$5,MO_Common_ColumnHeader,0)) -> 365 | D3: =INDEX(MO_Common_FPDays,0,MATCH(D$5,MO_Common_ColumnHeader,0)) -> 365 | E3: =INDEX(MO_Common_FPDays,0,MATCH(E$5,MO_Common_ColumnHeader,0)) -> 365 | F3: =INDEX(MO_Common_FPDays,0,MATCH(F$5,MO_Common_ColumnHeader,0)) -> 366 | G3: =INDEX(MO_Common_FPDays,0,MATCH(G$5,MO_Common_ColumnHeader,0)) -> 90 | H3: =INDEX(MO_Common_FPDays,0,MATCH(H$5,MO_Common_ColumnHeader,0)) -> 91 | I3: =INDEX(MO_Common_FPDays,0,MATCH(I$5,MO_Common_ColumnHeader,0)) -> 92 | J3: =INDEX(MO_Common_FPDays,0,MATCH(J$5,MO_Common_ColumnHeader,0)) -> 92 | ... CF3: =INDEX(MO_Common_FPDays,0,MATCH(CF$5,MO_Common_ColumnHeader,0)) -> 365
A4: =MO.DataSourceName -> Bloomberg | B4: =MO.RealTime -> OFF | C4: =INDEX(MO_Common_QEndDate,0,MATCH(C$5,MO_Common_ColumnHeader,0)) -> 40178 | D4: =INDEX(MO_Common_QEndDate,0,MATCH(D$5,MO_Common_ColumnHeader,0)) -> 40543 | E4: =INDEX(MO_Common_QEndDate,0,MATCH(E$5,MO_Common_ColumnHeader,0)) -> 40908 | F4: =INDEX(MO_Common_QEndDate,0,MATCH(F$5,MO_Common_ColumnHeader,0)) -> 41274 | G4: =INDEX(MO_Common_QEndDate,0,MATCH(G$5,MO_Common_ColumnHeader,0)) -> 41364 | H4: =INDEX(MO_Common_QEndDate,0,MATCH(H$5,MO_Common_ColumnHeader,0)) -> 41455 | I4: =INDEX(MO_Common_QEndDate,0,MATCH(I$5,MO_Common_ColumnHeader,0)) -> 41547 | J4: =INDEX(MO_Common_QEndDate,0,MATCH(J$5,MO_Common_ColumnHeader,0)) -> 41639 | ... CF4: =INDEX(MO_Common_QEndDate,0,MATCH(CF$5,MO_Common_ColumnHeader,0)) -> 47848
A5: =MO.ReportFX -> USD | C5: =Model!C5 -> FY2009 | D5: =Model!D5 -> FY2010 | E5: =Model!E5 -> FY2011 | F5: =Model!F5 -> FY2012 | G5: =Model!G5 -> Q1-2013 | H5: =Model!H5 -> Q2-2013 | I5: =Model!I5 -> Q3-2013 | J5: =Model!J5 -> Q4-2013 | ... CF5: =Model!CF5 -> FY2030
A6: Costs Incurred in Exploration, Property Acquisitions and Development
A7: U.S. Wells, mm | AO7: 571 | AT7: 190 | AY7: 184 | BD7: 239 | BI7: 280 | BN7: 193 | BS7: 127
A8: U.S. Geological and geophysical, mm | AO8: 82 | AT8: 83 | AY8: 67 | BD8: 98 | BI8: 84 | BN8: 173 | BS8: 115
A9: U.S. Other, mm | AO9: 140 | AT9: 125 | AY9: 80 | BD9: 53 | BI9: 50 | BN9: 62 | BS9: 75
A10: U.S. Total exploration, mm | AO10: =SUM(AO7:AO9) -> 793 | AT10: =SUM(AT7:AT9) -> 398 | AY10: =SUM(AY7:AY9) -> 331 | BD10: =SUM(BD7:BD9) -> 390 | BI10: =SUM(BI7:BI9) -> 414 | BN10: =SUM(BN7:BN9) -> 428 | BS10: =SUM(BS7:BS9) -> 317
A11: U.S. Proved - Company1944, mm | AO11: 81 | AT11: 3463
A12: U.S. Proved - Other, mm | AT12: 23 | AY12: 98 | BD12: 18 | BI12: 10123 | BN12: 11 | BS12: 19947
A13: U.S. Unproved - Company1944, mm | AO13: 68 | AT13: 2845
A14: U.S. Unproved - Other, mm | AT14: 35 | AY14: 13 | BD14: 104 | BI14: 504 | BN14: 69 | BS14: 1783
A15: U.S. Total property acquisitions, mm | AO15: =SUM(AO11:AO14) -> 149 | AT15: =SUM(AT11:AT14) -> 6366 | AY15: =SUM(AY11:AY14) -> 111 | BD15: =SUM(BD11:BD14) -> 122 | BI15: =SUM(BI11:BI14) -> 10627 | BN15: =SUM(BN11:BN14) -> 80 | BS15: =SUM(BS11:BS14) -> 21730
A16: U.S. Development, mm | AO16: 7072 | AT16: 4622 | AY16: 4360 | BD16: 6221 | BI16: 9645 | BN16: 9334 | BS16: 8532
A17: U.S. Total Costs Incurred, mm | AO17: =AO10+AO15+AO16 -> 8014 | AT17: =AT10+AT15+AT16 -> 11386 | AY17: =AY10+AY15+AY16 -> 4802 | BD17: =BD10+BD15+BD16 -> 6733 | BI17: =BI10+BI15+BI16 -> 20686 | BN17: =BN10+BN15+BN16 -> 9842 | BS17: =BS10+BS15+BS16 -> 30579
A18: Other Americas Wells, mm | AO18: 44 | AT18: 181 | AY18: 31 | BD18: 84 | BI18: 92 | BN18: 2 | BS18: 161
A19: Other Americas Geological and geophysical, mm | AO19: 118 | AT19: 29 | AY19: 58 | BD19: 28 | BI19: 49 | BN19: 81 | BS19: 140
A20: Other Americas Other, mm | AO20: 52 | AT20: 77 | AY20: 80 | BD20: 72 | BI20: 104 | BN20: 62 | BS20: 71
A21: Other Americas Total exploration, mm | AO21: =SUM(AO18:AO20) -> 214 | AT21: =SUM(AT18:AT20) -> 287 | AY21: =SUM(AY18:AY20) -> 169 | BD21: =SUM(BD18:BD20) -> 184 | BI21: =SUM(BI18:BI20) -> 245 | BN21: =SUM(BN18:BN20) -> 145 | BS21: =SUM(BS18:BS20) -> 372
A22: Other Americas Proved - Company1944, mm | AO22: 34 | AT22: 0
A23: Other Americas Proved - Other, mm | AT23: 0 | AY23: 0 | BD23: 0 | BI23: 0 | BN23: 0 | BS23: 22987
A24: Other Americas Unproved - Company1944, mm | AO24: 150 | AT24: 2
A25: Other Americas Unproved - Other, mm | AT25: 0 | AY25: 16 | BD25: 78 | BI25: 1 | BN25: 38 | BS25: 28141
A26: Other Americas Total property acquisitions, mm | AO26: =SUM(AO22:AO25) -> 184 | AT26: =SUM(AT22:AT25) -> 2 | AY26: =SUM(AY22:AY25) -> 16 | BD26: =SUM(BD22:BD25) -> 78 | BI26: =SUM(BI22:BI25) -> 1 | BN26: =SUM(BN22:BN25) -> 38 | BS26: =SUM(BS22:BS25) -> 51128
A27: Other Americas Development, mm | AO27: 1216 | AT27: 740 | AY27: 640 | BD27: 863 | BI27: 986 | BN27: 1261 | BS27: 2402
A28: Other Americas Total Costs Incurred, mm | AO28: =AO21+AO26+AO27 -> 1614 | AT28: =AT21+AT26+AT27 -> 1029 | AY28: =AY21+AY26+AY27 -> 825 | BD28: =BD21+BD26+BD27 -> 1125 | BI28: =BI21+BI26+BI27 -> 1232 | BN28: =BN21+BN26+BN27 -> 1444 | BS28: =BS21+BS26+BS27 -> 53902
A29: Africa Wells, mm | AO29: 9 | AT29: 1 | AY29: 5 | BD29: 78 | BI29: 36 | BN29: 155 | BS29: 109
A30: Africa Geological and geophysical, mm | AO30: 21 | AT30: 58 | AY30: 40 | BD30: 110 | BI30: 83 | BN30: 47 | BS30: 162
A31: Africa Other, mm | AO31: 35 | AT31: 42 | AY31: 39 | BD31: 75 | BI31: 57 | BN31: 70 | BS31: 92
A32: Africa Total exploration, mm | AO32: =SUM(AO29:AO31) -> 65 | AT32: =SUM(AT29:AT31) -> 101 | AY32: =SUM(AY29:AY31) -> 84 | BD32: =SUM(BD29:BD31) -> 263 | BI32: =SUM(BI29:BI31) -> 176 | BN32: =SUM(BN29:BN31) -> 272 | BS32: =SUM(BS29:BS31) -> 363
A33: Africa Proved - Company1944, mm | AT33: 438
A34: Africa Proved - Other, mm | AT34: 2 | AY34: 15 | BD34: 63 | BN34: 95 | BS34: 0
A35: Africa Unproved - Company1944, mm | AT35: 113
A36: Africa Unproved - Other, mm | AT36: 10 | AY36: 0 | BD36: 73 | BN36: 22 | BS36: 15
A37: Africa Total property acquisitions, mm | AO37: =SUM(AO34:AO36) -> 0 | AT37: =SUM(AT33:AT36) -> 563 | AY37: =SUM(AY33:AY36) -> 15 | BD37: =SUM(BD33:BD36) -> 136 | BI37: =SUM(BI33:BI36) -> 0 | BN37: =SUM(BN33:BN36) -> 117 | BS37: =SUM(BS33:BS36) -> 15
A38: Africa Development, mm | AO38: 279 | AT38: 386 | AY38: 383 | BD38: 21 | BI38: 784 | BN38: 895 | BS38: 1390
A39: Africa Total Costs Incurred, mm | AO39: =AO32+AO37+AO38 -> 344 | AT39: =AT32+AT37+AT38 -> 1050 | AY39: =AY32+AY37+AY38 -> 482 | BD39: =BD32+BD37+BD38 -> 420 | BI39: =BI32+BI37+BI38 -> 960 | BN39: =BN32+BN37+BN38 -> 1284 | BS39: =BS32+BS37+BS38 -> 1768
