Workbook
Name __FDS_UNIQUE_RANGE_ID_GENERATOR_COUNTER: 1
Name A_ALL_Ticker0001: Ticker0001_Annotation_Sheet!$A$1:$FE$309
Name A_ALL_KEYWORDS_TYPE_ScalarContributed_EQTY_200000801: Ticker0001_Annotation_Sheet!$245:$245,Ticker0001_Annotation_Sheet!$248:$254,Ticker0001_Annotation_Sheet!$296:$296,Ticker0001_Annotation_Sheet!$300:$302,Ticker0001_Annotation_Sheet!$307:$309
Name A_ALL_KEYWORDS_TYPE_ScalarContributed_EQTY_200000801: Ticker0001_Annotation_Sheet!$248:$254,Ticker0001_Annotation_Sheet!$296:$296,Ticker0001_Annotation_Sheet!$300:$302,Ticker0001_Annotation_Sheet!$307:$309,Ticker0001_Annotation_Sheet!$245:$246
Name A_ALL_KEYWORDS_TYPE_ScalarContributed_ISSR_208000149: Ticker0001_Annotation_Sheet!$9:$9,Ticker0001_Annotation_Sheet!$39:$39
Name A_ALL_KEYWORDS_TYPE_ScalarReference_EQTY_200000801: Ticker0001_Annotation_Sheet!$238:$243
Name A_ALL_KEYWORDS_TYPE_ScalarReference_ISSR_208000149: Ticker0001_Annotation_Sheet!$6:$7
Name A_ALL_PERIODS_Ticker0001: Ticker0001_Annotation_Sheet!$F$1:$FE$1
Name A_ALL_SECTION_KEYWORDS_EQTY_200000801_1314: Ticker0001_Annotation_Sheet!$C$298
Name A_ALL_SECTION_KEYWORDS_EQTY_200000801_1319: Ticker0001_Annotation_Sheet!$C$300:$C$303
Name A_ALL_SECTION_KEYWORDS_EQTY_200000801_131E: Ticker0001_Annotation_Sheet!$C$305
Name A_ALL_SECTION_KEYWORDS_EQTY_200000801_131O: Ticker0001_Annotation_Sheet!$C$307:$C$309
Name A_ALL_SECTION_KEYWORDS_EQTY_200000801_13A: Ticker0001_Annotation_Sheet!$C$245:$C$254
Name A_ALL_SECTION_KEYWORDS_EQTY_200000801_13A: Ticker0001_Annotation_Sheet!$C$245:$C$254
Name A_ALL_SECTION_KEYWORDS_EQTY_200000801_13K: Ticker0001_Annotation_Sheet!$C$256:$C$271
Name A_ALL_SECTION_KEYWORDS_EQTY_200000801_13U: Ticker0001_Annotation_Sheet!$C$273:$C$288
Name A_ALL_SECTION_KEYWORDS_EQTY_200000801_13V: Ticker0001_Annotation_Sheet!$C$290
Name A_ALL_SECTION_KEYWORDS_EQTY_200000801_13W: Ticker0001_Annotation_Sheet!$C$292:$C$296
Name A_ALL_SECTION_KEYWORDS_EQTY_200000801_Reference_Data: Ticker0001_Annotation_Sheet!$C$238:$C$243
Name A_ALL_SECTION_KEYWORDS_ISSR_208000149_1314: Ticker0001_Annotation_Sheet!$C$41:$C$70
Name A_ALL_SECTION_KEYWORDS_ISSR_208000149_13168: Ticker0001_Annotation_Sheet!$C$128:$C$189
Name A_ALL_SECTION_KEYWORDS_ISSR_208000149_1316T: Ticker0001_Annotation_Sheet!$C$191:$C$197
Name A_ALL_SECTION_KEYWORDS_ISSR_208000149_1316U: Ticker0001_Annotation_Sheet!$C$199:$C$213
Name A_ALL_SECTION_KEYWORDS_ISSR_208000149_1319: Ticker0001_Annotation_Sheet!$C$72:$C$90
Name A_ALL_SECTION_KEYWORDS_ISSR_208000149_131E: Ticker0001_Annotation_Sheet!$C$92:$C$108
Name A_ALL_SECTION_KEYWORDS_ISSR_208000149_131J: Ticker0001_Annotation_Sheet!$C$110:$C$122
Name A_ALL_SECTION_KEYWORDS_ISSR_208000149_131O: Ticker0001_Annotation_Sheet!$C$124
Name A_ALL_SECTION_KEYWORDS_ISSR_208000149_131O: Ticker0001_Annotation_Sheet!$C$124,Ticker0001_Annotation_Sheet!$C$126
Name A_ALL_SECTION_KEYWORDS_ISSR_208000149_136E: Ticker0001_Annotation_Sheet!$C$215:$C$224
Name A_ALL_SECTION_KEYWORDS_ISSR_208000149_136J: Ticker0001_Annotation_Sheet!$C$226:$C$235
Name A_ALL_SECTION_KEYWORDS_ISSR_208000149_13A: Ticker0001_Annotation_Sheet!$C$9
Name A_ALL_SECTION_KEYWORDS_ISSR_208000149_13U: Ticker0001_Annotation_Sheet!$C$11:$C$30
Name A_ALL_SECTION_KEYWORDS_ISSR_208000149_13V: Ticker0001_Annotation_Sheet!$C$32:$C$39
Name A_ALL_SECTION_KEYWORDS_ISSR_208000149_Reference_Data: Ticker0001_Annotation_Sheet!$C$6:$C$7
Name A_CURRENCY_EQTY_200000801_PRI: Ticker0001_Annotation_Sheet!$E$242
Name A_CURRENCY_EQTY_200000801_PUB: Ticker0001_Annotation_Sheet!$E$241
Name A_CURRENCY_EQTY_200000801_REP: Ticker0001_Annotation_Sheet!$E$243
Name A_CURRENCY_ISSR_208000149_REP: Ticker0001_Annotation_Sheet!$E$7
Name A_ENTITY_DATA_EQTY_200000801: Ticker0001_Annotation_Sheet!$E$237:$FE$309
Name A_ENTITY_DATA_ISSR_208000149: Ticker0001_Annotation_Sheet!$E$5:$FE$235
Name A_KEYWORD_EQTY_200000801_AMER_CONVICTION: Ticker0001_Annotation_Sheet!$247:$247
Name A_KEYWORD_EQTY_200000801_AMER_LIST: Ticker0001_Annotation_Sheet!$245:$245
Name A_KEYWORD_EQTY_200000801_BETA_ANALYST: Ticker0001_Annotation_Sheet!$307:$307
Name A_KEYWORD_EQTY_200000801_BVPS: Ticker0001_Annotation_Sheet!$298:$298
Name A_KEYWORD_EQTY_200000801_BVPS_PUB: Ticker0001_Annotation_Sheet!$256:$256
Name A_KEYWORD_EQTY_200000801_CEEE_EPS: Ticker0001_Annotation_Sheet!$261:$261
Name A_KEYWORD_EQTY_200000801_CEEE_NDEBT: Ticker0001_Annotation_Sheet!$266:$266
Name A_KEYWORD_EQTY_200000801_CF_NI_PRE_PREF: Ticker0001_Annotation_Sheet!$305:$305
Name A_KEYWORD_EQTY_200000801_COMMON_DIV_PAID: Ticker0001_Annotation_Sheet!$284:$284
Name A_KEYWORD_EQTY_200000801_CURRENCY_ISO: Ticker0001_Annotation_Sheet!$243:$243
Name A_KEYWORD_EQTY_200000801_DILUTE_SHARES: Ticker0001_Annotation_Sheet!$287:$287
Name A_KEYWORD_EQTY_200000801_DPS: Ticker0001_Annotation_Sheet!$285:$285
Name A_KEYWORD_EQTY_200000801_DPS_PUB: Ticker0001_Annotation_Sheet!$257:$257
Name A_KEYWORD_EQTY_200000801_DPS_SPECIAL_PUB: Ticker0001_Annotation_Sheet!$258:$258
Name A_KEYWORD_EQTY_200000801_EBIT_PUB: Ticker0001_Annotation_Sheet!$268:$268
Name A_KEYWORD_EQTY_200000801_EBITDA_PUB: Ticker0001_Annotation_Sheet!$259:$259
Name A_KEYWORD_EQTY_200000801_EPS: Ticker0001_Annotation_Sheet!$280:$280
Name A_KEYWORD_EQTY_200000801_EPS_EX_ESO_B: Ticker0001_Annotation_Sheet!$294:$294
Name A_KEYWORD_EQTY_200000801_EPS_EX_ESO_D: Ticker0001_Annotation_Sheet!$295:$295
Name A_KEYWORD_EQTY_200000801_EPS_FUL_DIL: Ticker0001_Annotation_Sheet!$281:$281

Sheet __FDSCACHE__
B1: This sheet contains FactSet XML data for use with this workbook's =FDS codes. Modifying the worksheet's contents may damage the workbook's =FDS functionality.

Sheet Cover Sheet
I2: Company1149, Company2521 & Co.
I3: Global Investment Research
A6: Sector: Hardware and Communications Technology
A8: Company Model
A10: Company0243. (Ticker0001)
A13: Person1252 Person1255, CFA, CPA
A14: (212) 902 8618
A15: person@example.com
A31: Source: Company data, Company1150 Global Investment Research

Sheet Revenue summary
A3: Company0243. (Ticker0001)
A4: Revenue summary
A6: # weeks in the quarter | BR6: 13 | BS6: 13 | BT6: 13 | BU6: 13 | BV6: 13 | BW6: =(BW7-BV7)/7 | BX6: =(BX7-BW7)/7 | BY6: =(BY7-BX7)/7 | BZ6: =(BZ7-BY7)/7 | CA6: =(CA7-BZ7)/7 | CB6: =(CB7-CA7)/7 | CC6: =(CC7-CB7)/7 | CD6: =(CD7-CC7)/7 | ... EK6: =(EK7-EJ7)/7
A7: Quarter end date | BV7: 41636 | BW7: 41727 | BX7: 41818 | BY7: 41909 | BZ7: 42000 | CA7: 42091 | CB7: 42182 | CC7: 42273 | CD7: ='Income Statement'!CD6 | CE7: ='Income Statement'!CE6 | CF7: ='Income Statement'!CF6 | CG7: ='Income Statement'!CG6 | CH7: ='Income Statement'!CH6 | CI7: ='Income Statement'!CI6 | CJ7: ='Income Statement'!CJ6 | CK7: ='Income Statement'!CK6 | ... EK7: ='Income Statement'!EK6
B8: Q196 | C8: Q296 | D8: Q396 | E8: Q496 | F8: Q197 | G8: Q297 | H8: Q397 | I8: Q497 | J8: Q198 | K8: Q298 | L8: Q398 | M8: Q498 | N8: Q199 | O8: Q299 | P8: Q399 | Q8: Q499 | R8: Q100 | S8: Q200 | T8: Q300 | U8: Q400 | V8: Q101 | W8: Q201 | X8: Q301 | Y8: Q401 | Z8: Q102 | AA8: Q202 | AB8: Q302 | AC8: Q402 | AD8: Q103 | AE8: Q203 | AF8: Q303 | AG8: Q403 | AH8: Q104 | AI8: Q204 | AJ8: Q304 | AK8: Q404 | AL8: Q105 | AM8: Q205 | AN8: Q305 | AO8: Q405 | AP8: Q106 | AQ8: Q206 | AR8: Q306 | AS8: Q406 | AT8: Q107 | AU8: Q207 | AV8: Q307 | AW8: Q407 | AX8: Q108 | AY8: Q208 | AZ8: Q308 | BA8: Q408 | BB8: Q109 | BC8: Q209 | BD8: Q309 | BE8: Q409 | BF8: Q110 | BG8: Q210 | BH8: Q310 | BI8: Q410 | BJ8: ='Income Statement'!BJ7 | BK8: ='Income Statement'!BK7 | BL8: ='Income Statement'!BL7 | BM8: ='Income Statement'!BM7 | BN8: ='Income Statement'!BN7 | BO8: ='Income Statement'!BO7 | BP8: ='Income Statement'!BP7 | BQ8: ='Income Statement'!BQ7 | ... EK8: ='Income Statement'!EK7 | FF8: FISCAL | GQ8: CALENDAR
A9: $, millions | B9: 35064 | C9: 35155 | D9: 35246 | E9: 35338 | F9: 35430 | G9: 35520 | H9: 35611 | I9: 35703 | J9: 35795 | K9: 35885 | L9: 35976 | M9: 36068 | N9: 36160 | O9: 36250 | P9: 36341 | Q9: 36433 | R9: 36525 | S9: 36616 | T9: 36707 | U9: 36799 | V9: 36891 | W9: 36981 | X9: 37072 | Y9: 37164 | Z9: 37256 | AA9: 37346 | AB9: 37437 | AC9: 37529 | AD9: 37621 | AE9: 37711 | AF9: 37802 | AG9: 37894 | AH9: 37986 | AI9: 38077 | AJ9: 38168 | AK9: 38260 | AL9: 38352 | AM9: 38442 | AN9: 38533 | AO9: 38625 | AP9: 38717 | AQ9: 38807 | AR9: 38898 | AS9: 38990 | AT9: 39082 | AU9: 39172 | AV9: 39263 | AW9: 39355 | AX9: 39447 | AY9: 39538 | AZ9: 39629 | BA9: 39721 | BB9: 39813 | BC9: 39903 | BD9: 39994 | BE9: 40086 | BF9: 40178 | BG9: 40268 | BH9: 40359 | BI9: 40451 | BJ9: 40543 | BK9: 40633 | BL9: 40724 | BM9: 40816 | BN9: 40908 | BO9: 40999 | BP9: 41090 | BQ9: 41182 | BR9: 41274 | BS9: 41364 | BT9: 41455 | BU9: 41547 | BV9: 41639 | BW9: 41729 | BX9: 41820 | BY9: 41912 | BZ9: ='Income Statement'!BZ8 | CA9: ='Income Statement'!CA8 | CB9: ='Income Statement'!CB8 | CC9: ='Income Statement'!CC8 | CD9: ='Income Statement'!CD8 | CE9: ='Income Statement'!CE8 | CF9: ='Income Statement'!CF8 | CG9: ='Income Statement'!CG8 | ... EK9: ='Income Statement'!EK8 | EM9: 1996 | EN9: 1997 | EO9: 1998 | EP9: 1999 | EQ9: 2000 | ER9: 2001 | ES9: 2002 | ET9: 2003 | EU9: 2004 | EV9: 2005 | EW9: 2006 | EX9: 2007 | EY9: 2008 | EZ9: 2009 | FA9: 2010 | FB9: 2011 | FC9: 2012 | FD9: FY'2013 | FE9: ='Income Statement'!FE8 | FF9: ='Income Statement'!FF8 | FG9: ='Income Statement'!FG8 | FH9: ='Income Statement'!FH8 | FI9: ='Income Statement'!FI8 | FJ9: ='Income Statement'!FJ8 | FK9: ='Income Statement'!FK8 | FL9: ='Income Statement'!FL8 | ... FU9: ='Income Statement'!FU8 | FX9: 1996 | FY9: 1997 | FZ9: 1998 | GA9: 1999 | GB9: 2000 | GC9: 2001 | GD9: 2002 | GE9: 2003 | GF9: 2004 | GG9: 2005 | GH9: 2006 | GI9: 2007 | GJ9: 2008 | GK9: 2009 | GL9: 2010 | GM9: 2011 | GN9: 2012 | GO9: 2013 | GP9: ='Income Statement'!GO8 | GQ9: ='Income Statement'!GP8 | GR9: ='Income Statement'!GQ8 | GS9: ='Income Statement'!GR8 | GT9: ='Income Statement'!GS8 | GU9: ='Income Statement'!GT8 | GV9: ='Income Statement'!GU8 | GW9: ='Income Statement'!GV8 | ... HE9: ='Income Statement'!HD8
A10: Segments: | BV10: <--Accounting change in FQ1'19. Segment level #s below are estimates until FQ4'17, Company0242 restated FY18 and beyond numbers, do not compare to FY12 and prior numbers | GS10: Segment level numbers not comparable to CY18 and beyond numbers due to accounting change-->
A11: Product0489 | AV11: ='Segment - Products'!AV194 | AW11: ='Segment - Products'!AW194 | AX11: ='Segment - Products'!AX194 | AY11: ='Segment - Products'!AY194 | AZ11: ='Segment - Products'!AZ194 | BA11: ='Segment - Products'!BA194 | BB11: ='Segment - Products'!BB194 | BC11: ='Segment - Products'!BC194 | ... BU11: ='Segment - Products'!BU194 | BV11: ='Segment - Products'!BV11 | BW11: ='Segment - Products'!BW11 | BX11: ='Segment - Products'!BX11 | BY11: ='Segment - Products'!BY11 | BZ11: ='Segment - Products'!BZ11 | CA11: ='Segment - Products'!CA11 | CB11: ='Segment - Products'!CB11 | CC11: ='Segment - Products'!CC11 | ... DD11: ='Segment - Products'!DD11 | DE11: 42626 | DF11: 65775 | DG11: 51334 | DH11: 39669 | DI11: 43805 | DJ11: 69702 | DK11: 45963 | DL11: 39296 | DM11: 46222 | DN11: 69138 | DO11: 46841 | DP11: 44582 | DQ11: ='Segment - Products'!DQ11 | DR11: ='Segment - Products'!DR11 | DS11: ='Segment - Products'!DS11 | DT11: ='Segment - Products'!DT11 | DU11: ='Segment - Products'!DU11 | DV11: ='Segment - Products'!DV11 | DW11: ='Segment - Products'!DW11 | DX11: ='Segment - Products'!DX11 | ... EK11: ='Segment - Products'!EK11 | EX11: =SUM(AT11:AW11) | EY11: =SUM(AX11:BA11) | EZ11: =SUM(BB11:BE11) | FA11: =SUM(BF11:BI11) | FB11: =SUM(BJ11:BM11) | FC11: =SUM(BN11:BQ11) | FD11: =SUM(BR11:BU11) | FE11: =SUM(BV11:BY11) | FF11: =SUM(BZ11:CC11) | FG11: =SUM(CD11:CG11) | FH11: 139337 | FI11: =SUM(CL11:CO11) | FJ11: =SUM(CP11:CS11) | FK11: =SUM(CT11:CW11) | FL11: =SUM(CX11:DA11) | FM11: =SUM(DB11:DE11) | FN11: =SUM(DF11:DI11) | FO11: =SUM(DJ11:DM11) | FP11: =SUM(DN11:DQ11) | FQ11: =SUM(DR11:DU11) | FR11: =SUM(DV11:DY11) | FS11: =SUM(DZ11:EC11) | FT11: =SUM(ED11:EG11) | FU11: =SUM(EH11:EK11) | GI11: =SUM(AU11:AX11) | GJ11: =SUM(AY11:BB11) | GK11: =SUM(BC11:BF11) | GL11: =SUM(BG11:BJ11) | GM11: =SUM(BK11:BN11) | GN11: =SUM(BO11:BR11) | GO11: =SUM(BS11:BV11) | GP11: =SUM(BW11:BZ11) | GQ11: =SUM(CA11:CD11) | GR11: =SUM(CE11:CH11) | GS11: =SUM(CI11:CL11) | GT11: =SUM(CM11:CP11) | GU11: =SUM(CQ11:CT11) | GV11: =SUM(CU11:CX11) | GW11: =SUM(CY11:DB11) | GX11: =SUM(DC11:DF11) | GY11: =SUM(DG11:DJ11) | GZ11: =SUM(DK11:DN11) | HA11: =SUM(DO11:DR11) | HB11: =SUM(DS11:DV11) | HC11: =SUM(DW11:DZ11) | HD11: =SUM(EA11:ED11) | HE11: =SUM(EE11:EH11)
A12: Mac | AT12: ='Segment - Products'!AT196 | AU12: ='Segment - Products'!AU196 | AV12: ='Segment - Products'!AV196 | AW12: ='Segment - Products'!AW196 | AX12: ='Segment - Products'!AX196 | AY12: ='Segment - Products'!AY196 | AZ12: ='Segment - Products'!AZ196 | BA12: ='Segment - Products'!BA196 | ... BU12: ='Segment - Products'!BU196 | BV12: ='Segment - Products'!BV12 | BW12: ='Segment - Products'!BW12 | BX12: ='Segment - Products'!BX12 | BY12: ='Segment - Products'!BY12 | BZ12: ='Segment - Products'!BZ12 | CA12: ='Segment - Products'!CA12 | CB12: ='Segment - Products'!CB12 | CC12: ='Segment - Products'!CC12 | ... DD12: ='Segment - Products'!DD12 | DE12: 11508 | DF12: 7735 | DG12: 7168 | DH12: 6840 | DI12: 7614 | DJ12: 7780 | DK12: 7451 | DL12: 7009 | DM12: 7744 | DN12: 8987 | DO12: 7949 | DP12: 8046 | DQ12: ='Segment - Products'!DQ12 | DR12: ='Segment - Products'!DR12 | DS12: ='Segment - Products'!DS12 | DT12: ='Segment - Products'!DT12 | DU12: ='Segment - Products'!DU12 | DV12: ='Segment - Products'!DV12 | DW12: ='Segment - Products'!DW12 | DX12: ='Segment - Products'!DX12 | ... EK12: ='Segment - Products'!EK12 | EX12: =SUM(AT12:AW12) | EY12: =SUM(AX12:BA12) | EZ12: =SUM(BB12:BE12) | FA12: =SUM(BF12:BI12) | FB12: =SUM(BJ12:BM12) | FC12: =SUM(BN12:BQ12) | FD12: =SUM(BR12:BU12) | FE12: =SUM(BV12:BY12) | FF12: =SUM(BZ12:CC12) | FG12: =SUM(CD12:CG12) | FH12: 25569 | FI12: =SUM(CL12:CO12) | FJ12: =SUM(CP12:CS12) | FK12: =SUM(CT12:CW12) | FL12: =SUM(CX12:DA12) | FM12: =SUM(DB12:DE12) | FN12: =SUM(DF12:DI12) | FO12: =SUM(DJ12:DM12) | FP12: =SUM(DN12:DQ12) | FQ12: =SUM(DR12:DU12) | FR12: =SUM(DV12:DY12) | FS12: =SUM(DZ12:EC12) | FT12: =SUM(ED12:EG12) | FU12: =SUM(EH12:EK12) | GI12: =SUM(AU12:AX12) | GJ12: =SUM(AY12:BB12) | GK12: =SUM(BC12:BF12) | GL12: =SUM(BG12:BJ12) | GM12: =SUM(BK12:BN12) | GN12: =SUM(BO12:BR12) | GO12: =SUM(BS12:BV12) | GP12: =SUM(BW12:BZ12) | GQ12: =SUM(CA12:CD12) | GR12: =SUM(CE12:CH12) | GS12: =SUM(CI12:CL12) | GT12: =SUM(CM12:CP12) | GU12: =SUM(CQ12:CT12) | GV12: =SUM(CU12:CX12) | GW12: =SUM(CY12:DB12) | GX12: =SUM(DC12:DF12) | GY12: =SUM(DG12:DJ12) | GZ12: =SUM(DK12:DN12) | HA12: =SUM(DO12:DR12) | HB12: =SUM(DS12:DV12) | HC12: =SUM(DW12:DZ12) | HD12: =SUM(EA12:ED12) | HE12: =SUM(EE12:EH12)
A13: Product0487 | AV13: ='Segment - Products'!AV195 | AW13: ='Segment - Products'!AW195 | AX13: ='Segment - Products'!AX195 | AY13: ='Segment - Products'!AY195 | AZ13: ='Segment - Products'!AZ195 | BA13: ='Segment - Products'!BA195 | BB13: ='Segment - Products'!BB195 | BC13: ='Segment - Products'!BC195 | ... BU13: ='Segment - Products'!BU195 | BV13: ='Segment - Products'!BV13 | BW13: ='Segment - Products'!BW13 | BX13: ='Segment - Products'!BX13 | BY13: ='Segment - Products'!BY13 | BZ13: ='Segment - Products'!BZ13 | CA13: ='Segment - Products'!CA13 | CB13: ='Segment - Products'!CB13 | CC13: ='Segment - Products'!CC13 | ... DD13: ='Segment - Products'!DD13 | DE13: 7174 | DF13: 9396 | DG13: 6670 | DH13: 5791 | DI13: 6443 | DJ13: 7023 | DK13: 5559 | DL13: 7162 | DM13: 6950 | DN13: 8088 | DO13: 6402 | DP13: 6581 | DQ13: ='Segment - Products'!DQ13 | DR13: ='Segment - Products'!DR13 | DS13: ='Segment - Products'!DS13 | DT13: ='Segment - Products'!DT13 | DU13: ='Segment - Products'!DU13 | DV13: ='Segment - Products'!DV13 | DW13: ='Segment - Products'!DW13 | DX13: ='Segment - Products'!DX13 | ... EK13: ='Segment - Products'!EK13 | EX13: =SUM(AT13:AW13) | EY13: =SUM(AX13:BA13) | EZ13: =SUM(BB13:BE13) | FA13: =SUM(BF13:BI13) | FB13: =SUM(BJ13:BM13) | FC13: =SUM(BN13:BQ13) | FD13: =SUM(BR13:BU13) | FE13: =SUM(BV13:BY13) | FF13: =SUM(BZ13:CC13) | FG13: =SUM(CD13:CG13) | FH13: 18802 | FI13: =SUM(CL13:CO13) | FJ13: =SUM(CP13:CS13) | FK13: =SUM(CT13:CW13) | FL13: =SUM(CX13:DA13) | FM13: =SUM(DB13:DE13) | FN13: =SUM(DF13:DI13) | FO13: =SUM(DJ13:DM13) | FP13: =SUM(DN13:DQ13) | FQ13: =SUM(DR13:DU13) | FR13: =SUM(DV13:DY13) | FS13: =SUM(DZ13:EC13) | FT13: =SUM(ED13:EG13) | FU13: =SUM(EH13:EK13) | GI13: =SUM(AU13:AX13) | GJ13: =SUM(AY13:BB13) | GK13: =SUM(BC13:BF13) | GL13: =SUM(BG13:BJ13) | GM13: =SUM(BK13:BN13) | GN13: =SUM(BO13:BR13) | GO13: =SUM(BS13:BV13) | GP13: =SUM(BW13:BZ13) | GQ13: =SUM(CA13:CD13) | GR13: =SUM(CE13:CH13) | GS13: =SUM(CI13:CL13) | GT13: =SUM(CM13:CP13) | GU13: =SUM(CQ13:CT13) | GV13: =SUM(CU13:CX13) | GW13: =SUM(CY13:DB13) | GX13: =SUM(DC13:DF13) | GY13: =SUM(DG13:DJ13) | GZ13: =SUM(DK13:DN13) | HA13: =SUM(DO13:DR13) | HB13: =SUM(DS13:DV13) | HC13: =SUM(DW13:DZ13) | HD13: =SUM(EA13:ED13) | HE13: =SUM(EE13:EH13)
A14: Wearables, Home and Accessories | AT14: ='Segment - Products'!AT197 | AU14: ='Segment - Products'!AU197 | AV14: ='Segment - Products'!AV197 | AW14: ='Segment - Products'!AW197 | AX14: ='Segment - Products'!AX197 | AY14: ='Segment - Products'!AY197 | AZ14: ='Segment - Products'!AZ197 | BA14: ='Segment - Products'!BA197 | ... BU14: ='Segment - Products'!BU197 | BV14: ='Segment - Products'!BV14 | BW14: ='Segment - Products'!BW14 | BX14: ='Segment - Products'!BX14 | BY14: ='Segment - Products'!BY14 | BZ14: ='Segment - Products'!BZ14 | CA14: ='Segment - Products'!CA14 | CB14: ='Segment - Products'!CB14 | CC14: ='Segment - Products'!CC14 | ... DD14: ='Segment - Products'!DD14 | DE14: 9650 | DF14: 13482 | DG14: 8757 | DH14: 8284 | DI14: 9322 | DJ14: 11953 | DK14: 7913 | DL14: 8097 | DM14: 9042 | DN14: 11747 | DO14: 7522 | DP14: 7404 | DQ14: ='Segment - Products'!DQ14 | DR14: ='Segment - Products'!DR14 | DS14: ='Segment - Products'!DS14 | DT14: ='Segment - Products'!DT14 | DU14: ='Segment - Products'!DU14 | DV14: ='Segment - Products'!DV14 | DW14: ='Segment - Products'!DW14 | DX14: ='Segment - Products'!DX14 | ... EK14: ='Segment - Products'!EK14 | EX14: =SUM(AT14:AW14) | EY14: =SUM(AX14:BA14) | EZ14: =SUM(BB14:BE14) | FA14: =SUM(BF14:BI14) | FB14: =SUM(BJ14:BM14) | FC14: =SUM(BN14:BQ14) | FD14: =SUM(BR14:BU14) | FE14: =SUM(BV14:BY14) | FF14: =SUM(BZ14:CC14) | FG14: =SUM(CD14:CG14) | FH14: 12826 | FI14: =SUM(CL14:CO14) | FJ14: =SUM(CP14:CS14) | FK14: =SUM(CT14:CW14) | FL14: =SUM(CX14:DA14) | FM14: =SUM(DB14:DE14) | FN14: =SUM(DF14:DI14) | FO14: =SUM(DJ14:DM14) | FP14: =SUM(DN14:DQ14) | FQ14: =SUM(DR14:DU14) | FR14: =SUM(DV14:DY14) | FS14: =SUM(DZ14:EC14) | FT14: =SUM(ED14:EG14) | FU14: =SUM(EH14:EK14) | GI14: =SUM(AU14:AX14) | GJ14: =SUM(AY14:BB14) | GK14: =SUM(BC14:BF14) | GL14: =SUM(BG14:BJ14) | GM14: =SUM(BK14:BN14) | GN14: =SUM(BO14:BR14) | GO14: =SUM(BS14:BV14) | GP14: =SUM(BW14:BZ14) | GQ14: =SUM(CA14:CD14) | GR14: =SUM(CE14:CH14) | GS14: =SUM(CI14:CL14) | GT14: =SUM(CM14:CP14) | GU14: =SUM(CQ14:CT14) | GV14: =SUM(CU14:CX14) | GW14: =SUM(CY14:DB14) | GX14: =SUM(DC14:DF14) | GY14: =SUM(DG14:DJ14) | GZ14: =SUM(DK14:DN14) | HA14: =SUM(DO14:DR14) | HB14: =SUM(DS14:DV14) | HC14: =SUM(DW14:DZ14) | HD14: =SUM(EA14:ED14) | HE14: =SUM(EE14:EH14)
A15: Products | AT15: =SUM(AT11:AT14) | AU15: =SUM(AU11:AU14) | AV15: =SUM(AV11:AV14) | AW15: =SUM(AW11:AW14) | AX15: =SUM(AX11:AX14) | AY15: =SUM(AY11:AY14) | AZ15: =SUM(AZ11:AZ14) | BA15: =SUM(BA11:BA14) | ... EK15: =SUM(EK11:EK14) | EX15: =SUM(AT15:AW15) | EY15: =SUM(AX15:BA15) | EZ15: =SUM(BB15:BE15) | FA15: =SUM(BF15:BI15) | FB15: =SUM(BJ15:BM15) | FC15: =SUM(BN15:BQ15) | FD15: =SUM(BR15:BU15) | FE15: =SUM(BV15:BY15) | FF15: =SUM(BZ15:CC15) | FG15: =SUM(CD15:CG15) | FH15: =SUM(FH11:FH14) | FI15: =SUM(CL15:CO15) | FJ15: =SUM(CP15:CS15) | FK15: =SUM(CT15:CW15) | FL15: =SUM(CX15:DA15) | FM15: =SUM(DB15:DE15) | FN15: =SUM(DF15:DI15) | FO15: =SUM(DJ15:DM15) | FP15: =SUM(DN15:DQ15) | FQ15: =SUM(DR15:DU15) | FR15: =SUM(DV15:DY15) | FS15: =SUM(DZ15:EC15) | FT15: =SUM(ED15:EG15) | FU15: =SUM(EH15:EK15) | GI15: =SUM(AU15:AX15) | GJ15: =SUM(AY15:BB15) | GK15: =SUM(BC15:BF15) | GL15: =SUM(BG15:BJ15) | GM15: =SUM(BK15:BN15) | GN15: =SUM(BO15:BR15) | GO15: =SUM(BS15:BV15) | GP15: =SUM(BW15:BZ15) | GQ15: =SUM(CA15:CD15) | GR15: =SUM(CE15:CH15) | GS15: =SUM(CI15:CL15) | GT15: =SUM(CM15:CP15) | GU15: =SUM(CQ15:CT15) | GV15: =SUM(CU15:CX15) | GW15: =SUM(CY15:DB15) | GX15: =SUM(DC15:DF15) | GY15: =SUM(DG15:DJ15) | GZ15: =SUM(DK15:DN15) | HA15: =SUM(DO15:DR15) | HB15: =SUM(DS15:DV15) | HC15: =SUM(DW15:DZ15) | HD15: =SUM(EA15:ED15) | HE15: =SUM(EE15:EH15)
A16: Services | AT16: =AT17-AT15 | AU16: =AU17-AU15 | AV16: =AV17-AV15 | AW16: =AW17-AW15 | AX16: =AX17-AX15 | AY16: =AY17-AY15 | AZ16: =AZ17-AZ15 | BA16: =BA17-BA15 | ... CK16: =CK17-CK15 | CL16: ='Segment - Services'!CL21 | CM16: ='Segment - Services'!CM21 | CN16: ='Segment - Services'!CN21 | CO16: ='Segment - Services'!CO21 | CP16: ='Segment - Services'!CP21 | CQ16: ='Segment - Services'!CQ21 | CR16: ='Segment - Services'!CR21 | CS16: ='Segment - Services'!CS21 | ... DD16: ='Segment - Services'!DD21 | DE16: 19188 | DF16: 20766 | DG16: 20907 | DH16: 21213 | DI16: 22314 | DJ16: 23117 | DK16: 23867 | DL16: 24213 | DM16: 24972 | DN16: 26340 | DO16: 26645 | DP16: 27423 | DQ16: ='Segment - Services'!DQ21 | DR16: ='Segment - Services'!DR21 | DS16: ='Segment - Services'!DS21 | DT16: ='Segment - Services'!DT21 | DU16: ='Segment - Services'!DU21 | DV16: ='Segment - Services'!DV21 | DW16: ='Segment - Services'!DW21 | DX16: ='Segment - Services'!DX21 | ... EK16: ='Segment - Services'!EK21 | EX16: =SUM(AT16:AW16) | EY16: =SUM(AX16:BA16) | EZ16: =SUM(BB16:BE16) | FA16: =SUM(BF16:BI16) | FB16: =SUM(BJ16:BM16) | FC16: =SUM(BN16:BQ16) | FD16: =SUM(BR16:BU16) | FE16: =SUM(BV16:BY16) | FF16: =SUM(BZ16:CC16) | FG16: =SUM(CD16:CG16) | FH16: 32700 | FI16: =SUM(CL16:CO16) | FJ16: =SUM(CP16:CS16) | FK16: =SUM(CT16:CW16) | FL16: =SUM(CX16:DA16) | FM16: =SUM(DB16:DE16) | FN16: =SUM(DF16:DI16) | FO16: =SUM(DJ16:DM16) | FP16: =SUM(DN16:DQ16) | FQ16: =SUM(DR16:DU16) | FR16: =SUM(DV16:DY16) | FS16: =SUM(DZ16:EC16) | FT16: =SUM(ED16:EG16) | FU16: =SUM(EH16:EK16) | GI16: =SUM(AU16:AX16) | GJ16: =SUM(AY16:BB16) | GK16: =SUM(BC16:BF16) | GL16: =SUM(BG16:BJ16) | GM16: =SUM(BK16:BN16) | GN16: =SUM(BO16:BR16) | GO16: =SUM(BS16:BV16) | GP16: =SUM(BW16:BZ16) | GQ16: =SUM(CA16:CD16) | GR16: =SUM(CE16:CH16) | GS16: =SUM(CI16:CL16) | GT16: =SUM(CM16:CP16) | GU16: =SUM(CQ16:CT16) | GV16: =SUM(CU16:CX16) | GW16: =SUM(CY16:DB16) | GX16: =SUM(DC16:DF16) | GY16: =SUM(DG16:DJ16) | GZ16: =SUM(DK16:DN16) | HA16: =SUM(DO16:DR16) | HB16: =SUM(DS16:DV16) | HC16: =SUM(DW16:DZ16) | HD16: =SUM(EA16:ED16) | HE16: =SUM(EE16:EH16)
A17: Total revenue | J17: ='Income Statement'!J9 | K17: ='Income Statement'!K9 | L17: ='Income Statement'!L9 | M17: ='Income Statement'!M9 | N17: ='Income Statement'!N9 | O17: ='Income Statement'!O9 | P17: ='Income Statement'!P9 | Q17: ='Income Statement'!Q9 | ... CG17: ='Income Statement'!CG9 | CH17: 78351 | CI17: 52896 | CJ17: 45408 | CK17: 52579 | CL17: =CL15+CL16 | CM17: =CM15+CM16 | CN17: =CN15+CN16 | CO17: =CO15+CO16 | CP17: =CP15+CP16 | CQ17: =CQ15+CQ16 | CR17: =CR15+CR16 | CS17: =CS15+CS16 | ... EK17: =EK15+EK16 | EO17: =SUM(J17:M17) | EP17: =SUM(N17:Q17) | EQ17: =SUM(R17:U17) | ER17: =SUM(V17:Y17) | ES17: =SUM(Z17:AC17) | ET17: =SUM(AD17:AG17) | EU17: =SUM(AI17:AL17) | EV17: =SUM(AM17:AP17) | EW17: =SUM(AQ17:AT17) | EX17: =SUM(AT17:AW17) | EY17: =SUM(AX17:BA17) | EZ17: =SUM(BB17:BE17) | FA17: =SUM(BF17:BI17) | FB17: =SUM(BJ17:BM17) | FC17: =SUM(BN17:BQ17) | FD17: =SUM(BR17:BU17) | FE17: =SUM(BV17:BY17) | FF17: =SUM(BZ17:CC17) | FG17: =SUM(CD17:CG17) | FH17: =FH15+FH16 | FI17: =SUM(CL17:CO17) | FJ17: =SUM(CP17:CS17) | FK17: =SUM(CT17:CW17) | FL17: =SUM(CX17:DA17) | FM17: =SUM(DB17:DE17) | FN17: =SUM(DF17:DI17) | FO17: =SUM(DJ17:DM17) | FP17: =SUM(DN17:DQ17) | FQ17: =SUM(DR17:DU17) | FR17: =SUM(DV17:DY17) | FS17: =SUM(DZ17:EC17) | FT17: =SUM(ED17:EG17) | FU17: =SUM(EH17:EK17) | FY17: =SUM(G17:J17) | FZ17: =SUM(K17:N17) | GA17: =SUM(O17:R17) | GB17: =SUM(S17:V17) | GC17: =SUM(W17:Z17) | GD17: =SUM(AA17:AD17) | GE17: =SUM(AE17:AH17) | GF17: =SUM(AI17:AL17) | GG17: =SUM(AM17:AP17) | GH17: =SUM(AQ17:AT17) | GI17: =SUM(AU17:AX17) | GJ17: =SUM(AY17:BB17) | GK17: =SUM(BC17:BF17) | GL17: =SUM(BG17:BJ17) | GM17: =SUM(BK17:BN17) | GN17: =SUM(BO17:BR17) | GO17: =SUM(BS17:BV17) | GP17: =SUM(BW17:BZ17) | GQ17: =SUM(CA17:CD17) | GR17: =SUM(CE17:CH17) | GS17: =SUM(CI17:CL17) | GT17: =SUM(CM17:CP17) | GU17: =SUM(CQ17:CT17) | GV17: =SUM(CU17:CX17) | GW17: =SUM(CY17:DB17) | GX17: =SUM(DC17:DF17) | GY17: =SUM(DG17:DJ17) | GZ17: =SUM(DK17:DN17) | HA17: =SUM(DO17:DR17) | HB17: =SUM(DS17:DV17) | HC17: =SUM(DW17:DZ17) | HD17: =SUM(EA17:ED17) | HE17: =SUM(EE17:EH17)
A19: Year-over-year change (%) | B19: =B$8 | C19: =C$8 | D19: =D$8 | E19: =E$8 | F19: =F$8 | G19: =G$8 | H19: =H$8 | I19: =I$8 | ... EK19: =EK$8 | EN19: =EN$9 | EO19: =EO$9 | EP19: =EP$9 | EQ19: =EQ$9 | ER19: =ER$9 | ES19: =ES$9 | ET19: =ET$9 | EU19: =EU$9 | ... FU19: =FU$9 | FX19: =FX$9 | FY19: =FY$9 | FZ19: =FZ$9 | GA19: =GA$9 | GB19: =GB$9 | GC19: =GC$9 | GD19: =GD$9 | GE19: =GE$9 | ... HE19: =HE$9
A20: Product0489 | AZ20: =+AZ11/AV11-1 | BA20: =+BA11/AW11-1 | BB20: =+BB11/AX11-1 | BC20: =+BC11/AY11-1 | BD20: =+BD11/AZ11-1 | BE20: =+BE11/BA11-1 | BF20: =+BF11/BB11-1 | BG20: =+BG11/BC11-1 | ... EK20: =+EK11/EG11-1 | EY20: =+EY11/EX11-1 | EZ20: =+EZ11/EY11-1 | FA20: =+FA11/EZ11-1 | FB20: =+FB11/FA11-1 | FC20: =+FC11/FB11-1 | FD20: =+FD11/FC11-1 | FE20: =+FE11/FD11-1 | FF20: =+FF11/FE11-1 | FG20: =+FG11/FF11-1 | FI20: =+FI11/FH11-1 | FJ20: =+FJ11/FI11-1 | FK20: =+FK11/FJ11-1 | FL20: =+FL11/FK11-1 | FM20: =+FM11/FL11-1 | FN20: =+FN11/FM11-1 | FO20: =+FO11/FN11-1 | FP20: =+FP11/FO11-1 | ... FU20: =+FU11/FT11-1 | GJ20: =+GJ11/GI11-1 | GK20: =+GK11/GJ11-1 | GL20: =+GL11/GK11-1 | GM20: =+GM11/GL11-1 | GN20: =+GN11/GM11-1 | GO20: =+GO11/GN11-1 | GP20: =+GP11/GO11-1 | GQ20: =+GQ11/GP11-1 | ... HE20: =+HE11/HD11-1
A21: Mac | AX21: =+AX12/AT12-1 | AY21: =+AY12/AU12-1 | AZ21: =+AZ12/AV12-1 | BA21: =+BA12/AW12-1 | BB21: =+BB12/AX12-1 | BC21: =+BC12/AY12-1 | BD21: =+BD12/AZ12-1 | BE21: =+BE12/BA12-1 | ... EK21: =+EK12/EG12-1 | EY21: =+EY12/EX12-1 | EZ21: =+EZ12/EY12-1 | FA21: =+FA12/EZ12-1 | FB21: =+FB12/FA12-1 | FC21: =+FC12/FB12-1 | FD21: =+FD12/FC12-1 | FE21: =+FE12/FD12-1 | FF21: =+FF12/FE12-1 | FG21: =+FG12/FF12-1 | FI21: =+FI12/FH12-1 | FJ21: =+FJ12/FI12-1 | FK21: =+FK12/FJ12-1 | FL21: =+FL12/FK12-1 | FM21: =+FM12/FL12-1 | FN21: =+FN12/FM12-1 | FO21: =+FO12/FN12-1 | FP21: =+FP12/FO12-1 | ... FU21: =+FU12/FT12-1 | GJ21: =+GJ12/GI12-1 | GK21: =+GK12/GJ12-1 | GL21: =+GL12/GK12-1 | GM21: =+GM12/GL12-1 | GN21: =+GN12/GM12-1 | GO21: =+GO12/GN12-1 | GP21: =+GP12/GO12-1 | GQ21: =+GQ12/GP12-1 | ... HE21: =+HE12/HD12-1
A22: Product0487 | BZ22: =+BZ13/BV13-1 | CA22: =+CA13/BW13-1 | CB22: =+CB13/BX13-1 | CC22: =+CC13/BY13-1 | CD22: =+CD13/BZ13-1 | CE22: =+CE13/CA13-1 | CF22: =+CF13/CB13-1 | CG22: =+CG13/CC13-1 | ... EK22: =+EK13/EG13-1 | FE22: =+FE13/FD13-1 | FF22: =+FF13/FE13-1 | FG22: =+FG13/FF13-1 | FI22: =+FI13/FH13-1 | FJ22: =+FJ13/FI13-1 | FK22: =+FK13/FJ13-1 | FL22: =+FL13/FK13-1 | FM22: =+FM13/FL13-1 | FN22: =+FN13/FM13-1 | FO22: =+FO13/FN13-1 | FP22: =+FP13/FO13-1 | ... FU22: =+FU13/FT13-1 | GM22: =+GM13/GL13-1 | GN22: =+GN13/GM13-1 | GO22: =+GO13/GN13-1 | GP22: =+GP13/GO13-1 | GQ22: =+GQ13/GP13-1 | GR22: =+GR13/GQ13-1 | GS22: =+GS13/GR13-1 | GT22: =+GT13/GS13-1 | ... HE22: =+HE13/HD13-1
A23: Wearables, Home and Accessories | AX23: =+AX14/AT14-1 | AY23: =+AY14/AU14-1 | AZ23: =+AZ14/AV14-1 | BA23: =+BA14/AW14-1 | BB23: =+BB14/AX14-1 | BC23: =+BC14/AY14-1 | BD23: =+BD14/AZ14-1 | BE23: =+BE14/BA14-1 | ... EK23: =+EK14/EG14-1 | EY23: =+EY14/EX14-1 | EZ23: =+EZ14/EY14-1 | FA23: =+FA14/EZ14-1 | FB23: =+FB14/FA14-1 | FC23: =+FC14/FB14-1 | FD23: =+FD14/FC14-1 | FE23: =+FE14/FD14-1 | FF23: =+FF14/FE14-1 | FG23: =+FG14/FF14-1 | FI23: =+FI14/FH14-1 | FJ23: =+FJ14/FI14-1 | FK23: =+FK14/FJ14-1 | FL23: =+FL14/FK14-1 | FM23: =+FM14/FL14-1 | FN23: =+FN14/FM14-1 | FO23: =+FO14/FN14-1 | FP23: =+FP14/FO14-1 | ... FU23: =+FU14/FT14-1 | GJ23: =+GJ14/GI14-1 | GK23: =+GK14/GJ14-1 | GL23: =+GL14/GK14-1 | GM23: =+GM14/GL14-1 | GN23: =+GN14/GM14-1 | GO23: =+GO14/GN14-1 | GP23: =+GP14/GO14-1 | GQ23: =+GQ14/GP14-1 | ... HE23: =+HE14/HD14-1
A24: Products | AX24: =+AX15/AT15-1 | AY24: =+AY15/AU15-1 | AZ24: =+AZ15/AV15-1 | BA24: =+BA15/AW15-1 | BB24: =+BB15/AX15-1 | BC24: =+BC15/AY15-1 | BD24: =+BD15/AZ15-1 | BE24: =+BE15/BA15-1 | ... EK24: =+EK15/EG15-1 | EY24: =+EY15/EX15-1 | EZ24: =+EZ15/EY15-1 | FA24: =+FA15/EZ15-1 | FB24: =+FB15/FA15-1 | FC24: =+FC15/FB15-1 | FD24: =+FD15/FC15-1 | FE24: =+FE15/FD15-1 | FF24: =+FF15/FE15-1 | FG24: =+FG15/FF15-1 | FI24: =+FI15/FH15-1 | FJ24: =+FJ15/FI15-1 | FK24: =+FK15/FJ15-1 | FL24: =+FL15/FK15-1 | FM24: =+FM15/FL15-1 | FN24: =+FN15/FM15-1 | FO24: =+FO15/FN15-1 | FP24: =+FP15/FO15-1 | ... FU24: =+FU15/FT15-1 | GJ24: =+GJ15/GI15-1 | GK24: =+GK15/GJ15-1 | GL24: =+GL15/GK15-1 | GM24: =+GM15/GL15-1 | GN24: =+GN15/GM15-1 | GO24: =+GO15/GN15-1 | GP24: =+GP15/GO15-1 | GQ24: =+GQ15/GP15-1 | ... HE24: =+HE15/HD15-1
A25: Services | AX25: =+AX16/AT16-1 | AY25: =+AY16/AU16-1 | AZ25: =+AZ16/AV16-1 | BA25: =+BA16/AW16-1 | BB25: =+BB16/AX16-1 | BC25: =+BC16/AY16-1 | BD25: =+BD16/AZ16-1 | BE25: =+BE16/BA16-1 | ... CN25: =+CN16/CJ16-1 | CO25: 0.245 | CP25: =+CP16/CL16-1 | CQ25: =+CQ16/CM16-1 | CR25: =+CR16/CN16-1 | CS25: =+CS16/CO16-1 | CT25: =+CT16/CP16-1 | CU25: =+CU16/CQ16-1 | CV25: =+CV16/CR16-1 | CW25: =+CW16/CS16-1 | ... EK25: =+EK16/EG16-1 | EY25: =+EY16/EX16-1 | EZ25: =+EZ16/EY16-1 | FA25: =+FA16/EZ16-1 | FB25: =+FB16/FA16-1 | FC25: =+FC16/FB16-1 | FD25: =+FD16/FC16-1 | FE25: =+FE16/FD16-1 | FF25: =+FF16/FE16-1 | FG25: =+FG16/FF16-1 | FI25: =+FI16/FH16-1 | FJ25: =+FJ16/FI16-1 | FK25: =+FK16/FJ16-1 | FL25: =+FL16/FK16-1 | FM25: =+FM16/FL16-1 | FN25: =+FN16/FM16-1 | FO25: =+FO16/FN16-1 | FP25: =+FP16/FO16-1 | ... FU25: =+FU16/FT16-1 | GJ25: =+GJ16/GI16-1 | GK25: =+GK16/GJ16-1 | GL25: =+GL16/GK16-1 | GM25: =+GM16/GL16-1 | GN25: =+GN16/GM16-1 | GO25: =+GO16/GN16-1 | GP25: =+GP16/GO16-1 | GQ25: =+GQ16/GP16-1 | ... HE25: =+HE16/HD16-1
A26: Total revenue | N26: =+N17/J17-1 | O26: =+O17/K17-1 | P26: =+P17/L17-1 | Q26: =+Q17/M17-1 | R26: =+R17/N17-1 | S26: =+S17/O17-1 | T26: =+T17/P17-1 | U26: =+U17/Q17-1 | ... EK26: =+EK17/EG17-1 | EP26: =+EP17/EO17-1 | EQ26: =+EQ17/EP17-1 | ER26: =+ER17/EQ17-1 | ES26: =+ES17/ER17-1 | ET26: =+ET17/ES17-1 | EU26: =+EU17/ET17-1 | EV26: =+EV17/EU17-1 | EW26: =+EW17/EV17-1 | ... FU26: =+FU17/FT17-1 | GJ26: =+GJ17/GI17-1 | GK26: =+GK17/GJ17-1 | GL26: =+GL17/GK17-1 | GM26: =+GM17/GL17-1 | GN26: =+GN17/GM17-1 | GO26: =+GO17/GN17-1 | GP26: =+GP17/GO17-1 | GQ26: =+GQ17/GP17-1 | ... HE26: =+HE17/HD17-1
A27: Forex impact | BZ27: =BZ26-BZ28 | CB27: =CB26-CB28 | CC27: =CC26-CC28 | CD27: =CD26-CD28 | CE27: =CE26-CE28 | CH27: =CH26-CH28 | CI27: =CI26-CI28 | CJ27: =CJ26-CJ28 | CO27: =-200/CK17 | CP27: =CP26-CP28 | CQ27: =-1300/CM17 | CR27: -0.03 | CS27: =-1000/CO17 | CT27: =-1000/CP17 | CU27: -0.01 | CV27: -0.03 | CW27: 0 | CX27: 0 | CY27: 0.05 | CZ27: 0.05 | DA27: =CZ27-3% | DB27: 0.01 | DC27: -0.02 | DD27: -0.032 | DE27: -0.06 | DF27: -0.08 | DG27: -0.05 | DH27: -0.04 | DI27: -0.02 | DJ27: 0 | DK27: -0.014 | DL27: -0.025 | DM27: -0.015 | DN27: 0 | DO27: -0.025 | DP27: 0 | DQ27: 0.013786601 | DR27: 0.024440998 | DS27: 0.035794557 | DT27: 0.0078554353 | DU27: -0.0015877283
A28: Constant currency revenue growth | BZ28: 0.335 | CB28: 0.405 | CC28: 0.303 | CD28: 0.08 | CE28: -0.088 | CH28: 0.05 | CI28: 0.066 | CJ28: 0.092 | CO28: =CO26-CO27 | CP28: -0.03 | CQ28: =CQ26-CQ27 | CR28: =CR26-CR27 | CS28: =CS26-CS27 | CT28: =CT26-CT27 | CU28: =CU26-CU27 | CV28: =CV26-CV27 | CW28: =CW26-CW27 | CX28: =CX26-CX27 | ... EK28: =EK26-EK27
A30: Quarter-over-quarter change (%) | B30: =B$8 | C30: =C$8 | D30: =D$8 | E30: =E$8 | F30: =F$8 | G30: =G$8 | H30: =H$8 | I30: =I$8 | ... EK30: =EK$8
A31: Product0489 | AW31: =+AW11/AV11-1 | AX31: =+AX11/AW11-1 | AY31: =+AY11/AX11-1 | AZ31: =+AZ11/AY11-1 | BA31: =+BA11/AZ11-1 | BB31: =+BB11/BA11-1 | BC31: =+BC11/BB11-1 | BD31: =+BD11/BC11-1 | ... EK31: =+EK11/EJ11-1
A32: Mac | AU32: =+AU12/AT12-1 | AV32: =+AV12/AU12-1 | AW32: =+AW12/AV12-1 | AX32: =+AX12/AW12-1 | AY32: =+AY12/AX12-1 | AZ32: =+AZ12/AY12-1 | BA32: =+BA12/AZ12-1 | BB32: =+BB12/BA12-1 | ... EK32: =+EK12/EJ12-1
A33: Product0487 | BW33: =+BW13/BV13-1 | BX33: =+BX13/BW13-1 | BY33: =+BY13/BX13-1 | BZ33: =+BZ13/BY13-1 | CA33: =+CA13/BZ13-1 | CB33: =+CB13/CA13-1 | CC33: =+CC13/CB13-1 | CD33: =+CD13/CC13-1 | ... EK33: =+EK13/EJ13-1
A34: Wearables, Home and Accessories | AU34: =+AU14/AT14-1 | AV34: =+AV14/AU14-1 | AW34: =+AW14/AV14-1 | AX34: =+AX14/AW14-1 | AY34: =+AY14/AX14-1 | AZ34: =+AZ14/AY14-1 | BA34: =+BA14/AZ14-1 | BB34: =+BB14/BA14-1 | ... EK34: =+EK14/EJ14-1
A35: Products | AU35: =+AU15/AT15-1 | AV35: =+AV15/AU15-1 | AW35: =+AW15/AV15-1 | AX35: =+AX15/AW15-1 | AY35: =+AY15/AX15-1 | AZ35: =+AZ15/AY15-1 | BA35: =+BA15/AZ15-1 | BB35: =+BB15/BA15-1 | ... EK35: =+EK15/EJ15-1
A36: Services | AU36: =+AU16/AT16-1 | AV36: =+AV16/AU16-1 | AW36: =+AW16/AV16-1 | AX36: =+AX16/AW16-1 | AY36: =+AY16/AX16-1 | AZ36: =+AZ16/AY16-1 | BA36: =+BA16/AZ16-1 | BB36: =+BB16/BA16-1 | ... EK36: =+EK16/EJ16-1
A37: Total revenue | K37: =+K17/J17-1 | L37: =+L17/K17-1 | M37: =+M17/L17-1 | N37: =+N17/M17-1 | O37: =+O17/N17-1 | P37: =+P17/O17-1 | Q37: =+Q17/P17-1 | R37: =+R17/Q17-1 | ... EK37: =+EK17/EJ17-1
A39: % of revenue | B39: =B$8 | C39: =C$8 | D39: =D$8 | E39: =E$8 | F39: =F$8 | G39: =G$8 | H39: =H$8 | I39: =I$8 | ... EK39: =EK$8 | EM39: =EM$9 | EN39: =EN$9 | EO39: =EO$9 | EP39: =EP$9 | EQ39: =EQ$9 | ER39: =ER$9 | ES39: =ES$9 | ET39: =ET$9 | ... FU39: =FU$9 | FX39: =FX$9 | FY39: =FY$9 | FZ39: =FZ$9 | GA39: =GA$9 | GB39: =GB$9 | GC39: =GC$9 | GD39: =GD$9 | GE39: =GE$9 | ... HE39: =HE$9
A40: Product0489 | AT40: =AT11/AT$17 | AU40: =AU11/AU$17 | AV40: =AV11/AV$17 | AW40: =AW11/AW$17 | AX40: =AX11/AX$17 | AY40: =AY11/AY$17 | AZ40: =AZ11/AZ$17 | BA40: =BA11/BA$17 | ... EK40: =EK11/EK$17 | EX40: =EX11/EX$17 | EY40: =EY11/EY$17 | EZ40: =EZ11/EZ$17 | FA40: =FA11/FA$17 | FB40: =FB11/FB$17 | FC40: =FC11/FC$17 | FD40: =FD11/FD$17 | FE40: =FE11/FE$17 | ... FU40: =FU11/FU$17 | GI40: =GI11/GI$17 | GJ40: =GJ11/GJ$17 | GK40: =GK11/GK$17 | GL40: =GL11/GL$17 | GM40: =GM11/GM$17 | GN40: =GN11/GN$17 | GO40: =GO11/GO$17 | GP40: =GP11/GP$17 | ... HE40: =HE11/HE$17
A41: Mac | AT41: =AT12/AT$17 | AU41: =AU12/AU$17 | AV41: =AV12/AV$17 | AW41: =AW12/AW$17 | AX41: =AX12/AX$17 | AY41: =AY12/AY$17 | AZ41: =AZ12/AZ$17 | BA41: =BA12/BA$17 | ... EK41: =EK12/EK$17 | EX41: =EX12/EX$17 | EY41: =EY12/EY$17 | EZ41: =EZ12/EZ$17 | FA41: =FA12/FA$17 | FB41: =FB12/FB$17 | FC41: =FC12/FC$17 | FD41: =FD12/FD$17 | FE41: =FE12/FE$17 | ... FU41: =FU12/FU$17 | GI41: =GI12/GI$17 | GJ41: =GJ12/GJ$17 | GK41: =GK12/GK$17 | GL41: =GL12/GL$17 | GM41: =GM12/GM$17 | GN41: =GN12/GN$17 | GO41: =GO12/GO$17 | GP41: =GP12/GP$17 | ... HE41: =HE12/HE$17
A42: Product0487 | AT42: =AT13/AT$17 | AU42: =AU13/AU$17 | AV42: =AV13/AV$17 | AW42: =AW13/AW$17 | AX42: =AX13/AX$17 | AY42: =AY13/AY$17 | AZ42: =AZ13/AZ$17 | BA42: =BA13/BA$17 | ... EK42: =EK13/EK$17 | EX42: =EX13/EX$17 | EY42: =EY13/EY$17 | EZ42: =EZ13/EZ$17 | FA42: =FA13/FA$17 | FB42: =FB13/FB$17 | FC42: =FC13/FC$17 | FD42: =FD13/FD$17 | FE42: =FE13/FE$17 | ... FU42: =FU13/FU$17 | GI42: =GI13/GI$17 | GJ42: =GJ13/GJ$17 | GK42: =GK13/GK$17 | GL42: =GL13/GL$17 | GM42: =GM13/GM$17 | GN42: =GN13/GN$17 | GO42: =GO13/GO$17 | GP42: =GP13/GP$17 | ... HE42: =HE13/HE$17
A43: Wearables, Home and Accessories | AT43: =AT14/AT$17 | AU43: =AU14/AU$17 | AV43: =AV14/AV$17 | AW43: =AW14/AW$17 | AX43: =AX14/AX$17 | AY43: =AY14/AY$17 | AZ43: =AZ14/AZ$17 | BA43: =BA14/BA$17 | ... EK43: =EK14/EK$17 | EX43: =EX14/EX$17 | EY43: =EY14/EY$17 | EZ43: =EZ14/EZ$17 | FA43: =FA14/FA$17 | FB43: =FB14/FB$17 | FC43: =FC14/FC$17 | FD43: =FD14/FD$17 | FE43: =FE14/FE$17 | ... FU43: =FU14/FU$17 | GI43: =GI14/GI$17 | GJ43: =GJ14/GJ$17 | GK43: =GK14/GK$17 | GL43: =GL14/GL$17 | GM43: =GM14/GM$17 | GN43: =GN14/GN$17 | GO43: =GO14/GO$17 | GP43: =GP14/GP$17 | ... HE43: =HE14/HE$17
A44: Products | AT44: =AT15/AT$17 | AU44: =AU15/AU$17 | AV44: =AV15/AV$17 | AW44: =AW15/AW$17 | AX44: =AX15/AX$17 | AY44: =AY15/AY$17 | AZ44: =AZ15/AZ$17 | BA44: =BA15/BA$17 | ... EK44: =EK15/EK$17 | EX44: =EX15/EX$17 | EY44: =EY15/EY$17 | EZ44: =EZ15/EZ$17 | FA44: =FA15/FA$17 | FB44: =FB15/FB$17 | FC44: =FC15/FC$17 | FD44: =FD15/FD$17 | FE44: =FE15/FE$17 | ... FU44: =FU15/FU$17 | GI44: =GI15/GI$17 | GJ44: =GJ15/GJ$17 | GK44: =GK15/GK$17 | GL44: =GL15/GL$17 | GM44: =GM15/GM$17 | GN44: =GN15/GN$17 | GO44: =GO15/GO$17 | GP44: =GP15/GP$17 | ... HE44: =HE15/HE$17
A45: Services | AT45: =AT16/AT$17 | AU45: =AU16/AU$17 | AV45: =AV16/AV$17 | AW45: =AW16/AW$17 | AX45: =AX16/AX$17 | AY45: =AY16/AY$17 | AZ45: =AZ16/AZ$17 | BA45: =BA16/BA$17 | ... EK45: =EK16/EK$17 | EX45: =EX16/EX$17 | EY45: =EY16/EY$17 | EZ45: =EZ16/EZ$17 | FA45: =FA16/FA$17 | FB45: =FB16/FB$17 | FC45: =FC16/FC$17 | FD45: =FD16/FD$17 | FE45: =FE16/FE$17 | ... FU45: =FU16/FU$17 | GI45: =GI16/GI$17 | GJ45: =GJ16/GJ$17 | GK45: =GK16/GK$17 | GL45: =GL16/GL$17 | GM45: =GM16/GM$17 | GN45: =GN16/GN$17 | GO45: =GO16/GO$17 | GP45: =GP16/GP$17 | ... HE45: =HE16/HE$17
A46: Total revenue | AT46: =AT17/AT$17 | AU46: =AU17/AU$17 | AV46: =AV17/AV$17 | AW46: =AW17/AW$17 | AX46: =AX17/AX$17 | AY46: =AY17/AY$17 | AZ46: =AZ17/AZ$17 | BA46: =BA17/BA$17 | ... EK46: =EK17/EK$17 | EX46: =EX17/EX$17 | EY46: =EY17/EY$17 | EZ46: =EZ17/EZ$17 | FA46: =FA17/FA$17 | FB46: =FB17/FB$17 | FC46: =FC17/FC$17 | FD46: =FD17/FD$17 | FE46: =FE17/FE$17 | ... FU46: =FU17/FU$17 | FY46: =FY17/FY$17 | FZ46: =FZ17/FZ$17 | GA46: =GA17/GA$17 | GB46: =GB17/GB$17 | GC46: =GC17/GC$17 | GD46: =GD17/GD$17 | GE46: =GE17/GE$17 | GF46: =GF17/GF$17 | ... HE46: =HE17/HE$17
...

Sheet Segment - Products
A3: Company0243. (Ticker0001)
A4: Products
A6: # weeks in the quarter | BR6: =BS6 | BS6: =BT6 | BT6: =BU6 | BU6: =BV6 | BV6: =BW6 | BW6: =(BW7-BV7)/7 | BX6: =(BX7-BW7)/7 | BY6: =(BY7-BX7)/7 | BZ6: =(BZ7-BY7)/7 | CA6: =(CA7-BZ7)/7 | CB6: =(CB7-CA7)/7 | CC6: =(CC7-CB7)/7 | CD6: =(CD7-CC7)/7 | ... EK6: =(EK7-EJ7)/7
A7: Quarter end date | BV7: 41636 | BW7: 41727 | BX7: 41818 | BY7: 41909 | BZ7: 42000 | CA7: 42091 | CB7: 42182 | CC7: 42273 | CD7: ='Income Statement'!CD6 | CE7: ='Income Statement'!CE6 | CF7: ='Income Statement'!CF6 | CG7: ='Income Statement'!CG6 | CH7: ='Income Statement'!CH6 | CI7: ='Income Statement'!CI6 | CJ7: ='Income Statement'!CJ6 | CK7: ='Income Statement'!CK6 | ... EK7: ='Income Statement'!EK6
B8: Q196 | C8: Q296 | D8: Q396 | E8: Q496 | F8: Q197 | G8: Q297 | H8: Q397 | I8: Q497 | J8: Q198 | K8: Q298 | L8: Q398 | M8: Q498 | N8: Q199 | O8: Q299 | P8: Q399 | Q8: Q499 | R8: Q100 | S8: Q200 | T8: Q300 | U8: Q400 | V8: Q101 | W8: Q201 | X8: Q301 | Y8: Q401 | Z8: Q102 | AA8: Q202 | AB8: Q302 | AC8: Q402 | AD8: Q103 | AE8: Q203 | AF8: Q303 | AG8: Q403 | AH8: Q104 | AI8: Q204 | AJ8: Q304 | AK8: Q404 | AL8: Q105 | AM8: Q205 | AN8: Q305 | AO8: Q405 | AP8: Q106 | AQ8: Q206 | AR8: Q306 | AS8: Q406 | AT8: Q107 | AU8: Q207 | AV8: Q307 | AW8: Q407 | AX8: Q108 | AY8: Q208 | AZ8: Q308 | BA8: Q408 | BB8: Q109 | BC8: Q209 | BD8: Q309 | BE8: Q409 | BF8: Q110 | BG8: Q210 | BH8: Q310 | BI8: Q410 | BJ8: ='Income Statement'!BJ7 | BK8: ='Income Statement'!BK7 | BL8: ='Income Statement'!BL7 | BM8: ='Income Statement'!BM7 | BN8: ='Income Statement'!BN7 | BO8: ='Income Statement'!BO7 | BP8: ='Income Statement'!BP7 | BQ8: ='Income Statement'!BQ7 | ... EK8: ='Income Statement'!EK7 | FF8: FISCAL | GR8: CALENDAR
A9: $, millions | B9: 35064 | C9: 35155 | D9: 35246 | E9: 35338 | F9: 35430 | G9: 35520 | H9: 35611 | I9: 35703 | J9: 35795 | K9: 35885 | L9: 35976 | M9: 36068 | N9: 36160 | O9: 36250 | P9: 36341 | Q9: 36433 | R9: 36525 | S9: 36616 | T9: 36707 | U9: 36799 | V9: 36891 | W9: 36981 | X9: 37072 | Y9: 37164 | Z9: 37256 | AA9: 37346 | AB9: 37437 | AC9: 37529 | AD9: 37621 | AE9: 37711 | AF9: 37802 | AG9: 37894 | AH9: 37986 | AI9: 38077 | AJ9: 38168 | AK9: 38260 | AL9: 38352 | AM9: 38442 | AN9: 38533 | AO9: 38625 | AP9: 38717 | AQ9: 38807 | AR9: 38898 | AS9: 38990 | AT9: 39082 | AU9: 39172 | AV9: 39263 | AW9: 39355 | AX9: 39447 | AY9: 39538 | AZ9: 39629 | BA9: 39721 | BB9: 39813 | BC9: 39903 | BD9: 39994 | BE9: 40086 | BF9: 40178 | BG9: 40268 | BH9: 40359 | BI9: 40451 | BJ9: 40543 | BK9: 40633 | BL9: 40724 | BM9: 40816 | BN9: 40908 | BO9: 40999 | BP9: 41090 | BQ9: 41182 | BR9: 41274 | BS9: 41364 | BT9: 41455 | BU9: 41547 | BV9: 41639 | BW9: 41729 | BX9: 41820 | BY9: 41912 | BZ9: ='Income Statement'!BZ8 | CA9: ='Income Statement'!CA8 | CB9: ='Income Statement'!CB8 | CC9: ='Income Statement'!CC8 | CD9: ='Income Statement'!CD8 | CE9: ='Income Statement'!CE8 | CF9: ='Income Statement'!CF8 | CG9: ='Income Statement'!CG8 | ... EK9: ='Income Statement'!EK8 | EM9: 1996 | EN9: 1997 | EO9: 1998 | EP9: 1999 | EQ9: 2000 | ER9: 2001 | ES9: 2002 | ET9: 2003 | EU9: 2004 | EV9: 2005 | EW9: 2006 | EX9: 2007 | EY9: 2008 | EZ9: 2009 | FA9: 2010 | FB9: 2011 | FC9: 2012 | FD9: 2013 | FE9: ='Income Statement'!FE8 | FF9: ='Income Statement'!FF8 | FG9: ='Income Statement'!FG8 | FH9: ='Income Statement'!FH8 | FI9: ='Income Statement'!FI8 | FJ9: ='Income Statement'!FJ8 | FK9: ='Income Statement'!FK8 | FL9: ='Income Statement'!FL8 | ... FU9: ='Income Statement'!FU8 | FY9: 1996 | FZ9: 1997 | GA9: 1998 | GB9: 1999 | GC9: 2000 | GD9: 2001 | GE9: 2002 | GF9: 2003 | GG9: 2004 | GH9: 2005 | GI9: 2006 | GJ9: 2007 | GK9: 2008 | GL9: 2009 | GM9: 2010 | GN9: 2011 | GO9: 2012 | GP9: 2013 | GQ9: ='Income Statement'!GO8 | GR9: ='Income Statement'!GP8 | GS9: ='Income Statement'!GQ8 | GT9: ='Income Statement'!GR8 | GU9: ='Income Statement'!GS8 | GV9: ='Income Statement'!GT8 | GW9: ='Income Statement'!GU8 | GX9: ='Income Statement'!GV8 | ... HF9: ='Income Statement'!HD8
A10: Product revenue ($, mn) | B10: ='Revenue summary'!B$8 | C10: ='Revenue summary'!C$8 | D10: ='Revenue summary'!D$8 | E10: ='Revenue summary'!E$8 | F10: ='Revenue summary'!F$8 | G10: ='Revenue summary'!G$8 | H10: ='Revenue summary'!H$8 | I10: ='Revenue summary'!I$8 | ... CK10: ='Revenue summary'!CK$8
A11: Product0489 | BB11: =BB194 | BC11: =BC194 | BD11: =BD194 | BE11: =BE194 | BF11: =BF194 | BG11: =BG194 | BH11: =BH194 | BI11: =BI194 | ... BU11: =BU194 | BV11: =BZ11/BZ194*BV194 | BW11: =CA11/CA194*BW194 | BX11: =CB11/CB194*BX194 | BY11: =CC11/CC194*BY194 | BZ11: =CD11/CD194*BZ194 | CA11: =CE11/CE194*CA194 | CB11: =CF11/CF194*CB194 | CC11: =CG11/CG194*CC194 | ... CK11: =CO11/CO194*CK194 | CL11: 61104 | CM11: 37559 | CN11: 29470 | CO11: 36755 | CP11: 51982 | CQ11: 31051 | CR11: 25986 | CS11: 33362 | CT11: 55957 | CU11: 28962 | CV11: 26418 | CW11: 26444 | CX11: 65597 | CY11: 47938 | CZ11: 39570 | DA11: 38868 | DB11: 71628 | DC11: 50570 | DD11: 40665 | DE11: ='Revenue summary'!DE11 | DF11: ='Revenue summary'!DF11 | DG11: ='Revenue summary'!DG11 | DH11: ='Revenue summary'!DH11 | DI11: ='Revenue summary'!DI11 | DJ11: ='Revenue summary'!DJ11 | DK11: ='Revenue summary'!DK11 | DL11: ='Revenue summary'!DL11 | ... DP11: ='Revenue summary'!DP11 | DQ11: =DQ70 | DR11: =DR70 | DS11: =DS70 | DT11: =DT70 | DU11: =DU70 | DV11: =DV70 | DW11: =DW70 | DX11: =DX70 | ... EK11: =EK70 | EO11: =SUM(J11:M11) | EP11: =SUM(N11:Q11) | EQ11: =SUM(R11:U11) | ER11: =SUM(V11:Y11) | ES11: =SUM(Z11:AC11) | ET11: =SUM(AD11:AG11) | EU11: =SUM(AH11:AK11) | EV11: =SUM(AL11:AO11) | EW11: =SUM(AP11:AS11) | EX11: =SUM(AT11:AW11) | EY11: =SUM(AX11:BA11) | EZ11: =SUM(BB11:BE11) | FA11: =SUM(BF11:BI11) | FB11: =SUM(BJ11:BM11) | FC11: =SUM(BN11:BQ11) | FD11: =SUM(BR11:BU11) | FE11: =SUM(BV11:BY11) | FF11: =SUM(BZ11:CC11) | FG11: =SUM(CD11:CG11) | FH11: ='Revenue summary'!FH11 | FI11: =SUM(CL11:CO11) | FJ11: =SUM(CP11:CS11) | FK11: =SUM(CT11:CW11) | FL11: =SUM(CX11:DA11) | FM11: =SUM(DB11:DE11) | FN11: =SUM(DF11:DI11) | FO11: =SUM(DJ11:DM11) | FP11: =SUM(DN11:DQ11) | FQ11: =SUM(DR11:DU11) | FR11: =SUM(DV11:DY11) | FS11: =SUM(DZ11:EC11) | FT11: =SUM(ED11:EG11) | FU11: =SUM(EH11:EK11) | FZ11: =SUM(G11:J11) | GA11: =SUM(K11:N11) | GB11: =SUM(O11:R11) | GC11: =SUM(S11:V11) | GD11: =SUM(W11:Z11) | GE11: =SUM(AA11:AD11) | GF11: =SUM(AE11:AH11) | GG11: =SUM(AI11:AL11) | GH11: =SUM(AM11:AP11) | GI11: =SUM(AQ11:AT11) | GJ11: =SUM(AU11:AX11) | GK11: =SUM(AY11:BB11) | GL11: =SUM(BC11:BF11) | GM11: =SUM(BG11:BJ11) | GN11: =SUM(BK11:BN11) | GO11: =SUM(BO11:BR11) | GP11: =SUM(BS11:BV11) | GQ11: =SUM(BW11:BZ11) | GR11: =SUM(CA11:CD11) | GS11: =SUM(CE11:CH11) | GT11: =SUM(CI11:CL11) | GU11: =SUM(CM11:CP11) | GV11: =SUM(CQ11:CT11) | GW11: =SUM(CU11:CX11) | GX11: =SUM(CY11:DB11) | GY11: =SUM(DC11:DF11) | GZ11: =SUM(DG11:DJ11) | HA11: =SUM(DK11:DN11) | HB11: =SUM(DO11:DR11) | HC11: =SUM(DS11:DV11) | HD11: =SUM(DW11:DZ11) | HE11: =SUM(EA11:ED11) | HF11: =SUM(EE11:EH11)
A12: Mac | J12: =N12/N196*J196 | K12: =O12/O196*K196 | L12: =P12/P196*L196 | M12: =Q12/Q196*M196 | N12: =R12/R196*N196 | O12: =S12/S196*O196 | P12: =T12/T196*P196 | Q12: =U12/U196*Q196 | ... Y12: =AC12/AC196*Y196 | Z12: =Z196 | AA12: =AA196 | AB12: =AB196 | AC12: =AC196 | AD12: =AD196 | AE12: =AE196 | AF12: =AF196 | AG12: =AG196 | ... BU12: =BU196 | BV12: =BZ12/BZ196*BV196 | BW12: =CA12/CA196*BW196 | BX12: =CB12/CB196*BX196 | BY12: =CC12/CC196*BY196 | BZ12: =CD12/CD196*BZ196 | CA12: =CE12/CE196*CA196 | CB12: =CF12/CF196*CB196 | CC12: =CG12/CG196*CC196 | ... CK12: =CO12/CO196*CK196 | CL12: 6824 | CM12: 5776 | CN12: 5258 | CO12: 7340 | CP12: 7416 | CQ12: 5513 | CR12: 5820 | CS12: 6991 | CT12: 7160 | CU12: 5351 | CV12: 7079 | CW12: 9032 | CX12: 8675 | CY12: 9102 | CZ12: 8235 | DA12: 9178 | DB12: 10852 | DC12: 10435 | DD12: 7382 | DE12: ='Revenue summary'!DE12 | DF12: ='Revenue summary'!DF12 | DG12: ='Revenue summary'!DG12 | DH12: ='Revenue summary'!DH12 | DI12: ='Revenue summary'!DI12 | DJ12: ='Revenue summary'!DJ12 | DK12: ='Revenue summary'!DK12 | DL12: ='Revenue summary'!DL12 | ... DP12: ='Revenue summary'!DP12 | DQ12: =DQ93*DQ152 | DR12: =DR93*DR152 | DS12: =DS93*DS152 | DT12: =DT93*DT152 | DU12: =DU93*DU152 | DV12: =DV93*DV152 | DW12: =DW93*DW152 | DX12: =DX93*DX152 | ... EK12: =EK93*EK152 | EO12: =SUM(J12:M12) | EP12: =SUM(N12:Q12) | EQ12: =SUM(R12:U12) | ER12: =SUM(V12:Y12) | ES12: =SUM(Z12:AC12) | ET12: =SUM(AD12:AG12) | EU12: =SUM(AH12:AK12) | EV12: =SUM(AL12:AO12) | EW12: =SUM(AP12:AS12) | EX12: =SUM(AT12:AW12) | EY12: =SUM(AX12:BA12) | EZ12: =SUM(BB12:BE12) | FA12: =SUM(BF12:BI12) | FB12: =SUM(BJ12:BM12) | FC12: =SUM(BN12:BQ12) | FD12: =SUM(BR12:BU12) | FE12: =SUM(BV12:BY12) | FF12: =SUM(BZ12:CC12) | FG12: =SUM(CD12:CG12) | FH12: ='Revenue summary'!FH12 | FI12: =SUM(CL12:CO12) | FJ12: =SUM(CP12:CS12) | FK12: =SUM(CT12:CW12) | FL12: =SUM(CX12:DA12) | FM12: =SUM(DB12:DE12) | FN12: =SUM(DF12:DI12) | FO12: =SUM(DJ12:DM12) | FP12: =SUM(DN12:DQ12) | FQ12: =SUM(DR12:DU12) | FR12: =SUM(DV12:DY12) | FS12: =SUM(DZ12:EC12) | FT12: =SUM(ED12:EG12) | FU12: =SUM(EH12:EK12) | FZ12: =SUM(G12:J12) | GA12: =SUM(K12:N12) | GB12: =SUM(O12:R12) | GC12: =SUM(S12:V12) | GD12: =SUM(W12:Z12) | GE12: =SUM(AA12:AD12) | GF12: =SUM(AE12:AH12) | GG12: =SUM(AI12:AL12) | GH12: =SUM(AM12:AP12) | GI12: =SUM(AQ12:AT12) | GJ12: =SUM(AU12:AX12) | GK12: =SUM(AY12:BB12) | GL12: =SUM(BC12:BF12) | GM12: =SUM(BG12:BJ12) | GN12: =SUM(BK12:BN12) | GO12: =SUM(BO12:BR12) | GP12: =SUM(BS12:BV12) | GQ12: =SUM(BW12:BZ12) | GR12: =SUM(CA12:CD12) | GS12: =SUM(CE12:CH12) | GT12: =SUM(CI12:CL12) | GU12: =SUM(CM12:CP12) | GV12: =SUM(CQ12:CT12) | GW12: =SUM(CU12:CX12) | GX12: =SUM(CY12:DB12) | GY12: =SUM(DC12:DF12) | GZ12: =SUM(DG12:DJ12) | HA12: =SUM(DK12:DN12) | HB12: =SUM(DO12:DR12) | HC12: =SUM(DS12:DV12) | HD12: =SUM(DW12:DZ12) | HE12: =SUM(EA12:ED12) | HF12: =SUM(EE12:EH12)
A13: Product0487 | BH13: =BH195 | BI13: =BI195 | BJ13: =BJ195 | BK13: =BK195 | BL13: =BL195 | BM13: =BM195 | BN13: =BN195 | BO13: =BO195 | ... BU13: =BU195 | BV13: =BZ13/BZ195*BV195 | BW13: =CA13/CA195*BW195 | BX13: =CB13/CB195*BX195 | BY13: =CC13/CC195*BY195 | BZ13: =CD13/CD195*BZ195 | CA13: =CE13/CE195*CA195 | CB13: =CF13/CF195*CB195 | CC13: =CG13/CG195*CC195 | ... CK13: =CO13/CO195*CK195 | CL13: 5755 | CM13: 4008 | CN13: 4634 | CO13: 3983 | CP13: 6729 | CQ13: 4872 | CR13: 5023 | CS13: 4656 | CT13: 5977 | CU13: 4368 | CV13: 6582 | CW13: 6797 | CX13: 8435 | CY13: 7807 | CZ13: 7368 | DA13: 8252 | DB13: 7248 | DC13: 7646 | DD13: 7224 | DE13: ='Revenue summary'!DE13 | DF13: ='Revenue summary'!DF13 | DG13: ='Revenue summary'!DG13 | DH13: ='Revenue summary'!DH13 | DI13: ='Revenue summary'!DI13 | DJ13: ='Revenue summary'!DJ13 | DK13: ='Revenue summary'!DK13 | DL13: ='Revenue summary'!DL13 | ... DP13: ='Revenue summary'!DP13 | DQ13: =DQ49 | DR13: =DR49 | DS13: =DS49 | DT13: =DT49 | DU13: =DU49 | DV13: =DV49 | DW13: =DW49 | DX13: =DX49 | ... EK13: =EK49 | EO13: =SUM(J13:M13) | EP13: =SUM(N13:Q13) | EQ13: =SUM(R13:U13) | ER13: =SUM(V13:Y13) | ES13: =SUM(Z13:AC13) | ET13: =SUM(AD13:AG13) | EU13: =SUM(AH13:AK13) | EV13: =SUM(AL13:AO13) | EW13: =SUM(AP13:AS13) | EX13: =SUM(AT13:AW13) | EY13: =SUM(AX13:BA13) | EZ13: =SUM(BB13:BE13) | FA13: =SUM(BF13:BI13) | FB13: =SUM(BJ13:BM13) | FC13: =SUM(BN13:BQ13) | FD13: =SUM(BR13:BU13) | FE13: =SUM(BV13:BY13) | FF13: =SUM(BZ13:CC13) | FG13: =SUM(CD13:CG13) | FH13: ='Revenue summary'!FH13 | FI13: =SUM(CL13:CO13) | FJ13: =SUM(CP13:CS13) | FK13: =SUM(CT13:CW13) | FL13: =SUM(CX13:DA13) | FM13: =SUM(DB13:DE13) | FN13: =SUM(DF13:DI13) | FO13: =SUM(DJ13:DM13) | FP13: =SUM(DN13:DQ13) | FQ13: =SUM(DR13:DU13) | FR13: =SUM(DV13:DY13) | FS13: =SUM(DZ13:EC13) | FT13: =SUM(ED13:EG13) | FU13: =SUM(EH13:EK13) | FZ13: =SUM(G13:J13) | GA13: =SUM(K13:N13) | GB13: =SUM(O13:R13) | GC13: =SUM(S13:V13) | GD13: =SUM(W13:Z13) | GE13: =SUM(AA13:AD13) | GF13: =SUM(AE13:AH13) | GG13: =SUM(AI13:AL13) | GH13: =SUM(AM13:AP13) | GI13: =SUM(AQ13:AT13) | GJ13: =SUM(AU13:AX13) | GK13: =SUM(AY13:BB13) | GL13: =SUM(BC13:BF13) | GM13: =SUM(BG13:BJ13) | GN13: =SUM(BK13:BN13) | GO13: =SUM(BO13:BR13) | GP13: =SUM(BS13:BV13) | GQ13: =SUM(BW13:BZ13) | GR13: =SUM(CA13:CD13) | GS13: =SUM(CE13:CH13) | GT13: =SUM(CI13:CL13) | GU13: =SUM(CM13:CP13) | GV13: =SUM(CQ13:CT13) | GW13: =SUM(CU13:CX13) | GX13: =SUM(CY13:DB13) | GY13: =SUM(DC13:DF13) | GZ13: =SUM(DG13:DJ13) | HA13: =SUM(DK13:DN13) | HB13: =SUM(DO13:DR13) | HC13: =SUM(DS13:DV13) | HD13: =SUM(DW13:DZ13) | HE13: =SUM(EA13:ED13) | HF13: =SUM(EE13:EH13)
A14: Wearables, Home and Accessories | Z14: =Z197 | AA14: =AA197 | AB14: =AB197 | AC14: =AC197 | AD14: =AD197 | AE14: =AE197 | AF14: =AF197 | AG14: =AG197 | ... BU14: =BU197 | BV14: =BZ14/BZ197*BV197 | BW14: =CA14/CA197*BW197 | BX14: =CB14/CB197*BX197 | BY14: =CC14/CC197*BY197 | BZ14: =CD14/CD197*BZ197 | CA14: =CE14/CE197*CA197 | CB14: =CF14/CF197*CB197 | CC14: =CG14/CG197*CC197 | ... CK14: =CO14/CO197*CK197 | CL14: 5481 | CM14: 3944 | CN14: 3733 | CO14: 4223 | CP14: 7308 | CQ14: 5129 | CR14: 5525 | CS14: 6520 | CT14: 10010 | CU14: 6284 | CV14: 6450 | CW14: 7876 | CX14: 12971 | CY14: 7836 | CZ14: 8775 | DA14: 8785 | DB14: 14701 | DC14: 8806 | DD14: 8084 | DE14: ='Revenue summary'!DE14 | DF14: ='Revenue summary'!DF14 | DG14: ='Revenue summary'!DG14 | DH14: ='Revenue summary'!DH14 | DI14: ='Revenue summary'!DI14 | DJ14: ='Revenue summary'!DJ14 | DK14: ='Revenue summary'!DK14 | DL14: ='Revenue summary'!DL14 | ... DP14: ='Revenue summary'!DP14 | DQ14: =DQ15+DQ16+DQ17+DQ18 | DR14: =DR15+DR16+DR17+DR18 | DS14: =DS15+DS16+DS17+DS18 | DT14: =DT15+DT16+DT17+DT18 | DU14: =DU15+DU16+DU17+DU18 | DV14: =DV15+DV16+DV17+DV18 | DW14: =DW15+DW16+DW17+DW18 | DX14: =DX15+DX16+DX17+DX18 | ... EK14: =EK15+EK16+EK17+EK18 | ES14: =SUM(Z14:AC14) | ET14: =SUM(AD14:AG14) | EU14: =SUM(AH14:AK14) | EV14: =SUM(AL14:AO14) | EW14: =SUM(AP14:AS14) | EX14: =SUM(AT14:AW14) | EY14: =SUM(AX14:BA14) | EZ14: =SUM(BB14:BE14) | FA14: =SUM(BF14:BI14) | FB14: =SUM(BJ14:BM14) | FC14: =SUM(BN14:BQ14) | FD14: =SUM(BR14:BU14) | FE14: =SUM(BV14:BY14) | FF14: =SUM(BZ14:CC14) | FG14: =SUM(CD14:CG14) | FH14: ='Revenue summary'!FH14 | FI14: =SUM(CL14:CO14) | FJ14: =SUM(CP14:CS14) | FK14: =SUM(CT14:CW14) | FL14: =SUM(CX14:DA14) | FM14: =SUM(DB14:DE14) | FN14: =SUM(DF14:DI14) | FO14: =SUM(DJ14:DM14) | FP14: =SUM(DN14:DQ14) | FQ14: =SUM(DR14:DU14) | FR14: =SUM(DV14:DY14) | FS14: =SUM(DZ14:EC14) | FT14: =SUM(ED14:EG14) | FU14: =SUM(EH14:EK14) | FZ14: =SUM(G14:J14) | GA14: =SUM(K14:N14) | GB14: =SUM(O14:R14) | GC14: =SUM(S14:V14) | GD14: =SUM(W14:Z14) | GE14: =SUM(AA14:AD14) | GF14: =SUM(AE14:AH14) | GG14: =SUM(AI14:AL14) | GH14: =SUM(AM14:AP14) | GI14: =SUM(AQ14:AT14) | GJ14: =SUM(AU14:AX14) | GK14: =SUM(AY14:BB14) | GL14: =SUM(BC14:BF14) | GM14: =SUM(BG14:BJ14) | GN14: =SUM(BK14:BN14) | GO14: =SUM(BO14:BR14) | GP14: =SUM(BS14:BV14) | GQ14: =SUM(BW14:BZ14) | GR14: =SUM(CA14:CD14) | GS14: =SUM(CE14:CH14) | GT14: =SUM(CI14:CL14) | GU14: =SUM(CM14:CP14) | GV14: =SUM(CQ14:CT14) | GW14: =SUM(CU14:CX14) | GX14: =SUM(CY14:DB14) | GY14: =SUM(DC14:DF14) | GZ14: =SUM(DG14:DJ14) | HA14: =SUM(DK14:DN14) | HB14: =SUM(DO14:DR14) | HC14: =SUM(DS14:DV14) | HD14: =SUM(DW14:DZ14) | HE14: =SUM(EA14:ED14) | HF14: =SUM(EE14:EH14)
A15: Watch revenue | CB15: =+CB100*CB159 | CC15: =+CC100*CC159 | CD15: =+CD100*CD159 | CE15: =+CE100*CE159 | CF15: =+CF100*CF159 | CG15: =+CG100*CG159 | CH15: =+CH100*CH159 | CI15: =+CI100*CI159 | ... EK15: =+EK100*EK159 | FF15: =SUM(BZ15:CC15) | FG15: =SUM(CD15:CG15) | FH15: =SUM(CH15:CK15) | FI15: =SUM(CL15:CO15) | FJ15: =SUM(CP15:CS15) | FK15: =SUM(CT15:CW15) | FL15: =SUM(CX15:DA15) | FM15: =SUM(DB15:DE15) | FN15: =SUM(DF15:DI15) | FO15: =SUM(DJ15:DM15) | FP15: =SUM(DN15:DQ15) | FQ15: =SUM(DR15:DU15) | FR15: =SUM(DV15:DY15) | FS15: =SUM(DZ15:EC15) | FT15: =SUM(ED15:EG15) | FU15: =SUM(EH15:EK15) | GD15: =SUM(W15:Z15) | GE15: =SUM(AA15:AD15) | GF15: =SUM(AE15:AH15) | GG15: =SUM(AI15:AL15) | GH15: =SUM(AM15:AP15) | GI15: =SUM(AQ15:AT15) | GJ15: =SUM(AU15:AX15) | GK15: =SUM(AY15:BB15) | GL15: =SUM(BC15:BF15) | GM15: =SUM(BG15:BJ15) | GN15: =SUM(BK15:BN15) | GO15: =SUM(BO15:BR15) | GP15: =SUM(BS15:BV15) | GQ15: =SUM(BW15:BZ15) | GR15: =SUM(CA15:CD15) | GS15: =SUM(CE15:CH15) | GT15: =SUM(CI15:CL15) | GU15: =SUM(CM15:CP15) | GV15: =SUM(CQ15:CT15) | GW15: =SUM(CU15:CX15) | GX15: =SUM(CY15:DB15) | GY15: =SUM(DC15:DF15) | GZ15: =SUM(DG15:DJ15) | HA15: =SUM(DK15:DN15) | HB15: =SUM(DO15:DR15) | HC15: =SUM(DS15:DV15) | HD15: =SUM(DW15:DZ15) | HE15: =SUM(EA15:ED15) | HF15: =SUM(EE15:EH15)
A16: Accessories / Other | AV16: 308 | AZ16: 437 | BB16: 387 | BC16: 357 | BD16: 340 | BE16: =1475-BD16-BC16-BB16 | BF16: 469 | BG16: 472 | BH16: 396 | BI16: =1814-BH16-BG16-BF16 | BJ16: =+BJ197-BJ18-BJ15 | BK16: =+BK197-BK18-BK15 | BL16: =+BL197-BL18-BL15 | BM16: =+BM197-BM18-BM15 | BN16: =+BN197-BN18-BN15 | BO16: 1195 | BP16: 1227 | BQ16: =+BQ197-BQ18-BQ15 | BR16: 1829 | BS16: 1379 | BT16: 1179 | BU16: =+BU197-BU18-BU15 | BV16: =+BV14-BV18-BV15 | BW16: =+BW14-BW18-BW15 | BX16: =+BX14-BX18-BX15 | BY16: =+BY14-BY18-BY15 | BZ16: =+BZ14-BZ18-BZ15 | CA16: =+CA14-CA18-CA15 | CB16: =CB14-CB18-CB15 | CC16: =CC14-CC18-CC15 | CD16: =CD14-CD18-CD15 | CE16: =CE14-CE18-CE15 | CF16: =CF14-CF18-CF15 | CG16: =CG14-CG18-CG15 | CH16: =CH14-CH18-CH15 | CI16: =CI14-CI18-CI15 | ... CK16: =CK14-CK18-CK15 | CL16: =CL14-CL15 | CM16: =CM14-CM15 | CN16: =CN14-CN15 | CO16: =CO14-CO15 | CP16: =CP14-CP15 | CQ16: =CQ14-CQ15 | CR16: =CR14-CR15 | CS16: =CS14-CS15 | ... DA16: =DA14-DA15 | DB16: =DB14-DB15-DB18 | DC16: =DC14-DC15-DC18 | DD16: =DD14-DD15-DD18 | DE16: =DE14-DE15-DE18 | DF16: =DF14-DF15-DF18 | DG16: =DG14-DG15-DG18 | DH16: =DH14-DH15-DH18 | DI16: =DI14-DI15-DI18 | DJ16: =DJ14-DJ15-DJ18 | DK16: =DK14-DK15-DK18-DK17 | DL16: =DL14-DL15-DL18-DL17 | DM16: =DM14-DM15-DM18-DM17 | DN16: =DN14-DN15-DN18-DN17 | DO16: =DO14-DO15-DO18-DO17 | DP16: =DP14-DP15-DP18-DP17 | DQ16: =+DM16*(1+DQ27) | DR16: =+DN16*(1+DR27) | DS16: =+DO16*(1+DS27) | DT16: =+DP16*(1+DT27) | DU16: =+DQ16*(1+DU27) | DV16: =+DR16*(1+DV27) | DW16: =+DS16*(1+DW27) | DX16: =+DT16*(1+DX27) | ... EK16: =+EG16*(1+EK27) | FB16: =SUM(BJ16:BM16) | FC16: =SUM(BN16:BQ16) | FD16: =SUM(BR16:BU16) | FE16: =SUM(BV16:BY16) | FF16: =SUM(BZ16:CC16) | FG16: =SUM(CD16:CG16) | FH16: =SUM(CH16:CK16) | FI16: =SUM(CL16:CO16) | FJ16: =SUM(CP16:CS16) | FK16: =SUM(CT16:CW16) | FL16: =SUM(CX16:DA16) | FM16: =SUM(DB16:DE16) | FN16: =SUM(DF16:DI16) | FO16: =SUM(DJ16:DM16) | FP16: =SUM(DN16:DQ16) | FQ16: =SUM(DR16:DU16) | FR16: =SUM(DV16:DY16) | FS16: =SUM(DZ16:EC16) | FT16: =SUM(ED16:EG16) | FU16: =SUM(EH16:EK16) | GN16: =SUM(BK16:BN16) | GO16: =SUM(BO16:BR16) | GP16: =SUM(BS16:BV16) | GQ16: =SUM(BW16:BZ16) | GR16: =SUM(CA16:CD16) | GS16: =SUM(CE16:CH16) | GT16: =SUM(CI16:CL16) | GU16: =SUM(CM16:CP16) | GV16: =SUM(CQ16:CT16) | GW16: =SUM(CU16:CX16) | GX16: =SUM(CY16:DB16) | GY16: =SUM(DC16:DF16) | GZ16: =SUM(DG16:DJ16) | HA16: =SUM(DK16:DN16) | HB16: =SUM(DO16:DR16) | HC16: =SUM(DS16:DV16) | HD16: =SUM(DW16:DZ16) | HE16: =SUM(EA16:ED16) | HF16: =SUM(EE16:EH16)
A17: Product0448 | DK17: =0.1*3500 | DL17: =0.125*3500 | DM17: =0.1*3500 | DN17: =0.2*3000 | DO17: =0.2*3000 | DP17: =0.2*3000 | DQ17: =0.2*3000 | DR17: =0.5*2000 | DS17: =0.5*2000 | DT17: =0.5*2000 | DU17: =0.5*2000 | DV17: =0.5*2000 | DW17: =0.5*2000 | DX17: =0.5*2000 | DY17: =0.5*2000 | ... EK17: =0.5*2000 | FI17: =SUM(CL17:CO17) | FJ17: =SUM(CP17:CS17) | FK17: =SUM(CT17:CW17) | FL17: =SUM(CX17:DA17) | FM17: =SUM(DB17:DE17) | FN17: =SUM(DF17:DI17) | FO17: =SUM(DJ17:DM17) | FP17: =SUM(DN17:DQ17) | FQ17: =SUM(DR17:DU17) | FR17: =SUM(DV17:DY17) | FS17: =SUM(DZ17:EC17) | FT17: =SUM(ED17:EG17) | FU17: =SUM(EH17:EK17)
A18: Product0490 revenue | Z18: 46.625 | AA18: 21.375 | AB18: 22 | AC18: 53 | AD18: 81 | AE18: 32 | AF18: 111 | AG18: 121 | AH18: 256 | AI18: 264 | AJ18: 249 | AK18: 537 | AL18: 1211 | AM18: 1014 | AN18: 1103 | AO18: 1212 | AP18: 2906 | AQ18: 1714 | AR18: 1497 | AS18: 1559 | AT18: 3427 | AU18: 1689 | AV18: 1570 | AW18: 1619 | AX18: 3997 | AY18: 1818 | AZ18: 1678 | BA18: 1660 | BB18: 3371 | BC18: 1665 | BD18: 1492 | BE18: 1563 | BF18: 3391 | BG18: 1861 | BH18: 1545 | BI18: 1477 | BJ18: 3425 | BK18: 1600 | BL18: 1325 | BM18: 1103 | BN18: 2528 | BO18: 1207 | BP18: 1060 | BQ18: 820 | BR18: 2143 | BS18: 962 | BT18: 733 | BU18: 573 | BV18: 973 | BW18: 461 | BX18: 442 | BY18: 410 | BZ18: 653.87913 | CA18: 249.65013 | CB18: =+CB101*CB160 | CC18: =+CC101*CC160 | CD18: =+CD101*CD160 | CE18: =+CE101*CE160 | CF18: =+CF101*CF160 | CG18: =+CG101*CG160 | CH18: =+CH101*CH160 | CI18: =+CI101*CI160 | ... EK18: =+EK101*EK160 | ES18: =SUM(Z18:AC18) | ET18: =SUM(AD18:AG18) | EU18: =SUM(AH18:AK18) | EV18: =SUM(AL18:AO18) | EW18: =SUM(AP18:AS18) | EX18: =SUM(AT18:AW18) | EY18: =SUM(AX18:BA18) | EZ18: =SUM(BB18:BE18) | FA18: =SUM(BF18:BI18) | FB18: =SUM(BJ18:BM18) | FC18: =SUM(BN18:BQ18) | FD18: =SUM(BR18:BU18) | FE18: =SUM(BV18:BY18) | FF18: =SUM(BZ18:CC18) | FG18: =SUM(CD18:CG18) | FH18: =SUM(CH18:CK18) | FI18: =SUM(CL18:CO18) | FJ18: =SUM(CP18:CS18) | FK18: =SUM(CT18:CW18) | FL18: =SUM(CX18:DA18) | FM18: =SUM(DB18:DE18) | FN18: =SUM(DF18:DI18) | FO18: =SUM(DJ18:DM18) | FP18: =SUM(DN18:DQ18) | FQ18: =SUM(DR18:DU18) | FR18: =SUM(DV18:DY18) | FS18: =SUM(DZ18:EC18) | FT18: =SUM(ED18:EG18) | FU18: =SUM(EH18:EK18) | GD18: =SUM(W18:Z18) | GE18: =SUM(AA18:AD18) | GF18: =SUM(AE18:AH18) | GG18: =SUM(AI18:AL18) | GH18: =SUM(AM18:AP18) | GI18: =SUM(AQ18:AT18) | GJ18: =SUM(AU18:AX18) | GK18: =SUM(AY18:BB18) | GL18: =SUM(BC18:BF18) | GM18: =SUM(BG18:BJ18) | GN18: =SUM(BK18:BN18) | GO18: =SUM(BO18:BR18) | GP18: =SUM(BS18:BV18) | GQ18: =SUM(BW18:BZ18) | GR18: =SUM(CA18:CD18) | GS18: =SUM(CE18:CH18) | GT18: =SUM(CI18:CL18) | GU18: =SUM(CM18:CP18) | GV18: =SUM(CQ18:CT18) | GW18: =SUM(CU18:CX18) | GX18: =SUM(CY18:DB18) | GY18: =SUM(DC18:DF18) | GZ18: =SUM(DG18:DJ18) | HA18: =SUM(DK18:DN18) | HB18: =SUM(DO18:DR18) | HC18: =SUM(DS18:DV18) | HD18: =SUM(DW18:DZ18) | HE18: =SUM(EA18:ED18) | HF18: =SUM(EE18:EH18)
