Workbook
Name ACQPRICE: [3]Summary!$B$14
Name ACQPRICE: [4]Summary!$B$20
Name AMORT: Waterfall!$O$3
Name EXITCAP: Waterfall!$L$5
Name GLA: [3]Summary!$B$3
Name GOINGINCAP: Waterfall!$L$2
Name GPCF1: Waterfall!$E$2
Name GPCF2: Waterfall!$E$3
Name GPCF3: Waterfall!$E$4
Name GPCF4: Waterfall!$E$5
Name GPEQUITY: Waterfall!$C$8
Name HOLD: [3]Summary!$B$25
Name HOLD: [4]Summary!$B$31
Name HURDLE2: Waterfall!$C$3
Name HURDLE3: Waterfall!$C$4
Name INTEREST: Waterfall!#REF!
Name LPCF1: Waterfall!$F$2
Name LPCF2: Waterfall!$F$3
Name LPCF3: Waterfall!$F$4
Name LPCF4: Waterfall!$F$5
Name LPEQUITY: Waterfall!$C$9
Name LTV: Waterfall!#REF!
Name NLA: [3]Summary!$B$3
Name NOIGROWTH: Waterfall!$L$3
Name PREF: Waterfall!$C$2
Name PROMOTE2: Waterfall!$D$3
Name PROMOTE3: Waterfall!$D$4
Name PROMOTE4: Waterfall!$D$5
Name PURCHPRICE: Waterfall!#REF!
Name SALEMONTH: Waterfall!$L$1
Name UNITS: [4]Revenue!$A$17
Name WORKINGCAP: [3]Summary!$B$18
Name WORKINGCAP: [4]Summary!$B$24

Sheet S&U
A1: # Units | B1: ='Unit Mix'!C7 -> 61
B2: Funded at Closing | E2: Funded Post Closing | H2: Total Funding
A3: USES OF FUNDS | B3: Total | C3: % Cost | D3: Per Unit | E3: Total | F3: % Cost | G3: Per Unit | H3: Total | I3: % Cost | J3: Per Unit
A4: Land | B4: =Budget!E34 -> 4800000 | C4: =B4/$H$15 -> 0.19974427 | D4: =B4/$B$1 -> 78688.525 | E4: =Budget!F34 -> 0 | F4: =E4/$H$15 -> 0 | G4: =E4/$B$1 -> 0 | H4: =B4+E4 -> 4800000 | I4: =H4/$H$15 -> 0.19974427 | J4: =H4/$B$1 -> 78688.525
A5: Pre-Development | B5: =Budget!E35 -> 0 | C5: =B5/$H$15 -> 0 | D5: =B5/$B$1 -> 0 | E5: =Budget!F35 -> 200000 | F5: =E5/$H$15 -> 0.0083226779 | G5: =E5/$B$1 -> 3278.6885 | H5: =B5+E5 -> 200000 | I5: =H5/$H$15 -> 0.0083226779 | J5: =H5/$B$1 -> 3278.6885
A6: Hard Cost & Contingency | B6: =Budget!E36 -> 0 | C6: =B6/$H$15 -> 0 | D6: =B6/$B$1 -> 0 | E6: =Budget!F36 -> 16200000 | F6: =E6/$H$15 -> 0.67413691 | G6: =E6/$B$1 -> 265573.77 | H6: =B6+E6 -> 16200000 | I6: =H6/$H$15 -> 0.67413691 | J6: =H6/$B$1 -> 265573.77
A7: Soft Cost & Contingency | B7: =Budget!E37 -> 203435 | C7: =B7/$H$15 -> 0.0084656199 | D7: =B7/$B$1 -> 3335 | E7: =Budget!F37 -> 1013415 | F7: =E7/$H$15 -> 0.042171633 | G7: =E7/$B$1 -> 16613.361 | H7: =B7+E7 -> 1216850 | I7: =H7/$H$15 -> 0.050637253 | J7: =H7/$B$1 -> 19948.361
A8: Dvlp & Constr Mgt Fee | B8: =Budget!E38 -> 0 | C8: =B8/$H$15 -> 0 | D8: =B8/$B$1 -> 0 | E8: =Budget!F38 -> 280000 | F8: =E8/$H$15 -> 0.011651749 | G8: =E8/$B$1 -> 4590.1639 | H8: =B8+E8 -> 280000 | I8: =H8/$H$15 -> 0.011651749 | J8: =H8/$B$1 -> 4590.1639
A9: Closing Costs | B9: =Budget!E39 -> 150000 | C9: =B9/$H$15 -> 0.0062420084 | D9: =B9/$B$1 -> 2459.0164 | E9: =Budget!F39 -> 0 | F9: =E9/$H$15 -> 0 | G9: =E9/$B$1 -> 0 | H9: =B9+E9 -> 150000 | I9: =H9/$H$15 -> 0.0062420084 | J9: =H9/$B$1 -> 2459.0164
A10: Ops Deficit Rsv | B10: =Budget!E40 -> 0 | C10: =B10/$H$15 -> 0 | D10: =B10/$B$1 -> 0 | E10: =Budget!F40 -> 120381.34 | F10: =E10/$H$15 -> 0.0050094754 | G10: =E10/$B$1 -> 1973.4645 | H10: =B10+E10 -> 120381.34 | I10: =H10/$H$15 -> 0.0050094754 | J10: =H10/$B$1 -> 1973.4645
A11: Sr. Debt: Commit Fee | B11: =Budget!E41 -> 156000 | C11: =B11/$H$15 -> 0.0064916888 | D11: =B11/$B$1 -> 2557.377 | E11: =Budget!F41 -> 0 | F11: =E11/$H$15 -> 0 | G11: =E11/$B$1 -> 0 | H11: =B11+E11 -> 156000 | I11: =H11/$H$15 -> 0.0064916888 | J11: =H11/$B$1 -> 2557.377
A12: Sr. Debt: Debt Service | B12: =Budget!E42 -> 0 | C12: =B12/$H$15 -> 0 | D12: =B12/$B$1 -> 0 | E12: =Budget!F42 -> 907495.55 | F12: =E12/$H$15 -> 0.037763966 | G12: =E12/$B$1 -> 14876.976 | H12: =B12+E12 -> 907495.55 | I12: =H12/$H$15 -> 0.037763966 | J12: =H12/$B$1 -> 14876.976
C13: =B13/$B$20 -> #DIV/0! | D13: =B13/$B$1 -> 0 | E13: =SUM(E4:E12) -> 18721292 | F13: =E13/$B$20 -> #DIV/0! | G13: =E13/$B$1 -> 306906.42
C14: =B14/$B$20 -> #DIV/0! | D14: =B14/$B$1 -> 0
A15: Total | B15: =SUM(B4:B12) -> 5309435 | C15: =SUM(C4:C12) -> 0.22094359 | D15: =SUM(D4:D12) -> 87039.918 | E15: =SUM(E4:E12) -> 18721292 | F15: =SUM(F4:F12) -> 0.77905641 | G15: =SUM(G4:G12) -> 306906.42 | H15: =SUM(H4:H12) -> 24030727 | I15: =SUM(I4:I12) -> 1 | J15: =SUM(J4:J12) -> 393946.34
A17: SOURCE OF FUNDS | B17: Total | C17: % Cost | D17: Per Unit | E17: Total | F17: % Cost | G17: Per Unit | H17: Total | I17: % Cost | J17: Per Unit
A18: Property CashFlow | B18: =Draws!E13 -> 0 | C18: =B18/$H$21 -> 0 | D18: =B18/$B$1 -> 0 | E18: =Draws!F13 -> 94333.686 | F18: =E18/$H$21 -> 0.0039255444 | G18: =E18/$B$1 -> 1546.4539 | H18: =B18+E18 -> 94333.686 | I18: =H18/$H$21 -> 0.0039255444 | J18: =H18/$B$1 -> 1546.4539
A19: Equity | B19: =Draws!E15 -> 5309435 | C19: =B19/$H$21 -> 0.22094359 | D19: =B19/$B$1 -> 87039.918 | E19: =Draws!F15 -> 3090565 | F19: =E19/$H$21 -> 0.12860889 | G19: =E19/$B$1 -> 50665 | H19: =B19+E19 -> 8400000 | I19: =H19/$H$21 -> 0.34955247 | J19: =H19/$B$1 -> 137704.92
A20: Debt | B20: =Draws!E14 -> 0 | C20: =B20/$H$21 -> 0 | D20: =B20/$B$1 -> 0 | E20: =Draws!F14 -> 15536393 | F20: =E20/$H$21 -> 0.64652198 | G20: =E20/$B$1 -> 254694.97 | H20: =B20+E20 -> 15536393 | I20: =H20/$H$21 -> 0.64652198 | J20: =H20/$B$1 -> 254694.97
A21: Total | B21: =SUM(B18:B20) -> 5309435 | C21: =SUM(C18:C20) -> 0.22094359 | D21: =SUM(D18:D20) -> 87039.918 | E21: =SUM(E18:E20) -> 18721292 | F21: =SUM(F18:F20) -> 0.77905641 | G21: =SUM(G18:G20) -> 306906.42 | H21: =SUM(H18:H20) -> 24030727 | I21: =SUM(I18:I20) -> 1 | J21: =SUM(J18:J20) -> 393946.34
E23: Total Cost After Excess CF | H23: =H21-H18 -> 23936393
E24: Equity % Total | H24: 0.35
E25: Total Equity Required | H25: =H23*H24 -> 8377737.6

Sheet Budget
B1: Construction Budget
E2: At Closing | F2: Post Closing | G2: Total Cost
B3: Land | E3: =Draws!E69 -> 4800000 | F3: =Draws!F69 -> 0 | G3: =SUM(E3:F3) -> 4800000
B4: Pre-Development | E4: =Draws!E71 -> 0 | F4: =Draws!F71 -> 200000 | G4: =SUM(E4:F4) -> 200000
B5: Hard Costs
C6: Hard Costs (Construction) | E6: =Draws!E74 -> 0 | F6: =Draws!F74 -> 16200000 | G6: =SUM(E6:F6) -> 16200000
C7: Hard Cost Contingency | D7: (2) | E7: =Draws!E75 -> 0 | F7: =Draws!F75 -> 0 | G7: =SUM(E7:F7) -> 0
B8: Total Hard Costs + Contingency | E8: =SUM(E6:E7) -> 0 | F8: =SUM(F6:F7) -> 16200000 | G8: =SUM(G6:G7) -> 16200000
B9: Soft Costs
C10: =Draws!C79 -> Architectural | E10: =Draws!E79 -> 0 | F10: =Draws!F79 -> 244000 | G10: =SUM(E10:F10) -> 244000
C11: =Draws!C80 -> Engineering & Related | E11: =Draws!E80 -> 0 | F11: =Draws!F80 -> 33550 | G11: =SUM(E11:F11) -> 33550
C12: =Draws!C81 -> Impact/Permits | E12: =Draws!E81 -> 0 | F12: =Draws!F81 -> 549000 | G12: =SUM(E12:F12) -> 549000
C13: =Draws!C82 -> Marketing | E13: =Draws!E82 -> 0 | F13: =Draws!F82 -> 24400 | G13: =SUM(E13:F13) -> 24400
C14: =Draws!C83 -> Bldr Risk & Perf Bond | E14: =Draws!E83 -> 154635 | F14: =Draws!F83 -> 0 | G14: =SUM(E14:F14) -> 154635
C15: =Draws!C84 -> Legal & Professional | E15: =Draws!E84 -> 48800 | F15: =Draws!F84 -> 0 | G15: =SUM(E15:F15) -> 48800
C16: =Draws!C85 -> Investor Admin Costs | E16: =Draws!E85 -> 0 | F16: =Draws!F85 -> 9150 | G16: =SUM(E16:F16) -> 9150
C17: =Draws!C86 -> RE Tax During Constr | E17: =Draws!E86 -> 0 | F17: =Draws!F86 -> 92315 | G17: =SUM(E17:F17) -> 92315
B18: Subtotal Soft Costs | E18: =SUM(E10:E17) -> 203435 | F18: =SUM(F10:F17) -> 952415 | G18: =SUM(G10:G17) -> 1155850
B20: Soft Cost Contingency | D20: (3) | E20: =Draws!E89 -> 0 | F20: =Draws!F89 -> 61000 | G20: =Draws!G89 -> 61000
B21: Dvlp & Constr Mgt Fee | D21: (4) | E21: =Draws!E90 -> 0 | F21: =Draws!F90 -> 280000 | G21: =Draws!G90 -> 280000
B22: Closing Costs | E22: =Draws!E91 -> 150000 | F22: =Draws!F91 -> 0 | G22: =Draws!G91 -> 150000
B23: =Draws!C27 -> Ops Deficit Rsv | E23: =Draws!E92 -> 0 | F23: =Draws!F92 -> 120381.34 | G23: =Draws!G92 -> 120381.34
B24: =Draws!C28 -> Sr. Debt: Commit Fee | D24: 0.01 | E24: =Draws!E93 -> 156000 | F24: =Draws!F93 -> 0 | G24: =Draws!G93 -> 156000
B25: Sr. Debt: Debt Service | D25: (5) | E25: =Draws!E94 -> 0 | F25: =Draws!F94 -> 907495.55 | G25: =Draws!G94 -> 907495.55
C27: Total Development Costs | E27: =E3+E4+E8+E18+SUM(E20:E25) -> 5309435 | F27: =F3+F4+F8+F18+SUM(F20:F25) -> 18721292 | G27: =G3+G4+G8+G18+SUM(G20:G25) -> 24030727
B28: (2) Hard cost contingency: | D28: =G7/G6 -> 0 | E28: % hard costs.
B29: (3) Soft cost contingency: | D29: =G20/G18 -> 0.052775014 | E29: % soft costs.
B30: (4) Dvlp Fee | D30: =G21/(G18+G8) -> 0.016132889 | E30: % hard+soft costs
B32: Summary Construction Budget
E33: At Closing | F33: Post Closing | G33: Total Cost
B34: Land | E34: =Budget!E3 -> 4800000 | F34: =Budget!F3 -> 0 | G34: =Budget!G3 -> 4800000
B35: Pre-Development | E35: =E4 -> 0 | F35: =F4 -> 200000 | G35: =G4 -> 200000
B36: Hard Cost & Contingency | E36: =Budget!E8 -> 0 | F36: =Budget!F8 -> 16200000 | G36: =Budget!G8 -> 16200000
B37: Soft Cost & Contingency | E37: =Budget!E18+Budget!E20 -> 203435 | F37: =Budget!F18+Budget!F20 -> 1013415 | G37: =Budget!G18+Budget!G20 -> 1216850
B38: Dvlp & Constr Mgt Fee | E38: =Budget!E21 -> 0 | F38: =Budget!F21 -> 280000 | G38: =Budget!G21 -> 280000
B39: Closing Costs | E39: =Budget!E22 -> 150000 | F39: =Budget!F22 -> 0 | G39: =Budget!G22 -> 150000
B40: Ops Deficit Rsv | E40: =Budget!E23 -> 0 | F40: =Budget!F23 -> 120381.34 | G40: =Budget!G23 -> 120381.34
B41: Sr. Debt: Commit Fee | E41: =Budget!E24 -> 156000 | F41: =Budget!F24 -> 0 | G41: =Budget!G24 -> 156000
B42: Sr. Debt: Debt Service | E42: =Budget!E25 -> 0 | F42: =Budget!F25 -> 907495.55 | G42: =Budget!G25 -> 907495.55
B43: Total Development Costs | E43: =SUM(E34:E42) -> 5309435 | F43: =SUM(F34:F42) -> 18721292 | G43: =SUM(G34:G42) -> 24030727

Sheet Draws
B1: Sr. Interest | D1: =G29 -> 907495.55 | H1: =G16 -> 24030727
B2: IR Sized Based on | D2: Forward Rate | E2: (Rate Today or Forward Rate)
D3: Start Mo. | E3: End Mo. | F3: # Ms. | G3: Start Date
B4: Pre-Development | D4: 1 | E4: =D4+F4-1 -> 6 | F4: 6 | G4: 45597
B5: Construction | D5: =E4+1 -> 7 | E5: =D5+F5-1 -> 20 | F5: 14 | G5: =EDATE(G4,F4) -> 45778
B6: Lease-Up | D6: =E5+1 -> 21 | E6: =D6+F6-1 -> 22 | F6: 2 | G6: =EDATE(G5,F5) -> 46204
B7: NOI+ | D7: =E6+1 -> 23 | E7: =D7+F7-1 -> 24 | F7: 2 | G7: =EDATE(G6,F6) -> 46266
B8: Brk Even CF | D8: =E7+1 -> 25 | E8: =D8+F8-1 -> 29 | F8: 5 | G8: =EDATE(G7,F7) -> 46327 | H8: YEAR 0 | I8: YEAR 1 | U8: YEAR 2 | AG8: YEAR 3 | AS8: YEAR 4 | BE8: YEAR 5
B9: Sale Date | F9: 36 | G9: =EDATE(G4,F9-1) -> 46661 | I9: =IF(I11<=$E$4,"Pre-Dvlp",IF(I11<=$E$5,"Constr",IF(I11<=$E$6,"Lease-Up",IF(I11<=$E$7,"NOI+","B/E")))) -> Pre-Dvlp | J9: =IF(J11<=$E$4,"Pre-Dvlp",IF(J11<=$E$5,"Constr",IF(J11<=$E$6,"Lease-Up",IF(J11<=$E$7,"NOI+","B/E")))) -> Pre-Dvlp | K9: =IF(K11<=$E$4,"Pre-Dvlp",IF(K11<=$E$5,"Constr",IF(K11<=$E$6,"Lease-Up",IF(K11<=$E$7,"NOI+","B/E")))) -> Pre-Dvlp | L9: =IF(L11<=$E$4,"Pre-Dvlp",IF(L11<=$E$5,"Constr",IF(L11<=$E$6,"Lease-Up",IF(L11<=$E$7,"NOI+","B/E")))) -> Pre-Dvlp | M9: =IF(M11<=$E$4,"Pre-Dvlp",IF(M11<=$E$5,"Constr",IF(M11<=$E$6,"Lease-Up",IF(M11<=$E$7,"NOI+","B/E")))) -> Pre-Dvlp | N9: =IF(N11<=$E$4,"Pre-Dvlp",IF(N11<=$E$5,"Constr",IF(N11<=$E$6,"Lease-Up",IF(N11<=$E$7,"NOI+","B/E")))) -> Pre-Dvlp | O9: =IF(O11<=$E$4,"Pre-Dvlp",IF(O11<=$E$5,"Constr",IF(O11<=$E$6,"Lease-Up",IF(O11<=$E$7,"NOI+","B/E")))) -> Constr | P9: =IF(P11<=$E$4,"Pre-Dvlp",IF(P11<=$E$5,"Constr",IF(P11<=$E$6,"Lease-Up",IF(P11<=$E$7,"NOI+","B/E")))) -> Constr | ... BP9: =IF(BP11<=$E$4,"Pre-Dvlp",IF(BP11<=$E$5,"Constr",IF(BP11<=$E$6,"Lease-Up",IF(BP11<=$E$7,"NOI+","B/E")))) -> B/E
H10: =EDATE(G4,-1) -> 45566 | I10: =EOMONTH(H10,1) -> 45626 | J10: =EOMONTH(I10,1) -> 45657 | K10: =EOMONTH(J10,1) -> 45688 | L10: =EOMONTH(K10,1) -> 45716 | M10: =EOMONTH(L10,1) -> 45747 | N10: =EOMONTH(M10,1) -> 45777 | O10: =EOMONTH(N10,1) -> 45808 | P10: =EOMONTH(O10,1) -> 45838 | ... BP10: =EOMONTH(BO10,1) -> 47422
D11: Total | E11: at Closing | F11: To B/E | G11: Total | H11: Closing | I11: 1 | J11: =I11+1 -> 2 | K11: =J11+1 -> 3 | L11: =K11+1 -> 4 | M11: =L11+1 -> 5 | N11: =M11+1 -> 6 | O11: =N11+1 -> 7 | P11: =O11+1 -> 8 | Q11: =P11+1 -> 9 | ... BP11: =BO11+1 -> 60
B12: FUNDING SOURCES
C13: Excess Property CF | E13: =SUM(H13) -> 0 | F13: =SUM(I13:BP13) -> 94333.686 | G13: =E13+F13 -> 94333.686 | H13: 0 | I13: =IF(I9="B/E",0,IF('Lease Up'!I46>0,'Lease Up'!I46,0)) -> 0 | J13: =IF(J9="B/E",0,IF('Lease Up'!J46>0,'Lease Up'!J46,0)) -> 0 | K13: =IF(K9="B/E",0,IF('Lease Up'!K46>0,'Lease Up'!K46,0)) -> 0 | L13: =IF(L9="B/E",0,IF('Lease Up'!L46>0,'Lease Up'!L46,0)) -> 0 | M13: =IF(M9="B/E",0,IF('Lease Up'!M46>0,'Lease Up'!M46,0)) -> 0 | N13: =IF(N9="B/E",0,IF('Lease Up'!N46>0,'Lease Up'!N46,0)) -> 0 | O13: =IF(O9="B/E",0,IF('Lease Up'!O46>0,'Lease Up'!O46,0)) -> 0 | P13: =IF(P9="B/E",0,IF('Lease Up'!P46>0,'Lease Up'!P46,0)) -> 0 | ... BP13: =IF(BP9="B/E",0,IF('Lease Up'!BP46>0,'Lease Up'!BP46,0)) -> 0
C14: Senior Debt | E14: =SUM(H14) -> 0 | F14: =SUM(I14:BP14) -> 15536393 | G14: =E14+F14 -> 15536393 | H14: =IF(H15=H32,0,IF(H49=$D$15,H32,H32-H50)) -> 0 | I14: =I44+I45 -> 0 | J14: =J44+J45 -> 0 | K14: =K44+K45 -> 0 | L14: =L44+L45 -> 0 | M14: =M44+M45 -> 0 | N14: =N44+N45 -> 0 | O14: =O44+O45 -> 0 | P14: =P44+P45 -> 0 | ... BP14: =BP44+BP45 -> 0
C15: Equity | D15: 8400000 | E15: =SUM(H15) -> 5309435 | F15: =SUM(I15:BP15) -> 3090565 | G15: =E15+F15 -> 8400000 | H15: =IF(H49=$D$15,0,IF(H32+H49<=$D$15,H32,IF(H32+H49>$D$15,$D$15-H49,0))) -> 5309435 | I15: =IF(I49=$D$15,0,IF(I32+I49<=$D$15,I32,IF(I32+I49>$D$15,$D$15-I49,0))) -> 33333.333 | J15: =IF(J49=$D$15,0,IF(J32+J49<=$D$15,J32,IF(J32+J49>$D$15,$D$15-J49,0))) -> 33333.333 | K15: =IF(K49=$D$15,0,IF(K32+K49<=$D$15,K32,IF(K32+K49>$D$15,$D$15-K49,0))) -> 33333.333 | L15: =IF(L49=$D$15,0,IF(L32+L49<=$D$15,L32,IF(L32+L49>$D$15,$D$15-L49,0))) -> 33333.333 | M15: =IF(M49=$D$15,0,IF(M32+M49<=$D$15,M32,IF(M32+M49>$D$15,$D$15-M49,0))) -> 33333.333 | N15: =IF(N49=$D$15,0,IF(N32+N49<=$D$15,N32,IF(N32+N49>$D$15,$D$15-N49,0))) -> 33333.333 | O15: =IF(O49=$D$15,0,IF(O32+O49<=$D$15,O32,IF(O32+O49>$D$15,$D$15-O49,0))) -> 1249529.6 | ... BP15: =IF(BP49=$D$15,0,IF(BP32+BP49<=$D$15,BP32,IF(BP32+BP49>$D$15,$D$15-BP49,0))) -> 0
B16: TOTAL FUNDING SOURCES | E16: =SUM(E13:E15) -> 5309435 | F16: =SUM(F13:F15) -> 18721292 | G16: =SUM(G13:G15) -> 24030727 | H16: =SUM(H13:H15) -> 5309435 | I16: =SUM(I13:I15) -> 33333.333 | J16: =SUM(J13:J15) -> 33333.333 | K16: =SUM(K13:K15) -> 33333.333 | L16: =SUM(L13:L15) -> 33333.333 | ... BP16: =SUM(BP13:BP15) -> 0
B18: COSTS
C19: Land Acquisition | E19: =SUM(H19) -> 4800000 | F19: =SUM(I19:BP19) -> 0 | G19: =E19+F19 -> 4800000 | H19: =H69 -> 4800000 | I19: =I69 -> 0 | J19: =J69 -> 0 | K19: =K69 -> 0 | L19: =L69 -> 0 | M19: =M69 -> 0 | N19: =N69 -> 0 | O19: =O69 -> 0 | ... BP19: =BP69 -> 0
C20: Pre-Development | E20: =SUM(H20) -> 0 | F20: =SUM(I20:BP20) -> 200000 | G20: =E20+F20 -> 200000 | I20: =I71 -> 33333.333 | J20: =J71 -> 33333.333 | K20: =K71 -> 33333.333 | L20: =L71 -> 33333.333 | M20: =M71 -> 33333.333 | N20: =N71 -> 33333.333 | O20: =O71 -> 0 | P20: =P71 -> 0 | ... BP20: =BP71 -> 0
C21: Hard Costs | E21: =SUM(H21) -> 0 | F21: =SUM(I21:BP21) -> 16200000 | G21: =E21+F21 -> 16200000 | H21: =H74 -> 0 | I21: =I74 -> 0 | J21: =J74 -> 0 | K21: =K74 -> 0 | L21: =L74 -> 0 | M21: =M74 -> 0 | N21: =N74 -> 0 | O21: =O74 -> 1157142.9 | ... BP21: =BP74 -> 0
C22: Hard Cost Contingency | E22: =SUM(H22) -> 0 | F22: =SUM(I22:BP22) -> 0 | G22: =E22+F22 -> 0 | H22: =H75 -> 0 | I22: =I75 -> 0 | J22: =J75 -> 0 | K22: =K75 -> 0 | L22: =L75 -> 0 | M22: =M75 -> 0 | N22: =N75 -> 0 | O22: =O75 -> 0 | ... BP22: =BP75 -> 0
C23: Soft Costs | E23: =SUM(H23) -> 203435 | F23: =SUM(I23:BP23) -> 952415 | G23: =E23+F23 -> 1155850 | H23: =SUM(H79:H86) -> 203435 | I23: =SUM(I79:I86) -> 0 | J23: =SUM(J79:J86) -> 0 | K23: =SUM(K79:K86) -> 0 | L23: =SUM(L79:L86) -> 0 | M23: =SUM(M79:M86) -> 0 | N23: =SUM(N79:N86) -> 0 | O23: =SUM(O79:O86) -> 68029.643 | ... BP23: =SUM(BP79:BP86) -> 0
C24: Soft Cost Contingency | E24: =SUM(H24) -> 0 | F24: =SUM(I24:BP24) -> 61000 | G24: =E24+F24 -> 61000 | H24: =H89 -> 0 | I24: =I89 -> 0 | J24: =J89 -> 0 | K24: =K89 -> 0 | L24: =L89 -> 0 | M24: =M89 -> 0 | N24: =N89 -> 0 | O24: =O89 -> 4357.1429 | ... BP24: =BP89 -> 0
C25: Dvlp/Const Mgt Fees | E25: =SUM(H25) -> 0 | F25: =SUM(I25:BP25) -> 280000 | G25: =E25+F25 -> 280000 | H25: =H90 -> 0 | I25: =I90 -> 0 | J25: =J90 -> 0 | K25: =K90 -> 0 | L25: =L90 -> 0 | M25: =M90 -> 0 | N25: =N90 -> 0 | O25: =O90 -> 20000 | ... BP25: =BP90 -> 0
C26: Closing Costs | E26: =SUM(H26) -> 150000 | F26: =SUM(I26:BP26) -> 0 | G26: =E26+F26 -> 150000 | H26: =H91 -> 150000 | I26: =I91 -> 0 | J26: =J91 -> 0 | K26: =K91 -> 0 | L26: =L91 -> 0 | M26: =M91 -> 0 | N26: =N91 -> 0 | O26: =O91 -> 0 | ... BP26: =BP91 -> 0
C27: Ops Deficit Rsv | E27: =SUM(H27) -> 0 | F27: =SUM(I27:BP27) -> 120381.34 | G27: =E27+F27 -> 120381.34 | H27: =H92 -> 0 | I27: =I92 -> 0 | J27: =J92 -> 0 | K27: =K92 -> 0 | L27: =L92 -> 0 | M27: =M92 -> 0 | N27: =N92 -> 0 | O27: =O92 -> 0 | ... BP27: =BP92 -> 0
C28: Sr. Debt: Commit Fee | D28: 0.01 | E28: =SUM(H28) -> 156000 | F28: =SUM(I28:BP28) -> 0 | G28: =E28+F28 -> 156000 | H28: =H93 -> 156000 | I28: =I93 -> 0 | J28: =J93 -> 0 | K28: =K93 -> 0 | L28: =L93 -> 0 | M28: =M93 -> 0 | N28: =N93 -> 0 | O28: =O93 -> 0 | ... BP28: =BP93 -> 0
C29: Sr. Debt: Debt Service | E29: =SUM(H29) -> 0 | F29: =SUM(I29:BP29) -> 907495.55 | G29: =E29+F29 -> 907495.55 | H29: =H41 -> 0 | I29: =I41 -> 0 | J29: =J41 -> 0 | K29: =K41 -> 0 | L29: =L41 -> 0 | M29: =M41 -> 0 | N29: =N41 -> 0 | O29: =O41 -> 0 | ... BP29: =BP41 -> 0
B30: TOTAL COST | E30: =SUM(E19:E29) -> 5309435 | F30: =SUM(F19:F29) -> 18721292 | G30: =SUM(G19:G29) -> 24030727 | H30: =SUM(H19:H29) -> 5309435 | I30: =SUM(I19:I29) -> 33333.333 | J30: =SUM(J19:J29) -> 33333.333 | K30: =SUM(K19:K29) -> 33333.333 | L30: =SUM(L19:L29) -> 33333.333 | ... BP30: =SUM(BP19:BP29) -> 0
C31: Less: Excess Property CF | E31: =H31 -> 0 | F31: =SUM(I31:AN31) -> -94333.686 | G31: =-G13 -> -94333.686 | H31: =-H13 -> 0 | I31: =-I13 -> 0 | J31: =-J13 -> 0 | K31: =-K13 -> 0 | L31: =-L13 -> 0 | M31: =-M13 -> 0 | N31: =-N13 -> 0 | ... BP31: =-BP13 -> 0
B32: TOTAL CAPITALIZATION | E32: =H32 -> 5309435 | G32: =SUM(G30:G31) -> 23936393 | H32: =SUM(H30:H31) -> 5309435 | I32: =SUM(I30:I31) -> 33333.333 | J32: =SUM(J30:J31) -> 33333.333 | K32: =SUM(K30:K31) -> 33333.333 | L32: =SUM(L30:L31) -> 33333.333 | M32: =SUM(M30:M31) -> 33333.333 | N32: =SUM(N30:N31) -> 33333.333 | ... BP32: =SUM(BP30:BP31) -> 0
C33: 1 ms. Term SOFR - forward curve | H33: ='Forward Rate'!G6 -> 0.0530533 | I33: ='Forward Rate'!H6 -> 0.0523577 | J33: ='Forward Rate'!I6 -> 0.0518021 | K33: ='Forward Rate'!J6 -> 0.0512678 | L33: ='Forward Rate'!K6 -> 0.0496218 | M33: ='Forward Rate'!L6 -> 0.0493128 | N33: ='Forward Rate'!M6 -> 0.0493027 | O33: ='Forward Rate'!N6 -> 0.0474269 | ... BP33: ='Forward Rate'!BO6 -> 0.0375526
C34: Spread | H34: 0.03 | I34: =$H$34 -> 0.03 | J34: =$H$34 -> 0.03 | K34: =$H$34 -> 0.03 | L34: =$H$34 -> 0.03 | M34: =$H$34 -> 0.03 | N34: =$H$34 -> 0.03 | O34: =$H$34 -> 0.03 | P34: =$H$34 -> 0.03 | ... BP34: =$H$34 -> 0.03
C35: Total Rate | H35: =H33+H34 -> 0.0830533 | I35: =I33+I34 -> 0.0823577 | J35: =J33+J34 -> 0.0818021 | K35: =K33+K34 -> 0.0812678 | L35: =L33+L34 -> 0.0796218 | M35: =M33+M34 -> 0.0793128 | N35: =N33+N34 -> 0.0793027 | O35: =O33+O34 -> 0.0774269 | ... BP35: =BP33+BP34 -> 0.0675526
C36: Total Rate Floor | H36: =H35-2% -> 0.0630533 | I36: =$H$36 -> 0.0630533 | J36: =$H$36 -> 0.0630533 | K36: =$H$36 -> 0.0630533 | L36: =$H$36 -> 0.0630533 | M36: =$H$36 -> 0.0630533 | N36: =$H$36 -> 0.0630533 | O36: =$H$36 -> 0.0630533 | P36: =$H$36 -> 0.0630533 | ... BP36: =$H$36 -> 0.0630533
C37: Greater of Index + Spread or Floor | H37: =MAX(H35:H36) -> 0.0830533 | I37: =MAX(I35:I36) -> 0.0823577 | J37: =MAX(J35:J36) -> 0.0818021 | K37: =MAX(K35:K36) -> 0.0812678 | L37: =MAX(L35:L36) -> 0.0796218 | M37: =MAX(M35:M36) -> 0.0793128 | N37: =MAX(N35:N36) -> 0.0793027 | O37: =MAX(O35:O36) -> 0.0774269 | ... BP37: =MAX(BP35:BP36) -> 0.0675526
C38: Premium for Rate Sizing | H38: 0.005 | I38: =$H$38 -> 0.005 | J38: =$H$38 -> 0.005 | K38: =$H$38 -> 0.005 | L38: =$H$38 -> 0.005 | M38: =$H$38 -> 0.005 | N38: =$H$38 -> 0.005 | O38: =$H$38 -> 0.005 | P38: =$H$38 -> 0.005 | ... BP38: =$H$38 -> 0.005
C39: Rate for Sizing IR | H39: =IF($D$2="Forward Rate",SUM(H37:H38),H40) -> 0.0880533 | I39: =IF($D$2="Forward Rate",SUM(I37:I38),I40) -> 0.0873577 | J39: =IF($D$2="Forward Rate",SUM(J37:J38),J40) -> 0.0868021 | K39: =IF($D$2="Forward Rate",SUM(K37:K38),K40) -> 0.0862678 | L39: =IF($D$2="Forward Rate",SUM(L37:L38),L40) -> 0.0846218 | M39: =IF($D$2="Forward Rate",SUM(M37:M38),M40) -> 0.0843128 | N39: =IF($D$2="Forward Rate",SUM(N37:N38),N40) -> 0.0843027 | O39: =IF($D$2="Forward Rate",SUM(O37:O38),O40) -> 0.0824269 | ... BP39: =IF($D$2="Forward Rate",SUM(BP37:BP38),BP40) -> 0.0725526
C40: Today's Rate | H40: =$H$33+$H$34 -> 0.0830533 | I40: =$H$33+$H$34 -> 0.0830533 | J40: =$H$33+$H$34 -> 0.0830533 | K40: =$H$33+$H$34 -> 0.0830533 | L40: =$H$33+$H$34 -> 0.0830533 | M40: =$H$33+$H$34 -> 0.0830533 | N40: =$H$33+$H$34 -> 0.0830533 | O40: =$H$33+$H$34 -> 0.0830533 | ... BP40: =$H$33+$H$34 -> 0.0830533
C41: + Sr. Debt: Debt Service | E41: =H41 -> 0 | F41: =SUM(I41:BP41) -> 907495.55 | G41: =SUM(E41:F41) -> 907495.55 | H41: 0 | I41: =IF(I9="B/E",0,H47*I39/12*365/360) -> 0 | J41: =IF(J9="B/E",0,I47*J39/12*365/360) -> 0 | K41: =IF(K9="B/E",0,J47*K39/12*365/360) -> 0 | L41: =IF(L9="B/E",0,K47*L39/12*365/360) -> 0 | M41: =IF(M9="B/E",0,L47*M39/12*365/360) -> 0 | N41: =IF(N9="B/E",0,M47*N39/12*365/360) -> 0 | O41: =IF(O9="B/E",0,N47*O39/12*365/360) -> 0 | P41: =IF(P9="B/E",0,O47*P39/12*365/360) -> 0 | ... BP41: =IF(BP9="B/E",0,BO47*BP39/12*365/360) -> 0
...

Sheet Lease Up
Q1: Start Mo. | R1: End Mo. | S1: # Ms. To complete | T1: Start Date
K2: # units | L2: $/Unit | M2: Utiliz Rt | N2: Tot $/Mo. | P2: =Draws!B4 -> Pre-Development | Q2: =Draws!D4 -> 1 | R2: =Draws!E4 -> 6 | S2: =Draws!F4 -> 6 | T2: =Draws!G4 -> 45597
I3: Apartments (Unit) | K3: ='Unit Mix'!C7 -> 61 | L3: ='Unit Mix'!E7 -> 3288 | M3: 1 | N3: =K3*L3 -> 200568 | P3: =Draws!B5 -> Construction | Q3: =Draws!D5 -> 7 | R3: =Draws!E5 -> 20 | S3: =Draws!F5 -> 14 | T3: =Draws!G5 -> 45778
I4: Apartments (SF) | L4: ='Unit Mix'!F7 -> 2.7500686 | M4: Unit Mix Tab controls rents | P4: =Draws!B6 -> Lease-Up | Q4: =Draws!D6 -> 21 | R4: =Draws!E6 -> 22 | S4: =Draws!F6 -> 2 | T4: =Draws!G6 -> 46204
I5: Lease-up/Mo. | K5: 10 | L5: Tot. ls up ms | M5: =K3/K5 -> 6.1 | P5: =Draws!B7 -> NOI+ | Q5: =Draws!D7 -> 23 | R5: =Draws!E7 -> 24 | S5: =Draws!F7 -> 2 | T5: =Draws!G7 -> 46266
I6: Vacancy After Lease Up | M6: 0.05 | P6: =Draws!B8 -> Brk Even CF | Q6: =Draws!D8 -> 25 | R6: =Draws!E8 -> 29 | S6: =Draws!F8 -> 5 | T6: =Draws!G8 -> 46327
I7: Parking | K7: =ROUNDUP(161/2,0) -> 81 | L7: 150 | M7: 0.8 | N7: =K7*L7*M7 -> 9720 | P7: =Draws!B9 -> Sale Date | Q7: =Draws!D9 -> 0 | R7: =Draws!E9 -> 0 | S7: =Draws!F9 -> 36 | T7: =Draws!G9 -> 46661 | V7: if sale ms > | W7: =60-12 -> 48 | X7: then extend cash flows
I8: Other Services | K8: =$K$3 -> 61 | L8: 100 | M8: 0.8 | N8: =K8*L8*M8 -> 4880 | Q8: Start Mo. | R8: End Mo. | S8: # Ms. | T8: % | AI8: =AH19+K5 -> 70
I9: Premiums | K9: =$K$3 -> 61 | L9: 0 | M9: 1 | N9: =K9*L9*M9 -> 0 | P9: Pre-ls up exp | Q9: =Q4-4 -> 17 | R9: =Q9+S9-1 -> 20 | S9: 4 | T9: 0.5
I10: Lease-Up Concession % | K10: 0.01 | P10: Ls up exp | Q10: =R9+1 -> 21 | R10: =Q10+S10-1 -> 24 | S10: =ROUNDUP(M5*50%,0) -> 4 | T10: 0.75
I11: Sale Cap | J11: 0.065 | K11: Cost of Sale | L11: 0.03 | M11: Dsct Rt | N11: =J11+2% -> 0.085 | S11: eye-ball to get correct periods for Draw Schedule timing | AC11: Lease-Up | AD11: Lease-Up | AE11: NOI+ | AF11: NOI+ | AG11: B/E
I12: =Draws!I9 -> Pre-Dvlp | J12: =Draws!J9 -> Pre-Dvlp | K12: =Draws!K9 -> Pre-Dvlp | L12: =Draws!L9 -> Pre-Dvlp | M12: =Draws!M9 -> Pre-Dvlp | N12: =Draws!N9 -> Pre-Dvlp | O12: =Draws!O9 -> Constr | P12: =Draws!P9 -> Constr | ... BP12: =Draws!BP9 -> B/E
I13: =Draws!G4 -> 45597 | J13: =EDATE(I13,1) -> 45627 | K13: =EDATE(J13,1) -> 45658 | L13: =EDATE(K13,1) -> 45689 | M13: =EDATE(L13,1) -> 45717 | N13: =EDATE(M13,1) -> 45748 | O13: =EDATE(N13,1) -> 45778 | P13: =EDATE(O13,1) -> 45809 | Q13: =EDATE(P13,1) -> 45839 | ... BP13: =EDATE(BO13,1) -> 47392
F14: Year for Growth Calcs | I14: 1 | J14: 1 | K14: 1 | L14: 1 | M14: 1 | N14: 1 | O14: 1 | P14: 1 | Q14: 1 | R14: 1 | S14: 1 | T14: 1 | U14: 2 | V14: 2 | W14: 2 | X14: 2 | Y14: 2 | Z14: 2 | AA14: 2 | AB14: 2 | AC14: 2 | AD14: 2 | AE14: 2 | AF14: 2 | AG14: 3 | AH14: 3 | AI14: 3 | AJ14: 3 | AK14: 3 | AL14: 3 | AM14: 3 | AN14: 3 | AO14: 3 | AP14: 3 | AQ14: 3 | AR14: 3 | AS14: 4 | AT14: 4 | AU14: 4 | AV14: 4 | AW14: 4 | AX14: 4 | AY14: 4 | AZ14: 4 | BA14: 4 | BB14: 4 | BC14: 4 | BD14: 4 | BE14: 5 | BF14: 5 | BG14: 5 | BH14: 5 | BI14: 5 | BJ14: 5 | BK14: 5 | BL14: 5 | BM14: 5 | BN14: 5 | BO14: 5 | BP14: 5
F15: Month | I15: 1 | J15: =I15+1 -> 2 | K15: =J15+1 -> 3 | L15: =K15+1 -> 4 | M15: =L15+1 -> 5 | N15: =M15+1 -> 6 | O15: =N15+1 -> 7 | P15: =O15+1 -> 8 | Q15: =P15+1 -> 9 | ... BP15: =BO15+1 -> 60
F17: ASSUMPTIONS
F18: Apts: New Leases | I18: =IF(OR(I12="Constr",I12="Pre-Dvlp"),0,IF(H19=$K$3,0,IF((H19+$K$5)>$K$3,($K$3-H$19),$K$5))) -> 0 | J18: =IF(OR(J12="Constr",J12="Pre-Dvlp"),0,IF(I19=$K$3,0,IF((I19+$K$5)>$K$3,($K$3-I$19),$K$5))) -> 0 | K18: =IF(OR(K12="Constr",K12="Pre-Dvlp"),0,IF(J19=$K$3,0,IF((J19+$K$5)>$K$3,($K$3-J$19),$K$5))) -> 0 | L18: =IF(OR(L12="Constr",L12="Pre-Dvlp"),0,IF(K19=$K$3,0,IF((K19+$K$5)>$K$3,($K$3-K$19),$K$5))) -> 0 | M18: =IF(OR(M12="Constr",M12="Pre-Dvlp"),0,IF(L19=$K$3,0,IF((L19+$K$5)>$K$3,($K$3-L$19),$K$5))) -> 0 | N18: =IF(OR(N12="Constr",N12="Pre-Dvlp"),0,IF(M19=$K$3,0,IF((M19+$K$5)>$K$3,($K$3-M$19),$K$5))) -> 0 | O18: =IF(OR(O12="Constr",O12="Pre-Dvlp"),0,IF(N19=$K$3,0,IF((N19+$K$5)>$K$3,($K$3-N$19),$K$5))) -> 0 | P18: =IF(OR(P12="Constr",P12="Pre-Dvlp"),0,IF(O19=$K$3,0,IF((O19+$K$5)>$K$3,($K$3-O$19),$K$5))) -> 0 | ... BP18: =IF(OR(BP12="Constr",BP12="Pre-Dvlp"),0,IF(BO19=$K$3,0,IF((BO19+$K$5)>$K$3,($K$3-BO$19),$K$5))) -> 0
F19: Apts: Total Leased Up | I19: =I18+H19 -> 0 | J19: =J18+I19 -> 0 | K19: =K18+J19 -> 0 | L19: =L18+K19 -> 0 | M19: =M18+L19 -> 0 | N19: =N18+M19 -> 0 | O19: =O18+N19 -> 0 | P19: =P18+O19 -> 0 | ... BP19: =BP18+BO19 -> 61
F20: Apt - Occ. % | I20: =I19/$K$3 -> 0 | J20: =J19/$K$3 -> 0 | K20: =K19/$K$3 -> 0 | L20: =L19/$K$3 -> 0 | M20: =M19/$K$3 -> 0 | N20: =N19/$K$3 -> 0 | O20: =O19/$K$3 -> 0 | P20: =P19/$K$3 -> 0 | ... BP20: =BP19/$K$3 -> 1
F21: Share of Exp. | I21: =IF(I15<$Q$9,0,IF(I15<=$R$9,$T$9,IF(I15<=$R$10,$T$10,100%))) -> 0 | J21: =IF(J15<$Q$9,0,IF(J15<=$R$9,$T$9,IF(J15<=$R$10,$T$10,100%))) -> 0 | K21: =IF(K15<$Q$9,0,IF(K15<=$R$9,$T$9,IF(K15<=$R$10,$T$10,100%))) -> 0 | L21: =IF(L15<$Q$9,0,IF(L15<=$R$9,$T$9,IF(L15<=$R$10,$T$10,100%))) -> 0 | M21: =IF(M15<$Q$9,0,IF(M15<=$R$9,$T$9,IF(M15<=$R$10,$T$10,100%))) -> 0 | N21: =IF(N15<$Q$9,0,IF(N15<=$R$9,$T$9,IF(N15<=$R$10,$T$10,100%))) -> 0 | O21: =IF(O15<$Q$9,0,IF(O15<=$R$9,$T$9,IF(O15<=$R$10,$T$10,100%))) -> 0 | P21: =IF(P15<$Q$9,0,IF(P15<=$R$9,$T$9,IF(P15<=$R$10,$T$10,100%))) -> 0 | ... BP21: =IF(BP15<$Q$9,0,IF(BP15<=$R$9,$T$9,IF(BP15<=$R$10,$T$10,100%))) -> 1
F22: REVENUES | G22: Growth % | H22: Per Unit
F23: Rental Income | G23: 0.03 | H23: =L3 -> 3288 | I23: =(H$19*$H23)*((1+$G23)^I$14) -> 0 | J23: =(I$19*$H23)*((1+$G23)^J$14) -> 0 | K23: =(J$19*$H23)*((1+$G23)^K$14) -> 0 | L23: =(K$19*$H23)*((1+$G23)^L$14) -> 0 | M23: =(L$19*$H23)*((1+$G23)^M$14) -> 0 | N23: =(M$19*$H23)*((1+$G23)^N$14) -> 0 | O23: =(N$19*$H23)*((1+$G23)^O$14) -> 0 | P23: =(O$19*$H23)*((1+$G23)^P$14) -> 0 | ... BP23: =(BO$19*$H23)*((1+$G23)^BP$14) -> 232513.28
F24: Parking | G24: 0.03 | H24: =N7/K7 -> 120 | I24: =(($H24/12)*I$20)*((1+$G24)^I$14)*$K$3 -> 0 | J24: =(($H24/12)*J$20)*((1+$G24)^J$14)*$K$3 -> 0 | K24: =(($H24/12)*K$20)*((1+$G24)^K$14)*$K$3 -> 0 | L24: =(($H24/12)*L$20)*((1+$G24)^L$14)*$K$3 -> 0 | M24: =(($H24/12)*M$20)*((1+$G24)^M$14)*$K$3 -> 0 | N24: =(($H24/12)*N$20)*((1+$G24)^N$14)*$K$3 -> 0 | O24: =(($H24/12)*O$20)*((1+$G24)^O$14)*$K$3 -> 0 | P24: =(($H24/12)*P$20)*((1+$G24)^P$14)*$K$3 -> 0 | ... BP24: =(($H24/12)*BP$20)*((1+$G24)^BP$14)*$K$3 -> 707.15719
F25: Other Services | G25: 0.03 | H25: =N8/K8 -> 80 | I25: =(($H25/12)*I$20)*((1+$G25)^I$14)*$K$3 -> 0 | J25: =(($H25/12)*J$20)*((1+$G25)^J$14)*$K$3 -> 0 | K25: =(($H25/12)*K$20)*((1+$G25)^K$14)*$K$3 -> 0 | L25: =(($H25/12)*L$20)*((1+$G25)^L$14)*$K$3 -> 0 | M25: =(($H25/12)*M$20)*((1+$G25)^M$14)*$K$3 -> 0 | N25: =(($H25/12)*N$20)*((1+$G25)^N$14)*$K$3 -> 0 | O25: =(($H25/12)*O$20)*((1+$G25)^O$14)*$K$3 -> 0 | P25: =(($H25/12)*P$20)*((1+$G25)^P$14)*$K$3 -> 0 | ... BP25: =(($H25/12)*BP$20)*((1+$G25)^BP$14)*$K$3 -> 471.43812
F26: Premiums | G26: 0.03 | H26: =N9/K9 -> 0 | I26: =(($H26/12)*I$20)*((1+$G26)^I$14)*$K$3 -> 0 | J26: =(($H26/12)*J$20)*((1+$G26)^J$14)*$K$3 -> 0 | K26: =(($H26/12)*K$20)*((1+$G26)^K$14)*$K$3 -> 0 | L26: =(($H26/12)*L$20)*((1+$G26)^L$14)*$K$3 -> 0 | M26: =(($H26/12)*M$20)*((1+$G26)^M$14)*$K$3 -> 0 | N26: =(($H26/12)*N$20)*((1+$G26)^N$14)*$K$3 -> 0 | O26: =(($H26/12)*O$20)*((1+$G26)^O$14)*$K$3 -> 0 | P26: =(($H26/12)*P$20)*((1+$G26)^P$14)*$K$3 -> 0 | ... BP26: =(($H26/12)*BP$20)*((1+$G26)^BP$14)*$K$3 -> 0
F27: Gross Pot. Rev. | I27: =SUM(I23:I26) -> 0 | J27: =SUM(J23:J26) -> 0 | K27: =SUM(K23:K26) -> 0 | L27: =SUM(L23:L26) -> 0 | M27: =SUM(M23:M26) -> 0 | N27: =SUM(N23:N26) -> 0 | O27: =SUM(O23:O26) -> 0 | P27: =SUM(P23:P26) -> 0 | ... BP27: =SUM(BP23:BP26) -> 233691.88
F28: Less: Ls-Up Conc. | H28: =-K10 -> -0.01 | I28: =I23*$H$28 -> 0 | J28: =J23*$H$28 -> 0 | K28: =K23*$H$28 -> 0 | L28: =L23*$H$28 -> 0 | M28: =M23*$H$28 -> 0 | N28: =N23*$H$28 -> 0 | O28: =O23*$H$28 -> 0 | P28: =P23*$H$28 -> 0 | ... BP28: =BP23*$H$28 -> -2325.1328
F29: Less: Bad Debt | H29: -0.005 | I29: =I$27*$H29 -> 0 | J29: =J$27*$H29 -> 0 | K29: =K$27*$H29 -> 0 | L29: =L$27*$H29 -> 0 | M29: =M$27*$H29 -> 0 | N29: =N$27*$H29 -> 0 | O29: =O$27*$H29 -> 0 | P29: =P$27*$H29 -> 0 | ... BP29: =BP$27*$H29 -> -1168.4594
F30: Less: Apt Vac. | H30: -0.05 | I30: =I$27*$H30 -> 0 | J30: =J$27*$H30 -> 0 | K30: =K$27*$H30 -> 0 | L30: =L$27*$H30 -> 0 | M30: =M$27*$H30 -> 0 | N30: =N$27*$H30 -> 0 | O30: =O$27*$H30 -> 0 | P30: =P$27*$H30 -> 0 | ... BP30: =BP$27*$H30 -> -11684.594
F31: Eff. Gross Income | I31: =SUM(I27:I30) -> 0 | J31: =SUM(J27:J30) -> 0 | K31: =SUM(K27:K30) -> 0 | L31: =SUM(L27:L30) -> 0 | M31: =SUM(M27:M30) -> 0 | N31: =SUM(N27:N30) -> 0 | O31: =SUM(O27:O30) -> 0 | P31: =SUM(P27:P30) -> 0 | ... BP31: =SUM(BP27:BP30) -> 218513.69
F32: EXPENSES | G32: Growth % | H32: Per Unit
F33: Real Estate Taxes | G33: 0.03 | H33: 2995 | I33: =(($H33/12)*I$21)*((1+$G33)^I$14)*$K$3 -> 0 | J33: =(($H33/12)*J$21)*((1+$G33)^J$14)*$K$3 -> 0 | K33: =(($H33/12)*K$21)*((1+$G33)^K$14)*$K$3 -> 0 | L33: =(($H33/12)*L$21)*((1+$G33)^L$14)*$K$3 -> 0 | M33: =(($H33/12)*M$21)*((1+$G33)^M$14)*$K$3 -> 0 | N33: =(($H33/12)*N$21)*((1+$G33)^N$14)*$K$3 -> 0 | O33: =(($H33/12)*O$21)*((1+$G33)^O$14)*$K$3 -> 0 | P33: =(($H33/12)*P$21)*((1+$G33)^P$14)*$K$3 -> 0 | ... BP33: =(($H33/12)*BP$21)*((1+$G33)^BP$14)*$K$3 -> 17649.465
F34: Insurance | G34: 0.03 | H34: 900 | I34: =(($H34/12)*I$21)*((1+$G34)^I$14)*$K$3 -> 0 | J34: =(($H34/12)*J$21)*((1+$G34)^J$14)*$K$3 -> 0 | K34: =(($H34/12)*K$21)*((1+$G34)^K$14)*$K$3 -> 0 | L34: =(($H34/12)*L$21)*((1+$G34)^L$14)*$K$3 -> 0 | M34: =(($H34/12)*M$21)*((1+$G34)^M$14)*$K$3 -> 0 | N34: =(($H34/12)*N$21)*((1+$G34)^N$14)*$K$3 -> 0 | O34: =(($H34/12)*O$21)*((1+$G34)^O$14)*$K$3 -> 0 | P34: =(($H34/12)*P$21)*((1+$G34)^P$14)*$K$3 -> 0 | ... BP34: =(($H34/12)*BP$21)*((1+$G34)^BP$14)*$K$3 -> 5303.6789
F35: Utilities | G35: 0.03 | H35: 668 | I35: =(($H35/12)*I$21)*((1+$G35)^I$14)*$K$3 -> 0 | J35: =(($H35/12)*J$21)*((1+$G35)^J$14)*$K$3 -> 0 | K35: =(($H35/12)*K$21)*((1+$G35)^K$14)*$K$3 -> 0 | L35: =(($H35/12)*L$21)*((1+$G35)^L$14)*$K$3 -> 0 | M35: =(($H35/12)*M$21)*((1+$G35)^M$14)*$K$3 -> 0 | N35: =(($H35/12)*N$21)*((1+$G35)^N$14)*$K$3 -> 0 | O35: =(($H35/12)*O$21)*((1+$G35)^O$14)*$K$3 -> 0 | P35: =(($H35/12)*P$21)*((1+$G35)^P$14)*$K$3 -> 0 | ... BP35: =(($H35/12)*BP$21)*((1+$G35)^BP$14)*$K$3 -> 3936.5083
F36: Repairs & Maint. | G36: 0.03 | H36: 829 | I36: =(($H36/12)*I$21)*((1+$G36)^I$14)*$K$3 -> 0 | J36: =(($H36/12)*J$21)*((1+$G36)^J$14)*$K$3 -> 0 | K36: =(($H36/12)*K$21)*((1+$G36)^K$14)*$K$3 -> 0 | L36: =(($H36/12)*L$21)*((1+$G36)^L$14)*$K$3 -> 0 | M36: =(($H36/12)*M$21)*((1+$G36)^M$14)*$K$3 -> 0 | N36: =(($H36/12)*N$21)*((1+$G36)^N$14)*$K$3 -> 0 | O36: =(($H36/12)*O$21)*((1+$G36)^O$14)*$K$3 -> 0 | P36: =(($H36/12)*P$21)*((1+$G36)^P$14)*$K$3 -> 0 | ... BP36: =(($H36/12)*BP$21)*((1+$G36)^BP$14)*$K$3 -> 4885.2776
F37: Mgt. Fee | H37: 0.0275 | I37: =$H37*I31 -> 0 | J37: =$H37*J31 -> 0 | K37: =$H37*K31 -> 0 | L37: =$H37*L31 -> 0 | M37: =$H37*M31 -> 0 | N37: =$H37*N31 -> 0 | O37: =$H37*O31 -> 0 | P37: =$H37*P31 -> 0 | ... BP37: =$H37*BP31 -> 6009.1265
F38: Payroll & Benefits | G38: 0.03 | H38: 1800 | I38: =(($H38/12)*I$21)*((1+$G38)^I$14)*$K$3 -> 0 | J38: =(($H38/12)*J$21)*((1+$G38)^J$14)*$K$3 -> 0 | K38: =(($H38/12)*K$21)*((1+$G38)^K$14)*$K$3 -> 0 | L38: =(($H38/12)*L$21)*((1+$G38)^L$14)*$K$3 -> 0 | M38: =(($H38/12)*M$21)*((1+$G38)^M$14)*$K$3 -> 0 | N38: =(($H38/12)*N$21)*((1+$G38)^N$14)*$K$3 -> 0 | O38: =(($H38/12)*O$21)*((1+$G38)^O$14)*$K$3 -> 0 | P38: =(($H38/12)*P$21)*((1+$G38)^P$14)*$K$3 -> 0 | ... BP38: =(($H38/12)*BP$21)*((1+$G38)^BP$14)*$K$3 -> 10607.358
F39: Advertis. & Mktg | G39: 0.03 | H39: 346 | I39: =(($H39/12)*I$21)*((1+$G39)^I$14)*$K$3 -> 0 | J39: =(($H39/12)*J$21)*((1+$G39)^J$14)*$K$3 -> 0 | K39: =(($H39/12)*K$21)*((1+$G39)^K$14)*$K$3 -> 0 | L39: =(($H39/12)*L$21)*((1+$G39)^L$14)*$K$3 -> 0 | M39: =(($H39/12)*M$21)*((1+$G39)^M$14)*$K$3 -> 0 | N39: =(($H39/12)*N$21)*((1+$G39)^N$14)*$K$3 -> 0 | O39: =(($H39/12)*O$21)*((1+$G39)^O$14)*$K$3 -> 0 | P39: =(($H39/12)*P$21)*((1+$G39)^P$14)*$K$3 -> 0 | ... BP39: =(($H39/12)*BP$21)*((1+$G39)^BP$14)*$K$3 -> 2038.9699
F40: Rental Expense | G40: 0.03 | H40: 0 | I40: =(($H40/12)*I$21)*((1+$G40)^I$14)*$K$3 -> 0 | J40: =(($H40/12)*J$21)*((1+$G40)^J$14)*$K$3 -> 0 | K40: =(($H40/12)*K$21)*((1+$G40)^K$14)*$K$3 -> 0 | L40: =(($H40/12)*L$21)*((1+$G40)^L$14)*$K$3 -> 0 | M40: =(($H40/12)*M$21)*((1+$G40)^M$14)*$K$3 -> 0 | N40: =(($H40/12)*N$21)*((1+$G40)^N$14)*$K$3 -> 0 | O40: =(($H40/12)*O$21)*((1+$G40)^O$14)*$K$3 -> 0 | P40: =(($H40/12)*P$21)*((1+$G40)^P$14)*$K$3 -> 0 | ... BP40: =(($H40/12)*BP$21)*((1+$G40)^BP$14)*$K$3 -> 0
F41: General & Admin. | G41: 0.03 | H41: 346 | I41: =(($H41/12)*I$21)*((1+$G41)^I$14)*$K$3 -> 0 | J41: =(($H41/12)*J$21)*((1+$G41)^J$14)*$K$3 -> 0 | K41: =(($H41/12)*K$21)*((1+$G41)^K$14)*$K$3 -> 0 | L41: =(($H41/12)*L$21)*((1+$G41)^L$14)*$K$3 -> 0 | M41: =(($H41/12)*M$21)*((1+$G41)^M$14)*$K$3 -> 0 | N41: =(($H41/12)*N$21)*((1+$G41)^N$14)*$K$3 -> 0 | O41: =(($H41/12)*O$21)*((1+$G41)^O$14)*$K$3 -> 0 | P41: =(($H41/12)*P$21)*((1+$G41)^P$14)*$K$3 -> 0 | ... BP41: =(($H41/12)*BP$21)*((1+$G41)^BP$14)*$K$3 -> 2038.9699
...

Sheet Waterfall
B1: Waterfall Structure (IRR) | C1: Return | D1: GP Promote | E1: GP Cash Flow | F1: LP Cash Flow | H1: Return Metrics | K1: Sale Date | L1: =EDATE(Draws!G9,1) -> 46692
B2: Preferred Return | C2: 0.1 | E2: =+GPEQUITY -> 0.1 | F2: =+LPEQUITY -> 0.9 | H2: Project-Level IRR | I2: =IFERROR(XIRR(C34:BK34,C12:BK12),0) -> 0.19440213
B3: Hurdle #2 | C3: 0.15 | D3: 0.2 | E3: =$C$8+D3*$C$9 -> 0.28 | F3: =1-E3 -> 0.72 | H3: Project-Level EM | I3: =IFERROR(SUMIF(C34:BK34,">"&0,C34:BK34)/-SUMIF(C34:BK34,"<"&0,C34:BK34),0) -> 1.6338192
B4: Hurdle #3 | C4: 0.18 | D4: 0.3 | E4: =$C$8+D4*$C$9 -> 0.37 | F4: =1-E4 -> 0.63 | H4: LP IRR | I4: =C96 -> 0.17335182
B5: Hurdle #4 | D5: 0.4 | E5: =$C$8+D5*$C$9 -> 0.46 | F5: =1-E5 -> 0.54 | H5: LP EM | I5: =C97 -> 1.5550746
H6: GP IRR | I6: =C103 -> 0.35911848
B7: Equity Investment | H7: GP EM | I7: =C104 -> 2.3425207
B8: GP Equity | C8: 0.1 | D8: =GPEQUITY*SUM($C$14:$BK$14) -> 840000 | H8: GP Promote | I8: =C110 -> 661454.78
B9: LP Equity | C9: =1-C8 -> 0.9 | D9: =LPEQUITY*SUM($C$14:$BK$14) -> 7560000
C11: 0 | D11: =C11+1 -> 1 | E11: =D11+1 -> 2 | F11: =E11+1 -> 3 | G11: =F11+1 -> 4 | H11: =G11+1 -> 5 | I11: =H11+1 -> 6 | J11: =I11+1 -> 7 | K11: =J11+1 -> 8 | ... BK11: =BJ11+1 -> 60
B12: Total Project-Level Cash Flows | C12: =EOMONTH(Draws!H10,0) -> 45596 | D12: =EOMONTH(C12,1) -> 45626 | E12: =EOMONTH(D12,1) -> 45657 | F12: =EOMONTH(E12,1) -> 45688 | G12: =EOMONTH(F12,1) -> 45716 | H12: =EOMONTH(G12,1) -> 45747 | I12: =EOMONTH(H12,1) -> 45777 | J12: =EOMONTH(I12,1) -> 45808 | K12: =EOMONTH(J12,1) -> 45838 | ... BK12: =EOMONTH(BJ12,1) -> 47422
B14: =Draws!C15 -> Equity | C14: =IF(C$11>Draws!$F$9,0,Draws!H15) -> 5309435 | D14: =IF(D$11>Draws!$F$9,0,Draws!I15) -> 33333.333 | E14: =IF(E$11>Draws!$F$9,0,Draws!J15) -> 33333.333 | F14: =IF(F$11>Draws!$F$9,0,Draws!K15) -> 33333.333 | G14: =IF(G$11>Draws!$F$9,0,Draws!L15) -> 33333.333 | H14: =IF(H$11>Draws!$F$9,0,Draws!M15) -> 33333.333 | I14: =IF(I$11>Draws!$F$9,0,Draws!N15) -> 33333.333 | J14: =IF(J$11>Draws!$F$9,0,Draws!O15) -> 1249529.6 | ... BK14: =IF(BK$11>Draws!$F$9,0,Draws!BP15) -> 0
B15: =Draws!C14 -> Senior Debt | C15: =IF(C$11>Draws!$F$9,0,Draws!H14) -> 0 | D15: =IF(D$11>Draws!$F$9,0,Draws!I14) -> 0 | E15: =IF(E$11>Draws!$F$9,0,Draws!J14) -> 0 | F15: =IF(F$11>Draws!$F$9,0,Draws!K14) -> 0 | G15: =IF(G$11>Draws!$F$9,0,Draws!L14) -> 0 | H15: =IF(H$11>Draws!$F$9,0,Draws!M14) -> 0 | I15: =IF(I$11>Draws!$F$9,0,Draws!N14) -> 0 | J15: =IF(J$11>Draws!$F$9,0,Draws!O14) -> 0 | ... BK15: =IF(BK$11>Draws!$F$9,0,Draws!BP14) -> 0
B17: ='Lease Up'!F31 -> Eff. Gross Income | D17: =IF(D$11>Draws!$F$9,0,'Lease Up'!I31) -> 0 | E17: =IF(E$11>Draws!$F$9,0,'Lease Up'!J31) -> 0 | F17: =IF(F$11>Draws!$F$9,0,'Lease Up'!K31) -> 0 | G17: =IF(G$11>Draws!$F$9,0,'Lease Up'!L31) -> 0 | H17: =IF(H$11>Draws!$F$9,0,'Lease Up'!M31) -> 0 | I17: =IF(I$11>Draws!$F$9,0,'Lease Up'!N31) -> 0 | J17: =IF(J$11>Draws!$F$9,0,'Lease Up'!O31) -> 0 | K17: =IF(K$11>Draws!$F$9,0,'Lease Up'!P31) -> 0 | ... BK17: =IF(BK$11>Draws!$F$9,0,'Lease Up'!BP31) -> 0
B18: ='Lease Up'!F43 -> Total Expenses | D18: =IF(D$11>Draws!$F$9,0,'Lease Up'!I43) -> 0 | E18: =IF(E$11>Draws!$F$9,0,'Lease Up'!J43) -> 0 | F18: =IF(F$11>Draws!$F$9,0,'Lease Up'!K43) -> 0 | G18: =IF(G$11>Draws!$F$9,0,'Lease Up'!L43) -> 0 | H18: =IF(H$11>Draws!$F$9,0,'Lease Up'!M43) -> 0 | I18: =IF(I$11>Draws!$F$9,0,'Lease Up'!N43) -> 0 | J18: =IF(J$11>Draws!$F$9,0,'Lease Up'!O43) -> 0 | K18: =IF(K$11>Draws!$F$9,0,'Lease Up'!P43) -> 0 | ... BK18: =IF(BK$11>Draws!$F$9,0,'Lease Up'!BP43) -> 0
B19: NOI | C19: =C17-C18 -> 0 | D19: =D17-D18 -> 0 | E19: =E17-E18 -> 0 | F19: =F17-F18 -> 0 | G19: =G17-G18 -> 0 | H19: =H17-H18 -> 0 | I19: =I17-I18 -> 0 | J19: =J17-J18 -> 0 | ... BK19: =BK17-BK18 -> 0
B20: Expense Ratio | C20: =IFERROR(C18/C17," ") | D20: =IFERROR(D18/D17," ") | E20: =IFERROR(E18/E17," ") | F20: =IFERROR(F18/F17," ") | G20: =IFERROR(G18/G17," ") | H20: =IFERROR(H18/H17," ") | I20: =IFERROR(I18/I17," ") | J20: =IFERROR(J18/J17," ") | ... BK20: =IFERROR(BK18/BK17," ")
AA21: =AA22-Z22 -> 117.11817
B22: ='Lease Up'!F47 -> Debt Service | D22: ='Lease Up'!I47 -> 0 | E22: ='Lease Up'!J47 -> 0 | F22: ='Lease Up'!K47 -> 0 | G22: ='Lease Up'!L47 -> 0 | H22: ='Lease Up'!M47 -> 0 | I22: ='Lease Up'!N47 -> 0 | J22: ='Lease Up'!O47 -> 0 | K22: ='Lease Up'!P47 -> 0 | ... AA22: ='Lease Up'!AF47 -> 97470.404 | AB22: =AA22+AA21 -> 97587.522 | AC22: =AB22 -> 97587.522 | AD22: =AC22 -> 97587.522 | AE22: =AD22 -> 97587.522 | AF22: =AE22 -> 97587.522 | AG22: =AF22 -> 97587.522 | AH22: =AG22 -> 97587.522 | AI22: =AH22 -> 97587.522 | AJ22: =AI22 -> 97587.522 | ... AM22: =AL22 -> 97587.522 | AN22: ='Lease Up'!AS47 -> 0 | AO22: ='Lease Up'!AT47 -> 0 | AP22: ='Lease Up'!AU47 -> 0 | AQ22: ='Lease Up'!AV47 -> 0 | AR22: ='Lease Up'!AW47 -> 0 | AS22: ='Lease Up'!AX47 -> 0 | AT22: ='Lease Up'!AY47 -> 0 | AU22: ='Lease Up'!AZ47 -> 0 | ... BK22: ='Lease Up'!BP47 -> 0
B23: DSCR | D23: =IFERROR(MAX(D19,0)/D22," ") | E23: =IFERROR(MAX(E19,0)/E22," ") | F23: =IFERROR(MAX(F19,0)/F22," ") | G23: =IFERROR(MAX(G19,0)/G22," ") | H23: =IFERROR(MAX(H19,0)/H22," ") | I23: =IFERROR(MAX(I19,0)/I22," ") | J23: =IFERROR(MAX(J19,0)/J22," ") | K23: =IFERROR(MAX(K19,0)/K22," ") | ... BK23: =IFERROR(MAX(BK19,0)/BK22," ")
B25: Cashflow After Debt Service | C25: =C19-C22 -> 0 | D25: =D19-D22 -> 0 | E25: =E19-E22 -> 0 | F25: =F19-F22 -> 0 | G25: =G19-G22 -> 0 | H25: =H19-H22 -> 0 | I25: =I19-I22 -> 0 | J25: =J19-J22 -> 0 | ... BK25: =BK19-BK22 -> 0
B27: ='Lease Up'!F45 -> Replacement Rsv | D27: =IF(D$11>Draws!$F$9,0,'Lease Up'!I45) -> 0 | E27: =IF(E$11>Draws!$F$9,0,'Lease Up'!J45) -> 0 | F27: =IF(F$11>Draws!$F$9,0,'Lease Up'!K45) -> 0 | G27: =IF(G$11>Draws!$F$9,0,'Lease Up'!L45) -> 0 | H27: =IF(H$11>Draws!$F$9,0,'Lease Up'!M45) -> 0 | I27: =IF(I$11>Draws!$F$9,0,'Lease Up'!N45) -> 0 | J27: =IF(J$11>Draws!$F$9,0,'Lease Up'!O45) -> 0 | K27: =IF(K$11>Draws!$F$9,0,'Lease Up'!P45) -> 0 | ... BK27: =IF(BK$11>Draws!$F$9,0,'Lease Up'!BP45) -> 0
B29: Cashflow from Property After Rsv. | C29: =C25-C27 -> 0 | D29: =D25-D27 -> 0 | E29: =E25-E27 -> 0 | F29: =F25-F27 -> 0 | G29: =G25-G27 -> 0 | H29: =H25-H27 -> 0 | I29: =I25-I27 -> 0 | J29: =J25-J27 -> 0 | ... BK29: =BK25-BK27 -> 0
B31: =Draws!C55 -> Sale Price | C31: =Draws!H55 -> 0 | D31: =Draws!I55 -> 0 | E31: =Draws!J55 -> 0 | F31: =Draws!K55 -> 0 | G31: =Draws!L55 -> 0 | H31: =Draws!M55 -> 0 | I31: =Draws!N55 -> 0 | J31: =Draws!O55 -> 0 | ... BK31: =Draws!BP55 -> 0
B32: =Draws!C56 -> Less: Debt | C32: =Draws!H56 -> 0 | D32: =Draws!I56 -> 0 | E32: =Draws!J56 -> 0 | F32: =Draws!K56 -> 0 | G32: =Draws!L56 -> 0 | H32: =Draws!M56 -> 0 | I32: =Draws!N56 -> 0 | J32: =Draws!O56 -> 0 | ... BK32: =Draws!BP56 -> 0
B34: Net Cashflow from Investment | C34: =MAX(C29+C31+C32,0)-C14 -> -5309435 | D34: =MAX(D29+D31+D32,0)-D14 -> -33333.333 | E34: =MAX(E29+E31+E32,0)-E14 -> -33333.333 | F34: =MAX(F29+F31+F32,0)-F14 -> -33333.333 | G34: =MAX(G29+G31+G32,0)-G14 -> -33333.333 | H34: =MAX(H29+H31+H32,0)-H14 -> -33333.333 | I34: =MAX(I29+I31+I32,0)-I14 -> -33333.333 | J34: =MAX(J29+J31+J32,0)-J14 -> -1249529.6 | ... BK34: =MAX(BK29+BK31+BK32,0)-BK14 -> 0
B35: Property IRR | C35: =XIRR(C34:BK34,C12:BK12) -> 0.19440213
B36: Property Equity Multiple | C36: =(SUM(C34:BK34)+D8+D9)/(D8+D9) -> 1.6338192
B37: Cash on Cash | C37: =(SUM(D37:BK37)/Draws!F9) -> 0.045383866 | D37: =MAX(D34,0)/($D$8+$D$9) -> 0 | E37: =MAX(E34,0)/($D$8+$D$9) -> 0 | F37: =MAX(F34,0)/($D$8+$D$9) -> 0 | G37: =MAX(G34,0)/($D$8+$D$9) -> 0 | H37: =MAX(H34,0)/($D$8+$D$9) -> 0 | I37: =MAX(I34,0)/($D$8+$D$9) -> 0 | J37: =MAX(J34,0)/($D$8+$D$9) -> 0 | K37: =MAX(K34,0)/($D$8+$D$9) -> 0 | ... BK37: =MAX(BK34,0)/($D$8+$D$9) -> 0
B38: Net Return | C38: =SUM(C34:BK34) -> 5324081.1
B40: Equity Contributions
B41: GP Contributions | C41: =C34*GPEQUITY -> -530943.5 | D41: =IF(D34<0,D34*GPEQUITY,0) -> -3333.3333 | E41: =IF(E34<0,E34*GPEQUITY,0) -> -3333.3333 | F41: =IF(F34<0,F34*GPEQUITY,0) -> -3333.3333 | G41: =IF(G34<0,G34*GPEQUITY,0) -> -3333.3333 | H41: =IF(H34<0,H34*GPEQUITY,0) -> -3333.3333 | I41: =IF(I34<0,I34*GPEQUITY,0) -> -3333.3333 | J41: =IF(J34<0,J34*GPEQUITY,0) -> -124952.96 | K41: =IF(K34<0,K34*GPEQUITY,0) -> -124952.96 | ... BK41: =IF(BK34<0,BK34*GPEQUITY,0) -> 0
B42: LP Contributions | C42: =C34*LPEQUITY -> -4778491.5 | D42: =IF(D34<0,D34*LPEQUITY,0) -> -30000 | E42: =IF(E34<0,E34*LPEQUITY,0) -> -30000 | F42: =IF(F34<0,F34*LPEQUITY,0) -> -30000 | G42: =IF(G34<0,G34*LPEQUITY,0) -> -30000 | H42: =IF(H34<0,H34*LPEQUITY,0) -> -30000 | I42: =IF(I34<0,I34*LPEQUITY,0) -> -30000 | J42: =IF(J34<0,J34*LPEQUITY,0) -> -1124576.7 | K42: =IF(K34<0,K34*LPEQUITY,0) -> -1124576.7 | ... BK42: =IF(BK34<0,BK34*LPEQUITY,0) -> 0
B44: Preferred Return
B45: Beginning Balance | C45: 0 | D45: =IF(D12>SALEMONTH,0,C49) -> 4778491.5 | E45: =IF(E12>SALEMONTH,0,D49) -> 4846071.8 | F45: =IF(F12>SALEMONTH,0,E49) -> 4915459.2 | G45: =IF(G12>SALEMONTH,0,F49) -> 4985410.5 | H45: =IF(H12>SALEMONTH,0,G49) -> 5051994.8 | I45: =IF(I12>SALEMONTH,0,H49) -> 5123055.8 | J45: =IF(J12>SALEMONTH,0,I49) -> 5193346 | K45: =IF(K12>SALEMONTH,0,J49) -> 6360132.5 | ... AL45: =IF(AL12>SALEMONTH,0,AK49) -> 9249641.2 | AM45: =IF(AM12>SALEMONTH+1,0,AL49) -> 9270352 | AN45: =IF(AN12>SALEMONTH,0,AM49) -> 0 | AO45: =IF(AO12>SALEMONTH,0,AN49) -> 0 | AP45: =IF(AP12>SALEMONTH,0,AO49) -> 0 | AQ45: =IF(AQ12>SALEMONTH,0,AP49) -> 0 | AR45: =IF(AR12>SALEMONTH,0,AQ49) -> 0 | AS45: =IF(AS12>SALEMONTH,0,AR49) -> 0 | AT45: =IF(AT12>SALEMONTH,0,AS49) -> 0 | AU45: =IF(AU12>SALEMONTH,0,AT49) -> 0 | ... BK45: =IF(BK12>SALEMONTH,0,BJ49) -> 0
B46: Preferred Interest Accrual | C46: 0 | D46: =D45*(1+PREF)^((D12-C12)/365)-D45 -> 37580.338 | E46: =E45*(1+PREF)^((E12-D12)/365)-E45 -> 39387.365 | F46: =F45*(1+PREF)^((F12-E12)/365)-F45 -> 39951.324 | G46: =G45*(1+PREF)^((G12-F12)/365)-G45 -> 36584.238 | H46: =H45*(1+PREF)^((H12-G12)/365)-H45 -> 41061.042 | I46: =I45*(1+PREF)^((I12-H12)/365)-I45 -> 40290.156 | J46: =J45*(1+PREF)^((J12-I12)/365)-J45 -> 42209.901 | K46: =K45*(1+PREF)^((K12-J12)/365)-K45 -> 50019.117 | ... BK46: =BK45*(1+PREF)^((BK12-BJ12)/365)-BK45 -> 0
B47: LP Contributions | C47: =-C42 -> 4778491.5 | D47: =-D42 -> 30000 | E47: =-E42 -> 30000 | F47: =-F42 -> 30000 | G47: =-G42 -> 30000 | H47: =-H42 -> 30000 | I47: =-I42 -> 30000 | J47: =-J42 -> 1124576.7 | ... BK47: =-BK42 -> 0
B48: LP Distributions | C48: =MIN(C45+C46,MAX(C34,0)*LPEQUITY) -> 0 | D48: =MIN(D45+D46,MAX(D34,0)*LPEQUITY) -> 0 | E48: =MIN(E45+E46,MAX(E34,0)*LPEQUITY) -> 0 | F48: =MIN(F45+F46,MAX(F34,0)*LPEQUITY) -> 0 | G48: =MIN(G45+G46,MAX(G34,0)*LPEQUITY) -> 0 | H48: =MIN(H45+H46,MAX(H34,0)*LPEQUITY) -> 0 | I48: =MIN(I45+I46,MAX(I34,0)*LPEQUITY) -> 0 | J48: =MIN(J45+J46,MAX(J34,0)*LPEQUITY) -> 0 | ... BK48: =MIN(BK45+BK46,MAX(BK34,0)*LPEQUITY) -> 0
A49: IRR | B49: Ending Balance | C49: =C45+C46+C47-C48 -> 4778491.5 | D49: =D45+D46+D47-D48 -> 4846071.8 | E49: =E45+E46+E47-E48 -> 4915459.2 | F49: =F45+F46+F47-F48 -> 4985410.5 | G49: =G45+G46+G47-G48 -> 5051994.8 | H49: =H45+H46+H47-H48 -> 5123055.8 | I49: =I45+I46+I47-I48 -> 5193346 | J49: =J45+J46+J47-J48 -> 6360132.5 | ... BK49: =BK45+BK46+BK47-BK48 -> 0
A50: =IFERROR(XIRR(C50:BK50,$C$12:$BK$12),0) -> 0.10000001 | B50: Total LP Cash Flow | C50: =C48-C47 -> -4778491.5 | D50: =D48-D47 -> -30000 | E50: =E48-E47 -> -30000 | F50: =F48-F47 -> -30000 | G50: =G48-G47 -> -30000 | H50: =H48-H47 -> -30000 | I50: =I48-I47 -> -30000 | J50: =J48-J47 -> -1124576.7 | ... BK50: =BK48-BK47 -> 0
...

Sheet Unit Mix
B1: Multifamily
B2: Market Rate
B3: Unit Type | C3: No. of Units | D3: SF | E3: Rent /mo. | F3: Rent PSF | G3: Annual Rent | H3: Tot SF | I3: W/Conc | J3: Concession/yr
B4: 1 BD / 1 BA | C4: 10 | D4: 740 | E4: ='Rent Comps'!S23 -> 2315 | F4: =IF(C4=0,0,E4/D4) -> 3.1283784 | G4: =C4*E4*12 -> 277800 | H4: =C4*D4 -> 7400 | I4: ='Rent Comps'!T23*'Unit Mix'!C4*12 -> 275030 | J4: =G4-I4 -> 2770 | K4: 23 | L4: =K4/$K$7 -> 0.19166667 | M4: =L4*$M$7 -> 11.691667 | N4: 12
B5: 2 BD / 2 BA | C5: 28 | D5: 1105 | E5: ='Rent Comps'!Z23 -> 3000.3333 | F5: =IF(C5=0,0,E5/D5) -> 2.7152338 | G5: =C5*E5*12 -> 1008112 | H5: =C5*D5 -> 30940 | I5: ='Rent Comps'!AA23*'Unit Mix'!C5*12 -> 999292 | J5: =G5-I5 -> 8820 | K5: 66 | L5: =K5/$K$7 -> 0.55 | M5: =L5*$M$7 -> 33.55 | N5: 33
B6: 3 BD / 2 BA | C6: 23 | D6: 1504 | E6: ='Rent Comps'!AG23 -> 4397.8889 | F6: =IF(C6=0,0,E6/D6) -> 2.9241283 | G6: =C6*E6*12 -> 1213817.3 | H6: =C6*D6 -> 34592 | I6: ='Rent Comps'!AH23*'Unit Mix'!C6*12 -> 1204218.7 | J6: =G6-I6 -> 9598.6667 | K6: 31 | L6: =K6/$K$7 -> 0.25833333 | M6: =L6*$M$7 -> 15.758333 | N6: 16
B7: Total/Average | C7: =SUM(C4:C6) -> 61 | D7: =IF(C7=0,0,SUMPRODUCT(C4:C6,D4:D6)/SUM(C4:C6)) -> 1195.6066 | E7: 3288 | F7: =IF(C7=0,0,E7/D7) -> 2.7500686 | G7: =SUM(G4:G6) -> 2499729.3 | H7: =SUM(H4:H6) -> 72932 | I7: =SUM(I4:I6) -> 2478540.7 | J7: =G7-I7 -> 21188.667 | K7: =SUM(K4:K6) -> 120 | M7: 61
E8: cell E7 controls rental rates
C9: # Units | E9: =C7 -> 61 | F9: 61
C10: Avg. SF | E10: =D7 -> 1195.6066 | F10: =D7 -> 1195.6066
C11: Avg. Rent/SF | E11: 2.75 | F11: 3
C12: Avg. Rent/Unit | E12: =(E9*E10*E11)/E9 -> 3287.918 | F12: =(F9*F10*F11)/F9 -> 3586.8197
B14: Rent Comps
B15: Unit Type | C15: No. of Units | D15: SF | E15: Rent /mo. | F15: Rent PSF | G15: Annual Rent | H15: Tot SF | I15: W/Conc | J15: Concession/yr
B16: 1 BD / 1 BA | C16: 10 | D16: ='Rent Comps'!R23 -> 800.41667 | E16: ='Rent Comps'!S23 -> 2315 | F16: =IF(C16=0,0,E16/D16) -> 2.8922436 | G16: =C16*E16*12 -> 277800 | H16: =C16*D16 -> 8004.1667 | I16: ='Rent Comps'!T30*'Unit Mix'!C16*12 -> 0 | J16: =G16-I16 -> 277800 | K16: 23 | L16: =K16/$K$7 -> 0.19166667 | M16: =L16*$M$7 -> 11.691667 | N16: 12
B17: 2 BD / 2 BA | C17: 28 | D17: ='Rent Comps'!Y23 -> 1169.5 | E17: ='Rent Comps'!Z23 -> 3000.3333 | F17: =IF(C17=0,0,E17/D17) -> 2.5654838 | G17: =C17*E17*12 -> 1008112 | H17: =C17*D17 -> 32746 | I17: ='Rent Comps'!AA30*'Unit Mix'!C17*12 -> 0 | J17: =G17-I17 -> 1008112 | K17: 66 | L17: =K17/$K$7 -> 0.55 | M17: =L17*$M$7 -> 33.55 | N17: 33
B18: 3 BD / 2 BA | C18: 23 | D18: ='Rent Comps'!AF23 -> 1565.3333 | E18: ='Rent Comps'!AG23 -> 4397.8889 | F18: =IF(C18=0,0,E18/D18) -> 2.8095542 | G18: =C18*E18*12 -> 1213817.3 | H18: =C18*D18 -> 36002.667 | I18: ='Rent Comps'!AH30*'Unit Mix'!C18*12 -> 0 | J18: =G18-I18 -> 1213817.3 | K18: 31 | L18: =K18/$K$7 -> 0.25833333 | M18: =L18*$M$7 -> 15.758333 | N18: 16
B19: Total/Average | C19: =SUM(C16:C18) -> 61 | D19: =IF(C19=0,0,SUMPRODUCT(C16:C18,D16:D18)/SUM(C16:C18)) -> 1258.2432 | E19: =IF(C19=0,0,G19/C19/12) -> 3414.9308 | F19: =IF(C19=0,0,E19/D19) -> 2.7140467 | G19: =SUM(G16:G18) -> 2499729.3 | H19: =SUM(H16:H18) -> 76752.833 | I19: =SUM(I16:I18) -> 0 | J19: =G19-I19 -> 2499729.3 | K19: =SUM(K16:K18) -> 120 | M19: 61
B23: Affordable
B24: Unit Type | C24: No. of Units | D24: Square Feet | E24: Rent | F24: Rent PSF | G24: Annual Rent
B25: 1 BD | C25: 0 | D25: 0 | E25: 0 | F25: =IF(C25=0,0,E25/D25) -> 0 | G25: =C25*E25*12 -> 0
B26: 1 BD + Den | C26: 0 | D26: 0 | E26: 0 | F26: =IF(C26=0,0,E26/D26) -> 0 | G26: =C26*E26*12 -> 0
B27: 2 BD / 2 BA | C27: 0 | D27: 0 | E27: 0 | F27: =IF(C27=0,0,E27/D27) -> 0 | G27: =C27*E27*12 -> 0
B28: 3 BD / 1 BA | C28: 0 | D28: 0 | E28: 0 | F28: =IF(C28=0,0,E28/D28) -> 0 | G28: =C28*E28*12 -> 0
B29: 3 BD / 2 BA | C29: 0 | D29: 0 | E29: 0 | F29: =IF(C29=0,0,E29/D29) -> 0 | G29: =C29*E29*12 -> 0
C30: 0 | D30: 0 | E30: 0 | F30: =IF(C30=0,0,E30/D30) -> 0 | G30: =C30*E30*12 -> 0
B31: Total/Average | C31: =SUM(C25:C30) -> 0 | D31: =IF(C31=0,0,SUMPRODUCT(C25:C30,D25:D30)/SUM(C25:C30)) -> 0 | E31: =IF(C31=0,0,G31/C31/12) -> 0 | F31: =IF(C31=0,0,E31/D31) -> 0 | G31: =SUM(G25:G30) -> 0
B33: Weighted Average
B34: Total/Average | C34: =+C31+C7 -> 61 | D34: =IF(C34=0,0,((C7*D7)+(C31*D31))/C34) -> 1195.6066 | E34: =IF(C34=0,0,G34/C34/12) -> 3414.9308 | F34: =IF(C34=0,0,E34/D34) -> 2.8562329 | G34: =+G31+G7 -> 2499729.3
B37: Commercial
B38: Type | C38: Status | D38: Suite | E38: Tenant | F38: Square Feet | G38: % of Total | H38: Rent PSF | I38: Annual Rent | J38: Annual Reimb. | K38: Lease Start | L38: Lease End | M38: Option
B39: Retail | C39: Leased | E39: Tenant 1 | F39: 0 | G39: =IF($F$46=0,0,F39/$F$46) -> 0 | H39: 0 | I39: =H39*F39 -> 0 | J39: 0 | K39: 43101 | L39: 43101
B40: Retail | C40: Vacant | E40: Tenant 2 | F40: 0 | G40: =IF($F$46=0,0,F40/$F$46) -> 0 | H40: 0 | I40: =H40*F40 -> 0 | J40: 0 | K40: 43101 | L40: 43102
B41: Retail | C41: Leased | E41: Tenant 3 | F41: 0 | G41: =IF($F$46=0,0,F41/$F$46) -> 0 | H41: 0 | I41: =H41*F41 -> 0 | J41: 0 | K41: 43101 | L41: 43103
B42: Retail | C42: Leased | E42: Tenant 4 | F42: 0 | G42: =IF($F$46=0,0,F42/$F$46) -> 0 | H42: 0 | I42: =H42*F42 -> 0 | J42: 0 | K42: 43101 | L42: 43103
B43: Retail | C43: Leased | E43: Tenant 5 | F43: 0 | G43: =IF($F$46=0,0,F43/$F$46) -> 0 | H43: 0 | I43: =H43*F43 -> 0 | J43: 0 | K43: 43101 | L43: 43103
B44: Office | C44: Vacant | E44: Tenant 6 | F44: 0 | G44: =IF($F$46=0,0,F44/$F$46) -> 0 | H44: 0 | I44: =H44*F44 -> 0 | J44: 0 | K44: 43101 | L44: 43106
B45: Office | C45: Vacant | E45: Tenant 7 | F45: 0 | G45: =IF($F$46=0,0,F45/$F$46) -> 0 | H45: 0 | I45: =H45*F45 -> 0 | J45: 0 | K45: 43101 | L45: 43107
B46: Total | F46: =SUM(F39:F45) -> 0 | G46: =SUM(G39:G45) -> 0 | H46: =IFERROR(I46/F46,0) -> 0 | I46: =SUM(I39:I45) -> 0 | J46: =SUM(J39:J45) -> 0
I47: Reimbursement Override | J47: 0
...

Sheet Forward Rate
B1: https://example.com/
D2: Loan Yrs | E2: 5
D3: Min.Index | E3: =MIN($E$6:BL6) -> 0.0371808 | G3: 1 | H3: 2 | I3: 3 | J3: 4 | K3: 5 | L3: 6 | M3: 7 | N3: 8 | O3: 9 | P3: 10 | Q3: 11 | R3: 12 | S3: 13 | T3: 14 | U3: 15 | V3: 16 | W3: 17 | X3: 18 | Y3: 19 | Z3: 20 | AA3: 21 | AB3: 22 | AC3: 23 | AD3: 24 | AE3: 25 | AF3: 26 | AG3: 27 | AH3: 28 | AI3: 29 | AJ3: 30 | AK3: 31 | AL3: 32 | AM3: 33 | AN3: 34 | AO3: 35 | AP3: 36 | AQ3: 37 | AR3: 38 | AS3: 39 | AT3: 40 | AU3: 41 | AV3: 42 | AW3: 43 | AX3: 44 | AY3: 45 | AZ3: 46 | BA3: 47 | BB3: 48 | BC3: 49 | BD3: 50 | BE3: 51 | BF3: 52 | BG3: 53 | BH3: 54 | BI3: 55 | BJ3: 56 | BK3: 57 | BL3: 58
D4: Year | E4: 1 | F4: 1 | G4: 1 | H4: 1 | I4: 1 | J4: 1 | K4: 1 | L4: 1 | M4: 1 | N4: 1 | O4: 1 | P4: 1 | Q4: =E4+1 -> 2 | R4: =F4+1 -> 2 | S4: =G4+1 -> 2 | T4: =H4+1 -> 2 | U4: =I4+1 -> 2 | V4: =J4+1 -> 2 | W4: =K4+1 -> 2 | X4: =L4+1 -> 2 | ... DU4: =DI4+1 -> 11
D5: Date | E5: 45455 | F5: 45485 | G5: 45516 | H5: 45547 | I5: 45580 | J5: 45608 | K5: 45638 | L5: 45670 | M5: 45700 | N5: 45728 | O5: 45761 | P5: 45789 | Q5: 45820 | R5: 45852 | S5: 45881 | T5: 45912 | U5: 45944 | V5: 45973 | W5: 46003 | X5: 46034 | Y5: 46065 | Z5: 46093 | AA5: 46125 | AB5: 46154 | AC5: 46185 | AD5: 46216 | AE5: 46246 | AF5: 46279 | AG5: 46308 | AH5: 46338 | AI5: 46370 | AJ5: 46399 | AK5: 46430 | AL5: 46458 | AM5: 46489 | AN5: 46519 | AO5: 46552 | AP5: 46580 | AQ5: 46611 | AR5: 46643 | AS5: 46672 | AT5: 46703 | AU5: 46734 | AV5: 46764 | AW5: 46797 | AX5: 46825 | AY5: 46855 | AZ5: 46885 | BA5: 46916 | BB5: 46946 | BC5: 46979 | BD5: 47008 | BE5: 47038 | BF5: 47070 | BG5: 47099 | BH5: 47130 | BI5: 47161 | BJ5: 47189 | BK5: 47220 | BL5: 47252 | BM5: 47281 | BN5: 47311 | BO5: 47343 | BP5: 47373 | BQ5: 47403 | BR5: 47435 | BS5: 47464 | BT5: 47497 | BU5: 47526 | BV5: 47554 | BW5: 47585 | BX5: 47616 | BY5: 47646 | BZ5: 47676 | CA5: 47707 | CB5: 47738 | CC5: 47771 | CD5: 47799 | CE5: 47829 | CF5: 47861 | CG5: 47891 | CH5: 47919 | CI5: 47952 | CJ5: 47980 | CK5: 48011 | CL5: 48043 | CM5: 48072 | CN5: 48103 | CO5: 48135 | CP5: 48164 | CQ5: 48194 | CR5: 48225 | CS5: 48256 | CT5: 48285 | CU5: 48316 | CV5: 48346 | CW5: 48379 | CX5: 48407 | CY5: 48438 | CZ5: 48470 | DA5: 48499 | DB5: 48530 | DC5: 48561 | DD5: 48591 | DE5: 48624 | DF5: 48652 | DG5: 48681 | DH5: 48711 | DI5: 48743 | DJ5: 48772 | DK5: 48803 | DL5: 48834 | DM5: 48864 | DN5: 48897 | DO5: 48925 | DP5: 48956 | DQ5: 48988 | DR5: 49016 | DS5: 49046 | DT5: 49076 | DU5: 49107
A6: Date | B6: 1-month Term SOFR | D6: 1-month Term SOFR | E6: 0.053291 | F6: 0.0532664 | G6: 0.0530533 | H6: 0.0523577 | I6: 0.0518021 | J6: 0.0512678 | K6: 0.0496218 | L6: 0.0493128 | M6: 0.0493027 | N6: 0.0474269 | O6: 0.0469083 | P6: 0.0469113 | Q6: 0.0451619 | R6: 0.0447548 | S6: 0.0447548 | T6: 0.0437221 | U6: 0.042989 | V6: 0.0424915 | W6: 0.0420029 | X6: 0.0415444 | Y6: 0.0411388 | Z6: 0.0407816 | AA6: 0.040438 | AB6: 0.040156 | AC6: 0.0398925 | AD6: 0.0396465 | AE6: 0.0394175 | AF6: 0.0391868 | AG6: 0.038991 | AH6: 0.0388005 | AI6: 0.0386124 | AJ6: 0.0384527 | AK6: 0.0382955 | AL6: 0.0381622 | AM6: 0.038028 | AN6: 0.0379106 | AO6: 0.0377935 | AP6: 0.0377035 | AQ6: 0.0376126 | AR6: 0.0375261 | AS6: 0.0374577 | AT6: 0.0373924 | AU6: 0.037336 | AV6: 0.0372924 | AW6: 0.0372459 | AX6: 0.0372216 | AY6: 0.0371989 | AZ6: 0.0371878 | BA6: 0.0371808 | BB6: 0.0371865 | BC6: 0.0371872 | BD6: 0.0371933 | BE6: 0.0372102 | BF6: 0.0372237 | BG6: 0.0372463 | BH6: 0.0372723 | BI6: 0.0372953 | BJ6: 0.037334 | BK6: 0.0373754 | BL6: 0.0374175 | BM6: 0.0374584 | BN6: 0.0375087 | BO6: 0.0375526 | BP6: 0.0375925 | BQ6: 0.0376392 | BR6: 0.0376769 | BS6: 0.0377226 | BT6: 0.0377592 | BU6: 0.0377871 | BV6: 0.0378283 | BW6: 0.0378642 | BX6: 0.0378989 | BY6: 0.0379288 | BZ6: 0.0379627 | CA6: 0.0379939 | CB6: 0.0380289 | CC6: 0.0380546 | CD6: 0.0380772 | CE6: 0.0381077 | CF6: 0.0381315 | CG6: 0.0381477 | CH6: 0.0381805 | CI6: 0.0381967 | CJ6: 0.0382178 | CK6: 0.03824 | CL6: 0.0382584 | CM6: 0.0382777 | CN6: 0.0383011 | CO6: 0.038321 | CP6: 0.0383393 | CQ6: 0.0383634 | CR6: 0.0383864 | CS6: 0.038405 | CT6: 0.0384323 | CU6: 0.0384543 | CV6: 0.0384858 | CW6: 0.0385054 | CX6: 0.0385313 | CY6: 0.0385601 | CZ6: 0.0385828 | DA6: 0.0386109 | DB6: 0.0386387 | DC6: 0.038667 | DD6: 0.0386999 | DE6: 0.0387183 | DF6: 0.0387528 | DG6: 0.0387785 | DH6: 0.0388133 | DI6: 0.0388403 | DJ6: 0.0388725 | DK6: 0.0389046 | DL6: 0.0389346 | DM6: 0.0389745 | DN6: 0.0390023 | DO6: 0.0390357 | DP6: 0.0390729 | DQ6: 0.0390983 | DR6: 0.0391384 | DS6: 0.0391705 | DT6: 0.0392084 | DU6: 0.0392423
A7: 45455 | B7: 0.053291
A8: 45485 | B8: 0.0532664
A9: 45516 | B9: 0.0530533
A10: 45547 | B10: 0.0523577
A11: 45580 | B11: 0.0518021
A12: 45608 | B12: 0.0512678
A13: 45638 | B13: 0.0496218
A14: 45670 | B14: 0.0493128
A15: 45700 | B15: 0.0493027
A16: 45728 | B16: 0.0474269
A17: 45761 | B17: 0.0469083
A18: 45789 | B18: 0.0469113
... A127: 49107 | B127: 0.0392423

Sheet Rent Comps
AT2: Apart | AU2: Note | AV2: units | AW2: Occ | AX2: Built | AY2: Rent | AZ2: PSF | BA2: Builder | BB2: Bldg. Address
AT3: Subject
C8: RENTAL COMPS
I9: Studios | P9: 1BR | W9: 2BR | AD9: 3BR | AK9: Total | AS9: .
C10: Name | D10: Address | E10: Submkt | F10: Built | G10: # Unit | H10: Occ. | I10: # Unit | J10: # Vac | K10: SF | L10: Avg $ | M10: Eff. $ | N10: $/SF | O10: Conc % | P10: # Unit | Q10: # Vac | R10: SF | S10: Avg $ | T10: Eff $ | U10: $/SF | V10: Conc% | W10: # Unit | X10: # Vac | Y10: SF | Z10: Avg $ | AA10: Eff. $ | AB10: $/SF | AC10: Conc% | AD10: # Unit | AE10: # Vac | AF10: SF | AG10: Avg $ | AH10: Eff $ | AI10: $/SF | AJ10: Conc% | AK10: # Unit | AL10: # Vac | AM10: SF | AN10: Avg $ | AO10: Eff $ | AP10: $/SF | AQ10: Conc%
C11: The Harrison | D11: 2555-2575 University Pkwy | E11: Person1180 | F11: 2020 | G11: =AK11 -> 240 | H11: =1-(AL11/AK11) -> 0.93333333 | I11: 0 | J11: 0 | K11: 0 | L11: 0 | M11: 0 | N11: =IF(K11=0,0,L11/K11) -> 0 | O11: =IF(L11=0,0,(L11-M11)/L11) -> 0 | P11: 96 | Q11: 7 | R11: 810 | S11: 1864 | T11: 1864 | U11: =IF(R11=0,0,S11/R11) -> 2.3012346 | V11: =IF(S11=0,0,(S11-T11)/S11) -> 0 | W11: 113 | X11: 6 | Y11: 1140 | Z11: 2158 | AA11: 2158 | AB11: =IF(Y11=0,0,Z11/Y11) -> 1.8929825 | AC11: =IF(Z11=0,0,(Z11-AA11)/Z11) -> 0 | AD11: 31 | AE11: 3 | AF11: 1351 | AG11: 2789 | AH11: 2789 | AI11: =IF(AF11=0,0,AG11/AF11) -> 2.0643967 | AJ11: =IF(AG11=0,0,(AG11-AH11)/AG11) -> 0 | AK11: =I11+P11+W11+AD11 -> 240 | AL11: =J11+Q11+X11+AE11 -> 16 | AM11: =((I11*K11)+(P11*R11)+(W11*Y11)+(AD11*AF11))/AK11 -> 1035.2542 | AN11: =(($I11*L11)+($P11*S11)+($W11*Z11)+($AD11*AG11))/$AK11 -> 2121.9042 | AO11: =(($I11*M11)+($P11*T11)+($W11*AA11)+($AD11*AH11))/$AK11 -> 2121.9042 | AP11: =IF(AM11=0,0,AN11/AM11) -> 2.0496456 | AQ11: =IF(AN11=0,0,(AN11-AO11)/AN11) -> 0
C12: Loop 2800 | D12: 2800 Telluride Loop | E12: Person1180 | F12: 2018 | G12: =AK12 -> 324 | H12: =1-(AL12/AK12) -> 0.95679012 | I12: 0 | J12: 0 | K12: 0 | L12: 0 | M12: 0 | N12: =IF(K12=0,0,L12/K12) -> 0 | O12: =IF(L12=0,0,(L12-M12)/L12) -> 0 | P12: 110 | Q12: 5 | R12: 814 | S12: 1741 | T12: 1741 | U12: =IF(R12=0,0,S12/R12) -> 2.1388206 | V12: =IF(S12=0,0,(S12-T12)/S12) -> 0 | W12: 178 | X12: 7 | Y12: 1167 | Z12: 2089 | AA12: 2089 | AB12: =IF(Y12=0,0,Z12/Y12) -> 1.79006 | AC12: =IF(Z12=0,0,(Z12-AA12)/Z12) -> 0 | AD12: 36 | AE12: 2 | AF12: 1319 | AG12: 2532 | AH12: 2532 | AI12: =IF(AF12=0,0,AG12/AF12) -> 1.9196361 | AJ12: =IF(AG12=0,0,(AG12-AH12)/AG12) -> 0 | AK12: =I12+P12+W12+AD12 -> 324 | AL12: =J12+Q12+X12+AE12 -> 14 | AM12: =((I12*K12)+(P12*R12)+(W12*Y12)+(AD12*AF12))/AK12 -> 1064.0432 | AN12: =(($I12*L12)+($P12*S12)+($W12*Z12)+($AD12*AG12))/$AK12 -> 2020.0741 | AO12: =(($I12*M12)+($P12*T12)+($W12*AA12)+($AD12*AH12))/$AK12 -> 2020.0741 | AP12: =IF(AM12=0,0,AN12/AM12) -> 1.8984888 | AQ12: =IF(AN12=0,0,(AN12-AO12)/AN12) -> 0
