Workbook

Sheet FORECAST_ASSUMPTIONS
B1: ($ in millions)
B3: FY2025E - FY2035E Forecast Assumptions
B5: FY2025E Gross Bookings Growth Rate (%)
B6: Mobility Segment | C6: 0.21
B7: Delivery Segment | C7: 0.175
B8: Freight Segment | C8: 0.02
B10: FY2026E - FY2035E Annual Change in Gross Bookings Growth Rate (Percentage Points)
B11: Mobility Segment | C11: -0.01
B12: Delivery Segment | C12: -0.0125
B13: Freight Segment | C13: -0.001
B15: FY2025E - FY2035E Annual Change in Take Rate (Percentage Points)
B16: Mobility Segment | C16: 0.005
B17: Delivery Segment | C17: -0.003
B18: Freight Segment | C18: 0
B20: FY2025E - FY2035E Annual Change in Adjusted EBITDA Margin (Percentage Points)
B21: Mobility Segment | C21: 0.0025
B22: Delivery Segment | C22: 0.001
B23: Freight Segment | C23: 0.01
B25: FY2025E - FY2035E Corporate Overhead Expense Annual Growth Rate (%)
B26: Corporate Overhead Expense Annual Growth Rate (%) | C26: 0.04
B28: Tax Rate (% of EBIT)
B29: Tax Rate (% of EBIT) | C29: 0.25
B31: Capital Expenditures ("CapEx")
B32: CapEx (% of Total Gross Bookings) | C32: 0.002
B34: Depreciation & Amortization ("D&A")
B35: Weighted Average Useful Life on CapEx (Years) | C35: 5
B36: Net Property & Equipment ("Net PP&E") Balance at 12/31/2024 | C36: 1952
B37: Net Carrying Value of Intangibles at 12/31/2024 | C37: 1125
B38: FY2025E Amortization of Intangibles | C38: 246
B39: FY2026E Amortization of Intangibles | C39: 185
B40: FY2027E Amortization of Intangibles | C40: 170
B41: FY2028E Amortization of Intangibles | C41: 127
B42: FY2029E Amortization of Intangibles | C42: 84
B43: FY2030E - FY2035E Amortization of Intangibles (Spread Evenly Across FY2030E - FY2035E) | C43: 311
B45: Δ in Net Working Capital ("NWC")
B46: Δ in NWC (% of the Y/Y $ Change in Total Gross Bookings) | C46: 0.025
B48: Stock Based Compensation ("SBC")
B49: SBC (% of Total Gross Bookings) | C49: 0.0125
B52: Notes:
B53: • Fiscal year ends on December 31st
...

Sheet VALUATION_MODEL
B1: ($ in millions)
C4: Historical | E4: Projections | P4: Terminal
B5: Company2835 Company2746 (FYE 12/31) | C5: FY2023A | D5: FY2024A | E5: FY2025E | F5: FY2026E | G5: FY2027E | H5: FY2028E | I5: FY2029E | J5: FY2030E | K5: FY2031E | L5: FY2032E | M5: FY2033E | N5: FY2034E | O5: FY2035E | P5: Value
B7: Gross Bookings Growth Rate (%)
B8: Mobility Segment | D8: =IFERROR(D14/C14-1,"n/m") | E8: =FORECAST_ASSUMPTIONS!C6 | F8: =E8+FORECAST_ASSUMPTIONS!$C$11 | G8: =F8+FORECAST_ASSUMPTIONS!$C$11 | H8: =G8+FORECAST_ASSUMPTIONS!$C$11 | I8: =H8+FORECAST_ASSUMPTIONS!$C$11 | J8: =I8+FORECAST_ASSUMPTIONS!$C$11 | K8: =J8+FORECAST_ASSUMPTIONS!$C$11 | L8: =K8+FORECAST_ASSUMPTIONS!$C$11 | M8: =L8+FORECAST_ASSUMPTIONS!$C$11 | ... O8: =N8+FORECAST_ASSUMPTIONS!$C$11
B9: Delivery Segment | D9: =IFERROR(D15/C15-1,"n/m") | E9: =FORECAST_ASSUMPTIONS!C7 | F9: =E9+FORECAST_ASSUMPTIONS!$C$12 | G9: =F9+FORECAST_ASSUMPTIONS!$C$12 | H9: =G9+FORECAST_ASSUMPTIONS!$C$12 | I9: =H9+FORECAST_ASSUMPTIONS!$C$12 | J9: =I9+FORECAST_ASSUMPTIONS!$C$12 | K9: =J9+FORECAST_ASSUMPTIONS!$C$12 | L9: =K9+FORECAST_ASSUMPTIONS!$C$12 | M9: =L9+FORECAST_ASSUMPTIONS!$C$12 | ... O9: =N9+FORECAST_ASSUMPTIONS!$C$12
B10: Freight Segment | D10: =IFERROR(D16/C16-1,"n/m") | E10: =FORECAST_ASSUMPTIONS!C8 | F10: =E10+FORECAST_ASSUMPTIONS!$C$13 | G10: =F10+FORECAST_ASSUMPTIONS!$C$13 | H10: =G10+FORECAST_ASSUMPTIONS!$C$13 | I10: =H10+FORECAST_ASSUMPTIONS!$C$13 | J10: =I10+FORECAST_ASSUMPTIONS!$C$13 | K10: =J10+FORECAST_ASSUMPTIONS!$C$13 | L10: =K10+FORECAST_ASSUMPTIONS!$C$13 | M10: =L10+FORECAST_ASSUMPTIONS!$C$13 | ... O10: =N10+FORECAST_ASSUMPTIONS!$C$13
B11: Total Gross Bookings Annual Growth Rate | D11: =IFERROR(D17/C17-1,"n/m") | E11: =E17/D17-1 | F11: =F17/E17-1 | G11: =G17/F17-1 | H11: =H17/G17-1 | I11: =I17/H17-1 | J11: =J17/I17-1 | K11: =K17/J17-1 | L11: =L17/K17-1 | ... O11: =O17/N17-1
B13: Gross Bookings ($)
B14: Mobility Segment | C14: 68897 | D14: 83024 | E14: =D14*(1+E8) | F14: =E14*(1+F8) | G14: =F14*(1+G8) | H14: =G14*(1+H8) | I14: =H14*(1+I8) | J14: =I14*(1+J8) | K14: =J14*(1+K8) | L14: =K14*(1+L8) | ... O14: =N14*(1+O8)
B15: Delivery Segment | C15: 63726 | D15: 74614 | E15: =D15*(1+E9) | F15: =E15*(1+F9) | G15: =F15*(1+G9) | H15: =G15*(1+H9) | I15: =H15*(1+I9) | J15: =I15*(1+J9) | K15: =J15*(1+K9) | L15: =K15*(1+L9) | ... O15: =N15*(1+O9)
B16: Freight Segment | C16: 5241 | D16: 5135 | E16: =D16*(1+E10) | F16: =E16*(1+F10) | G16: =F16*(1+G10) | H16: =G16*(1+H10) | I16: =H16*(1+I10) | J16: =I16*(1+J10) | K16: =J16*(1+K10) | L16: =K16*(1+L10) | ... O16: =N16*(1+O10)
B17: Total Gross Bookings | C17: =SUM(C14:C16) | D17: =SUM(D14:D16) | E17: =SUM(E14:E16) | F17: =SUM(F14:F16) | G17: =SUM(G14:G16) | H17: =SUM(H14:H16) | I17: =SUM(I14:I16) | J17: =SUM(J14:J16) | ... O17: =SUM(O14:O16) | P17: =O17
B18: Annual Growth Rate (%) | D18: =D17/C17-1 | E18: =E17/D17-1 | F18: =F17/E17-1 | G18: =G17/F17-1 | H18: =H17/G17-1 | I18: =I17/H17-1 | J18: =J17/I17-1 | K18: =K17/J17-1 | ... O18: =O17/N17-1
B20: Take Rate (%)
B21: Mobility Segment | C21: =C27/C14 | D21: =D27/D14 | E21: =D21+FORECAST_ASSUMPTIONS!$C$16 | F21: =E21+FORECAST_ASSUMPTIONS!$C$16 | G21: =F21+FORECAST_ASSUMPTIONS!$C$16 | H21: =G21+FORECAST_ASSUMPTIONS!$C$16 | I21: =H21+FORECAST_ASSUMPTIONS!$C$16 | J21: =I21+FORECAST_ASSUMPTIONS!$C$16 | K21: =J21+FORECAST_ASSUMPTIONS!$C$16 | L21: =K21+FORECAST_ASSUMPTIONS!$C$16 | ... O21: =N21+FORECAST_ASSUMPTIONS!$C$16
B22: Delivery Segment | C22: =C28/C15 | D22: =D28/D15 | E22: =D22+FORECAST_ASSUMPTIONS!$C$17 | F22: =E22+FORECAST_ASSUMPTIONS!$C$17 | G22: =F22+FORECAST_ASSUMPTIONS!$C$17 | H22: =G22+FORECAST_ASSUMPTIONS!$C$17 | I22: =H22+FORECAST_ASSUMPTIONS!$C$17 | J22: =I22+FORECAST_ASSUMPTIONS!$C$17 | K22: =J22+FORECAST_ASSUMPTIONS!$C$17 | L22: =K22+FORECAST_ASSUMPTIONS!$C$17 | ... O22: =N22+FORECAST_ASSUMPTIONS!$C$17
B23: Freight Segment | C23: =C29/C16 | D23: =D29/D16 | E23: =D23+FORECAST_ASSUMPTIONS!$C$18 | F23: =E23+FORECAST_ASSUMPTIONS!$C$18 | G23: =F23+FORECAST_ASSUMPTIONS!$C$18 | H23: =G23+FORECAST_ASSUMPTIONS!$C$18 | I23: =H23+FORECAST_ASSUMPTIONS!$C$18 | J23: =I23+FORECAST_ASSUMPTIONS!$C$18 | K23: =J23+FORECAST_ASSUMPTIONS!$C$18 | L23: =K23+FORECAST_ASSUMPTIONS!$C$18 | ... O23: =N23+FORECAST_ASSUMPTIONS!$C$18
B24: Total Take Rate | C24: =C30/C17 | D24: =D30/D17 | E24: =E30/E17 | F24: =F30/F17 | G24: =G30/G17 | H24: =H30/H17 | I24: =I30/I17 | J24: =J30/J17 | ... O24: =O30/O17
B26: Revenue ($)
B27: Mobility Segment | C27: 19832 | D27: 25087 | E27: =E14*E21 | F27: =F14*F21 | G27: =G14*G21 | H27: =H14*H21 | I27: =I14*I21 | J27: =J14*J21 | K27: =K14*K21 | L27: =L14*L21 | ... O27: =O14*O21
B28: Delivery Segment | C28: 12204 | D28: 13750 | E28: =E15*E22 | F28: =F15*F22 | G28: =G15*G22 | H28: =H15*H22 | I28: =I15*I22 | J28: =J15*J22 | K28: =K15*K22 | L28: =L15*L22 | ... O28: =O15*O22
B29: Freight Segment | C29: 5245 | D29: 5141 | E29: =E16*E23 | F29: =F16*F23 | G29: =G16*G23 | H29: =H16*H23 | I29: =I16*I23 | J29: =J16*J23 | K29: =K16*K23 | L29: =L16*L23 | ... O29: =O16*O23
B30: Total Revenue | C30: =SUM(C27:C29) | D30: =SUM(D27:D29) | E30: =SUM(E27:E29) | F30: =SUM(F27:F29) | G30: =SUM(G27:G29) | H30: =SUM(H27:H29) | I30: =SUM(I27:I29) | J30: =SUM(J27:J29) | ... O30: =SUM(O27:O29) | P30: =O30
B31: Annual Growth Rate (%) | D31: =D30/C30-1 | E31: =E30/D30-1 | F31: =F30/E30-1 | G31: =G30/F30-1 | H31: =H30/G30-1 | I31: =I30/H30-1 | J31: =J30/I30-1 | K31: =K30/J30-1 | ... O31: =O30/N30-1
B33: Adjusted EBITDA Margin (%)
B34: Mobility Segment | C34: =IFERROR(C41/C27,"n/m") | D34: =IFERROR(D41/D27,"n/m") | E34: =D34+FORECAST_ASSUMPTIONS!$C$21 | F34: =E34+FORECAST_ASSUMPTIONS!$C$21 | G34: =F34+FORECAST_ASSUMPTIONS!$C$21 | H34: =G34+FORECAST_ASSUMPTIONS!$C$21 | I34: =H34+FORECAST_ASSUMPTIONS!$C$21 | J34: =I34+FORECAST_ASSUMPTIONS!$C$21 | K34: =J34+FORECAST_ASSUMPTIONS!$C$21 | L34: =K34+FORECAST_ASSUMPTIONS!$C$21 | ... O34: =N34+FORECAST_ASSUMPTIONS!$C$21
B35: Delivery Segment | C35: =IFERROR(C42/C28,"n/m") | D35: =IFERROR(D42/D28,"n/m") | E35: =D35+FORECAST_ASSUMPTIONS!$C$22 | F35: =E35+FORECAST_ASSUMPTIONS!$C$22 | G35: =F35+FORECAST_ASSUMPTIONS!$C$22 | H35: =G35+FORECAST_ASSUMPTIONS!$C$22 | I35: =H35+FORECAST_ASSUMPTIONS!$C$22 | J35: =I35+FORECAST_ASSUMPTIONS!$C$22 | K35: =J35+FORECAST_ASSUMPTIONS!$C$22 | L35: =K35+FORECAST_ASSUMPTIONS!$C$22 | ... O35: =N35+FORECAST_ASSUMPTIONS!$C$22
B36: Freight Segment | C36: =IFERROR(C43/C29,"n/m") | D36: =IFERROR(D43/D29,"n/m") | E36: =D36+FORECAST_ASSUMPTIONS!$C$23 | F36: =E36+FORECAST_ASSUMPTIONS!$C$23 | G36: =F36+FORECAST_ASSUMPTIONS!$C$23 | H36: =G36+FORECAST_ASSUMPTIONS!$C$23 | I36: =H36+FORECAST_ASSUMPTIONS!$C$23 | J36: =I36+FORECAST_ASSUMPTIONS!$C$23 | K36: =J36+FORECAST_ASSUMPTIONS!$C$23 | L36: =K36+FORECAST_ASSUMPTIONS!$C$23 | ... O36: =N36+FORECAST_ASSUMPTIONS!$C$23
B37: Corporate Overhead Expense | C37: N/A | D37: N/A | E37: N/A | F37: N/A | G37: N/A | H37: N/A | I37: N/A | J37: N/A | K37: N/A | L37: N/A | M37: N/A | N37: N/A | O37: N/A
B38: Adjusted EBITDA Margin | C38: =IFERROR(C45/C30,"n/m") | D38: =IFERROR(D45/D30,"n/m") | E38: =IFERROR(E45/E30,"n/m") | F38: =IFERROR(F45/F30,"n/m") | G38: =IFERROR(G45/G30,"n/m") | H38: =IFERROR(H45/H30,"n/m") | I38: =IFERROR(I45/I30,"n/m") | J38: =IFERROR(J45/J30,"n/m") | ... O38: =IFERROR(O45/O30,"n/m")
B40: Adjusted EBITDA ($)
B41: Mobility Segment | C41: 4963 | D41: 6497 | E41: =E27*E34 | F41: =F27*F34 | G41: =G27*G34 | H41: =H27*H34 | I41: =I27*I34 | J41: =J27*J34 | K41: =K27*K34 | L41: =L27*L34 | ... O41: =O27*O34
B42: Delivery Segment | C42: 1506 | D42: 2471 | E42: =E28*E35 | F42: =F28*F35 | G42: =G28*G35 | H42: =H28*H35 | I42: =I28*I35 | J42: =J28*J35 | K42: =K28*K35 | L42: =L28*L35 | ... O42: =O28*O35
B43: Freight Segment | C43: -64 | D43: -74 | E43: =E29*E36 | F43: =F29*F36 | G43: =G29*G36 | H43: =H29*H36 | I43: =I29*I36 | J43: =J29*J36 | K43: =K29*K36 | L43: =L29*L36 | ... O43: =O29*O36
B44: Corporate Overhead Expense | C44: -2353 | D44: -2410 | E44: =D44*(1+FORECAST_ASSUMPTIONS!$C$26) | F44: =E44*(1+FORECAST_ASSUMPTIONS!$C$26) | G44: =F44*(1+FORECAST_ASSUMPTIONS!$C$26) | H44: =G44*(1+FORECAST_ASSUMPTIONS!$C$26) | I44: =H44*(1+FORECAST_ASSUMPTIONS!$C$26) | J44: =I44*(1+FORECAST_ASSUMPTIONS!$C$26) | K44: =J44*(1+FORECAST_ASSUMPTIONS!$C$26) | L44: =K44*(1+FORECAST_ASSUMPTIONS!$C$26) | ... O44: =N44*(1+FORECAST_ASSUMPTIONS!$C$26)
B45: Adj. EBITDA | C45: =SUM(C41:C44) | D45: =SUM(D41:D44) | E45: =SUM(E41:E44) | F45: =SUM(F41:F44) | G45: =SUM(G41:G44) | H45: =SUM(H41:H44) | I45: =SUM(I41:I44) | J45: =SUM(J41:J44) | ... O45: =SUM(O41:O44) | P45: =O45
B46: Annual Growth Rate (%) | D46: =D45/C45-1 | E46: =E45/D45-1 | F46: =F45/E45-1 | G46: =G45/F45-1 | H46: =H45/G45-1 | I46: =I45/H45-1 | J46: =J45/I45-1 | K46: =K45/J45-1 | ... O46: =O45/N45-1
B48: (-) D&A | E48: =-'D&A_BUILD'!E51 | F48: =-'D&A_BUILD'!F51 | G48: =-'D&A_BUILD'!G51 | H48: =-'D&A_BUILD'!H51 | I48: =-'D&A_BUILD'!I51 | J48: =-'D&A_BUILD'!J51 | K48: =-'D&A_BUILD'!K51 | L48: =-'D&A_BUILD'!L51 | ... O48: =-'D&A_BUILD'!O51
B50: EBIT | E50: =SUM(E45,E48) | F50: =SUM(F45,F48) | G50: =SUM(G45,G48) | H50: =SUM(H45,H48) | I50: =SUM(I45,I48) | J50: =SUM(J45,J48) | K50: =SUM(K45,K48) | L50: =SUM(L45,L48) | ... O50: =SUM(O45,O48)
...

Sheet D&A_BUILD
B1: ($ in millions)
D3: Historical | E3: Projections
D4: FY2024A | E4: FY2025E | F4: FY2026E | G4: FY2027E | H4: FY2028E | I4: FY2029E | J4: FY2030E | K4: FY2031E | L4: FY2032E | M4: FY2033E | N4: FY2034E | O4: FY2035E
B6: Weighted Average Useful Life on CapEx (Years) | C6: =FORECAST_ASSUMPTIONS!$C$35
B8: Net PP&E Balance
B9: Vintage | C9: CapEx (Additions)
B10: Pre-FY2025E | D10: =FORECAST_ASSUMPTIONS!$C$36 | E10: =IF(D10+-$D10/$C$6<0,0,D10+-$D10/$C$6) | F10: =IF(E10+-$D10/$C$6<0,0,E10+-$D10/$C$6) | G10: =IF(F10+-$D10/$C$6<0,0,F10+-$D10/$C$6) | H10: =IF(G10+-$D10/$C$6<0,0,G10+-$D10/$C$6) | I10: =IF(H10+-$D10/$C$6<0,0,H10+-$D10/$C$6) | J10: =IF(I10+-$D10/$C$6<0,0,I10+-$D10/$C$6) | K10: =IF(J10+-$D10/$C$6<0,0,J10+-$D10/$C$6) | L10: =IF(K10+-$D10/$C$6<0,0,K10+-$D10/$C$6) | ... O10: =IF(N10+-$D10/$C$6<0,0,N10+-$D10/$C$6)
B11: FY2025E | C11: {=TRANSPOSE(VALUATION_MODEL!E57:O57)} | E11: =-$C11 | F11: =IF(E11+$C11/$C$6<0,0,E11+$C11/$C$6) | G11: =IF(F11+$C11/$C$6<0,0,F11+$C11/$C$6) | H11: =IF(G11+$C11/$C$6<0,0,G11+$C11/$C$6) | I11: =IF(H11+$C11/$C$6<0,0,H11+$C11/$C$6) | J11: =IF(I11+$C11/$C$6<0,0,I11+$C11/$C$6) | K11: =IF(J11+$C11/$C$6<0,0,J11+$C11/$C$6) | L11: =IF(K11+$C11/$C$6<0,0,K11+$C11/$C$6) | M11: =IF(L11+$C11/$C$6<0,0,L11+$C11/$C$6) | ... O11: =IF(N11+$C11/$C$6<0,0,N11+$C11/$C$6)
B12: FY2026E | F12: =-$C12 | G12: =IF(F12+$C12/$C$6<0,0,F12+$C12/$C$6) | H12: =IF(G12+$C12/$C$6<0,0,G12+$C12/$C$6) | I12: =IF(H12+$C12/$C$6<0,0,H12+$C12/$C$6) | J12: =IF(I12+$C12/$C$6<0,0,I12+$C12/$C$6) | K12: =IF(J12+$C12/$C$6<0,0,J12+$C12/$C$6) | L12: =IF(K12+$C12/$C$6<0,0,K12+$C12/$C$6) | M12: =IF(L12+$C12/$C$6<0,0,L12+$C12/$C$6) | N12: =IF(M12+$C12/$C$6<0,0,M12+$C12/$C$6) | O12: =IF(N12+$C12/$C$6<0,0,N12+$C12/$C$6)
B13: FY2027E | G13: =-$C13 | H13: =IF(G13+$C13/$C$6<0,0,G13+$C13/$C$6) | I13: =IF(H13+$C13/$C$6<0,0,H13+$C13/$C$6) | J13: =IF(I13+$C13/$C$6<0,0,I13+$C13/$C$6) | K13: =IF(J13+$C13/$C$6<0,0,J13+$C13/$C$6) | L13: =IF(K13+$C13/$C$6<0,0,K13+$C13/$C$6) | M13: =IF(L13+$C13/$C$6<0,0,L13+$C13/$C$6) | N13: =IF(M13+$C13/$C$6<0,0,M13+$C13/$C$6) | O13: =IF(N13+$C13/$C$6<0,0,N13+$C13/$C$6)
B14: FY2028E | H14: =-$C14 | I14: =IF(H14+$C14/$C$6<0,0,H14+$C14/$C$6) | J14: =IF(I14+$C14/$C$6<0,0,I14+$C14/$C$6) | K14: =IF(J14+$C14/$C$6<0,0,J14+$C14/$C$6) | L14: =IF(K14+$C14/$C$6<0,0,K14+$C14/$C$6) | M14: =IF(L14+$C14/$C$6<0,0,L14+$C14/$C$6) | N14: =IF(M14+$C14/$C$6<0,0,M14+$C14/$C$6) | O14: =IF(N14+$C14/$C$6<0,0,N14+$C14/$C$6)
B15: FY2029E | I15: =-$C15 | J15: =IF(I15+$C15/$C$6<0,0,I15+$C15/$C$6) | K15: =IF(J15+$C15/$C$6<0,0,J15+$C15/$C$6) | L15: =IF(K15+$C15/$C$6<0,0,K15+$C15/$C$6) | M15: =IF(L15+$C15/$C$6<0,0,L15+$C15/$C$6) | N15: =IF(M15+$C15/$C$6<0,0,M15+$C15/$C$6) | O15: =IF(N15+$C15/$C$6<0,0,N15+$C15/$C$6)
B16: FY2030E | J16: =-$C16 | K16: =IF(J16+$C16/$C$6<0,0,J16+$C16/$C$6) | L16: =IF(K16+$C16/$C$6<0,0,K16+$C16/$C$6) | M16: =IF(L16+$C16/$C$6<0,0,L16+$C16/$C$6) | N16: =IF(M16+$C16/$C$6<0,0,M16+$C16/$C$6) | O16: =IF(N16+$C16/$C$6<0,0,N16+$C16/$C$6)
B17: FY2031E | K17: =-$C17 | L17: =IF(K17+$C17/$C$6<0,0,K17+$C17/$C$6) | M17: =IF(L17+$C17/$C$6<0,0,L17+$C17/$C$6) | N17: =IF(M17+$C17/$C$6<0,0,M17+$C17/$C$6) | O17: =IF(N17+$C17/$C$6<0,0,N17+$C17/$C$6)
B18: FY2032E | L18: =-$C18 | M18: =IF(L18+$C18/$C$6<0,0,L18+$C18/$C$6) | N18: =IF(M18+$C18/$C$6<0,0,M18+$C18/$C$6) | O18: =IF(N18+$C18/$C$6<0,0,N18+$C18/$C$6)
B19: FY2033E | M19: =-$C19 | N19: =IF(M19+$C19/$C$6<0,0,M19+$C19/$C$6) | O19: =IF(N19+$C19/$C$6<0,0,N19+$C19/$C$6)
B20: FY2034E | N20: =-$C20 | O20: =IF(N20+$C20/$C$6<0,0,N20+$C20/$C$6)
B21: FY2035E | O21: =-$C21
B22: Total Net PP&E | D22: =SUM(D10:D21) | E22: =SUM(E10:E21) | F22: =SUM(F10:F21) | G22: =SUM(G10:G21) | H22: =SUM(H10:H21) | I22: =SUM(I10:I21) | J22: =SUM(J10:J21) | K22: =SUM(K10:K21) | ... O22: =SUM(O10:O21)
B25: D&A on PP&E
B26: Vintage
B27: Pre-FY2025E | E27: =IF(D10-E10<0,0,D10-E10) | F27: =IF(E10-F10<0,0,E10-F10) | G27: =IF(F10-G10<0,0,F10-G10) | H27: =IF(G10-H10<0,0,G10-H10) | I27: =IF(H10-I10<0,0,H10-I10) | J27: =IF(I10-J10<0,0,I10-J10) | K27: =IF(J10-K10<0,0,J10-K10) | L27: =IF(K10-L10<0,0,K10-L10) | ... O27: =IF(N10-O10<0,0,N10-O10)
B28: FY2025E | E28: =IF(D11-E11<0,0,D11-E11) | F28: =IF(E11-F11<0,0,E11-F11) | G28: =IF(F11-G11<0,0,F11-G11) | H28: =IF(G11-H11<0,0,G11-H11) | I28: =IF(H11-I11<0,0,H11-I11) | J28: =IF(I11-J11<0,0,I11-J11) | K28: =IF(J11-K11<0,0,J11-K11) | L28: =IF(K11-L11<0,0,K11-L11) | ... O28: =IF(N11-O11<0,0,N11-O11)
B29: FY2026E | F29: =IF(E12-F12<0,0,E12-F12) | G29: =IF(F12-G12<0,0,F12-G12) | H29: =IF(G12-H12<0,0,G12-H12) | I29: =IF(H12-I12<0,0,H12-I12) | J29: =IF(I12-J12<0,0,I12-J12) | K29: =IF(J12-K12<0,0,J12-K12) | L29: =IF(K12-L12<0,0,K12-L12) | M29: =IF(L12-M12<0,0,L12-M12) | ... O29: =IF(N12-O12<0,0,N12-O12)
B30: FY2027E | G30: =IF(F13-G13<0,0,F13-G13) | H30: =IF(G13-H13<0,0,G13-H13) | I30: =IF(H13-I13<0,0,H13-I13) | J30: =IF(I13-J13<0,0,I13-J13) | K30: =IF(J13-K13<0,0,J13-K13) | L30: =IF(K13-L13<0,0,K13-L13) | M30: =IF(L13-M13<0,0,L13-M13) | N30: =IF(M13-N13<0,0,M13-N13) | O30: =IF(N13-O13<0,0,N13-O13)
B31: FY2028E | H31: =IF(G14-H14<0,0,G14-H14) | I31: =IF(H14-I14<0,0,H14-I14) | J31: =IF(I14-J14<0,0,I14-J14) | K31: =IF(J14-K14<0,0,J14-K14) | L31: =IF(K14-L14<0,0,K14-L14) | M31: =IF(L14-M14<0,0,L14-M14) | N31: =IF(M14-N14<0,0,M14-N14) | O31: =IF(N14-O14<0,0,N14-O14)
B32: FY2029E | I32: =IF(H15-I15<0,0,H15-I15) | J32: =IF(I15-J15<0,0,I15-J15) | K32: =IF(J15-K15<0,0,J15-K15) | L32: =IF(K15-L15<0,0,K15-L15) | M32: =IF(L15-M15<0,0,L15-M15) | N32: =IF(M15-N15<0,0,M15-N15) | O32: =IF(N15-O15<0,0,N15-O15)
B33: FY2030E | J33: =IF(I16-J16<0,0,I16-J16) | K33: =IF(J16-K16<0,0,J16-K16) | L33: =IF(K16-L16<0,0,K16-L16) | M33: =IF(L16-M16<0,0,L16-M16) | N33: =IF(M16-N16<0,0,M16-N16) | O33: =IF(N16-O16<0,0,N16-O16)
B34: FY2031E | K34: =IF(J17-K17<0,0,J17-K17) | L34: =IF(K17-L17<0,0,K17-L17) | M34: =IF(L17-M17<0,0,L17-M17) | N34: =IF(M17-N17<0,0,M17-N17) | O34: =IF(N17-O17<0,0,N17-O17)
B35: FY2032E | L35: =IF(K18-L18<0,0,K18-L18) | M35: =IF(L18-M18<0,0,L18-M18) | N35: =IF(M18-N18<0,0,M18-N18) | O35: =IF(N18-O18<0,0,N18-O18)
B36: FY2033E | M36: =IF(L19-M19<0,0,L19-M19) | N36: =IF(M19-N19<0,0,M19-N19) | O36: =IF(N19-O19<0,0,N19-O19)
B37: FY2034E | N37: =IF(M20-N20<0,0,M20-N20) | O37: =IF(N20-O20<0,0,N20-O20)
B38: FY2035E | O38: =IF(N21-O21<0,0,N21-O21)
B39: Total D&A on PP&E | E39: =SUM(E27:E38) | F39: =SUM(F27:F38) | G39: =SUM(G27:G38) | H39: =SUM(H27:H38) | I39: =SUM(I27:I38) | J39: =SUM(J27:J38) | K39: =SUM(K27:K38) | L39: =SUM(L27:L38) | ... O39: =SUM(O27:O38)
B42: Amortization of Intangibles
B43: Net Carrying Value of Intangibles | D43: =FORECAST_ASSUMPTIONS!$C$37 | E43: =D43-E45 | F43: =E43-F45 | G43: =F43-G45 | H43: =G43-H45 | I43: =H43-I45 | J43: =I43-J45 | K43: =J43-K45 | L43: =K43-L45 | ... O43: =N43-O45
B45: Amortization of Intangibles | E45: {=TRANSPOSE(FORECAST_ASSUMPTIONS!$C$38:$C$42)} | J45: =FORECAST_ASSUMPTIONS!$C$43/COUNTA($J$4:$O$4) | K45: =FORECAST_ASSUMPTIONS!$C$43/COUNTA($J$4:$O$4) | L45: =FORECAST_ASSUMPTIONS!$C$43/COUNTA($J$4:$O$4) | M45: =FORECAST_ASSUMPTIONS!$C$43/COUNTA($J$4:$O$4) | N45: =FORECAST_ASSUMPTIONS!$C$43/COUNTA($J$4:$O$4) | O45: =FORECAST_ASSUMPTIONS!$C$43/COUNTA($J$4:$O$4)
B48: Grand Total D&A
B49: D&A on PP&E | E49: =E39 | F49: =F39 | G49: =G39 | H49: =H39 | I49: =I39 | J49: =J39 | K49: =K39 | L49: =L39 | ... O49: =O39
B50: Amortization of Intangibles | E50: =E45 | F50: =F45 | G50: =G45 | H50: =H45 | I50: =I45 | J50: =J45 | K50: =K45 | L50: =L45 | ... O50: =O45
...
