Workbook

Sheet Company1153 Assumptions
B2: COMPANY1153 (Company0080) - OPERATING MODEL ASSUMPTIONS
B3: 3-Year Historical (2021-2023) | 5-Year Projections (2024-2028)
B5: SCENARIO SELECTION
B6: Selected Scenario: | D6: Base
B8: Historical | G8: Projections
D9: 2021 | E9: 2022 | F9: 2023 | G9: 2024 | H9: 2025 | I9: 2026 | J9: 2027 | K9: 2028
B11: 1. REVENUE ASSUMPTIONS
B13: Revenue Growth Rates (%)
C14: Scenario | D14: 2021 | E14: 2022 | F14: 2023 | G14: 2024 | H14: 2025 | I14: 2026 | J14: 2027 | K14: 2028
B15: Company1153 Search | C15: Base | G15: 0.085 | H15: 0.075 | I15: 0.065 | J15: 0.055 | K15: 0.05
C16: Bull | G16: 0.105 | H16: 0.095 | I16: 0.085 | J16: 0.075 | K16: 0.07
C17: Bear | G17: 0.06 | H17: 0.05 | I17: 0.04 | J17: 0.035 | K17: 0.03
B19: Product0476 Ads | C19: Base | G19: 0.15 | H19: 0.13 | I19: 0.11 | J19: 0.1 | K19: 0.09
C20: Bull | G20: 0.18 | H20: 0.16 | I20: 0.14 | J20: 0.12 | K20: 0.11
C21: Bear | G21: 0.12 | H21: 0.1 | I21: 0.08 | J21: 0.07 | K21: 0.06
B23: Company1153 Cloud | C23: Base | G23: 0.28 | H23: 0.25 | I23: 0.22 | J23: 0.2 | K23: 0.18
C24: Bull | G24: 0.32 | H24: 0.3 | I24: 0.27 | J24: 0.24 | K24: 0.22
C25: Bear | G25: 0.24 | H25: 0.2 | I25: 0.17 | J25: 0.15 | K25: 0.14
B27: Other Revenues | C27: Base | G27: 0.05 | H27: 0.045 | I27: 0.04 | J27: 0.035 | K27: 0.03
C28: Bull | G28: 0.07 | H28: 0.06 | I28: 0.055 | J28: 0.05 | K28: 0.045
C29: Bear | G29: 0.03 | H29: 0.025 | I29: 0.02 | J29: 0.015 | K29: 0.01
B31: 2. OPERATING EXPENSE ASSUMPTIONS
B33: Operating Expenses (% of Revenue)
B35: Research & Development | C35: Base | D35: 0.151 | E35: 0.148 | F35: 0.145 | G35: 0.143 | H35: 0.14 | I35: 0.138 | J35: 0.135 | K35: 0.133
C36: Bull | D36: 0.151 | E36: 0.148 | F36: 0.145 | G36: 0.138 | H36: 0.135 | I36: 0.132 | J36: 0.13 | K36: 0.128
C37: Bear | D37: 0.151 | E37: 0.148 | F37: 0.145 | G37: 0.148 | H37: 0.145 | I37: 0.143 | J37: 0.14 | K37: 0.138
B39: Sales & Marketing | C39: Base | D39: 0.115 | E39: 0.112 | F39: 0.108 | G39: 0.105 | H39: 0.103 | I39: 0.1 | J39: 0.098 | K39: 0.095
C40: Bull | D40: 0.115 | E40: 0.112 | F40: 0.108 | G40: 0.102 | H40: 0.1 | I40: 0.097 | J40: 0.095 | K40: 0.092
C41: Bear | D41: 0.115 | E41: 0.112 | F41: 0.108 | G41: 0.108 | H41: 0.106 | I41: 0.103 | J41: 0.101 | K41: 0.098
B43: General & Administrative | C43: Base | D43: 0.068 | E43: 0.065 | F43: 0.063 | G43: 0.062 | H43: 0.06 | I43: 0.058 | J43: 0.057 | K43: 0.055
C44: Bull | D44: 0.068 | E44: 0.065 | F44: 0.063 | G44: 0.06 | H44: 0.058 | I44: 0.056 | J44: 0.055 | K44: 0.053
C45: Bear | D45: 0.068 | E45: 0.065 | F45: 0.063 | G45: 0.064 | H45: 0.062 | I45: 0.06 | J45: 0.059 | K45: 0.057
B47: Stock-Based Compensation | C47: Base | D47: 0.092 | E47: 0.095 | F47: 0.098 | G47: 0.095 | H47: 0.093 | I47: 0.09 | J47: 0.088 | K47: 0.085
C48: Bull | D48: 0.092 | E48: 0.095 | F48: 0.098 | G48: 0.092 | H48: 0.09 | I48: 0.087 | J48: 0.085 | K48: 0.082
C49: Bear | D49: 0.092 | E49: 0.095 | F49: 0.098 | G49: 0.098 | H49: 0.096 | I49: 0.093 | J49: 0.091 | K49: 0.088
B51: 3. BALANCE SHEET & CASH FLOW ASSUMPTIONS
B53: Working Capital Metrics
B55: Days Sales Outstanding (DSO) | C55: Base | D55: 48 | E55: 47 | F55: 46 | G55: 46 | H55: 45 | I55: 45 | J55: 44 | K55: 44
C56: Bull | D56: 48 | E56: 47 | F56: 46 | G56: 45 | H56: 44 | I56: 43 | J56: 42 | K56: 42
C57: Bear | D57: 48 | E57: 47 | F57: 46 | G57: 47 | H57: 47 | I57: 46 | J57: 46 | K57: 45
...

Sheet Company1808 Assumptions
B2: COMPANY1809 - OPERATING MODEL ASSUMPTIONS
B3: 3-Year Historical (2021-2023) | 5-Year Projections (2024-2028)
B5: SCENARIO SELECTION
B6: Selected Scenario: | D6: Base
B8: Historical | G8: Projections
D9: 2021 | E9: 2022 | F9: 2023 | G9: 2024 | H9: 2025 | I9: 2026 | J9: 2027 | K9: 2028
B11: 1. REVENUE ASSUMPTIONS
B13: Revenue Growth Rates (%)
C14: Scenario | D14: 2021 | E14: 2022 | F14: 2023 | G14: 2024 | H14: 2025 | I14: 2026 | J14: 2027 | K14: 2028
B15: Family of Apps (FoA) | C15: Base | G15: 0.12 | H15: 0.1 | I15: 0.085 | J15: 0.075 | K15: 0.07
C16: Bull | G16: 0.14 | H16: 0.12 | I16: 0.105 | J16: 0.095 | K16: 0.09
C17: Bear | G17: 0.1 | H17: 0.08 | I17: 0.065 | J17: 0.055 | K17: 0.05
B19: Product0338 | C19: Base | G19: 0.25 | H19: 0.35 | I19: 0.45 | J19: 0.4 | K19: 0.35
C20: Bull | G20: 0.3 | H20: 0.45 | I20: 0.55 | J20: 0.5 | K20: 0.45
C21: Bear | G21: 0.2 | H21: 0.25 | I21: 0.35 | J21: 0.3 | K21: 0.25
B24: User Growth Metrics
B26: DAU Growth (%) | C26: Base | G26: 0.03 | H26: 0.025 | I26: 0.02 | J26: 0.015 | K26: 0.01
C27: Bull | G27: 0.04 | H27: 0.035 | I27: 0.03 | J27: 0.025 | K27: 0.02
C28: Bear | G28: 0.02 | H28: 0.015 | I28: 0.01 | J28: 0.005 | K28: 0
B30: ARPU Growth (%) | C30: Base | G30: 0.085 | H30: 0.07 | I30: 0.06 | J30: 0.055 | K30: 0.05
C31: Bull | G31: 0.1 | H31: 0.085 | I31: 0.075 | J31: 0.07 | K31: 0.065
C32: Bear | G32: 0.07 | H32: 0.055 | I32: 0.045 | J32: 0.04 | K32: 0.035
B34: 2. OPERATING EXPENSE ASSUMPTIONS
B36: Operating Expenses (% of Revenue)
B38: Research & Development | C38: Base | D38: 0.255 | E38: 0.27 | F38: 0.29 | G38: 0.285 | H38: 0.28 | I38: 0.275 | J38: 0.27 | K38: 0.265
C39: Bull | D39: 0.255 | E39: 0.27 | F39: 0.29 | G39: 0.28 | H39: 0.275 | I39: 0.27 | J39: 0.265 | K39: 0.26
C40: Bear | D40: 0.255 | E40: 0.27 | F40: 0.29 | G40: 0.29 | H40: 0.285 | I40: 0.28 | J40: 0.275 | K40: 0.27
B42: Sales & Marketing | C42: Base | D42: 0.118 | E42: 0.125 | F42: 0.13 | G42: 0.125 | H42: 0.12 | I42: 0.115 | J42: 0.11 | K42: 0.105
C43: Bull | D43: 0.118 | E43: 0.125 | F43: 0.13 | G43: 0.12 | H43: 0.115 | I43: 0.11 | J43: 0.105 | K43: 0.1
C44: Bear | D44: 0.118 | E44: 0.125 | F44: 0.13 | G44: 0.13 | H44: 0.125 | I44: 0.12 | J44: 0.115 | K44: 0.11
B46: General & Administrative | C46: Base | D46: 0.102 | E46: 0.108 | F46: 0.115 | G46: 0.11 | H46: 0.105 | I46: 0.1 | J46: 0.095 | K46: 0.09
C47: Bull | D47: 0.102 | E47: 0.108 | F47: 0.115 | G47: 0.105 | H47: 0.1 | I47: 0.095 | J47: 0.09 | K47: 0.085
C48: Bear | D48: 0.102 | E48: 0.108 | F48: 0.115 | G48: 0.115 | H48: 0.11 | I48: 0.105 | J48: 0.1 | K48: 0.095
B50: Stock-Based Compensation | C50: Base | D50: 0.085 | E50: 0.102 | F50: 0.118 | G50: 0.11 | H50: 0.105 | I50: 0.1 | J50: 0.095 | K50: 0.09
C51: Bull | D51: 0.085 | E51: 0.102 | F51: 0.118 | G51: 0.105 | H51: 0.1 | I51: 0.095 | J51: 0.09 | K51: 0.085
C52: Bear | D52: 0.085 | E52: 0.102 | F52: 0.118 | G52: 0.115 | H52: 0.11 | I52: 0.105 | J52: 0.1 | K52: 0.095
B54: 3. BALANCE SHEET & CASH FLOW ASSUMPTIONS
B56: Working Capital Metrics
B58: Days Sales Outstanding (DSO) | C58: Base | D58: 55 | E58: 53 | F58: 51 | G58: 50 | H58: 49 | I58: 48 | J58: 47 | K58: 46
C59: Bull | D59: 55 | E59: 53 | F59: 51 | G59: 49 | H59: 47 | I59: 46 | J59: 45 | K59: 44
...

Sheet Company1153 IS
B2: COMPANY1153 (Company0080) - INCOME STATEMENT
B3: $ in millions
B5: Selected Scenario: | D5: {='Company1153 Assumptions'!D6}
B7: Historical | F7: Projections
C8: 2021 | D8: 2022 | E8: 2023 | F8: 2024 | G8: 2025 | H8: 2026 | I8: 2027 | J8: 2028
B10: REVENUE
B12: Company1153 Search | C12: 148951 | D12: 162450 | E12: 175033 | F12: =E12*(1+INDEX('Company1153 Assumptions'!G$15:G$17,MATCH($D$5,'Company1153 Assumptions'!$C$15:$C$17,0))) | G12: =F12*(1+INDEX('Company1153 Assumptions'!H$15:H$17,MATCH($D$5,'Company1153 Assumptions'!$C$15:$C$17,0))) | H12: =G12*(1+INDEX('Company1153 Assumptions'!I$15:I$17,MATCH($D$5,'Company1153 Assumptions'!$C$15:$C$17,0))) | I12: =H12*(1+INDEX('Company1153 Assumptions'!J$15:J$17,MATCH($D$5,'Company1153 Assumptions'!$C$15:$C$17,0))) | J12: =I12*(1+INDEX('Company1153 Assumptions'!K$15:K$17,MATCH($D$5,'Company1153 Assumptions'!$C$15:$C$17,0)))
B13: Product0476 Ads | C13: 28845 | D13: 29243 | E13: 31865 | F13: =E13*(1+INDEX('Company1153 Assumptions'!G$19:G$21,MATCH($D$5,'Company1153 Assumptions'!$C$19:$C$21,0))) | G13: =F13*(1+INDEX('Company1153 Assumptions'!H$19:H$21,MATCH($D$5,'Company1153 Assumptions'!$C$19:$C$21,0))) | H13: =G13*(1+INDEX('Company1153 Assumptions'!I$19:I$21,MATCH($D$5,'Company1153 Assumptions'!$C$19:$C$21,0))) | I13: =H13*(1+INDEX('Company1153 Assumptions'!J$19:J$21,MATCH($D$5,'Company1153 Assumptions'!$C$19:$C$21,0))) | J13: =I13*(1+INDEX('Company1153 Assumptions'!K$19:K$21,MATCH($D$5,'Company1153 Assumptions'!$C$19:$C$21,0)))
B14: Company1153 Cloud | C14: 13059 | D14: 19206 | E14: 26280 | F14: =E14*(1+INDEX('Company1153 Assumptions'!G$23:G$25,MATCH($D$5,'Company1153 Assumptions'!$C$23:$C$25,0))) | G14: =F14*(1+INDEX('Company1153 Assumptions'!H$23:H$25,MATCH($D$5,'Company1153 Assumptions'!$C$23:$C$25,0))) | H14: =G14*(1+INDEX('Company1153 Assumptions'!I$23:I$25,MATCH($D$5,'Company1153 Assumptions'!$C$23:$C$25,0))) | I14: =H14*(1+INDEX('Company1153 Assumptions'!J$23:J$25,MATCH($D$5,'Company1153 Assumptions'!$C$23:$C$25,0))) | J14: =I14*(1+INDEX('Company1153 Assumptions'!K$23:K$25,MATCH($D$5,'Company1153 Assumptions'!$C$23:$C$25,0)))
B15: Other Revenues | C15: 28032 | D15: 29071 | E15: 30300 | F15: =E15*(1+INDEX('Company1153 Assumptions'!G$27:G$29,MATCH($D$5,'Company1153 Assumptions'!$C$27:$C$29,0))) | G15: =F15*(1+INDEX('Company1153 Assumptions'!H$27:H$29,MATCH($D$5,'Company1153 Assumptions'!$C$27:$C$29,0))) | H15: =G15*(1+INDEX('Company1153 Assumptions'!I$27:I$29,MATCH($D$5,'Company1153 Assumptions'!$C$27:$C$29,0))) | I15: =H15*(1+INDEX('Company1153 Assumptions'!J$27:J$29,MATCH($D$5,'Company1153 Assumptions'!$C$27:$C$29,0))) | J15: =I15*(1+INDEX('Company1153 Assumptions'!K$27:K$29,MATCH($D$5,'Company1153 Assumptions'!$C$27:$C$29,0)))
B16: Total Revenue | C16: =SUM(C12:C15) | D16: =SUM(D12:D15) | E16: =SUM(E12:E15) | F16: =SUM(F12:F15) | G16: =SUM(G12:G15) | H16: =SUM(H12:H15) | I16: =SUM(I12:I15) | J16: =SUM(J12:J15)
B17: YoY Growth % | D17: =D16/C16-1 | E17: =E16/D16-1 | F17: =F16/E16-1 | G17: =G16/F16-1 | H17: =H16/G16-1 | I17: =I16/H16-1 | J17: =J16/I16-1
B19: OPERATING EXPENSES
B21: Cost of Revenue | C21: =C16*(1-C23) | D21: =D16*(1-D23) | E21: =E16*(1-E23) | F21: =F16*(1-F23) | G21: =G16*(1-G23) | H21: =H16*(1-H23) | I21: =I16*(1-I23) | J21: =J16*(1-J23)
B22: Gross Profit | C22: =C16-C21 | D22: =D16-D21 | E22: =E16-E21 | F22: =F16-F21 | G22: =G16-G21 | H22: =H16-H21 | I22: =I16-I21 | J22: =J16-J21
B23: Gross Margin % | C23: 0.545 | D23: 0.548 | E23: 0.55 | F23: 0.552 | G23: 0.554 | H23: 0.556 | I23: 0.558 | J23: 0.56
B25: Research & Development | C25: =C16*INDEX('Company1153 Assumptions'!D$35:D$37,MATCH($D$5,'Company1153 Assumptions'!$C$35:$C$37,0)) | D25: =D16*INDEX('Company1153 Assumptions'!E$35:E$37,MATCH($D$5,'Company1153 Assumptions'!$C$35:$C$37,0)) | E25: =E16*INDEX('Company1153 Assumptions'!F$35:F$37,MATCH($D$5,'Company1153 Assumptions'!$C$35:$C$37,0)) | F25: =F16*INDEX('Company1153 Assumptions'!G$35:G$37,MATCH($D$5,'Company1153 Assumptions'!$C$35:$C$37,0)) | G25: =G16*INDEX('Company1153 Assumptions'!H$35:H$37,MATCH($D$5,'Company1153 Assumptions'!$C$35:$C$37,0)) | H25: =H16*INDEX('Company1153 Assumptions'!I$35:I$37,MATCH($D$5,'Company1153 Assumptions'!$C$35:$C$37,0)) | I25: =I16*INDEX('Company1153 Assumptions'!J$35:J$37,MATCH($D$5,'Company1153 Assumptions'!$C$35:$C$37,0)) | J25: =J16*INDEX('Company1153 Assumptions'!K$35:K$37,MATCH($D$5,'Company1153 Assumptions'!$C$35:$C$37,0))
B26: Sales & Marketing | C26: =C16*INDEX('Company1153 Assumptions'!D$39:D$41,MATCH($D$5,'Company1153 Assumptions'!$C$39:$C$41,0)) | D26: =D16*INDEX('Company1153 Assumptions'!E$39:E$41,MATCH($D$5,'Company1153 Assumptions'!$C$39:$C$41,0)) | E26: =E16*INDEX('Company1153 Assumptions'!F$39:F$41,MATCH($D$5,'Company1153 Assumptions'!$C$39:$C$41,0)) | F26: =F16*INDEX('Company1153 Assumptions'!G$39:G$41,MATCH($D$5,'Company1153 Assumptions'!$C$39:$C$41,0)) | G26: =G16*INDEX('Company1153 Assumptions'!H$39:H$41,MATCH($D$5,'Company1153 Assumptions'!$C$39:$C$41,0)) | H26: =H16*INDEX('Company1153 Assumptions'!I$39:I$41,MATCH($D$5,'Company1153 Assumptions'!$C$39:$C$41,0)) | I26: =I16*INDEX('Company1153 Assumptions'!J$39:J$41,MATCH($D$5,'Company1153 Assumptions'!$C$39:$C$41,0)) | J26: =J16*INDEX('Company1153 Assumptions'!K$39:K$41,MATCH($D$5,'Company1153 Assumptions'!$C$39:$C$41,0))
B27: General & Administrative | C27: =C16*INDEX('Company1153 Assumptions'!D$43:D$45,MATCH($D$5,'Company1153 Assumptions'!$C$43:$C$45,0)) | D27: =D16*INDEX('Company1153 Assumptions'!E$43:E$45,MATCH($D$5,'Company1153 Assumptions'!$C$43:$C$45,0)) | E27: =E16*INDEX('Company1153 Assumptions'!F$43:F$45,MATCH($D$5,'Company1153 Assumptions'!$C$43:$C$45,0)) | F27: =F16*INDEX('Company1153 Assumptions'!G$43:G$45,MATCH($D$5,'Company1153 Assumptions'!$C$43:$C$45,0)) | G27: =G16*INDEX('Company1153 Assumptions'!H$43:H$45,MATCH($D$5,'Company1153 Assumptions'!$C$43:$C$45,0)) | H27: =H16*INDEX('Company1153 Assumptions'!I$43:I$45,MATCH($D$5,'Company1153 Assumptions'!$C$43:$C$45,0)) | I27: =I16*INDEX('Company1153 Assumptions'!J$43:J$45,MATCH($D$5,'Company1153 Assumptions'!$C$43:$C$45,0)) | J27: =J16*INDEX('Company1153 Assumptions'!K$43:K$45,MATCH($D$5,'Company1153 Assumptions'!$C$43:$C$45,0))
B28: Stock-Based Compensation | C28: =C16*INDEX('Company1153 Assumptions'!D$47:D$49,MATCH($D$5,'Company1153 Assumptions'!$C$47:$C$49,0)) | D28: =D16*INDEX('Company1153 Assumptions'!E$47:E$49,MATCH($D$5,'Company1153 Assumptions'!$C$47:$C$49,0)) | E28: =E16*INDEX('Company1153 Assumptions'!F$47:F$49,MATCH($D$5,'Company1153 Assumptions'!$C$47:$C$49,0)) | F28: =F16*INDEX('Company1153 Assumptions'!G$47:G$49,MATCH($D$5,'Company1153 Assumptions'!$C$47:$C$49,0)) | G28: =G16*INDEX('Company1153 Assumptions'!H$47:H$49,MATCH($D$5,'Company1153 Assumptions'!$C$47:$C$49,0)) | H28: =H16*INDEX('Company1153 Assumptions'!I$47:I$49,MATCH($D$5,'Company1153 Assumptions'!$C$47:$C$49,0)) | I28: =I16*INDEX('Company1153 Assumptions'!J$47:J$49,MATCH($D$5,'Company1153 Assumptions'!$C$47:$C$49,0)) | J28: =J16*INDEX('Company1153 Assumptions'!K$47:K$49,MATCH($D$5,'Company1153 Assumptions'!$C$47:$C$49,0))
B29: Total Operating Expenses | C29: =SUM(C25:C28) | D29: =SUM(D25:D28) | E29: =SUM(E25:E28) | F29: =SUM(F25:F28) | G29: =SUM(G25:G28) | H29: =SUM(H25:H28) | I29: =SUM(I25:I28) | J29: =SUM(J25:J28)
B31: Operating Income (EBIT) | C31: =C22-C29 | D31: =D22-D29 | E31: =E22-E29 | F31: =F22-F29 | G31: =G22-G29 | H31: =H22-H29 | I31: =I22-I29 | J31: =J22-J29
B32: Operating Margin % | C32: =C31/C16 | D32: =D31/D16 | E32: =E31/E16 | F32: =F31/F16 | G32: =G31/G16 | H32: =H31/H16 | I32: =I31/I16 | J32: =J31/J16
B34: Interest Income | C34: =100000*INDEX('Company1153 Assumptions'!$D$85:$D$87,MATCH($D$5,'Company1153 Assumptions'!$C$85:$C$87,0)) | D34: =100000*INDEX('Company1153 Assumptions'!$E$85:$E$87,MATCH($D$5,'Company1153 Assumptions'!$C$85:$C$87,0)) | E34: =100000*INDEX('Company1153 Assumptions'!$F$85:$F$87,MATCH($D$5,'Company1153 Assumptions'!$C$85:$C$87,0)) | F34: =110000*INDEX('Company1153 Assumptions'!$G$85:$G$87,MATCH($D$5,'Company1153 Assumptions'!$C$85:$C$87,0)) | G34: =120000*INDEX('Company1153 Assumptions'!$H$85:$H$87,MATCH($D$5,'Company1153 Assumptions'!$C$85:$C$87,0)) | H34: =130000*INDEX('Company1153 Assumptions'!$I$85:$I$87,MATCH($D$5,'Company1153 Assumptions'!$C$85:$C$87,0)) | I34: =140000*INDEX('Company1153 Assumptions'!$J$85:$J$87,MATCH($D$5,'Company1153 Assumptions'!$C$85:$C$87,0)) | J34: =150000*INDEX('Company1153 Assumptions'!$K$85:$K$87,MATCH($D$5,'Company1153 Assumptions'!$C$85:$C$87,0))
B36: Income Before Tax | C36: =C31+C34 | D36: =D31+D34 | E36: =E31+E34 | F36: =F31+F34 | G36: =G31+G34 | H36: =H31+H34 | I36: =I31+I34 | J36: =J31+J34
B37: Tax Provision | C37: =C36*INDEX('Company1153 Assumptions'!D$78:D$80,MATCH($D$5,'Company1153 Assumptions'!$C$78:$C$80,0)) | D37: =D36*INDEX('Company1153 Assumptions'!E$78:E$80,MATCH($D$5,'Company1153 Assumptions'!$C$78:$C$80,0)) | E37: =E36*INDEX('Company1153 Assumptions'!F$78:F$80,MATCH($D$5,'Company1153 Assumptions'!$C$78:$C$80,0)) | F37: =F36*INDEX('Company1153 Assumptions'!G$78:G$80,MATCH($D$5,'Company1153 Assumptions'!$C$78:$C$80,0)) | G37: =G36*INDEX('Company1153 Assumptions'!H$78:H$80,MATCH($D$5,'Company1153 Assumptions'!$C$78:$C$80,0)) | H37: =H36*INDEX('Company1153 Assumptions'!I$78:I$80,MATCH($D$5,'Company1153 Assumptions'!$C$78:$C$80,0)) | I37: =I36*INDEX('Company1153 Assumptions'!J$78:J$80,MATCH($D$5,'Company1153 Assumptions'!$C$78:$C$80,0)) | J37: =J36*INDEX('Company1153 Assumptions'!K$78:K$80,MATCH($D$5,'Company1153 Assumptions'!$C$78:$C$80,0))
B39: NET INCOME | C39: =C36-C37 | D39: =D36-D37 | E39: =E36-E37 | F39: =F36-F37 | G39: =G36-G37 | H39: =H36-H37 | I39: =I36-I37 | J39: =J36-J37
B40: Net Margin % | C40: =C39/C16 | D40: =D39/D16 | E40: =E39/E16 | F40: =F39/F16 | G40: =G39/G16 | H40: =H39/H16 | I40: =I39/I16 | J40: =J39/J16
B42: EARNINGS PER SHARE
B44: Basic Shares Outstanding | C44: 13000 | D44: 12800 | E44: 12600 | F44: 12400 | G44: 12200 | H44: 12000 | I44: 11800 | J44: 11600
B45: Basic EPS | C45: =C39/C44 | D45: =D39/D44 | E45: =E39/E44 | F45: =F39/F44 | G45: =G39/G44 | H45: =H39/H44 | I45: =I39/I44 | J45: =J39/J44

Sheet Company1808 IS
B2: COMPANY1809 - INCOME STATEMENT
B3: $ in millions
B5: Selected Scenario: | D5: {='Company1808 Assumptions'!D6}
B7: Historical | F7: Projections
C8: 2021 | D8: 2022 | E8: 2023 | F8: 2024 | G8: 2025 | H8: 2026 | I8: 2027 | J8: 2028
B10: REVENUE
B12: Family of Apps | C12: 115655 | D12: 114450 | E12: 133008 | F12: =E12*(1+INDEX('Company1808 Assumptions'!G$15:G$17,MATCH($D$5,'Company1808 Assumptions'!$C$15:$C$17,0))) | G12: =F12*(1+INDEX('Company1808 Assumptions'!H$15:H$17,MATCH($D$5,'Company1808 Assumptions'!$C$15:$C$17,0))) | H12: =G12*(1+INDEX('Company1808 Assumptions'!I$15:I$17,MATCH($D$5,'Company1808 Assumptions'!$C$15:$C$17,0))) | I12: =H12*(1+INDEX('Company1808 Assumptions'!J$15:J$17,MATCH($D$5,'Company1808 Assumptions'!$C$15:$C$17,0))) | J12: =I12*(1+INDEX('Company1808 Assumptions'!K$15:K$17,MATCH($D$5,'Company1808 Assumptions'!$C$15:$C$17,0)))
B13: Product0338 | C13: 2274 | D13: 2159 | E13: 1896 | F13: =E13*(1+INDEX('Company1808 Assumptions'!G$19:G$21,MATCH($D$5,'Company1808 Assumptions'!$C$19:$C$21,0))) | G13: =F13*(1+INDEX('Company1808 Assumptions'!H$19:H$21,MATCH($D$5,'Company1808 Assumptions'!$C$19:$C$21,0))) | H13: =G13*(1+INDEX('Company1808 Assumptions'!I$19:I$21,MATCH($D$5,'Company1808 Assumptions'!$C$19:$C$21,0))) | I13: =H13*(1+INDEX('Company1808 Assumptions'!J$19:J$21,MATCH($D$5,'Company1808 Assumptions'!$C$19:$C$21,0))) | J13: =I13*(1+INDEX('Company1808 Assumptions'!K$19:K$21,MATCH($D$5,'Company1808 Assumptions'!$C$19:$C$21,0)))
B14: Total Revenue | C14: =SUM(C12:C13) | D14: =SUM(D12:D13) | E14: =SUM(E12:E13) | F14: =SUM(F12:F13) | G14: =SUM(G12:G13) | H14: =SUM(H12:H13) | I14: =SUM(I12:I13) | J14: =SUM(J12:J13)
B15: YoY Growth % | D15: =D14/C14-1 | E15: =E14/D14-1 | F15: =F14/E14-1 | G15: =G14/F14-1 | H15: =H14/G14-1 | I15: =I14/H14-1 | J15: =J14/I14-1
B17: OPERATING EXPENSES
B19: Cost of Revenue | C19: =C14*(1-C21) | D19: =D14*(1-D21) | E19: =E14*(1-E21) | F19: =F14*(1-F21) | G19: =G14*(1-G21) | H19: =H14*(1-H21) | I19: =I14*(1-I21) | J19: =J14*(1-J21)
B20: Gross Profit | C20: =C14-C19 | D20: =D14-D19 | E20: =E14-E19 | F20: =F14-F19 | G20: =G14-G19 | H20: =H14-H19 | I20: =I14-I19 | J20: =J14-J19
B21: Gross Margin % | C21: 0.802 | D21: 0.798 | E21: 0.795 | F21: 0.797 | G21: 0.799 | H21: 0.801 | I21: 0.803 | J21: 0.805
B23: Research & Development | C23: =C14*INDEX('Company1808 Assumptions'!D$38:D$40,MATCH($D$5,'Company1808 Assumptions'!$C$38:$C$40,0)) | D23: =D14*INDEX('Company1808 Assumptions'!E$38:E$40,MATCH($D$5,'Company1808 Assumptions'!$C$38:$C$40,0)) | E23: =E14*INDEX('Company1808 Assumptions'!F$38:F$40,MATCH($D$5,'Company1808 Assumptions'!$C$38:$C$40,0)) | F23: =F14*INDEX('Company1808 Assumptions'!G$38:G$40,MATCH($D$5,'Company1808 Assumptions'!$C$38:$C$40,0)) | G23: =G14*INDEX('Company1808 Assumptions'!H$38:H$40,MATCH($D$5,'Company1808 Assumptions'!$C$38:$C$40,0)) | H23: =H14*INDEX('Company1808 Assumptions'!I$38:I$40,MATCH($D$5,'Company1808 Assumptions'!$C$38:$C$40,0)) | I23: =I14*INDEX('Company1808 Assumptions'!J$38:J$40,MATCH($D$5,'Company1808 Assumptions'!$C$38:$C$40,0)) | J23: =J14*INDEX('Company1808 Assumptions'!K$38:K$40,MATCH($D$5,'Company1808 Assumptions'!$C$38:$C$40,0))
B24: Sales & Marketing | C24: =C14*INDEX('Company1808 Assumptions'!D$42:D$44,MATCH($D$5,'Company1808 Assumptions'!$C$42:$C$44,0)) | D24: =D14*INDEX('Company1808 Assumptions'!E$42:E$44,MATCH($D$5,'Company1808 Assumptions'!$C$42:$C$44,0)) | E24: =E14*INDEX('Company1808 Assumptions'!F$42:F$44,MATCH($D$5,'Company1808 Assumptions'!$C$42:$C$44,0)) | F24: =F14*INDEX('Company1808 Assumptions'!G$42:G$44,MATCH($D$5,'Company1808 Assumptions'!$C$42:$C$44,0)) | G24: =G14*INDEX('Company1808 Assumptions'!H$42:H$44,MATCH($D$5,'Company1808 Assumptions'!$C$42:$C$44,0)) | H24: =H14*INDEX('Company1808 Assumptions'!I$42:I$44,MATCH($D$5,'Company1808 Assumptions'!$C$42:$C$44,0)) | I24: =I14*INDEX('Company1808 Assumptions'!J$42:J$44,MATCH($D$5,'Company1808 Assumptions'!$C$42:$C$44,0)) | J24: =J14*INDEX('Company1808 Assumptions'!K$42:K$44,MATCH($D$5,'Company1808 Assumptions'!$C$42:$C$44,0))
B25: General & Administrative | C25: =C14*INDEX('Company1808 Assumptions'!D$46:D$48,MATCH($D$5,'Company1808 Assumptions'!$C$46:$C$48,0)) | D25: =D14*INDEX('Company1808 Assumptions'!E$46:E$48,MATCH($D$5,'Company1808 Assumptions'!$C$46:$C$48,0)) | E25: =E14*INDEX('Company1808 Assumptions'!F$46:F$48,MATCH($D$5,'Company1808 Assumptions'!$C$46:$C$48,0)) | F25: =F14*INDEX('Company1808 Assumptions'!G$46:G$48,MATCH($D$5,'Company1808 Assumptions'!$C$46:$C$48,0)) | G25: =G14*INDEX('Company1808 Assumptions'!H$46:H$48,MATCH($D$5,'Company1808 Assumptions'!$C$46:$C$48,0)) | H25: =H14*INDEX('Company1808 Assumptions'!I$46:I$48,MATCH($D$5,'Company1808 Assumptions'!$C$46:$C$48,0)) | I25: =I14*INDEX('Company1808 Assumptions'!J$46:J$48,MATCH($D$5,'Company1808 Assumptions'!$C$46:$C$48,0)) | J25: =J14*INDEX('Company1808 Assumptions'!K$46:K$48,MATCH($D$5,'Company1808 Assumptions'!$C$46:$C$48,0))
B26: Stock-Based Compensation | C26: =C14*INDEX('Company1808 Assumptions'!D$50:D$52,MATCH($D$5,'Company1808 Assumptions'!$C$50:$C$52,0)) | D26: =D14*INDEX('Company1808 Assumptions'!E$50:E$52,MATCH($D$5,'Company1808 Assumptions'!$C$50:$C$52,0)) | E26: =E14*INDEX('Company1808 Assumptions'!F$50:F$52,MATCH($D$5,'Company1808 Assumptions'!$C$50:$C$52,0)) | F26: =F14*INDEX('Company1808 Assumptions'!G$50:G$52,MATCH($D$5,'Company1808 Assumptions'!$C$50:$C$52,0)) | G26: =G14*INDEX('Company1808 Assumptions'!H$50:H$52,MATCH($D$5,'Company1808 Assumptions'!$C$50:$C$52,0)) | H26: =H14*INDEX('Company1808 Assumptions'!I$50:I$52,MATCH($D$5,'Company1808 Assumptions'!$C$50:$C$52,0)) | I26: =I14*INDEX('Company1808 Assumptions'!J$50:J$52,MATCH($D$5,'Company1808 Assumptions'!$C$50:$C$52,0)) | J26: =J14*INDEX('Company1808 Assumptions'!K$50:K$52,MATCH($D$5,'Company1808 Assumptions'!$C$50:$C$52,0))
B27: Total Operating Expenses | C27: =SUM(C23:C26) | D27: =SUM(D23:D26) | E27: =SUM(E23:E26) | F27: =SUM(F23:F26) | G27: =SUM(G23:G26) | H27: =SUM(H23:H26) | I27: =SUM(I23:I26) | J27: =SUM(J23:J26)
B29: Operating Income (EBIT) | C29: =C20-C27 | D29: =D20-D27 | E29: =E20-E27 | F29: =F20-F27 | G29: =G20-G27 | H29: =H20-H27 | I29: =I20-I27 | J29: =J20-J27
B30: Operating Margin % | C30: =C29/C14 | D30: =D29/D14 | E30: =E29/E14 | F30: =F29/F14 | G30: =G29/G14 | H30: =H29/H14 | I30: =I29/I14 | J30: =J29/J14
B32: Interest Income | C32: =40000*INDEX('Company1808 Assumptions'!$D$88:$D$90,MATCH($D$5,'Company1808 Assumptions'!$C$88:$C$90,0)) | D32: =40000*INDEX('Company1808 Assumptions'!$E$88:$E$90,MATCH($D$5,'Company1808 Assumptions'!$C$88:$C$90,0)) | E32: =40000*INDEX('Company1808 Assumptions'!$F$88:$F$90,MATCH($D$5,'Company1808 Assumptions'!$C$88:$C$90,0)) | F32: =45000*INDEX('Company1808 Assumptions'!$G$88:$G$90,MATCH($D$5,'Company1808 Assumptions'!$C$88:$C$90,0)) | G32: =50000*INDEX('Company1808 Assumptions'!$H$88:$H$90,MATCH($D$5,'Company1808 Assumptions'!$C$88:$C$90,0)) | H32: =55000*INDEX('Company1808 Assumptions'!$I$88:$I$90,MATCH($D$5,'Company1808 Assumptions'!$C$88:$C$90,0)) | I32: =60000*INDEX('Company1808 Assumptions'!$J$88:$J$90,MATCH($D$5,'Company1808 Assumptions'!$C$88:$C$90,0)) | J32: =65000*INDEX('Company1808 Assumptions'!$K$88:$K$90,MATCH($D$5,'Company1808 Assumptions'!$C$88:$C$90,0))
B34: Income Before Tax | C34: =C29+C32 | D34: =D29+D32 | E34: =E29+E32 | F34: =F29+F32 | G34: =G29+G32 | H34: =H29+H32 | I34: =I29+I32 | J34: =J29+J32
B35: Tax Provision | C35: =C34*INDEX('Company1808 Assumptions'!D$81:D$83,MATCH($D$5,'Company1808 Assumptions'!$C$81:$C$83,0)) | D35: =D34*INDEX('Company1808 Assumptions'!E$81:E$83,MATCH($D$5,'Company1808 Assumptions'!$C$81:$C$83,0)) | E35: =E34*INDEX('Company1808 Assumptions'!F$81:F$83,MATCH($D$5,'Company1808 Assumptions'!$C$81:$C$83,0)) | F35: =F34*INDEX('Company1808 Assumptions'!G$81:G$83,MATCH($D$5,'Company1808 Assumptions'!$C$81:$C$83,0)) | G35: =G34*INDEX('Company1808 Assumptions'!H$81:H$83,MATCH($D$5,'Company1808 Assumptions'!$C$81:$C$83,0)) | H35: =H34*INDEX('Company1808 Assumptions'!I$81:I$83,MATCH($D$5,'Company1808 Assumptions'!$C$81:$C$83,0)) | I35: =I34*INDEX('Company1808 Assumptions'!J$81:J$83,MATCH($D$5,'Company1808 Assumptions'!$C$81:$C$83,0)) | J35: =J34*INDEX('Company1808 Assumptions'!K$81:K$83,MATCH($D$5,'Company1808 Assumptions'!$C$81:$C$83,0))
B37: NET INCOME | C37: =C34-C35 | D37: =D34-D35 | E37: =E34-E35 | F37: =F34-F35 | G37: =G34-G35 | H37: =H34-H35 | I37: =I34-I35 | J37: =J34-J35
B38: Net Margin % | C38: =C37/C14 | D38: =D37/D14 | E38: =E37/E14 | F38: =F37/F14 | G38: =G37/G14 | H38: =H37/H14 | I38: =I37/I14 | J38: =J37/J14
B40: EARNINGS PER SHARE
B42: Basic Shares Outstanding | C42: 2800 | D42: 2750 | E42: 2700 | F42: 2650 | G42: 2600 | H42: 2550 | I42: 2500 | J42: 2450
B43: Basic EPS | C43: =C37/C42 | D43: =D37/D42 | E43: =E37/E42 | F43: =F37/F42 | G43: =G37/G42 | H43: =H37/H42 | I43: =I37/I42 | J43: =J37/J42
