Workbook
Name Ccy: Inputs!$C$17
Name circ: Inputs!$C$20
Name CoName: Inputs!$C$15
Name ExitMultiple: Sensitivity!$E$6
Name IQ_CH: 110000
Name IQ_CQ: 5000
Name IQ_CY: 10000
Name IQ_DAILY: 500000
Name IQ_FH: 100000
Name IQ_FQ: 500
Name IQ_FY: 1000
Name IQ_LTM: 2000
Name IQ_MONTH: 15000
Name IQ_NTM: 6000
Name IQ_WEEK: 50000
Name IQ_YTD: 3000
Name OpCase: Sensitivity!$E$5
Name Premium: Sensitivity!$E$4
Name Units: Inputs!$C$18

Sheet Inputs
A1: Deal Structuring Training
A2: LBO modeling
A4: Special features
B6: Integrated LBO model
B7: Circular reference switch
B8: Sources and uses of funds
B9: Debt schedule
B10: Income statement, balance sheet, and cash flow statement
B11: Sensitivity analysis
A13: Model information
B15: Company name | C15: Company2272
B16: Latest BS date | C16: 42369
B17: Currency | C17: $
B18: Units | C18: m
B19: Analyst name | C19: Your name
B20: Circular switch | C20: 1

Sheet S&U
A1: =CoName -> Company2272
A2: =Ccy&Units&" unless otherwise stated" -> $m unless otherwise stated
A4: Acquisition analysis and assumptions
A6: Offer price | G6: =B13 -> Net shares to dilutive instruments | J6: Options | K6: RSU
B7: Unaffected share price | E7: 23.19 | F7: =Ccy -> $ | G7: Options outstanding | J7: 4.5 | K7: 5.4 | L7: =Units -> m
B8: Premium paid | E8: 0.38 | G8: Options strike price | J8: 37.34 | K8: 0 | L8: =Ccy -> $
B9: Acquisition price | E9: =E7*(1+Premium) -> 32.0022 | F9: =Ccy -> $ | G9: Net new shares | J9: =MAX(0,$E$9-J8)*J7/$E$9 -> 0 | K9: =MAX(0,$E$9-K8)*K7/$E$9 -> 5.4 | L9: =Units -> m
A11: Acquisition equity value | G11: Fee assumptions
B12: Basic shares outstanding | E12: 125.80522 | F12: =Units -> m | G12: Debt financing fees % debt issued | J12: 0.02
B13: Net shares to dilutive instruments | E13: =SUM(J9:K9) -> 5.4 | F13: =Units -> m | G13: Debt financing fees amortization (yrs) | J13: 6
B14: Diluted shares outstanding | E14: =SUM(E12:E13) -> 131.20522 | F14: =Units -> m | G14: Advisory fees % acquisition EV | J14: 0.015
B15: Acquisition equity value | E15: =E9*E14 -> 4198.8557
G16: Ownership structure | J16: % on entry | K16: % on exit
A17: Acquisition valuation bridge | G17: Mezzanine | J17: 0 | K17: 0.01
B18: Acquisition equity value | E18: =E15 -> 4198.8557 | G18: Management | J18: 0.01 | K18: 0.03
B19: Existing net debt (from latest balance sheet) | E19: =BS!C18+BS!C19+BS!C24-BS!C7 -> 9.6 | G19: Institutions | J19: =1-SUM(J17:J18) -> 0.99 | K19: =1-SUM(K17:K18) -> 0.96
B20: Acquisition enterprise value | E20: =E18+E19 -> 4208.4557
A22: Acquisition multiples
B23: LTM EBITDA | E23: =OpMod!E78 -> 599.9
B24: LTM EBITDA multiple | E24: =$E$20/E23 -> 7.015262
A26: Sources and uses of funds
A28: Uses of funds
B29: Acquisition equity value | C29: =E18 -> 4198.8557
B30: Refinanced debt
B31: Short-term debt | C31: =BS!C18+BS!C19 -> 1.7
B32: Long-term debt | C32: =BS!C24 -> 492.6
B33: Financing fees | C33: =SUM('S&U'!C41:C44)*J12 -> 64
B34: Advisory fees | C34: =E20*J14 -> 63.126835
B35: Total uses of funds | C35: =SUM(C29:C34) -> 4820.2825
A37: Sources of funds | E37: Analysis of sources of funds
G38: % of total | H38: Debt/EBITDA | I38: Swap rate | J38: Spread | K38: Interest rate | L38: Average life | M38: Year paid off
B39: Target cash | C39: =BS!C7 -> 484.7 | E39: =B39 -> Target cash | G39: =C39/$C$35 -> 0.10055427 | K39: 0.01
B40: Revolver | C40: 0 | E40: =B40 -> Revolver | G40: =C40/$C$35 -> 0 | I40: 0.0055 | J40: 0.03 | K40: =I40+J40 -> 0.0355
B41: Term debt A | C41: 1200 | E41: =B41 -> Term debt A | G41: =C41/$C$35 -> 0.24894806 | H41: =SUM($C$41:C41)/$E$23 -> 2.0003334 | I41: 0.0184 | J41: 0.04 | K41: =I41+J41 -> 0.0584 | L41: =IFERROR(SUMPRODUCT(FS!F78:O78,Returns!F9:O9)/-'S&U'!C41,"nm") -> 4.8544874 | M41: =COUNTIF(Debt!E82:O82,">0") -> 7
B42: Term debt B | C42: 900 | E42: =B42 -> Term debt B | G42: =C42/$C$35 -> 0.18671105 | H42: =SUM($C$41:C42)/$E$23 -> 3.5005834 | I42: 0.0236 | J42: 0.045 | K42: =I42+J42 -> 0.0686 | M42: =COUNTIF(Debt!E83:O83,">0") -> 8
B43: High yield | C43: 600 | E43: =B43 -> High yield | G43: =C43/$C$35 -> 0.12447403 | H43: =SUM($C$41:C43)/$E$23 -> 4.5007501 | K43: 0.08625 | M43: =COUNTIF(Debt!E84:O84,">0") -> 10
B44: Mezzanine (PIK) | C44: 500 | E44: =B44 -> Mezzanine (PIK) | G44: =C44/$C$35 -> 0.10372836 | H44: =SUM($C$41:C44)/$E$23 -> 5.3342224 | I44: 0.0281 | J44: 0.1 | K44: =I44+J44 -> 0.1281 | M44: =COUNTIF(Debt!E85:O85,">0") -> 10
B45: Shareholder Loan (PIK) | C45: =C35-SUM(C39:C44,C46) -> 535.58253 | E45: =B45 -> Shareholder Loan (PIK) | G45: =C45/$C$35 -> 0.11111019 | K45: 0.15
B46: Ordinary shares | C46: 600 | E46: =B46 -> Ordinary shares | G46: =C46/$C$35 -> 0.12447403
B47: Total sources | C47: =SUM(C39:C46) -> 4820.2825 | E47: =B47 -> Total sources | G47: =SUM(G39:G46) -> 1

Sheet OpMod
A1: =CoName -> Company2272 | C1: Hist. | D1: Hist. | E1: Hist. | F1: Proj. | G1: Proj. | H1: Proj. | I1: Proj. | J1: Proj. | K1: Proj. | L1: Proj. | M1: Proj. | N1: Proj. | O1: Proj.
A2: =Ccy&Units&" unless otherwise stated" -> $m unless otherwise stated | C2: =DATE(YEAR(D2)-1,MONTH(D2),DAY(D2)) -> 41639 | D2: =DATE(YEAR(E2)-1,MONTH(E2),DAY(E2)) -> 42004 | E2: =Inputs!C16 -> 42369 | F2: =DATE(YEAR(E2)+1,MONTH(E2),DAY(E2)) -> 42735 | G2: =DATE(YEAR(F2)+1,MONTH(F2),DAY(F2)) -> 43100 | H2: =DATE(YEAR(G2)+1,MONTH(G2),DAY(G2)) -> 43465 | I2: =DATE(YEAR(H2)+1,MONTH(H2),DAY(H2)) -> 43830 | J2: =DATE(YEAR(I2)+1,MONTH(I2),DAY(I2)) -> 44196 | K2: =DATE(YEAR(J2)+1,MONTH(J2),DAY(J2)) -> 44561 | L2: =DATE(YEAR(K2)+1,MONTH(K2),DAY(K2)) -> 44926 | M2: =DATE(YEAR(L2)+1,MONTH(L2),DAY(L2)) -> 45291 | ... O2: =DATE(YEAR(N2)+1,MONTH(N2),DAY(N2)) -> 46022
A4: =CHOOSE(OpCase,A27,A50) -> Operating model assumptions - Base case
A6: Case | C6: 1
A8: Income statement
B9: Sales growth | D9: =D76/C76-1 -> 0.16914256 | E9: =E76/D76-1 -> 0.11530317 | F9: =CHOOSE(OpCase,F32,F55) -> 0.115 | G9: =CHOOSE(OpCase,G32,G55) -> 0.1 | H9: =CHOOSE(OpCase,H32,H55) -> 0.09 | I9: =CHOOSE(OpCase,I32,I55) -> 0.08 | J9: =CHOOSE(OpCase,J32,J55) -> 0.07 | K9: =CHOOSE(OpCase,K32,K55) -> 0.06 | L9: =CHOOSE(OpCase,L32,L55) -> 0.05 | M9: =CHOOSE(OpCase,M32,M55) -> 0.04 | ... O9: =CHOOSE(OpCase,O32,O55) -> 0.03
B10: EBITDA margin | C10: =C78/C76 -> 0.28922335 | D10: =D78/D76 -> 0.29547481 | E10: =E78/E76 -> 0.29975516 | F10: =CHOOSE(OpCase,F33,F56) -> 0.33 | G10: =CHOOSE(OpCase,G33,G56) -> 0.33 | H10: =CHOOSE(OpCase,H33,H56) -> 0.33 | I10: =CHOOSE(OpCase,I33,I56) -> 0.33 | J10: =CHOOSE(OpCase,J33,J56) -> 0.33 | K10: =CHOOSE(OpCase,K33,K56) -> 0.33 | L10: =CHOOSE(OpCase,L33,L56) -> 0.33 | M10: =CHOOSE(OpCase,M33,M56) -> 0.33 | ... O10: =CHOOSE(OpCase,O33,O56) -> 0.33
B11: Tax rate | F11: =CHOOSE(OpCase,F34,F57) -> 0.35 | G11: =CHOOSE(OpCase,G34,G57) -> 0.35 | H11: =CHOOSE(OpCase,H34,H57) -> 0.35 | I11: =CHOOSE(OpCase,I34,I57) -> 0.35 | J11: =CHOOSE(OpCase,J34,J57) -> 0.35 | K11: =CHOOSE(OpCase,K34,K57) -> 0.35 | L11: =CHOOSE(OpCase,L34,L57) -> 0.35 | M11: =CHOOSE(OpCase,M34,M57) -> 0.35 | ... O11: =CHOOSE(OpCase,O34,O57) -> 0.35
A13: Property, plant & equipment
B14: Capital expenditure % of sales | C14: =C86/C76 -> 0.29489184 | D14: =D86/D76 -> 0.2398016 | E14: =E86/E76 -> 0.23729576 | F14: =CHOOSE(OpCase,F37,F60) -> 0.23 | G14: =CHOOSE(OpCase,G37,G60) -> 0.22 | H14: =CHOOSE(OpCase,H37,H60) -> 0.21 | I14: =CHOOSE(OpCase,I37,I60) -> 0.2 | J14: =CHOOSE(OpCase,J37,J60) -> 0.2 | K14: =CHOOSE(OpCase,K37,K60) -> 0.2 | L14: =CHOOSE(OpCase,L37,L60) -> 0.2 | M14: =CHOOSE(OpCase,M37,M60) -> 0.2 | ... O14: =CHOOSE(OpCase,O37,O60) -> 0.2
B15: Depreciation % of beginning PP&E | E15: =E87/D88 -> -0.37808452 | F15: =CHOOSE(OpCase,F38,F61) -> -0.38 | G15: =CHOOSE(OpCase,G38,G61) -> -0.38 | H15: =CHOOSE(OpCase,H38,H61) -> -0.38 | I15: =CHOOSE(OpCase,I38,I61) -> -0.38 | J15: =CHOOSE(OpCase,J38,J61) -> -0.38 | K15: =CHOOSE(OpCase,K38,K61) -> -0.38 | L15: =CHOOSE(OpCase,L38,L61) -> -0.38 | M15: =CHOOSE(OpCase,M38,M61) -> -0.38 | ... O15: =CHOOSE(OpCase,O38,O61) -> -0.38
A17: Operating working capital
B18: Inventories % of sales | E18: =E91/E$76 -> 0 | F18: =CHOOSE(OpCase,F41,F64) -> 0 | G18: =CHOOSE(OpCase,G41,G64) -> 0 | H18: =CHOOSE(OpCase,H41,H64) -> 0 | I18: =CHOOSE(OpCase,I41,I64) -> 0 | J18: =CHOOSE(OpCase,J41,J64) -> 0 | K18: =CHOOSE(OpCase,K41,K64) -> 0 | L18: =CHOOSE(OpCase,L41,L64) -> 0 | M18: =CHOOSE(OpCase,M41,M64) -> 0 | ... O18: =CHOOSE(OpCase,O41,O64) -> 0
B19: Trade and other receivables % of sales | E19: =E92/E$76 -> 0.1167741 | F19: =CHOOSE(OpCase,F42,F65) -> 0.12 | G19: =CHOOSE(OpCase,G42,G65) -> 0.12 | H19: =CHOOSE(OpCase,H42,H65) -> 0.12 | I19: =CHOOSE(OpCase,I42,I65) -> 0.12 | J19: =CHOOSE(OpCase,J42,J65) -> 0.12 | K19: =CHOOSE(OpCase,K42,K65) -> 0.12 | L19: =CHOOSE(OpCase,L42,L65) -> 0.12 | M19: =CHOOSE(OpCase,M42,M65) -> 0.12 | ... O19: =CHOOSE(OpCase,O42,O65) -> 0.12
B20: Trade and other payables % of sales | E20: =E93/E$76 -> 0.068105731 | F20: =CHOOSE(OpCase,F43,F66) -> 0.08 | G20: =CHOOSE(OpCase,G43,G66) -> 0.08 | H20: =CHOOSE(OpCase,H43,H66) -> 0.08 | I20: =CHOOSE(OpCase,I43,I66) -> 0.08 | J20: =CHOOSE(OpCase,J43,J66) -> 0.08 | K20: =CHOOSE(OpCase,K43,K66) -> 0.08 | L20: =CHOOSE(OpCase,L43,L66) -> 0.08 | M20: =CHOOSE(OpCase,M43,M66) -> 0.08 | ... O20: =CHOOSE(OpCase,O43,O66) -> 0.08
B21: Other current liabilities % of sales | E21: =E94/E$76 -> 0.049417878 | F21: =CHOOSE(OpCase,F44,F67) -> 0.05 | G21: =CHOOSE(OpCase,G44,G67) -> 0.05 | H21: =CHOOSE(OpCase,H44,H67) -> 0.05 | I21: =CHOOSE(OpCase,I44,I67) -> 0.05 | J21: =CHOOSE(OpCase,J44,J67) -> 0.05 | K21: =CHOOSE(OpCase,K44,K67) -> 0.05 | L21: =CHOOSE(OpCase,L44,L67) -> 0.05 | M21: =CHOOSE(OpCase,M44,M67) -> 0.05 | ... O21: =CHOOSE(OpCase,O44,O67) -> 0.05
A23: Other operating items
B24: Other long-term assets % of sales | E24: =E98/E76 -> 0.033328337 | F24: =CHOOSE(OpCase,F47,F70) -> 0.033 | G24: =CHOOSE(OpCase,G47,G70) -> 0.033 | H24: =CHOOSE(OpCase,H47,H70) -> 0.033 | I24: =CHOOSE(OpCase,I47,I70) -> 0.033 | J24: =CHOOSE(OpCase,J47,J70) -> 0.033 | K24: =CHOOSE(OpCase,K47,K70) -> 0.033 | L24: =CHOOSE(OpCase,L47,L70) -> 0.033 | M24: =CHOOSE(OpCase,M47,M70) -> 0.033 | ... O24: =CHOOSE(OpCase,O47,O70) -> 0.033
B25: Other long-term liabilities % of sales | E25: =E99/E76 -> 0.15819717 | F25: =CHOOSE(OpCase,F48,F71) -> 0.158 | G25: =CHOOSE(OpCase,G48,G71) -> 0.158 | H25: =CHOOSE(OpCase,H48,H71) -> 0.158 | I25: =CHOOSE(OpCase,I48,I71) -> 0.158 | J25: =CHOOSE(OpCase,J48,J71) -> 0.158 | K25: =CHOOSE(OpCase,K48,K71) -> 0.158 | L25: =CHOOSE(OpCase,L48,L71) -> 0.158 | M25: =CHOOSE(OpCase,M48,M71) -> 0.158 | ... O25: =CHOOSE(OpCase,O48,O71) -> 0.158
A27: ="Operating model assumptions - "&A29 -> Operating model assumptions - Base case
A29: Base case
A31: Income statement
B32: Sales growth | D32: =D9 -> 0.16914256 | E32: =E9 -> 0.11530317 | F32: 0.115 | G32: 0.1 | H32: 0.09 | I32: 0.08 | J32: 0.07 | K32: 0.06 | L32: 0.05 | M32: 0.04 | N32: 0.03 | O32: 0.03
B33: EBITDA margin | C33: =C10 -> 0.28922335 | D33: =D10 -> 0.29547481 | E33: =E10 -> 0.29975516 | F33: 0.33 | G33: 0.33 | H33: 0.33 | I33: 0.33 | J33: 0.33 | K33: 0.33 | L33: 0.33 | M33: 0.33 | N33: 0.33 | O33: 0.33
B34: Tax rate | F34: 0.35 | G34: 0.35 | H34: 0.35 | I34: 0.35 | J34: 0.35 | K34: 0.35 | L34: 0.35 | M34: 0.35 | N34: 0.35 | O34: 0.35
A36: Property, plant & equipment
B37: Capital expenditure % of sales | C37: =C14 -> 0.29489184 | D37: =D14 -> 0.2398016 | E37: =E14 -> 0.23729576 | F37: 0.23 | G37: 0.22 | H37: 0.21 | I37: 0.2 | J37: 0.2 | K37: 0.2 | L37: 0.2 | M37: 0.2 | N37: 0.2 | O37: 0.2
B38: Depreciation % of beginning PP&E | E38: =E15 -> -0.37808452 | F38: -0.38 | G38: -0.38 | H38: -0.38 | I38: -0.38 | J38: -0.38 | K38: -0.38 | L38: -0.38 | M38: -0.38 | N38: -0.38 | O38: -0.38
A40: Operating working capital
B41: Inventories % of sales | E41: =E18 -> 0 | F41: 0 | G41: 0 | H41: 0 | I41: 0 | J41: 0 | K41: 0 | L41: 0 | M41: 0 | N41: 0 | O41: 0
B42: Trade and other receivables % of sales | E42: =E19 -> 0.1167741 | F42: 0.12 | G42: 0.12 | H42: 0.12 | I42: 0.12 | J42: 0.12 | K42: 0.12 | L42: 0.12 | M42: 0.12 | N42: 0.12 | O42: 0.12
B43: Trade and other payables % of sales | E43: =E20 -> 0.068105731 | F43: 0.08 | G43: 0.08 | H43: 0.08 | I43: 0.08 | J43: 0.08 | K43: 0.08 | L43: 0.08 | M43: 0.08 | N43: 0.08 | O43: 0.08
B44: Other current liabilities % of sales | E44: =E21 -> 0.049417878 | F44: 0.05 | G44: 0.05 | H44: 0.05 | I44: 0.05 | J44: 0.05 | K44: 0.05 | L44: 0.05 | M44: 0.05 | N44: 0.05 | O44: 0.05
A46: Other operating items
B47: Other long-term assets % of sales | E47: =E24 -> 0.033328337 | F47: 0.033 | G47: 0.033 | H47: 0.033 | I47: 0.033 | J47: 0.033 | K47: 0.033 | L47: 0.033 | M47: 0.033 | N47: 0.033 | O47: 0.033
B48: Other long-term liabilities % of sales | E48: =E25 -> 0.15819717 | F48: 0.158 | G48: 0.158 | H48: 0.158 | I48: 0.158 | J48: 0.158 | K48: 0.158 | L48: 0.158 | M48: 0.158 | N48: 0.158 | O48: 0.158
A50: ="Operating model assumptions - "&A52 -> Operating model assumptions - Management case
A52: Management case
A54: Income statement
B55: Sales growth | D55: =D32 -> 0.16914256 | E55: =E32 -> 0.11530317 | F55: 0.12 | G55: 0.12 | H55: 0.12 | I55: 0.12 | J55: 0.12 | K55: 0.06 | L55: 0.05 | M55: 0.04 | N55: 0.03 | O55: 0.03
...

Sheet Calcs
A1: =CoName -> Company2272 | E1: Hist. | F1: Proj. | G1: Proj. | H1: Proj. | I1: Proj. | J1: Proj. | K1: Proj. | L1: Proj. | M1: Proj. | N1: Proj. | O1: Proj.
A2: =Ccy&Units&" unless otherwise stated" -> $m unless otherwise stated | E2: =Inputs!C16 -> 42369 | F2: =DATE(YEAR(E2)+1,MONTH(E2),DAY(E2)) -> 42735 | G2: =DATE(YEAR(F2)+1,MONTH(F2),DAY(F2)) -> 43100 | H2: =DATE(YEAR(G2)+1,MONTH(G2),DAY(G2)) -> 43465 | I2: =DATE(YEAR(H2)+1,MONTH(H2),DAY(H2)) -> 43830 | J2: =DATE(YEAR(I2)+1,MONTH(I2),DAY(I2)) -> 44196 | K2: =DATE(YEAR(J2)+1,MONTH(J2),DAY(J2)) -> 44561 | L2: =DATE(YEAR(K2)+1,MONTH(K2),DAY(K2)) -> 44926 | M2: =DATE(YEAR(L2)+1,MONTH(L2),DAY(L2)) -> 45291 | ... O2: =DATE(YEAR(N2)+1,MONTH(N2),DAY(N2)) -> 46022
A4: Goodwill
B6: Purchase price | E6: ='S&U'!E15 -> 4198.8557
B8: Fair value of net assets acquired
B9: Book value of net assets acquired | E9: =BS!C15-BS!C31 -> 968.1
B10: Deduct existing goodwill of target | E10: =-BS!C13 -> -81.1
B11: Fair value of net assets acquired | E11: =SUM(E9:E10) -> 887
B13: Goodwill | E13: =E6-E11 -> 3311.8557
A15: Debt issuance fees
B17: Beginning debt issuance fees | F17: =E19 -> 64 | G17: =F19 -> 53.333333 | H17: =G19 -> 42.666667 | I17: =H19 -> 32 | J17: =I19 -> 21.333333 | K17: =J19 -> 10.666667 | L17: =K19 -> 0 | M17: =L19 -> 0 | ... O17: =N19 -> 0
B18: Amortization | F18: =-MIN(F17,$E$19/'S&U'!$J$13) -> -10.666667 | G18: =-MIN(G17,$E$19/'S&U'!$J$13) -> -10.666667 | H18: =-MIN(H17,$E$19/'S&U'!$J$13) -> -10.666667 | I18: =-MIN(I17,$E$19/'S&U'!$J$13) -> -10.666667 | J18: =-MIN(J17,$E$19/'S&U'!$J$13) -> -10.666667 | K18: =-MIN(K17,$E$19/'S&U'!$J$13) -> -10.666667 | L18: =-MIN(L17,$E$19/'S&U'!$J$13) -> 0 | M18: =-MIN(M17,$E$19/'S&U'!$J$13) -> 0 | ... O18: =-MIN(O17,$E$19/'S&U'!$J$13) -> 0
B19: Ending debt issuance fees | E19: ='S&U'!C33 -> 64 | F19: =SUM(F17:F18) -> 53.333333 | G19: =SUM(G17:G18) -> 42.666667 | H19: =SUM(H17:H18) -> 32 | I19: =SUM(I17:I18) -> 21.333333 | J19: =SUM(J17:J18) -> 10.666667 | K19: =SUM(K17:K18) -> 0 | L19: =SUM(L17:L18) -> 0 | M19: =SUM(M17:M18) -> 0 | ... O19: =SUM(O17:O18) -> 0
A21: Retained earnings
B23: Beginning retained earnings | F23: =E25 -> -63.126835 | G23: =F25 -> -114.99289 | H23: =G25 -> -152.36979 | I23: =H25 -> -176.31329 | J23: =I25 -> -187.83277 | K23: =J25 -> -188.99531 | L23: =K25 -> -190.81416 | M23: =L25 -> -196.04803 | ... O23: =N25 -> -255.98156
B24: Net income | F24: =FS!F21 -> -51.866053 | G24: =FS!G21 -> -37.376905 | H24: =FS!H21 -> -23.943501 | I24: =FS!I21 -> -11.519472 | J24: =FS!J21 -> -1.1625428 | K24: =FS!K21 -> -1.8188522 | L24: =FS!L21 -> -5.233872 | M24: =FS!M21 -> -17.614846 | ... O24: =FS!O21 -> -105.98469
B25: Ending retained earnings | E25: =BS!F35 -> -63.126835 | F25: =SUM(F23:F24) -> -114.99289 | G25: =SUM(G23:G24) -> -152.36979 | H25: =SUM(H23:H24) -> -176.31329 | I25: =SUM(I23:I24) -> -187.83277 | J25: =SUM(J23:J24) -> -188.99531 | K25: =SUM(K23:K24) -> -190.81416 | L25: =SUM(L23:L24) -> -196.04803 | M25: =SUM(M23:M24) -> -213.66288 | ... O25: =SUM(O23:O24) -> -361.96625

Sheet BS
A1: =CoName -> Company2272 | C1: Op Co | D1: New Co | E1: Adj. | F1: Combo
A2: =Ccy&Units&" unless otherwise stated" -> $m unless otherwise stated | C2: =Inputs!$C$16 -> 42369 | D2: =Inputs!$C$16 -> 42369 | E2: =Inputs!$C$16 -> 42369 | F2: =Inputs!$C$16 -> 42369
A4: Balance sheet | C4: Op Co | D4: New Co | E4: Adj. | F4: Combo
A6: Assets
B7: Cash and financial investments | C7: 484.7 | D7: ='S&U'!C47-'S&U'!C39-'S&U'!C33 -> 4271.5825 | E7: =-D7-C7 -> -4756.2825 | F7: =SUM(C7:E7) -> 0
B8: Inventories | C8: 0 | F8: =SUM(C8:E8) -> 0
B9: Trade and other receivables | C9: 233.7 | F9: =SUM(C9:E9) -> 233.7
B10: Total current assets | C10: =SUM(C7:C9) -> 718.4 | D10: =SUM(D7:D9) -> 4271.5825 | E10: =SUM(E7:E9) -> -4756.2825 | F10: =SUM(F7:F9) -> 233.7
B12: Property, plant and equipment | C12: 1148 | F12: =SUM(C12:E12) -> 1148
B13: Goodwill | C13: 81.1 | E13: =Calcs!E13-BS!C13 -> 3230.7557 | F13: =SUM(C13:E13) -> 3311.8557
B14: Other LT assets | C14: 66.7 | F14: =SUM(C14:E14) -> 66.7
B15: Total assets | C15: =SUM(C10,C12:C14) -> 2014.2 | D15: =SUM(D10,D12:D14) -> 4271.5825 | E15: =SUM(E10,E12:E14) -> -1525.5268 | F15: =SUM(F10,F12:F14) -> 4760.2557
A17: Liabilities and equity
B18: Short-term debt | C18: 1.7 | E18: =-C18 -> -1.7 | F18: =SUM(C18:E18) -> 0
B19: Revolver | C19: 0 | D19: ='S&U'!C40 -> 0 | E19: =-C19 -> 0 | F19: =SUM(C19:E19) -> 0
B20: Trade and other payables | C20: 136.3 | F20: =SUM(C20:E20) -> 136.3
B21: Other current liabilities | C21: 98.9 | F21: =SUM(C21:E21) -> 98.9
B22: Total current liabilities | C22: =SUM(C18:C21) -> 236.9 | D22: =SUM(D18:D21) -> 0 | E22: =SUM(E18:E21) -> -1.7 | F22: =SUM(F18:F21) -> 235.2
B24: Long-term debt | C24: 492.6 | E24: =-C24 -> -492.6 | F24: =SUM(C24:E24) -> 0
B25: Term debt A | D25: ='S&U'!C41 -> 1200 | F25: =SUM(C25:E25) -> 1200
B26: Term debt B | D26: ='S&U'!C42 -> 900 | F26: =SUM(C26:E26) -> 900
B27: High yield | D27: ='S&U'!C43 -> 600 | F27: =SUM(C27:E27) -> 600
B28: Mezzanine (PIK) | D28: ='S&U'!C44 -> 500 | F28: =SUM(C28:E28) -> 500
B29: Debt financing fees | D29: =-'S&U'!C33 -> -64 | F29: =SUM(C29:E29) -> -64
B30: Other LT liabilities | C30: 316.6 | F30: =SUM(C30:E30) -> 316.6
B31: Total liabilities | C31: =SUM(C22,C24:C30) -> 1046.1 | D31: =SUM(D22,D24:D30) -> 3136 | E31: =SUM(E22,E24:E30) -> -494.3 | F31: =SUM(F22,F24:F30) -> 3687.8
B33: Shareholder loan | D33: ='S&U'!C45 -> 535.58253 | F33: =SUM(C33:E33) -> 535.58253
B34: Ordinary equity | C34: 798.4 | D34: ='S&U'!C46 -> 600 | E34: =-C34 -> -798.4 | F34: =SUM(C34:E34) -> 600
B35: Retained earnings (deficit) | C35: 169.7 | E35: =-C35-'S&U'!C34 -> -232.82684 | F35: =SUM(C35:E35) -> -63.126835
B36: Shareholders equity | C36: =SUM(C33:C35) -> 968.1 | D36: =SUM(D33:D35) -> 1135.5825 | E36: =SUM(E33:E35) -> -1031.2268 | F36: =SUM(F33:F35) -> 1072.4557
B38: Total liabilities & equity | C38: =SUM(C36,C31) -> 2014.2 | D38: =SUM(D36,D31) -> 4271.5825 | E38: =SUM(E36,E31) -> -1525.5268 | F38: =SUM(F36,F31) -> 4760.2557
B40: Check | C40: =IF(C38=C15,"OK",C15-C38) -> OK | D40: =IF(D38=D15,"OK",D15-D38) -> OK | E40: =IF(E38=E15,"OK",E15-E38) -> OK | F40: =IF(F38=F15,"OK",F15-F38) -> OK

Sheet FS
A1: =CoName -> Company2272 | C1: Hist. | D1: Hist. | E1: Hist. | F1: Proj. | G1: Proj. | H1: Proj. | I1: Proj. | J1: Proj. | K1: Proj. | L1: Proj. | M1: Proj. | N1: Proj. | O1: Proj.
A2: =Ccy&Units&" unless otherwise stated" -> $m unless otherwise stated | C2: =DATE(YEAR(D2)-1,MONTH(D2),DAY(D2)) -> 41639 | D2: =DATE(YEAR(E2)-1,MONTH(E2),DAY(E2)) -> 42004 | E2: =Inputs!C16 -> 42369 | F2: =DATE(YEAR(E2)+1,MONTH(E2),DAY(E2)) -> 42735 | G2: =DATE(YEAR(F2)+1,MONTH(F2),DAY(F2)) -> 43100 | H2: =DATE(YEAR(G2)+1,MONTH(G2),DAY(G2)) -> 43465 | I2: =DATE(YEAR(H2)+1,MONTH(H2),DAY(H2)) -> 43830 | J2: =DATE(YEAR(I2)+1,MONTH(I2),DAY(I2)) -> 44196 | K2: =DATE(YEAR(J2)+1,MONTH(J2),DAY(J2)) -> 44561 | L2: =DATE(YEAR(K2)+1,MONTH(K2),DAY(K2)) -> 44926 | M2: =DATE(YEAR(L2)+1,MONTH(L2),DAY(L2)) -> 45291 | ... O2: =DATE(YEAR(N2)+1,MONTH(N2),DAY(N2)) -> 46022
A4: Income statement
B6: Sales | C6: =OpMod!C76 -> 1534.8 | D6: =OpMod!D76 -> 1794.4 | E6: =OpMod!E76 -> 2001.3 | F6: =OpMod!F76 -> 2231.4495 | G6: =OpMod!G76 -> 2454.5945 | H6: =OpMod!H76 -> 2675.508 | I6: =OpMod!I76 -> 2889.5486 | J6: =OpMod!J76 -> 3091.817 | ... O6: =OpMod!O76 -> 3796.7914
B8: EBITDA | C8: =OpMod!C78 -> 443.9 | D8: =OpMod!D78 -> 530.2 | E8: =OpMod!E78 -> 599.9 | F8: =OpMod!F78 -> 736.37833 | G8: =OpMod!G78 -> 810.01617 | H8: =OpMod!H78 -> 882.91762 | I8: =OpMod!I78 -> 953.55103 | J8: =OpMod!J78 -> 1020.2996 | ... O8: =OpMod!O78 -> 1252.9411
B9: Depreciation | F9: =OpMod!F79 -> -436.24 | G9: =OpMod!G79 -> -465.49749 | H9: =OpMod!H79 -> -493.81254 | I9: =OpMod!I79 -> -519.66931 | J9: =OpMod!J79 -> -541.80066 | K9: =OpMod!K79 -> -570.8945 | L9: =OpMod!L79 -> -603.03137 | M9: =OpMod!M79 -> -635.41006 | ... O9: =OpMod!O79 -> -693.03816
B10: Amortization of debt financing fees | F10: =Calcs!F18 -> -10.666667 | G10: =Calcs!G18 -> -10.666667 | H10: =Calcs!H18 -> -10.666667 | I10: =Calcs!I18 -> -10.666667 | J10: =Calcs!J18 -> -10.666667 | K10: =Calcs!K18 -> -10.666667 | L10: =Calcs!L18 -> 0 | M10: =Calcs!M18 -> 0 | ... O10: =Calcs!O18 -> 0
B11: Interest income on cash | F11: =IF(circ=1,Debt!F107,Debt!F98) -> 0.055786238 | G11: =IF(circ=1,Debt!G107,Debt!G98) -> 0.1171511 | H11: =IF(circ=1,Debt!H107,Debt!H98) -> 0.12825256 | I11: =IF(circ=1,Debt!I107,Debt!I98) -> 0.13912641 | J11: =IF(circ=1,Debt!J107,Debt!J98) -> 0.14953414 | K11: =IF(circ=1,Debt!K107,Debt!K98) -> 0.15922857 | L11: =IF(circ=1,Debt!L107,Debt!L98) -> 0.16796296 | M11: =IF(circ=1,Debt!M107,Debt!M98) -> 0.17550081 | ... O11: =IF(circ=1,Debt!O107,Debt!O98) -> 0.18707491
B12: Interest expense on revolver | F12: =IF(circ=1,Debt!F108,Debt!F99) -> 0 | G12: =IF(circ=1,Debt!G108,Debt!G99) -> 0 | H12: =IF(circ=1,Debt!H108,Debt!H99) -> 0 | I12: =IF(circ=1,Debt!I108,Debt!I99) -> 0 | J12: =IF(circ=1,Debt!J108,Debt!J99) -> 0 | K12: =IF(circ=1,Debt!K108,Debt!K99) -> 0 | L12: =IF(circ=1,Debt!L108,Debt!L99) -> -0.80749895 | M12: =IF(circ=1,Debt!M108,Debt!M99) -> -12.574909 | ... O12: =IF(circ=1,Debt!O108,Debt!O99) -> -47.081385
B13: Interest expense on Term debt A | F13: =IF(circ=1,Debt!F109,Debt!F100) -> -68.185415 | G13: =IF(circ=1,Debt!G109,Debt!G100) -> -63.59193 | H13: =IF(circ=1,Debt!H109,Debt!H100) -> -56.946514 | I13: =IF(circ=1,Debt!I109,Debt!I100) -> -47.660273 | J13: =IF(circ=1,Debt!J109,Debt!J100) -> -36.378987 | K13: =IF(circ=1,Debt!K109,Debt!K100) -> -23.809036 | L13: =IF(circ=1,Debt!L109,Debt!L100) -> -8.5903233 | M13: =IF(circ=1,Debt!M109,Debt!M100) -> 0 | ... O13: =IF(circ=1,Debt!O109,Debt!O100) -> 0
B14: Interest expense on Term debt B | F14: =IF(circ=1,Debt!F110,Debt!F101) -> -61.74 | G14: =IF(circ=1,Debt!G110,Debt!G101) -> -61.74 | H14: =IF(circ=1,Debt!H110,Debt!H101) -> -61.74 | I14: =IF(circ=1,Debt!I110,Debt!I101) -> -61.74 | J14: =IF(circ=1,Debt!J110,Debt!J101) -> -61.74 | K14: =IF(circ=1,Debt!K110,Debt!K101) -> -61.74 | L14: =IF(circ=1,Debt!L110,Debt!L101) -> -61.74 | M14: =IF(circ=1,Debt!M110,Debt!M101) -> -30.87 | ... O14: =IF(circ=1,Debt!O110,Debt!O101) -> 0
B15: Interest expense on high yield bond | F15: =Debt!F102 -> -51.75 | G15: =Debt!G102 -> -51.75 | H15: =Debt!H102 -> -51.75 | I15: =Debt!I102 -> -51.75 | J15: =Debt!J102 -> -51.75 | K15: =Debt!K102 -> -51.75 | L15: =Debt!L102 -> -51.75 | M15: =Debt!M102 -> -51.75 | ... O15: =Debt!O102 -> -51.75
B16: Interest expense on mezzanine finance | F16: =Debt!F103 -> -64.05 | G16: =Debt!G103 -> -72.254805 | H16: =Debt!H103 -> -81.510646 | I16: =Debt!I103 -> -91.952159 | J16: =Debt!J103 -> -103.73123 | K16: =Debt!K103 -> -117.0192 | L16: =Debt!L103 -> -132.00936 | M16: =Debt!M103 -> -148.91976 | ... O16: =Debt!O103 -> -189.51672
B17: Interest expense on shareholder loan | F17: =Debt!F104 -> -80.337379 | G17: =Debt!G104 -> -92.387986 | H17: =Debt!H104 -> -106.24618 | I17: =Debt!I104 -> -122.18311 | J17: =Debt!J104 -> -140.51058 | K17: =Debt!K104 -> -161.58716 | L17: =Debt!L104 -> -185.82524 | M17: =Debt!M104 -> -213.69903 | ... O17: =Debt!O104 -> -282.61696
B18: Income before tax | F18: =SUM(F8:F17) -> -36.53534 | G18: =SUM(G8:G17) -> -7.755554 | H18: =SUM(H8:H17) -> 20.373328 | I18: =SUM(I8:I17) -> 48.068642 | J18: =SUM(J8:J17) -> 73.871015 | K18: =SUM(K8:K17) -> 84.210239 | L18: =SUM(L8:L17) -> 92.007634 | M18: =SUM(M8:M17) -> 87.968942 | ... O18: =SUM(O8:O17) -> -10.875006
B20: Tax expense | F20: =-OpMod!F11*(F18-F17) -> -15.330714 | G20: =-OpMod!G11*(G18-G17) -> -29.621351 | H20: =-OpMod!H11*(H18-H17) -> -44.316829 | I20: =-OpMod!I11*(I18-I17) -> -59.588114 | J20: =-OpMod!J11*(J18-J17) -> -75.033557 | K20: =-OpMod!K11*(K18-K17) -> -86.029091 | L20: =-OpMod!L11*(L18-L17) -> -97.241506 | M20: =-OpMod!M11*(M18-M17) -> -105.58379 | ... O20: =-OpMod!O11*(O18-O17) -> -95.109684
B21: Net income | F21: =SUM(F18,F20) -> -51.866053 | G21: =SUM(G18,G20) -> -37.376905 | H21: =SUM(H18,H20) -> -23.943501 | I21: =SUM(I18,I20) -> -11.519472 | J21: =SUM(J18,J20) -> -1.1625428 | K21: =SUM(K18,K20) -> -1.8188522 | L21: =SUM(L18,L20) -> -5.233872 | M21: =SUM(M18,M20) -> -17.614846 | ... O21: =SUM(O18,O20) -> -105.98469
A23: Balance sheet
A25: Assets
B26: Cash and financial investments | E26: =BS!F7 -> 0 | F26: =F83 -> 11.157248 | G26: =G83 -> 12.272972 | H26: =H83 -> 13.37754 | I26: =I83 -> 14.447743 | J26: =J83 -> 15.459085 | K26: =K83 -> 16.38663 | L26: =L83 -> 17.205962 | M26: =M83 -> 17.8942 | ... O26: =O83 -> 18.983957
B27: Inventories | E27: =BS!F8 -> 0 | F27: =OpMod!F91 -> 0 | G27: =OpMod!G91 -> 0 | H27: =OpMod!H91 -> 0 | I27: =OpMod!I91 -> 0 | J27: =OpMod!J91 -> 0 | K27: =OpMod!K91 -> 0 | L27: =OpMod!L91 -> 0 | M27: =OpMod!M91 -> 0 | ... O27: =OpMod!O91 -> 0
B28: Trade and other receivables | E28: =BS!F9 -> 233.7 | F28: =OpMod!F92 -> 267.77394 | G28: =OpMod!G92 -> 294.55133 | H28: =OpMod!H92 -> 321.06095 | I28: =OpMod!I92 -> 346.74583 | J28: =OpMod!J92 -> 371.01804 | K28: =OpMod!K92 -> 393.27912 | L28: =OpMod!L92 -> 412.94308 | M28: =OpMod!M92 -> 429.4608 | ... O28: =OpMod!O92 -> 455.61496
B29: Total current assets | E29: =SUM(E26:E28) -> 233.7 | F29: =SUM(F26:F28) -> 278.93119 | G29: =SUM(G26:G28) -> 306.82431 | H29: =SUM(H26:H28) -> 334.43849 | I29: =SUM(I26:I28) -> 361.19357 | J29: =SUM(J26:J28) -> 386.47712 | K29: =SUM(K26:K28) -> 409.66575 | L29: =SUM(L26:L28) -> 430.14904 | ... O29: =SUM(O26:O28) -> 474.59892
B31: Property, plant and equipment | E31: =BS!F12 -> 1148 | F31: =OpMod!F88 -> 1224.9934 | G31: =OpMod!G88 -> 1299.5067 | H31: =OpMod!H88 -> 1367.5508 | I31: =OpMod!I88 -> 1425.7912 | J31: =OpMod!J88 -> 1502.354 | K31: =OpMod!K88 -> 1586.9247 | L31: =OpMod!L88 -> 1672.1317 | M31: =OpMod!M88 -> 1752.4897 | ... O31: =OpMod!O88 -> 1890.1047
B32: Goodwill | E32: =BS!F13 -> 3311.8557 | F32: =$E$32 -> 3311.8557 | G32: =$E$32 -> 3311.8557 | H32: =$E$32 -> 3311.8557 | I32: =$E$32 -> 3311.8557 | J32: =$E$32 -> 3311.8557 | K32: =$E$32 -> 3311.8557 | L32: =$E$32 -> 3311.8557 | M32: =$E$32 -> 3311.8557 | ... O32: =$E$32 -> 3311.8557
B33: Other LT assets | E33: =BS!F14 -> 66.7 | F33: =OpMod!F98 -> 73.637833 | G33: =OpMod!G98 -> 81.001617 | H33: =OpMod!H98 -> 88.291762 | I33: =OpMod!I98 -> 95.355103 | J33: =OpMod!J98 -> 102.02996 | K33: =OpMod!K98 -> 108.15176 | L33: =OpMod!L98 -> 113.55935 | M33: =OpMod!M98 -> 118.10172 | ... O33: =OpMod!O98 -> 125.29411
B34: Total assets | E34: =SUM(E29,E31:E33) -> 4760.2557 | F34: =SUM(F29,F31:F33) -> 4889.4181 | G34: =SUM(G29,G31:G33) -> 4999.1883 | H34: =SUM(H29,H31:H33) -> 5102.1368 | I34: =SUM(I29,I31:I33) -> 5194.1956 | J34: =SUM(J29,J31:J33) -> 5302.7167 | K34: =SUM(K29,K31:K33) -> 5416.5979 | L34: =SUM(L29,L31:L33) -> 5527.6958 | ... O34: =SUM(O29,O31:O33) -> 5801.8535
A36: Liabilities and equity
B37: Short-term debt | E37: =BS!F18 -> 0 | F37: =E37 -> 0 | G37: =F37 -> 0 | H37: =G37 -> 0 | I37: =H37 -> 0 | J37: =I37 -> 0 | K37: =J37 -> 0 | L37: =K37 -> 0 | M37: =L37 -> 0 | ... O37: =N37 -> 0
B38: Revolver | E38: =BS!F19 -> 0 | F38: =Debt!F81 -> 0 | G38: =Debt!G81 -> 0 | H38: =Debt!H81 -> 0 | I38: =Debt!I81 -> 0 | J38: =Debt!J81 -> 0 | K38: =Debt!K81 -> 0 | L38: =Debt!L81 -> 45.492899 | M38: =Debt!M81 -> 662.9527 | ... O38: =Debt!O81 -> 2303.6138
B39: Trade and other payables | E39: =BS!F20 -> 136.3 | F39: =OpMod!F93 -> 178.51596 | G39: =OpMod!G93 -> 196.36756 | H39: =OpMod!H93 -> 214.04064 | I39: =OpMod!I93 -> 231.16389 | J39: =OpMod!J93 -> 247.34536 | K39: =OpMod!K93 -> 262.18608 | L39: =OpMod!L93 -> 275.29538 | M39: =OpMod!M93 -> 286.3072 | ... O39: =OpMod!O93 -> 303.74331
B40: Other current liabilities | E40: =BS!F21 -> 98.9 | F40: =OpMod!F94 -> 111.57247 | G40: =OpMod!G94 -> 122.72972 | H40: =OpMod!H94 -> 133.7754 | I40: =OpMod!I94 -> 144.47743 | J40: =OpMod!J94 -> 154.59085 | K40: =OpMod!K94 -> 163.8663 | L40: =OpMod!L94 -> 172.05962 | M40: =OpMod!M94 -> 178.942 | ... O40: =OpMod!O94 -> 189.83957
B41: Total current liabilities | E41: =SUM(E37:E40) -> 235.2 | F41: =SUM(F37:F40) -> 290.08844 | G41: =SUM(G37:G40) -> 319.09728 | H41: =SUM(H37:H40) -> 347.81603 | I41: =SUM(I37:I40) -> 375.64132 | J41: =SUM(J37:J40) -> 401.93621 | K41: =SUM(K37:K40) -> 426.05238 | L41: =SUM(L37:L40) -> 492.8479 | ... O41: =SUM(O37:O40) -> 2797.1967
B43: Long-term debt | E43: =BS!F24 -> 0 | F43: =E43 -> 0 | G43: =F43 -> 0 | H43: =G43 -> 0 | I43: =H43 -> 0 | J43: =I43 -> 0 | K43: =J43 -> 0 | L43: =K43 -> 0 | M43: =L43 -> 0 | ... O43: =N43 -> 0
B44: Term debt A | E44: =BS!F25 -> 1200 | F44: =Debt!F82 -> 1135.117 | G44: =Debt!G82 -> 1042.6889 | H44: =Debt!H82 -> 907.53424 | I44: =Debt!I82 -> 724.6669 | J44: =Debt!J82 -> 521.18881 | K44: =Debt!K82 -> 294.18915 | L44: =Debt!L82 -> 0 | M44: =Debt!M82 -> 0 | ... O44: =Debt!O82 -> 0
B45: Term debt B | E45: =BS!F26 -> 900 | F45: =Debt!F83 -> 900 | G45: =Debt!G83 -> 900 | H45: =Debt!H83 -> 900 | I45: =Debt!I83 -> 900 | J45: =Debt!J83 -> 900 | K45: =Debt!K83 -> 900 | L45: =Debt!L83 -> 900 | M45: =Debt!M83 -> 0 | ... O45: =Debt!O83 -> 0
B46: High yield | E46: =BS!F27 -> 600 | F46: =Debt!F84 -> 600 | G46: =Debt!G84 -> 600 | H46: =Debt!H84 -> 600 | I46: =Debt!I84 -> 600 | J46: =Debt!J84 -> 600 | K46: =Debt!K84 -> 600 | L46: =Debt!L84 -> 600 | M46: =Debt!M84 -> 600 | ... O46: =Debt!O84 -> 0
B47: Mezzanine (PIK) | E47: =BS!F28 -> 500 | F47: =Debt!F85 -> 564.05 | G47: =Debt!G85 -> 636.3048 | H47: =Debt!H85 -> 717.81545 | I47: =Debt!I85 -> 809.76761 | J47: =Debt!J85 -> 913.49884 | K47: =Debt!K85 -> 1030.518 | L47: =Debt!L85 -> 1162.5274 | M47: =Debt!M85 -> 1311.4472 | ... O47: =Debt!O85 -> 0
B48: Debt financing fees | E48: =BS!F29 -> -64 | F48: =-Calcs!F19 -> -53.333333 | G48: =-Calcs!G19 -> -42.666667 | H48: =-Calcs!H19 -> -32 | I48: =-Calcs!I19 -> -21.333333 | J48: =-Calcs!J19 -> -10.666667 | K48: =-Calcs!K19 -> 0 | L48: =-Calcs!L19 -> 0 | M48: =-Calcs!M19 -> 0 | ... O48: =-Calcs!O19 -> 0
B49: Other LT liabilities | E49: =BS!F30 -> 316.6 | F49: =OpMod!F99 -> 352.56902 | G49: =OpMod!G99 -> 387.82592 | H49: =OpMod!H99 -> 422.73026 | I49: =OpMod!I99 -> 456.54868 | J49: =OpMod!J99 -> 488.50708 | K49: =OpMod!K99 -> 517.81751 | L49: =OpMod!L99 -> 543.70838 | M49: =OpMod!M99 -> 565.45672 | ... O49: =OpMod!O99 -> 599.89303
...

Sheet Debt
A1: =CoName -> Company2272 | E1: Hist. | F1: Proj. | G1: Proj. | H1: Proj. | I1: Proj. | J1: Proj. | K1: Proj. | L1: Proj. | M1: Proj. | N1: Proj. | O1: Proj.
A2: =Ccy&Units&" unless otherwise stated" -> $m unless otherwise stated | E2: =Inputs!C16 -> 42369 | F2: =DATE(YEAR(E2)+1,MONTH(E2),DAY(E2)) -> 42735 | G2: =DATE(YEAR(F2)+1,MONTH(F2),DAY(F2)) -> 43100 | H2: =DATE(YEAR(G2)+1,MONTH(G2),DAY(G2)) -> 43465 | I2: =DATE(YEAR(H2)+1,MONTH(H2),DAY(H2)) -> 43830 | J2: =DATE(YEAR(I2)+1,MONTH(I2),DAY(I2)) -> 44196 | K2: =DATE(YEAR(J2)+1,MONTH(J2),DAY(J2)) -> 44561 | L2: =DATE(YEAR(K2)+1,MONTH(K2),DAY(K2)) -> 44926 | M2: =DATE(YEAR(L2)+1,MONTH(L2),DAY(L2)) -> 45291 | ... O2: =DATE(YEAR(N2)+1,MONTH(N2),DAY(N2)) -> 46022
A4: Cash available for debt repayment
B6: Minimum cash as % of sales | F6: 0.005 | G6: 0.005 | H6: 0.005 | I6: 0.005 | J6: 0.005 | K6: 0.005 | L6: 0.005 | M6: 0.005 | N6: 0.005 | O6: 0.005
B8: Beginning cash | F8: =FS!E83 -> 0 | G8: =FS!F83 -> 11.157248 | H8: =FS!G83 -> 12.272972 | I8: =FS!H83 -> 13.37754 | J8: =FS!I83 -> 14.447743 | K8: =FS!J83 -> 15.459085 | L8: =FS!K83 -> 16.38663 | M8: =FS!L83 -> 17.205962 | ... O8: =FS!N83 -> 18.431026
B9: Cash flow available for debt repayment | F9: =FS!F75 -> 76.04029 | G9: =FS!G75 -> 93.543828 | H9: =FS!H75 -> 136.25919 | I9: =FS!I75 -> 183.93754 | J9: =FS!J75 -> 204.48943 | K9: =FS!K75 -> 227.9272 | L9: =FS!L75 -> 249.51559 | M9: =FS!M75 -> 283.22844 | ... O9: =FS!O75 -> 314.75801
B10: Minimum cash required | F10: =F6*OpMod!F76 -> 11.157247 | G10: =G6*OpMod!G76 -> 12.272972 | H10: =H6*OpMod!H76 -> 13.37754 | I10: =I6*OpMod!I76 -> 14.447743 | J10: =J6*OpMod!J76 -> 15.459085 | K10: =K6*OpMod!K76 -> 16.38663 | L10: =L6*OpMod!L76 -> 17.205962 | M10: =M6*OpMod!M76 -> 17.8942 | ... O10: =O6*OpMod!O76 -> 18.983957
B11: Cash available for debt repayment | F11: =F8+F9-F10 -> 64.883042 | G11: =G8+G9-G10 -> 92.428103 | H11: =H8+H9-H10 -> 135.15462 | I11: =I8+I9-I10 -> 182.86734 | J11: =J8+J9-J10 -> 203.47809 | K11: =K8+K9-K10 -> 226.99965 | L11: =L8+L9-L10 -> 248.69625 | M11: =M8+M9-M10 -> 282.5402 | ... O11: =O8+O9-O10 -> 314.20508
A13: Mandated repayments
A15: Mandated repayment terms
B16: Term debt A | F16: 0.025 | G16: 0.025 | H16: 0.05 | I16: 0.05 | J16: 0.05 | K16: 0.05 | L16: 0.75 | M16: 0 | N16: 0 | O16: 0
B17: Term debt B | F17: 0 | G17: 0 | H17: 0 | I17: 0 | J17: 0 | K17: 0 | L17: 0 | M17: 1 | N17: 0 | O17: 0
B18: High Yield | O18: 1
B19: Mezzanine (PIK) | O19: 1
A21: Mandated repayment amounts
B22: Term debt A | F22: =F47 -> -30 | G22: =G47 -> -30 | H22: =H47 -> -60 | I22: =I47 -> -60 | J22: =J47 -> -60 | K22: =K47 -> -60 | L22: =L47 -> -294.18915 | M22: =M47 -> 0 | ... O22: =O47 -> 0
B23: Term debt B | F23: =F55 -> 0 | G23: =G55 -> 0 | H23: =H55 -> 0 | I23: =I55 -> 0 | J23: =J55 -> 0 | K23: =K55 -> 0 | L23: =L55 -> 0 | M23: =M55 -> -900 | ... O23: =O55 -> 0
B24: High Yield | F24: =F61 -> 0 | G24: =G61 -> 0 | H24: =H61 -> 0 | I24: =I61 -> 0 | J24: =J61 -> 0 | K24: =K61 -> 0 | L24: =L61 -> 0 | M24: =M61 -> 0 | ... O24: =O61 -> -600
B25: Mezzanine (PIK) | F25: =F67 -> 0 | G25: =G67 -> 0 | H25: =H67 -> 0 | I25: =I67 -> 0 | J25: =J67 -> 0 | K25: =K67 -> 0 | L25: =L67 -> 0 | M25: =M67 -> 0 | ... O25: =O67 -> -1668.9603
A27: Cash available after mandated repayment
B28: Cash available for debt repayment | F28: =F11 -> 64.883042 | G28: =G11 -> 92.428103 | H28: =H11 -> 135.15462 | I28: =I11 -> 182.86734 | J28: =J11 -> 203.47809 | K28: =K11 -> 226.99965 | L28: =L11 -> 248.69625 | M28: =M11 -> 282.5402 | ... O28: =O11 -> 314.20508
B29: Mandated payment amount | F29: =SUM(F22:F25) -> -30 | G29: =SUM(G22:G25) -> -30 | H29: =SUM(H22:H25) -> -60 | I29: =SUM(I22:I25) -> -60 | J29: =SUM(J22:J25) -> -60 | K29: =SUM(K22:K25) -> -60 | L29: =SUM(L22:L25) -> -294.18915 | M29: =SUM(M22:M25) -> -900 | ... O29: =SUM(O22:O25) -> -2268.9603
B30: Cash available after mandated repayment | F30: =SUM(F28:F29) -> 34.883042 | G30: =SUM(G28:G29) -> 62.428103 | H30: =SUM(H28:H29) -> 75.154618 | I30: =SUM(I28:I29) -> 122.86734 | J30: =SUM(J28:J29) -> 143.47809 | K30: =SUM(K28:K29) -> 166.99965 | L30: =SUM(L28:L29) -> -45.492899 | M30: =SUM(M28:M29) -> -617.4598 | ... O30: =SUM(O28:O29) -> -1954.7552
A32: Revolving credit facility
B34: Beginning balance | F34: =E36 -> 0 | G34: =F36 -> 0 | H34: =G36 -> 0 | I34: =H36 -> 0 | J34: =I36 -> 0 | K34: =J36 -> 0 | L34: =K36 -> 0 | M34: =L36 -> 45.492899 | ... O34: =N36 -> 348.8586
B35: Issuance (repayment) | F35: =-MIN(F34,F30) -> 0 | G35: =-MIN(G34,G30) -> 0 | H35: =-MIN(H34,H30) -> 0 | I35: =-MIN(I34,I30) -> 0 | J35: =-MIN(J34,J30) -> 0 | K35: =-MIN(K34,K30) -> 0 | L35: =-MIN(L34,L30) -> 45.492899 | M35: =-MIN(M34,M30) -> 617.4598 | ... O35: =-MIN(O34,O30) -> 1954.7552
B36: Ending balance | E36: ='S&U'!C40 -> 0 | F36: =SUM(F34:F35) -> 0 | G36: =SUM(G34:G35) -> 0 | H36: =SUM(H34:H35) -> 0 | I36: =SUM(I34:I35) -> 0 | J36: =SUM(J34:J35) -> 0 | K36: =SUM(K34:K35) -> 0 | L36: =SUM(L34:L35) -> 45.492899 | M36: =SUM(M34:M35) -> 662.9527 | ... O36: =SUM(O34:O35) -> 2303.6138
A38: Cash sweep
B40: Cash flow available for accelerated repayment after servicing revolver | F40: =SUM(F30,F35) -> 34.883042 | G40: =SUM(G30,G35) -> 62.428103 | H40: =SUM(H30,H35) -> 75.154618 | I40: =SUM(I30,I35) -> 122.86734 | J40: =SUM(J30,J35) -> 143.47809 | K40: =SUM(K30,K35) -> 166.99965 | L40: =SUM(L30,L35) -> 0 | M40: =SUM(M30,M35) -> 0 | ... O40: =SUM(O30,O35) -> 0
B41: % of surplus cash used to sweep debt | F41: 1 | G41: 1 | H41: 1 | I41: 1 | J41: 1 | K41: 1 | L41: 1 | M41: 1 | N41: 1 | O41: 1
B42: Cash used in sweep | F42: =F40*F41 -> 34.883042 | G42: =G40*G41 -> 62.428103 | H42: =H40*H41 -> 75.154618 | I42: =I40*I41 -> 122.86734 | J42: =J40*J41 -> 143.47809 | K42: =K40*K41 -> 166.99965 | L42: =L40*L41 -> 0 | M42: =M40*M41 -> 0 | ... O42: =O40*O41 -> 0
A44: Debt balances and accelerated repayments
A45: Term debt A
B46: Beginning balance | F46: =E49 -> 1200 | G46: =F49 -> 1135.117 | H46: =G49 -> 1042.6889 | I46: =H49 -> 907.53424 | J46: =I49 -> 724.6669 | K46: =J49 -> 521.18881 | L46: =K49 -> 294.18915 | M46: =L49 -> 0 | ... O46: =N49 -> 0
B47: Mandated repayment | F47: =-MIN(F46,F16*$E$49) -> -30 | G47: =-MIN(G46,G16*$E$49) -> -30 | H47: =-MIN(H46,H16*$E$49) -> -60 | I47: =-MIN(I46,I16*$E$49) -> -60 | J47: =-MIN(J46,J16*$E$49) -> -60 | K47: =-MIN(K46,K16*$E$49) -> -60 | L47: =-MIN(L46,L16*$E$49) -> -294.18915 | M47: =-MIN(M46,M16*$E$49) -> 0 | ... O47: =-MIN(O46,O16*$E$49) -> 0
B48: Accelerated repayment | C48: 1 | F48: =-MIN(F46+F47,F42)*$C$48 -> -34.883042 | G48: =-MIN(G46+G47,G42)*$C$48 -> -62.428103 | H48: =-MIN(H46+H47,H42)*$C$48 -> -75.154618 | I48: =-MIN(I46+I47,I42)*$C$48 -> -122.86734 | J48: =-MIN(J46+J47,J42)*$C$48 -> -143.47809 | K48: =-MIN(K46+K47,K42)*$C$48 -> -166.99965 | L48: =-MIN(L46+L47,L42)*$C$48 -> 0 | M48: =-MIN(M46+M47,M42)*$C$48 -> 0 | ... O48: =-MIN(O46+O47,O42)*$C$48 -> 0
B49: Ending balance | E49: ='S&U'!C41 -> 1200 | F49: =SUM(F46:F48) -> 1135.117 | G49: =SUM(G46:G48) -> 1042.6889 | H49: =SUM(H46:H48) -> 907.53424 | I49: =SUM(I46:I48) -> 724.6669 | J49: =SUM(J46:J48) -> 521.18881 | K49: =SUM(K46:K48) -> 294.18915 | L49: =SUM(L46:L48) -> 0 | M49: =SUM(M46:M48) -> 0 | ... O49: =SUM(O46:O48) -> 0
B51: Cash available for term debt B accelerated repayment | F51: =SUM(F42,F48) -> 0 | G51: =SUM(G42,G48) -> 0 | H51: =SUM(H42,H48) -> 0 | I51: =SUM(I42,I48) -> 0 | J51: =SUM(J42,J48) -> 0 | K51: =SUM(K42,K48) -> 0 | L51: =SUM(L42,L48) -> 0 | M51: =SUM(M42,M48) -> 0 | ... O51: =SUM(O42,O48) -> 0
A53: Term debt B
B54: Beginning balance | F54: =E57 -> 900 | G54: =F57 -> 900 | H54: =G57 -> 900 | I54: =H57 -> 900 | J54: =I57 -> 900 | K54: =J57 -> 900 | L54: =K57 -> 900 | M54: =L57 -> 900 | ... O54: =N57 -> 0
...

Sheet Returns
A1: =CoName -> Company2272 | E1: Hist. | F1: Proj. | G1: Proj. | H1: Proj. | I1: Proj. | J1: Proj. | K1: Proj. | L1: Proj. | M1: Proj. | N1: Proj. | O1: Proj.
A2: =Ccy&Units&" unless otherwise stated" -> $m unless otherwise stated | E2: =Inputs!C16 -> 42369 | F2: =DATE(YEAR(E2)+1,MONTH(E2),DAY(E2)) -> 42735 | G2: =DATE(YEAR(F2)+1,MONTH(F2),DAY(F2)) -> 43100 | H2: =DATE(YEAR(G2)+1,MONTH(G2),DAY(G2)) -> 43465 | I2: =DATE(YEAR(H2)+1,MONTH(H2),DAY(H2)) -> 43830 | J2: =DATE(YEAR(I2)+1,MONTH(I2),DAY(I2)) -> 44196 | K2: =DATE(YEAR(J2)+1,MONTH(J2),DAY(J2)) -> 44561 | L2: =DATE(YEAR(K2)+1,MONTH(K2),DAY(K2)) -> 44926 | M2: =DATE(YEAR(L2)+1,MONTH(L2),DAY(L2)) -> 45291 | ... O2: =DATE(YEAR(N2)+1,MONTH(N2),DAY(N2)) -> 46022
B4: Entry EBITDA multiple | E4: ='S&U'!E24 -> 7.015262
B5: Exit EBITDA multiple | E5: 7
B6: Basis of interest calcuations: | E6: =IF(circ=1,"Average","Beginning")&" balance driven" -> Average balance driven
A8: Sources and uses of funds at exit
B9: Year | E9: =YEAR(E$2)-YEAR($E$2) -> 0 | F9: =YEAR(F$2)-YEAR($E$2) -> 1 | G9: =YEAR(G$2)-YEAR($E$2) -> 2 | H9: =YEAR(H$2)-YEAR($E$2) -> 3 | I9: =YEAR(I$2)-YEAR($E$2) -> 4 | J9: =YEAR(J$2)-YEAR($E$2) -> 5 | K9: =YEAR(K$2)-YEAR($E$2) -> 6 | L9: =YEAR(L$2)-YEAR($E$2) -> 7 | ... O9: =YEAR(O$2)-YEAR($E$2) -> 10
B10: EBITDA | E10: =OpMod!E78 -> 599.9 | F10: =OpMod!F78 -> 736.37833 | G10: =OpMod!G78 -> 810.01617 | H10: =OpMod!H78 -> 882.91762 | I10: =OpMod!I78 -> 953.55103 | J10: =OpMod!J78 -> 1020.2996 | K10: =OpMod!K78 -> 1081.5176 | L10: =OpMod!L78 -> 1135.5935 | ... O10: =OpMod!O78 -> 1252.9411
B12: Enterprise value on exit | F12: =F10*ExitMultiple -> 5154.6483 | G12: =G10*ExitMultiple -> 5670.1132 | H12: =H10*ExitMultiple -> 6180.4234 | I12: =I10*ExitMultiple -> 6674.8572 | J12: =J10*ExitMultiple -> 7142.0972 | K12: =K10*ExitMultiple -> 7570.6231 | L12: =L10*ExitMultiple -> 7949.1542 | M12: =M10*ExitMultiple -> 8267.1204 | ... O12: =O10*ExitMultiple -> 8770.588
B13: Cash | E13: =FS!E83 -> 0 | F13: =Debt!F80 -> 11.157248 | G13: =Debt!G80 -> 12.272972 | H13: =Debt!H80 -> 13.37754 | I13: =Debt!I80 -> 14.447743 | J13: =Debt!J80 -> 15.459085 | K13: =Debt!K80 -> 16.38663 | L13: =Debt!L80 -> 17.205962 | M13: =Debt!M80 -> 17.8942 | ... O13: =Debt!O80 -> 18.983957
B14: Revolver | E14: =-Debt!E81 -> 0 | F14: =-Debt!F81 -> 0 | G14: =-Debt!G81 -> 0 | H14: =-Debt!H81 -> 0 | I14: =-Debt!I81 -> 0 | J14: =-Debt!J81 -> 0 | K14: =-Debt!K81 -> 0 | L14: =-Debt!L81 -> -45.492899 | ... O14: =-Debt!O81 -> -2303.6138
B15: Term debt A | E15: =-Debt!E82 -> -1200 | F15: =-Debt!F82 -> -1135.117 | G15: =-Debt!G82 -> -1042.6889 | H15: =-Debt!H82 -> -907.53424 | I15: =-Debt!I82 -> -724.6669 | J15: =-Debt!J82 -> -521.18881 | K15: =-Debt!K82 -> -294.18915 | L15: =-Debt!L82 -> 0 | ... O15: =-Debt!O82 -> 0
B16: Term debt B | E16: =-Debt!E83 -> -900 | F16: =-Debt!F83 -> -900 | G16: =-Debt!G83 -> -900 | H16: =-Debt!H83 -> -900 | I16: =-Debt!I83 -> -900 | J16: =-Debt!J83 -> -900 | K16: =-Debt!K83 -> -900 | L16: =-Debt!L83 -> -900 | ... O16: =-Debt!O83 -> 0
B17: High Yield | E17: =-Debt!E84 -> -600 | F17: =-Debt!F84 -> -600 | G17: =-Debt!G84 -> -600 | H17: =-Debt!H84 -> -600 | I17: =-Debt!I84 -> -600 | J17: =-Debt!J84 -> -600 | K17: =-Debt!K84 -> -600 | L17: =-Debt!L84 -> -600 | ... O17: =-Debt!O84 -> 0
B18: Mezzanine (PIK) | E18: =-Debt!E85 -> -500 | F18: =-Debt!F85 -> -564.05 | G18: =-Debt!G85 -> -636.3048 | H18: =-Debt!H85 -> -717.81545 | I18: =-Debt!I85 -> -809.76761 | J18: =-Debt!J85 -> -913.49884 | K18: =-Debt!K85 -> -1030.518 | L18: =-Debt!L85 -> -1162.5274 | ... O18: =-Debt!O85 -> 0
B19: Shareholder Loan (PIK) | E19: =-Debt!E86 -> -535.58253 | F19: =-Debt!F86 -> -615.91991 | G19: =-Debt!G86 -> -708.30789 | H19: =-Debt!H86 -> -814.55408 | I19: =-Debt!I86 -> -936.73719 | J19: =-Debt!J86 -> -1077.2478 | K19: =-Debt!K86 -> -1238.8349 | L19: =-Debt!L86 -> -1424.6602 | ... O19: =-Debt!O86 -> -2166.73
B20: Equity value on exit | F20: =SUM(F12:F19) -> 1350.7187 | G20: =SUM(G12:G19) -> 1795.0846 | H20: =SUM(H12:H19) -> 2253.8971 | I20: =SUM(I12:I19) -> 2718.1333 | J20: =SUM(J12:J19) -> 3145.6209 | K20: =SUM(K12:K19) -> 3523.4676 | L20: =SUM(L12:L19) -> 3833.6797 | M20: =SUM(M12:M19) -> 4072.2555 | ... O20: =SUM(O12:O19) -> 4319.2282
A22: Total equity returns
B23: Year | E23: =YEAR(E$2)-YEAR($E$2) -> 0 | F23: =YEAR(F$2)-YEAR($E$2) -> 1 | G23: =YEAR(G$2)-YEAR($E$2) -> 2 | H23: =YEAR(H$2)-YEAR($E$2) -> 3 | I23: =YEAR(I$2)-YEAR($E$2) -> 4 | J23: =YEAR(J$2)-YEAR($E$2) -> 5 | K23: =YEAR(K$2)-YEAR($E$2) -> 6 | L23: =YEAR(L$2)-YEAR($E$2) -> 7 | ... O23: =YEAR(O$2)-YEAR($E$2) -> 10
B24: Shareholder loan | E24: =-E19 -> 535.58253 | F24: =-F19 -> 615.91991 | G24: =-G19 -> 708.30789 | H24: =-H19 -> 814.55408 | I24: =-I19 -> 936.73719 | J24: =-J19 -> 1077.2478 | K24: =-K19 -> 1238.8349 | L24: =-L19 -> 1424.6602 | ... O24: =-O19 -> 2166.73
B25: Ordinary equity | E25: ='S&U'!C46 -> 600 | F25: =F20 -> 1350.7187 | G25: =G20 -> 1795.0846 | H25: =H20 -> 2253.8971 | I25: =I20 -> 2718.1333 | J25: =J20 -> 3145.6209 | K25: =K20 -> 3523.4676 | L25: =L20 -> 3833.6797 | M25: =M20 -> 4072.2555 | ... O25: =O20 -> 4319.2282
B27: Exit year | C27: MOIC | D27: IRR | E27: Investment | F27: Return
B28: Year 1 | C28: =SUM(F28:J28)/-E28 -> 1.7318324 | D28: =IRR(E28:O28) -> 0.73183242 | E28: =-SUM(E$24:E$25) -> -1135.5825 | F28: =SUM(F$24:F$25) -> 1966.6386
B29: Year 2 | C29: =SUM(F29:J29)/-E29 -> 2.2045007 | D29: =IRR(E29:O29) -> 0.48475611 | E29: =-SUM(E$24:E$25) -> -1135.5825 | F29: 0 | G29: =SUM(G$24:G$25) -> 2503.3925
B30: Year 3 | C30: =SUM(F30:J30)/-E30 -> 2.7020944 | D30: =IRR(E30:O30) -> 0.39283661 | E30: =-SUM(E$24:E$25) -> -1135.5825 | F30: 0 | G30: 0 | H30: =SUM(H$24:H$25) -> 3068.4512
B31: Year 4 | C31: =SUM(F31:J31)/-E31 -> 3.2184983 | D31: =IRR(E31:O31) -> 0.33940934 | E31: =-SUM(E$24:E$25) -> -1135.5825 | F31: 0 | G31: 0 | H31: 0 | I31: =SUM(I$24:I$25) -> 3654.8705
B32: Year 5 | C32: =SUM(F32:J32)/-E32 -> 3.7186806 | D32: =IRR(E32:O32) -> 0.30040244 | E32: =-SUM(E$24:E$25) -> -1135.5825 | F32: 0 | G32: 0 | H32: 0 | I32: 0 | J32: =SUM(J$24:J$25) -> 4222.8687
A34: Returns to institutional investors
B35: Year | E35: =YEAR(E$2)-YEAR($E$2) -> 0 | F35: =YEAR(F$2)-YEAR($E$2) -> 1 | G35: =YEAR(G$2)-YEAR($E$2) -> 2 | H35: =YEAR(H$2)-YEAR($E$2) -> 3 | I35: =YEAR(I$2)-YEAR($E$2) -> 4 | J35: =YEAR(J$2)-YEAR($E$2) -> 5 | K35: =YEAR(K$2)-YEAR($E$2) -> 6 | L35: =YEAR(L$2)-YEAR($E$2) -> 7 | ... O35: =YEAR(O$2)-YEAR($E$2) -> 10
B36: Shareholder loan | E36: =-E19 -> 535.58253 | F36: =-F19 -> 615.91991 | G36: =-G19 -> 708.30789 | H36: =-H19 -> 814.55408 | I36: =-I19 -> 936.73719 | J36: =-J19 -> 1077.2478 | K36: =-K19 -> 1238.8349 | L36: =-L19 -> 1424.6602 | ... O36: =-O19 -> 2166.73
B37: Ordinary equity | E37: =E25*'S&U'!$J$19 -> 594 | F37: =F25*'S&U'!$K$19 -> 1296.69 | G37: =G25*'S&U'!$K$19 -> 1723.2812 | H37: =H25*'S&U'!$K$19 -> 2163.7413 | I37: =I25*'S&U'!$K$19 -> 2609.408 | J37: =J25*'S&U'!$K$19 -> 3019.7961 | K37: =K25*'S&U'!$K$19 -> 3382.5289 | L37: =L25*'S&U'!$K$19 -> 3680.3325 | M37: =M25*'S&U'!$K$19 -> 3909.3653 | ... O37: =O25*'S&U'!$K$19 -> 4146.459
B39: Exit year | C39: MOIC | D39: IRR | E39: Investment | F39: Return
B40: Year 1 | C40: =SUM(F40:J40)/-E40 -> 1.6932007 | D40: =IRR(E40:O40) -> 0.69320066 | E40: =-SUM($E$36:$E$37) -> -1129.5825 | F40: =SUM(F$36:F$37) -> 1912.6099
B41: Year 2 | C41: =SUM(F41:J41)/-E41 -> 2.1526441 | D41: =IRR(E41:O41) -> 0.46718917 | E41: =-SUM($E$36:$E$37) -> -1129.5825 | F41: 0 | G41: =SUM(G$36:G$37) -> 2431.5891
B42: Year 3 | C42: =SUM(F42:J42)/-E42 -> 2.6366337 | D42: =IRR(E42:O42) -> 0.38149695 | E42: =-SUM($E$36:$E$37) -> -1129.5825 | F42: 0 | G42: 0 | H42: =SUM(H$36:H$37) -> 2978.2953
B43: Year 4 | C43: =SUM(F43:J43)/-E43 -> 3.1393414 | D43: =IRR(E43:O43) -> 0.33109679 | E43: =-SUM($E$36:$E$37) -> -1129.5825 | F43: 0 | G43: 0 | H43: 0 | I43: =SUM(I$36:I$37) -> 3546.1451
B44: Year 5 | C44: =SUM(F44:J44)/-E44 -> 3.6270425 | D44: =IRR(E44:O44) -> 0.29392925 | E44: =-SUM($E$36:$E$37) -> -1129.5825 | F44: 0 | G44: 0 | H44: 0 | I44: 0 | J44: =SUM(J$36:J$37) -> 4097.0438
A46: Returns to mezzanine investors
B47: Year | E47: =YEAR(E$2)-YEAR($E$2) -> 0 | F47: =YEAR(F$2)-YEAR($E$2) -> 1 | G47: =YEAR(G$2)-YEAR($E$2) -> 2 | H47: =YEAR(H$2)-YEAR($E$2) -> 3 | I47: =YEAR(I$2)-YEAR($E$2) -> 4 | J47: =YEAR(J$2)-YEAR($E$2) -> 5 | K47: =YEAR(K$2)-YEAR($E$2) -> 6 | L47: =YEAR(L$2)-YEAR($E$2) -> 7 | ... O47: =YEAR(O$2)-YEAR($E$2) -> 10
B48: Mezzanine loan plus accrued interest | E48: =-E18 -> 500 | F48: =-F18 -> 564.05 | G48: =-G18 -> 636.3048 | H48: =-H18 -> 717.81545 | I48: =-I18 -> 809.76761 | J48: =-J18 -> 913.49884 | K48: =-K18 -> 1030.518 | L48: =-L18 -> 1162.5274 | ... O48: =-O18 -> 0
...

Sheet Sensitivity
A1: =CoName -> Company2272
A2: =Ccy&Units&" unless otherwise stated" -> $m unless otherwise stated
B4: Premium paid (clone assumption) | E4: ='S&U'!E8 -> 0.38
B5: Operating case (clone assumption) | E5: =OpMod!C6 -> 1
B6: Exit multiple (clone assumption) | E6: =Returns!E5 -> 7
A8: Sensitivity analysis
B10: Sensitvity of returns to | C10: Premium | D10: Offer price | E10: Investment | F10: Institutional | G10: Mezzanine | H10: Mgmt
B11: Premium paid | C11: paid | D11: $ | E11: Year 3 IRR | F11: Year 3 IRR | G11: Year 3 IRR | H11: MOIC
D12: ='S&U'!E9 -> 32.0022 | E12: =Returns!D30 -> 0.39283661 | F12: =Returns!D42 -> 0.38149695 | G12: =Returns!D54 -> 0.13978575 | H12: =Returns!C65 -> 11.269486
C13: =C14-1% -> 0.32 | D13: 30.6108 | E13: 0.4780476 | F13: 0.46466813 | G13: 0.14123011 | H13: 12.678556
C14: =C15-1% -> 0.33 | D14: 30.8427 | E14: 0.46237449 | F14: 0.44934609 | G14: 0.14098964 | H14: 12.443711
C15: =C16-1% -> 0.34 | D15: 31.0746 | E15: 0.44734571 | F15: 0.43466394 | G15: 0.14074906 | H15: 12.208866
C16: =C17-1% -> 0.35 | D16: 31.3065 | E16: 0.43291628 | F16: 0.42057668 | G16: 0.14050839 | H16: 11.974021
C17: =C18-1% -> 0.36 | D17: 31.5384 | E17: 0.41904559 | F17: 0.40704371 | G17: 0.14026761 | H17: 11.739176
C18: =C19-1% -> 0.37 | D18: 31.7703 | E18: 0.40569685 | F18: 0.39402826 | G18: 0.14002673 | H18: 11.504331
C19: ='S&U'!E8 -> 0.38 | D19: 32.0022 | E19: 0.39283661 | F19: 0.38149695 | G19: 0.13978575 | H19: 11.269486
C20: =C19+1% -> 0.39 | D20: 32.2341 | E20: 0.38043444 | F20: 0.36941941 | G20: 0.13954467 | H20: 11.034641
C21: =C20+1% -> 0.4 | D21: 32.466 | E21: 0.36846252 | F21: 0.35776787 | G21: 0.13930348 | H21: 10.799796
C22: =C21+1% -> 0.41 | D22: 32.6979 | E22: 0.35689539 | F22: 0.34651698 | G22: 0.1390622 | H22: 10.564951
C23: =C22+1% -> 0.42 | D23: 32.9298 | E23: 0.34570969 | F23: 0.33564345 | G23: 0.13882081 | H23: 10.330105
C24: =C23+1% -> 0.43 | D24: 33.1617 | E24: 0.33488395 | F24: 0.32512588 | G24: 0.13857932 | H24: 10.09526
B26: Sensitvity of returns to | C26: Exit | D26: Offer price | E26: Investment | F26: Institutional | G26: Mezzanine | H26: Mgmt
B27: Exit multiple | C27: mulitple | D27: $ | E27: Year 3 IRR | F27: Year 3 IRR | G27: Year 3 IRR | H27: MOIC
D28: ='S&U'!$E$9 -> 32.0022 | E28: =Returns!$D$30 -> 0.39283661 | F28: =Returns!$D$42 -> 0.38149695 | G28: =Returns!$D$54 -> 0.13978575 | H28: =Returns!$C$65 -> 11.269486
C29: =C30-0.5 -> 6 | D29: 32.0022 | E29: 0.24388318 | F29: 0.23557108 | G29: 0.13523674 | H29: 6.8548976
C30: =C31-0.5 -> 6.5 | D30: 32.0022 | E30: 0.32255387 | F30: 0.31258979 | G30: 0.13751579 | H30: 9.0621917
C31: =Returns!E5 -> 7 | D31: 32.0022 | E31: 0.39283661 | F31: 0.38149695 | G31: 0.13978575 | H31: 11.269486
C32: =C31+0.5 -> 7.5 | D32: 32.0022 | E32: 0.45666302 | F32: 0.44414075 | G32: 0.1420467 | H32: 13.47678
C33: =C32+0.5 -> 8 | D33: 32.0022 | E33: 0.51533838 | F33: 0.50177571 | G33: 0.14429874 | H33: 15.684074
B35: Sensitvity of returns to | C35: Operating | D35: Offer price | E35: Investment | F35: Institutional | G35: Mezzanine | H35: Mgmt
B36: Operating case | C36: case | D36: $ | E36: Year 3 IRR | F36: Year 3 IRR | G36: Year 3 IRR | H36: MOIC
D37: ='S&U'!$E$9 -> 32.0022 | E37: =Returns!$D$30 -> 0.39283661 | F37: =Returns!$D$42 -> 0.38149695 | G37: =Returns!$D$54 -> 0.13978575 | H37: =Returns!$C$65 -> 11.269486
B38: Base | C38: 1 | D38: 32.0022 | E38: 0.39283661 | F38: 0.38149695 | G38: 0.13978575 | H38: 11.269486
B39: Management | C39: 2 | D39: 32.0022 | E39: 0.4563533 | F39: 0.44383664 | G39: 0.14203526 | H39: 13.465588
