Workbook

Sheet Nest Inputs
B2: NESTED FORMULA TEST SUITE — BASE INPUTS
B4: Test Input Values | D4: Description
B5: Zero | C5: 0 | D5: Hard-coded zero
B6: One | C6: 1 | D6: Hard-coded one
B7: Neg One | C7: -1 | D7: Hard-coded negative one
B8: Small Int | C8: 7 | D8: Small positive integer
B9: Neg Small Int | C9: -7 | D9: Small negative integer
B10: Pi Approx | C10: 3.1415927 | D10: Irrational approximation
B11: Decimal | C11: 0.001 | D11: Very small decimal
B12: Large | C12: 50000 | D12: Large integer
B13: Neg Large | C13: -50000 | D13: Large negative integer
B15: Derived Inputs (Level 0)
B16: Sum_01 | C16: =C5+C6 -> 1
B17: Diff_01 | C17: =C6-C7 -> 2
B18: Prod_01 | C18: =C6*C7 -> -1
B19: Ratio_01 | C19: =C8/C9 -> -1
B20: SqRoot_8 | C20: =SQRT(C12) -> 223.6068
B21: Abs_9 | C21: =ABS(C13) -> 50000
B22: Pct_6 | C22: =C10/100 -> 0.031415927
B23: Mod_4_1 | C23: =MOD(C8,C6) -> 0
B24: Power_1_4 | C24: =C6^C8 -> 1

Sheet Depth Chain
B2: DEPTH CHAIN — SAME-SHEET NESTING (12 LEVELS)
B4: Input → | C4: Zero | D4: One | E4: Neg One | F4: SmInt | G4: NSmInt | H4: Pi | I4: Dec | J4: Large | K4: NLarge
B5: L0: Raw Input | C5: ='Nest Inputs'!C5 -> 0 | D5: ='Nest Inputs'!C6 -> 1 | E5: ='Nest Inputs'!C7 -> -1 | F5: ='Nest Inputs'!C8 -> 7 | G5: ='Nest Inputs'!C9 -> -7 | H5: ='Nest Inputs'!C10 -> 3.1415927 | I5: ='Nest Inputs'!C11 -> 0.001 | J5: ='Nest Inputs'!C12 -> 50000 | K5: ='Nest Inputs'!C13 -> -50000
B6: L1: +1 | C6: =C5+1 -> 1 | D6: =D5+1 -> 2 | E6: =E5+1 -> 0 | F6: =F5+1 -> 8 | G6: =G5+1 -> -6 | H6: =H5+1 -> 4.1415926 | I6: =I5+1 -> 1.001 | J6: =J5+1 -> 50001 | K6: =K5+1 -> -49999
B7: L2: *2 | C7: =C6*2 -> 2 | D7: =D6*2 -> 4 | E7: =E6*2 -> 0 | F7: =F6*2 -> 16 | G7: =G6*2 -> -12 | H7: =H6*2 -> 8.2831853 | I7: =I6*2 -> 2.002 | J7: =J6*2 -> 100002 | K7: =K6*2 -> -99998
B8: L3: ABS() | C8: =ABS(C7) -> 2 | D8: =ABS(D7) -> 4 | E8: =ABS(E7) -> 0 | F8: =ABS(F7) -> 16 | G8: =ABS(G7) -> 12 | H8: =ABS(H7) -> 8.2831853 | I8: =ABS(I7) -> 2.002 | J8: =ABS(J7) -> 100002 | K8: =ABS(K7) -> 99998
B9: L4: +L0 | C9: =C8+C5 -> 2 | D9: =D8+D5 -> 5 | E9: =E8+E5 -> -1 | F9: =F8+F5 -> 23 | G9: =G8+G5 -> 5 | H9: =H8+H5 -> 11.424778 | I9: =I8+I5 -> 2.003 | J9: =J8+J5 -> 150002 | K9: =K8+K5 -> 49998
B10: L5: SQRT(ABS()) | C10: =SQRT(ABS(C9)) -> 1.4142136 | D10: =SQRT(ABS(D9)) -> 2.236068 | E10: =SQRT(ABS(E9)) -> 1 | F10: =SQRT(ABS(F9)) -> 4.7958315 | G10: =SQRT(ABS(G9)) -> 2.236068 | H10: =SQRT(ABS(H9)) -> 3.3800559 | I10: =SQRT(ABS(I9)) -> 1.4152738 | J10: =SQRT(ABS(J9)) -> 387.30092 | K10: =SQRT(ABS(K9)) -> 223.60233
B11: L6: *L2+L3 | C11: =C10*C7+C8 -> 4.8284271 | D11: =D10*D7+D8 -> 12.944272 | E11: =E10*E7+E8 -> 0 | F11: =F10*F7+F8 -> 92.733304 | G11: =G10*G7+G8 -> -14.832816 | H11: =H10*H7+H8 -> 36.280815 | I11: =I10*I7+I8 -> 4.8353782 | J11: =J10*J7+J8 -> 38830868 | K11: =K10*K7+K8 -> -22259787
B12: L7: ROUND(,4) | C12: =ROUND(C11,4) -> 4.8284 | D12: =ROUND(D11,4) -> 12.9443 | E12: =ROUND(E11,4) -> 0 | F12: =ROUND(F11,4) -> 92.7333 | G12: =ROUND(G11,4) -> -14.8328 | H12: =ROUND(H11,4) -> 36.2808 | I12: =ROUND(I11,4) -> 4.8354 | J12: =ROUND(J11,4) -> 38830868 | K12: =ROUND(K11,4) -> -22259787
B13: L8: IF(>0,L7,-L5) | C13: =IF(C12>0,C12,-C10) -> 4.8284 | D13: =IF(D12>0,D12,-D10) -> 12.9443 | E13: =IF(E12>0,E12,-E10) -> -1 | F13: =IF(F12>0,F12,-F10) -> 92.7333 | G13: =IF(G12>0,G12,-G10) -> -2.236068 | H13: =IF(H12>0,H12,-H10) -> 36.2808 | I13: =IF(I12>0,I12,-I10) -> 4.8354 | J13: =IF(J12>0,J12,-J10) -> 38830868 | K13: =IF(K12>0,K12,-K10) -> -223.60233
B14: L9: MOD(ABS(),7) | C14: =MOD(ABS(C13),7) -> 4.8284 | D14: =MOD(ABS(D13),7) -> 5.9443 | E14: =MOD(ABS(E13),7) -> 1 | F14: =MOD(ABS(F13),7) -> 1.7333 | G14: =MOD(ABS(G13),7) -> 2.236068 | H14: =MOD(ABS(H13),7) -> 1.2808 | I14: =MOD(ABS(I13),7) -> 4.8354 | J14: =MOD(ABS(J13),7) -> 6.2619 | K14: =MOD(ABS(K13),7) -> 6.6023256
B15: L10: SUM(L0:L9) | C15: =SUM(C5:C14) -> 27.727841 | D15: =SUM(D5:D14) -> 63.01324 | E15: =SUM(E5:E14) -> -1 | F15: =SUM(F5:F14) -> 354.72904 | G15: =SUM(G5:G14) -> -35.429548 | H15: =SUM(H5:H14) -> 148.7776 | I15: =SUM(I5:I14) -> 27.765852 | J15: =SUM(J5:J14) -> 1.1694301e+08 | K15: =SUM(K5:K14) -> -44569569
B16: L11: L10/MAX(L0:L5,1) | C16: =C15/MAX(C5:C10,1) -> 13.86392 | D16: =D15/MAX(D5:D10,1) -> 12.602648 | E16: =E15/MAX(E5:E10,1) -> -1 | F16: =F15/MAX(F5:F10,1) -> 15.423002 | G16: =G15/MAX(G5:G10,1) -> -2.9524623 | H16: =H15/MAX(H5:H10,1) -> 13.022363 | I16: =I15/MAX(I5:I10,1) -> 13.862133 | J16: =J15/MAX(J5:J10,1) -> 779.60964 | K16: =K15/MAX(K5:K10,1) -> -445.70461
B19: HORIZONTAL CHAIN — LEFT-TO-RIGHT NESTING (9 LEVELS)
B21: Input ↓ | C21: L0: Input | D21: L1: +10 | E21: L2: *3 | F21: L3: ABS() | G21: L4: -L0 | H21: L5: ^2 | I21: L6: /100 | J21: L7: ROUND(,2) | K21: L8: MAX(.,0)
B22: Zero | C22: ='Nest Inputs'!C5 -> 0 | D22: =C22+10 -> 10 | E22: =D22*3 -> 30 | F22: =ABS(E22) -> 30 | G22: =F22-C22 -> 30 | H22: =G22^2 -> 900 | I22: =H22/100 -> 9 | J22: =ROUND(I22,2) -> 9 | K22: =MAX(J22,0) -> 9
B23: One | C23: ='Nest Inputs'!C6 -> 1 | D23: =C23+10 -> 11 | E23: =D23*3 -> 33 | F23: =ABS(E23) -> 33 | G23: =F23-C23 -> 32 | H23: =G23^2 -> 1024 | I23: =H23/100 -> 10.24 | J23: =ROUND(I23,2) -> 10.24 | K23: =MAX(J23,0) -> 10.24
B24: Neg One | C24: ='Nest Inputs'!C7 -> -1 | D24: =C24+10 -> 9 | E24: =D24*3 -> 27 | F24: =ABS(E24) -> 27 | G24: =F24-C24 -> 28 | H24: =G24^2 -> 784 | I24: =H24/100 -> 7.84 | J24: =ROUND(I24,2) -> 7.84 | K24: =MAX(J24,0) -> 7.84
B25: SmInt | C25: ='Nest Inputs'!C8 -> 7 | D25: =C25+10 -> 17 | E25: =D25*3 -> 51 | F25: =ABS(E25) -> 51 | G25: =F25-C25 -> 44 | H25: =G25^2 -> 1936 | I25: =H25/100 -> 19.36 | J25: =ROUND(I25,2) -> 19.36 | K25: =MAX(J25,0) -> 19.36
B26: NSmInt | C26: ='Nest Inputs'!C9 -> -7 | D26: =C26+10 -> 3 | E26: =D26*3 -> 9 | F26: =ABS(E26) -> 9 | G26: =F26-C26 -> 16 | H26: =G26^2 -> 256 | I26: =H26/100 -> 2.56 | J26: =ROUND(I26,2) -> 2.56 | K26: =MAX(J26,0) -> 2.56
B27: Pi | C27: ='Nest Inputs'!C10 -> 3.1415927 | D27: =C27+10 -> 13.141593 | E27: =D27*3 -> 39.424778 | F27: =ABS(E27) -> 39.424778 | G27: =F27-C27 -> 36.283185 | H27: =G27^2 -> 1316.4695 | I27: =H27/100 -> 13.164695 | J27: =ROUND(I27,2) -> 13.16 | K27: =MAX(J27,0) -> 13.16
B28: Dec | C28: ='Nest Inputs'!C11 -> 0.001 | D28: =C28+10 -> 10.001 | E28: =D28*3 -> 30.003 | F28: =ABS(E28) -> 30.003 | G28: =F28-C28 -> 30.002 | H28: =G28^2 -> 900.12 | I28: =H28/100 -> 9.0012 | J28: =ROUND(I28,2) -> 9 | K28: =MAX(J28,0) -> 9
B29: Large | C29: ='Nest Inputs'!C12 -> 50000 | D29: =C29+10 -> 50010 | E29: =D29*3 -> 150030 | F29: =ABS(E29) -> 150030 | G29: =F29-C29 -> 100030 | H29: =G29^2 -> 10006000900 | I29: =H29/100 -> 100060009 | J29: =ROUND(I29,2) -> 100060009 | K29: =MAX(J29,0) -> 100060009
B30: NLarge | C30: ='Nest Inputs'!C13 -> -50000 | D30: =C30+10 -> -49990 | E30: =D30*3 -> -149970 | F30: =ABS(E30) -> 149970 | G30: =F30-C30 -> 199970 | H30: =G30^2 -> 39988000900 | I30: =H30/100 -> 399880009 | J30: =ROUND(I30,2) -> 399880009 | K30: =MAX(J30,0) -> 399880009

Sheet Cross-Sheet Nest
B2: CROSS-SHEET NESTING — FORMULAS REFERENCING FORMULAS ACROSS SHEETS
B4: Section 1: Layered on Depth Chain Vertical (adds 4 more levels → total 16 deep)
B5: Input → | C5: Zero | D5: One | E5: Neg One | F5: SmInt | G5: NSmInt | H5: Pi | I5: Dec | J5: Large | K5: NLarge
B6: L12: Pull DC.L11 | C6: ='Depth Chain'!C16 -> 13.86392 | D6: ='Depth Chain'!D16 -> 12.602648 | E6: ='Depth Chain'!E16 -> -1 | F6: ='Depth Chain'!F16 -> 15.423002 | G6: ='Depth Chain'!G16 -> -2.9524623 | H6: ='Depth Chain'!H16 -> 13.022363 | I6: ='Depth Chain'!I16 -> 13.862133 | J6: ='Depth Chain'!J16 -> 779.60964 | K6: ='Depth Chain'!K16 -> -445.70461
B7: L13: +NI.Derived | C7: =C6+'Nest Inputs'!C16 -> 14.86392 | D7: =D6+'Nest Inputs'!C17 -> 14.602648 | E7: =E6+'Nest Inputs'!C18 -> -2 | F7: =F6+'Nest Inputs'!C19 -> 14.423002 | G7: =G6+'Nest Inputs'!C20 -> 220.65434 | H7: =H6+'Nest Inputs'!C21 -> 50013.022 | I7: =I6+'Nest Inputs'!C22 -> 13.893549 | J7: =J6+'Nest Inputs'!C23 -> 779.60964 | K7: =K6+'Nest Inputs'!C24 -> -444.70461
B8: L14: *DC.Horiz.L8 | C8: =C7*'Depth Chain'!K22 -> 133.77528 | D8: =D7*'Depth Chain'!K23 -> 149.53112 | E8: =E7*'Depth Chain'!K24 -> -15.68 | F8: =F7*'Depth Chain'!K25 -> 279.22931 | G8: =G7*'Depth Chain'!K26 -> 564.8751 | H8: =H7*'Depth Chain'!K27 -> 658171.37 | I8: =I7*'Depth Chain'!K28 -> 125.04194 | J8: =J7*'Depth Chain'!K29 -> 7.8007748e+10 | K8: =K7*'Depth Chain'!K30 -> -1.7782848e+11
B9: L15: AVERAGE(L12:L14) | C9: =AVERAGE(C6:C8) -> 54.167708 | D9: =AVERAGE(D6:D8) -> 58.912137 | E9: =AVERAGE(E6:E8) -> -6.2266667 | F9: =AVERAGE(F6:F8) -> 103.0251 | G9: =AVERAGE(G6:G8) -> 260.85899 | H9: =AVERAGE(H6:H8) -> 236065.81 | I9: =AVERAGE(I6:I8) -> 50.93254 | J9: =AVERAGE(J6:J8) -> 2.6002583e+10 | K9: =AVERAGE(K6:K8) -> -5.9276161e+10
B12: Section 2: Cross-Column Fan (each column depends on previous column + cross-sheet ref)
B13: Row ↓ | C13: C | D13: D | E13: E | F13: F | G13: G | H13: H | I13: I | J13: J | K13: K
B14: Col C: Base | C14: ='Nest Inputs'!C5 -> 0 | D14: =C14+'Depth Chain'!D5 -> 1 | E14: =D14+'Nest Inputs'!C16 -> 2 | F14: =E14*C14 -> 0 | G14: =SUM(C14:F14) -> 3 | H14: =G14/MAX(C14:G14,1) -> 1 | I14: =SQRT(ABS(H14)) -> 1 | J14: =I14+'Depth Chain'!J10 -> 388.30092 | K14: =ROUND(J14,2) -> 388.3
B15: Col D: C+DC | C15: ='Nest Inputs'!C6 -> 1 | D15: =C15+'Depth Chain'!D6 -> 3 | E15: =D15+'Nest Inputs'!C17 -> 5 | F15: =E15*C15 -> 5 | G15: =SUM(C15:F15) -> 14 | H15: =G15/MAX(C15:G15,1) -> 1 | I15: =SQRT(ABS(H15)) -> 1 | J15: =I15+'Depth Chain'!J10 -> 388.30092 | K15: =ROUND(J15,2) -> 388.3
B16: Col E: D+NI | C16: ='Nest Inputs'!C7 -> -1 | D16: =C16+'Depth Chain'!D7 -> 3 | E16: =D16+'Nest Inputs'!C18 -> 2 | F16: =E16*C16 -> -2 | G16: =SUM(C16:F16) -> 2 | H16: =G16/MAX(C16:G16,1) -> 0.66666667 | I16: =SQRT(ABS(H16)) -> 0.81649658 | J16: =I16+'Depth Chain'!J10 -> 388.11741 | K16: =ROUND(J16,2) -> 388.12
B17: Col F: E*C | C17: ='Nest Inputs'!C8 -> 7 | D17: =C17+'Depth Chain'!D8 -> 11 | E17: =D17+'Nest Inputs'!C19 -> 10 | F17: =E17*C17 -> 70 | G17: =SUM(C17:F17) -> 98 | H17: =G17/MAX(C17:G17,1) -> 1 | I17: =SQRT(ABS(H17)) -> 1 | J17: =I17+'Depth Chain'!J10 -> 388.30092 | K17: =ROUND(J17,2) -> 388.3
B18: Col G: SUM(C:F) | C18: ='Nest Inputs'!C9 -> -7 | D18: =C18+'Depth Chain'!D9 -> -2 | E18: =D18+'Nest Inputs'!C20 -> 221.6068 | F18: =E18*C18 -> -1551.2476 | G18: =SUM(C18:F18) -> -1338.6408 | H18: =G18/MAX(C18:G18,1) -> -6.0406125 | I18: =SQRT(ABS(H18)) -> 2.4577657 | J18: =I18+'Depth Chain'!J10 -> 389.75868 | K18: =ROUND(J18,2) -> 389.76
B19: Col H: G/MAX(C:F,1) | C19: ='Nest Inputs'!C10 -> 3.1415927 | D19: =C19+'Depth Chain'!D10 -> 5.3776606 | E19: =D19+'Nest Inputs'!C21 -> 50005.378 | F19: =E19*C19 -> 157096.53 | G19: =SUM(C19:F19) -> 207110.42 | H19: =G19/MAX(C19:G19,1) -> 1 | I19: =SQRT(ABS(H19)) -> 1 | J19: =I19+'Depth Chain'!J10 -> 388.30092 | K19: =ROUND(J19,2) -> 388.3
B20: Col I: SQRT(ABS(H)) | C20: ='Nest Inputs'!C11 -> 0.001 | D20: =C20+'Depth Chain'!D11 -> 12.945272 | E20: =D20+'Nest Inputs'!C22 -> 12.976688 | F20: =E20*C20 -> 0.012976688 | G20: =SUM(C20:F20) -> 25.935936 | H20: =G20/MAX(C20:G20,1) -> 1 | I20: =SQRT(ABS(H20)) -> 1 | J20: =I20+'Depth Chain'!J10 -> 388.30092 | K20: =ROUND(J20,2) -> 388.3
B21: Col J: I+DC.L5 | C21: ='Nest Inputs'!C12 -> 50000 | D21: =C21+'Depth Chain'!D12 -> 50012.944 | E21: =D21+'Nest Inputs'!C23 -> 50012.944 | F21: =E21*C21 -> 2500647215 | G21: =SUM(C21:F21) -> 2.5007972e+09 | H21: =G21/MAX(C21:G21,1) -> 1 | I21: =SQRT(ABS(H21)) -> 1 | J21: =I21+'Depth Chain'!J10 -> 388.30092 | K21: =ROUND(J21,2) -> 388.3
B22: Col K: ROUND(J,2) | C22: ='Nest Inputs'!C13 -> -50000 | D22: =C22+'Depth Chain'!D13 -> -49987.056 | E22: =D22+'Nest Inputs'!C24 -> -49986.056 | F22: =E22*C22 -> 2499302785 | G22: =SUM(C22:F22) -> 2.4991528e+09 | H22: =G22/MAX(C22:G22,1) -> 0.99993999 | I22: =SQRT(ABS(H22)) -> 0.99997 | J22: =I22+'Depth Chain'!J10 -> 388.30089 | K22: =ROUND(J22,2) -> 388.3
B25: Section 3: Deep Aggregation (formulas referencing formulas referencing formulas)
B26: Input → | C26: Zero | D26: One | E26: Neg One | F26: SmInt | G26: NSmInt | H26: Pi | I26: Dec | J26: Large | K26: NLarge
B27: Agg1: SUM(S1.L12:L15) | C27: =SUM(C6:C9) -> 216.67083 | D27: =SUM(D6:D9) -> 235.64855 | E27: =SUM(E6:E9) -> -24.906667 | F27: =SUM(F6:F9) -> 412.10042 | G27: =SUM(G6:G9) -> 1043.436 | H27: =SUM(H6:H9) -> 944263.23 | I27: =SUM(I6:I9) -> 203.73016 | J27: =SUM(J6:J9) -> 1.0401033e+11 | K27: =SUM(K6:K9) -> -2.3710464e+11
B28: Agg2: Agg1*S2.ColK | C28: =C27*K14 -> 84133.284 | D28: =D27*K15 -> 91502.331 | E28: =E27*K16 -> -9666.7755 | F28: =F27*K17 -> 160018.59 | G28: =G27*K18 -> 406689.6 | H28: =H27*K19 -> 3.6665741e+08 | I28: =I27*K20 -> 79108.421 | J28: =J27*K21 -> 4.0387212e+13 | K28: =K27*K22 -> -9.2067733e+13
B29: Agg3: IF(Agg2>0,Agg1,-Agg2) | C29: =IF(C28>0,C27,-C28) -> 216.67083 | D29: =IF(D28>0,D27,-D28) -> 235.64855 | E29: =IF(E28>0,E27,-E28) -> 9666.7755 | F29: =IF(F28>0,F27,-F28) -> 412.10042 | G29: =IF(G28>0,G27,-G28) -> 1043.436 | H29: =IF(H28>0,H27,-H28) -> 944263.23 | I29: =IF(I28>0,I27,-I28) -> 203.73016 | J29: =IF(J28>0,J27,-J28) -> 1.0401033e+11 | K29: =IF(K28>0,K27,-K28) -> 9.2067733e+13
B30: Agg4: Agg3+DC.L10 | C30: =C29+'Depth Chain'!C15 -> 244.39867 | D30: =D29+'Depth Chain'!D15 -> 298.66179 | E30: =E29+'Depth Chain'!E15 -> 9665.7755 | F30: =F29+'Depth Chain'!F15 -> 766.82945 | G30: =G29+'Depth Chain'!G15 -> 1008.0064 | H30: =H29+'Depth Chain'!H15 -> 944412 | I30: =I29+'Depth Chain'!I15 -> 231.49601 | J30: =J29+'Depth Chain'!J15 -> 1.0412728e+11 | K30: =K29+'Depth Chain'!K15 -> 9.2067688e+13
B31: Agg5: ROUND(Agg4/Agg1,6) | C31: =IFERROR(ROUND(C30/C27,6),0) -> 1.127972 | D31: =IFERROR(ROUND(D30/D27,6),0) -> 1.267403 | E31: =IFERROR(ROUND(E30/E27,6),0) -> -388.07985 | F31: =IFERROR(ROUND(F30/F27,6),0) -> 1.860783 | G31: =IFERROR(ROUND(G30/G27,6),0) -> 0.966045 | H31: =IFERROR(ROUND(H30/H27,6),0) -> 1.000158 | I31: =IFERROR(ROUND(I30/I27,6),0) -> 1.136287 | J31: =IFERROR(ROUND(J30/J27,6),0) -> 1.001124 | K31: =IFERROR(ROUND(K30/K27,6),0) -> -388.29981
B32: Agg6: ABS(Agg5-Agg3) | C32: =ABS(C31-C29) -> 215.54286 | D32: =ABS(D31-D29) -> 234.38115 | E32: =ABS(E31-E29) -> 10054.855 | F32: =ABS(F31-F29) -> 410.23963 | G32: =ABS(G31-G29) -> 1042.4699 | H32: =ABS(H31-H29) -> 944262.23 | I32: =ABS(I31-I29) -> 202.59387 | J32: =ABS(J31-J29) -> 1.0401033e+11 | K32: =ABS(K31-K29) -> 9.2067733e+13

Sheet Diamond Deps
B2: DIAMOND DEPENDENCIES — FAN-OUT / FAN-IN ACROSS ALL SHEETS
B4: Section 1: Diamond (1 source → 3 paths → 1 merge, per input)
B5: Input → | C5: Zero | D5: One | E5: Neg One | F5: SmInt | G5: NSmInt | H5: Pi | I5: Dec | J5: Large | K5: NLarge
B6: Source: NI raw | C6: ='Nest Inputs'!C5 -> 0 | D6: ='Nest Inputs'!C6 -> 1 | E6: ='Nest Inputs'!C7 -> -1 | F6: ='Nest Inputs'!C8 -> 7 | G6: ='Nest Inputs'!C9 -> -7 | H6: ='Nest Inputs'!C10 -> 3.1415927 | I6: ='Nest Inputs'!C11 -> 0.001 | J6: ='Nest Inputs'!C12 -> 50000 | K6: ='Nest Inputs'!C13 -> -50000
B7: Path A: DC.Vert.L11 | C7: ='Depth Chain'!C16 -> 13.86392 | D7: ='Depth Chain'!D16 -> 12.602648 | E7: ='Depth Chain'!E16 -> -1 | F7: ='Depth Chain'!F16 -> 15.423002 | G7: ='Depth Chain'!G16 -> -2.9524623 | H7: ='Depth Chain'!H16 -> 13.022363 | I7: ='Depth Chain'!I16 -> 13.862133 | J7: ='Depth Chain'!J16 -> 779.60964 | K7: ='Depth Chain'!K16 -> -445.70461
B8: Path B: DC.Horiz.L8 | C8: ='Depth Chain'!K22 -> 9 | D8: ='Depth Chain'!K23 -> 10.24 | E8: ='Depth Chain'!K24 -> 7.84 | F8: ='Depth Chain'!K25 -> 19.36 | G8: ='Depth Chain'!K26 -> 2.56 | H8: ='Depth Chain'!K27 -> 13.16 | I8: ='Depth Chain'!K28 -> 9 | J8: ='Depth Chain'!K29 -> 100060009 | K8: ='Depth Chain'!K30 -> 399880009
B9: Path C: CSN.S1.L15 | C9: ='Cross-Sheet Nest'!C9 -> 54.167708 | D9: ='Cross-Sheet Nest'!D9 -> 58.912137 | E9: ='Cross-Sheet Nest'!E9 -> -6.2266667 | F9: ='Cross-Sheet Nest'!F9 -> 103.0251 | G9: ='Cross-Sheet Nest'!G9 -> 260.85899 | H9: ='Cross-Sheet Nest'!H9 -> 236065.81 | I9: ='Cross-Sheet Nest'!I9 -> 50.93254 | J9: ='Cross-Sheet Nest'!J9 -> 2.6002583e+10 | K9: ='Cross-Sheet Nest'!K9 -> -5.9276161e+10
B10: Merge: A+B+C | C10: =C7+C8+C9 -> 77.031628 | D10: =D7+D8+D9 -> 81.754785 | E10: =E7+E8+E9 -> 0.61333333 | F10: =F7+F8+F9 -> 137.80811 | G10: =G7+G8+G9 -> 260.46653 | H10: =H7+H8+H9 -> 236091.99 | I10: =I7+I8+I9 -> 73.794673 | J10: =J7+J8+J9 -> 2.6102644e+10 | K10: =K7+K8+K9 -> -5.8876281e+10
B11: Merge2: Merge*Src/MAX | C11: =IFERROR(C10*C6/MAX(ABS(C7),ABS(C8),ABS(C9),1),0) -> 0 | D11: =IFERROR(D10*D6/MAX(ABS(D7),ABS(D8),ABS(D9),1),0) -> 1.3877409 | E11: =IFERROR(E10*E6/MAX(ABS(E7),ABS(E8),ABS(E9),1),0) -> -0.078231293 | F11: =IFERROR(F10*F6/MAX(ABS(F7),ABS(F8),ABS(F9),1),0) -> 9.3633173 | G11: =IFERROR(G10*G6/MAX(ABS(G7),ABS(G8),ABS(G9),1),0) -> -6.9894685 | H11: =IFERROR(H10*H6/MAX(ABS(H7),ABS(H8),ABS(H9),1),0) -> 3.1419411 | I11: =IFERROR(I10*I6/MAX(ABS(I7),ABS(I8),ABS(I9),1),0) -> 0.0014488709 | J11: =IFERROR(J10*J6/MAX(ABS(J7),ABS(J8),ABS(J9),1),0) -> 50192.405 | K11: =IFERROR(K10*K6/MAX(ABS(K7),ABS(K8),ABS(K9),1),0) -> 49662.698
B12: Final: ROUND(ABS(),4) | C12: =ROUND(ABS(C11),4) -> 0 | D12: =ROUND(ABS(D11),4) -> 1.3877 | E12: =ROUND(ABS(E11),4) -> 0.0782 | F12: =ROUND(ABS(F11),4) -> 9.3633 | G12: =ROUND(ABS(G11),4) -> 6.9895 | H12: =ROUND(ABS(H11),4) -> 3.1419 | I12: =ROUND(ABS(I11),4) -> 0.0014 | J12: =ROUND(ABS(J11),4) -> 50192.406 | K12: =ROUND(ABS(K11),4) -> 49662.698
B15: Section 2: Multi-Source Matrix (each cell pulls from a different sheet+level combo)
B16: Input → | C16: Zero | D16: One | E16: Neg One | F16: SmInt | G16: NSmInt | H16: Pi | I16: Dec | J16: Large | K16: NLarge
B17: NI.Raw + NI.Derived | C17: ='Nest Inputs'!C5+'Nest Inputs'!C16 -> 1 | D17: ='Nest Inputs'!C6+'Nest Inputs'!C17 -> 3 | E17: ='Nest Inputs'!C7+'Nest Inputs'!C18 -> -2 | F17: ='Nest Inputs'!C8+'Nest Inputs'!C19 -> 6 | G17: ='Nest Inputs'!C9+'Nest Inputs'!C20 -> 216.6068 | H17: ='Nest Inputs'!C10+'Nest Inputs'!C21 -> 50003.142 | I17: ='Nest Inputs'!C11+'Nest Inputs'!C22 -> 0.032415927 | J17: ='Nest Inputs'!C12+'Nest Inputs'!C23 -> 50000 | K17: ='Nest Inputs'!C13+'Nest Inputs'!C24 -> -49999
B18: DC.V.L3 * DC.H.L4 | C18: ='Depth Chain'!C8*'Depth Chain'!G22 -> 60 | D18: ='Depth Chain'!D8*'Depth Chain'!G23 -> 128 | E18: ='Depth Chain'!E8*'Depth Chain'!G24 -> 0 | F18: ='Depth Chain'!F8*'Depth Chain'!G25 -> 704 | G18: ='Depth Chain'!G8*'Depth Chain'!G26 -> 192 | H18: ='Depth Chain'!H8*'Depth Chain'!G27 -> 300.54035 | I18: ='Depth Chain'!I8*'Depth Chain'!G28 -> 60.064004 | J18: ='Depth Chain'!J8*'Depth Chain'!G29 -> 10003200060 | K18: ='Depth Chain'!K8*'Depth Chain'!G30 -> 19996600060
B19: CSN.S2.ColE + DD.S1.Merge | C19: ='Cross-Sheet Nest'!E14+C10 -> 79.031628 | D19: ='Cross-Sheet Nest'!E15+D10 -> 86.754785 | E19: ='Cross-Sheet Nest'!E16+E10 -> 2.6133333 | F19: ='Cross-Sheet Nest'!E17+F10 -> 147.80811 | G19: ='Cross-Sheet Nest'!E18+G10 -> 482.07333 | H19: ='Cross-Sheet Nest'!E19+H10 -> 286097.37 | I19: ='Cross-Sheet Nest'!E20+I10 -> 86.771361 | J19: ='Cross-Sheet Nest'!E21+J10 -> 2.6102694e+10 | K19: ='Cross-Sheet Nest'!E22+K10 -> -5.8876331e+10
B20: SUM of above 3 rows | C20: =SUM(C17:C19) -> 140.03163 | D20: =SUM(D17:D19) -> 217.75479 | E20: =SUM(E17:E19) -> 0.61333333 | F20: =SUM(F17:F19) -> 857.80811 | G20: =SUM(G17:G19) -> 890.68012 | H20: =SUM(H17:H19) -> 336401.05 | I20: =SUM(I17:I19) -> 146.86778 | J20: =SUM(J17:J19) -> 3.6105944e+10 | K20: =SUM(K17:K19) -> -3.8879781e+10
B21: Running product: row*prev | C21: =IFERROR(C20*C20,0) -> 19608.857 | D21: =IFERROR(D20*D20,0) -> 47417.146 | E21: =IFERROR(E20*E20,0) -> 0.37617778 | F21: =IFERROR(F20*F20,0) -> 735834.75 | G21: =IFERROR(G20*G20,0) -> 793311.08 | H21: =IFERROR(H20*H20,0) -> 1.1316567e+11 | I21: =IFERROR(I20*I20,0) -> 21570.145 | J21: =IFERROR(J20*J20,0) -> 1.3036392e+21 | K21: =IFERROR(K20*K20,0) -> 1.5116374e+21
B22: Grand: IFERROR(row/SUM(r1:r3),0) | C22: =IFERROR(C21/SUM(C17:C19),0) -> 140.03163 | D22: =IFERROR(D21/SUM(D17:D19),0) -> 217.75479 | E22: =IFERROR(E21/SUM(E17:E19),0) -> 0.61333333 | F22: =IFERROR(F21/SUM(F17:F19),0) -> 857.80811 | G22: =IFERROR(G21/SUM(G17:G19),0) -> 890.68012 | H22: =IFERROR(H21/SUM(H17:H19),0) -> 336401.05 | I22: =IFERROR(I21/SUM(I17:I19),0) -> 146.86778 | J22: =IFERROR(J21/SUM(J17:J19),0) -> 3.6105944e+10 | K22: =IFERROR(K21/SUM(K17:K19),0) -> -3.8879781e+10
B25: Section 3: Ultimate Convergence (single deep chain, max cross-sheet depth)
B27: U0: NI.C6 (=1) | C27: ='Nest Inputs'!C6 -> 1
B28: U1: DC.D16 (L11 of '1') | C28: ='Depth Chain'!D16 -> 12.602648
B29: U2: CSN.D9 (S1.L15 of '1') | C29: ='Cross-Sheet Nest'!D9 -> 58.912137
B30: U3: DD.S1.Final.D (above) | C30: =D12 -> 1.3877
B31: U4: U0+U1+U2+U3 | C31: =C27+C28+C29+C30 -> 73.902485
B32: U5: DD.S2.Grand.D | C32: =D22 -> 217.75479
B33: U6: U4*U5 | C33: =C31*C32 -> 16092.62
B34: U7: CSN.Agg6.D | C34: ='Cross-Sheet Nest'!D32 -> 234.38115
B35: U8: U6+U7 | C35: =C33+C34 -> 16327.001
B36: U9: ROUND(ABS(U8),2) | C36: =ROUND(ABS(C35),2) -> 16327
B37: U10: IF(U9>U4,U9-U4,U4-U9) | C37: =IF(C36>C31,C36-C31,C31-C36) -> 16253.098

Sheet Extreme Depth
B2: EXTREME DEPTH CHAINS — 1,000 & 10,000 LEVEL NESTING
B4: Section 1: 1,000-Level Dependency Chain (C5:C1004) | E4: Section 2: 10,000-Level Dependency Chain (E5:E10004)
B5: L0: Seed (=1) | C5: 1 | E5: 1
B6: L1: *1.001 | C6: =C5*1.001 -> 1.001 | E6: =E5*1.001 -> 1.001
B7: L2: -0.5 | C7: =C6-0.5 -> 0.501 | E7: =E6-0.5 -> 0.501
B8: L3: MOD(,100) | C8: =MOD(ABS(C7),100) -> 0.501 | E8: =MOD(ABS(E7),100) -> 0.501
B9: L4: +1 | C9: =C8+1 -> 1.501 | E9: =E8+1 -> 1.501
B10: L5: *1.001 | C10: =C9*1.001 -> 1.502501 | E10: =E9*1.001 -> 1.502501
B11: L6: -0.5 | C11: =C10-0.5 -> 1.002501 | E11: =E10-0.5 -> 1.002501
B12: L7: MOD(,100) | C12: =MOD(ABS(C11),100) -> 1.002501 | E12: =MOD(ABS(E11),100) -> 1.002501
B13: L8: +1 | C13: =C12+1 -> 2.002501 | E13: =E12+1 -> 2.002501
B14: L9: *1.001 | C14: =C13*1.001 -> 2.0045035 | E14: =E13*1.001 -> 2.0045035
B15: L10: -0.5 | C15: =C14-0.5 -> 1.5045035 | E15: =E14-0.5 -> 1.5045035
B16: L11: MOD(,100) | C16: =MOD(ABS(C15),100) -> 1.5045035 | E16: =MOD(ABS(E15),100) -> 1.5045035
B17: L12: +1 | C17: =C16+1 -> 2.5045035 | E17: =E16+1 -> 2.5045035
B18: L13: *1.001 | C18: =C17*1.001 -> 2.507008 | E18: =E17*1.001 -> 2.507008
B19: L14: -0.5 | C19: =C18-0.5 -> 2.007008 | E19: =E18-0.5 -> 2.007008
B20: L15: MOD(,100) | C20: =MOD(ABS(C19),100) -> 2.007008 | E20: =MOD(ABS(E19),100) -> 2.007008
B21: L16: +1 | C21: =C20+1 -> 3.007008 | E21: =E20+1 -> 3.007008
B22: L17: *1.001 | C22: =C21*1.001 -> 3.010015 | E22: =E21*1.001 -> 3.010015
B23: L18: -0.5 | C23: =C22-0.5 -> 2.510015 | E23: =E22-0.5 -> 2.510015
B24: L19: MOD(,100) | C24: =MOD(ABS(C23),100) -> 2.510015 | E24: =MOD(ABS(E23),100) -> 2.510015
B25: L20: +1 | C25: =C24+1 -> 3.510015 | E25: =E24+1 -> 3.510015
B26: L21: *1.001 | C26: =C25*1.001 -> 3.513525 | E26: =E25*1.001 -> 3.513525
B27: L22: -0.5 | C27: =C26-0.5 -> 3.013525 | E27: =E26-0.5 -> 3.013525
B28: L23: MOD(,100) | C28: =MOD(ABS(C27),100) -> 3.013525 | E28: =MOD(ABS(E27),100) -> 3.013525
B29: L24: +1 | C29: =C28+1 -> 4.013525 | E29: =E28+1 -> 4.013525
B30: L25: *1.001 | C30: =C29*1.001 -> 4.0175386 | E30: =E29*1.001 -> 4.0175386
B31: L26: -0.5 | C31: =C30-0.5 -> 3.5175386 | E31: =E30-0.5 -> 3.5175386
B32: L27: MOD(,100) | C32: =MOD(ABS(C31),100) -> 3.5175386 | E32: =MOD(ABS(E31),100) -> 3.5175386
B33: L28: +1 | C33: =C32+1 -> 4.5175386 | E33: =E32+1 -> 4.5175386
B34: L29: *1.001 | C34: =C33*1.001 -> 4.5220561 | E34: =E33*1.001 -> 4.5220561
B35: L30: -0.5 | C35: =C34-0.5 -> 4.0220561 | E35: =E34-0.5 -> 4.0220561
B36: L31: MOD(,100) | C36: =MOD(ABS(C35),100) -> 4.0220561 | E36: =MOD(ABS(E35),100) -> 4.0220561
B37: L32: +1 | C37: =C36+1 -> 5.0220561 | E37: =E36+1 -> 5.0220561
B38: L33: *1.001 | C38: =C37*1.001 -> 5.0270781 | E38: =E37*1.001 -> 5.0270781
B39: L34: -0.5 | C39: =C38-0.5 -> 4.5270781 | E39: =E38-0.5 -> 4.5270781
B40: L35: MOD(,100) | C40: =MOD(ABS(C39),100) -> 4.5270781 | E40: =MOD(ABS(E39),100) -> 4.5270781
B41: L36: +1 | C41: =C40+1 -> 5.5270781 | E41: =E40+1 -> 5.5270781
B42: L37: *1.001 | C42: =C41*1.001 -> 5.5326052 | E42: =E41*1.001 -> 5.5326052
...

Sheet XSheet Chain A
B2: CROSS-SHEET DEEP CHAIN — SHEET A (ODD LEVELS)
B4: Section 1: 1,000-Level Cross-Sheet Chain (alternating A↔B) | E4: Section 2: 10,000-Level Cross-Sheet Chain
B5: L1 | C5: ='XSheet Chain B'!C5*1.001 -> 1.001 | E5: ='XSheet Chain B'!E5*1.001 -> 1.001
B6: L3 | C6: =MOD(ABS('XSheet Chain B'!C6),100) -> 0.501 | E6: =MOD(ABS('XSheet Chain B'!E6),100) -> 0.501
B7: L5 | C7: ='XSheet Chain B'!C7*1.001 -> 1.502501 | E7: ='XSheet Chain B'!E7*1.001 -> 1.502501
B8: L7 | C8: =MOD(ABS('XSheet Chain B'!C8),100) -> 1.002501 | E8: =MOD(ABS('XSheet Chain B'!E8),100) -> 1.002501
B9: L9 | C9: ='XSheet Chain B'!C9*1.001 -> 2.0045035 | E9: ='XSheet Chain B'!E9*1.001 -> 2.0045035
B10: L11 | C10: =MOD(ABS('XSheet Chain B'!C10),100) -> 1.5045035 | E10: =MOD(ABS('XSheet Chain B'!E10),100) -> 1.5045035
B11: L13 | C11: ='XSheet Chain B'!C11*1.001 -> 2.507008 | E11: ='XSheet Chain B'!E11*1.001 -> 2.507008
B12: L15 | C12: =MOD(ABS('XSheet Chain B'!C12),100) -> 2.007008 | E12: =MOD(ABS('XSheet Chain B'!E12),100) -> 2.007008
B13: L17 | C13: ='XSheet Chain B'!C13*1.001 -> 3.010015 | E13: ='XSheet Chain B'!E13*1.001 -> 3.010015
B14: L19 | C14: =MOD(ABS('XSheet Chain B'!C14),100) -> 2.510015 | E14: =MOD(ABS('XSheet Chain B'!E14),100) -> 2.510015
B15: L21 | C15: ='XSheet Chain B'!C15*1.001 -> 3.513525 | E15: ='XSheet Chain B'!E15*1.001 -> 3.513525
B16: L23 | C16: =MOD(ABS('XSheet Chain B'!C16),100) -> 3.013525 | E16: =MOD(ABS('XSheet Chain B'!E16),100) -> 3.013525
B17: L25 | C17: ='XSheet Chain B'!C17*1.001 -> 4.0175386 | E17: ='XSheet Chain B'!E17*1.001 -> 4.0175386
B18: L27 | C18: =MOD(ABS('XSheet Chain B'!C18),100) -> 3.5175386 | E18: =MOD(ABS('XSheet Chain B'!E18),100) -> 3.5175386
B19: L29 | C19: ='XSheet Chain B'!C19*1.001 -> 4.5220561 | E19: ='XSheet Chain B'!E19*1.001 -> 4.5220561
B20: L31 | C20: =MOD(ABS('XSheet Chain B'!C20),100) -> 4.0220561 | E20: =MOD(ABS('XSheet Chain B'!E20),100) -> 4.0220561
B21: L33 | C21: ='XSheet Chain B'!C21*1.001 -> 5.0270781 | E21: ='XSheet Chain B'!E21*1.001 -> 5.0270781
B22: L35 | C22: =MOD(ABS('XSheet Chain B'!C22),100) -> 4.5270781 | E22: =MOD(ABS('XSheet Chain B'!E22),100) -> 4.5270781
B23: L37 | C23: ='XSheet Chain B'!C23*1.001 -> 5.5326052 | E23: ='XSheet Chain B'!E23*1.001 -> 5.5326052
B24: L39 | C24: =MOD(ABS('XSheet Chain B'!C24),100) -> 5.0326052 | E24: =MOD(ABS('XSheet Chain B'!E24),100) -> 5.0326052
B25: L41 | C25: ='XSheet Chain B'!C25*1.001 -> 6.0386378 | E25: ='XSheet Chain B'!E25*1.001 -> 6.0386378
B26: L43 | C26: =MOD(ABS('XSheet Chain B'!C26),100) -> 5.5386378 | E26: =MOD(ABS('XSheet Chain B'!E26),100) -> 5.5386378
B27: L45 | C27: ='XSheet Chain B'!C27*1.001 -> 6.5451765 | E27: ='XSheet Chain B'!E27*1.001 -> 6.5451765
B28: L47 | C28: =MOD(ABS('XSheet Chain B'!C28),100) -> 6.0451765 | E28: =MOD(ABS('XSheet Chain B'!E28),100) -> 6.0451765
B29: L49 | C29: ='XSheet Chain B'!C29*1.001 -> 7.0522216 | E29: ='XSheet Chain B'!E29*1.001 -> 7.0522216
B30: L51 | C30: =MOD(ABS('XSheet Chain B'!C30),100) -> 6.5522216 | E30: =MOD(ABS('XSheet Chain B'!E30),100) -> 6.5522216
B31: L53 | C31: ='XSheet Chain B'!C31*1.001 -> 7.5597739 | E31: ='XSheet Chain B'!E31*1.001 -> 7.5597739
B32: L55 | C32: =MOD(ABS('XSheet Chain B'!C32),100) -> 7.0597739 | E32: =MOD(ABS('XSheet Chain B'!E32),100) -> 7.0597739
B33: L57 | C33: ='XSheet Chain B'!C33*1.001 -> 8.0678336 | E33: ='XSheet Chain B'!E33*1.001 -> 8.0678336
B34: L59 | C34: =MOD(ABS('XSheet Chain B'!C34),100) -> 7.5678336 | E34: =MOD(ABS('XSheet Chain B'!E34),100) -> 7.5678336
B35: L61 | C35: ='XSheet Chain B'!C35*1.001 -> 8.5764015 | E35: ='XSheet Chain B'!E35*1.001 -> 8.5764015
B36: L63 | C36: =MOD(ABS('XSheet Chain B'!C36),100) -> 8.0764015 | E36: =MOD(ABS('XSheet Chain B'!E36),100) -> 8.0764015
B37: L65 | C37: ='XSheet Chain B'!C37*1.001 -> 9.0854779 | E37: ='XSheet Chain B'!E37*1.001 -> 9.0854779
B38: L67 | C38: =MOD(ABS('XSheet Chain B'!C38),100) -> 8.5854779 | E38: =MOD(ABS('XSheet Chain B'!E38),100) -> 8.5854779
B39: L69 | C39: ='XSheet Chain B'!C39*1.001 -> 9.5950634 | E39: ='XSheet Chain B'!E39*1.001 -> 9.5950634
B40: L71 | C40: =MOD(ABS('XSheet Chain B'!C40),100) -> 9.0950634 | E40: =MOD(ABS('XSheet Chain B'!E40),100) -> 9.0950634
B41: L73 | C41: ='XSheet Chain B'!C41*1.001 -> 10.105158 | E41: ='XSheet Chain B'!E41*1.001 -> 10.105158
B42: L75 | C42: =MOD(ABS('XSheet Chain B'!C42),100) -> 9.6051584 | E42: =MOD(ABS('XSheet Chain B'!E42),100) -> 9.6051584
...

Sheet XSheet Chain B
B2: CROSS-SHEET DEEP CHAIN — SHEET B (EVEN LEVELS)
B4: Section 1: 1,000-Level Cross-Sheet Chain (alternating A↔B) | E4: Section 2: 10,000-Level Cross-Sheet Chain
B5: L0: Seed (=1) | C5: 1 | E5: 1
B6: L2 | C6: ='XSheet Chain A'!C5-0.5 -> 0.501 | E6: ='XSheet Chain A'!E5-0.5 -> 0.501
B7: L4 | C7: ='XSheet Chain A'!C6+1 -> 1.501 | E7: ='XSheet Chain A'!E6+1 -> 1.501
B8: L6 | C8: ='XSheet Chain A'!C7-0.5 -> 1.002501 | E8: ='XSheet Chain A'!E7-0.5 -> 1.002501
B9: L8 | C9: ='XSheet Chain A'!C8+1 -> 2.002501 | E9: ='XSheet Chain A'!E8+1 -> 2.002501
B10: L10 | C10: ='XSheet Chain A'!C9-0.5 -> 1.5045035 | E10: ='XSheet Chain A'!E9-0.5 -> 1.5045035
B11: L12 | C11: ='XSheet Chain A'!C10+1 -> 2.5045035 | E11: ='XSheet Chain A'!E10+1 -> 2.5045035
B12: L14 | C12: ='XSheet Chain A'!C11-0.5 -> 2.007008 | E12: ='XSheet Chain A'!E11-0.5 -> 2.007008
B13: L16 | C13: ='XSheet Chain A'!C12+1 -> 3.007008 | E13: ='XSheet Chain A'!E12+1 -> 3.007008
B14: L18 | C14: ='XSheet Chain A'!C13-0.5 -> 2.510015 | E14: ='XSheet Chain A'!E13-0.5 -> 2.510015
B15: L20 | C15: ='XSheet Chain A'!C14+1 -> 3.510015 | E15: ='XSheet Chain A'!E14+1 -> 3.510015
B16: L22 | C16: ='XSheet Chain A'!C15-0.5 -> 3.013525 | E16: ='XSheet Chain A'!E15-0.5 -> 3.013525
B17: L24 | C17: ='XSheet Chain A'!C16+1 -> 4.013525 | E17: ='XSheet Chain A'!E16+1 -> 4.013525
B18: L26 | C18: ='XSheet Chain A'!C17-0.5 -> 3.5175386 | E18: ='XSheet Chain A'!E17-0.5 -> 3.5175386
B19: L28 | C19: ='XSheet Chain A'!C18+1 -> 4.5175386 | E19: ='XSheet Chain A'!E18+1 -> 4.5175386
B20: L30 | C20: ='XSheet Chain A'!C19-0.5 -> 4.0220561 | E20: ='XSheet Chain A'!E19-0.5 -> 4.0220561
B21: L32 | C21: ='XSheet Chain A'!C20+1 -> 5.0220561 | E21: ='XSheet Chain A'!E20+1 -> 5.0220561
B22: L34 | C22: ='XSheet Chain A'!C21-0.5 -> 4.5270781 | E22: ='XSheet Chain A'!E21-0.5 -> 4.5270781
B23: L36 | C23: ='XSheet Chain A'!C22+1 -> 5.5270781 | E23: ='XSheet Chain A'!E22+1 -> 5.5270781
B24: L38 | C24: ='XSheet Chain A'!C23-0.5 -> 5.0326052 | E24: ='XSheet Chain A'!E23-0.5 -> 5.0326052
B25: L40 | C25: ='XSheet Chain A'!C24+1 -> 6.0326052 | E25: ='XSheet Chain A'!E24+1 -> 6.0326052
B26: L42 | C26: ='XSheet Chain A'!C25-0.5 -> 5.5386378 | E26: ='XSheet Chain A'!E25-0.5 -> 5.5386378
B27: L44 | C27: ='XSheet Chain A'!C26+1 -> 6.5386378 | E27: ='XSheet Chain A'!E26+1 -> 6.5386378
B28: L46 | C28: ='XSheet Chain A'!C27-0.5 -> 6.0451765 | E28: ='XSheet Chain A'!E27-0.5 -> 6.0451765
B29: L48 | C29: ='XSheet Chain A'!C28+1 -> 7.0451765 | E29: ='XSheet Chain A'!E28+1 -> 7.0451765
B30: L50 | C30: ='XSheet Chain A'!C29-0.5 -> 6.5522216 | E30: ='XSheet Chain A'!E29-0.5 -> 6.5522216
B31: L52 | C31: ='XSheet Chain A'!C30+1 -> 7.5522216 | E31: ='XSheet Chain A'!E30+1 -> 7.5522216
B32: L54 | C32: ='XSheet Chain A'!C31-0.5 -> 7.0597739 | E32: ='XSheet Chain A'!E31-0.5 -> 7.0597739
B33: L56 | C33: ='XSheet Chain A'!C32+1 -> 8.0597739 | E33: ='XSheet Chain A'!E32+1 -> 8.0597739
B34: L58 | C34: ='XSheet Chain A'!C33-0.5 -> 7.5678336 | E34: ='XSheet Chain A'!E33-0.5 -> 7.5678336
B35: L60 | C35: ='XSheet Chain A'!C34+1 -> 8.5678336 | E35: ='XSheet Chain A'!E34+1 -> 8.5678336
B36: L62 | C36: ='XSheet Chain A'!C35-0.5 -> 8.0764015 | E36: ='XSheet Chain A'!E35-0.5 -> 8.0764015
B37: L64 | C37: ='XSheet Chain A'!C36+1 -> 9.0764015 | E37: ='XSheet Chain A'!E36+1 -> 9.0764015
B38: L66 | C38: ='XSheet Chain A'!C37-0.5 -> 8.5854779 | E38: ='XSheet Chain A'!E37-0.5 -> 8.5854779
B39: L68 | C39: ='XSheet Chain A'!C38+1 -> 9.5854779 | E39: ='XSheet Chain A'!E38+1 -> 9.5854779
B40: L70 | C40: ='XSheet Chain A'!C39-0.5 -> 9.0950634 | E40: ='XSheet Chain A'!E39-0.5 -> 9.0950634
B41: L72 | C41: ='XSheet Chain A'!C40+1 -> 10.095063 | E41: ='XSheet Chain A'!E40+1 -> 10.095063
B42: L74 | C42: ='XSheet Chain A'!C41-0.5 -> 9.6051584 | E42: ='XSheet Chain A'!E41-0.5 -> 9.6051584
...
