Workbook
Name NA: "NA "
Name NM: "NM "

Sheet Cover
D11: Company1438
B21: Person0091, CFA | D21: SUMMARY DATA
B22: Company1150 & Co. | D22: Company Name: | G22: Company1438
B23: US Pharmaceuticals | D23: Ticker: | G23: Ticker0018
B24: +1 212.902.0691 (New York) | D24: Date of last update: | G24: 10.14.2025
B25: person@example.com
D26: QUICK LINKS
B27: Person0293 | D27: Sales Model
B28: Company1150 & Co. | D28: Consolidated Valuation
B29: Medical Technology | D29: Pharma Valuation
B30: +1 212.357.4617 (San Francisco) | D30: Income Statement
B31: person@example.com | D31: Balance Sheet
D32: Cash Flows
B33: Person0813 Person0525
B34: Company1150 & Co. | D34: COLOR CODE
B35: US Pharmaceuticals | D35: Blue | G35: Hardcoded data
B36: +1 415.249.7412 (San Francisco) | D36: Green | G36: Links to other tabs
B37: person@example.com | D37: Black | G37: Formula within sheet
B39: Person0896
B40: Company1150 & Co.
B41: Medical Technology
B42: +1 917.343.8573 (New York)
B43: person@example.com
B45: Person0522
B46: Company1150 & Co.
B47: US Pharmaceuticals
B48: +1 212.357.9930 (New York)
B49: person@example.com

Sheet Sales Model
B1: Total Sales
B2: U.S. | D2: 13050.774 | E2: 3847 | F2: 4014.1368 | G2: 4098 | H2: 3867 | I2: 15826.137 | J2: 4324 | K2: 4545 | L2: 4463 | M2: 4371 | N2: 17703 | O2: 4712 | P2: 5059 | Q2: 4976 | R2: 5075 | S2: 19822 | T2: 5521 | U2: 5599 | V2: 5589 | W2: 5746 | X2: 22455 | Y2: 6011.6 | Z2: 6112 | AA2: 6414 | AB2: 6737 | AC2: 25274.6 | AD2: 6918 | AE2: 6668 | AF2: 6790 | AG2: 7394 | AH2: 27770 | AI2: 7258 | AJ2: 7065 | AK2: 6967 | AL2: 7087 | AM2: 28377 | AN2: 7371 | AO2: 7375 | AP2: 7488 | AQ2: 7541 | AR2: 29775 | AS2: 8247.0246 | AT2: 8041 | AU2: 7927 | AV2: 8231 | AW2: 32446.025 | AX2: 8477 | AY2: 8210 | AZ2: 7955 | BA2: 7667 | BB2: 32309 | BC2: 8338 | BD2: 7983 | BE2: 7519.362 | BF2: 8235.9974 | BG2: 32076.359 | BH2: 8052 | BI2: 7779.3813 | BJ2: 7496 | BK2: 7610 | BL2: 30937.381 | BM2: 7608 | BN2: 7447 | BO2: 6868 | BP2: 6985 | BQ2: 28908 | BR2: 7219 | BS2: 7360 | BT2: 7791 | BU2: 7460 | BV2: 29830 | BW2: 7941.574 | BX2: 8006.6783 | BY2: =BY23 | BZ2: 7681.9241 | CA2: 31641.673 | CF2: 32367.79 | CK2: 33202.864 | CP2: 33656.978
B3: International | D3: 10944.224 | E3: 2947 | F3: 3002.8443 | G3: 2796 | H3: 2899 | I3: 11644.844 | J3: 3116 | K3: 3125 | L3: 2975 | M3: 2927 | N3: 12143 | O3: 3143 | P3: 3120 | Q3: 3082 | R3: 3150 | S3: 12495 | T3: 3222 | U3: 3474 | V3: 3490 | W3: 3657 | X3: 13843 | Y3: 3808.9 | Z3: 4220 | AA3: 4041 | AB3: 4517 | AC3: 16586.9 | AD3: 4641 | AE3: 4816 | AF3: 4763 | AG3: 5358 | AH3: 19578 | AI3: 5574.2 | AJ3: 5697 | AK3: 5343 | AL3: 5523 | AM3: 22137.2 | AN3: 5621 | AO3: 5988 | AP3: 5799 | AQ3: 6141 | AR3: 23549 | AS3: 6790 | AT3: 7090 | AU3: 7043 | AV3: 7727.1566 | AW3: 28650.157 | AX3: 7717 | AY3: 8240 | AZ3: 7966 | BA3: 7515 | BB3: 31438 | BC3: 6688 | BD3: 7256 | BE3: 7559.0466 | BF3: 8309.0566 | BG3: 29812.103 | BH3: 7579 | BI3: 7550.6057 | BJ3: 7486 | BK3: 8034 | BL3: 30649.606 | BM3: 8565 | BN3: 9150 | BO3: 9137 | BP3: 9270 | BQ3: 36122 | BR3: 8920 | BS3: 9115 | BT3: 9261 | BU3: 10098 | BV3: 37394 | BW3: 9728.7194 | BX3: 9969.99 | BY3: =BY24 | BZ3: 10381.806 | CA3: 39809.48 | CF3: 40900.193 | CK3: 42170.682 | CP3: 43812.993
B4: Worldwide | D4: 23994.999 | E4: 6794 | F4: 7016.9811 | G4: 6894 | H4: 6766 | I4: 27470.981 | J4: 7440 | K4: 7670 | L4: 7438 | M4: 7298 | N4: 29846 | O4: 7855 | P4: 8179 | Q4: 8058 | R4: 8225 | S4: 32317 | T4: 8743 | U4: 9073 | V4: 9079 | W4: 9403 | X4: 36298 | Y4: 9820.5 | Z4: 10332 | AA4: 10455 | AB4: 11254 | AC4: 41861.5 | AD4: 11559 | AE4: 11484 | AF4: 11553 | AG4: 12752 | AH4: 47348 | AI4: 12832.2 | AJ4: 12762 | AK4: 12310 | AL4: 12610 | AM4: 50514.2 | AN4: 12992 | AO4: 13363 | AP4: 13287 | AQ4: 13682 | AR4: 53324 | AS4: 15037.025 | AT4: 15131 | AU4: 14970 | AV4: 15958.157 | AW4: 61096.181 | AX4: 16194 | AY4: 16450 | AZ4: 15921 | BA4: 15182 | BB4: 63747 | BC4: 15026 | BD4: 15239 | BE4: 15078.409 | BF4: 16545.054 | BG4: 61888.463 | BH4: 15631 | BI4: 15329.987 | BJ4: 14982 | BK4: 15644 | BL4: 61586.987 | BM4: 16173 | BN4: 16597 | BO4: 16005 | BP4: 16255 | BQ4: 65030 | BR4: 16139 | BS4: 16475 | BT4: 17052 | BU4: 17558 | BV4: 67224 | BW4: 17670.293 | BX4: 17976.668 | BY4: =BY25 | BZ4: 18063.73 | CA4: 71451.153 | CF4: 73267.983 | CK4: 75373.547 | CP4: 77469.971
BW5: =+BW2-BW23 | BX5: =+BX2-BX23 | BY5: =+BY2-BY23 | BZ5: =+BZ2-BZ23 | CA5: =+CA2-CA23 | CF5: =+CF2-CF23 | CK5: =+CK2-CK23 | CP5: =+CP2-CP23
B9: =Cover!D11 | DP9: =DP15/DK15-1 | DQ9: =DQ15/DL15-1 | DR9: =DR15/DM15-1 | DS9: =DS15/DN15-1
DP10: =DP16/DK16-1 | DQ10: =DQ16/DL16-1 | DR10: =DR16/DM16-1 | DS10: =DS16/DN16-1
B11: Sales Model | DP11: =DP17/DK17-1 | DQ11: =DQ17/DL17-1 | DR11: =DR17/DM17-1 | DS11: =DS17/DN17-1
B13: ($ in millions)
DJ14: Pharma Revenues ex-COVID
BW15: =+BW3-BW24 | BX15: =+BX3-BX24 | BY15: =+BY3-BY24 | BZ15: =+BZ3-BZ24 | CA15: =+CA3-CA24 | DJ15: US | DK15: =DK34-DK1651 | DL15: =DL34-DL1651 | DM15: =DM34-DM1651 | DN15: =DN34-DN1651 | DO15: =DO34-DO1651 | DP15: =DP34-DP1651 | DQ15: =DQ34-DQ1651 | DR15: =DR34-DR1651 | ... EC15: =EC34-EC1651 | EI15: =EI34-EI1651 | EJ15: =EJ34-EJ1651 | EK15: =EK34-EK1651 | EL15: =EL34-EL1651 | EM15: =EM34-EM1651 | EN15: =EN34-EN1651
BW16: =+BW4-BW25 | BX16: =+BX4-BX25 | BY16: =+BY4-BY25 | BZ16: =+BZ4-BZ25 | CA16: =+CA4-CA25 | DJ16: OUS | DK16: =DK35-DK1652 | DL16: =DL35-DL1652 | DM16: =DM35-DM1652 | DN16: =DN35-DN1652 | DO16: =DO35-DO1652 | DP16: =DP35-DP1652 | DQ16: =DQ35-DQ1652 | DR16: =DR35-DR1652 | ... EC16: =EC35-EC1652 | EI16: =EI35-EI1652 | EJ16: =EJ35-EJ1652 | EK16: =EK35-EK1652 | EL16: =EL35-EL1652 | EM16: =EM35-EM1652 | EN16: =EN35-EN1652
DJ17: Total | DK17: =DK36-DK1653 | DL17: =DL36-DL1653 | DM17: =DM36-DM1653 | DN17: =DN36-DN1653 | DO17: =DO36-DO1653 | DP17: =DP36-DP1653 | DQ17: =DQ36-DQ1653 | DR17: =DR36-DR1653 | ... EC17: =EC36-EC1653 | EI17: =EI36-EI1653 | EJ17: =EJ36-EJ1653 | EK17: =EK36-EK1653 | EL17: =EL36-EL1653 | EM17: =EM36-EM1653 | EN17: =EN36-EN1653
CL18: =1.05113636363636-1 | CM18: =1.11725571725572-1 | CN18: =1.10829921845925-1 | CO18: 4Q2016A | CT18: 4Q2017E Ticker0015
B19: $ millions | C19: Patents | D19: 1998 | E19: 1Q99 | F19: 2Q99 | G19: 3Q99 | H19: 4Q99 | I19: 1999 | J19: 1Q00 | K19: 2Q00 | L19: 3Q00 | M19: 4Q00 | N19: 2000 | O19: 1Q01 | P19: 2Q01 | Q19: 3Q01 | R19: 4Q01 | S19: 2001 | T19: 1Q02 | U19: 2Q02 | V19: 3Q02 | W19: 4Q02 | X19: 2002 | Y19: 1Q03 | Z19: 2Q03 | AA19: 3Q03 | AB19: 4Q03 | AC19: 2003 | AD19: 1Q04 | AE19: 2Q04 | AF19: 3Q04 | AG19: 4Q04 | AH19: 2004 | AI19: 1Q05 | AJ19: 2Q05 | AK19: 3Q05 | AL19: 4Q05 | AM19: 2005 | AN19: 1Q06 | AO19: 2Q06 | AP19: 3Q06 | AQ19: 4Q06 | AR19: 2006 | AS19: 1Q07 | AT19: 2Q07 | AU19: 3Q07 | AV19: 4Q07 | AW19: 2007 | AX19: 1Q08 | AY19: 2Q08 | AZ19: 3Q08 | BA19: 4Q08 | BB19: 2008 | BC19: 1Q09 | BD19: 2Q09 | BE19: 3Q09 | BF19: 4Q09 | BG19: 2009 | BH19: 1Q10 | BI19: 2Q10 | BJ19: 3Q10 | BK19: 4Q10 | BL19: 2010 | BM19: 1Q11 | BN19: 2Q11 | BO19: 3Q11 | BP19: 4Q11 | BQ19: 2011 | BR19: 1Q12 | BS19: 2Q12 | BT19: 3Q12 | BU19: 4Q12 | BV19: 2012 | BW19: 1Q13 | BX19: 2Q13 | BY19: 3Q13 | BZ19: 4Q13 | CA19: 2013 | CB19: 1Q14 | CC19: 2Q14 | CD19: 3Q14 | CE19: 4Q14 | CF19: 2014 | CG19: 1Q15 | CH19: 2Q15 | CI19: 3Q15 | CJ19: 4Q15 | CK19: 2015 | CL19: 1Q16 | CM19: 2Q16 | CN19: 3Q16 | CO19: 4Q16 | CP19: 2016 | CQ19: 1Q17 | CR19: 2Q17 | CS19: 3Q17 | CT19: 4Q17 | CU19: 2017 | CV19: 1Q18 | CW19: 2Q18 | CX19: 3Q18 | CY19: 4Q18 | CZ19: 2018 | DA19: 1Q19 | DB19: 2Q19 | DC19: 3Q19 | DD19: 4Q19 | DE19: 2019 | DF19: 1Q20 | DG19: 2Q20 | DH19: 3Q20 | DI19: 4Q20 | DJ19: 2020 | DK19: 1Q21 | DL19: 2Q21 | DM19: 3Q21 | DN19: 4Q21 | DO19: 2021 | DP19: 1Q22 | DQ19: 2Q22 | DR19: 3Q22 | DS19: 4Q22 | DT19: 2022 | DU19: 1Q23 | DV19: 2Q23 | DW19: 3Q23 | DX19: 4Q23 | DY19: 2023 | DZ19: 1Q24 | EA19: 2Q24 | EB19: 3Q24 | EC19: 4Q24 | ED19: 2024 | EE19: 1Q25 | EF19: 2Q25 | EG19: 3Q25 | EH19: 4Q25E | EI19: 2025E | EJ19: 2026E | EK19: 2027 | EL19: =EK19+1 | EM19: =EL19+1 | EN19: =EM19+1 | EO19: =EN19+1 | EP19: =EO19+1 | EQ19: =EP19+1 | ER19: =EQ19+1 | ES19: =ER19+1 | ... EW19: =EV19+1
B20: Worldwide FX Revenue Impact | BM20: =+BH24*BM21/BH25 | BN20: =+BI24*BN21/BI25 | BO20: =+BJ24*BO21/BJ25 | BP20: =+BK24*BP21/BK25 | BR20: =+BM24*BR21/BM25 | BS20: =+BN24*BS21/BN25 | BT20: =+BO24*BT21/BO25 | BU20: =+BP24*BU21/BP25 | BW20: =+BR24*BW21/BR25 | BX20: =+BS24*BX21/BS25 | BY20: =+BT24*BY21/BT25 | BZ20: =+BU24*BZ21/BU25 | CB20: =+BW24*CB21/BW25 | CC20: =+BX24*CC21/BX25 | CD20: =+BY24*CD21/BY25 | CE20: =+BZ24*CE21/BZ25 | CG20: =+CB24*CG21/CB25 | CH20: =+CC24*CH21/CC25 | CI20: =+CD24*CI21/CD25 | CJ20: =+CE24*CJ21/CE25 | CL20: =+CG24*CL21/CG25 | CM20: =+CH24*CM21/CH25 | CN20: =+CI24*CN21/CI25 | CO20: =+CJ24*CO21/CJ25 | CP20: =CP21*CK24/CK25 | CQ20: =+CL24*CQ21/CL25 | CR20: =+CM24*CR21/CM25 | CS20: =+CN24*CS21/CN25 | CT20: =+CO24*CT21/CO25 | CU20: =CU21*CP24/CP25 | CV20: =+CQ24*CV21/CQ25 | CW20: =+CR24*CW21/CR25 | CX20: =+CS24*CX21/CS25 | CY20: =+CT24*CY21/CT25 | CZ20: =CZ21*CU24/CU25 | DA20: =+CV24*DA21/CV25 | DB20: =+CW24*DB21/CW25 | DC20: =+CX24*DC21/CX25 | DD20: =+CY24*DD21/CY25 | DE20: =DE21*CZ24/CZ25 | DF20: =+DA24*DF21/DA25 | DG20: =+DB24*DG21/DB25 | DH20: =+DC24*DH21/DC25 | DI20: =+DD24*DI21/DD25 | DJ20: =DJ21*DE24/DE25 | DK20: =+DF24*DK21/DF25 | DL20: =+DG24*DL21/DG25 | DM20: =+DH24*DM21/DH25 | DN20: =+DI24*DN21/DI25 | DO20: =DO21*DJ24/DJ25 | DP20: =+DK24*DP21/DK25 | DQ20: =+DL24*DQ21/DL25 | DR20: =+DM24*DR21/DM25 | DS20: =+DN24*DS21/DN25 | DT20: =DT21*DO24/DO25 | DU20: =+DP24*DU21/DP25 | DV20: =+DQ24*DV21/DQ25 | DW20: 0.004 | DX20: 0.001 | DZ20: =+DU24*DZ21/DU25 | EA20: =+DV24*EA21/DV25 | EB20: =+DW24*EB21/DW25 | EC20: =+DX24*EC21/DX25 | ED20: =ED21*DY24/DY25 | EE20: =+DZ24*EE21/DZ25 | EF20: =+EA24*EF21/EA25 | EG20: =+EB24*EG21/EB25
B21: FX impact | AI21: 0.054 | AJ21: 0.049 | AK21: 0.019 | AL21: -0.053000204 | AM21: =SUMPRODUCT(AI21:AL21,AD24:AG24/AH24) | AN21: -0.053 | AO21: -0.001 | AP21: 0.028 | AQ21: 0.054873837 | AR21: =SUMPRODUCT(AN21:AQ21,AI24:AL24)/AM24 | AS21: 0.054 | AT21: 0.054 | AU21: 0.068 | AV21: 0.10005372 | AW21: =SUMPRODUCT(AS21:AV21,AN24:AQ24)/AR24 | AX21: 0.113 | AY21: 0.119 | AZ21: 0.066 | BA21: -0.081 | BB21: =SUMPRODUCT(AX21:BA21,AS24:AV24)/AW24 | BC21: -0.126 | BD21: -0.119 | BE21: -0.049 | BF21: 0.092 | BG21: =SUMPRODUCT(BC21:BF21,AX24:BA24)/BB24 | BH21: 0.089 | BI21: 0.005 | BJ21: =-(0.8%*BE25)/BJ24 | BK21: =(-0.4%*BF25)/BK24 | BL21: =SUMPRODUCT(BH21:BK21,BC24:BF24)/BG24 | BM21: =(1.7%*BH25)/BH24 | BN21: =(5.7%*BI25)/BI24 | BO21: =(4.2%*BJ25)/BJ24 | BP21: =(-0.1%*BK25)/BK24 | BQ21: =SUMPRODUCT(BM21:BP21,BH24:BK24)/BL24 | BR21: =(-1.2%*BM25)/BM24 | BS21: =(-4.2%*BN25)/BN24 | BT21: =(-4.3%*BO25)/BO24 | BU21: =(-1.3%*BP25)/BP24 | BV21: =SUMPRODUCT(BR21:BU21,BM24:BP24)/BQ24 | BW21: =(-1.3%*BR25)/BR24 | BX21: =(-1.5%*BS25)/BS24 | BY21: =(-1.6%*BT25)/BT24 | BZ21: =(-1.8%*BU25)/BU24 | CA21: =SUMPRODUCT(BW21:BZ21,BR24:BU24)/BV24 | CB21: =(-1.8%*BW25)/BW24 | CC21: =(-0.3%*BX25)/BX24 | CD21: =(-0.7%*BY25)/BY24 | CE21: =(-4.5%*BZ25)/BZ24 | CF21: =SUMPRODUCT(CB21:CE21,BW24:BZ24)/CA24 | CG21: =(-7.2%*CB25)/CB24 | CH21: =(-7.9%*CC25)/CC24 | CI21: =(-8.2%*CD25)/CD24 | CJ21: =(-6.8%*CE25)/CE24 | CK21: =SUMPRODUCT(CG21:CJ21,CB24:CE24)/CF24 | CL21: -0.033 | CM21: -0.006 | CN21: -0.005 | CO21: -0.006 | CP21: =SUMPRODUCT(CL21:CO21,CG24:CJ24)/CK24 | CQ21: -0.009 | CR21: -0.021 | CS21: 0.016 | CT21: 0.045 | CU21: =SUMPRODUCT(CQ21:CT21,CL24:CO24)/CP24 | CV21: 0.09 | CW21: 0.04 | CX21: -0.04 | CY21: -0.047 | CZ21: =SUMPRODUCT(CV21:CY21,CQ24:CT24)/CU24 | DA21: -0.077 | DB21: -0.058 | DC21: -0.028 | DD21: -0.046 | DE21: =SUMPRODUCT(DA21:DD21,CV24:CY24)/CZ24 | DF21: -0.03 | DG21: -0.037 | DH21: -0.02 | DI21: -0.02 | DJ21: =SUMPRODUCT(DF21:DI21,DA24:DD24)/DE24 | DK21: -0.05 | DL21: -0.085457214 | DM21: 0.017 | DN21: -0.027 | DO21: =SUMPRODUCT(DK21:DN21,DF24:DI24)/DJ24 | DP21: -0.054 | DQ21: -0.101 | DR21: -0.126 | DS21: -0.104 | DT21: =SUMPRODUCT(DP21:DS21,DK24:DN24)/DO24 | DU21: -0.065 | DV21: -0.025 | DW21: 0.009 | DX21: 0.002 | EB21: -0.035 | ED21: =+ED1370 | EH21: 0.035 | EJ21: 0.015 | EK21: 0 | EL21: 0 | EM21: 0 | EN21: 0
B22: TOTAL SALES | DW22: Excludes Consumer Health -->
A23: Total Ticker0018 Sales - US | B23: US | D23: =+D1487+D885+D1348 | E23: =+E1487+E885+E1348 | F23: =+F1487+F885+F1348 | G23: =+G1487+G885+G1348 | H23: =+H1487+H885+H1348 | I23: =+I1487+I885+I1348 | J23: =+J1487+J885+J1348 | K23: =+K1487+K885+K1348 | ... DV23: =+DV1487+DV885+DV1348 | DW23: =+DW885+DW1348 | DX23: =+DX885+DX1348 | DY23: =+DY885+DY1348 | DZ23: =+DZ885+DZ1348 | EA23: =+EA885+EA1348 | EB23: =+EB885+EB1348 | EC23: =+EC885+EC1348 | ED23: =+ED885+ED1348 | ... EN23: =+EN885+EN1348
A24: =+A25&" - OUS" | B24: International | D24: =+D1488+D886+D1349 | E24: =+E1488+E886+E1349 | F24: =+F1488+F886+F1349 | G24: =+G1488+G886+G1349 | H24: =+H1488+H886+H1349 | I24: =+I1488+I886+I1349 | J24: =+J1488+J886+J1349 | K24: =+K1488+K886+K1349 | ... DV24: =+DV1488+DV886+DV1349 | DW24: =+DW886+DW1349 | DX24: =+DX886+DX1349 | DY24: =+DY886+DY1349 | DZ24: =+DZ886+DZ1349 | EA24: =+EA886+EA1349 | EB24: =+EB886+EB1349 | EC24: =+EC886+EC1349 | ED24: =+ED886+ED1349 | ... EN24: =+EN886+EN1349
A25: Total Ticker0018 Sales | B25: Worldwide | D25: =+D1489+D887+D1350 | E25: =+E1489+E887+E1350 | F25: =+F1489+F887+F1350 | G25: =+G1489+G887+G1350 | H25: =+H1489+H887+H1350 | I25: =+I1489+I887+I1350 | J25: =+J1489+J887+J1350 | K25: =+K1489+K887+K1350 | ... DV25: =+DV1489+DV887+DV1350 | DW25: =+DW887+DW1350 | DX25: =+DX887+DX1350 | DY25: =+DY887+DY1350 | DZ25: =+DZ887+DZ1350 | EA25: =+EA887+EA1350 | EB25: =+EB887+EB1350 | EC25: =+EC887+EC1350 | ED25: =+ED887+ED1350 | ... EN25: =+EN887+EN1350
B27: Total sales % growth
B28: US | I28: =IF(D23="NM","NM",IF(I23="NM","NM",IF(D23<=0,"NM",IF(I23=0,"NM",IF(ABS(I23/D23-1)>2.5,"NM",IF((ABS(I23-D23)=ABS(ABS(I23)-ABS(D23))),(I23/D23-1),"NM")))))) | J28: =IF(E23="NM","NM",IF(J23="NM","NM",IF(E23<=0,"NM",IF(J23=0,"NM",IF(ABS(J23/E23-1)>2.5,"NM",IF((ABS(J23-E23)=ABS(ABS(J23)-ABS(E23))),(J23/E23-1),"NM")))))) | K28: =IF(F23="NM","NM",IF(K23="NM","NM",IF(F23<=0,"NM",IF(K23=0,"NM",IF(ABS(K23/F23-1)>2.5,"NM",IF((ABS(K23-F23)=ABS(ABS(K23)-ABS(F23))),(K23/F23-1),"NM")))))) | L28: =IF(G23="NM","NM",IF(L23="NM","NM",IF(G23<=0,"NM",IF(L23=0,"NM",IF(ABS(L23/G23-1)>2.5,"NM",IF((ABS(L23-G23)=ABS(ABS(L23)-ABS(G23))),(L23/G23-1),"NM")))))) | M28: =IF(H23="NM","NM",IF(M23="NM","NM",IF(H23<=0,"NM",IF(M23=0,"NM",IF(ABS(M23/H23-1)>2.5,"NM",IF((ABS(M23-H23)=ABS(ABS(M23)-ABS(H23))),(M23/H23-1),"NM")))))) | N28: =IF(I23="NM","NM",IF(N23="NM","NM",IF(I23<=0,"NM",IF(N23=0,"NM",IF(ABS(N23/I23-1)>2.5,"NM",IF((ABS(N23-I23)=ABS(ABS(N23)-ABS(I23))),(N23/I23-1),"NM")))))) | O28: =IF(J23="NM","NM",IF(O23="NM","NM",IF(J23<=0,"NM",IF(O23=0,"NM",IF(ABS(O23/J23-1)>2.5,"NM",IF((ABS(O23-J23)=ABS(ABS(O23)-ABS(J23))),(O23/J23-1),"NM")))))) | P28: =IF(K23="NM","NM",IF(P23="NM","NM",IF(K23<=0,"NM",IF(P23=0,"NM",IF(ABS(P23/K23-1)>2.5,"NM",IF((ABS(P23-K23)=ABS(ABS(P23)-ABS(K23))),(P23/K23-1),"NM")))))) | ... CF28: =IF(CA23="NM","NM",IF(CF23="NM","NM",IF(CA23<=0,"NM",IF(CF23=0,"NM",IF(ABS(CF23/CA23-1)>2.5,"NM",IF((ABS(CF23-CA23)=ABS(ABS(CF23)-ABS(CA23))),(CF23/CA23-1),"NM")))))) | CG28: =IF(CB23=0, "NA", CG23/CB23-1) | CH28: =IF(CC23=0, "NA", CH23/CC23-1) | CI28: =IF(CD23=0, "NA", CI23/CD23-1) | CJ28: =IF(CE23=0, "NA", CJ23/CE23-1) | CK28: =IF(CF23=0, "NA", CK23/CF23-1) | CL28: =IF(CG23=0, "NA", CL23/CG23-1) | CM28: =IF(CH23=0, "NA", CM23/CH23-1) | CN28: =IF(CI23=0, "NA", CN23/CI23-1) | ... EI28: =IF(ED23=0, "NA", EI23/ED23-1) | EJ28: =IF(EI23=0, "NA", EJ23/EI23-1) | EK28: =IF(EJ23=0, "NA", EK23/EJ23-1) | EL28: =IF(EK23=0, "NA", EL23/EK23-1) | EM28: =IF(EL23=0, "NA", EM23/EL23-1) | EN28: =IF(EM23=0, "NA", EN23/EM23-1)
B29: Int'l | I29: =IF(D24="NM","NM",IF(I24="NM","NM",IF(D24<=0,"NM",IF(I24=0,"NM",IF(ABS(I24/D24-1)>2.5,"NM",IF((ABS(I24-D24)=ABS(ABS(I24)-ABS(D24))),(I24/D24-1),"NM")))))) | J29: =IF(E24="NM","NM",IF(J24="NM","NM",IF(E24<=0,"NM",IF(J24=0,"NM",IF(ABS(J24/E24-1)>2.5,"NM",IF((ABS(J24-E24)=ABS(ABS(J24)-ABS(E24))),(J24/E24-1),"NM")))))) | K29: =IF(F24="NM","NM",IF(K24="NM","NM",IF(F24<=0,"NM",IF(K24=0,"NM",IF(ABS(K24/F24-1)>2.5,"NM",IF((ABS(K24-F24)=ABS(ABS(K24)-ABS(F24))),(K24/F24-1),"NM")))))) | L29: =IF(G24="NM","NM",IF(L24="NM","NM",IF(G24<=0,"NM",IF(L24=0,"NM",IF(ABS(L24/G24-1)>2.5,"NM",IF((ABS(L24-G24)=ABS(ABS(L24)-ABS(G24))),(L24/G24-1),"NM")))))) | M29: =IF(H24="NM","NM",IF(M24="NM","NM",IF(H24<=0,"NM",IF(M24=0,"NM",IF(ABS(M24/H24-1)>2.5,"NM",IF((ABS(M24-H24)=ABS(ABS(M24)-ABS(H24))),(M24/H24-1),"NM")))))) | N29: =IF(I24="NM","NM",IF(N24="NM","NM",IF(I24<=0,"NM",IF(N24=0,"NM",IF(ABS(N24/I24-1)>2.5,"NM",IF((ABS(N24-I24)=ABS(ABS(N24)-ABS(I24))),(N24/I24-1),"NM")))))) | O29: =IF(J24="NM","NM",IF(O24="NM","NM",IF(J24<=0,"NM",IF(O24=0,"NM",IF(ABS(O24/J24-1)>2.5,"NM",IF((ABS(O24-J24)=ABS(ABS(O24)-ABS(J24))),(O24/J24-1),"NM")))))) | P29: =IF(K24="NM","NM",IF(P24="NM","NM",IF(K24<=0,"NM",IF(P24=0,"NM",IF(ABS(P24/K24-1)>2.5,"NM",IF((ABS(P24-K24)=ABS(ABS(P24)-ABS(K24))),(P24/K24-1),"NM")))))) | ... CF29: =IF(CA24="NM","NM",IF(CF24="NM","NM",IF(CA24<=0,"NM",IF(CF24=0,"NM",IF(ABS(CF24/CA24-1)>2.5,"NM",IF((ABS(CF24-CA24)=ABS(ABS(CF24)-ABS(CA24))),(CF24/CA24-1),"NM")))))) | CG29: =IF(CB24=0, "NA", CG24/CB24-1) | CH29: =IF(CC24=0, "NA", CH24/CC24-1) | CI29: =IF(CD24=0, "NA", CI24/CD24-1) | CJ29: =IF(CE24=0, "NA", CJ24/CE24-1) | CK29: =IF(CF24=0, "NA", CK24/CF24-1) | CL29: =IF(CG24=0, "NA", CL24/CG24-1) | CM29: =IF(CH24=0, "NA", CM24/CH24-1) | CN29: =IF(CI24=0, "NA", CN24/CI24-1) | ... EI29: =IF(ED24=0, "NA", EI24/ED24-1) | EJ29: =IF(EI24=0, "NA", EJ24/EI24-1) | EK29: =IF(EJ24=0, "NA", EK24/EJ24-1) | EL29: =IF(EK24=0, "NA", EL24/EK24-1) | EM29: =IF(EL24=0, "NA", EM24/EL24-1) | EN29: =IF(EM24=0, "NA", EN24/EM24-1)
B30: Int'l (ex-currency) | AI30: =IF(ISNUMBER(AI29),(1+AI29)/(1+AI$21)-1,"NM") | AJ30: =IF(ISNUMBER(AJ29),(1+AJ29)/(1+AJ$21)-1,"NM") | AK30: =IF(ISNUMBER(AK29),(1+AK29)/(1+AK$21)-1,"NM") | AL30: =IF(ISNUMBER(AL29),(1+AL29)/(1+AL$21)-1,"NM") | AM30: =IF(ISNUMBER(AM29),(1+AM29)/(1+AM$21)-1,"NM") | AN30: =IF(ISNUMBER(AN29),(1+AN29)/(1+AN$21)-1,"NM") | AO30: =IF(ISNUMBER(AO29),(1+AO29)/(1+AO$21)-1,"NM") | AP30: =IF(ISNUMBER(AP29),(1+AP29)/(1+AP$21)-1,"NM") | ... CF30: =IF(ISNUMBER(CF29),(1+CF29)/(1+CF$21)-1,"NM") | CG30: =CG29-CG$21 | CH30: =CH29-CH$21 | CI30: =CI29-CI$21 | CJ30: =CJ29-CJ$21 | CK30: =CK29-CK$21 | CL30: =CL29-CL$21 | CM30: =CM29-CM$21 | CN30: =CN29-CN$21 | ... EN30: =EN29-EN$21
B31: Worldwide | I31: =IF(D25="NM","NM",IF(I25="NM","NM",IF(D25<=0,"NM",IF(I25=0,"NM",IF(ABS(I25/D25-1)>2.5,"NM",IF((ABS(I25-D25)=ABS(ABS(I25)-ABS(D25))),(I25/D25-1),"NM")))))) | J31: =IF(E25="NM","NM",IF(J25="NM","NM",IF(E25<=0,"NM",IF(J25=0,"NM",IF(ABS(J25/E25-1)>2.5,"NM",IF((ABS(J25-E25)=ABS(ABS(J25)-ABS(E25))),(J25/E25-1),"NM")))))) | K31: =IF(F25="NM","NM",IF(K25="NM","NM",IF(F25<=0,"NM",IF(K25=0,"NM",IF(ABS(K25/F25-1)>2.5,"NM",IF((ABS(K25-F25)=ABS(ABS(K25)-ABS(F25))),(K25/F25-1),"NM")))))) | L31: =IF(G25="NM","NM",IF(L25="NM","NM",IF(G25<=0,"NM",IF(L25=0,"NM",IF(ABS(L25/G25-1)>2.5,"NM",IF((ABS(L25-G25)=ABS(ABS(L25)-ABS(G25))),(L25/G25-1),"NM")))))) | M31: =IF(H25="NM","NM",IF(M25="NM","NM",IF(H25<=0,"NM",IF(M25=0,"NM",IF(ABS(M25/H25-1)>2.5,"NM",IF((ABS(M25-H25)=ABS(ABS(M25)-ABS(H25))),(M25/H25-1),"NM")))))) | N31: =IF(I25="NM","NM",IF(N25="NM","NM",IF(I25<=0,"NM",IF(N25=0,"NM",IF(ABS(N25/I25-1)>2.5,"NM",IF((ABS(N25-I25)=ABS(ABS(N25)-ABS(I25))),(N25/I25-1),"NM")))))) | O31: =IF(J25="NM","NM",IF(O25="NM","NM",IF(J25<=0,"NM",IF(O25=0,"NM",IF(ABS(O25/J25-1)>2.5,"NM",IF((ABS(O25-J25)=ABS(ABS(O25)-ABS(J25))),(O25/J25-1),"NM")))))) | P31: =IF(K25="NM","NM",IF(P25="NM","NM",IF(K25<=0,"NM",IF(P25=0,"NM",IF(ABS(P25/K25-1)>2.5,"NM",IF((ABS(P25-K25)=ABS(ABS(P25)-ABS(K25))),(P25/K25-1),"NM")))))) | ... BP31: =IF(BK25="NM","NM",IF(BP25="NM","NM",IF(BK25<=0,"NM",IF(BP25=0,"NM",IF(ABS(BP25/BK25-1)>2.5,"NM",IF((ABS(BP25-BK25)=ABS(ABS(BP25)-ABS(BK25))),(BP25/BK25-1),"NM")))))) | BQ31: =IF(ISNUMBER(BQ30),(1+BQ30)/(1+BQ$21)-1,"NM") | BR31: =IF(BM25="NM","NM",IF(BR25="NM","NM",IF(BM25<=0,"NM",IF(BR25=0,"NM",IF(ABS(BR25/BM25-1)>2.5,"NM",IF((ABS(BR25-BM25)=ABS(ABS(BR25)-ABS(BM25))),(BR25/BM25-1),"NM")))))) | BS31: =IF(BN25="NM","NM",IF(BS25="NM","NM",IF(BN25<=0,"NM",IF(BS25=0,"NM",IF(ABS(BS25/BN25-1)>2.5,"NM",IF((ABS(BS25-BN25)=ABS(ABS(BS25)-ABS(BN25))),(BS25/BN25-1),"NM")))))) | BT31: =IF(BO25="NM","NM",IF(BT25="NM","NM",IF(BO25<=0,"NM",IF(BT25=0,"NM",IF(ABS(BT25/BO25-1)>2.5,"NM",IF((ABS(BT25-BO25)=ABS(ABS(BT25)-ABS(BO25))),(BT25/BO25-1),"NM")))))) | BU31: =IF(BP25="NM","NM",IF(BU25="NM","NM",IF(BP25<=0,"NM",IF(BU25=0,"NM",IF(ABS(BU25/BP25-1)>2.5,"NM",IF((ABS(BU25-BP25)=ABS(ABS(BU25)-ABS(BP25))),(BU25/BP25-1),"NM")))))) | BV31: =IF(BQ25="NM","NM",IF(BV25="NM","NM",IF(BQ25<=0,"NM",IF(BV25=0,"NM",IF(ABS(BV25/BQ25-1)>2.5,"NM",IF((ABS(BV25-BQ25)=ABS(ABS(BV25)-ABS(BQ25))),(BV25/BQ25-1),"NM")))))) | BW31: =IF(BR25="NM","NM",IF(BW25="NM","NM",IF(BR25<=0,"NM",IF(BW25=0,"NM",IF(ABS(BW25/BR25-1)>2.5,"NM",IF((ABS(BW25-BR25)=ABS(ABS(BW25)-ABS(BR25))),(BW25/BR25-1),"NM")))))) | BX31: =IF(BS25="NM","NM",IF(BX25="NM","NM",IF(BS25<=0,"NM",IF(BX25=0,"NM",IF(ABS(BX25/BS25-1)>2.5,"NM",IF((ABS(BX25-BS25)=ABS(ABS(BX25)-ABS(BS25))),(BX25/BS25-1),"NM")))))) | BY31: =IF(BT25="NM","NM",IF(BY25="NM","NM",IF(BT25<=0,"NM",IF(BY25=0,"NM",IF(ABS(BY25/BT25-1)>2.5,"NM",IF((ABS(BY25-BT25)=ABS(ABS(BY25)-ABS(BT25))),(BY25/BT25-1),"NM")))))) | ... CF31: =IF(CA25="NM","NM",IF(CF25="NM","NM",IF(CA25<=0,"NM",IF(CF25=0,"NM",IF(ABS(CF25/CA25-1)>2.5,"NM",IF((ABS(CF25-CA25)=ABS(ABS(CF25)-ABS(CA25))),(CF25/CA25-1),"NM")))))) | CG31: =IF(CB25=0, "NA", CG25/CB25-1) | CH31: =IF(CC25=0, "NA", CH25/CC25-1) | CI31: =IF(CD25=0, "NA", CI25/CD25-1) | CJ31: =IF(CE25=0, "NA", CJ25/CE25-1) | CK31: =IF(CF25=0, "NA", CK25/CF25-1) | CL31: =IF(CG25=0, "NA", CL25/CG25-1) | CM31: =IF(CH25=0, "NA", CM25/CH25-1) | CN31: =IF(CI25=0, "NA", CN25/CI25-1) | ... EI31: =IF(ED25=0, "NA", EI25/ED25-1) | EJ31: =IF(EI25=0, "NA", EJ25/EI25-1) | EK31: =IF(EJ25=0, "NA", EK25/EJ25-1) | EL31: =IF(EK25=0, "NA", EL25/EK25-1) | EM31: =IF(EL25=0, "NA", EM25/EL25-1) | EN31: =IF(EM25=0, "NA", EN25/EM25-1)
B33: Innovative Medicine
A34: Pharma - US | B34: US | D34: =+D885 | E34: =+E885 | F34: =+F885 | G34: =+G885 | H34: =+H885 | I34: =+I885 | J34: =+J885 | K34: =+K885 | ... CE34: =+CE885 | CF34: =SUM(CB34:CE34) | CG34: =+CG885 | CH34: =+CH885 | CI34: =+CI885 | CJ34: =+CJ885 | CK34: =SUM(CG34:CJ34) | CL34: =+CL885 | CM34: =+CM885 | CN34: =+CN885 | CO34: =+CO885 | CP34: =+CP885 | CQ34: =+CQ885 | CR34: =+CR885 | CS34: =+CS885 | ... ES34: =+ES885
A35: =+A36&" - OUS" | B35: International | D35: =+D886 | E35: =+E886 | F35: =+F886 | G35: =+G886 | H35: =+H886 | I35: =+I886 | J35: =+J886 | K35: =+K886 | ... CE35: =+CE886 | CF35: =SUM(CB35:CE35) | CG35: =+CG886 | CH35: =+CH886 | CI35: =+CI886 | CJ35: =+CJ886 | CK35: =SUM(CG35:CJ35) | CL35: =+CL886 | CM35: =+CM886 | CN35: =+CN886 | CO35: =+CO886 | CP35: =+CP886 | CQ35: =+CQ886 | CR35: =+CR886 | CS35: =+CS886 | ... ES35: =+ES886
A36: Pharma | B36: Worldwide | D36: =+D35+D34 | E36: =+E35+E34 | F36: =+F35+F34 | G36: =+G35+G34 | H36: =+H35+H34 | I36: =+I35+I34 | J36: =+J35+J34 | K36: =+K35+K34 | ... CE36: =+CE35+CE34 | CF36: =SUM(CB36:CE36) | CG36: =+CG35+CG34 | CH36: =+CH35+CH34 | CI36: =+CI35+CI34 | CJ36: =+CJ35+CJ34 | CK36: =SUM(CG36:CJ36) | CL36: =+CL35+CL34 | CM36: =+CM35+CM34 | CN36: =+CN35+CN34 | CO36: =+CO35+CO34 | CP36: =+CP35+CP34 | CQ36: =+CQ35+CQ34 | CR36: =+CR35+CR34 | CS36: =+CS35+CS34 | ... ES36: =+ES35+ES34
B38: Innovative Medicine sales % growth
B39: US | I39: =IF(D34="NM","NM",IF(I34="NM","NM",IF(D34<=0,"NM",IF(I34=0,"NM",IF(ABS(I34/D34-1)>2.5,"NM",IF((ABS(I34-D34)=ABS(ABS(I34)-ABS(D34))),(I34/D34-1),"NM")))))) | J39: =IF(E34="NM","NM",IF(J34="NM","NM",IF(E34<=0,"NM",IF(J34=0,"NM",IF(ABS(J34/E34-1)>2.5,"NM",IF((ABS(J34-E34)=ABS(ABS(J34)-ABS(E34))),(J34/E34-1),"NM")))))) | K39: =IF(F34="NM","NM",IF(K34="NM","NM",IF(F34<=0,"NM",IF(K34=0,"NM",IF(ABS(K34/F34-1)>2.5,"NM",IF((ABS(K34-F34)=ABS(ABS(K34)-ABS(F34))),(K34/F34-1),"NM")))))) | L39: =IF(G34="NM","NM",IF(L34="NM","NM",IF(G34<=0,"NM",IF(L34=0,"NM",IF(ABS(L34/G34-1)>2.5,"NM",IF((ABS(L34-G34)=ABS(ABS(L34)-ABS(G34))),(L34/G34-1),"NM")))))) | M39: =IF(H34="NM","NM",IF(M34="NM","NM",IF(H34<=0,"NM",IF(M34=0,"NM",IF(ABS(M34/H34-1)>2.5,"NM",IF((ABS(M34-H34)=ABS(ABS(M34)-ABS(H34))),(M34/H34-1),"NM")))))) | N39: =IF(I34="NM","NM",IF(N34="NM","NM",IF(I34<=0,"NM",IF(N34=0,"NM",IF(ABS(N34/I34-1)>2.5,"NM",IF((ABS(N34-I34)=ABS(ABS(N34)-ABS(I34))),(N34/I34-1),"NM")))))) | O39: =IF(J34="NM","NM",IF(O34="NM","NM",IF(J34<=0,"NM",IF(O34=0,"NM",IF(ABS(O34/J34-1)>2.5,"NM",IF((ABS(O34-J34)=ABS(ABS(O34)-ABS(J34))),(O34/J34-1),"NM")))))) | P39: =IF(K34="NM","NM",IF(P34="NM","NM",IF(K34<=0,"NM",IF(P34=0,"NM",IF(ABS(P34/K34-1)>2.5,"NM",IF((ABS(P34-K34)=ABS(ABS(P34)-ABS(K34))),(P34/K34-1),"NM")))))) | ... CE39: =IF(BZ34="NM","NM",IF(CE34="NM","NM",IF(BZ34<=0,"NM",IF(CE34=0,"NM",IF(ABS(CE34/BZ34-1)>2.5,"NM",IF((ABS(CE34-BZ34)=ABS(ABS(CE34)-ABS(BZ34))),(CE34/BZ34-1),"NM")))))) | CF39: =IF(CA34=0, "NA", CF34/CA34-1) | CG39: =IF(CB34=0, "NA", CG34/CB34-1) | CH39: =IF(CC34=0, "NA", CH34/CC34-1) | CI39: =IF(CD34=0, "NA", CI34/CD34-1) | CJ39: =IF(CE34=0, "NA", CJ34/CE34-1) | CK39: =IF(CF34=0, "NA", CK34/CF34-1) | CL39: =IF(CG34=0, "NA", CL34/CG34-1) | CM39: =IF(CH34=0, "NA", CM34/CH34-1) | ... EI39: =IF(ED34=0, "NA", EI34/ED34-1) | EJ39: =IF(EI34=0, "NA", EJ34/EI34-1) | EK39: =IF(EJ34=0, "NA", EK34/EJ34-1) | EL39: =IF(EK34=0, "NA", EL34/EK34-1) | EM39: =IF(EL34=0, "NA", EM34/EL34-1) | EN39: =IF(EM34=0, "NA", EN34/EM34-1) | EO39: =IF(EN34=0, "NA", EO34/EN34-1) | EP39: =IF(EO34=0, "NA", EP34/EO34-1) | EQ39: =IF(EP34=0, "NA", EQ34/EP34-1) | ... ES39: =IF(ER34=0, "NA", ES34/ER34-1)
B40: International | I40: =IF(D35="NM","NM",IF(I35="NM","NM",IF(D35<=0,"NM",IF(I35=0,"NM",IF(ABS(I35/D35-1)>2.5,"NM",IF((ABS(I35-D35)=ABS(ABS(I35)-ABS(D35))),(I35/D35-1),"NM")))))) | J40: =IF(E35="NM","NM",IF(J35="NM","NM",IF(E35<=0,"NM",IF(J35=0,"NM",IF(ABS(J35/E35-1)>2.5,"NM",IF((ABS(J35-E35)=ABS(ABS(J35)-ABS(E35))),(J35/E35-1),"NM")))))) | K40: =IF(F35="NM","NM",IF(K35="NM","NM",IF(F35<=0,"NM",IF(K35=0,"NM",IF(ABS(K35/F35-1)>2.5,"NM",IF((ABS(K35-F35)=ABS(ABS(K35)-ABS(F35))),(K35/F35-1),"NM")))))) | L40: =IF(G35="NM","NM",IF(L35="NM","NM",IF(G35<=0,"NM",IF(L35=0,"NM",IF(ABS(L35/G35-1)>2.5,"NM",IF((ABS(L35-G35)=ABS(ABS(L35)-ABS(G35))),(L35/G35-1),"NM")))))) | M40: =IF(H35="NM","NM",IF(M35="NM","NM",IF(H35<=0,"NM",IF(M35=0,"NM",IF(ABS(M35/H35-1)>2.5,"NM",IF((ABS(M35-H35)=ABS(ABS(M35)-ABS(H35))),(M35/H35-1),"NM")))))) | N40: =IF(I35="NM","NM",IF(N35="NM","NM",IF(I35<=0,"NM",IF(N35=0,"NM",IF(ABS(N35/I35-1)>2.5,"NM",IF((ABS(N35-I35)=ABS(ABS(N35)-ABS(I35))),(N35/I35-1),"NM")))))) | O40: =IF(J35="NM","NM",IF(O35="NM","NM",IF(J35<=0,"NM",IF(O35=0,"NM",IF(ABS(O35/J35-1)>2.5,"NM",IF((ABS(O35-J35)=ABS(ABS(O35)-ABS(J35))),(O35/J35-1),"NM")))))) | P40: =IF(K35="NM","NM",IF(P35="NM","NM",IF(K35<=0,"NM",IF(P35=0,"NM",IF(ABS(P35/K35-1)>2.5,"NM",IF((ABS(P35-K35)=ABS(ABS(P35)-ABS(K35))),(P35/K35-1),"NM")))))) | ... CE40: =IF(BZ35="NM","NM",IF(CE35="NM","NM",IF(BZ35<=0,"NM",IF(CE35=0,"NM",IF(ABS(CE35/BZ35-1)>2.5,"NM",IF((ABS(CE35-BZ35)=ABS(ABS(CE35)-ABS(BZ35))),(CE35/BZ35-1),"NM")))))) | CF40: =IF(CA35=0, "NA", CF35/CA35-1) | CG40: =IF(CB35=0, "NA", CG35/CB35-1) | CH40: =IF(CC35=0, "NA", CH35/CC35-1) | CI40: =IF(CD35=0, "NA", CI35/CD35-1) | CJ40: =IF(CE35=0, "NA", CJ35/CE35-1) | CK40: =IF(CF35=0, "NA", CK35/CF35-1) | CL40: =IF(CG35=0, "NA", CL35/CG35-1) | CM40: =IF(CH35=0, "NA", CM35/CH35-1) | ... EI40: =IF(ED35=0, "NA", EI35/ED35-1) | EJ40: =IF(EI35=0, "NA", EJ35/EI35-1) | EK40: =IF(EJ35=0, "NA", EK35/EJ35-1) | EL40: =IF(EK35=0, "NA", EL35/EK35-1) | EM40: =IF(EL35=0, "NA", EM35/EL35-1) | EN40: =IF(EM35=0, "NA", EN35/EM35-1) | EO40: =IF(EN35=0, "NA", EO35/EN35-1) | EP40: =IF(EO35=0, "NA", EP35/EO35-1) | EQ40: =IF(EP35=0, "NA", EQ35/EP35-1) | ... ES40: =IF(ER35=0, "NA", ES35/ER35-1)
B41: International (ex-currency) | AI41: =IF(ISNUMBER(AI40),(1+AI40)/(1+AI$21)-1,"NM") | AJ41: =IF(ISNUMBER(AJ40),(1+AJ40)/(1+AJ$21)-1,"NM") | AK41: =IF(ISNUMBER(AK40),(1+AK40)/(1+AK$21)-1,"NM") | AL41: =IF(ISNUMBER(AL40),(1+AL40)/(1+AL$21)-1,"NM") | AM41: =IF(ISNUMBER(AM40),(1+AM40)/(1+AM$21)-1,"NM") | AN41: =IF(ISNUMBER(AN40),(1+AN40)/(1+AN$21)-1,"NM") | AO41: =IF(ISNUMBER(AO40),(1+AO40)/(1+AO$21)-1,"NM") | AP41: =IF(ISNUMBER(AP40),(1+AP40)/(1+AP$21)-1,"NM") | ... CE41: =IF(ISNUMBER(CE40),(1+CE40)/(1+CE$21)-1,"NM") | CF41: =CF40-CF$21 | CG41: =CG40-CG$21 | CH41: =CH40-CH$21 | CI41: =CI40-CI$21 | CJ41: =CJ40-CJ$21 | CK41: =CK40-CK$21 | CL41: =CL40-CL$21 | CM41: =CM40-CM$21 | ... ES41: =ES40-ES$21
B42: Worldwide | I42: =IF(D36="NM","NM",IF(I36="NM","NM",IF(D36<=0,"NM",IF(I36=0,"NM",IF(ABS(I36/D36-1)>2.5,"NM",IF((ABS(I36-D36)=ABS(ABS(I36)-ABS(D36))),(I36/D36-1),"NM")))))) | J42: =IF(E36="NM","NM",IF(J36="NM","NM",IF(E36<=0,"NM",IF(J36=0,"NM",IF(ABS(J36/E36-1)>2.5,"NM",IF((ABS(J36-E36)=ABS(ABS(J36)-ABS(E36))),(J36/E36-1),"NM")))))) | K42: =IF(F36="NM","NM",IF(K36="NM","NM",IF(F36<=0,"NM",IF(K36=0,"NM",IF(ABS(K36/F36-1)>2.5,"NM",IF((ABS(K36-F36)=ABS(ABS(K36)-ABS(F36))),(K36/F36-1),"NM")))))) | L42: =IF(G36="NM","NM",IF(L36="NM","NM",IF(G36<=0,"NM",IF(L36=0,"NM",IF(ABS(L36/G36-1)>2.5,"NM",IF((ABS(L36-G36)=ABS(ABS(L36)-ABS(G36))),(L36/G36-1),"NM")))))) | M42: =IF(H36="NM","NM",IF(M36="NM","NM",IF(H36<=0,"NM",IF(M36=0,"NM",IF(ABS(M36/H36-1)>2.5,"NM",IF((ABS(M36-H36)=ABS(ABS(M36)-ABS(H36))),(M36/H36-1),"NM")))))) | N42: =IF(I36="NM","NM",IF(N36="NM","NM",IF(I36<=0,"NM",IF(N36=0,"NM",IF(ABS(N36/I36-1)>2.5,"NM",IF((ABS(N36-I36)=ABS(ABS(N36)-ABS(I36))),(N36/I36-1),"NM")))))) | O42: =IF(J36="NM","NM",IF(O36="NM","NM",IF(J36<=0,"NM",IF(O36=0,"NM",IF(ABS(O36/J36-1)>2.5,"NM",IF((ABS(O36-J36)=ABS(ABS(O36)-ABS(J36))),(O36/J36-1),"NM")))))) | P42: =IF(K36="NM","NM",IF(P36="NM","NM",IF(K36<=0,"NM",IF(P36=0,"NM",IF(ABS(P36/K36-1)>2.5,"NM",IF((ABS(P36-K36)=ABS(ABS(P36)-ABS(K36))),(P36/K36-1),"NM")))))) | ... CE42: =IF(BZ36="NM","NM",IF(CE36="NM","NM",IF(BZ36<=0,"NM",IF(CE36=0,"NM",IF(ABS(CE36/BZ36-1)>2.5,"NM",IF((ABS(CE36-BZ36)=ABS(ABS(CE36)-ABS(BZ36))),(CE36/BZ36-1),"NM")))))) | CF42: =IF(CA36=0, "NA", CF36/CA36-1) | CG42: =IF(CB36=0, "NA", CG36/CB36-1) | CH42: =IF(CC36=0, "NA", CH36/CC36-1) | CI42: =IF(CD36=0, "NA", CI36/CD36-1) | CJ42: =IF(CE36=0, "NA", CJ36/CE36-1) | CK42: =IF(CF36=0, "NA", CK36/CF36-1) | CL42: =IF(CG36=0, "NA", CL36/CG36-1) | CM42: =IF(CH36=0, "NA", CM36/CH36-1) | ... EI42: =IF(ED36=0, "NA", EI36/ED36-1) | EJ42: =IF(EI36=0, "NA", EJ36/EI36-1) | EK42: =IF(EJ36=0, "NA", EK36/EJ36-1) | EL42: =IF(EK36=0, "NA", EL36/EK36-1) | EM42: =IF(EL36=0, "NA", EM36/EL36-1) | EN42: =IF(EM36=0, "NA", EN36/EM36-1) | EO42: =IF(EN36=0, "NA", EO36/EN36-1) | EP42: =IF(EO36=0, "NA", EP36/EO36-1) | EQ42: =IF(EP36=0, "NA", EQ36/EP36-1) | ... ES42: =IF(ER36=0, "NA", ES36/ER36-1)
B44: MedTech
A45: =A47&" - US" | B45: US | D45: =+D1348 | E45: =+E1348 | F45: =+F1348 | G45: =+G1348 | H45: =+H1348 | I45: =+I1348 | J45: =+J1348 | K45: =+K1348 | ... EN45: =+EN1348
A46: =+A47&" - OUS" | B46: International | D46: =+D1349 | E46: =+E1349 | F46: =+F1349 | G46: =+G1349 | H46: =+H1349 | I46: =+I1349 | J46: =+J1349 | K46: =+K1349 | ... EN46: =+EN1349
A47: MD&D | B47: Worldwide | D47: =+D46+D45 | E47: =+E46+E45 | F47: =+F46+F45 | G47: =+G46+G45 | H47: =+H46+H45 | I47: =+I46+I45 | J47: =+J46+J45 | K47: =+K46+K45 | ... EN47: =+EN46+EN45
B49: MedTech sales % growth
...

Sheet Income Statement
B1: Currency - Do not Delete | DI1: Revenues orig | DL1: 17080.278 | DM1: 17886.258 | DN1: 67580.536 | DO1: 17711.23 | DP1: 17923.25 | DQ1: 17713.758 | DR1: 18614.339 | DS1: 71962.577 | DX1: 74345.446 | EC1: 77094.753 | EH1: 77094.753 | EM1: 82418.119 | ER1: 82418.119 | EW1: 82418.119 | FB1: 82418.119 | FG1: 82418.119 | FL1: 82418.119 | FS1: 82418.119 | FX1: 82418.119 | GC1: 82418.119 | GH1: 82418.119 | GI1: 82418.119 | GJ1: 82418.119 | GK1: 82418.119 | GL1: 82418.119 | GM1: 82418.119
DI2: Revenues chg | DL2: =+DL24-DL1 | DM2: =+DM24-DM1 | DN2: =+DN24-DN1 | DO2: =+DO24-DO1 | DP2: =+DP24-DP1 | DQ2: =+DQ24-DQ1 | DR2: =+DR24-DR1 | DS2: =+DS24-DS1 | DX2: =+DX24-DX1 | EC2: =+EC24-EC1 | EH2: =+EH24-EH1 | EM2: =+EM24-EM1 | ER2: =+ER24-ER1 | EW2: =+EW24-EW1 | FB2: =+FB24-FB1 | FG2: =+FG24-FG1 | FL2: =+FL24-FL1 | FS2: =+FS24-FS1 | FX2: =+FX24-FX1 | GC2: =+GC24-GC1 | GH2: =+GH24-GH1 | GI2: =+GI24-GI1 | GJ2: =+GJ24-GJ1 | GK2: =+GK24-GK1 | GL2: =+GL24-GL1 | GM2: =+GM24-GM1
DI3: NI orig | DL3: 3402.2048 | DM3: 3269.7013 | DN3: 14119.906 | DO3: 3731.3551 | DP3: 3775.3481 | DQ3: 3734.8602 | DR3: 3926.0754 | DS3: 15167.639 | DX3: 16137.893 | EC3: 17195.504 | EH3: 17195.504 | EM3: 19271.507 | ER3: 19271.507 | EW3: 19271.507 | FB3: 19271.507 | FG3: 19271.507 | FL3: 19271.507 | FS3: 19271.507 | FX3: 19271.507 | GC3: 19271.507 | GH3: 19271.507 | GI3: 19271.507 | GJ3: 19271.507 | GK3: 19271.507 | GL3: 19271.507 | GM3: 19271.507
DI4: NI shld chg | DL4: =+DL2*30% | DM4: =+DM2*30% | DN4: =+DN2*30% | DO4: =+DO2*30% | DP4: =+DP2*30% | DQ4: =+DQ2*30% | DR4: =+DR2*30% | DS4: =+DS2*30% | DX4: =+DX2*30% | EC4: =+EC2*30% | EH4: =+EH2*30% | EM4: =+EM2*30% | ER4: =+ER2*30% | EW4: =+EW2*30% | FB4: =+FB2*30% | FG4: =+FG2*30% | FL4: =+FL2*30% | FS4: =+FS2*30% | FX4: =+FX2*30% | GC4: =+GC2*30% | GH4: =+GH2*30% | GI4: =+GI2*30% | GJ4: =+GJ2*30% | GK4: =+GK2*30% | GL4: =+GL2*30% | GM4: =+GM2*30%
DI5: NI below | DL5: =+DL43-DL3 | DM5: =+DM43-DM3 | DN5: =+DN43-DN3 | DO5: =+DO43-DO3 | DP5: =+DP43-DP3 | DQ5: =+DQ43-DQ3 | DR5: =+DR43-DR3 | DS5: =+DS43-DS3 | DX5: =+DX43-DX3 | EC5: =+EC43-EC3 | EH5: =+EH43-EH3 | EM5: =+EM43-EM3 | ER5: =+ER43-ER3 | EW5: =+EW43-EW3 | FB5: =+FB43-FB3 | FG5: =+FG43-FG3 | FL5: =+FL43-FL3 | FS5: =+FS43-FS3 | FX5: =+FX43-FX3 | GC5: =+GC43-GC3 | GH5: =+GH43-GH3 | GI5: =+GI43-GI3 | GJ5: =+GJ43-GJ3 | GK5: =+GK43-GK3 | GL5: =+GL43-GL3 | GM5: =+GM43-GM3
DI6: EPS orig | DL6: 1.2217959 | DM6: 1.1763554 | DN6: 5.0712536 | DO6: 1.3449023 | DP6: 1.3632525 | DQ6: 1.3511085 | DR6: 1.4228941 | DS6: 5.4819539 | DX6: 5.8757373 | EC6: 6.3074278 | EH6: 6.3074278 | EM6: 7.1757844 | ER6: 7.1757844 | EW6: 7.1757844 | FB6: 7.1757844 | FG6: 7.1757844 | FL6: 7.1757844 | FS6: 7.1757844 | FX6: 7.1757844 | GC6: 7.1757844 | GH6: 7.1757844 | GI6: 7.1757844 | GJ6: 7.1757844 | GK6: 7.1757844 | GL6: 7.1757844 | GM6: 7.1757844
DI7: EPS shld chg | DL7: =+DL4/DL61 | DM7: =+DM4/DM61 | DN7: =+DN4/DN61 | DO7: =+DO4/DO61 | DP7: =+DP4/DP61 | DQ7: =+DQ4/DQ61 | DR7: =+DR4/DR61 | DS7: =+DS4/DS61 | DX7: =+DX4/DX61 | EC7: =+EC4/EC61 | EH7: =+EH4/EH61 | EM7: =+EM4/EM61 | ER7: =+ER4/ER61 | EW7: =+EW4/EW61 | FB7: =+FB4/FB61 | FG7: =+FG4/FG61 | FL7: =+FL4/FL61 | FS7: =+FS4/FS61 | FX7: =+FX4/FX61 | GC7: =+GC4/GC61 | GH7: =+GH4/GH61 | GI7: =+GI4/GI61 | GJ7: =+GJ4/GJ61 | GK7: =+GK4/GK61 | GL7: =+GL4/GL61 | GM7: =+GM4/GM61
DI8: EPS below | DL8: =+DL55-DL6 | DM8: =+DM55-DM6 | DN8: =+DN55-DN6 | DO8: =+DO55-DO6 | DP8: =+DP55-DP6 | DQ8: =+DQ55-DQ6 | DR8: =+DR55-DR6 | DS8: =+DS55-DS6 | DX8: =+DX55-DX6 | EC8: =+EC55-EC6 | EH8: =+EH55-EH6 | EM8: =+EM55-EM6 | ER8: =+ER55-ER6 | EW8: =+EW55-EW6 | FB8: =+FB55-FB6 | FG8: =+FG55-FG6 | FL8: =+FL55-FL6 | FS8: =+FS55-FS6 | FX8: =+FX55-FX6 | GC8: =+GC55-GC6 | GH8: =+GH55-GH6 | GI8: =+GI55-GI6 | GJ8: =+GJ55-GJ6 | GK8: =+GK55-GK6 | GL8: =+GL55-GL6 | GM8: =+GM55-GM6
DI9: Consensus
B12: =Cover!D11
B14: Income Statement
B16: ($ in millions)
EI18: =EI28/EM28
DY19: 312 | DZ19: 307 | EA19: 293 | EB19: 288 | FO19: Restated (excl. Consumer Health)
B20: $ mn, except per share data | C20: =+#REF! | E20: 1987 | F20: 1988 | G20: 1989 | H20: 1990 | I20: 1Q91 | J20: 2Q91 | K20: 3Q91 | L20: 4Q91 | M20: 1991 | N20: 1Q92 | O20: 2Q92 | P20: 3Q92 | Q20: 4Q92 | R20: 1992 | S20: 1Q93 | T20: 2Q93 | U20: 3Q93 | V20: 4Q93 | W20: 1993 | X20: 1Q94 | Y20: 2Q94 | Z20: 3Q94 | AA20: 4Q94 | AB20: 1994 | AC20: 1Q95 | AD20: 2Q95 | AE20: 3Q95 | AF20: 4Q95 | AG20: 1995 | AH20: 1Q96 | AI20: 2Q96 | AJ20: 3Q96 | AK20: 4Q96 | AL20: 1996 | AM20: 1Q97 | AN20: 2Q97 | AO20: 3Q97 | AP20: 4Q97 | AQ20: 1997 | AR20: 1Q98 | AS20: 2Q98 | AT20: 3Q98 | AU20: 4Q98 | AV20: 1998 | AW20: 1Q99 | AX20: 2Q99 | AY20: 3Q99 | AZ20: 4Q99 | BA20: 1999 | BB20: 1Q00 | BC20: 2Q00 | BD20: 3Q00 | BE20: 4Q00 | BF20: 2000 | BG20: 1Q01 | BH20: 2Q01 | BI20: 3Q01 | BJ20: 4Q01 | BK20: 2001 | BL20: 1Q02 | BM20: 2Q02 | BN20: 3Q02 | BO20: 4Q02 | BP20: 2002 | BQ20: 1Q03 | BR20: 2Q03 | BS20: 3Q03 | BT20: 4Q03 | BU20: 2003 | BV20: 1Q04 | BW20: 2Q04 | BX20: 3Q04 | BY20: 4Q04 | BZ20: 2004 | CA20: 1Q05 | CB20: 2Q05 | CC20: 3Q05 | CD20: 4Q05 | CE20: 2005 | CF20: 1Q06 | CG20: 2Q06 | CH20: 3Q06 | CI20: 4Q06 | CJ20: 2006 | CK20: 1Q07 | CL20: 2Q07 | CM20: 3Q07 | CN20: 4Q07 | CO20: 2007 | CP20: 1Q08 | CQ20: 2Q08 | CR20: 3Q08 | CS20: 4Q08 | CT20: 2008 | CU20: 1Q09 | CV20: 2Q09 | CW20: 3Q09 | CX20: 4Q09 | CY20: 2009 | CZ20: =+'Sales Model'!BH19 | DA20: =+'Sales Model'!BI19 | DB20: =+'Sales Model'!BJ19 | DC20: =+'Sales Model'!BK19 | DD20: 2010 | DE20: =+'Sales Model'!BM19 | DF20: =+'Sales Model'!BN19 | DG20: =+'Sales Model'!BO19 | DH20: =+'Sales Model'!BP19 | DI20: 2011 | DJ20: =+'Sales Model'!BR19 | DK20: =+'Sales Model'!BS19 | DL20: =+'Sales Model'!BT19 | DM20: =+'Sales Model'!BU19 | DN20: 2012 | DO20: 1Q13 | DP20: 2Q13 | DQ20: 3Q13 | DR20: 4Q13 | DS20: 2013 | DT20: 1Q14 | DU20: 2Q14 | DV20: 3Q14 | DW20: 4Q14 | DX20: 2014 | DY20: 1Q15 | DZ20: 2Q15 | EA20: 3Q15 | EB20: 4Q15 | EC20: 2015 | ED20: 1Q16 | EE20: 2Q16 | EF20: 3Q16 | EG20: 4Q16 | EH20: 2016 | EI20: 1Q17 | EJ20: 2Q17 | EK20: 3Q17 | EL20: 4Q17 | EM20: 2017 | EN20: 1Q18 | EO20: 2Q18 | EP20: 3Q18 | EQ20: 4Q18 | ER20: 2018 | ES20: 1Q19 | ET20: 2Q19 | EU20: 3Q19 | EV20: 4Q19 | EW20: 2019 | EX20: 1Q20 | EY20: 2Q20 | EZ20: 3Q20 | FA20: 4Q20 | FB20: 2020 | FC20: 1Q21 | FD20: 2Q21 | FE20: 3Q21 | FF20: 4Q21 | FG20: 2021 | FH20: 1Q22 | FI20: 2Q22 | FJ20: 3Q22 | FK20: 4Q22 | FL20: 2022 | FM20: 1Q23 | FN20: 2Q23 | FO20: 1Q22 | FP20: 2Q22 | FQ20: 3Q22 | FR20: 4Q22 | FS20: 2022 | FT20: 1Q23 | FU20: 2Q23 | FV20: 3Q23 | FW20: 4Q23 | FX20: 2023 | FY20: 1Q24 | FZ20: 2Q24 | GA20: 3Q24 | GB20: 4Q24 | GC20: 2024 | GD20: 1Q25 | GE20: 2Q25 | GF20: 3Q25 | GG20: 4Q25E | GH20: 2025E | GI20: 2026E | GJ20: 2027E | GK20: 2028E | GL20: 2029E | GM20: 2030E
B22: Domestic | E22: 4167 | F22: 4576 | G22: 4881 | H22: =#REF! | I22: =#REF! | J22: =#REF! | K22: =#REF! | M22: =#REF! | R22: =#REF! | S22: =#REF! | T22: =#REF! | U22: =#REF! | V22: =#REF! | W22: =S22+T22+U22+V22 | X22: =#REF! | Y22: =#REF! | Z22: 2002 | AA22: 2054 | AB22: =X22+Y22+Z22+AA22 | AC22: 2176 | AD22: 2230 | AE22: 2335 | AF22: 2449 | AG22: =AC22+AD22+AE22+AF22 | AH22: 2652 | AI22: 2637 | AJ22: 2790 | AK22: 2820 | AL22: 10899 | AM22: 2947 | AN22: 2881 | AO22: 2962 | AP22: 2967 | AQ22: 11757 | AR22: 3152 | AS22: 3093 | AT22: 3149 | AU22: 3492 | AV22: ='Sales Model'!D23 | AW22: ='Sales Model'!E23 | AX22: ='Sales Model'!F23 | AY22: ='Sales Model'!G23 | AZ22: ='Sales Model'!H23 | BA22: ='Sales Model'!I23 | BB22: ='Sales Model'!J23 | BC22: ='Sales Model'!K23 | ... BE22: ='Sales Model'!M23 | BF22: =SUM(BB22:BE22) | BG22: ='Sales Model'!O23 | BH22: ='Sales Model'!P23 | BI22: ='Sales Model'!Q23 | BJ22: ='Sales Model'!R23 | BK22: =SUM(BG22:BJ22) | BL22: ='Sales Model'!T23 | BM22: ='Sales Model'!U23 | BN22: ='Sales Model'!V23 | BO22: ='Sales Model'!W23 | BP22: =SUM(BL22:BO22) | BQ22: ='Sales Model'!Y23 | BR22: ='Sales Model'!Z23 | BS22: ='Sales Model'!AA23 | BT22: ='Sales Model'!AB23 | BU22: =SUM(BQ22:BT22) | BV22: ='Sales Model'!AD23 | BW22: ='Sales Model'!AE23 | BX22: ='Sales Model'!AF23 | BY22: ='Sales Model'!AG23 | BZ22: ='Sales Model'!AH23 | CA22: ='Sales Model'!AI23 | CB22: ='Sales Model'!AJ23 | CC22: ='Sales Model'!AK23 | ... DC22: ='Sales Model'!BK23 | DD22: =SUM(CZ22,DA22,DB22,DC22) | DE22: ='Sales Model'!BM23 | DF22: 7447 | DG22: 6868 | DH22: 6985 | DI22: =SUM(DE22:DH22) | DJ22: 7219 | DK22: 7360 | DL22: 7791 | DM22: 7460 | DN22: =SUM(DJ22:DM22) | DO22: 8025 | DP22: 7946 | DQ22: 7925 | DR22: 8014 | DS22: =SUM(DO22:DR22) | DT22: 8204 | DU22: 9132 | DV22: 8842 | DW22: 8604 | DX22: =SUM(DT22:DW22) | DY22: 8692 | DZ22: 8911 | EA22: 8791 | EB22: 9293 | EC22: =SUM(DY22:EB22) | ED22: 9321 | EE22: 9572 | EF22: 9381 | EG22: 9537 | EH22: =SUM(ED22:EG22) | EI22: 9378 | EJ22: 9726 | EK22: 10290 | EL22: 10469 | EM22: =SUM(EI22:EL22) | EN22: 9951 | EO22: 10640 | EP22: =+'Sales Model'!CX23 | EQ22: =+'Sales Model'!CY23 | ER22: =SUM(EN22:EQ22) | ES22: 10129 | ET22: 10403 | EU22: 10791 | EV22: 10774 | EW22: =SUM(ES22:EV22) | EX22: 10699 | EY22: ='Sales Model'!DG23 | EZ22: ='Sales Model'!DH23 | FA22: ='Sales Model'!DI23 | FB22: =SUM(EX22:FA22) | FC22: ='Sales Model'!DK23 | FD22: ='Sales Model'!DL23 | FE22: ='Sales Model'!DM23 | FF22: ='Sales Model'!DN23 | FG22: ='Sales Model'!DO23 | FH22: ='Sales Model'!DP23 | FI22: ='Sales Model'!DQ23 | FJ22: ='Sales Model'!DR23 | ... FN22: ='Sales Model'!DV23 | FO22: 9857 | FP22: 10510 | FQ22: 10794 | FR22: 10820 | FS22: 41981 | FT22: 10782.3 | FU22: 11656.7 | FV22: 11996 | FW22: 12009 | FX22: 46444 | FY22: 11620 | FZ22: 12569 | GA22: 12909 | GB22: 13204 | GC22: =SUM(FY22:GB22) | GD22: 12305 | GE22: 13544 | GF22: 13708 | GG22: ='Sales Model'!EH23 | GH22: ='Sales Model'!EI23 | GI22: ='Sales Model'!EJ23 | GJ22: ='Sales Model'!EK23 | GK22: ='Sales Model'!EL23 | GL22: ='Sales Model'!EM23 | GM22: ='Sales Model'!EN23
B23: International | E23: 3845 | F23: 4424 | G23: 4876 | H23: =#REF! | I23: =#REF! | J23: =#REF! | K23: =#REF! | L23: =#REF! | M23: =#REF! | N23: =#REF! | O23: =#REF! | P23: =#REF! | Q23: =R23-N23-O23-P23 | R23: =#REF! | S23: =#REF! | T23: =#REF! | U23: =#REF! | V23: 125 | W23: =S23+T23+U23+V23 | X23: =#REF! | Y23: =#REF! | Z23: 2036 | AA23: 2036 | AB23: =X23+Y23+Z23+AA23 | AC23: 2320 | AD23: 2532 | AE23: 2403 | AF23: 2397 | AG23: =AC23+AD23+AE23+AF23 | AH23: 2682 | AI23: 2745 | AJ23: 2612 | AK23: 2682 | AL23: 10721 | AM23: 2768 | AN23: 2817 | AO23: 2624 | AP23: 2663 | AQ23: 10872 | AR23: 2688 | AS23: 2781 | AT23: 2662 | AU23: 2978 | AV23: ='Sales Model'!D24 | AW23: ='Sales Model'!E24 | AX23: ='Sales Model'!F24 | AY23: ='Sales Model'!G24 | AZ23: ='Sales Model'!H24 | BA23: ='Sales Model'!I24 | BB23: ='Sales Model'!J24 | BC23: ='Sales Model'!K24 | ... BE23: ='Sales Model'!M24 | BF23: =SUM(BB23:BE23) | BG23: ='Sales Model'!O24 | BH23: ='Sales Model'!P24 | BI23: ='Sales Model'!Q24 | BJ23: ='Sales Model'!R24 | BK23: =SUM(BG23:BJ23) | BL23: ='Sales Model'!T24 | BM23: ='Sales Model'!U24 | BN23: ='Sales Model'!V24 | BO23: ='Sales Model'!W24 | BP23: =SUM(BL23:BO23) | BQ23: ='Sales Model'!Y24 | BR23: ='Sales Model'!Z24 | BS23: ='Sales Model'!AA24 | BT23: ='Sales Model'!AB24 | BU23: =SUM(BQ23:BT23) | BV23: ='Sales Model'!AD24 | BW23: ='Sales Model'!AE24 | BX23: ='Sales Model'!AF24 | BY23: ='Sales Model'!AG24 | BZ23: ='Sales Model'!AH24 | CA23: ='Sales Model'!AI24 | CB23: ='Sales Model'!AJ24 | CC23: ='Sales Model'!AK24 | ... DC23: ='Sales Model'!BK24 | DD23: =SUM(CZ23,DA23,DB23,DC23) | DE23: ='Sales Model'!BM24 | DF23: 9150 | DG23: 9137 | DH23: 9270 | DI23: =SUM(DE23:DH23) | DJ23: 8920 | DK23: 9115 | DL23: 9261 | DM23: 10098 | DN23: =SUM(DJ23:DM23) | DO23: 9480 | DP23: 9931 | DQ23: 9650 | DR23: 10341 | DS23: =SUM(DO23:DR23) | DT23: 9911 | DU23: 10363 | DV23: 9625 | DW23: 9650 | DX23: =SUM(DT23:DW23) | DY23: 8682 | DZ23: 8876 | EA23: 8311 | EB23: 8518 | EC23: =SUM(DY23:EB23) | ED23: 8161 | EE23: 8910 | EF23: 8439 | EG23: 8569 | EH23: =SUM(ED23:EG23) | EI23: 8388 | EJ23: 9113 | EK23: 9360 | EL23: 9726 | EM23: =SUM(EI23:EL23) | EN23: 10058 | EO23: 10190 | EP23: =+'Sales Model'!CX24 | EQ23: =+'Sales Model'!CY24 | ER23: =SUM(EN23:EQ23) | ES23: 9892 | ET23: 10159 | EU23: 9938 | EV23: 9973 | EW23: =SUM(ES23:EV23) | EX23: 9992 | EY23: ='Sales Model'!DG24 | EZ23: ='Sales Model'!DH24 | FA23: ='Sales Model'!DI24 | FB23: =SUM(EX23:FA23) | FC23: ='Sales Model'!DK24 | FD23: ='Sales Model'!DL24 | FE23: ='Sales Model'!DM24 | FF23: ='Sales Model'!DN24 | FG23: ='Sales Model'!DO24 | FH23: ='Sales Model'!DP24 | FI23: ='Sales Model'!DQ24 | FJ23: ='Sales Model'!DR24 | ... FN23: ='Sales Model'!DV24 | FO23: 9983 | FP23: 9705 | FQ23: 9202 | FR23: 9119 | FS23: 38009 | FT23: 10112 | FU23: 9862 | FV23: 9355 | FW23: 9386 | FX23: 38715 | FY23: 9763 | FZ23: 9878 | GA23: 9562 | GB23: 9316 | GC23: =SUM(FY23:GB23) | GD23: 9588 | GE23: 10199 | GF23: 10285 | GG23: ='Sales Model'!EH24 | GH23: ='Sales Model'!EI24 | GI23: ='Sales Model'!EJ24 | GJ23: ='Sales Model'!EK24 | GK23: ='Sales Model'!EL24 | GL23: ='Sales Model'!EM24 | GM23: ='Sales Model'!EN24
B24: Total Sales | E24: =SUM(E22:E23) | F24: =SUM(F22:F23) | G24: =SUM(G22:G23) | H24: =SUM(H22:H23) | I24: =SUM(I22:I23) | J24: =SUM(J22:J23) | K24: =SUM(K22:K23) | L24: 1586 | M24: =M22+M23 | N24: 1668 | O24: 1767 | P24: 1733 | Q24: 1682 | R24: =R22+R23 | S24: =SUM(S22:S23) | T24: =SUM(T22:T23) | U24: =SUM(U22:U23) | V24: 85 | W24: =W22+W23 | X24: =SUM(X22:X23) | Y24: =SUM(Y22:Y23) | Z24: =SUM(Z22:Z23) | AA24: =SUM(AA22:AA23) | AB24: =AB22+AB23 | AC24: =SUM(AC22:AC23) | AD24: =SUM(AD22:AD23) | AE24: =SUM(AE22:AE23) | AF24: =SUM(AF22:AF23) | AG24: =AG22+AG23 | AH24: =SUM(AH22:AH23) | AI24: =SUM(AI22:AI23) | AJ24: =SUM(AJ22:AJ23) | AK24: =SUM(AK22:AK23) | AL24: =AL22+AL23 | AM24: =SUM(AM22:AM23) | AN24: =SUM(AN22:AN23) | AO24: =SUM(AO22:AO23) | AP24: =SUM(AP22:AP23) | AQ24: =AQ22+AQ23 | AR24: =SUM(AR22:AR23) | AS24: =SUM(AS22:AS23) | AT24: =SUM(AT22:AT23) | AU24: =SUM(AU22:AU23) | AV24: =AV22+AV23 | AW24: =SUM(AW22:AW23) | AX24: =SUM(AX22:AX23) | AY24: =SUM(AY22:AY23) | AZ24: =SUM(AZ22:AZ23) | BA24: =BA23+BA22 | BB24: =BB22+BB23 | BC24: =BC22+BC23 | BD24: =BD22+BD23 | BE24: =BE22+BE23 | BF24: =BF23+BF22 | BG24: =BG22+BG23 | BH24: =BH22+BH23 | BI24: =BI22+BI23 | BJ24: =BJ22+BJ23 | BK24: =BK23+BK22 | BL24: =BL22+BL23 | BM24: =BM22+BM23 | BN24: =BN22+BN23 | BO24: =BO22+BO23 | BP24: =BP23+BP22 | BQ24: =BQ22+BQ23 | BR24: =BR22+BR23 | BS24: =BS22+BS23 | BT24: =BT22+BT23 | BU24: =BU23+BU22 | BV24: =BV22+BV23 | BW24: =BW22+BW23 | BX24: =BX22+BX23 | BY24: =BY22+BY23 | BZ24: =BZ23+BZ22 | CA24: =CA22+CA23 | CB24: =CB22+CB23 | CC24: =CC22+CC23 | CD24: =CD22+CD23 | CE24: =CE23+CE22 | CF24: =CF22+CF23 | CG24: =CG22+CG23 | CH24: =CH22+CH23 | CI24: =CI22+CI23 | CJ24: =CJ23+CJ22 | CK24: =CK22+CK23 | CL24: =CL22+CL23 | CM24: =CM22+CM23 | CN24: =CN22+CN23 | CO24: =CO23+CO22 | CP24: =CP22+CP23 | CQ24: =CQ22+CQ23 | CR24: =CR22+CR23 | CS24: =CS22+CS23 | CT24: =CT23+CT22 | CU24: =CU22+CU23 | CV24: =CV22+CV23 | CW24: =CW22+CW23 | CX24: =CX22+CX23 | CY24: =CY23+CY22 | CZ24: =CZ23+CZ22 | DA24: =DA23+DA22 | DB24: =DB23+DB22 | DC24: =DC22+DC23 | DD24: =DD23+DD22 | DE24: =DE22+DE23 | DF24: =DF22+DF23 | DG24: =DG22+DG23 | DH24: =DH22+DH23 | DI24: =SUM(DE24:DH24) | DJ24: =DJ22+DJ23 | DK24: =DK22+DK23 | DL24: =DL22+DL23 | DM24: =DM22+DM23 | DN24: =DN23+DN22 | DO24: =DO22+DO23 | DP24: =DP22+DP23 | DQ24: =DQ22+DQ23 | DR24: =DR22+DR23 | DS24: =DS23+DS22 | DT24: =DT22+DT23 | DU24: =DU22+DU23 | DV24: =DV22+DV23 | DW24: =DW22+DW23 | DX24: =DX23+DX22 | DY24: =DY22+DY23 | DZ24: =DZ22+DZ23 | EA24: =EA22+EA23 | EB24: =EB22+EB23 | EC24: =EC23+EC22 | ED24: =ED22+ED23 | EE24: =EE22+EE23 | EF24: =EF22+EF23 | EG24: =EG22+EG23 | EH24: =EH23+EH22 | EI24: =EI22+EI23 | EJ24: =EJ22+EJ23 | EK24: =EK22+EK23 | EL24: =EL22+EL23 | EM24: =EM23+EM22 | EN24: =EN22+EN23 | EO24: =EO22+EO23 | EP24: =EP22+EP23 | EQ24: =EQ22+EQ23 | ER24: =ER23+ER22 | ES24: =ES22+ES23 | ET24: =ET22+ET23 | EU24: =EU22+EU23 | EV24: =EV22+EV23 | EW24: =EW23+EW22 | EX24: =EX22+EX23 | EY24: =EY22+EY23 | EZ24: =EZ22+EZ23 | FA24: =FA22+FA23 | FB24: =SUM(EX24:FA24) | FC24: =FC22+FC23 | FD24: =FD22+FD23 | FE24: =FE22+FE23 | FF24: =FF22+FF23 | FG24: =SUM(FC24:FF24) | FH24: =FH22+FH23 | FI24: =FI22+FI23 | FJ24: =FJ22+FJ23 | FK24: =FK22+FK23 | FL24: =SUM(FH24:FK24) | FM24: =FM22+FM23 | FN24: =FN22+FN23 | FO24: =FO22+FO23 | FP24: =FP22+FP23 | FQ24: =FQ22+FQ23 | FR24: =FR22+FR23 | FS24: =SUM(FO24:FR24) | FT24: =FT22+FT23 | FU24: =FU22+FU23 | FV24: =FV22+FV23 | FW24: =FW22+FW23 | FX24: =FX23+FX22 | FY24: =FY22+FY23 | FZ24: =FZ22+FZ23 | GA24: =GA22+GA23 | GB24: =GB22+GB23 | GC24: =GC23+GC22 | GD24: =GD22+GD23 | GE24: =GE22+GE23 | GF24: =GF22+GF23 | GG24: =GG22+GG23 | GH24: =GH23+GH22 | GI24: =GI23+GI22 | GJ24: =GJ23+GJ22 | GK24: =GK23+GK22 | GL24: =GL23+GL22 | GM24: =GM23+GM22
B26: Cost of Goods Sold | E26: 2958 | F26: 3292 | G26: 3480 | H26: 3937 | I26: 1039 | J26: 984 | K26: 1079 | L26: =M26-SUM(I26:K26) | M26: 4204 | N26: 1127 | O26: 1119 | P26: 1198 | Q26: =R26-N26-O26-P26 | R26: 4678 | S26: 1163 | T26: 1148 | U26: 1188 | V26: 1292 | W26: =S26+T26+U26+V26 | X26: 1181 | Y26: 1287 | Z26: 1364 | AA26: 1467 | AB26: =X26+Y26+Z26+AA26 | AC26: 1447 | AD26: 1562 | AE26: 1543 | AF26: 1683 | AG26: =AC26+AD26+AE26+AF26 | AH26: 1719 | AI26: 1732 | AJ26: 1715 | AK26: 1852 | AL26: 7018 | AM26: 1772 | AN26: 1749 | AO26: 1750 | AP26: 1881 | AQ26: 7152 | AR26: 1798 | AS26: 1827 | AT26: 1790 | AU26: 2189 | AV26: 7604 | AW26: 2070 | AX26: 2123 | AY26: 2068 | AZ26: 2181 | BA26: =SUM(AW26:AZ26) | BB26: 2242 | BC26: 2261 | BD26: 2191 | BE26: 2214 | BF26: =SUM(BB26:BE26) | BG26: 2311 | BH26: 2372 | BI26: 2396 | BJ26: 2502 | BK26: =SUM(BG26:BJ26) | BL26: 2457 | BM26: 2582 | BN26: 2611 | BO26: 2797 | BP26: =SUM(BL26:BO26) | BQ26: 2722 | BR26: 2966 | BS26: 2980 | BT26: 3508 | BU26: =SUM(BQ26:BT26) | BV26: 3367 | BW26: 3162 | BX26: 3187 | BY26: 3706 | BZ26: =SUM(BV26:BY26) | CA26: 3482 | CB26: 3508 | CC26: 3340 | CD26: 3624 | CE26: =SUM(CA26:CD26) | CF26: 3612 | CG26: 3788 | CH26: 3650 | CI26: 4007 | CJ26: =+SUM(CF26:CI26) | CK26: 4385 | CL26: 4358 | CM26: 4274 | CN26: 4734 | CO26: =+SUM(CK26:CN26) | CP26: 4614 | CQ26: 4751 | CR26: 4774 | CS26: 4372 | CT26: =SUM(CP26:CS26) | CU26: 4251 | CV26: 4450 | CW26: 4434 | CX26: =5312-113 | CY26: =SUM(CU26:CX26) | CZ26: =4528 | DA26: 4630 | DB26: 4594 | DC26: 5040 | DD26: =SUM(CZ26:DC26) | DE26: 4778 | DF26: 5172 | DG26: 5072 | DH26: 5338 | DI26: =SUM(DE26:DH26) | DJ26: 4915 | DK26: 5143 | DL26: =5597-165 | DM26: =6003-221 | DN26: =SUM(DJ26:DM26) | DO26: =5554-147 | DP26: 5489 | DQ26: 5344 | DR26: 5955 | DS26: =SUM(DO26:DR26) | DT26: =5455-351 | DU26: =6039-348 | DV26: =5399-334 | DW26: =5853-344 | DX26: =SUM(DT26:DW26) | DY26: =5282-312 | DZ26: =5357-307 | EA26: =5224-293 | EB26: =5673-288 | EC26: =SUM(DY26:EB26) | ED26: =5329-282 | EE26: =5336-326 | EF26: =5486-319 | EG26: =5534-344 | EH26: =SUM(ED26:EG26) | EI26: 5057 | EJ26: =5823-370 | EK26: 5463 | EL26: 5943 | EM26: =SUM(EI26:EL26) | EN26: 5416 | EO26: 5768 | EP26: 5481 | EQ26: 5856 | ER26: =SUM(EN26:EQ26) | ES26: 5462 | ET26: 5822 | EU26: 5709 | EV26: 5940 | EW26: =SUM(ES26:EV26) | EX26: 5915 | EY26: 5422 | EZ26: 5741 | FA26: 6550 | FB26: =SUM(EX26:FA26) | FC26: 5804 | FD26: 6345 | FE26: 6077 | FF26: 6797 | FG26: =SUM(FC26:FF26) | FH26: 6452 | FI26: 6600 | FJ26: 6622 | FK26: 6472 | FL26: =SUM(FH26:FK26) | FM26: 6954 | FN26: 6991 | FO26: 4968 | FP26: 5094 | FQ26: 5074 | FR26: 4889 | FS26: =SUM(FO26:FR26) | FT26: 5340 | FU26: 5336 | FV26: 5205 | FW26: 5530 | FX26: 21411 | FY26: 5404 | FZ26: 5677 | GA26: 5612 | GB26: 5775 | GC26: =SUM(FY26:GB26) | GD26: 6177 | GE26: 6334 | GF26: 6231 | GG26: =GG24*(1-GG65) | GH26: =SUM(GD26:GG26) | GI26: =GI24*(1-GI65) | GJ26: =GJ24*(1-GJ65) | GK26: =GK24*(1-GK65) | GL26: =GL24*(1-GL65) | GM26: =GM24*(1-GM65)
B27: SG&A | E27: 3228 | F27: 3630 | G27: 3897 | H27: 4469 | I27: 1269 | J27: 1216 | K27: 1272 | L27: =M27-SUM(I27:K27) | M27: 5099 | N27: 1355 | O27: 1389 | P27: 1431 | Q27: =R27-N27-O27-P27 | R27: 5671 | S27: 1436 | T27: 1432 | U27: 1445 | V27: 742 | W27: =S27+T27+U27+V27 | X27: 1480 | Y27: 1558 | Z27: 1601 | AA27: 1711 | AB27: =X27+Y27+Z27+AA27 | AC27: 1720 | AD27: 1857 | AE27: 1857 | AF27: 2028 | AG27: =AC27+AD27+AE27+AF27 | AH27: 1996 | AI27: 2027 | AJ27: 2092 | AK27: 2279 | AL27: 8394 | AM27: 2138 | AN27: 2142 | AO27: 2149 | AP27: 2286 | AQ27: 8715 | AR27: 2116 | AS27: 2140 | AT27: 2187 | AU27: 2584 | AV27: =SUM(AR27:AU27) | AW27: 2437 | AX27: 2588 | AY27: 2617 | AZ27: 2861 | BA27: =SUM(AW27:AZ27) | BB27: 2679 | BC27: 2829 | BD27: 2767 | BE27: 2943 | BF27: =SUM(BB27:BE27) | BG27: 2666 | BH27: 2802 | BI27: 2703 | BJ27: 3089 | BK27: =SUM(BG27:BJ27) | BL27: 2843 | BM27: 3017 | BN27: 3006 | BO27: 3350 | BP27: =SUM(BL27:BO27) | BQ27: 3253 | BR27: 3396 | BS27: 3428 | BT27: 4054 | BU27: =SUM(BQ27:BT27) | BV27: 3640 | BW27: 3711 | BX27: 3854 | BY27: 4655 | BZ27: =SUM(BV27:BY27) | CA27: 4043 | CB27: 4194 | CC27: 4078 | CD27: 4562 | CE27: =SUM(CA27:CD27) | CF27: 4095 | CG27: 4351 | CH27: 4291 | CI27: 4696 | CJ27: =+SUM(CF27:CI27) | CK27: 4802 | CL27: 5029 | CM27: 4899 | CN27: 5721 | CO27: =+SUM(CK27:CN27) | CP27: 5123 | CQ27: 5507 | CR27: 5195 | CS27: 5665 | CT27: =SUM(CP27:CS27) | CU27: 4608 | CV27: 4797 | CW27: 4767 | CX27: 5629 | CY27: =SUM(CU27:CX27) | CZ27: 4779 | DA27: 4756 | DB27: 4709 | DC27: 5180 | DD27: =SUM(CZ27:DC27) | DE27: 5056 | DF27: 5215 | DG27: 5240 | DH27: 5458 | DI27: =SUM(DE27:DH27) | DJ27: 5015 | DK27: 4965 | DL27: 5228 | DM27: 5661 | DN27: =SUM(DJ27:DM27) | DO27: 5223 | DP27: 5376 | DQ27: 5314 | DR27: 5917 | DS27: =SUM(DO27:DR27) | DT27: 5183 | DU27: 5481 | DV27: =5468-220 | DW27: 5822 | DX27: =SUM(DT27:DW27) | DY27: 4847 | DZ27: 5384 | EA27: 5081 | EB27: 5891 | EC27: =SUM(DY27:EB27) | ED27: 4688 | EE27: =5176 | EF27: 4772 | EG27: 5309 | EH27: =SUM(ED27:EG27) | EI27: 4737 | EJ27: 5262 | EK27: 5396 | EL27: 6025 | EM27: =SUM(EI27:EL27) | EN27: 5263 | EO27: 5743 | EP27: 5543 | EQ27: 5991 | ER27: =SUM(EN27:EQ27) | ES27: 5219 | ET27: 5546 | EU27: 5374 | EV27: 6039 | EW27: =SUM(ES27:EV27) | EX27: 5203 | EY27: 4987 | EZ27: 5427 | FA27: 6450 | FB27: =SUM(EX27:FA27) | FC27: 5427 | FD27: 6067 | FE27: 5994 | FF27: 7147 | FG27: =SUM(FC27:FF27) | FH27: 5932 | FI27: 6220 | FJ27: 6080 | FK27: 6460 | FL27: =SUM(FH27:FK27) | FM27: 6093 | FN27: 6613 | FO27: 4806 | FP27: 5114 | FQ27: 4968 | FR27: 5330 | FS27: =SUM(FO27:FR27) | FT27: 4899 | FU27: 5388 | FV27: 5394 | FW27: 5802 | FX27: 21483 | FY27: 5253 | FZ27: 5676 | GA27: 5475 | GB27: 6449 | GC27: =SUM(FY27:GB27) | GD27: 5112 | GE27: 5889 | GF27: 5922 | GG27: =GH27-SUM(GD27:GF27) | GH27: =GH24*GH66 | GI27: =GI24*GI66 | GJ27: =GJ24*GJ66 | GK27: =GK24*GK66 | GL27: =GL24*GL66 | GM27: =GM24*GM66
B28: R&D | E28: 617 | F28: 674 | G28: 719 | H28: 834 | I28: 219 | J28: 225 | K28: 242 | L28: 294 | M28: 980 | N28: 262 | O28: 268 | P28: 277 | Q28: =R28-N28-O28-P28 | R28: 1127 | S28: 281 | T28: 286 | U28: 277 | V28: 286 | W28: =S28+T28+U28+V28 | X28: 289 | Y28: 313 | Z28: 316 | AA28: 360 | AB28: =X28+Y28+Z28+AA28 | AC28: 353 | AD28: 380 | AE28: 395 | AF28: 506 | AG28: =AC28+AD28+AE28+AF28 | AH28: 428 | AI28: 448 | AJ28: 441 | AK28: 588 | AL28: 1905 | AM28: 478 | AN28: 520 | AO28: 516 | AP28: 626 | AQ28: 2140 | AR28: 514 | AS28: 548 | AT28: 524 | AU28: 750 | AV28: =SUM(AR28:AU28) | AW28: 557 | AX28: 596 | AY28: 635 | AZ28: 812 | BA28: =SUM(AW28:AZ28) | BB28: 677 | BC28: 713 | BD28: 739 | BE28: 976 | BF28: =SUM(BB28:BE28) | BG28: 759 | BH28: 829 | BI28: 899 | BJ28: 1104 | BK28: =SUM(BG28:BJ28) | BL28: 831 | BM28: 932 | BN28: 952 | BO28: 1242 | BP28: =SUM(BL28:BO28) | BQ28: 936 | BR28: 1082 | BS28: 1177 | BT28: 1489 | BU28: =SUM(BQ28:BT28) | BV28: 1095 | BW28: 1182 | BX28: 1198 | BY28: 1727 | BZ28: =SUM(BV28:BY28) | CA28: 1347 | CB28: 1487 | CC28: 1502 | CD28: 1976 | CE28: =SUM(CA28:CD28) | CF28: 1532 | CG28: 1828 | CH28: 1719 | CI28: 2046 | CJ28: =+SUM(CF28:CI28) | CK28: 1652 | CL28: 1866 | CM28: 1834 | CN28: 2328 | CO28: =+SUM(CK28:CN28) | CP28: 1712 | CQ28: 1896 | CR28: 1861 | CS28: 2108 | CT28: =SUM(CP28:CS28) | CU28: 1518 | CV28: 1638 | CW28: 1617 | CX28: 2213 | CY28: =SUM(CU28:CX28) | CZ28: 1557 | DA28: 1648 | DB28: 1657 | DC28: 1982 | DD28: =SUM(CZ28:DC28) | DE28: 1738 | DF28: 1882 | DG28: 1773 | DH28: 2155 | DI28: =SUM(DE28:DH28) | DJ28: 1645 | DK28: 1766 | DL28: 1923 | DM28: 2331 | DN28: =SUM(DJ28:DM28) | DO28: 1784 | DP28: 1946 | DQ28: 2042 | DR28: 2411 | DS28: =SUM(DO28:DR28) | DT28: 1831 | DU28: 2005 | DV28: 2023 | DW28: 2635 | DX28: =SUM(DT28:DW28) | DY28: 1899 | DZ28: 2129 | EA28: 2154 | EB28: 2864 | EC28: =SUM(DY28:EB28) | ED28: 2013 | EE28: 2264 | EF28: 2178 | EG28: 2640 | EH28: =SUM(ED28:EG28) | EI28: 2060 | EJ28: 2285 | EK28: 2574 | EL28: 3635 | EM28: =SUM(EI28:EL28) | EN28: 2404 | EO28: 2639 | EP28: 2508 | EQ28: 3224 | ER28: =SUM(EN28:EQ28) | ES28: 2858 | ET28: 2666 | EU28: 2599 | EV28: 3185 | EW28: =SUM(ES28:EV28) | EX28: 2580 | EY28: 2679 | EZ28: 2829 | FA28: 4003 | FB28: =SUM(EX28:FA28) | FC28: 3154 | FD28: 3364 | FE28: 3391 | FF28: 4680 | FG28: =SUM(FC28:FF28) | FH28: 3430 | FI28: 3554 | FJ28: 3475 | FK28: 3681 | FL28: =SUM(FH28:FK28) | FM28: 3495 | FN28: 3737 | FO28: 3323 | FP28: 3436 | FQ28: 3363 | FR28: 3550 | FS28: =SUM(FO28:FR28) | FT28: 3389 | FU28: 3613 | FV28: 3378 | FW28: 4425 | FX28: 14805 | FY28: 3490 | FZ28: 3382 | GA28: 4895 | GB28: 5267 | GC28: =SUM(FY28:GB28) | GD28: 3219 | GE28: 3559 | GF28: 3672 | GG28: =GH28-SUM(GD28:GF28) | GH28: =GH24*GH67 | GI28: =GI24*GI67 | GJ28: =GJ24*GJ67 | GK28: =GK24*GK67 | GL28: =GL24*GL67 | GM28: =GM24*GM67
B29: Operating Income (cont ops) | E29: =E24-E26-E27-E28 | F29: =F24-F26-F27-F28 | G29: =G24-G26-G27-G28 | H29: =H24-H26-H27-H28 | I29: =I24-I26-I27-I28 | J29: =J24-J26-J27-J28 | K29: =K24-K26-K27-K28 | L29: =L24-L26-L27-L28 | ... AF29: =AF24-AF26-AF27-AF28 | AG29: =AC29+AD29+AE29+AF29 | AH29: =AH24-AH26-AH27-AH28 | AI29: =AI24-AI26-AI27-AI28 | AJ29: =AJ24-AJ26-AJ27-AJ28 | AK29: =AK24-AK26-AK27-AK28 | AL29: =AL24-AL26-AL27-AL28 | AM29: =AM24-AM26-AM27-AM28 | AN29: =AN24-AN26-AN27-AN28 | AO29: =AO24-AO26-AO27-AO28 | ... GB29: =GB24-GB26-GB27-GB28 | GC29: =GC24-GC26-GC27-GC28-GC33 | GD29: =GD24-GD26-GD27-GD28 | GE29: =GE24-GE26-GE27-GE28 | GF29: =GF24-GF26-GF27-GF28 | GG29: =+GH29-SUM(GD29:GF29) | GH29: =GH24-GH26-GH27-GH28 | GI29: =GI24-GI26-GI27-GI28 | GJ29: =GJ24-GJ26-GJ27-GJ28 | GK29: =GK24-GK26-GK27-GK28 | GL29: =GL24-GL26-GL27-GL28 | GM29: =GM24-GM26-GM27-GM28
B31: Latin American operations | H31: -104 | V31: 220
B32: Non-recurring items, pre-tax | V32: 15
B33: In-process R&D | E33: 0 | F33: 0 | G33: 0 | H33: 0 | I33: 0 | J33: 0 | K33: 0 | L33: 0 | M33: 0 | N33: 0 | O33: 0 | P33: 0 | Q33: 0 | R33: 0 | S33: 0 | T33: 0 | U33: 0 | V33: 0 | W33: 0 | X33: 0 | Y33: 0 | Z33: 0 | AA33: 0 | AB33: 0 | AC33: 0 | AD33: 0 | AE33: 0 | AF33: 0 | AG33: 0 | AH33: 0 | AI33: 0 | AJ33: 0 | AK33: 0 | AL33: 0 | AM33: 0 | AN33: 0 | AO33: 0 | AP33: 0 | AQ33: 0 | AR33: 134 | AS33: 0 | AT33: 0 | AU33: 164 | AV33: =SUM(AR33:AU33) | AW33: 0 | AX33: 0 | AY33: 0 | AZ33: 0 | BA33: =SUM(AW33:AZ33) | BB33: 0 | BC33: 0 | BD33: 0 | BE33: 66 | BF33: =SUM(BB33:BE33) | BG33: 0 | BH33: 0 | BI33: 0 | BJ33: 0 | BK33: =SUM(BG33:BJ33) | BL33: 0 | BM33: 0 | BN33: 0 | BO33: 0 | BP33: =SUM(BL33:BO33) | BQ33: 18 | BR33: 900 | BS33: 0 | BT33: 0 | BU33: =SUM(BQ33:BT33) | BV33: 0 | BW33: 0 | BX33: 0 | BY33: 15 | BZ33: =SUM(BV33:BY33) | CA33: 0 | CB33: 353 | CD33: 9 | CE33: =SUM(CA33:CD33) | CF33: 37 | CG33: 87 | CH33: 115 | CI33: 320 | CJ33: =+SUM(CF33:CI33) | CK33: 807 | CL33: 0 | CM33: 0 | CN33: 0 | CO33: =+SUM(CK33:CN33) | CP33: 0 | CQ33: 0 | CR33: 0 | CS33: 0 | CT33: 0 | CU33: 0 | CV33: 0 | CW33: 0 | CX33: 0 | CY33: 0 | CZ33: 0 | DA33: 0 | DB33: 0 | DC33: 0 | DD33: 0 | DE33: 0 | DF33: 0 | DG33: 0 | DH33: 0 | DI33: 0 | DJ33: 0 | DK33: 0 | DL33: 0 | DM33: 0 | DN33: 0 | DO33: 0 | DP33: 0 | DQ33: 0 | DR33: 0 | DS33: =SUM(DO33:DR33) | DT33: 0 | DU33: 0 | DV33: 0 | DW33: 0 | DX33: 0 | DY33: 0 | DZ33: 0 | EA33: 0 | EB33: 0 | EC33: 0 | ED33: 0 | EE33: 0 | EF33: 0 | EG33: 0 | EH33: 0 | EI33: 0 | EJ33: 0 | EK33: 0 | EL33: 0 | EM33: 0 | EN33: 0 | EO33: 0 | EP33: 0 | EQ33: 0 | ER33: 0 | ES33: 0 | ET33: 0 | EU33: 0 | EV33: 0 | EW33: 0 | EX33: 0 | EY33: 0 | EZ33: 0 | FA33: 0 | FB33: 0 | FC33: 0 | FD33: 0 | FE33: 0 | FF33: 0 | FG33: 0 | FH33: 0 | FI33: 0 | FJ33: 0 | FK33: 0 | FL33: 0 | FM33: 0 | FN33: 0 | FO33: 0 | FP33: 0 | FQ33: 0 | FR33: 0 | FS33: 0 | FT33: 0 | FU33: 0 | FV33: 0 | FW33: 0 | FX33: 0 | FY33: 0 | FZ33: 0 | GA33: 0 | GB33: 0 | GC33: =SUM(FY33:GB33) | GD33: 0 | GE33: 0 | GF33: 0 | GG33: 0 | GH33: 0 | GI33: 0 | GJ33: 0 | GK33: 0 | GL33: 0 | GM33: 0
