Workbook
Name _________________________2003Q4_T10: #REF!
Name _________________________TOP10: #REF!
Name ________________________2003Q4_T10: #REF!
Name ________________________TOP10: #REF!
Name _______________________2003Q4_T10: #REF!
Name _______________________TOP10: #REF!
Name ______________________2003Q4_T10: #REF!
Name ______________________TOP10: #REF!
Name _____________________2003Q4_T10: #REF!
Name _____________________TOP10: #REF!
Name ____________________2003Q4_T10: #REF!
Name ____________________TOP10: #REF!
Name ___________________2003Q4_T10: #REF!
Name ___________________TOP10: #REF!
Name __________________2003Q4_T10: #REF!
Name __________________TOP10: #REF!
Name _________________2003Q4_T10: #REF!
Name _________________TOP10: #REF!
Name ________________2003Q4_T10: #REF!
Name ________________TOP10: #REF!
Name _______________2003Q4_T10: #REF!
Name _______________TOP10: #REF!
Name ______________2003Q4_T10: #REF!
Name ______________TOP10: #REF!
Name _____________2003Q4_T10: #REF!
Name _____________TOP10: #REF!
Name ____________2003Q4_T10: #REF!
Name ____________TOP10: #REF!
Name ___________2003Q4_T10: #REF!
Name ___________TOP10: #REF!
Name __________2003Q4_T10: #REF!
Name __________TOP10: #REF!
Name _________2003Q4_T10: #REF!
Name _________TOP10: #REF!
Name ________2003Q4_T10: #REF!
Name ________TOP10: #REF!
Name _______2003Q4_T10: #REF!
Name _______CSC2: #REF!
Name _______DAT1: #REF!
Name _______DAT2: #REF!
Name _______DAT3: #REF!
Name _______DAT4: #REF!
Name _______DAT5: #REF!
Name _______DAT6: #REF!
Name _______DAT7: #REF!
Name _______DAT8: #REF!
Name _______DCF2: #REF!
Name _______eps1998: #REF!
Name _______eps1999: #REF!
Name _______eps2000: #REF!
Name _______eps2001: #REF!
Name _______EPS94: #REF!
Name _______EPS95: #REF!
Name _______EPS96: #REF!
Name _______EPS97: #REF!
Name _______EPS98: #REF!
Name _______rev1997: #REF!
Name _______rev1998: #REF!
Name _______rev1999: #REF!
Name _______rev2000: #REF!

Sheet Cover
E8: Company1953 (Ticker0027)
E9: Semiconductors
E10: Last updated: 10/06/25
F16: Analyst 1
F17: person@example.com
F18: 212-902-1000
F20: Analyst 2
F21: person@example.com
F22: 212-902-1000
F24: Analyst 3
F25: person@example.com
F27: Analyst 4
F28: person@example.com
F30: Analyst 5
F31: person@example.com
... F34: person@example.com

Sheet Worksheet
BV1: ="FY"&BZ3 | BW1: ="FY"&CA3 | BX1: ="FY"&CB3 | BY1: ="FY"&CC3 | BZ1: ="FY"&CD3 | CA1: FY2Q21 | CB1: FY3Q21 | CC1: FY4Q21 | CD1: FY1Q22 | CE1: FY2Q22 | CF1: FY3Q22 | CG1: FY4Q22 | CH1: FY1Q23 | CI1: FY2Q23 | CJ1: FY3Q23 | CK1: FY4Q23 | CL1: FY1Q24 | CM1: FY2Q24 | CN1: FY3Q24 | CO1: FY4Q24 | CP1: FY1Q25 | CQ1: FY2Q25 | CR1: FY3Q25 | CS1: FY4Q25 | CT1: FY1Q26 | CU1: FY2Q26 | CV1: FY3Q26E | CW1: FY4Q26E | CX1: FY1Q27E | CY1: FY2Q27E | CZ1: FY3Q27E | DA1: FY4Q27E | DB1: FY1Q28E | DC1: FY2Q28E | DD1: FY3Q28E | DE1: FY4Q28E | DU1: FY15 | DV1: FY16 | DW1: FY17 | DX1: FY18 | DY1: FY19 | DZ1: FY20 | EA1: FY21 | EB1: FY22 | EC1: FY23 | ED1: FY24 | EE1: FY25 | EF1: FY26E | EG1: FY27E | EH1: FY28E
AE2: =SUM(AB5:AE5) | AF2: =SUM(AC5:AF5) | AG2: =SUM(AD5:AG5) | AH2: =SUM(AE5:AH5) | AI2: =SUM(AF5:AI5) | AJ2: =SUM(AG5:AJ5) | AK2: =SUM(AH5:AK5) | AL2: =SUM(AI5:AL5) | BZ2: Company1719
B3: 1Q01 | C3: 2Q01 | D3: 3Q01 | E3: 4Q01 | F3: 1Q02 | G3: 2Q02 | H3: 3Q02 | I3: 4Q02 | J3: 1Q03 | K3: 2Q03 | L3: 3Q03 | M3: 4Q03 | N3: 1Q04 | O3: 2Q04 | P3: 3Q04 | Q3: 4Q04 | R3: 1Q05 | S3: 2Q05 | T3: 3Q05 | U3: 4Q05 | V3: 1Q06 | W3: 2Q06 | X3: 3Q06 | Y3: 4Q06 | Z3: 1Q07 | AA3: 2Q07 | AB3: 3Q07 | AC3: 4Q07 | AD3: 1Q08 | AE3: 2Q08 | AF3: 3Q08 | AG3: 4Q08 | AH3: 1Q09 | AI3: 2Q09 | AJ3: 3Q09 | AK3: 4Q09 | AL3: 1Q10 | AM3: 2Q10 | AN3: 3Q10 | AO3: 4Q10 | AP3: 1Q11 | AQ3: 2Q11 | AR3: 3Q11 | AS3: 4Q11 | AT3: 1Q12 | AU3: 2Q12 | AV3: 3Q12 | AW3: 4Q12 | AX3: 1Q13 | AY3: 2Q13 | AZ3: 3Q13 | BA3: 4Q13 | BB3: 1Q14 | BC3: 2Q14 | BD3: 3Q14 | BE3: 4Q14 | BF3: 1Q15 | BG3: 2Q15 | BH3: 3Q15 | BI3: 4Q15 | BJ3: 1Q16 | BK3: 2Q16 | BL3: 3Q16 | BM3: 4Q16 | BN3: 1Q17 | BO3: 2Q17 | BP3: 3Q17 | BQ3: 4Q17 | BR3: 1Q18 | BS3: 2Q18 | BT3: 3Q18 | BU3: 4Q18 | BV3: 1Q19 | BW3: 2Q19 | BX3: 3Q19 | BY3: 4Q19 | BZ3: 1Q20 | CA3: 2Q20 | CB3: 3Q20 | CC3: 4Q20 | CD3: 1Q21 | CE3: 2Q21 | CF3: 3Q21 | CG3: 4Q21 | CH3: 1Q22 | CI3: 2Q22 | CJ3: 3Q22 | CK3: 4Q22 | CL3: 1Q23 | CM3: 2Q23 | CN3: 3Q23 | CO3: 4Q23 | CP3: 1Q24 | CQ3: 2Q24 | CR3: 3Q24 | CS3: 4Q24 | CT3: 1Q25 | CU3: 2Q25 | CV3: 3Q25E | CW3: 4Q25E | CX3: 1Q26E | CY3: 2Q26E | CZ3: 3Q26E | DA3: 4Q26E | DB3: 1Q27E | DC3: 2Q27E | DD3: 3Q27E | DE3: 4Q27E | DH3: Calendar year
A4: Ticker0027 | B4: 37010 | C4: 37101 | D4: 37192 | E4: 37283 | F4: 37374 | G4: 37465 | H4: 37556 | I4: 37647 | J4: 37741 | K4: 37833 | L4: 37925 | M4: 38017 | N4: 38102 | O4: 38199 | P4: 38291 | Q4: 38383 | R4: 38443 | S4: 38564 | T4: 38656 | U4: 38748 | V4: 38837 | W4: 38928 | X4: 39019 | Y4: 39113 | Z4: 39201 | AA4: 39294 | AB4: 39386 | AC4: 39478 | AD4: 4/31/2008 | AE4: 39660 | AF4: 39752 | AG4: 39844 | AH4: 4/31/2009 | AI4: 40025 | AJ4: 40117 | AK4: 40209 | AL4: 4/31/2010 | AM4: 40390 | AN4: 40482 | AO4: 40574 | AP4: 4/31/2011 | AQ4: 40755 | AR4: 40847 | AS4: 40939 | AT4: 4/31/2012 | AU4: 41121 | AV4: 41213 | AW4: 41305 | AX4: 4/31/2013 | AY4: 41486 | AZ4: 41578 | BA4: 41670 | BB4: 4/31/14 | BC4: 41851 | BD4: 41943 | BE4: 42035 | BF4: 4/31/15 | BG4: 42216 | BH4: 42308 | BI4: 42400 | BJ4: 4/31/16 | BK4: 42582 | BL4: 42674 | BM4: 42766 | BN4: 4/31/2017 | BO4: 42947 | BP4: 43039 | BQ4: 43131 | BR4: 4/31/18 | BS4: 43312 | BT4: 43404 | BU4: 43496 | BV4: 4/31/19 | BW4: 43677 | BX4: 43769 | BY4: 43861 | BZ4: 4/31/20 | CA4: 44043 | CB4: 44135 | CC4: 44227 | CD4: 4/31/21 | CE4: 44408 | CF4: 44500 | CG4: 44592 | CH4: 4/31/22 | CI4: 44773 | CJ4: 44865 | CK4: 44957 | CL4: 4/31/23 | CM4: 45138 | CN4: 45230 | CO4: 45322 | CP4: 4/31/24 | CQ4: 45504 | CR4: 45596 | CS4: 45688 | CT4: 4/31/25 | CU4: 45869 | CV4: 45961 | CW4: 46053 | CX4: 4/31/26 | CY4: 46234 | CZ4: 46326 | DA4: 46418 | DB4: 4/31/26 | DC4: 46234 | DD4: 46326 | DE4: 46418 | DH4: 2001 | DI4: 2002 | DJ4: 2003 | DK4: 2004 | DL4: 2005 | DM4: 2006 | DN4: 2007 | DO4: 2008 | DP4: 2009 | DQ4: 2010 | DR4: 2011 | DS4: 2012 | DT4: 2013 | DU4: 2014 | DV4: 2015 | DW4: 2016 | DX4: 2017 | DY4: 2018 | DZ4: 2019 | EA4: 2020 | EB4: 2021 | EC4: 2022 | ED4: 2023 | EE4: 2024 | EF4: 2025E | EG4: 2026E | EH4: 2027E
A5: Revenue | B5: =Ticker0027!V7 | C5: =Ticker0027!W7 | D5: =Ticker0027!X7 | E5: =Ticker0027!Y7 | F5: =Ticker0027!AA7 | G5: =Ticker0027!AB7 | H5: =Ticker0027!AC7 | I5: =Ticker0027!AD7 | J5: =Ticker0027!AF7 | K5: =Ticker0027!AG7 | L5: =Ticker0027!AH7 | M5: =Ticker0027!AI7 | N5: =Ticker0027!AK7 | O5: =Ticker0027!AL7 | P5: =Ticker0027!AM7 | Q5: =Ticker0027!AN7 | R5: =Ticker0027!AP7 | S5: =Ticker0027!AQ7 | T5: =Ticker0027!AR7 | U5: =Ticker0027!AS7 | V5: =Ticker0027!AU7 | W5: =Ticker0027!AV7 | X5: =Ticker0027!AW7 | Y5: =Ticker0027!AX7 | Z5: =Ticker0027!AZ7 | AA5: =Ticker0027!BA7 | AB5: =Ticker0027!BB7 | AC5: =Ticker0027!BC7 | AD5: =Ticker0027!BE7 | AE5: =Ticker0027!BF7 | AF5: =Ticker0027!BG7 | AG5: =Ticker0027!BH7 | AH5: =Ticker0027!BJ7 | AI5: =Ticker0027!BK7 | AJ5: =Ticker0027!BL7 | AK5: =Ticker0027!BM7 | AL5: =Ticker0027!BO7 | AM5: =Ticker0027!BP7 | AN5: =Ticker0027!BQ7 | AO5: =Ticker0027!BR7 | AP5: =Ticker0027!BT7 | AQ5: =Ticker0027!BU7 | AR5: =Ticker0027!BV7 | AS5: =Ticker0027!BW7 | AT5: =Ticker0027!BY7 | AU5: =Ticker0027!BZ7 | AV5: =Ticker0027!CA7 | AW5: =Ticker0027!CB7 | AX5: =Ticker0027!CD7 | AY5: =Ticker0027!CE7 | AZ5: =Ticker0027!CF7 | BA5: =Ticker0027!CG7 | BB5: =Ticker0027!CI7 | BC5: =Ticker0027!CJ7 | BD5: =Ticker0027!CK7 | BE5: =Ticker0027!CL7 | BF5: =Ticker0027!CN7 | BG5: =Ticker0027!CO7 | BH5: =Ticker0027!CP7 | BI5: =Ticker0027!CQ7 | BJ5: =Ticker0027!CS7 | BK5: =Ticker0027!CT7 | BL5: =Ticker0027!CU7 | BM5: =Ticker0027!CV7 | BN5: =Ticker0027!CX7 | BO5: =Ticker0027!CY7 | BP5: =Ticker0027!CZ7 | BQ5: =Ticker0027!DA7 | BR5: =Ticker0027!DC7 | BS5: =Ticker0027!DD7 | BT5: =Ticker0027!DE7 | BU5: =Ticker0027!DF7 | BV5: =Ticker0027!DH7 | BW5: =Ticker0027!DI7 | BX5: =Ticker0027!DJ7 | BY5: =Ticker0027!DK7 | BZ5: =Ticker0027!DM7 | CA5: =Ticker0027!DN7 | CB5: =Ticker0027!DO7 | CC5: =Ticker0027!DP7 | CD5: =Ticker0027!DR7 | CE5: =Ticker0027!DS7 | CF5: =Ticker0027!DT7 | CG5: =Ticker0027!DU7 | CH5: =Ticker0027!DW7 | CI5: =Ticker0027!DX7 | CJ5: =Ticker0027!DY7 | CK5: =Ticker0027!DZ7 | CL5: =Ticker0027!EB7 | CM5: =Ticker0027!EC7 | CN5: =Ticker0027!ED7 | CO5: =Ticker0027!EE7 | CP5: =Ticker0027!EG7 | CQ5: =Ticker0027!EH7 | CR5: =Ticker0027!EI7 | CS5: =Ticker0027!EJ7 | CT5: =Ticker0027!EL7 | CU5: =Ticker0027!EM7 | CV5: =CV131 | CW5: =CW131 | CX5: =CX131 | CY5: =CY131 | CZ5: =CZ131 | DA5: =DA131 | DB5: =DB131 | DC5: =DC131 | ... DE5: =DE131 | DH5: =SUM(B5:E5) | DI5: =SUM(F5:I5) | DJ5: =SUM(J5:M5) | DK5: =SUM(N5:Q5) | DL5: =SUM(R5:U5) | DM5: =SUM(V5:Y5) | DN5: =SUM(Z5:AC5) | DO5: =SUM(AD5:AG5) | DP5: =SUM(AH5:AK5) | DQ5: =SUM(AL5:AO5) | DR5: =SUM(AP5:AS5) | DS5: =SUM(AT5:AW5) | DT5: =SUM(AX5:BA5) | DU5: =SUM(BB5:BE5) | DV5: =SUM(BF5:BI5) | DW5: =SUM(BJ5:BM5) | DX5: =SUM(BN5:BQ5) | DY5: =SUM(BR5:BU5) | DZ5: =BV5+BW5+BX5+BY5 | EA5: =CC5+CB5+CA5+BZ5 | EB5: =+CD5+CE5+CF5+CG5 | EC5: =SUM(CH5:CK5) | ED5: =SUM(CL5:CO5) | EE5: =SUM(CP5:CS5) | EF5: =SUM(CT5:CW5) | EG5: =SUM(CX5:DA5) | EH5: =SUM(DB5:DE5)
A6: qoq | C6: =C5/B5-1 | D6: =D5/C5-1 | E6: =E5/D5-1 | F6: =F5/E5-1 | G6: =G5/F5-1 | H6: =H5/G5-1 | I6: =I5/H5-1 | J6: =J5/I5-1 | ... DE6: =DE5/DD5-1 | DH6: -- | DI6: -- | DJ6: -- | DK6: -- | DL6: -- | DM6: -- | DN6: -- | DO6: -- | DP6: -- | DQ6: -- | DR6: -- | DS6: -- | DT6: -- | DU6: -- | DV6: -- | DW6: -- | DX6: -- | DY6: -- | DZ6: -- | EA6: -- | EB6: -- | EC6: -- | ED6: -- | EE6: -- | EF6: -- | EG6: -- | EH6: --
A7: yoy | F7: =F5/B5-1 | G7: =G5/C5-1 | H7: =H5/D5-1 | I7: =I5/E5-1 | J7: =J5/F5-1 | K7: =K5/G5-1 | L7: =L5/H5-1 | M7: =M5/I5-1 | ... DE7: =DE5/DA5-1 | DI7: =DI5/DH5-1 | DJ7: =DJ5/DI5-1 | DK7: =DK5/DJ5-1 | DL7: =DL5/DK5-1 | DM7: =DM5/DL5-1 | DN7: =DN5/DM5-1 | DO7: =DO5/DN5-1 | DP7: =DP5/DO5-1 | ... EH7: =EH5/EG5-1
A8: COGS (incl D&A) | B8: =Ticker0027!V10 | C8: =Ticker0027!W10 | D8: =Ticker0027!X10 | E8: =Ticker0027!Y10 | F8: =Ticker0027!AA10 | G8: =Ticker0027!AB10 | H8: =Ticker0027!AC10 | I8: =Ticker0027!AD10 | J8: =Ticker0027!AF10 | K8: =Ticker0027!AG10 | L8: =Ticker0027!AH10 | M8: =Ticker0027!AI10 | N8: =Ticker0027!AK10 | O8: =Ticker0027!AL10 | P8: =Ticker0027!AM10 | Q8: =Ticker0027!AN10 | R8: =Ticker0027!AP10 | S8: =Ticker0027!AQ10 | T8: =Ticker0027!AR10 | U8: =Ticker0027!AS10 | V8: =Ticker0027!AU10 | W8: =Ticker0027!AV10 | X8: =Ticker0027!AW10 | Y8: =Ticker0027!AX10 | Z8: =Ticker0027!AZ10 | AA8: =Ticker0027!BA10 | AB8: =Ticker0027!BB10 | AC8: =Ticker0027!BC10 | AD8: =Ticker0027!BE10 | AE8: =Ticker0027!BF10 | AF8: =Ticker0027!BG10 | AG8: =Ticker0027!BH10 | AH8: =Ticker0027!BJ10 | AI8: =Ticker0027!BK10 | AJ8: =Ticker0027!BL10 | AK8: =Ticker0027!BM10 | AL8: =Ticker0027!BO10 | AM8: =Ticker0027!BP10 | AN8: =Ticker0027!BQ10 | AO8: =Ticker0027!BR10 | AP8: =Ticker0027!BT10 | AQ8: =Ticker0027!BU10 | AR8: =Ticker0027!BV10 | AS8: =Ticker0027!BW10 | AT8: =Ticker0027!BY10 | AU8: =Ticker0027!BZ10 | AV8: =Ticker0027!CA10 | AW8: =Ticker0027!CB10 | AX8: =Ticker0027!CD10 | AY8: =Ticker0027!CE10 | AZ8: =Ticker0027!CF10 | BA8: =Ticker0027!CG10 | BB8: =Ticker0027!CI10 | BC8: =Ticker0027!CJ10 | BD8: =Ticker0027!CK10 | BE8: =Ticker0027!CL10 | BF8: =Ticker0027!CN10 | BG8: =Ticker0027!CO10 | BH8: =Ticker0027!CP10 | BI8: =Ticker0027!CQ10 | BJ8: =Ticker0027!CS10 | BK8: =Ticker0027!CT10 | BL8: =Ticker0027!CU10 | BM8: =Ticker0027!CV10 | BN8: =Ticker0027!CX10 | BO8: =Ticker0027!CY10 | BP8: =Ticker0027!CZ10 | BQ8: =Ticker0027!DA10 | BR8: =Ticker0027!DC10 | BS8: =Ticker0027!DD10 | BT8: =Ticker0027!DE10 | BU8: =Ticker0027!DF10 | BV8: =Ticker0027!DH10 | BW8: =Ticker0027!DI10 | BX8: =Ticker0027!DJ10 | BY8: =Ticker0027!DK10 | BZ8: =Ticker0027!DM10 | CA8: =Ticker0027!DN10 | CB8: =Ticker0027!DO10 | CC8: =Ticker0027!DP10 | CD8: =Ticker0027!DR10 | CE8: =Ticker0027!DS10 | CF8: =Ticker0027!DT10 | CG8: =Ticker0027!DU10 | CH8: =Ticker0027!DW10 | CI8: =Ticker0027!DX10 | CJ8: =Ticker0027!DY10 | CK8: =Ticker0027!DZ10 | CL8: =Ticker0027!EB10 | CM8: =Ticker0027!EC10 | CN8: =Ticker0027!ED10 | CO8: =Ticker0027!EE10 | CP8: =Ticker0027!EG10 | CQ8: =Ticker0027!EH10 | CR8: =Ticker0027!EI10 | CS8: =Ticker0027!EJ10 | CT8: =Ticker0027!EL10 | CU8: =Ticker0027!EM10 | CV8: =CV5-CV15 | CW8: =CW5-CW15 | CX8: =CX5-CX15 | CY8: =CY5-CY15 | CZ8: =CZ5-CZ15 | DA8: =DA5-DA15 | DB8: =DB5-DB15 | DC8: =DC5-DC15 | ... DE8: =DE5-DE15 | DH8: =SUM(B8:E8) | DI8: =SUM(F8:I8) | DJ8: =SUM(J8:M8) | DK8: =SUM(N8:Q8) | DL8: =SUM(R8:U8) | DM8: =SUM(V8:Y8) | DN8: =SUM(Z8:AC8) | DO8: =SUM(AD8:AG8) | DP8: =SUM(AH8:AK8) | DQ8: =SUM(AL8:AO8) | DR8: =SUM(AP8:AS8) | DS8: =SUM(AT8:AW8) | DT8: =SUM(AX8:BA8) | DU8: =SUM(BB8:BE8) | DV8: =SUM(BF8:BI8) | DW8: =SUM(BJ8:BM8) | DX8: =SUM(BN8:BQ8) | DY8: =SUM(BR8:BU8) | DZ8: =BV8+BW8+BX8+BY8 | EA8: =CC8+CB8+CA8+BZ8 | EB8: =+CD8+CE8+CF8+CG8 | EC8: =SUM(CH8:CK8) | ED8: =SUM(CL8:CO8) | EE8: =SUM(CP8:CS8) | EF8: =SUM(CT8:CW8) | EG8: =SUM(CX8:DA8) | EH8: =SUM(DB8:DE8)
A9: qoq | C9: =C8/B8-1 | D9: =D8/C8-1 | E9: =E8/D8-1 | F9: =F8/E8-1 | G9: =G8/F8-1 | H9: =H8/G8-1 | I9: =I8/H8-1 | J9: =J8/I8-1 | ... DE9: =DE8/DD8-1 | DH9: -- | DI9: -- | DJ9: -- | DK9: -- | DL9: -- | DM9: -- | DN9: -- | DO9: -- | DP9: -- | DQ9: -- | DR9: -- | DS9: -- | DT9: -- | DU9: -- | DV9: -- | DW9: -- | DX9: -- | DY9: -- | DZ9: -- | EA9: -- | EB9: -- | EC9: -- | ED9: -- | EE9: -- | EF9: -- | EG9: -- | EH9: --
A10: yoy | F10: =F8/B8-1 | G10: =G8/C8-1 | H10: =H8/D8-1 | I10: =I8/E8-1 | J10: =J8/F8-1 | K10: =K8/G8-1 | L10: =L8/H8-1 | M10: =M8/I8-1 | ... DE10: =DE8/DA8-1 | DI10: =DI8/DH8-1 | DJ10: =DJ8/DI8-1 | DK10: =DK8/DJ8-1 | DL10: =DL8/DK8-1 | DM10: =DM8/DL8-1 | DN10: =DN8/DM8-1 | DO10: =DO8/DN8-1 | DP10: =DP8/DO8-1 | ... EH10: =EH8/EG8-1
A11: Depreciation | B11: =Ticker0027!V11 | C11: =Ticker0027!W11 | D11: =Ticker0027!X11 | E11: =Ticker0027!Y11 | F11: =Ticker0027!AA11 | G11: =Ticker0027!AB11 | H11: =Ticker0027!AC11 | I11: =Ticker0027!AD11 | J11: =Ticker0027!AF11 | K11: =Ticker0027!AG11 | L11: =Ticker0027!AH11 | M11: =Ticker0027!AI11 | N11: =Ticker0027!AK11 | O11: =Ticker0027!AL11 | P11: =Ticker0027!AM11 | Q11: =Ticker0027!AN11 | R11: =Ticker0027!AP11 | S11: =Ticker0027!AQ11 | T11: =Ticker0027!AR11 | U11: =Ticker0027!AS11 | V11: =Ticker0027!AU11 | W11: =Ticker0027!AV11 | X11: =Ticker0027!AW11 | Y11: =Ticker0027!AX11 | Z11: =Ticker0027!AZ11 | AA11: =Ticker0027!BA11 | AB11: =Ticker0027!BB11 | AC11: =Ticker0027!BC11 | AD11: =Ticker0027!BE11 | AE11: =Ticker0027!BF11 | AF11: =Ticker0027!BG11 | AG11: =Ticker0027!BH11 | AH11: =Ticker0027!BJ11 | AI11: =Ticker0027!BK11 | AJ11: =Ticker0027!BL11 | AK11: =Ticker0027!BM11 | AL11: =Ticker0027!BO11 | AM11: =Ticker0027!BP11 | AN11: =Ticker0027!BQ11 | AO11: =Ticker0027!BR11 | AP11: =Ticker0027!BT11 | AQ11: =Ticker0027!BU11 | AR11: =Ticker0027!BV11 | AS11: =Ticker0027!BW11 | AT11: =Ticker0027!BY11 | AU11: =Ticker0027!BZ11 | AV11: =Ticker0027!CA11 | AW11: =Ticker0027!CB11 | AX11: =Ticker0027!CD11 | AY11: =Ticker0027!CE11 | AZ11: =Ticker0027!CF11 | BA11: =Ticker0027!CG11 | BB11: =Ticker0027!CI11 | BC11: =Ticker0027!CJ11 | BD11: =Ticker0027!CK11 | BE11: =Ticker0027!CL11 | BF11: =Ticker0027!CN11 | BG11: =Ticker0027!CO11 | BH11: =Ticker0027!CP11 | BI11: =Ticker0027!CQ11 | BJ11: =Ticker0027!CS11 | BK11: =Ticker0027!CT11 | BL11: =Ticker0027!CU11 | BM11: =Ticker0027!CV11 | BN11: =Ticker0027!CX11 | BO11: =Ticker0027!CY11 | BP11: =Ticker0027!CZ11 | BQ11: =Ticker0027!DA11 | BR11: =Ticker0027!DC11 | BS11: =Ticker0027!DD11 | BT11: =Ticker0027!DE11 | BU11: =Ticker0027!DF11 | BV11: =Ticker0027!DH11 | BW11: =Ticker0027!DI11 | BX11: =Ticker0027!DJ11 | BY11: =Ticker0027!DK11 | BZ11: =Ticker0027!DM11 | CA11: =Ticker0027!DN11 | CB11: =Ticker0027!DO11 | CC11: =Ticker0027!DP11 | CD11: =Ticker0027!DR11 | CE11: =Ticker0027!DS11 | CF11: =Ticker0027!DT11 | CG11: =Ticker0027!DU11 | CH11: =Ticker0027!DW11 | CI11: =Ticker0027!DX11 | CJ11: =Ticker0027!DY11 | CK11: =Ticker0027!DZ11 | CL11: =Ticker0027!EB11 | CM11: =Ticker0027!EC11 | CN11: =Ticker0027!ED11 | CO11: =Ticker0027!EE11 | CP11: =Ticker0027!EG11 | CQ11: =Ticker0027!EH11 | CR11: =Ticker0027!EI11 | CS11: =Ticker0027!EJ11 | CT11: =Ticker0027!EL11 | CU11: =Ticker0027!EM11 | CV11: =+CU11+5 | CW11: =+CV11+5 | CX11: =+CW11+5 | CY11: =+CX11+5 | CZ11: =+CY11+5 | DA11: =+CZ11+5 | DB11: =+DA11+5 | DC11: =+DB11+5 | ... DE11: =+DD11+5 | DH11: =SUM(B11:E11) | DI11: =SUM(F11:I11) | DJ11: =SUM(J11:M11) | DK11: =SUM(N11:Q11) | DL11: =SUM(R11:U11) | DM11: =SUM(V11:Y11) | DN11: =SUM(Z11:AC11) | DO11: =SUM(AD11:AG11) | DP11: =SUM(AH11:AK11) | DQ11: =SUM(AL11:AO11) | DR11: =SUM(AP11:AS11) | DS11: =SUM(AT11:AW11) | DT11: =SUM(AX11:BA11) | DU11: =SUM(BB11:BE11) | DV11: =SUM(BF11:BI11) | DW11: =SUM(BJ11:BM11) | DX11: =SUM(BN11:BQ11) | DY11: =SUM(BR11:BU11) | DZ11: =BV11+BW11+BX11+BY11 | EA11: =CC11+CB11+CA11+BZ11 | EB11: =+CD11+CE11+CF11+CG11 | EC11: =SUM(CH11:CK11) | ED11: =SUM(CL11:CO11) | EE11: =SUM(CP11:CS11) | EF11: =SUM(CT11:CW11) | EG11: =SUM(CX11:DA11) | EH11: =SUM(DB11:DE11)
A12: qoq | C12: =C11/B11-1 | D12: =D11/C11-1 | E12: =E11/D11-1 | F12: =F11/E11-1 | G12: =G11/F11-1 | H12: =H11/G11-1 | I12: =I11/H11-1 | J12: =J11/I11-1 | ... DE12: =DE11/DD11-1 | DY12: -- | DZ12: -- | EA12: -- | EB12: -- | EC12: -- | ED12: -- | EE12: -- | EF12: -- | EG12: -- | EH12: --
A13: yoy | F13: =F11/B11-1 | G13: =G11/C11-1 | H13: =H11/D11-1 | I13: =I11/E11-1 | J13: =J11/F11-1 | K13: =K11/G11-1 | L13: =L11/H11-1 | M13: =M11/I11-1 | ... DE13: =DE11/DA11-1 | DI13: =DI11/DH11-1 | DJ13: =DJ11/DI11-1 | DK13: =DK11/DJ11-1 | DL13: =DL11/DK11-1 | DM13: =DM11/DL11-1 | DN13: =DN11/DM11-1 | DO13: =DO11/DN11-1 | DP13: =DP11/DO11-1 | ... EH13: =EH11/EG11-1
A14: as a % of revenue | B14: =B11/B$5 | C14: =C11/C$5 | D14: =D11/D$5 | E14: =E11/E$5 | F14: =F11/F$5 | G14: =G11/G$5 | H14: =H11/H$5 | I14: =I11/I$5 | ... DE14: =DE11/DE$5 | DH14: =DH11/DH$5 | DI14: =DI11/DI$5 | DJ14: =DJ11/DJ$5 | DK14: =DK11/DK$5 | DL14: =DL11/DL$5 | DM14: =DM11/DM$5 | DN14: =DN11/DN$5 | DO14: =DO11/DO$5 | ... EH14: =EH11/EH$5
A15: Gross profit | B15: =B5-B8-B11 | C15: =C5-C8-C11 | D15: =D5-D8-D11 | E15: =E5-E8-E11 | F15: =F5-F8-F11 | G15: =G5-G8-G11 | H15: =H5-H8-H11 | I15: =I5-I8-I11 | ... CU15: =CU5-CU8-CU11 | CV15: =CV174 | CW15: =CW174 | CX15: =CX174 | CY15: =CY174 | CZ15: =CZ174 | DA15: =DA174 | DB15: =DB174 | DC15: =DC174 | ... DE15: =DE174 | DH15: =SUM(B15:E15) | DI15: =SUM(F15:I15) | DJ15: =SUM(J15:M15) | DK15: =SUM(N15:Q15) | DL15: =SUM(R15:U15) | DM15: =SUM(V15:Y15) | DN15: =SUM(Z15:AC15) | DO15: =SUM(AD15:AG15) | DP15: =SUM(AH15:AK15) | DQ15: =SUM(AL15:AO15) | DR15: =SUM(AP15:AS15) | DS15: =SUM(AT15:AW15) | DT15: =SUM(AX15:BA15) | DU15: =SUM(BB15:BE15) | DV15: =SUM(BF15:BI15) | DW15: =SUM(BJ15:BM15) | DX15: =SUM(BN15:BQ15) | DY15: =SUM(BR15:BU15) | DZ15: =BV15+BW15+BX15+BY15 | EA15: =CC15+CB15+CA15+BZ15 | EB15: =+CD15+CE15+CF15+CG15 | EC15: =SUM(CH15:CK15) | ED15: =SUM(CL15:CO15) | EE15: =SUM(CP15:CS15) | EF15: =SUM(CT15:CW15) | EG15: =SUM(CX15:DA15) | EH15: =SUM(DB15:DE15)
A16: qoq | C16: =C15/B15-1 | D16: =D15/C15-1 | E16: =E15/D15-1 | F16: =F15/E15-1 | G16: =G15/F15-1 | H16: =H15/G15-1 | I16: =I15/H15-1 | J16: =J15/I15-1 | ... DE16: =DE15/DD15-1 | DH16: -- | DI16: -- | DJ16: -- | DK16: -- | DL16: -- | DM16: -- | DN16: -- | DO16: -- | DP16: -- | DQ16: -- | DR16: -- | DS16: -- | DT16: -- | DU16: -- | DV16: -- | DW16: -- | DX16: -- | DY16: -- | DZ16: -- | EA16: -- | EB16: -- | EC16: -- | ED16: -- | EE16: -- | EF16: -- | EG16: -- | EH16: --
A17: yoy | F17: =F15/B15-1 | G17: =G15/C15-1 | H17: =H15/D15-1 | I17: =I15/E15-1 | J17: =J15/F15-1 | K17: =K15/G15-1 | L17: =L15/H15-1 | M17: =M15/I15-1 | ... DE17: =DE15/DA15-1 | DI17: =DI15/DH15-1 | DJ17: =DJ15/DI15-1 | DK17: =DK15/DJ15-1 | DL17: =DL15/DK15-1 | DM17: =DM15/DL15-1 | DN17: =DN15/DM15-1 | DO17: =DO15/DN15-1 | DP17: =DP15/DO15-1 | ... EH17: =EH15/EG15-1
A18: as a % of revenue | B18: =B15/B$5 | C18: =C15/C$5 | D18: =D15/D$5 | E18: =E15/E$5 | F18: =F15/F$5 | G18: =G15/G$5 | H18: =H15/H$5 | I18: =I15/I$5 | ... DE18: =DE15/DE$5 | DH18: =DH15/DH$5 | DI18: =DI15/DI$5 | DJ18: =DJ15/DJ$5 | DK18: =DK15/DK$5 | DL18: =DL15/DL$5 | DM18: =DM15/DM$5 | DN18: =DN15/DN$5 | DO18: =DO15/DO$5 | ... EH18: =EH15/EH$5
A19: as a % of revenue (ex SBC) | AL19: =(AL15+AL20)/AL5 | AM19: =(AM15+AM20)/AM5 | AN19: =(AN15+AN20)/AN5 | AO19: =(AO15+AO20)/AO5 | AP19: =(AP15+AP20)/AP5 | AQ19: =(AQ15+AQ20)/AQ5 | AR19: =(AR15+AR20)/AR5 | AS19: =(AS15+AS20)/AS5 | ... DE19: =(DE15+DE20)/DE5 | DR19: =(DR15+DR20)/DR5 | DS19: =(DS15+DS20)/DS5 | DT19: =(DT15+DT20)/DT5 | DU19: =(DU15+DU20)/DU5 | DV19: =(DV15+DV20)/DV5 | DW19: =(DW15+DW20)/DW5 | DX19: =(DX15+DX20)/DX5 | DY19: =(DY15+DY20)/DY5 | ... EH19: =(EH15+EH20)/EH5
A20: SBC in GM | AL20: 1.803 | AM20: 2.289 | AN20: 2.49 | AO20: 1.726 | AP20: 2.477 | AQ20: 2.748 | AR20: 3.049 | AS20: 3.048 | AT20: 2.526 | AU20: 2.649 | AV20: 2.489 | AW20: 2.826 | AX20: 2.653 | AY20: 2.168 | AZ20: 3.09 | BA20: 2.777 | BB20: 2.919 | BC20: 3 | BD20: 4 | BE20: 4 | BF20: 2 | BG20: 3 | BH20: 4 | BI20: 5 | BJ20: 4 | BK20: 4 | BL20: 3 | BM20: 4 | BN20: 4 | BO20: 4 | BP20: 6 | BQ20: 7 | BR20: 8 | BS20: 8 | BT20: 5 | BU20: 6 | BV20: 4 | BW20: 8 | BX20: 15 | BY20: 12 | BZ20: 21 | CA20: 14 | CB20: 28 | CC20: 26 | CD20: 25 | CE20: 32 | CF20: 44 | CG20: 39 | CH20: 38 | CI20: 38 | CJ20: 32 | CK20: 30 | CL20: 27 | CM20: 31 | CN20: 38 | CO20: 45 | CP20: 36 | CQ20: 40 | CR20: 50 | CS20: 53 | CT20: 64 | CU20: 58 | CV20: =CU20+1 | CW20: =CV20+1 | CX20: =CW20+1 | CY20: =CX20+1 | CZ20: =CY20+1 | DA20: =CZ20+1 | DB20: =DA20+1 | DC20: =DB20+1 | ... DE20: =DD20+1 | DR20: =SUM(AP20:AS20) | DS20: =SUM(AT20:AW20) | DT20: =SUM(AX20:BA20) | DU20: =SUM(BB20:BE20) | DV20: =SUM(BF20:BI20) | DW20: =SUM(BJ20:BM20) | DX20: =SUM(BN20:BQ20) | DY20: =SUM(BR20:BU20) | DZ20: =BV20+BW20+BX20+BY20 | EA20: =CC20+CB20+CA20+BZ20 | EB20: =+CD20+CE20+CF20+CG20 | EC20: =SUM(CH20:CK20) | ED20: =SUM(CL20:CO20) | EE20: =SUM(CP20:CS20) | EF20: =SUM(CT20:CW20) | EG20: =SUM(CX20:DA20) | EH20: =SUM(DB20:DE20)
A21: Opex (incl SBC) | B21: =B30+B35 | C21: =C30+C35 | D21: =D30+D35 | E21: =E30+E35 | F21: =F30+F35 | G21: =G30+G35 | H21: =H30+H35 | I21: =I30+I35 | ... DE21: =DE30+DE35 | DH21: =SUM(B21:E21) | DI21: =SUM(F21:I21) | DJ21: =SUM(J21:M21) | DK21: =SUM(N21:Q21) | DL21: =SUM(R21:U21) | DM21: =SUM(V21:Y21) | DN21: =SUM(Z21:AC21) | DO21: =SUM(AD21:AG21) | DP21: =SUM(AH21:AK21) | DQ21: =SUM(AL21:AO21) | DR21: =SUM(AP21:AS21) | DS21: =SUM(AT21:AW21) | DT21: =SUM(AX21:BA21) | DU21: =SUM(BB21:BE21) | DV21: =SUM(BF21:BI21) | DW21: =SUM(BJ21:BM21) | DX21: =SUM(BN21:BQ21) | DY21: =SUM(BR21:BU21) | DZ21: =BV21+BW21+BX21+BY21 | EA21: =CC21+CB21+CA21+BZ21 | EB21: =+CD21+CE21+CF21+CG21 | EC21: =SUM(CH21:CK21) | ED21: =SUM(CL21:CO21) | EE21: =SUM(CP21:CS21) | EF21: =SUM(CT21:CW21) | EG21: =SUM(CX21:DA21) | EH21: =SUM(DB21:DE21)
A22: qoq | C22: =C21/B21-1 | D22: =D21/C21-1 | E22: =E21/D21-1 | F22: =F21/E21-1 | G22: =G21/F21-1 | H22: =H21/G21-1 | I22: =I21/H21-1 | J22: =J21/I21-1 | ... DE22: =DE21/DD21-1 | DH22: -- | DI22: -- | DJ22: -- | DK22: -- | DL22: -- | DM22: -- | DN22: -- | DO22: -- | DP22: -- | DQ22: -- | DR22: -- | DS22: -- | DT22: -- | DU22: -- | DV22: -- | DW22: -- | DX22: -- | DY22: -- | DZ22: -- | EA22: -- | EB22: -- | EC22: -- | ED22: -- | EE22: -- | EF22: -- | EG22: -- | EH22: --
A23: yoy | F23: =F21/B21-1 | G23: =G21/C21-1 | H23: =H21/D21-1 | I23: =I21/E21-1 | J23: =J21/F21-1 | K23: =K21/G21-1 | L23: =L21/H21-1 | M23: =M21/I21-1 | ... DE23: =DE21/DA21-1 | DI23: =DI21/DH21-1 | DJ23: =DJ21/DI21-1 | DK23: =DK21/DJ21-1 | DL23: =DL21/DK21-1 | DM23: =DM21/DL21-1 | DN23: =DN21/DM21-1 | DO23: =DO21/DN21-1 | DP23: =DP21/DO21-1 | ... EH23: =EH21/EG21-1
A24: as a % of revenue | B24: =B21/B$5 | C24: =C21/C$5 | D24: =D21/D$5 | E24: =E21/E$5 | F24: =F21/F$5 | G24: =G21/G$5 | H24: =H21/H$5 | I24: =I21/I$5 | ... DE24: =DE21/DE$5 | DH24: =DH21/DH$5 | DI24: =DI21/DI$5 | DJ24: =DJ21/DJ$5 | DK24: =DK21/DK$5 | DL24: =DL21/DL$5 | DM24: =DM21/DM$5 | DN24: =DN21/DN$5 | DO24: =DO21/DO$5 | ... EH24: =EH21/EH$5
A25: Opex (ex SBC) | AL25: =+AL21-AL29 | AM25: =+AM21-AM29 | AN25: =+AN21-AN29 | AO25: =+AO21-AO29 | AP25: =+AP21-AP29 | AQ25: =+AQ21-AQ29 | AR25: =+AR21-AR29 | AS25: =+AS21-AS29 | ... DE25: =+DE21-DE29 | DR25: =SUM(AP25:AS25) | DS25: =SUM(AT25:AW25) | DT25: =SUM(AX25:BA25) | DU25: =SUM(BB25:BE25) | DV25: =SUM(BF25:BI25) | DW25: =SUM(BJ25:BM25) | DX25: =SUM(BN25:BQ25) | DY25: =SUM(BR25:BU25) | DZ25: =BV25+BW25+BX25+BY25 | EA25: =CC25+CB25+CA25+BZ25 | EB25: =+CD25+CE25+CF25+CG25 | EC25: =SUM(CH25:CK25) | ED25: =SUM(CL25:CO25) | EE25: =SUM(CP25:CS25) | EF25: =SUM(CT25:CW25) | EG25: =SUM(CX25:DA25) | EH25: =SUM(DB25:DE25)
A26: qoq | AM26: =AM25/AL25-1 | AN26: =AN25/AM25-1 | AO26: =AO25/AN25-1 | AP26: =AP25/AO25-1 | AQ26: =AQ25/AP25-1 | AR26: =AR25/AQ25-1 | AS26: =AS25/AR25-1 | AT26: =AT25/AS25-1 | ... DE26: =DE25/DD25-1 | DH26: -- | DI26: -- | DJ26: -- | DK26: -- | DL26: -- | DM26: -- | DN26: -- | DO26: -- | DP26: -- | DQ26: -- | DR26: -- | DS26: -- | DT26: -- | DU26: -- | DV26: -- | DW26: -- | DX26: -- | DY26: -- | DZ26: -- | EA26: -- | EB26: -- | EC26: -- | ED26: -- | EE26: -- | EF26: -- | EG26: -- | EH26: --
A27: yoy | AP27: =AP25/AL25-1 | AQ27: =AQ25/AM25-1 | AR27: =AR25/AN25-1 | AS27: =AS25/AO25-1 | AT27: =AT25/AP25-1 | AU27: =AU25/AQ25-1 | AV27: =AV25/AR25-1 | AW27: =AW25/AS25-1 | ... DE27: =DE25/DA25-1 | DS27: =DS25/DR25-1 | DT27: =DT25/DS25-1 | DU27: =DU25/DT25-1 | DV27: =DV25/DU25-1 | DW27: =DW25/DV25-1 | DX27: =DX25/DW25-1 | DY27: =DY25/DX25-1 | DZ27: =DZ25/DY25-1 | ... EH27: =EH25/EG25-1
A28: as a % of revenue | AL28: =AL25/AL5 | AM28: =AM25/AM5 | AN28: =AN25/AN5 | AO28: =AO25/AO5 | AP28: =AP25/AP5 | AQ28: =AQ25/AQ5 | AR28: =AR25/AR5 | AS28: =AS25/AS5 | ... DE28: =DE25/DE5 | DR28: =DR25/DR5 | DS28: =DS25/DS5 | DT28: =DT25/DT5 | DU28: =DU25/DU5 | DV28: =DV25/DV5 | DW28: =DW25/DW5 | DX28: =DX25/DX5 | DY28: =DY25/DY5 | ... EH28: =EH25/EH5
A29: SBC in opex | AL29: =+AL34+AL39 | AM29: =+AM34+AM39 | AN29: =+AN34+AN39 | AO29: =+AO34+AO39 | AP29: =+AP34+AP39 | AQ29: =+AQ34+AQ39 | AR29: =+AR34+AR39 | AS29: =+AS34+AS39 | ... BZ29: =+BZ34+BZ39 | CA29: =132+228 | CB29: =+CB34+CB39 | CC29: =+CC34+CC39 | CD29: =+CD34+CD39 | CE29: =+CE34+CE39 | CF29: =+CF34+CF39 | CG29: =+CG34+CG39 | CH29: =+CH34+CH39 | CI29: =+CI34+CI39 | ... CU29: =+CU34+CU39 | CV29: =CU29*1.05 | CW29: =CV29*1.02 | CX29: =CW29*1.02 | CY29: =CX29*1.02 | CZ29: =CY29*1.02 | DA29: =CZ29*1.02 | DB29: =DA29*1.02 | DC29: =DB29*1.02 | DD29: =DC29*1.02 | DE29: =DD29*1.02 | DR29: =SUM(AP29:AS29) | DS29: =SUM(AT29:AW29) | DT29: =SUM(AX29:BA29) | DU29: =SUM(BB29:BE29) | DV29: =SUM(BF29:BI29) | DW29: =SUM(BJ29:BM29) | DX29: =SUM(BN29:BQ29) | DY29: =SUM(BR29:BU29) | DZ29: =BV29+BW29+BX29+BY29 | EA29: =CC29+CB29+CA29+BZ29 | EB29: =+CD29+CE29+CF29+CG29 | EC29: =SUM(CH29:CK29) | ED29: =SUM(CL29:CO29) | EE29: =SUM(CP29:CS29) | EF29: =SUM(CT29:CW29) | EG29: =SUM(CX29:DA29) | EH29: =SUM(DB29:DE29)
A30: R&D | B30: =Ticker0027!V19 | C30: =Ticker0027!W19 | D30: =Ticker0027!X19 | E30: =Ticker0027!Y19 | F30: =Ticker0027!AA19 | G30: =Ticker0027!AB19 | H30: =Ticker0027!AC19 | I30: =Ticker0027!AD19 | J30: =Ticker0027!AF19 | K30: =Ticker0027!AG19 | L30: =Ticker0027!AH19 | M30: =Ticker0027!AI19 | N30: =Ticker0027!AK19 | O30: =Ticker0027!AL19 | P30: =Ticker0027!AM19 | Q30: =Ticker0027!AN19 | R30: =Ticker0027!AP19 | S30: =Ticker0027!AQ19 | T30: =Ticker0027!AR19 | U30: =Ticker0027!AS19 | V30: =Ticker0027!AU19 | W30: =Ticker0027!AV19 | X30: =Ticker0027!AW19 | Y30: =Ticker0027!AX19 | Z30: =Ticker0027!AZ19 | AA30: =Ticker0027!BA19 | AB30: =Ticker0027!BB19 | AC30: =Ticker0027!BC19 | AD30: =Ticker0027!BE19 | AE30: =Ticker0027!BF19 | AF30: =Ticker0027!BG19 | AG30: =Ticker0027!BH19 | AH30: =Ticker0027!BJ19 | AI30: =Ticker0027!BK19 | AJ30: =Ticker0027!BL19 | AK30: =Ticker0027!BM19 | AL30: =Ticker0027!BO19 | AM30: =Ticker0027!BP19 | AN30: =Ticker0027!BQ19 | AO30: =Ticker0027!BR19 | AP30: =Ticker0027!BT19 | AQ30: =Ticker0027!BU19 | AR30: =Ticker0027!BV19 | AS30: =Ticker0027!BW19 | AT30: =Ticker0027!BY19 | AU30: =Ticker0027!BZ19 | AV30: =Ticker0027!CA19 | AW30: =Ticker0027!CB19 | AX30: =Ticker0027!CD19 | AY30: =Ticker0027!CE19 | AZ30: =Ticker0027!CF19 | BA30: =Ticker0027!CG19 | BB30: =Ticker0027!CI19 | BC30: =Ticker0027!CJ19 | BD30: =Ticker0027!CK19 | BE30: =Ticker0027!CL19 | BF30: =Ticker0027!CN19 | BG30: =Ticker0027!CO19 | BH30: =Ticker0027!CP19 | BI30: =Ticker0027!CQ19 | BJ30: =Ticker0027!CS19 | BK30: =Ticker0027!CT19 | BL30: =Ticker0027!CU19 | BM30: =Ticker0027!CV19 | BN30: =Ticker0027!CX19 | BO30: =Ticker0027!CY19 | BP30: =Ticker0027!CZ19 | BQ30: =Ticker0027!DA19 | BR30: =Ticker0027!DC19 | BS30: =Ticker0027!DD19 | BT30: =Ticker0027!DE19 | BU30: =Ticker0027!DF19 | BV30: =Ticker0027!DH19 | BW30: =Ticker0027!DI19 | BX30: =Ticker0027!DJ19 | BY30: =Ticker0027!DK19 | BZ30: =Ticker0027!DM19 | CA30: =Ticker0027!DN19 | CB30: =Ticker0027!DO19 | CC30: =Ticker0027!DP19 | CD30: =Ticker0027!DR19 | CE30: =Ticker0027!DS19 | CF30: =Ticker0027!DT19 | CG30: =Ticker0027!DU19 | CH30: =Ticker0027!DW19 | CI30: =Ticker0027!DX19 | CJ30: =Ticker0027!DY19 | CK30: =Ticker0027!DZ19 | CL30: =Ticker0027!EB19 | CM30: =Ticker0027!EC19 | CN30: =Ticker0027!ED19 | CO30: =Ticker0027!EE19 | CP30: =Ticker0027!EG19 | CQ30: =Ticker0027!EH19 | CR30: =Ticker0027!EI19 | CS30: =Ticker0027!EJ19 | CT30: =Ticker0027!EL19 | CU30: =Ticker0027!EM19 | CV30: =CU30*(1+CV31) | CW30: =CV30*(1+CW31) | CX30: =CW30*(1+CX31) | CY30: =CX30*(1+CY31) | CZ30: =CY30*(1+CZ31) | DA30: =CZ30*(1+DA31) | DB30: =DA30*(1+DB31) | DC30: =DB30*(1+DC31) | ... DE30: =DD30*(1+DE31) | DH30: =SUM(B30:E30) | DI30: =SUM(F30:I30) | DJ30: =SUM(J30:M30) | DK30: =SUM(N30:Q30) | DL30: =SUM(R30:U30) | DM30: =SUM(V30:Y30) | DN30: =SUM(Z30:AC30) | DO30: =SUM(AD30:AG30) | DP30: =SUM(AH30:AK30) | DQ30: =SUM(AL30:AO30) | DR30: =SUM(AP30:AS30) | DS30: =SUM(AT30:AW30) | DT30: =SUM(AX30:BA30) | DU30: =SUM(BB30:BE30) | DV30: =SUM(BF30:BI30) | DW30: =SUM(BJ30:BM30) | DX30: =SUM(BN30:BQ30) | DY30: =SUM(BR30:BU30) | DZ30: =BV30+BW30+BX30+BY30 | EA30: =CC30+CB30+CA30+BZ30 | EB30: =+CD30+CE30+CF30+CG30 | EC30: =SUM(CH30:CK30) | ED30: =SUM(CL30:CO30) | EE30: =SUM(CP30:CS30) | EF30: =SUM(CT30:CW30) | EG30: =SUM(CX30:DA30) | EH30: =SUM(DB30:DE30)
A31: qoq | C31: =C30/B30-1 | D31: =D30/C30-1 | E31: =E30/D30-1 | F31: =F30/E30-1 | G31: =G30/F30-1 | H31: =H30/G30-1 | I31: =I30/H30-1 | J31: =J30/I30-1 | ... CU31: =CU30/CT30-1 | CV31: 0.09 | CW31: 0.07 | CX31: 0.02 | CY31: 0.03 | CZ31: 0.03 | DA31: 0.03 | DB31: 0.03 | DC31: 0.02 | DD31: 0.02 | DE31: 0.01 | DH31: -- | DI31: -- | DJ31: -- | DK31: -- | DL31: -- | DM31: -- | DN31: -- | DO31: -- | DP31: -- | DQ31: -- | DR31: -- | DS31: -- | DT31: -- | DU31: -- | DV31: -- | DW31: -- | DX31: -- | DY31: -- | DZ31: -- | EA31: -- | EB31: -- | EC31: -- | ED31: -- | EE31: -- | EF31: -- | EG31: -- | EH31: --
A32: yoy | F32: =F30/B30-1 | G32: =G30/C30-1 | H32: =H30/D30-1 | I32: =I30/E30-1 | J32: =J30/F30-1 | K32: =K30/G30-1 | L32: =L30/H30-1 | M32: =M30/I30-1 | ... DE32: =DE30/DA30-1 | DI32: =DI30/DH30-1 | DJ32: =DJ30/DI30-1 | DK32: =DK30/DJ30-1 | DL32: =DL30/DK30-1 | DM32: =DM30/DL30-1 | DN32: =DN30/DM30-1 | DO32: =DO30/DN30-1 | DP32: =DP30/DO30-1 | ... EH32: =EH30/EG30-1
A33: as a % of revenue | B33: =B30/B$5 | C33: =C30/C$5 | D33: =D30/D$5 | E33: =E30/E$5 | F33: =F30/F$5 | G33: =G30/G$5 | H33: =H30/H$5 | I33: =I30/I$5 | ... DE33: =DE30/DE$5 | DH33: =DH30/DH$5 | DI33: =DI30/DI$5 | DJ33: =DJ30/DJ$5 | DK33: =DK30/DK$5 | DL33: =DL30/DL$5 | DM33: =DM30/DM$5 | DN33: =DN30/DN$5 | DO33: =DO30/DO$5 | ... EH33: =EH30/EH$5
A34: SBC in R&D | AL34: 14.614 | AM34: 14.532 | AN34: 14.104 | AO34: 14.724 | AP34: 18.589 | AQ34: 21.697 | AR34: 19.308 | AS34: 20.908 | AT34: 21.207 | AU34: 18.885 | AV34: 20.056 | AW34: 22.009 | AX34: 21.935 | AY34: 18.555 | AZ34: 20.902 | BA34: 21.548 | BB34: 20.494 | BC34: 21 | BD34: 22 | BE34: 23 | BF34: 27 | BG34: 27 | BH34: 28 | BI34: 33 | BJ34: 29 | BK34: 30 | BL34: 35 | BM34: 40 | BN34: 41 | BO34: 44 | BP34: 61 | BQ34: 73 | BR34: 74 | BS34: 76 | BT34: 88 | BU34: 99 | BV34: 114 | BW34: 145 | BX34: 141 | BY34: 140 | BZ34: 134 | CA34: 228 | CB34: 232 | CC34: 266 | CD34: 276 | CE34: 297 | CF34: 363 | CG34: 362 | CH34: 384 | CI34: 452 | CJ34: 530 | CK34: 527 | CL34: 524 | CM34: 600 | CN34: 701 | CO34: 706 | CP34: 727 | CQ34: 832 | CR34: 910 | CS34: 955 | CT34: 1063 | CU34: 1191 | CV34: =+CV29*CU34/CU29 | CW34: =+CW29*CV34/CV29 | CX34: =+CX29*CW34/CW29 | CY34: =+CY29*CX34/CX29 | CZ34: =+CZ29*CY34/CY29 | DA34: =+DA29*CZ34/CZ29 | DB34: =+DB29*DA34/DA29 | DC34: =+DC29*DB34/DB29 | ... DE34: =+DE29*DD34/DD29 | DR34: =SUM(AP34:AS34) | DS34: =SUM(AT34:AW34) | DT34: =SUM(AX34:BA34) | DU34: =SUM(BB34:BE34) | DV34: =SUM(BF34:BI34) | DW34: =SUM(BJ34:BM34) | DX34: =SUM(BN34:BQ34) | DY34: =SUM(BR34:BU34) | DZ34: =BV34+BW34+BX34+BY34 | EA34: =CC34+CB34+CA34+BZ34 | EB34: =+CD34+CE34+CF34+CG34 | EC34: =SUM(CH34:CK34) | ED34: =SUM(CL34:CO34) | EE34: =SUM(CP34:CS34) | EF34: =SUM(CT34:CW34) | EG34: =SUM(CX34:DA34) | EH34: =SUM(DB34:DE34)
A35: SG&A | B35: =Ticker0027!V17 | C35: =Ticker0027!W17 | D35: =Ticker0027!X17 | E35: =Ticker0027!Y17 | F35: =Ticker0027!AA17 | G35: =Ticker0027!AB17 | H35: =Ticker0027!AC17 | I35: =Ticker0027!AD17 | J35: =Ticker0027!AF17 | K35: =Ticker0027!AG17 | L35: =Ticker0027!AH17 | M35: =Ticker0027!AI17 | N35: =Ticker0027!AK17 | O35: =Ticker0027!AL17 | P35: =Ticker0027!AM17 | Q35: =Ticker0027!AN17 | R35: =Ticker0027!AP17 | S35: =Ticker0027!AQ17 | T35: =Ticker0027!AR17 | U35: =Ticker0027!AS17 | V35: =Ticker0027!AU17 | W35: =Ticker0027!AV17 | X35: =Ticker0027!AW17 | Y35: =Ticker0027!AX17 | Z35: =Ticker0027!AZ17 | AA35: =Ticker0027!BA17 | AB35: =Ticker0027!BB17 | AC35: =Ticker0027!BC17 | AD35: =Ticker0027!BE17 | AE35: =Ticker0027!BF17 | AF35: =Ticker0027!BG17 | AG35: =Ticker0027!BH17 | AH35: =Ticker0027!BJ17 | AI35: =Ticker0027!BK17 | AJ35: =Ticker0027!BL17 | AK35: =Ticker0027!BM17 | AL35: =Ticker0027!BO17 | AM35: =Ticker0027!BP17 | AN35: =Ticker0027!BQ17 | AO35: =Ticker0027!BR17 | AP35: =Ticker0027!BT17 | AQ35: =Ticker0027!BU17 | AR35: =Ticker0027!BV17 | AS35: =Ticker0027!BW17 | AT35: =Ticker0027!BY17 | AU35: =Ticker0027!BZ17 | AV35: =Ticker0027!CA17 | AW35: =Ticker0027!CB17 | AX35: =Ticker0027!CD17 | AY35: =Ticker0027!CE17 | AZ35: =Ticker0027!CF17 | BA35: =Ticker0027!CG17 | BB35: =Ticker0027!CI17 | BC35: =Ticker0027!CJ17 | BD35: =Ticker0027!CK17 | BE35: =Ticker0027!CL17 | BF35: =Ticker0027!CN17 | BG35: =Ticker0027!CO17 | BH35: =Ticker0027!CP17 | BI35: =Ticker0027!CQ17 | BJ35: =Ticker0027!CS17 | BK35: =Ticker0027!CT17 | BL35: =Ticker0027!CU17 | BM35: =Ticker0027!CV17 | BN35: =Ticker0027!CX17 | BO35: =Ticker0027!CY17 | BP35: =Ticker0027!CZ17 | BQ35: =Ticker0027!DA17 | BR35: =Ticker0027!DC17 | BS35: =Ticker0027!DD17 | BT35: =Ticker0027!DE17 | BU35: =Ticker0027!DF17 | BV35: =Ticker0027!DH17 | BW35: =Ticker0027!DI17 | BX35: =Ticker0027!DJ17 | BY35: =Ticker0027!DK17 | BZ35: =Ticker0027!DM17 | CA35: =Ticker0027!DN17 | CB35: =Ticker0027!DO17 | CC35: =Ticker0027!DP17 | CD35: =Ticker0027!DR17 | CE35: =Ticker0027!DS17 | CF35: =Ticker0027!DT17 | CG35: =Ticker0027!DU17 | CH35: =Ticker0027!DW17 | CI35: =Ticker0027!DX17 | CJ35: =Ticker0027!DY17 | CK35: =Ticker0027!DZ17 | CL35: =Ticker0027!EB17 | CM35: =Ticker0027!EC17 | CN35: =Ticker0027!ED17 | CO35: =Ticker0027!EE17 | CP35: =Ticker0027!EG17 | CQ35: =Ticker0027!EH17 | CR35: =Ticker0027!EI17 | CS35: =Ticker0027!EJ17 | CT35: =Ticker0027!EL17 | CU35: =Ticker0027!EM17 | CV35: =CU35*(1+CV36) | CW35: =CV35*(1+CW36) | CX35: =CW35*(1+CX36) | CY35: =CX35*(1+CY36) | CZ35: =CY35*(1+CZ36) | DA35: =CZ35*(1+DA36) | DB35: =DA35*(1+DB36) | DC35: =DB35*(1+DC36) | ... DE35: =DD35*(1+DE36) | DH35: =SUM(B35:E35) | DI35: =SUM(F35:I35) | DJ35: =SUM(J35:M35) | DK35: =SUM(N35:Q35) | DL35: =SUM(R35:U35) | DM35: =SUM(V35:Y35) | DN35: =SUM(Z35:AC35) | DO35: =SUM(AD35:AG35) | DP35: =SUM(AH35:AK35) | DQ35: =SUM(AL35:AO35) | DR35: =SUM(AP35:AS35) | DS35: =SUM(AT35:AW35) | DT35: =SUM(AX35:BA35) | DU35: =SUM(BB35:BE35) | DV35: =SUM(BF35:BI35) | DW35: =SUM(BJ35:BM35) | DX35: =SUM(BN35:BQ35) | DY35: =SUM(BR35:BU35) | DZ35: =BV35+BW35+BX35+BY35 | EA35: =CC35+CB35+CA35+BZ35 | EB35: =+CD35+CE35+CF35+CG35 | EC35: =SUM(CH35:CK35) | ED35: =SUM(CL35:CO35) | EE35: =SUM(CP35:CS35) | EF35: =SUM(CT35:CW35) | EG35: =SUM(CX35:DA35) | EH35: =SUM(DB35:DE35)
A36: qoq | C36: =C35/B35-1 | D36: =D35/C35-1 | E36: =E35/D35-1 | F36: =F35/E35-1 | G36: =G35/F35-1 | H36: =H35/G35-1 | I36: =I35/H35-1 | J36: =J35/I35-1 | ... CU36: =CU35/CT35-1 | CV36: 0.09 | CW36: 0.06 | CX36: 0.04 | CY36: 0.03 | CZ36: 0.03 | DA36: 0.03 | DB36: 0.02 | DC36: 0.01 | DD36: 0.01 | DE36: 0.01 | DH36: -- | DI36: -- | DJ36: -- | DK36: -- | DL36: -- | DM36: -- | DN36: -- | DO36: -- | DP36: -- | DQ36: -- | DR36: -- | DS36: -- | DT36: -- | DU36: -- | DV36: -- | DW36: -- | DX36: -- | DY36: -- | DZ36: -- | EA36: -- | EB36: -- | EC36: -- | ED36: -- | EE36: -- | EF36: -- | EG36: -- | EH36: --
A37: yoy | F37: =F35/B35-1 | G37: =G35/C35-1 | H37: =H35/D35-1 | I37: =I35/E35-1 | J37: =J35/F35-1 | K37: =K35/G35-1 | L37: =L35/H35-1 | M37: =M35/I35-1 | ... DE37: =DE35/DA35-1 | DI37: =DI35/DH35-1 | DJ37: =DJ35/DI35-1 | DK37: =DK35/DJ35-1 | DL37: =DL35/DK35-1 | DM37: =DM35/DL35-1 | DN37: =DN35/DM35-1 | DO37: =DO35/DN35-1 | DP37: =DP35/DO35-1 | ... EH37: =EH35/EG35-1
A38: as a % of revenue | B38: =B35/B$5 | C38: =C35/C$5 | D38: =D35/D$5 | E38: =E35/E$5 | F38: =F35/F$5 | G38: =G35/G$5 | H38: =H35/H$5 | I38: =I35/I$5 | ... DE38: =DE35/DE$5 | DH38: =DH35/DH$5 | DI38: =DI35/DI$5 | DJ38: =DJ35/DJ$5 | DK38: =DK35/DK$5 | DL38: =DL35/DL$5 | DM38: =DM35/DM$5 | DN38: =DN35/DN$5 | DO38: =DO35/DO$5 | ... EH38: =EH35/EH$5
A39: SBC in SGA | AL39: 8.76 | AM39: 7.81 | AN39: 8.585 | AO39: 8.916 | AP39: 10.673 | AQ39: 11.505 | AR39: 10.872 | AS39: 11.48 | AT39: 11.836 | AU39: 10.721 | AV39: 10.524 | AW39: 10.934 | AX39: 8.809 | AY39: 11.687 | AZ39: 10.307 | BA39: 11.879 | BB39: 12.108 | BC39: 14 | BD39: 16 | BE39: 15 | BF39: 16 | BG39: 17 | BH39: 19 | BI39: 22 | BJ39: 20 | BK39: 24 | BL39: 27 | BM39: 27 | BN39: 31 | BO39: 33 | BP39: 40 | BQ39: 46 | BR39: 47 | BS39: 48 | BT39: 47 | BU39: 51 | BV39: 60 | BW39: 71 | BX39: 67 | BY39: 68 | BZ39: 69 | CA39: 132 | CB39: 123 | CC39: 125 | CD39: 128 | CE39: 136 | CF39: 152 | CG39: 150 | CH39: 156 | CI39: 159 | CJ39: 183 | CK39: 182 | CL39: 184 | CM39: 211 | CN39: 240 | CO39: 242 | CP39: 248 | CQ39: 282 | CR39: 292 | CS39: 313 | CT39: 347 | CU39: 375 | CV39: =+CV29-CV34 | CW39: =+CW29-CW34 | CX39: =+CX29-CX34 | CY39: =+CY29-CY34 | CZ39: =+CZ29-CZ34 | DA39: =+DA29-DA34 | DB39: =+DB29-DB34 | DC39: =+DC29-DC34 | ... DE39: =+DE29-DE34 | DR39: =SUM(AP39:AS39) | DS39: =SUM(AT39:AW39) | DT39: =SUM(AX39:BA39) | DU39: =SUM(BB39:BE39) | DV39: =SUM(BF39:BI39) | DW39: =SUM(BJ39:BM39) | DX39: =SUM(BN39:BQ39) | DY39: =SUM(BR39:BU39) | DZ39: =BV39+BW39+BX39+BY39 | EA39: =CC39+CB39+CA39+BZ39 | EB39: =+CD39+CE39+CF39+CG39 | EC39: =SUM(CH39:CK39) | ED39: =SUM(CL39:CO39) | EE39: =SUM(CP39:CS39) | EF39: =SUM(CT39:CW39) | EG39: =SUM(CX39:DA39) | EH39: =SUM(DB39:DE39)
A40: Op profit (incl SBC) | B40: =B15-B30-B35 | C40: =C15-C30-C35 | D40: =D15-D30-D35 | E40: =E15-E30-E35 | F40: =F15-F30-F35 | G40: =G15-G30-G35 | H40: =H15-H30-H35 | I40: =I15-I30-I35 | ... DE40: =DE15-DE30-DE35 | DH40: =SUM(B40:E40) | DI40: =SUM(F40:I40) | DJ40: =SUM(J40:M40) | DK40: =SUM(N40:Q40) | DL40: =SUM(R40:U40) | DM40: =SUM(V40:Y40) | DN40: =SUM(Z40:AC40) | DO40: =SUM(AD40:AG40) | DP40: =SUM(AH40:AK40) | DQ40: =SUM(AL40:AO40) | DR40: =SUM(AP40:AS40) | DS40: =SUM(AT40:AW40) | DT40: =SUM(AX40:BA40) | DU40: =SUM(BB40:BE40) | DV40: =SUM(BF40:BI40) | DW40: =SUM(BJ40:BM40) | DX40: =SUM(BN40:BQ40) | DY40: =SUM(BR40:BU40) | DZ40: =BV40+BW40+BX40+BY40 | EA40: =CC40+CB40+CA40+BZ40 | EB40: =+CD40+CE40+CF40+CG40 | EC40: =SUM(CH40:CK40) | ED40: =SUM(CL40:CO40) | EE40: =SUM(CP40:CS40) | EF40: =SUM(CT40:CW40) | EG40: =SUM(CX40:DA40) | EH40: =SUM(DB40:DE40)
...

Sheet Ticker0027
A2: Company1953 | B2: Q198 | C2: Q298 | D2: Q398 | E2: Q498 | F2: FY | G2: Q199 | H2: Q299 | I2: Q399 | J2: Q499 | K2: FY | L2: Q100 | M2: Q200 | N2: Q300 | O2: Q400 | P2: FY | Q2: Q101 | R2: Q201 | S2: Q301 | T2: Q401 | U2: FY | V2: Q102 | W2: Q202 | X2: Q302 | Y2: Q402 | Z2: FY | AA2: Q103 | AB2: Q203 | AC2: Q303 | AD2: Q403 | AE2: FY | AF2: Q104 | AG2: Q204 | AH2: Q304 | AI2: Q404 | AJ2: FY | AK2: 1Q05 | AL2: 2Q05 | AM2: 3Q05 | AN2: 4Q05 | AO2: FY | AP2: 1Q06 | AQ2: 2Q06 | AR2: 3Q06 | AS2: 4Q06 | AT2: FY | AU2: 1Q07 | AV2: 2Q07 | AW2: 3Q07 | AX2: 4Q07 | AY2: FY | AZ2: 1Q08 | BA2: 2Q08 | BB2: 3Q08 | BC2: 4Q08 | BD2: FY | BE2: 1Q09 | BF2: 2Q09 | BG2: 3Q09 | BH2: 4Q09 | BI2: FY | BJ2: 1Q10 | BK2: 2Q10 | BL2: 3Q10 | BM2: 4Q10 | BN2: FY | BO2: 1Q11 | BP2: 2Q11 | BQ2: 3Q11 | BR2: 4Q11 | BS2: FY | BT2: 1Q12 | BU2: 2Q12 | BV2: 3Q12 | BW2: 4Q12 | BX2: FY | BY2: 1Q13 | BZ2: 2Q13 | CA2: 3Q13 | CB2: 4Q13 | CC2: FY | CD2: 1Q14 | CE2: 2Q14 | CF2: 3Q14 | CG2: 4Q14 | CH2: FY | CI2: 1Q15 | CJ2: 2Q15 | CK2: 3Q15 | CL2: 4Q15 | CM2: FY | CN2: 1Q16 | CO2: 2Q16 | CP2: 3Q16 | CQ2: 4Q16 | CR2: FY | CS2: 1Q17 | CT2: 2Q17 | CU2: 3Q17 | CV2: 4Q17 | CW2: FY | CX2: 1Q18 | CY2: 2Q18 | CZ2: 3Q18 | DA2: 4Q18 | DB2: FY | DC2: 1Q19 | DD2: 2Q19 | DE2: 3Q19 | DF2: 4Q19 | DG2: FY | DH2: 1Q20 | DI2: 2Q20 | DJ2: 3Q20 | DK2: 4Q20 | DL2: FY | DM2: 1Q21 | DN2: 2Q21 | DO2: 3Q21 | DP2: 4Q21 | DQ2: FY | DR2: 1Q22 | DS2: 2Q22 | DT2: 3Q22 | DU2: 4Q22 | DV2: FY | DW2: 1Q23 | DX2: 2Q23 | DY2: 3Q23 | DZ2: 4Q23 | EA2: FY | EB2: 1Q24 | EC2: 2Q24 | ED2: 3Q24 | EE2: 4Q24 | EF2: FY | EG2: 1Q25 | EH2: 2Q25 | EI2: 3Q25 | EJ2: 4Q25 | EK2: FY | EL2: 1Q26 | EM2: 2Q26 | EN2: 3Q26E | EO2: 4Q26E | EP2: FY | EQ2: 1Q27E | ER2: 2Q27E | ES2: 3Q27E | ET2: 4Q27E | EU2: FY | EV2: 1Q28E | EW2: 2Q28E | EX2: 3Q28E | EY2: 4Q28E | EZ2: FY
B3: 35519 | C3: 35610 | D3: 35701 | E3: 35795 | F3: =K3-1 | G3: 35911 | H3: 36002 | I3: 36093 | J3: 36191 | K3: =P3-1 | L3: 36282 | M3: 36373 | N3: 36464 | O3: 36555 | P3: =U3-1 | Q3: 36646 | R3: 36737 | S3: 36828 | T3: 36919 | U3: =Z3-1 | V3: 37010 | W3: 37101 | X3: 37192 | Y3: 37283 | Z3: =AE3-1 | AA3: 37374 | AB3: 37465 | AC3: 37556 | AD3: 37647 | AE3: =AJ3-1 | AF3: 37741 | AG3: 37833 | AH3: 37925 | AI3: 38017 | AJ3: =AO3-1 | AK3: 38102 | AL3: 38199 | AM3: 38291 | AN3: 38383 | AO3: =AT3-1 | AP3: 38443 | AQ3: 38564 | AR3: 38656 | AS3: 38748 | AT3: =AY3-1 | AU3: 38837 | AV3: 38928 | AW3: 39019 | AX3: 39113 | AY3: =BD3-1 | AZ3: 39201 | BA3: 39294 | BB3: 39386 | BC3: 39478 | BD3: =BI3-1 | BE3: 4/31/2008 | BF3: 39660 | BG3: 39752 | BH3: 39844 | BI3: =BN3-1 | BJ3: 4/31/2009 | BK3: 40025 | BL3: 40117 | BM3: 40209 | BN3: =BS3-1 | BO3: 4/31/2010 | BP3: 40390 | BQ3: 40482 | BR3: 40574 | BS3: =BX3-1 | BT3: 4/31/2011 | BU3: 40755 | BV3: 40847 | BW3: 40939 | BX3: =CC3-1 | BY3: 4/31/2012 | BZ3: 41121 | CA3: 41213 | CB3: 41305 | CC3: =CH3-1 | CD3: 4/31/2013 | CE3: 41486 | CF3: 41578 | CG3: 41670 | CH3: =CM3-1 | CI3: 4/31/2014 | CJ3: 41851 | CK3: 41943 | CL3: 42035 | CM3: =CR3-1 | CN3: 4/31/2015 | CO3: 42216 | CP3: 42308 | CQ3: 42400 | CR3: =CW3-1 | CS3: 4/31/2016 | CT3: 42582 | CU3: 42674 | CV3: 42766 | CW3: =DB3-1 | CX3: 4/31/2017 | CY3: 42947 | CZ3: 43039 | DA3: 43131 | DB3: 2018 | DC3: 4/31/2018 | DD3: 43312 | DE3: 43404 | DF3: 43496 | DG3: 2019 | DH3: 4/31/2019 | DI3: 43677 | DJ3: 43769 | DK3: 43861 | DL3: 2020 | DM3: 4/31/2020 | DN3: 44043 | DO3: 44135 | DP3: 44227 | DQ3: 2021 | DR3: 4/31/2021 | DS3: 44408 | DT3: 44500 | DU3: 44592 | DV3: 2022 | DW3: 4/31/2022 | DX3: 44773 | DY3: 44865 | DZ3: 44957 | EA3: 2023 | EB3: 4/31/23 | EC3: 45138 | ED3: 45230 | EE3: 45322 | EF3: 2024 | EG3: 4/31/24 | EH3: 45504 | EI3: 45596 | EJ3: 45688 | EK3: 2025 | EL3: 4/31/25 | EM3: 45869 | EN3: 45961 | EO3: 46053 | EP3: 2026 | EQ3: 4/31/26 | ER3: 46234 | ES3: 46326 | ET3: 46418 | EU3: 2027 | EV3: 4/31/27 | EW3: 46599 | EX3: 46691 | EY3: 46783 | EZ3: 2028
A4: Fiscal year ends January | B4: Nov | C4: Feb | D4: May | E4: Aug | G4: Nov | H4: Feb | I4: May | J4: Aug | L4: Nov | M4: Feb | N4: May | O4: Aug | Q4: Nov | R4: Feb | S4: May | T4: Aug | V4: Nov | W4: Feb | X4: May | Y4: Aug | AA4: Nov | AB4: Feb | AC4: May | AD4: Aug
A5: Company1953 Income Statement
A7: Revenue | B7: 0.065 | C7: 0.006 | D7: 5.466 | E7: 23.534 | F7: =SUM(B7:E7) | G7: 28.263 | H7: 12.134 | I7: 52.303 | J7: 65.537 | K7: =SUM(G7:J7) | L7: 71.018 | M7: 78.017 | N7: 97.015 | O7: 128.455 | P7: =SUM(L7:O7) | Q7: 148.483 | R7: 169.318 | S7: 197.667 | T7: 219.796 | U7: =SUM(Q7:T7) | V7: 240.932 | W7: 259.875 | X7: 364.976 | Y7: 503.688 | Z7: =SUM(V7:Y7) | AA7: 582.905 | AB7: 427.285 | AC7: 430.304 | AD7: =468.953-40.365 | AE7: =SUM(AA7:AD7) | AF7: 404.983 | AG7: 459.774 | AH7: 486.069 | AI7: 472.119 | AJ7: =SUM(AF7:AI7) | AK7: 471.905 | AL7: 456.061 | AM7: 515.591 | AN7: 566.476 | AO7: =SUM(AK7:AN7) | AP7: 583.846 | AQ7: 574.812 | AR7: 583.415 | AS7: 633.614 | AT7: =SUM(AP7:AS7) | AU7: 681.807 | AV7: 687.519 | AW7: 820.572 | AX7: 878.873 | AY7: =SUM(AU7:AX7) | AZ7: 844.28 | BA7: 935.253 | BB7: 1115.597 | BC7: 1202.73 | BD7: =SUM(AZ7:BC7) | BE7: 1153.388 | BF7: 892.676 | BG7: 897.655 | BH7: 481.14 | BI7: =SUM(BE7:BH7) | BJ7: 664.231 | BK7: 776.52 | BL7: 903.206 | BM7: 982.488 | BN7: =SUM(BJ7:BM7) | BO7: 1001.813 | BP7: 811.208 | BQ7: 843.912 | BR7: 886.376 | BS7: =SUM(BO7:BR7) | BT7: 962.039 | BU7: 1016.517 | BV7: 1066.18 | BW7: 953.194 | BX7: =SUM(BT7:BW7) | BY7: 924.877 | BZ7: 1044.27 | CA7: 1204.11 | CB7: 1106.902 | CC7: =SUM(BY7:CB7) | CD7: 954.739 | CE7: 977.238 | CF7: 1053.967 | CG7: 1144.218 | CH7: =SUM(CD7:CG7) | CI7: 1102.787 | CJ7: 1102.824 | CK7: 1225.382 | CL7: 1250.514 | CM7: =SUM(CI7:CL7) | CN7: =1151 | CO7: =1153 | CP7: =1305 | CQ7: =1401 | CR7: =SUM(CN7:CQ7) | CS7: 1305 | CT7: 1428 | CU7: 2004 | CV7: 2173 | CW7: =SUM(CS7:CV7) | CX7: 1937 | CY7: 2230 | CZ7: 2636 | DA7: 2911 | DB7: =SUM(CX7:DA7) | DC7: 3207 | DD7: 3123 | DE7: 3181 | DF7: 2205 | DG7: =SUM(DC7:DF7) | DH7: 2220 | DI7: 2579 | DJ7: 3014 | DK7: 3105 | DL7: =SUM(DH7:DK7) | DM7: 3080 | DN7: 3866 | DO7: 4726 | DP7: 5003 | DQ7: =SUM(DM7:DP7) | DR7: 5661 | DS7: 6507 | DT7: 7103 | DU7: 7643 | DV7: =SUM(DR7:DU7) | DW7: 8288 | DX7: 6704 | DY7: 5931 | DZ7: 6051 | EA7: =SUM(DW7:DZ7) | EB7: 7192 | EC7: 13507 | ED7: 18120 | EE7: 22103 | EF7: =SUM(EB7:EE7) | EG7: 26044 | EH7: 30040 | EI7: 35082 | EJ7: 39331 | EK7: =SUM(EG7:EJ7) | EL7: 44062 | EM7: 46743 | EN7: =Worksheet!CV5 | EO7: =Worksheet!CW5 | EP7: =SUM(EL7:EO7) | EQ7: =Worksheet!CX5 | ER7: =Worksheet!CY5 | ES7: =Worksheet!CZ5 | ET7: =Worksheet!DA5 | EU7: =SUM(EQ7:ET7) | EV7: =Worksheet!DB5 | EW7: =Worksheet!DC5 | EX7: =Worksheet!DD5 | EY7: =Worksheet!DE5 | EZ7: =SUM(EV7:EY7)
A8: % Growth qoq | F8: -- | G8: =G7/E7-1 | H8: =H7/G7-1 | I8: =I7/H7-1 | J8: =J7/I7-1 | K8: -- | L8: =L7/J7-1 | M8: =M7/L7-1 | N8: =N7/M7-1 | O8: =O7/N7-1 | P8: -- | Q8: =Q7/O7-1 | R8: =R7/Q7-1 | S8: =S7/R7-1 | T8: =T7/S7-1 | U8: -- | V8: =V7/T7-1 | W8: =W7/V7-1 | X8: =X7/W7-1 | Y8: =Y7/X7-1 | Z8: -- | AA8: =AA7/Y7-1 | AB8: =AB7/AA7-1 | AC8: =AC7/AB7-1 | AD8: =AD7/AC7-1 | AE8: -- | AF8: =AF7/AD7-1 | AG8: =AG7/AF7-1 | AH8: =AH7/AG7-1 | AI8: =AI7/AH7-1 | AJ8: -- | AK8: =AK7/AI7-1 | AL8: =AL7/AK7-1 | AM8: =AM7/AL7-1 | AN8: =AN7/AM7-1 | AO8: -- | AP8: =AP7/AN7-1 | AQ8: =AQ7/AP7-1 | AR8: =AR7/AQ7-1 | AS8: =AS7/AR7-1 | AT8: -- | AU8: =AU7/AS7-1 | AV8: =AV7/AU7-1 | AW8: =AW7/AV7-1 | AX8: =AX7/AW7-1 | AY8: -- | AZ8: =AZ7/AX7-1 | BA8: =BA7/AZ7-1 | BB8: =BB7/BA7-1 | BC8: =BC7/BB7-1 | BD8: -- | BE8: =BE7/BC7-1 | BF8: =BF7/BE7-1 | BG8: =BG7/BF7-1 | BH8: =BH7/BG7-1 | BI8: -- | BJ8: =BJ7/BH7-1 | BK8: =BK7/BJ7-1 | BL8: =BL7/BK7-1 | BM8: =BM7/BL7-1 | BN8: -- | BO8: =BO7/BM7-1 | BP8: =BP7/BO7-1 | BQ8: =BQ7/BP7-1 | BR8: =BR7/BQ7-1 | BS8: -- | BT8: =BT7/BR7-1 | BU8: =BU7/BT7-1 | BV8: =BV7/BU7-1 | BW8: =BW7/BV7-1 | BX8: -- | BY8: =BY7/BW7-1 | BZ8: =BZ7/BY7-1 | CA8: =CA7/BZ7-1 | CB8: =CB7/CA7-1 | CC8: -- | CD8: =CD7/CB7-1 | CE8: =CE7/CD7-1 | CF8: =CF7/CE7-1 | CG8: =CG7/CF7-1 | CH8: -- | CI8: =CI7/CG7-1 | CJ8: =CJ7/CI7-1 | CK8: =CK7/CJ7-1 | CL8: =CL7/CK7-1 | CM8: -- | CN8: =CN7/CL7-1 | CO8: =CO7/CN7-1 | CP8: =CP7/CO7-1 | CQ8: =CQ7/CP7-1 | CR8: -- | CS8: =CS7/CQ7-1 | CT8: =CT7/CS7-1 | CU8: =CU7/CT7-1 | CV8: =CV7/CU7-1 | CW8: -- | CX8: =CX7/CV7-1 | CY8: =CY7/CX7-1 | CZ8: =CZ7/CY7-1 | DA8: =DA7/CZ7-1 | DB8: -- | DC8: =DC7/DA7-1 | DD8: =DD7/DC7-1 | DE8: =DE7/DD7-1 | DF8: =DF7/DE7-1 | DG8: -- | DH8: =DH7/DF7-1 | DI8: =DI7/DH7-1 | DJ8: =DJ7/DI7-1 | DK8: =DK7/DJ7-1 | DL8: -- | DM8: =DM7/DK7-1 | DN8: =DN7/DM7-1 | DO8: =DO7/DN7-1 | DP8: =DP7/DO7-1 | DQ8: -- | DR8: =DR7/DP7-1 | DS8: =DS7/DR7-1 | DT8: =DT7/DS7-1 | DU8: =DU7/DT7-1 | DV8: -- | DW8: =DW7/DU7-1 | DX8: =DX7/DW7-1 | DY8: =DY7/DX7-1 | DZ8: =DZ7/DY7-1 | EA8: -- | EB8: =EB7/DZ7-1 | EC8: =EC7/EB7-1 | ED8: =ED7/EC7-1 | EE8: =EE7/ED7-1 | EF8: -- | EG8: =EG7/EE7-1 | EH8: =EH7/EG7-1 | EI8: =EI7/EH7-1 | EJ8: =EJ7/EI7-1 | EK8: -- | EL8: =EL7/EJ7-1 | EM8: =EM7/EL7-1 | EN8: =EN7/EM7-1 | EO8: =EO7/EN7-1 | EP8: -- | EQ8: =EQ7/EO7-1 | ER8: =ER7/EQ7-1 | ES8: =ES7/ER7-1 | ET8: =ET7/ES7-1 | EU8: -- | EV8: =EV7/ET7-1 | EW8: =EW7/EV7-1 | EX8: =EX7/EW7-1 | EY8: =EY7/EX7-1 | EZ8: --
A9: % Growth yoy | G9: =+G7/B7-1 | H9: =+H7/C7-1 | I9: =+I7/D7-1 | J9: =+J7/E7-1 | K9: =K7/F7-1 | L9: =+L7/G7-1 | M9: =+M7/H7-1 | N9: =+N7/I7-1 | O9: =+O7/J7-1 | P9: =P7/K7-1 | Q9: =+Q7/L7-1 | R9: =+R7/M7-1 | S9: =+S7/N7-1 | T9: =+T7/O7-1 | U9: =U7/P7-1 | V9: =+V7/Q7-1 | W9: =+W7/R7-1 | X9: =+X7/S7-1 | Y9: =+Y7/T7-1 | Z9: =Z7/U7-1 | AA9: =+AA7/V7-1 | AB9: =+AB7/W7-1 | AC9: =+AC7/X7-1 | AD9: =+AD7/Y7-1 | AE9: =AE7/Z7-1 | AF9: =+AF7/AA7-1 | AG9: =+AG7/AB7-1 | AH9: =+AH7/AC7-1 | AI9: =+AI7/AD7-1 | AJ9: =AJ7/AE7-1 | AK9: =+AK7/AF7-1 | AL9: =+AL7/AG7-1 | AM9: =+AM7/AH7-1 | AN9: =+AN7/AI7-1 | AO9: =AO7/AJ7-1 | AP9: =+AP7/AK7-1 | AQ9: =+AQ7/AL7-1 | AR9: =+AR7/AM7-1 | AS9: =+AS7/AN7-1 | AT9: =AT7/AO7-1 | AU9: =+AU7/AP7-1 | AV9: =+AV7/AQ7-1 | AW9: =+AW7/AR7-1 | AX9: =+AX7/AS7-1 | AY9: =AY7/AT7-1 | AZ9: =+AZ7/AU7-1 | BA9: =+BA7/AV7-1 | BB9: =+BB7/AW7-1 | BC9: =+BC7/AX7-1 | BD9: =BD7/AY7-1 | BE9: =+BE7/AZ7-1 | BF9: =+BF7/BA7-1 | BG9: =+BG7/BB7-1 | BH9: =+BH7/BC7-1 | BI9: =BI7/BD7-1 | BJ9: =+BJ7/BE7-1 | BK9: =+BK7/BF7-1 | BL9: =+BL7/BG7-1 | BM9: =+BM7/BH7-1 | BN9: =BN7/BI7-1 | BO9: =+BO7/BJ7-1 | BP9: =+BP7/BK7-1 | BQ9: =+BQ7/BL7-1 | BR9: =+BR7/BM7-1 | BS9: =BS7/BN7-1 | BT9: =+BT7/BO7-1 | BU9: =+BU7/BP7-1 | BV9: =+BV7/BQ7-1 | BW9: =+BW7/BR7-1 | BX9: =BX7/BS7-1 | BY9: =+BY7/BT7-1 | BZ9: =+BZ7/BU7-1 | CA9: =+CA7/BV7-1 | CB9: =+CB7/BW7-1 | CC9: =CC7/BX7-1 | CD9: =+CD7/BY7-1 | CE9: =+CE7/BZ7-1 | CF9: =+CF7/CA7-1 | CG9: =+CG7/CB7-1 | CH9: =CH7/CC7-1 | CI9: =+CI7/CD7-1 | CJ9: =+CJ7/CE7-1 | CK9: =+CK7/CF7-1 | CL9: =+CL7/CG7-1 | CM9: =CM7/CH7-1 | CN9: =+CN7/CI7-1 | CO9: =+CO7/CJ7-1 | CP9: =+CP7/CK7-1 | CQ9: =+CQ7/CL7-1 | CR9: =CR7/CM7-1 | CS9: =+CS7/CN7-1 | CT9: =+CT7/CO7-1 | CU9: =+CU7/CP7-1 | CV9: =+CV7/CQ7-1 | CW9: =CW7/CR7-1 | CX9: =+CX7/CS7-1 | CY9: =+CY7/CT7-1 | CZ9: =+CZ7/CU7-1 | DA9: =+DA7/CV7-1 | DB9: =DB7/CW7-1 | DC9: =+DC7/CX7-1 | DD9: =+DD7/CY7-1 | DE9: =+DE7/CZ7-1 | DF9: =+DF7/DA7-1 | DG9: =DG7/DB7-1 | DH9: =+DH7/DC7-1 | DI9: =+DI7/DD7-1 | DJ9: =+DJ7/DE7-1 | DK9: =+DK7/DF7-1 | DL9: =DL7/DG7-1 | DM9: =+DM7/DH7-1 | DN9: =+DN7/DI7-1 | DO9: =+DO7/DJ7-1 | DP9: =+DP7/DK7-1 | DQ9: =DQ7/DL7-1 | DR9: =+DR7/DM7-1 | DS9: =+DS7/DN7-1 | DT9: =+DT7/DO7-1 | DU9: =+DU7/DP7-1 | DV9: =DV7/DQ7-1 | DW9: =+DW7/DR7-1 | DX9: =+DX7/DS7-1 | DY9: =+DY7/DT7-1 | DZ9: =+DZ7/DU7-1 | EA9: =EA7/DV7-1 | EB9: =+EB7/DW7-1 | EC9: =+EC7/DX7-1 | ED9: =+ED7/DY7-1 | EE9: =+EE7/DZ7-1 | EF9: =EF7/EA7-1 | EG9: =+EG7/EB7-1 | EH9: =+EH7/EC7-1 | EI9: =+EI7/ED7-1 | EJ9: =+EJ7/EE7-1 | EK9: =EK7/EF7-1 | EL9: =+EL7/EG7-1 | EM9: =+EM7/EH7-1 | EN9: =+EN7/EI7-1 | EO9: =+EO7/EJ7-1 | EP9: =EP7/EK7-1 | EQ9: =+EQ7/EL7-1 | ER9: =+ER7/EM7-1 | ES9: =+ES7/EN7-1 | ET9: =+ET7/EO7-1 | EU9: =EU7/EP7-1 | EV9: =+EV7/EQ7-1 | EW9: =+EW7/ER7-1 | EX9: =+EX7/ES7-1 | EY9: =+EY7/ET7-1 | EZ9: =EZ7/EU7-1
A10: COGS (ex. D&A) | B10: 0.208 | C10: 0.15 | D10: 4.548 | E10: 16.338 | F10: =SUM(B10:E10) | G10: 20.13 | H10: 11.967 | I10: 32.507 | J10: 41.136 | K10: =SUM(G10:J10) | L10: =45.946-L11 | M10: =49.225-M11 | N10: =56.747-N11 | O10: =80.744-O11 | P10: =SUM(L10:O10) | Q10: =96.964-Q11 | R10: =105.334-R11 | S10: =123.775-S11 | T10: =136.312-T11 | U10: =SUM(Q10:T10) | V10: =146.712-V11 | W10: =157.636-W11 | X10: =231.508-X11 | Y10: =314.377-Y11 | Z10: =SUM(V10:Y10) | AA10: =375.74-AA11 | AB10: =327.983-AB11-21 | AC10: =322.106-AC11 | AD10: =301.442-AD11 | AE10: =SUM(AA10:AD10) | AF10: =278.415-AF11 | AG10: =329.8-AG11 | AH10: =351.938-AH11 | AI10: =333.914-AI11 | AJ10: =SUM(AF10:AI10) | AK10: =323.069-AK11 | AL10: =315.968-AL11 | AM10: =348.849-AM11 | AN10: =372.661-AN11 | AO10: =SUM(AK10:AN10) | AP10: =373.693-AP11 | AQ10: =357.278-AQ11 | AR10: =355.247-AR11 | AS10: =378.674-AS11 | AT10: =SUM(AP10:AS10) | AU10: =393.134-AU11 | AV10: =395.391-AV11 | AW10: =486.63-AW11-16 | AX10: =493.167-AX11 | AY10: =SUM(AU10:AX10) | AZ10: =464.142-AZ11 | BA10: =511.261-BA11 | BB10: =600.044-BB11 | BC10: =653.133-BC11 | BD10: =SUM(AZ10:BC10) | BE10: =638.545-BE11 | BF10: =742.759-195.954-BF11 | BG10: 529.812 | BH10: =339.474-BH11 | BI10: =SUM(BE10:BH10) | BJ10: =463.123-BJ11 | BK10: =619.797-119.993-BK11 | BL10: =511.423+24.115-BL11 | BM10: =543.767-BM11 | BN10: =SUM(BJ10:BM10) | BO10: =545.436-BO11 | BP10: =676.916-181.193-BP11 | BQ10: =451.85-BQ11 | BR10: =460.017-BR11 | BS10: =SUM(BO10:BR10) | BT10: =477.536-BT11 | BU10: =491.233-BU11 | BV10: =509.463-BV11 | BW10: =463.181-7.3-BW11 | BX10: =SUM(BT10:BW10) | BY10: =461.513-BY11 | BZ10: =503.551-BZ11 | CA10: =567.452-CA11 | CB10: =521.3-CB11 | CC10: =SUM(BY10:CB10) | CD10: =436.171-CD11 | CE10: =431.7-2.29-CE11 | CF10: =469.552-CF11 | CG10: =524.976-1.45+7.782-CG11 | CH10: =SUM(CD10:CG10) | CI10: =498.585-CI11 | CJ10: =483.85-CJ11 | CK10: =548.684-CK11 | CL10: =550.911-CL11 | CM10: =SUM(CI10:CL10) | CN10: =498-CN11 | CO10: =519-CO11-15 | CP10: =571-CP11 | CQ10: =610-CQ11-5 | CR10: =SUM(CN10:CQ10) | CS10: =554-CS11-10 | CT10: =602-CT11 | CU10: =821-CU11 | CV10: =870-CV11 | CW10: =SUM(CS10:CV10) | CX10: =787-CX11 | CY10: =928-CY11 | CZ10: =1067-CZ11 | DA10: =1110-1-DA11 | DB10: =SUM(CX10:DA10) | DC10: =1139-DC11 | DD10: =1148-DD11 | DE10: =1260-14-DE11 | DF10: =998-21-DF11 | DG10: =SUM(DC10:DF10) | DH10: =924-10-DH11 | DI10: =1038-2-DI11 | DJ10: =1098-DJ11 | DK10: =1090-3-DK11 | DL10: =SUM(DH10:DK10) | DM10: =1076-1-DM11 | DN10: =1591-245-17-DN11 | DO10: =1766-86-21-DO11 | DP10: =1846-DP11-92-1 | DQ10: =SUM(DM10:DP10) | DR10: =2032-87-5-DR11 | DS10: =2292-86-4-DS11 | DT10: =2472-86-DT11 | DU10: =2644-DU11-86 | DV10: =SUM(DR10:DU10) | DW10: =2857-94-DW11 | DX10: =3789-121-DX11 | DY10: =2754-120-DY11 | DZ10: =2218-120-DZ11-16 | EA10: =SUM(DW10:DZ10) | EB10: =2544-119-EB11-8 | EC10: =4045-119-EC11-2 | ED10: =4720-119-ED11-26 | EE10: =5312-119-EE11-4 | EF10: =SUM(EB10:EE10) | EG10: =5638-119-EG11+1 | EH10: =7466-118-EH11+3 | EI10: =8926-116-EI11 | EJ10: =10608-118-EJ11 | EK10: =SUM(EG10:EJ10) | EL10: =17394-123-3-EL11 | EM10: =12890-49-EM11 | EN10: =EN7-EN13-EN11 | EO10: =EO7-EO13-EO11 | EP10: =SUM(EL10:EO10) | EQ10: =EQ7-EQ13-EQ11 | ER10: =ER7-ER13-ER11 | ES10: =ES7-ES13-ES11 | ET10: =ET7-ET13-ET11 | EU10: =SUM(EQ10:ET10) | EV10: =EV7-EV13-EV11 | EW10: =EW7-EW13-EW11 | EX10: =EX7-EX13-EX11 | EY10: =EY7-EY13-EY11 | EZ10: =SUM(EV10:EY10)
A11: D&A | B11: 0 | C11: 0 | D11: 0 | E11: 0 | F11: =SUM(B11:E11) | G11: 0.743 | H11: 0.994 | I11: 1.059 | J11: 1.21 | K11: =SUM(G11:J11) | L11: 1.458 | M11: 2.182 | N11: 2.503 | O11: 2.863 | P11: =SUM(L11:O11) | Q11: =3.048 | R11: =3.311 | S11: =4.362 | T11: =15.724-SUM(Q11:S11) | U11: =SUM(Q11:T11) | V11: 6.195 | W11: 10.62 | X11: 11.917 | Y11: 14.759 | Z11: =SUM(V11:Y11) | AA11: 12.83 | AB11: =26.899-AA11 | AC11: 16.166 | AD11: 15.151 | AE11: =SUM(AA11:AD11) | AF11: 15.958 | AG11: =35.568-AF11 | AH11: =58.41-+AG11-AF11 | AI11: =82.016-SUM(AF11:AH11) | AJ11: =SUM(AF11:AI11) | AK11: 23.412 | AL11: =47.486-AK11 | AM11: =71.512-+AL11-AK11 | AN11: =102.597-SUM(AK11:AM11) | AO11: =SUM(AK11:AN11) | AP11: 24.893 | AQ11: =49.667-AP11 | AR11: =74.189-SUM(AP11:AQ11) | AS11: =97.977-SUM(AP11:AR11) | AT11: =SUM(AP11:AS11) | AU11: =AU116 | AV11: =AV116 | AW11: =AW116 | AX11: =AX116 | AY11: =SUM(AU11:AX11) | AZ11: =AZ116 | BA11: =BA116 | BB11: =BB116 | BC11: =BC116 | BD11: =SUM(AZ11:BC11) | BE11: =BE116 | BF11: 46 | BG11: 49.3 | BH11: =BH116 | BI11: =SUM(BE11:BH11) | BJ11: 48.1 | BK11: 49 | BL11: 48 | BM11: 48 | BN11: =SUM(BJ11:BM11) | BO11: 47.147 | BP11: 46.573 | BQ11: 46.876 | BR11: =BR116 | BS11: =SUM(BO11:BR11) | BT11: 47.764 | BU11: =99.923-BT11 | BV11: 52.4 | BW11: 51.882 | BX11: =SUM(BT11:BW11) | BY11: 54.491 | BZ11: =110.686-BY11 | CA11: =167.834-BZ11-BY11 | CB11: 58.5 | CC11: =SUM(BY11:CB11) | CD11: 59.744 | CE11: =121.584-CD11 | CF11: =184.31-CE11-CD11 | CG11: =239.148-CF11-CE11-CD11 | CH11: =SUM(CD11:CG11) | CI11: 55.083 | CJ11: =110.69-CI11 | CK11: 55 | CL11: 55 | CM11: =SUM(CI11:CL11) | CN11: 54 | CO11: 54 | CP11: 48 | CQ11: 46 | CR11: =SUM(CN11:CQ11) | CS11: 45 | CT11: 47 | CU11: 48 | CV11: 47 | CW11: =SUM(CS11:CV11) | CX11: 47 | CY11: 49 | CZ11: 50 | DA11: 53 | DB11: =SUM(CX11:DA11) | DC11: 57 | DD11: 59 | DE11: 68 | DF11: 78 | DG11: =SUM(DC11:DF11) | DH11: 91 | DI11: 92 | DJ11: 92 | DK11: 106 | DL11: =SUM(DH11:DK11) | DM11: 107 | DN11: =404-185 | DO11: 299 | DP11: 287 | DQ11: =SUM(DM11:DP11) | DR11: 281 | DS11: =286 | DT11: 298 | DU11: 309 | DV11: =SUM(DR11:DU11) | DW11: 334 | DX11: 378 | DY11: 406 | DZ11: 426 | EA11: =SUM(DW11:DZ11) | EB11: 384 | EC11: 365 | ED11: 372 | EE11: 387 | EF11: =SUM(EB11:EE11) | EG11: 410 | EH11: 433 | EI11: 478 | EJ11: 543 | EK11: =SUM(EG11:EJ11) | EL11: 611 | EM11: 668 | EN11: =Worksheet!CV11 | EO11: =Worksheet!CW11 | EP11: =SUM(EL11:EO11) | EQ11: =Worksheet!CX11 | ER11: =Worksheet!CY11 | ES11: =Worksheet!CZ11 | ET11: =Worksheet!DA11 | EU11: =SUM(EQ11:ET11) | EV11: =Worksheet!DB11 | EW11: =Worksheet!DC11 | EX11: =Worksheet!DD11 | EY11: =Worksheet!DE11 | EZ11: =SUM(EV11:EY11)
