Workbook

Sheet ASSUMPTIONS
A1: Property Level information
C2: By: Person0241 Person1264
A4: Address | B4: 317 West 71st St New York, NY
A5: Asking Price | B5: 5950000
A6: Gross SF | B6: 5380
A7: Resedential Units | B7: 7
A8: Block / Lot | B8: 1183/24
A9: Lot Size (SF) | B9: 1737
A10: Lot Dimenisons | B10: 17 x 102.17
A11: Zoning / FAR | B11: R8B / 4.0
A12: Air Rights / Development Rights | B12: 1568
A13: Historic / Landmark Status | B13: West 71st Street Historic Districts
A14: Frontage / Street Width | B14: 17
A15: Historicals / Current
A18: Revenue | I18: Months
A19: Unit | B19: Status | C19: # of Bdrm | D19: Terrace | E19: Lease expiration | F19: Est. Sq Ft | G19: Base Rent | H19: Annual Rent | I19: 12
A20: 1- (Grnd Fl) | B20: Free Market | C20: 2 | D20: No | E20: Vacant | F20: 1021 | G20: 6800 | H20: =G20*$I$19 -> 81600
A21: 2- (2R) | B21: Free Market | C21: 1 | D21: No | E21: Vacant | F21: 510 | G21: 3400 | H21: =G21*$I$19 -> 40800
A22: 3- (2F) | B22: Free Market | C22: 1 | D22: No | E22: Vacant | F22: 510 | G22: 3400 | H22: =G22*$I$19 -> 40800
A23: 4- (Ent 3rd Fl.) | B23: Free Market | C23: 2 | D23: No | E23: MTM | F23: 1021 | G23: 4000 | H23: =G23*$I$19 -> 48000
A24: 5- (4R) | B24: Free Market | C24: 1 | D24: Yes | E24: Vacant | F24: 414 | G24: 2700 | H24: =G24*$I$19 -> 32400
A25: 6- (4F) | B25: Free Market | C25: 1 | D25: No | E25: MTM | F25: 414 | G25: 2300 | H25: =G25*$I$19 -> 27600
A26: 7- (Ent 5th Fl) | B26: Free Market | C26: 1 | D26: Yes | E26: 42428 | F26: 482 | G26: 2300 | H26: =G26*$I$19 -> 27600
E27: TOTAL | F27: =SUM(F20:F26) -> 4372 | G27: =SUM(G20:G26) -> 24900 | H27: =SUM(H20:H26) -> 298800
A29: Potential Gross Income | B29: =H27 -> 298800
A30: (Vacancy) | B30: =SUMIF(E20:E26, "vacant",H20:H26) -> 195600
A31: Effective Gross Income | B31: =B29-B30 -> 103200
A32: Operating Expenses
B35: Expenses / PSF | C35: Annual Expenses
A36: Real Estate Taxes | B36: =C36/$B$6 -> 10.952974 | C36: 58927
A37: Water & Sewer | B37: =C37/$B$6 -> 1 | C37: 5380
A38: Insurance | B38: =C38/$B$6 -> 1 | C38: 5380
A39: Fuel | B39: =C39/$B$6 -> 1.65 | C39: 8877
A40: Electric | B40: =C40/$B$6 -> 0.35 | C40: 1883
A41: Repairs & Maintenance | B41: =C41/$B$6 -> 1 | C41: 5380
A42: Payroll | B42: =C42/$B$6 -> 1.1152416 | C42: 6000
A43: Management | B43: =C43/$B$6 -> 0.57546468 | C43: =D43*B31 -> 3096 | D43: 0.03 | E43: of Effective Gross Revenue
A44: Total | B44: =C44/$B$6 -> 17.64368 | C44: =SUM(C36:C43) -> 94923
A45: Capital Expenditures
A47: Reserves | B47: 0
...

Sheet RENT ROLL
A1: Rent Roll
A3: Unit | B3: Status | C3: # of Bedrooms | D3: Baths | E3: Terrace | F3: Lease Expiration | G3: Est. Square Footage | H3: Base Rent | I3: Annual Rent
A4: =ASSUMPTIONS!A20 -> 1- (Grnd Fl) | B4: =ASSUMPTIONS!B20 -> Free Market | C4: =ASSUMPTIONS!C20 -> 2 | E4: =ASSUMPTIONS!D20 -> No | F4: =ASSUMPTIONS!E20 -> Vacant | G4: =ASSUMPTIONS!F20 -> 1021 | H4: =ASSUMPTIONS!G20 -> 6800 | I4: =ASSUMPTIONS!H20 -> 81600
A5: =ASSUMPTIONS!A21 -> 2- (2R) | B5: =ASSUMPTIONS!B21 -> Free Market | C5: =ASSUMPTIONS!C21 -> 1 | E5: =ASSUMPTIONS!D21 -> No | F5: =ASSUMPTIONS!E21 -> Vacant | G5: =ASSUMPTIONS!F21 -> 510 | H5: =ASSUMPTIONS!G21 -> 3400 | I5: =ASSUMPTIONS!H21 -> 40800
A6: =ASSUMPTIONS!A22 -> 3- (2F) | B6: =ASSUMPTIONS!B22 -> Free Market | C6: =ASSUMPTIONS!C22 -> 1 | E6: =ASSUMPTIONS!D22 -> No | F6: =ASSUMPTIONS!E22 -> Vacant | G6: =ASSUMPTIONS!F22 -> 510 | H6: =ASSUMPTIONS!G22 -> 3400 | I6: =ASSUMPTIONS!H22 -> 40800
A7: =ASSUMPTIONS!A23 -> 4- (Ent 3rd Fl.) | B7: =ASSUMPTIONS!B23 -> Free Market | C7: =ASSUMPTIONS!C23 -> 2 | E7: =ASSUMPTIONS!D23 -> No | F7: =ASSUMPTIONS!E23 -> MTM | G7: =ASSUMPTIONS!F23 -> 1021 | H7: =ASSUMPTIONS!G23 -> 4000 | I7: =ASSUMPTIONS!H23 -> 48000
A8: =ASSUMPTIONS!A24 -> 5- (4R) | B8: =ASSUMPTIONS!B24 -> Free Market | C8: =ASSUMPTIONS!C24 -> 1 | E8: =ASSUMPTIONS!D24 -> Yes | F8: =ASSUMPTIONS!E24 -> Vacant | G8: =ASSUMPTIONS!F24 -> 414 | H8: =ASSUMPTIONS!G24 -> 2700 | I8: =ASSUMPTIONS!H24 -> 32400
A9: =ASSUMPTIONS!A25 -> 6- (4F) | B9: =ASSUMPTIONS!B25 -> Free Market | C9: =ASSUMPTIONS!C25 -> 1 | E9: =ASSUMPTIONS!D25 -> No | F9: =ASSUMPTIONS!E25 -> MTM | G9: =ASSUMPTIONS!F25 -> 414 | H9: =ASSUMPTIONS!G25 -> 2300 | I9: =ASSUMPTIONS!H25 -> 27600
A10: =ASSUMPTIONS!A26 -> 7- (Ent 5th Fl) | B10: =ASSUMPTIONS!B26 -> Free Market | C10: =ASSUMPTIONS!C26 -> 1 | E10: =ASSUMPTIONS!D26 -> Yes | F10: =ASSUMPTIONS!E26 -> 42428 | G10: =ASSUMPTIONS!F26 -> 482 | H10: =ASSUMPTIONS!G26 -> 2300 | I10: =ASSUMPTIONS!H26 -> 27600
F11: TOTAL | G11: =SUM(G4:G10) -> 4372 | H11: =SUM(H4:H10) -> 24900 | I11: =SUM(I4:I10) -> 298800
A14: WORKSPACE
A15: Anuuak Basis (#of months)
A16: Sum (Monthly Rent
A17: Sum (Annual Rent)
A18: Max Monthly Rent
A19: Min Monthly Rent
A20: Avg Rent
A21: Number of Units

Sheet Projected Rent Roll
A1: Rent Roll
A3: Unit | B3: Status | C3: # of Bedrooms | D3: Baths | E3: Terrace | F3: Lease Expiration | G3: Est. Square Footage | H3: Base Rent | I3: Annual Rent
A4: =ASSUMPTIONS!A20 -> 1- (Grnd Fl) | B4: =ASSUMPTIONS!B20 -> Free Market | C4: =ASSUMPTIONS!C20 -> 2 | E4: =ASSUMPTIONS!D20 -> No | F4: =ASSUMPTIONS!E20 -> Vacant | G4: =ASSUMPTIONS!F20 -> 1021 | H4: =ASSUMPTIONS!G20 -> 6800 | I4: =ASSUMPTIONS!H20 -> 81600
A5: =ASSUMPTIONS!A21 -> 2- (2R) | B5: =ASSUMPTIONS!B21 -> Free Market | C5: =ASSUMPTIONS!C21 -> 1 | E5: =ASSUMPTIONS!D21 -> No | F5: =ASSUMPTIONS!E21 -> Vacant | G5: =ASSUMPTIONS!F21 -> 510 | H5: =ASSUMPTIONS!G21 -> 3400 | I5: =ASSUMPTIONS!H21 -> 40800
A6: =ASSUMPTIONS!A22 -> 3- (2F) | B6: =ASSUMPTIONS!B22 -> Free Market | C6: =ASSUMPTIONS!C22 -> 1 | E6: =ASSUMPTIONS!D22 -> No | F6: =ASSUMPTIONS!E22 -> Vacant | G6: =ASSUMPTIONS!F22 -> 510 | H6: =ASSUMPTIONS!G22 -> 3400 | I6: =ASSUMPTIONS!H22 -> 40800
A7: =ASSUMPTIONS!A23 -> 4- (Ent 3rd Fl.) | B7: =ASSUMPTIONS!B23 -> Free Market | C7: =ASSUMPTIONS!C23 -> 2 | E7: =ASSUMPTIONS!D23 -> No | F7: =ASSUMPTIONS!E23 -> MTM | G7: =ASSUMPTIONS!F23 -> 1021 | H7: =ASSUMPTIONS!G23 -> 4000 | I7: =ASSUMPTIONS!H23 -> 48000
A8: =ASSUMPTIONS!A24 -> 5- (4R) | B8: =ASSUMPTIONS!B24 -> Free Market | C8: =ASSUMPTIONS!C24 -> 1 | E8: =ASSUMPTIONS!D24 -> Yes | F8: =ASSUMPTIONS!E24 -> Vacant | G8: =ASSUMPTIONS!F24 -> 414 | H8: =ASSUMPTIONS!G24 -> 2700 | I8: =ASSUMPTIONS!H24 -> 32400
A9: =ASSUMPTIONS!A25 -> 6- (4F) | B9: =ASSUMPTIONS!B25 -> Free Market | C9: =ASSUMPTIONS!C25 -> 1 | E9: =ASSUMPTIONS!D25 -> No | F9: =ASSUMPTIONS!E25 -> MTM | G9: =ASSUMPTIONS!F25 -> 414 | H9: =ASSUMPTIONS!G25 -> 2300 | I9: =ASSUMPTIONS!H25 -> 27600
A10: =ASSUMPTIONS!A26 -> 7- (Ent 5th Fl) | B10: =ASSUMPTIONS!B26 -> Free Market | C10: =ASSUMPTIONS!C26 -> 1 | E10: =ASSUMPTIONS!D26 -> Yes | F10: =ASSUMPTIONS!E26 -> 42428 | G10: =ASSUMPTIONS!F26 -> 482 | H10: =ASSUMPTIONS!G26 -> 2300 | I10: =ASSUMPTIONS!H26 -> 27600
F11: TOTAL | G11: =SUM(G4:G10) -> 4372 | H11: =SUM(H4:H10) -> 24900 | I11: =SUM(I4:I10) -> 298800
A15: avg | B15: =AVERAGE(H4:H10) -> 3557.1429
A16: min | B16: =MIN(H4:H10) -> 2300
A17: max | B17: =MAX(H4:H10) -> 6800
A18: median | B18: =MEDIAN(H4:H10) -> 3400
A19: count | B19: =COUNT(H4:H10) -> 7

Sheet OPERATING STATEMENT
A1: OPERATING STATEMENT
A3: Revenue | B3: Historical | C3: Projected
C4: Year 1 | D4: Year 2 | E4: Year 3 | F4: Year 4 | G4: Year 5 | H4: Year 6 | I4: Year 7 | J4: Year 8 | K4: Year 9 | L4: Year 10 | M4: Year 11
A5: Potential Gross Income | B5: =ASSUMPTIONS!B29 -> 298800 | C5: =B5 -> 298800 | D5: =C5*(1+ASSUMPTIONS!C86) -> 307764 | E5: =D5*(1+ASSUMPTIONS!D86) -> 316996.92 | F5: =E5*(1+ASSUMPTIONS!E86) -> 326506.83 | G5: =F5*(1+ASSUMPTIONS!F86) -> 336302.03 | H5: =G5*(1+ASSUMPTIONS!G86) -> 346391.09 | I5: =H5*(1+ASSUMPTIONS!H86) -> 356782.83 | J5: =I5*(1+ASSUMPTIONS!I86) -> 367486.31 | K5: =J5*(1+ASSUMPTIONS!J86) -> 378510.9 | ... M5: =L5*(1+ASSUMPTIONS!L86) -> 401562.21
A6: (Vacancy) | B6: =ASSUMPTIONS!B30 -> 195600 | C6: =C5*ASSUMPTIONS!B$85 -> 8964 | D6: =D5*ASSUMPTIONS!C$85 -> 9232.92 | E6: =E5*ASSUMPTIONS!D$85 -> 9509.9076 | F6: =F5*ASSUMPTIONS!E$85 -> 9795.2048 | G6: =G5*ASSUMPTIONS!F$85 -> 10089.061 | H6: =H5*ASSUMPTIONS!G$85 -> 10391.733 | I6: =I5*ASSUMPTIONS!H$85 -> 10703.485 | J6: =J5*ASSUMPTIONS!I$85 -> 11024.589 | ... M6: =M5*ASSUMPTIONS!L$85 -> 12046.866
A7: Effective Gross Income | B7: =B5-B6 -> 103200 | C7: =C5-C6 -> 289836 | D7: =D5-D6 -> 298531.08 | E7: =E5-E6 -> 307487.01 | F7: =F5-F6 -> 316711.62 | G7: =G5-G6 -> 326212.97 | H7: =H5-H6 -> 335999.36 | I7: =I5-I6 -> 346079.34 | ... M7: =M5-M6 -> 389515.35
A9: Expenses
A10: Real Estate Taxes | B10: =ASSUMPTIONS!C36 -> 58927 | C10: =ASSUMPTIONS!C69 -> 58927 | D10: =C10*(1+ASSUMPTIONS!C87) -> 60694.81 | E10: =D10*(1+ASSUMPTIONS!D87) -> 62515.654 | F10: =E10*(1+ASSUMPTIONS!E87) -> 64391.124 | G10: =F10*(1+ASSUMPTIONS!F87) -> 66322.858 | H10: =G10*(1+ASSUMPTIONS!G87) -> 68312.543 | I10: =H10*(1+ASSUMPTIONS!H87) -> 70361.92 | J10: =I10*(1+ASSUMPTIONS!I87) -> 72472.777 | K10: =J10*(1+ASSUMPTIONS!J87) -> 74646.961 | ... M10: =L10*(1+ASSUMPTIONS!L87) -> 79192.96
A11: Water & Sewer | B11: =ASSUMPTIONS!C37 -> 5380 | C11: =ASSUMPTIONS!C70 -> 5380 | D11: =C11*(1+ASSUMPTIONS!C87) -> 5541.4 | E11: =D11*(1+ASSUMPTIONS!D87) -> 5707.642 | F11: =E11*(1+ASSUMPTIONS!E87) -> 5878.8713 | G11: =F11*(1+ASSUMPTIONS!F87) -> 6055.2374 | H11: =G11*(1+ASSUMPTIONS!G87) -> 6236.8945 | I11: =H11*(1+ASSUMPTIONS!H87) -> 6424.0014 | J11: =I11*(1+ASSUMPTIONS!I87) -> 6616.7214 | K11: =J11*(1+ASSUMPTIONS!J87) -> 6815.223 | ... M11: =L11*(1+ASSUMPTIONS!L87) -> 7230.2701
A12: Insurance | B12: =ASSUMPTIONS!C38 -> 5380 | C12: =ASSUMPTIONS!C71 -> 5380 | D12: =C12*(1+ASSUMPTIONS!C87) -> 5541.4 | E12: =D12*(1+ASSUMPTIONS!D87) -> 5707.642 | F12: =E12*(1+ASSUMPTIONS!E87) -> 5878.8713 | G12: =F12*(1+ASSUMPTIONS!F87) -> 6055.2374 | H12: =G12*(1+ASSUMPTIONS!G87) -> 6236.8945 | I12: =H12*(1+ASSUMPTIONS!H87) -> 6424.0014 | J12: =I12*(1+ASSUMPTIONS!I87) -> 6616.7214 | K12: =J12*(1+ASSUMPTIONS!J87) -> 6815.223 | ... M12: =L12*(1+ASSUMPTIONS!L87) -> 7230.2701
A13: Fuel | B13: =ASSUMPTIONS!C39 -> 8877 | C13: =ASSUMPTIONS!C72 -> 8877 | D13: =C13*(1+ASSUMPTIONS!C87) -> 9143.31 | E13: =D13*(1+ASSUMPTIONS!D87) -> 9417.6093 | F13: =E13*(1+ASSUMPTIONS!E87) -> 9700.1376 | G13: =F13*(1+ASSUMPTIONS!F87) -> 9991.1417 | H13: =G13*(1+ASSUMPTIONS!G87) -> 10290.876 | I13: =H13*(1+ASSUMPTIONS!H87) -> 10599.602 | J13: =I13*(1+ASSUMPTIONS!I87) -> 10917.59 | K13: =J13*(1+ASSUMPTIONS!J87) -> 11245.118 | ... M13: =L13*(1+ASSUMPTIONS!L87) -> 11929.946
A14: Electric | B14: =ASSUMPTIONS!C40 -> 1883 | C14: =ASSUMPTIONS!C73 -> 1883 | D14: =C14*(1+ASSUMPTIONS!C87) -> 1939.49 | E14: =D14*(1+ASSUMPTIONS!D87) -> 1997.6747 | F14: =E14*(1+ASSUMPTIONS!E87) -> 2057.6049 | G14: =F14*(1+ASSUMPTIONS!F87) -> 2119.3331 | H14: =G14*(1+ASSUMPTIONS!G87) -> 2182.9131 | I14: =H14*(1+ASSUMPTIONS!H87) -> 2248.4005 | J14: =I14*(1+ASSUMPTIONS!I87) -> 2315.8525 | K14: =J14*(1+ASSUMPTIONS!J87) -> 2385.3281 | ... M14: =L14*(1+ASSUMPTIONS!L87) -> 2530.5945
A15: Repairs & Maintenance | B15: =ASSUMPTIONS!C41 -> 5380 | C15: =ASSUMPTIONS!C74 -> 5380 | D15: =C15*(1+ASSUMPTIONS!C87) -> 5541.4 | E15: =D15*(1+ASSUMPTIONS!D87) -> 5707.642 | F15: =E15*(1+ASSUMPTIONS!E87) -> 5878.8713 | G15: =F15*(1+ASSUMPTIONS!F87) -> 6055.2374 | H15: =G15*(1+ASSUMPTIONS!G87) -> 6236.8945 | I15: =H15*(1+ASSUMPTIONS!H87) -> 6424.0014 | J15: =I15*(1+ASSUMPTIONS!I87) -> 6616.7214 | K15: =J15*(1+ASSUMPTIONS!J87) -> 6815.223 | ... M15: =L15*(1+ASSUMPTIONS!L87) -> 7230.2701
A16: Payroll | B16: =ASSUMPTIONS!C42 -> 6000 | C16: =ASSUMPTIONS!C75 -> 6000 | D16: =C16*(1+ASSUMPTIONS!C87) -> 6180 | E16: =D16*(1+ASSUMPTIONS!D87) -> 6365.4 | F16: =E16*(1+ASSUMPTIONS!E87) -> 6556.362 | G16: =F16*(1+ASSUMPTIONS!F87) -> 6753.0529 | H16: =G16*(1+ASSUMPTIONS!G87) -> 6955.6444 | I16: =H16*(1+ASSUMPTIONS!H87) -> 7164.3138 | J16: =I16*(1+ASSUMPTIONS!I87) -> 7379.2432 | K16: =J16*(1+ASSUMPTIONS!J87) -> 7600.6205 | ... M16: =L16*(1+ASSUMPTIONS!L87) -> 8063.4983
A17: Management | B17: =ASSUMPTIONS!C43 -> 3096 | C17: =ASSUMPTIONS!C76 -> 8695.08 | D17: =C17*(1+ASSUMPTIONS!C87) -> 8955.9324 | E17: =D17*(1+ASSUMPTIONS!D87) -> 9224.6104 | F17: =E17*(1+ASSUMPTIONS!E87) -> 9501.3487 | G17: =F17*(1+ASSUMPTIONS!F87) -> 9786.3891 | H17: =G17*(1+ASSUMPTIONS!G87) -> 10079.981 | I17: =H17*(1+ASSUMPTIONS!H87) -> 10382.38 | J17: =I17*(1+ASSUMPTIONS!I87) -> 10693.852 | K17: =J17*(1+ASSUMPTIONS!J87) -> 11014.667 | ... M17: =L17*(1+ASSUMPTIONS!L87) -> 11685.46
A18: Total Operating Expenses | B18: =SUM(B10:B17) -> 94923 | C18: =SUM(C10:C17) -> 100522.08 | D18: =SUM(D10:D17) -> 103537.74 | E18: =SUM(E10:E17) -> 106643.87 | F18: =SUM(F10:F17) -> 109843.19 | G18: =SUM(G10:G17) -> 113138.49 | H18: =SUM(H10:H17) -> 116532.64 | I18: =SUM(I10:I17) -> 120028.62 | ... M18: =SUM(M10:M17) -> 135093.27
A20: Reserves for Capital Expenditures | B20: 0 | C20: =ASSUMPTIONS!C80 -> 26900 | D20: =C20*(1+ASSUMPTIONS!C89) -> 27707 | E20: =D20*(1+ASSUMPTIONS!D89) -> 28538.21 | F20: =E20*(1+ASSUMPTIONS!E89) -> 29394.356 | G20: =F20*(1+ASSUMPTIONS!F89) -> 30276.187 | H20: =G20*(1+ASSUMPTIONS!G89) -> 31184.473 | I20: =H20*(1+ASSUMPTIONS!H89) -> 32120.007 | J20: =I20*(1+ASSUMPTIONS!I89) -> 33083.607 | K20: =J20*(1+ASSUMPTIONS!J89) -> 34076.115 | ... M20: =L20*(1+ASSUMPTIONS!L89) -> 36151.351
A21: Tenant Improvements | B21: =ASSUMPTIONS!B81 -> 0 | C21: =ASSUMPTIONS!C81 -> 0 | D21: =ASSUMPTIONS!D81 -> 0 | E21: =ASSUMPTIONS!E81 -> 0 | F21: =ASSUMPTIONS!F81 -> 0 | G21: =ASSUMPTIONS!G81 -> 0 | H21: =ASSUMPTIONS!H81 -> 0 | I21: =ASSUMPTIONS!I81 -> 0 | ... M21: =ASSUMPTIONS!M81 -> 0
A22: Leasing Commissions | B22: =ASSUMPTIONS!B82 -> 0 | C22: =ASSUMPTIONS!C82 -> 0 | D22: =ASSUMPTIONS!D82 -> 0 | E22: =ASSUMPTIONS!E82 -> 0 | F22: =ASSUMPTIONS!F82 -> 0 | G22: =ASSUMPTIONS!G82 -> 0 | H22: =ASSUMPTIONS!H82 -> 0 | I22: =ASSUMPTIONS!I82 -> 0 | ... M22: =ASSUMPTIONS!M82 -> 0
A23: Total Reserves for Leasing and Capital Expenditures | C23: =SUM(C20:C22) -> 26900 | D23: =SUM(D20:D22) -> 27707 | E23: =SUM(E20:E22) -> 28538.21 | F23: =SUM(F20:F22) -> 29394.356 | G23: =SUM(G20:G22) -> 30276.187 | H23: =SUM(H20:H22) -> 31184.473 | I23: =SUM(I20:I22) -> 32120.007 | J23: =SUM(J20:J22) -> 33083.607 | ... M23: =SUM(M20:M22) -> 36151.351
A25: Net Operating Income | B25: =B7-B18 -> 8277 | C25: =C7-C18-C23 -> 162413.92 | D25: =D7-D18-D23 -> 167286.34 | E25: =E7-E18-E23 -> 172304.93 | F25: =F7-F18-F23 -> 177474.08 | G25: =G7-G18-G23 -> 182798.3 | H25: =H7-H18-H23 -> 188282.25 | I25: =I7-I18-I23 -> 193930.71 | J25: =J7-J18-J23 -> 199748.64 | ... M25: =M7-M18-M23 -> 218270.73
B26: In-Place Income

Sheet Sources and Uses
A1: Sources | B1: $ to Project Costs | C1: % to Project Costs
A2: Debt
A3: Loan | B3: ='Debt Financing'!B7 -> 1487500 | C3: =$B3/$B$7 -> 0.2336819
A4: Equity
A5: GP | B5: =SUM(ASSUMPTIONS!C129:C131) -> 975598.17 | C5: =$B5/$B$7 -> 0.15326362
A6: LP | B6: =ASSUMPTIONS!C132 -> 3902392.7 | C6: =$B6/$B$7 -> 0.61305448
A7: Total Sources | B7: =ASSUMPTIONS!F125 -> 6365490.8 | C7: =SUM(C3:C6) -> 1
A9: Uses
A10: Acquisition | B10: =ASSUMPTIONS!B5 -> 5950000 | C10: =$B10/$B$15 -> 0.9347276
A11: Indirect Costs | B11: ='Project Costs'!F16 -> 286520.85 | C11: =$B11/$B$15 -> 0.045011588
A12: Direct Costs | B12: ='Project Costs'!F20 -> 29590 | C12: =$B12/$B$15 -> 0.0046485025
A13: Financing Cost | B13: ='Project Costs'!F24 -> 59500 | C13: =$B13/$B$15 -> 0.009347276
A14: Markerting | B14: ='Project Costs'!F28 -> 39880 | C14: =$B14/$B$15 -> 0.0062650314
A15: Total Uses | B15: =SUM(B10:B14) -> 6365490.8 | C15: =SUM(C10:C14) -> 1

Sheet Debt Financing
A1: Year | B1: 1 | C1: 2 | D1: 3 | E1: 4 | F1: 5 | G1: 6 | H1: 7 | I1: 8 | J1: 9 | K1: 10 | L1: 11
A2: Interests | B2: =SUMIF($A$16:$A$375,B$1,$D$16:$D$375) -> 73876.6 | C2: =SUMIF($A$16:$A$375,C$1,$D$16:$D$375) -> 72753.798 | D2: =SUMIF($A$16:$A$375,D$1,$D$16:$D$375) -> 71573.551 | E2: =SUMIF($A$16:$A$375,E$1,$D$16:$D$375) -> 70332.921 | F2: =SUMIF($A$16:$A$375,F$1,$D$16:$D$375) -> 69028.818 | G2: =SUMIF($A$16:$A$375,G$1,$D$16:$D$375) -> 67657.994 | H2: =SUMIF($A$16:$A$375,H$1,$D$16:$D$375) -> 66217.036 | I2: =SUMIF($A$16:$A$375,I$1,$D$16:$D$375) -> 64702.356 | ... L2: =SUMIF($A$16:$A$375,L$1,$D$16:$D$375) -> 59677.291
A3: Principal | B3: =SUMIF($A$16:$A$375,B$1,$E$16:$E$375) -> 21946.06 | C3: =SUMIF($A$16:$A$375,C$1,$E$16:$E$375) -> 23068.862 | D3: =SUMIF($A$16:$A$375,D$1,$E$16:$E$375) -> 24249.108 | E3: =SUMIF($A$16:$A$375,E$1,$E$16:$E$375) -> 25489.739 | F3: =SUMIF($A$16:$A$375,F$1,$E$16:$E$375) -> 26793.842 | G3: =SUMIF($A$16:$A$375,G$1,$E$16:$E$375) -> 28164.666 | H3: =SUMIF($A$16:$A$375,H$1,$E$16:$E$375) -> 29605.624 | I3: =SUMIF($A$16:$A$375,I$1,$E$16:$E$375) -> 31120.304 | ... L3: =SUMIF($A$16:$A$375,L$1,$E$16:$E$375) -> 36145.368
A4: Debt Service | B4: =SUM(B2:B3) -> 95822.66 | C4: =SUM(C2:C3) -> 95822.66 | D4: =SUM(D2:D3) -> 95822.66 | E4: =SUM(E2:E3) -> 95822.66 | F4: =SUM(F2:F3) -> 95822.66 | G4: =SUM(G2:G3) -> 95822.66 | H4: =SUM(H2:H3) -> 95822.66 | I4: =SUM(I2:I3) -> 95822.66 | ... L4: =SUM(L2:L3) -> 95822.66
A7: Present Value of Loan Amount | B7: =ASSUMPTIONS!B92 -> 1487500
A8: Future Value of Loan Amount | B8: 0
A9: Rate of Interests | B9: =ASSUMPTIONS!B94 -> 0.05
A10: Number of Periods in Years | B10: =ASSUMPTIONS!B93 -> 30
A11: Monthyl Payement | B11: =-PMT(B9/12,B10*12,B7,B8,0) -> 7985.2216
A12: Annual Debt Service | B12: =B11*12 -> 95822.66
A15: Year | B15: Month | C15: Beginning Balance | D15: Interests Payment | E15: Principal Payment | F15: Monthly Payment | G15: Ending Balance
A16: =ROUNDUP(B16/12,0) -> 1 | B16: 1 | C16: =B7 -> 1487500 | D16: =-IPMT($B$9/12,$B16,$B$10*12,$B$7,$B$8,0) -> 6197.9167 | E16: =-PPMT($B$9/12,$B16,$B$10*12,$B$7,$B$8,0) -> 1787.305 | F16: =-PMT($B$9/12,$B$10*12,$B$7,$B$8,0) -> 7985.2216 | G16: =C16-E16 -> 1485712.7
A17: =ROUNDUP(B17/12,0) -> 1 | B17: 2 | C17: =G16 -> 1485712.7 | D17: =-IPMT($B$9/12,$B17,$B$10*12,$B$7,$B$8,0) -> 6190.4696 | E17: =-PPMT($B$9/12,$B17,$B$10*12,$B$7,$B$8,0) -> 1794.7521 | F17: =-PMT($B$9/12,$B$10*12,$B$7,$B$8,0) -> 7985.2216 | G17: =C17-E17 -> 1483917.9
A18: =ROUNDUP(B18/12,0) -> 1 | B18: 3 | C18: =G17 -> 1483917.9 | D18: =-IPMT($B$9/12,$B18,$B$10*12,$B$7,$B$8,0) -> 6182.9914 | E18: =-PPMT($B$9/12,$B18,$B$10*12,$B$7,$B$8,0) -> 1802.2302 | F18: =-PMT($B$9/12,$B$10*12,$B$7,$B$8,0) -> 7985.2216 | G18: =C18-E18 -> 1482115.7
A19: =ROUNDUP(B19/12,0) -> 1 | B19: 4 | C19: =G18 -> 1482115.7 | D19: =-IPMT($B$9/12,$B19,$B$10*12,$B$7,$B$8,0) -> 6175.4821 | E19: =-PPMT($B$9/12,$B19,$B$10*12,$B$7,$B$8,0) -> 1809.7395 | F19: =-PMT($B$9/12,$B$10*12,$B$7,$B$8,0) -> 7985.2216 | G19: =C19-E19 -> 1480306
A20: =ROUNDUP(B20/12,0) -> 1 | B20: 5 | C20: =G19 -> 1480306 | D20: =-IPMT($B$9/12,$B20,$B$10*12,$B$7,$B$8,0) -> 6167.9416 | E20: =-PPMT($B$9/12,$B20,$B$10*12,$B$7,$B$8,0) -> 1817.2801 | F20: =-PMT($B$9/12,$B$10*12,$B$7,$B$8,0) -> 7985.2216 | G20: =C20-E20 -> 1478488.7
A21: =ROUNDUP(B21/12,0) -> 1 | B21: 6 | C21: =G20 -> 1478488.7 | D21: =-IPMT($B$9/12,$B21,$B$10*12,$B$7,$B$8,0) -> 6160.3696 | E21: =-PPMT($B$9/12,$B21,$B$10*12,$B$7,$B$8,0) -> 1824.8521 | F21: =-PMT($B$9/12,$B$10*12,$B$7,$B$8,0) -> 7985.2216 | G21: =C21-E21 -> 1476663.8
A22: =ROUNDUP(B22/12,0) -> 1 | B22: 7 | C22: =G21 -> 1476663.8 | D22: =-IPMT($B$9/12,$B22,$B$10*12,$B$7,$B$8,0) -> 6152.766 | E22: =-PPMT($B$9/12,$B22,$B$10*12,$B$7,$B$8,0) -> 1832.4556 | F22: =-PMT($B$9/12,$B$10*12,$B$7,$B$8,0) -> 7985.2216 | G22: =C22-E22 -> 1474831.4
A23: =ROUNDUP(B23/12,0) -> 1 | B23: 8 | C23: =G22 -> 1474831.4 | D23: =-IPMT($B$9/12,$B23,$B$10*12,$B$7,$B$8,0) -> 6145.1308 | E23: =-PPMT($B$9/12,$B23,$B$10*12,$B$7,$B$8,0) -> 1840.0909 | F23: =-PMT($B$9/12,$B$10*12,$B$7,$B$8,0) -> 7985.2216 | G23: =C23-E23 -> 1472991.3
A24: =ROUNDUP(B24/12,0) -> 1 | B24: 9 | C24: =G23 -> 1472991.3 | D24: =-IPMT($B$9/12,$B24,$B$10*12,$B$7,$B$8,0) -> 6137.4637 | E24: =-PPMT($B$9/12,$B24,$B$10*12,$B$7,$B$8,0) -> 1847.7579 | F24: =-PMT($B$9/12,$B$10*12,$B$7,$B$8,0) -> 7985.2216 | G24: =C24-E24 -> 1471143.5
A25: =ROUNDUP(B25/12,0) -> 1 | B25: 10 | C25: =G24 -> 1471143.5 | D25: =-IPMT($B$9/12,$B25,$B$10*12,$B$7,$B$8,0) -> 6129.7647 | E25: =-PPMT($B$9/12,$B25,$B$10*12,$B$7,$B$8,0) -> 1855.4569 | F25: =-PMT($B$9/12,$B$10*12,$B$7,$B$8,0) -> 7985.2216 | G25: =C25-E25 -> 1469288.1
A26: =ROUNDUP(B26/12,0) -> 1 | B26: 11 | C26: =G25 -> 1469288.1 | D26: =-IPMT($B$9/12,$B26,$B$10*12,$B$7,$B$8,0) -> 6122.0337 | E26: =-PPMT($B$9/12,$B26,$B$10*12,$B$7,$B$8,0) -> 1863.188 | F26: =-PMT($B$9/12,$B$10*12,$B$7,$B$8,0) -> 7985.2216 | G26: =C26-E26 -> 1467424.9
A27: =ROUNDUP(B27/12,0) -> 1 | B27: 12 | C27: =G26 -> 1467424.9 | D27: =-IPMT($B$9/12,$B27,$B$10*12,$B$7,$B$8,0) -> 6114.2704 | E27: =-PPMT($B$9/12,$B27,$B$10*12,$B$7,$B$8,0) -> 1870.9513 | F27: =-PMT($B$9/12,$B$10*12,$B$7,$B$8,0) -> 7985.2216 | G27: =C27-E27 -> 1465553.9
A28: =ROUNDUP(B28/12,0) -> 2 | B28: 13 | C28: =G27 -> 1465553.9 | D28: =-IPMT($B$9/12,$B28,$B$10*12,$B$7,$B$8,0) -> 6106.4748 | E28: =-PPMT($B$9/12,$B28,$B$10*12,$B$7,$B$8,0) -> 1878.7469 | F28: =-PMT($B$9/12,$B$10*12,$B$7,$B$8,0) -> 7985.2216 | G28: =C28-E28 -> 1463675.2
... A315: =ROUNDUP(B315/12,0) -> 25 | B315: 300 | C315: =G314 -> 429338.84 | D315: =-IPMT($B$9/12,$B315,$B$10*12,$B$7,$B$8,0) -> 1788.9119 | E315: =-PPMT($B$9/12,$B315,$B$10*12,$B$7,$B$8,0) -> 6196.3098 | F315: =-PMT($B$9/12,$B$10*12,$B$7,$B$8,0) -> 7985.2216 | G315: =C315-E315 -> 423142.53

Sheet Project Costs
A1: Project Cost
A2: =ASSUMPTIONS!A99 -> Land and Exisiting Building
B3: =ASSUMPTIONS!B100 -> Acquistion Cost | C3: =ASSUMPTIONS!C100 -> 1105.948 | D3: SF | F3: =ASSUMPTIONS!F100 -> 5950000
A5: =ASSUMPTIONS!A101 -> Soft Costs
B6: {=ASSUMPTIONS!B102:B111} -> Architectural Fees | C6: {=ASSUMPTIONS!C102:C104} -> 0.0005 | E6: {=ASSUMPTIONS!E102:E110} -> 2975
B7: Engineering Fees | C7: 0.0005 | E7: 2975
B8: Acquistion Fees | C8: 0.03 | E8: 178500
B9: Consultants | E9: 5000
B10: Apprasial Fees | E10: 2000
B11: Legal and Accounting Fees | E11: 10000
B12: Real Estate Taxes | E12: 58927
B13: Insurance Costs | E13: 10000
B14: Building Permit Fees | E14: 2500
B15: Contingency | C15: =ASSUMPTIONS!C111 -> 0.05 | E15: =ASSUMPTIONS!E111 -> 13643.85
F16: =ASSUMPTIONS!F112 -> 286520.85
A17: =ASSUMPTIONS!A113 -> Direct Costs
B18: {=ASSUMPTIONS!B114:B115} -> Construction Costs | C18: {=ASSUMPTIONS!C114:C115} -> 5 | D18: SF | E18: {=ASSUMPTIONS!E114:E115} -> 26900
B19: Contigency | C19: 0.1 | E19: 2690
F20: =ASSUMPTIONS!F116 -> 29590
A21: =ASSUMPTIONS!A117 -> Financing Costs
B22: {=ASSUMPTIONS!B118:B119} -> Broker Fee | C22: {=ASSUMPTIONS!C118:C119} -> 0.01 | E22: {=ASSUMPTIONS!E118:E119} -> 14875
B23: Closing Costs | C23: 0.03 | E23: 44625
F24: =ASSUMPTIONS!F120 -> 59500
A25: =ASSUMPTIONS!A121 -> Marketing
B26: {=ASSUMPTIONS!B122:B123} -> Advertising | E26: {=ASSUMPTIONS!E122:E123} -> 10000
B27: Residential Commisions | C27: =ASSUMPTIONS!C123 -> 0.1 | E27: 29880
F28: =ASSUMPTIONS!F124 -> 39880
A29: =ASSUMPTIONS!A125 -> Total Project Cost | F29: =ASSUMPTIONS!F125 -> 6365490.8

Sheet Sale of Property
A1: Sale of Property
A3: Seling Price (Year 10) | B3: ='OPERATING STATEMENT'!M25/ASSUMPTIONS!B137 -> 5456768.2
A5: Gross Sale Price | B5: =B3 -> 5456768.2
A6: closing cost | B6: =B5*ASSUMPTIONS!B138 -> 272838.41
A7: disposition fee | B7: =B5*ASSUMPTIONS!B139 -> 163703.05
A8: Net Sale Price | B8: =B5-B6-B7 -> 5020226.7
A9: RMB (YR 10) | B9: ='Debt Financing'!G135 -> 1209963.2
A10: BTER | B10: =B8-B9 -> 3810263.5

Sheet Est Property Value
A2: Unlevered Cash Flow
A3: Year | B3: 1 | C3: 2 | D3: 3 | E3: 4 | F3: 5 | G3: 6 | H3: 7 | I3: 8 | J3: 9 | K3: 10
A4: Cash Outflow
A5: Total Project Cost | B5: =ASSUMPTIONS!F125 -> 6365490.8
A6: Cash Inflow
A7: NOI | B7: ='OPERATING STATEMENT'!C25 -> 162413.92 | C7: ='OPERATING STATEMENT'!D25 -> 167286.34 | D7: ='OPERATING STATEMENT'!E25 -> 172304.93 | E7: ='OPERATING STATEMENT'!F25 -> 177474.08 | F7: ='OPERATING STATEMENT'!G25 -> 182798.3 | G7: ='OPERATING STATEMENT'!H25 -> 188282.25 | H7: ='OPERATING STATEMENT'!I25 -> 193930.71 | I7: ='OPERATING STATEMENT'!J25 -> 199748.64 | ... K7: ='OPERATING STATEMENT'!L25 -> 211913.33
A8: Net Sale Proceeds | K8: ='Sale of Property'!B8 -> 5020226.7
A9: Total Cash Flows | B9: =SUM(B7:B8) -> 162413.92 | C9: =SUM(C7:C8) -> 167286.34 | D9: =SUM(D7:D8) -> 172304.93 | E9: =SUM(E7:E8) -> 177474.08 | F9: =SUM(F7:F8) -> 182798.3 | G9: =SUM(G7:G8) -> 188282.25 | H9: =SUM(H7:H8) -> 193930.71 | I9: =SUM(I7:I8) -> 199748.64 | ... K9: =SUM(K7:K8) -> 5232140.1
A12: Estimated Property Value
A13: Discount Rate | B13: Present Value of Future | C13: Going in Cap Rate
A14: 0.04 | B14: =NPV($A14,B$9:K$9) -> 4887289 | C14: =$B$9/$B14 -> 0.033231904
A15: 0.05 | B15: =NPV($A15,B$9:K$9) -> 4502715.1 | C15: =$B$9/$B15 -> 0.036070219
A16: 0.06 | B16: =NPV($A16,B$9:K$9) -> 4154357.9 | C16: =$B$9/$B16 -> 0.039094831
A17: 0.07 | B17: =NPV($A17,B$9:K$9) -> 3838432.5 | C17: =$B$9/$B17 -> 0.042312564
A18: 0.08 | B18: =NPV($A18,B$9:K$9) -> 3551583.1 | C18: =$B$9/$B18 -> 0.045730006
A19: 0.09 | B19: =NPV($A19,B$9:K$9) -> 3290831.5 | C19: =$B$9/$B19 -> 0.04935346
A20: 0.1 | B20: =NPV($A20,B$9:K$9) -> 3053530.5 | C20: =$B$9/$B20 -> 0.053188897
A21: 0.11 | B21: =NPV($A21,B$9:K$9) -> 2837325.4 | C21: =$B$9/$B21 -> 0.057241908
A22: 0.12 | B22: =NPV($A22,B$9:K$9) -> 2640118.5 | C22: =$B$9/$B22 -> 0.061517663
A23: 0.13 | B23: =NPV($A23,B$9:K$9) -> 2460039.4 | C23: =$B$9/$B23 -> 0.066020862
A24: 0.14 | B24: =NPV($A24,B$9:K$9) -> 2295418.2 | C24: =$B$9/$B24 -> 0.070755699
A25: 0.15 | B25: =NPV($A25,B$9:K$9) -> 2144762.7 | C25: =$B$9/$B25 -> 0.075725822
... A30: 0.2 | B30: =NPV($A30,B$9:K$9) -> 1558806.3 | C30: =$B$9/$B30 -> 0.10419121
A33: Levered Cash Flow
A34: Year | B34: 1 | C34: 2 | D34: 3 | E34: 4 | F34: 5 | G34: 6 | H34: 7 | I34: 8 | J34: 9 | K34: 10
A35: Cash Outflow | B35: =ASSUMPTIONS!F125 -> 6365490.8
A36: Total Project Cost
A37: Debt Service | B37: ='Debt Financing'!B4 -> 95822.66 | C37: ='Debt Financing'!C4 -> 95822.66 | D37: ='Debt Financing'!D4 -> 95822.66 | E37: ='Debt Financing'!E4 -> 95822.66 | F37: ='Debt Financing'!F4 -> 95822.66 | G37: ='Debt Financing'!G4 -> 95822.66 | H37: ='Debt Financing'!H4 -> 95822.66 | I37: ='Debt Financing'!I4 -> 95822.66 | ... K37: ='Debt Financing'!K4 -> 95822.66
A38: Cash Inflows
A39: NOI | B39: ='OPERATING STATEMENT'!C25 -> 162413.92 | C39: ='OPERATING STATEMENT'!D25 -> 167286.34 | D39: ='OPERATING STATEMENT'!E25 -> 172304.93 | E39: ='OPERATING STATEMENT'!F25 -> 177474.08 | F39: ='OPERATING STATEMENT'!G25 -> 182798.3 | G39: ='OPERATING STATEMENT'!H25 -> 188282.25 | H39: ='OPERATING STATEMENT'!I25 -> 193930.71 | I39: ='OPERATING STATEMENT'!J25 -> 199748.64 | ... K39: ='OPERATING STATEMENT'!L25 -> 211913.33
A40: Net Sale Proceeds | K40: ='Sale of Property'!B10 -> 3810263.5
A41: Total Cash Flows | B41: =(B$39+B$40)-B$37 -> 66591.26 | C41: =(C$39+C$40)-C$37 -> 71463.678 | D41: =(D$39+D$40)-D$37 -> 76482.268 | E41: =(E$39+E$40)-E$37 -> 81651.416 | F41: =(F$39+F$40)-F$37 -> 86975.638 | G41: =(G$39+G$40)-G$37 -> 92459.587 | H41: =(H$39+H$40)-H$37 -> 98108.054 | I41: =(I$39+I$40)-I$37 -> 103925.98 | ... K41: =(K$39+K$40)-K$37 -> 3926354.2
A44: Estimated Property Value
A45: Discount Rate | B45: Present Value of Future | C45: Total Costs Including Acquistion
A46: 0.1 | B46: =NPV(A46,B$41:K$41) -> 1998248.6 | C46: =$B46+'Debt Financing'!B7 -> 3485748.6
A47: 0.11 | B47: =NPV(A47,B$41:K$41) -> 1846873.3 | C47: =$B47+'Debt Financing'!B8 -> 1846873.3
A48: 0.12 | B48: =NPV(A48,B$41:K$41) -> 1709123.3 | C48: =$B48+'Debt Financing'!B9 -> 1709123.4
A49: 0.13 | B49: =NPV(A49,B$41:K$41) -> 1583641.2 | C49: =$B49+'Debt Financing'!B10 -> 1583671.2
A50: 0.14 | B50: =NPV(A50,B$41:K$41) -> 1469216 | C50: =$B50+'Debt Financing'!B11 -> 1477201.3
A51: 0.15 | B51: =NPV(A51,B$41:K$41) -> 1364766.6 | C51: =$B51+'Debt Financing'!B12 -> 1460589.2
...

Sheet IRR
A1: Unlevered Cash Flow
A2: Year | B2: 0 | C2: 1 | D2: 2 | E2: 3 | F2: 4 | G2: 5 | H2: 6 | I2: 7 | J2: 8 | K2: 9 | L2: 10
A3: Cash Outflow
A4: Total Project Cost | B4: =-(ASSUMPTIONS!F125-ASSUMPTIONS!F120) -> -6305990.8
A5: Cash Inflows
A6: NOI | C6: ='OPERATING STATEMENT'!C25 -> 162413.92 | D6: ='OPERATING STATEMENT'!D25 -> 167286.34 | E6: ='OPERATING STATEMENT'!E25 -> 172304.93 | F6: ='OPERATING STATEMENT'!F25 -> 177474.08 | G6: ='OPERATING STATEMENT'!G25 -> 182798.3 | H6: ='OPERATING STATEMENT'!H25 -> 188282.25 | I6: ='OPERATING STATEMENT'!I25 -> 193930.71 | J6: ='OPERATING STATEMENT'!J25 -> 199748.64 | ... L6: ='OPERATING STATEMENT'!L25 -> 211913.33
A7: Net Sales Proceeds | L7: ='Sale of Property'!B8 -> 5020226.7
A8: Total Cash Flows | B8: =SUM(B4:B7) -> -6305990.8 | C8: =SUM(C6:C7) -> 162413.92 | D8: =SUM(D6:D7) -> 167286.34 | E8: =SUM(E6:E7) -> 172304.93 | F8: =SUM(F6:F7) -> 177474.08 | G8: =SUM(G6:G7) -> 182798.3 | H8: =SUM(H6:H7) -> 188282.25 | I8: =SUM(I6:I7) -> 193930.71 | J8: =SUM(J6:J7) -> 199748.64 | ... L8: =SUM(L6:L7) -> 5232140.1
A10: Discount Rate | B10: =ASSUMPTIONS!B142 -> 0.1
A11: NPV | B11: =NPV(B10,C8:L8)+B8 -> -3252460.3
A12: IRR | B12: =IRR(B8:L8) -> 0.0099624749
A15: Levered Cash Flow
A16: Year | B16: 0 | C16: 1 | D16: 2 | E16: 3 | F16: 4 | G16: 5 | H16: 6 | I16: 7 | J16: 8 | K16: 9 | L16: 10
A17: Cash Outflow
A18: Equity | B18: =-(ASSUMPTIONS!F125-'Debt Financing'!B7) -> -4877990.8
A19: Debt Service | C19: =-'Debt Financing'!B4 -> -95822.66 | D19: =-'Debt Financing'!C4 -> -95822.66 | E19: =-'Debt Financing'!D4 -> -95822.66 | F19: =-'Debt Financing'!E4 -> -95822.66 | G19: =-'Debt Financing'!F4 -> -95822.66 | H19: =-'Debt Financing'!G4 -> -95822.66 | I19: =-'Debt Financing'!H4 -> -95822.66 | J19: =-'Debt Financing'!I4 -> -95822.66 | ... L19: =-'Debt Financing'!K4 -> -95822.66
A20: Cash Inflows
A21: NOI | C21: ='OPERATING STATEMENT'!C25 -> 162413.92 | D21: ='OPERATING STATEMENT'!D25 -> 167286.34 | E21: ='OPERATING STATEMENT'!E25 -> 172304.93 | F21: ='OPERATING STATEMENT'!F25 -> 177474.08 | G21: ='OPERATING STATEMENT'!G25 -> 182798.3 | H21: ='OPERATING STATEMENT'!H25 -> 188282.25 | I21: ='OPERATING STATEMENT'!I25 -> 193930.71 | J21: ='OPERATING STATEMENT'!J25 -> 199748.64 | ... L21: ='OPERATING STATEMENT'!L25 -> 211913.33
A22: BTER | L22: ='Sale of Property'!B10 -> 3810263.5
A23: Total Cash Flows | B23: =SUM(B18:B22) -> -4877990.8 | C23: =SUM(C19:C22) -> 66591.26 | D23: =SUM(D19:D22) -> 71463.678 | E23: =SUM(E19:E22) -> 76482.268 | F23: =SUM(F19:F22) -> 81651.416 | G23: =SUM(G19:G22) -> 86975.638 | H23: =SUM(H19:H22) -> 92459.587 | I23: =SUM(I19:I22) -> 98108.054 | J23: =SUM(J19:J22) -> 103925.98 | ... L23: =SUM(L19:L22) -> 3926354.2
A25: Discount Rate | B25: =ASSUMPTIONS!B143 -> 0.14
A26: NPV | B26: =NPV(B25,C23:L23)+B23 -> -3408774.8
A27: IRR | B27: =IRR(B23:L23) -> -0.0036953185
