Workbook
Name Scenarios: Formulas!$C$4:$C$6

Sheet Profile
A1: © Person0811. All rights reserved.
A2: MENU | B2: Advanced Financial Projection & Analysis Model
C3: This advanced financial model offers up to 10 years of projections, providing detailed insights for strategic planning. The template includes: - A scenario-based approach - 3-Statement financial model for the first year - Up to 10-year forecast analysis - Budget vs. actual variance analysis - Breakeven analysis - Financial ratios and business valuation - Professional chart presentations
C4: Table of Contents | E4: Profile
C5: Summary | E5: Business Type | F5: Financial
C6: Valuation | E6: Company Name | F6: Person0811
C7: Dashboard | E7: Country | F7: Switzerland
C8: Revenue | E8: Financial Year | F8: 2025
C9: Scenario | E9: Periods | F9: 10
C10: Actual Financial Statement | E10: Currency | F10: USD
C11: 12-Month Projection
C12: Variance Analysis
C13: Annual Forecast
C14: Breakeven Analysis | E14: Note:
C15: Ratio Analysis | E15: data | F15: input data only in blue cells like this

Sheet Summary
A1: © Person0811. All rights reserved.
A2: MENU | B2: =Profile!F6 -> Person0811
C4: Executive Summary
C5: =Formulas!A3 -> Amounts in USD
C6: Case Scenario | D6: =Scenario!E6 -> Base Case
C7: Key Financials | E7: =Profile!F8 -> 2025 | F7: =Formulas!D9 -> 2026 | G7: =Formulas!E9 -> 2027 | H7: =Formulas!F9 -> 2028 | I7: =Formulas!G9 -> 2029 | J7: =Formulas!H9 -> 2030 | K7: =Formulas!I9 -> 2031 | L7: =Formulas!J9 -> 2032 | M7: =Formulas!K9 -> 2033 | N7: =Formulas!L9 -> 2034
C9: Revenue | E9: ='Annual Forecast'!H10 -> 444500 | F9: ='Annual Forecast'!I10 -> 471170 | G9: ='Annual Forecast'!J10 -> 494728.5 | H9: ='Annual Forecast'!K10 -> 514517.64 | I9: ='Annual Forecast'!L10 -> 529953.17 | J9: ='Annual Forecast'!M10 -> 545851.76 | K9: ='Annual Forecast'!N10 -> 556768.8 | L9: ='Annual Forecast'!O10 -> 567904.18 | ... N9: ='Annual Forecast'!Q10 -> 590847.5
C10: Gross Profit | E10: ='Annual Forecast'!H18 -> 211137.5 | F10: ='Annual Forecast'!I18 -> 181400.45 | G10: ='Annual Forecast'!J18 -> 200365.04 | H10: ='Annual Forecast'!K18 -> 218670 | I10: ='Annual Forecast'!L18 -> 227879.86 | J10: ='Annual Forecast'!M18 -> 245633.29 | K10: ='Annual Forecast'!N18 -> 250545.96 | L10: ='Annual Forecast'!O18 -> 266914.96 | ... N10: ='Annual Forecast'!Q18 -> 280652.56
C11: Gross Profit Margin | E11: =IFERROR('Annual Forecast'!H19, "") -> 0.475 | F11: =IFERROR('Annual Forecast'!I19, "") -> 0.385 | G11: =IFERROR('Annual Forecast'!J19, "") -> 0.405 | H11: =IFERROR('Annual Forecast'!K19, "") -> 0.425 | I11: =IFERROR('Annual Forecast'!L19, "") -> 0.43 | J11: =IFERROR('Annual Forecast'!M19, "") -> 0.45 | K11: =IFERROR('Annual Forecast'!N19, "") -> 0.45 | L11: =IFERROR('Annual Forecast'!O19, "") -> 0.47 | ... N11: =IFERROR('Annual Forecast'!Q19, "") -> 0.475
C12: EBITDA | E12: ='Annual Forecast'!H29+'Annual Forecast'!H25 -> 104801.5 | F12: ='Annual Forecast'!I29+'Annual Forecast'!I25 -> 73784.29 | G12: ='Annual Forecast'!J29+'Annual Forecast'!J25 -> 94091.717 | H12: ='Annual Forecast'!K29+'Annual Forecast'!K25 -> 111545.74 | I12: ='Annual Forecast'!L29+'Annual Forecast'!L25 -> 120091.88 | J12: ='Annual Forecast'!M29+'Annual Forecast'!M25 -> 137161.67 | K12: ='Annual Forecast'!N29+'Annual Forecast'!N25 -> 144388.75 | L12: ='Annual Forecast'!O29+'Annual Forecast'!O25 -> 160334.6 | ... N12: ='Annual Forecast'!Q29+'Annual Forecast'!Q25 -> 173200.36
C13: Net Income | E13: ='Annual Forecast'!H36 -> 70583.137 | F13: ='Annual Forecast'!I36 -> 46776.03 | G13: ='Annual Forecast'!J36 -> 61265.553 | H13: ='Annual Forecast'!K36 -> 73946.577 | I13: ='Annual Forecast'!L36 -> 79374.697 | J13: ='Annual Forecast'!M36 -> 90823.764 | K13: ='Annual Forecast'!N36 -> 96224.13 | L13: ='Annual Forecast'!O36 -> 109030.25 | ... N13: ='Annual Forecast'!Q36 -> 121170.23
C14: Net Profit Margin | E14: =IFERROR('Annual Forecast'!H19,"") -> 0.475 | F14: =IFERROR('Annual Forecast'!I19,"") -> 0.385 | G14: =IFERROR('Annual Forecast'!J19,"") -> 0.405 | H14: =IFERROR('Annual Forecast'!K19,"") -> 0.425 | I14: =IFERROR('Annual Forecast'!L19,"") -> 0.43 | J14: =IFERROR('Annual Forecast'!M19,"") -> 0.45 | K14: =IFERROR('Annual Forecast'!N19,"") -> 0.45 | L14: =IFERROR('Annual Forecast'!O19,"") -> 0.47 | ... N14: =IFERROR('Annual Forecast'!Q19,"") -> 0.475
C16: Cumulative Cash Flow | E16: ='Annual Forecast'!H92 -> 172720.6 | F16: ='Annual Forecast'!I92 -> 201830.79 | G16: ='Annual Forecast'!J92 -> 244850.41 | H16: ='Annual Forecast'!K92 -> 295788.44 | I16: ='Annual Forecast'!L92 -> 353977.78 | J16: ='Annual Forecast'!M92 -> 424755.89 | K16: ='Annual Forecast'!N92 -> 495824.65 | L16: ='Annual Forecast'!O92 -> 584949.77 | ... N16: ='Annual Forecast'!Q92 -> 773696.06
C17: Free Cash Flow | E17: =Valuation!K17 -> 21473.719 | F17: =Valuation!L17 -> 44151.592 | G17: =Valuation!M17 -> 59959.454 | H17: =Valuation!N17 -> 69505.017 | I17: =Valuation!O17 -> 77295.546 | J17: =Valuation!P17 -> 91326.679 | K17: =Valuation!Q17 -> 92152.371 | L17: =Valuation!R17 -> 111854.66 | ... N17: =Valuation!T17 -> 123915.21
C18: EV/Revenue | E18: =IFERROR(Valuation!$K$40/E9,0) -> 0.64629787 | F18: =IFERROR(Valuation!$K$40/F9,0) -> 0.60971497 | G18: =IFERROR(Valuation!$K$40/G9,0) -> 0.58068092 | H18: =IFERROR(Valuation!$K$40/H9,0) -> 0.55834704 | I18: =IFERROR(Valuation!$K$40/I9,0) -> 0.54208451 | J18: =IFERROR(Valuation!$K$40/J9,0) -> 0.52629564 | K18: =IFERROR(Valuation!$K$40/K9,0) -> 0.51597611 | L18: =IFERROR(Valuation!$K$40/L9,0) -> 0.50585894 | ... N18: =IFERROR(Valuation!$K$40/N9,0) -> 0.48621582
C19: EV/EBITDA | E19: =IFERROR(Valuation!$K$40/E12,0) -> 2.7411764 | F19: =IFERROR(Valuation!$K$40/F12,0) -> 3.8935036 | G19: =IFERROR(Valuation!$K$40/G12,0) -> 3.0531848 | H19: =IFERROR(Valuation!$K$40/H12,0) -> 2.5754404 | I19: =IFERROR(Valuation!$K$40/I12,0) -> 2.3921635 | J19: =IFERROR(Valuation!$K$40/J12,0) -> 2.0944584 | K19: =IFERROR(Valuation!$K$40/K12,0) -> 1.9896246 | L19: =IFERROR(Valuation!$K$40/L12,0) -> 1.7917492 | ... N19: =IFERROR(Valuation!$K$40/N12,0) -> 1.6586536
C21: Return on Equity (ROE) | E21: =IFERROR(Formulas!C213,"") -> 0.41520551 | F21: =IFERROR(Formulas!D213,"") -> 0.22300286 | G21: =IFERROR(Formulas!E213,"") -> 0.23398891 | H21: =IFERROR(Formulas!F213,"") -> 0.22774825 | I21: =IFERROR(Formulas!G213,"") -> 0.20240691 | J21: =IFERROR(Formulas!H213,"") -> 0.1935079 | K21: =IFERROR(Formulas!I213,"") -> 0.17458956 | L21: =IFERROR(Formulas!J213,"") -> 0.16934883 | ... N21: =IFERROR(Formulas!L213,"") -> 0.14363565
C22: Return on Capital Employed (ROCE) | E22: =IFERROR(Formulas!C215,"") -> 0.32426125 | F22: =IFERROR(Formulas!D215,"") -> 0.18881148 | G22: =IFERROR(Formulas!E215,"") -> 0.20639391 | H22: =IFERROR(Formulas!F215,"") -> 0.20785802 | I22: =IFERROR(Formulas!G215,"") -> 0.18968494 | J22: =IFERROR(Formulas!H215,"") -> 0.18477365 | K22: =IFERROR(Formulas!I215,"") -> 0.16916169 | L22: =IFERROR(Formulas!J215,"") -> 0.16580009 | ... N22: =IFERROR(Formulas!L215,"") -> 0.14267781

Sheet Valuation
A1: © Person0811. All rights reserved.
A2: MENU | B2: =Profile!F6 -> Person0811
C4: Business Valuation
C5: =Formulas!A3 -> Amounts in USD
D6: Case Scenario | E6: =Scenario!E6 -> Base Case
C7: Discounted Cash Flow | K7: =Profile!F8 -> 2025 | L7: =Formulas!D9 -> 2026 | M7: =Formulas!E9 -> 2027 | N7: =Formulas!F9 -> 2028 | O7: =Formulas!G9 -> 2029 | P7: =Formulas!H9 -> 2030 | Q7: =Formulas!I9 -> 2031 | R7: =Formulas!J9 -> 2032 | S7: =Formulas!K9 -> 2033 | T7: =Formulas!L9 -> 2034
D9: EBT | K9: ='Annual Forecast'!H33 -> 94110.849 | L9: ='Annual Forecast'!I33 -> 62368.04 | M9: ='Annual Forecast'!J33 -> 81687.404 | N9: ='Annual Forecast'!K33 -> 98595.435 | O9: ='Annual Forecast'!L33 -> 105832.93 | P9: ='Annual Forecast'!M33 -> 121098.35 | Q9: ='Annual Forecast'!N33 -> 128298.84 | R9: ='Annual Forecast'!O33 -> 145373.67 | ... T9: ='Annual Forecast'!Q33 -> 161560.3
D10: Interest | K10: ='Annual Forecast'!H32 -> 3165.6506 | L10: ='Annual Forecast'!I32 -> 3025 | M10: ='Annual Forecast'!J32 -> 2750 | N10: ='Annual Forecast'!K32 -> 2475 | O10: ='Annual Forecast'!L32 -> 2200 | P10: ='Annual Forecast'!M32 -> 1925 | Q10: ='Annual Forecast'!N32 -> 1650 | R10: ='Annual Forecast'!O32 -> 1375 | ... T10: ='Annual Forecast'!Q32 -> 825
C11: EBIT | K11: =SUM(K9+K10) -> 97276.5 | L11: =SUM(L9+L10) -> 65393.04 | M11: =SUM(M9+M10) -> 84437.404 | N11: =SUM(N9+N10) -> 101070.44 | O11: =SUM(O9+O10) -> 108032.93 | P11: =SUM(P9+P10) -> 123023.35 | Q11: =SUM(Q9+Q10) -> 129948.84 | R11: =SUM(R9+R10) -> 146748.67 | ... T11: =SUM(T9+T10) -> 162385.3
D12: Less: Cash Taxes | K12: ='Annual Forecast'!H35 -> 23527.712 | L12: ='Annual Forecast'!I35 -> 15592.01 | M12: ='Annual Forecast'!J35 -> 20421.851 | N12: ='Annual Forecast'!K35 -> 24648.859 | O12: ='Annual Forecast'!L35 -> 26458.232 | P12: ='Annual Forecast'!M35 -> 30274.588 | Q12: ='Annual Forecast'!N35 -> 32074.71 | R12: ='Annual Forecast'!O35 -> 36343.416 | ... T12: ='Annual Forecast'!Q35 -> 40390.075
D13: Plus: Depreciation and Amortization | K13: ='Annual Forecast'!H25 -> 7525 | L13: ='Annual Forecast'!I25 -> 8391.25 | M13: ='Annual Forecast'!J25 -> 9654.3125 | N13: ='Annual Forecast'!K25 -> 10475.303 | O13: ='Annual Forecast'!L25 -> 12058.947 | P13: ='Annual Forecast'!M25 -> 14138.316 | Q13: ='Annual Forecast'!N25 -> 14439.905 | R13: ='Annual Forecast'!O25 -> 13585.938 | ... T13: ='Annual Forecast'!Q25 -> 10815.059
C14: EBITDA | K14: =K11-K12+K13 -> 81273.788 | L14: =L11-L12+L13 -> 58192.28 | M14: =M11-M12+M13 -> 73669.866 | N14: =N11-N12+N13 -> 86896.88 | O14: =O11-O12+O13 -> 93633.644 | P14: =P11-P12+P13 -> 106887.08 | Q14: =Q11-Q12+Q13 -> 112314.04 | R14: =R11-R12+R13 -> 123991.19 | ... T14: =T11-T12+T13 -> 132810.28
D15: Less: Capex | K15: =-'Annual Forecast'!H81 -> 21500 | L15: =-'Annual Forecast'!I81 -> 10000 | M15: =-'Annual Forecast'!J81 -> 12000 | N15: =-'Annual Forecast'!K81 -> 12000 | O15: =-'Annual Forecast'!L81 -> 15000 | P15: =-'Annual Forecast'!M81 -> 18000 | Q15: =-'Annual Forecast'!N81 -> 15000 | R15: =-'Annual Forecast'!O81 -> 12000 | ... T15: =-'Annual Forecast'!Q81 -> 8000
D16: Less: Changes in Working Capital | K16: =-SUM('Annual Forecast'!H74:H77) -> 38300.068 | L16: =-SUM('Annual Forecast'!I74:I77) -> 4040.6877 | M16: =-SUM('Annual Forecast'!J74:J77) -> 1710.4116 | N16: =-SUM('Annual Forecast'!K74:K77) -> 5391.8629 | O16: =-SUM('Annual Forecast'!L74:L77) -> 1338.0983 | P16: =-SUM('Annual Forecast'!M74:M77) -> -2439.5995 | Q16: =-SUM('Annual Forecast'!N74:N77) -> 5161.664 | R16: =-SUM('Annual Forecast'!O74:O77) -> 136.52276 | ... T16: =-SUM('Annual Forecast'!Q74:Q77) -> 895.07922
C17: Free Cash Flow to Firm (FCFF) | K17: =K14-K15-K16 -> 21473.719 | L17: =L14-L15-L16 -> 44151.592 | M17: =M14-M15-M16 -> 59959.454 | N17: =N14-N15-N16 -> 69505.017 | O17: =O14-O15-O16 -> 77295.546 | P17: =P14-P15-P16 -> 91326.679 | Q17: =Q14-Q15-Q16 -> 92152.371 | R17: =R14-R15-R16 -> 111854.66 | ... T17: =T14-T15-T16 -> 123915.21
D18: Terminal Value (EBITDA Multiple Approach) | K18: =K14*$K$26*Formulas!C12 -> 0 | L18: =L14*$K$26*Formulas!D12 -> 0 | M18: =M14*$K$26*Formulas!E12 -> 0 | N18: =N14*$K$26*Formulas!F12 -> 0 | O18: =O14*$K$26*Formulas!G12 -> 0 | P18: =P14*$K$26*Formulas!H12 -> 0 | Q18: =Q14*$K$26*Formulas!I12 -> 0 | R18: =R14*$K$26*Formulas!J12 -> 0 | ... T18: =T14*$K$26*Formulas!L12 -> 398430.85
C19: Net FCF | J19: =-K40 -> -287279.4 | K19: =K17+K18 -> 21473.719 | L19: =L17+L18 -> 44151.592 | M19: =M17+M18 -> 59959.454 | N19: =N17+N18 -> 69505.017 | O19: =O17+O18 -> 77295.546 | P19: =P17+P18 -> 91326.679 | Q19: =Q17+Q18 -> 92152.371 | R19: =R17+R18 -> 111854.66 | ... T19: =T17+T18 -> 522346.06
D21: PV of Terminal Value | K21: =K18/(1+$E$40)^Formulas!C13 -> 0 | L21: =L18/(1+$E$40)^Formulas!D13 -> 0 | M21: =M18/(1+$E$40)^Formulas!E13 -> 0 | N21: =N18/(1+$E$40)^Formulas!F13 -> 0 | O21: =O18/(1+$E$40)^Formulas!G13 -> 0 | P21: =P18/(1+$E$40)^Formulas!H13 -> 0 | Q21: =Q18/(1+$E$40)^Formulas!I13 -> 0 | R21: =R18/(1+$E$40)^Formulas!J13 -> 0 | ... T21: =T18/(1+$E$40)^Formulas!L13 -> 186007.64
D22: PV of Net FCF | K22: =K19/(1+$E$40)^Formulas!C13 -> 21473.719 | L22: =L19/(1+$E$40)^Formulas!D13 -> 40568.444 | M22: =M19/(1+$E$40)^Formulas!E13 -> 50622.272 | N22: =N19/(1+$E$40)^Formulas!F13 -> 53919.033 | O22: =O19/(1+$E$40)^Formulas!G13 -> 55096.295 | P22: =P19/(1+$E$40)^Formulas!H13 -> 59814.651 | Q22: =Q19/(1+$E$40)^Formulas!I13 -> 55457.259 | R22: =R19/(1+$E$40)^Formulas!J13 -> 61851.177 | ... T22: =T19/(1+$E$40)^Formulas!L13 -> 243857.52
C24: Business Valuation
C25: WACC Calculation | G25: Valuation Assumptions | M25: Equity Value Sensitivity
G26: EV/EBITDA Multiple | K26: 3 | O26: Weighted Average Cost of Capital (WACC)
D27: Debt to Total Capital | E27: =E43/E45 -> 0.35294118 | G27: Current Price | K27: 10 | M27: EV/EBITDA Multiple
D28: Equity to Total Capital | E28: =E44/E45 -> 0.64705882 | G28: Shares Outstanding | K28: 40000 | P28: =R28-2% -> 0.068323529 | Q28: =R28-1% -> 0.078323529 | R28: =E40 -> 0.088323529 | S28: =R28+1% -> 0.098323529 | T28: =R28+2% -> 0.10832353
C29: Debt / Equity | E29: =E27/E28 -> 0.54545455 | N29: =K26-2 -> 1 | O29: x | P29: =Formulas!N19 -> 969880.53 | Q29: =Formulas!O19 -> 926062.77 | R29: =Formulas!P19 -> 885558.34 | S29: =Formulas!Q19 -> 848075.91 | T29: =Formulas!R19 -> 813352.74
G30: Intrinsic Value | N30: =K26-1 -> 2 | O30: x | P30: =Formulas!N20 -> 1031361.1 | Q30: =Formulas!O20 -> 987543.35 | R30: =Formulas!P20 -> 947038.92 | S30: =Formulas!Q20 -> 909556.49 | T30: =Formulas!R20 -> 874833.32
D31: Pre-Tax Cost of Debt | E31: =Scenario!G30 -> 0.055 | H31: Sum of PV of Net FCF | K31: =SUM(K22:T22) -> 699571.05 | N31: =K26 -> 3 | O31: x | P31: =Formulas!N21 -> 1082621.5 | Q31: =Formulas!O21 -> 1038803.7 | R31: =Formulas!P21 -> 998299.29 | S31: =Formulas!Q21 -> 960816.86 | T31: =Formulas!R21 -> 926093.69
D32: Tax Rate | E32: =Scenario!G19 -> 0.25 | H32: Plus: PV of Terminal Value | K32: =SUM(K21:T21) -> 186007.64 | N32: =K26+1 -> 4 | O32: x | P32: =Formulas!N22 -> 1125025.9 | Q32: =Formulas!O22 -> 1081208.2 | R32: =Formulas!P22 -> 1040703.8 | S32: =Formulas!Q22 -> 1003221.3 | T32: =Formulas!R22 -> 968498.15
C33: After Tax Cost of Debt | E33: =E31*(1-E32) -> 0.04125 | H33: Less: Net Debt | K33: =K38-K39 -> -112720.6 | N33: =K26+2 -> 5 | O33: x | P33: =Formulas!N23 -> 1159763.4 | Q33: =Formulas!O23 -> 1115945.7 | R33: =Formulas!P23 -> 1075441.3 | S33: =Formulas!Q23 -> 1037958.8 | T33: =Formulas!R23 -> 1003235.7
G34: Equity Value | K34: =K31+K32-K33 -> 998299.29
D35: Risk Free Rate | E35: 0.03
D36: Equity Risk Premium | E36: 0.07 | G36: Market Value
D37: Levered Beta | E37: 1.2 | H37: Market Cap | K37: =K27*K28 -> 400000
C38: Cost of Equity | E38: =E35+(E36*E37) -> 0.114 | H38: Plus: Debt | K38: =E43 -> 60000
H39: Less: Cash | K39: ='12-Month Projection'!T92 -> 172720.6
C40: WACC (Discount Rate) | E40: =(E27*E33)+(E28*E38) -> 0.088323529 | G40: Enterprise Value (EV) | K40: =K37+K38-K39 -> 287279.4
C42: Capital Structure (Initial Investment) | G42: Rate of Return
D43: Debt | E43: =Scenario!G31 -> 60000 | H43: Current Share Price | K43: =K27 -> 10
D44: Equity | E44: =Scenario!G32 -> 110000 | H44: Upside | K44: =K45-K43 -> 14.957482
C45: Total | E45: =SUM(E43:E44) -> 170000 | H45: Target Share Price | K45: =K34/K28 -> 24.957482
...

Sheet Dashboard
A1: © Person0811. All rights reserved.
A2: MENU | B2: =Profile!F6 -> Person0811
C4: Dashboard
C5: =Formulas!A3 -> Amounts in USD
E6: Year | F6: 2025
D8: Total Revenue | F8: Total Expenses | L8: Closing Cash Balance | N8: Long-Term Debt
D9: =Formulas!C238 -> 444500 | F9: =Formulas!C242 -> 347223.5 | L9: =Formulas!C254 -> 172720.6 | N9: =Formulas!C258 -> 55000
D10: =Formulas!C240 -> 0 | F10: =Formulas!C244 -> 0 | J10: Net Profit Margin % | L10: =Formulas!C256 -> 0 | N10: =Formulas!C260 -> 0
D11: vs. Previous Year | F11: vs. Previous Year | J11: =Formulas!C270 -> 0.15879221 | L11: vs. Previous Year | N11: vs. Previous Year
D13: Net Profit | F13: EBITDA | J13: =Formulas!C272 -> 0 | L13: Current Ratio | N13: Quick Ratio
D14: =Formulas!C246 -> 70583.137 | F14: =Formulas!C250 -> 104801.5 | J14: vs. Previous Year | L14: =Formulas!C262 -> 5.060435 | N14: =Formulas!C266 -> 4.2607865
D15: =Formulas!C248 -> 0 | F15: =Formulas!C252 -> 0 | L15: =Formulas!C264 -> 0 | N15: =Formulas!C268 -> 0
D16: vs. Previous Year | F16: vs. Previous Year | L16: vs. Previous Year | N16: vs. Previous Year
M46: Income Statement | O46: =Formulas!C305 -> 2025
M47: Total Sales | O47: =Formulas!C306 -> 444500
M48: Total Cost of Sales | O48: =Formulas!C307 -> 233362.5
M49: Gross Profit | O49: =Formulas!C308 -> 211137.5
M50: Total Operating Expenses | O50: =Formulas!C309 -> 113861
M51: Operating Profit (EBIT) | O51: =Formulas!C310 -> 97276.5
M52: Interest | O52: =Formulas!C311 -> 3165.6506
M53: Earnings Before Taxes (EBT) | O53: =Formulas!C312 -> 94110.849
M54: Income Taxes | O54: =Formulas!C313 -> 23527.712
M55: Net Income | O55: =Formulas!C314 -> 70583.137
M56: Cash Flow Statement
M57: Cash from Operations | O57: =Formulas!C316 -> 39808.069
M58: Cash from Investing | O58: =Formulas!C317 -> -21500
M59: Cash from Financing | O59: =Formulas!C318 -> 154412.53
M60: Opening Cash Balance | O60: =Formulas!C319 -> 0
M61: Closing Cash Balance | O61: =Formulas!C320 -> 172720.6

Sheet Revenue
A1: © Person0811. All rights reserved.
A2: MENU | B2: =Profile!F6 -> Person0811
C4: Business Units Revenue
C5: =Formulas!A3 -> Amounts in USD
G6: =Profile!F8 -> 2025
C7: Revenue | G7: =Formulas!C41 -> January | H7: =Formulas!D41 -> February | I7: =Formulas!E41 -> March | J7: =Formulas!F41 -> April | K7: =Formulas!G41 -> May | L7: =Formulas!H41 -> June | M7: =Formulas!I41 -> July | N7: =Formulas!J41 -> August | ... R7: =Formulas!N41 -> December | S7: FY
C8: Seasonality Adjustment | G8: 0.02 | H8: 0.03 | I8: 0.04 | J8: 0.05 | K8: 0.1 | L8: 0.12 | M8: 0.08 | N8: 0.05 | O8: -0.02 | P8: 0.03 | Q8: 0.08 | R8: 0.12
C9: Category | E9: Volume | F9: Sales Price | G9: Sales | S9: Total Sales
D10: Service 1 | E10: 250 | F10: 10 | G10: =$E10*$F10*Formulas!C$42 -> 2550 | H10: =$E10*$F10*Formulas!D$42 -> 2575 | I10: =$E10*$F10*Formulas!E$42 -> 2600 | J10: =$E10*$F10*Formulas!F$42 -> 2625 | K10: =$E10*$F10*Formulas!G$42 -> 2750 | L10: =$E10*$F10*Formulas!H$42 -> 2800 | M10: =$E10*$F10*Formulas!I$42 -> 2700 | N10: =$E10*$F10*Formulas!J$42 -> 2625 | ... R10: =$E10*$F10*Formulas!N$42 -> 2800 | S10: =SUM(G10:R10) -> 31750
D11: Service 2 | E11: 200 | F11: 20 | G11: =$E11*$F11*Formulas!C$42 -> 4080 | H11: =$E11*$F11*Formulas!D$42 -> 4120 | I11: =$E11*$F11*Formulas!E$42 -> 4160 | J11: =$E11*$F11*Formulas!F$42 -> 4200 | K11: =$E11*$F11*Formulas!G$42 -> 4400 | L11: =$E11*$F11*Formulas!H$42 -> 4480 | M11: =$E11*$F11*Formulas!I$42 -> 4320 | N11: =$E11*$F11*Formulas!J$42 -> 4200 | ... R11: =$E11*$F11*Formulas!N$42 -> 4480 | S11: =SUM(G11:R11) -> 50800
D12: Service 3 | E12: 150 | F12: 30 | G12: =$E12*$F12*Formulas!C$42 -> 4590 | H12: =$E12*$F12*Formulas!D$42 -> 4635 | I12: =$E12*$F12*Formulas!E$42 -> 4680 | J12: =$E12*$F12*Formulas!F$42 -> 4725 | K12: =$E12*$F12*Formulas!G$42 -> 4950 | L12: =$E12*$F12*Formulas!H$42 -> 5040 | M12: =$E12*$F12*Formulas!I$42 -> 4860 | N12: =$E12*$F12*Formulas!J$42 -> 4725 | ... R12: =$E12*$F12*Formulas!N$42 -> 5040 | S12: =SUM(G12:R12) -> 57150
D13: Service 4 | E13: 100 | F13: 40 | G13: =$E13*$F13*Formulas!C$42 -> 4080 | H13: =$E13*$F13*Formulas!D$42 -> 4120 | I13: =$E13*$F13*Formulas!E$42 -> 4160 | J13: =$E13*$F13*Formulas!F$42 -> 4200 | K13: =$E13*$F13*Formulas!G$42 -> 4400 | L13: =$E13*$F13*Formulas!H$42 -> 4480 | M13: =$E13*$F13*Formulas!I$42 -> 4320 | N13: =$E13*$F13*Formulas!J$42 -> 4200 | ... R13: =$E13*$F13*Formulas!N$42 -> 4480 | S13: =SUM(G13:R13) -> 50800
D14: Service 5 | E14: 50 | F14: 50 | G14: =$E14*$F14*Formulas!C$42 -> 2550 | H14: =$E14*$F14*Formulas!D$42 -> 2575 | I14: =$E14*$F14*Formulas!E$42 -> 2600 | J14: =$E14*$F14*Formulas!F$42 -> 2625 | K14: =$E14*$F14*Formulas!G$42 -> 2750 | L14: =$E14*$F14*Formulas!H$42 -> 2800 | M14: =$E14*$F14*Formulas!I$42 -> 2700 | N14: =$E14*$F14*Formulas!J$42 -> 2625 | ... R14: =$E14*$F14*Formulas!N$42 -> 2800 | S14: =SUM(G14:R14) -> 31750
D15: (Add Service) | G15: =$E15*$F15*Formulas!C$42 -> 0 | H15: =$E15*$F15*Formulas!D$42 -> 0 | I15: =$E15*$F15*Formulas!E$42 -> 0 | J15: =$E15*$F15*Formulas!F$42 -> 0 | K15: =$E15*$F15*Formulas!G$42 -> 0 | L15: =$E15*$F15*Formulas!H$42 -> 0 | M15: =$E15*$F15*Formulas!I$42 -> 0 | N15: =$E15*$F15*Formulas!J$42 -> 0 | ... R15: =$E15*$F15*Formulas!N$42 -> 0 | S15: =SUM(G15:R15) -> 0
D16: (Add Service) | G16: =$E16*$F16*Formulas!C$42 -> 0 | H16: =$E16*$F16*Formulas!D$42 -> 0 | I16: =$E16*$F16*Formulas!E$42 -> 0 | J16: =$E16*$F16*Formulas!F$42 -> 0 | K16: =$E16*$F16*Formulas!G$42 -> 0 | L16: =$E16*$F16*Formulas!H$42 -> 0 | M16: =$E16*$F16*Formulas!I$42 -> 0 | N16: =$E16*$F16*Formulas!J$42 -> 0 | ... R16: =$E16*$F16*Formulas!N$42 -> 0 | S16: =SUM(G16:R16) -> 0
D17: (Add Service) | G17: =$E17*$F17*Formulas!C$42 -> 0 | H17: =$E17*$F17*Formulas!D$42 -> 0 | I17: =$E17*$F17*Formulas!E$42 -> 0 | J17: =$E17*$F17*Formulas!F$42 -> 0 | K17: =$E17*$F17*Formulas!G$42 -> 0 | L17: =$E17*$F17*Formulas!H$42 -> 0 | M17: =$E17*$F17*Formulas!I$42 -> 0 | N17: =$E17*$F17*Formulas!J$42 -> 0 | ... R17: =$E17*$F17*Formulas!N$42 -> 0 | S17: =SUM(G17:R17) -> 0
D18: (Add Service) | G18: =$E18*$F18*Formulas!C$42 -> 0 | H18: =$E18*$F18*Formulas!D$42 -> 0 | I18: =$E18*$F18*Formulas!E$42 -> 0 | J18: =$E18*$F18*Formulas!F$42 -> 0 | K18: =$E18*$F18*Formulas!G$42 -> 0 | L18: =$E18*$F18*Formulas!H$42 -> 0 | M18: =$E18*$F18*Formulas!I$42 -> 0 | N18: =$E18*$F18*Formulas!J$42 -> 0 | ... R18: =$E18*$F18*Formulas!N$42 -> 0 | S18: =SUM(G18:R18) -> 0
D19: (Add Service) | G19: =$E19*$F19*Formulas!C$42 -> 0 | H19: =$E19*$F19*Formulas!D$42 -> 0 | I19: =$E19*$F19*Formulas!E$42 -> 0 | J19: =$E19*$F19*Formulas!F$42 -> 0 | K19: =$E19*$F19*Formulas!G$42 -> 0 | L19: =$E19*$F19*Formulas!H$42 -> 0 | M19: =$E19*$F19*Formulas!I$42 -> 0 | N19: =$E19*$F19*Formulas!J$42 -> 0 | ... R19: =$E19*$F19*Formulas!N$42 -> 0 | S19: =SUM(G19:R19) -> 0
C20: Total Services | E20: =SUM(E10:E19) -> 750 | G20: =SUM(G10:G19) -> 17850 | H20: =SUM(H10:H19) -> 18025 | I20: =SUM(I10:I19) -> 18200 | J20: =SUM(J10:J19) -> 18375 | K20: =SUM(K10:K19) -> 19250 | L20: =SUM(L10:L19) -> 19600 | M20: =SUM(M10:M19) -> 18900 | N20: =SUM(N10:N19) -> 18375 | ... S20: =SUM(S10:S19) -> 222250
D22: Product 1 | E22: 250 | F22: 10 | G22: =$E22*$F22*Formulas!C$42 -> 2550 | H22: =$E22*$F22*Formulas!D$42 -> 2575 | I22: =$E22*$F22*Formulas!E$42 -> 2600 | J22: =$E22*$F22*Formulas!F$42 -> 2625 | K22: =$E22*$F22*Formulas!G$42 -> 2750 | L22: =$E22*$F22*Formulas!H$42 -> 2800 | M22: =$E22*$F22*Formulas!I$42 -> 2700 | N22: =$E22*$F22*Formulas!J$42 -> 2625 | ... R22: =$E22*$F22*Formulas!N$42 -> 2800 | S22: =SUM(G22:R22) -> 31750
D23: Product 2 | E23: 200 | F23: 20 | G23: =$E23*$F23*Formulas!C$42 -> 4080 | H23: =$E23*$F23*Formulas!D$42 -> 4120 | I23: =$E23*$F23*Formulas!E$42 -> 4160 | J23: =$E23*$F23*Formulas!F$42 -> 4200 | K23: =$E23*$F23*Formulas!G$42 -> 4400 | L23: =$E23*$F23*Formulas!H$42 -> 4480 | M23: =$E23*$F23*Formulas!I$42 -> 4320 | N23: =$E23*$F23*Formulas!J$42 -> 4200 | ... R23: =$E23*$F23*Formulas!N$42 -> 4480 | S23: =SUM(G23:R23) -> 50800
D24: Product 3 | E24: 150 | F24: 30 | G24: =$E24*$F24*Formulas!C$42 -> 4590 | H24: =$E24*$F24*Formulas!D$42 -> 4635 | I24: =$E24*$F24*Formulas!E$42 -> 4680 | J24: =$E24*$F24*Formulas!F$42 -> 4725 | K24: =$E24*$F24*Formulas!G$42 -> 4950 | L24: =$E24*$F24*Formulas!H$42 -> 5040 | M24: =$E24*$F24*Formulas!I$42 -> 4860 | N24: =$E24*$F24*Formulas!J$42 -> 4725 | ... R24: =$E24*$F24*Formulas!N$42 -> 5040 | S24: =SUM(G24:R24) -> 57150
D25: Product 4 | E25: 100 | F25: 40 | G25: =$E25*$F25*Formulas!C$42 -> 4080 | H25: =$E25*$F25*Formulas!D$42 -> 4120 | I25: =$E25*$F25*Formulas!E$42 -> 4160 | J25: =$E25*$F25*Formulas!F$42 -> 4200 | K25: =$E25*$F25*Formulas!G$42 -> 4400 | L25: =$E25*$F25*Formulas!H$42 -> 4480 | M25: =$E25*$F25*Formulas!I$42 -> 4320 | N25: =$E25*$F25*Formulas!J$42 -> 4200 | ... R25: =$E25*$F25*Formulas!N$42 -> 4480 | S25: =SUM(G25:R25) -> 50800
D26: Product 5 | E26: 50 | F26: 50 | G26: =$E26*$F26*Formulas!C$42 -> 2550 | H26: =$E26*$F26*Formulas!D$42 -> 2575 | I26: =$E26*$F26*Formulas!E$42 -> 2600 | J26: =$E26*$F26*Formulas!F$42 -> 2625 | K26: =$E26*$F26*Formulas!G$42 -> 2750 | L26: =$E26*$F26*Formulas!H$42 -> 2800 | M26: =$E26*$F26*Formulas!I$42 -> 2700 | N26: =$E26*$F26*Formulas!J$42 -> 2625 | ... R26: =$E26*$F26*Formulas!N$42 -> 2800 | S26: =SUM(G26:R26) -> 31750
D27: (Add Product) | G27: =$E27*$F27*Formulas!C$42 -> 0 | H27: =$E27*$F27*Formulas!D$42 -> 0 | I27: =$E27*$F27*Formulas!E$42 -> 0 | J27: =$E27*$F27*Formulas!F$42 -> 0 | K27: =$E27*$F27*Formulas!G$42 -> 0 | L27: =$E27*$F27*Formulas!H$42 -> 0 | M27: =$E27*$F27*Formulas!I$42 -> 0 | N27: =$E27*$F27*Formulas!J$42 -> 0 | ... R27: =$E27*$F27*Formulas!N$42 -> 0 | S27: =SUM(G27:R27) -> 0
D28: (Add Product) | G28: =$E28*$F28*Formulas!C$42 -> 0 | H28: =$E28*$F28*Formulas!D$42 -> 0 | I28: =$E28*$F28*Formulas!E$42 -> 0 | J28: =$E28*$F28*Formulas!F$42 -> 0 | K28: =$E28*$F28*Formulas!G$42 -> 0 | L28: =$E28*$F28*Formulas!H$42 -> 0 | M28: =$E28*$F28*Formulas!I$42 -> 0 | N28: =$E28*$F28*Formulas!J$42 -> 0 | ... R28: =$E28*$F28*Formulas!N$42 -> 0 | S28: =SUM(G28:R28) -> 0
D29: (Add Product) | G29: =$E29*$F29*Formulas!C$42 -> 0 | H29: =$E29*$F29*Formulas!D$42 -> 0 | I29: =$E29*$F29*Formulas!E$42 -> 0 | J29: =$E29*$F29*Formulas!F$42 -> 0 | K29: =$E29*$F29*Formulas!G$42 -> 0 | L29: =$E29*$F29*Formulas!H$42 -> 0 | M29: =$E29*$F29*Formulas!I$42 -> 0 | N29: =$E29*$F29*Formulas!J$42 -> 0 | ... R29: =$E29*$F29*Formulas!N$42 -> 0 | S29: =SUM(G29:R29) -> 0
D30: (Add Product) | G30: =$E30*$F30*Formulas!C$42 -> 0 | H30: =$E30*$F30*Formulas!D$42 -> 0 | I30: =$E30*$F30*Formulas!E$42 -> 0 | J30: =$E30*$F30*Formulas!F$42 -> 0 | K30: =$E30*$F30*Formulas!G$42 -> 0 | L30: =$E30*$F30*Formulas!H$42 -> 0 | M30: =$E30*$F30*Formulas!I$42 -> 0 | N30: =$E30*$F30*Formulas!J$42 -> 0 | ... R30: =$E30*$F30*Formulas!N$42 -> 0 | S30: =SUM(G30:R30) -> 0
D31: (Add Product) | G31: =$E31*$F31*Formulas!C$42 -> 0 | H31: =$E31*$F31*Formulas!D$42 -> 0 | I31: =$E31*$F31*Formulas!E$42 -> 0 | J31: =$E31*$F31*Formulas!F$42 -> 0 | K31: =$E31*$F31*Formulas!G$42 -> 0 | L31: =$E31*$F31*Formulas!H$42 -> 0 | M31: =$E31*$F31*Formulas!I$42 -> 0 | N31: =$E31*$F31*Formulas!J$42 -> 0 | ... R31: =$E31*$F31*Formulas!N$42 -> 0 | S31: =SUM(G31:R31) -> 0
C32: Total Products | E32: =SUM(E22:E31) -> 750 | G32: =SUM(G22:G31) -> 17850 | H32: =SUM(H22:H31) -> 18025 | I32: =SUM(I22:I31) -> 18200 | J32: =SUM(J22:J31) -> 18375 | K32: =SUM(K22:K31) -> 19250 | L32: =SUM(L22:L31) -> 19600 | M32: =SUM(M22:M31) -> 18900 | N32: =SUM(N22:N31) -> 18375 | ... S32: =SUM(S22:S31) -> 222250
C34: Grand Total Revenue | E34: =E20+E32 -> 1500 | G34: =G20+G32 -> 35700 | H34: =H20+H32 -> 36050 | I34: =I20+I32 -> 36400 | J34: =J20+J32 -> 36750 | K34: =K20+K32 -> 38500 | L34: =L20+L32 -> 39200 | M34: =M20+M32 -> 37800 | N34: =N20+N32 -> 36750 | ... S34: =S20+S32 -> 444500
C36: Cost of Goods Sold (COGS)
C38: Category | F38: % of Revenue | G38: Cost | S38: Total Cost
D39: Service 1 | F39: 0.15 | G39: =$F39*G10 -> 382.5 | H39: =$F39*H10 -> 386.25 | I39: =$F39*I10 -> 390 | J39: =$F39*J10 -> 393.75 | K39: =$F39*K10 -> 412.5 | L39: =$F39*L10 -> 420 | M39: =$F39*M10 -> 405 | N39: =$F39*N10 -> 393.75 | ... R39: =$F39*R10 -> 420 | S39: =SUM(G39:R39) -> 4762.5
D40: Service 2 | F40: 0.15 | G40: =$F40*G11 -> 612 | H40: =$F40*H11 -> 618 | I40: =$F40*I11 -> 624 | J40: =$F40*J11 -> 630 | K40: =$F40*K11 -> 660 | L40: =$F40*L11 -> 672 | M40: =$F40*M11 -> 648 | N40: =$F40*N11 -> 630 | ... R40: =$F40*R11 -> 672 | S40: =SUM(G40:R40) -> 7620
D41: Service 3 | F41: 0.15 | G41: =$F41*G12 -> 688.5 | H41: =$F41*H12 -> 695.25 | I41: =$F41*I12 -> 702 | J41: =$F41*J12 -> 708.75 | K41: =$F41*K12 -> 742.5 | L41: =$F41*L12 -> 756 | M41: =$F41*M12 -> 729 | N41: =$F41*N12 -> 708.75 | ... R41: =$F41*R12 -> 756 | S41: =SUM(G41:R41) -> 8572.5
D42: Service 4 | F42: 0.15 | G42: =$F42*G13 -> 612 | H42: =$F42*H13 -> 618 | I42: =$F42*I13 -> 624 | J42: =$F42*J13 -> 630 | K42: =$F42*K13 -> 660 | L42: =$F42*L13 -> 672 | M42: =$F42*M13 -> 648 | N42: =$F42*N13 -> 630 | ... R42: =$F42*R13 -> 672 | S42: =SUM(G42:R42) -> 7620
D43: Service 5 | F43: 0.15 | G43: =$F43*G14 -> 382.5 | H43: =$F43*H14 -> 386.25 | I43: =$F43*I14 -> 390 | J43: =$F43*J14 -> 393.75 | K43: =$F43*K14 -> 412.5 | L43: =$F43*L14 -> 420 | M43: =$F43*M14 -> 405 | N43: =$F43*N14 -> 393.75 | ... R43: =$F43*R14 -> 420 | S43: =SUM(G43:R43) -> 4762.5
D44: (Add Service) | G44: =$F44*G15 -> 0 | H44: =$F44*H15 -> 0 | I44: =$F44*I15 -> 0 | J44: =$F44*J15 -> 0 | K44: =$F44*K15 -> 0 | L44: =$F44*L15 -> 0 | M44: =$F44*M15 -> 0 | N44: =$F44*N15 -> 0 | ... R44: =$F44*R15 -> 0 | S44: =SUM(G44:R44) -> 0
D45: (Add Service) | G45: =$F45*G16 -> 0 | H45: =$F45*H16 -> 0 | I45: =$F45*I16 -> 0 | J45: =$F45*J16 -> 0 | K45: =$F45*K16 -> 0 | L45: =$F45*L16 -> 0 | M45: =$F45*M16 -> 0 | N45: =$F45*N16 -> 0 | ... R45: =$F45*R16 -> 0 | S45: =SUM(G45:R45) -> 0
...

Sheet Scenario
A1: © Person0811. All rights reserved.
A2: MENU | B2: =Profile!F6 -> Person0811
C4: Scenario Analysis
C5: =Formulas!A3 -> Amounts in USD
D6: Case Scenario | E6: Base Case | G6: Assumptions
C7: Active Case | G7: =Formulas!C9 -> 2025 | H7: =Formulas!D9 -> 2026 | I7: =Formulas!E9 -> 2027 | J7: =Formulas!F9 -> 2028 | K7: =Formulas!G9 -> 2029 | L7: =Formulas!H9 -> 2030 | M7: =Formulas!I9 -> 2031 | N7: =Formulas!J9 -> 2032 | ... P7: =Formulas!L9 -> 2034
C8: Income Statement
D9: Revenue Growth | E9: % change | G9: =Formulas!C45 -> 0 | H9: =Formulas!D45 -> 0.06 | I9: =Formulas!E45 -> 0.05 | J9: =Formulas!F45 -> 0.04 | K9: =Formulas!G45 -> 0.03 | L9: =Formulas!H45 -> 0.03 | M9: =Formulas!I45 -> 0.02 | N9: =Formulas!J45 -> 0.02 | ... P9: =Formulas!L45 -> 0.02
D10: Service Cost | E10: % of service revenue | H10: =Formulas!D49 -> 0.25 | I10: =Formulas!E49 -> 0.25 | J10: =Formulas!F49 -> 0.24 | K10: =Formulas!G49 -> 0.24 | L10: =Formulas!H49 -> 0.23 | M10: =Formulas!I49 -> 0.23 | N10: =Formulas!J49 -> 0.22 | O10: =Formulas!K49 -> 0.22 | P10: =Formulas!L49 -> 0.21
D11: Product Cost | E11: % of product revenue | H11: =Formulas!D53 -> 0.4 | I11: =Formulas!E53 -> 0.38 | J11: =Formulas!F53 -> 0.37 | K11: =Formulas!G53 -> 0.36 | L11: =Formulas!H53 -> 0.35 | M11: =Formulas!I53 -> 0.35 | N11: =Formulas!J53 -> 0.34 | O11: =Formulas!K53 -> 0.34 | P11: =Formulas!L53 -> 0.34
D12: Direct Labor Cost | E12: % of total revenue | G12: =Formulas!C57 -> 0.18 | H12: =Formulas!D57 -> 0.18 | I12: =Formulas!E57 -> 0.18 | J12: =Formulas!F57 -> 0.18 | K12: =Formulas!G57 -> 0.18 | L12: =Formulas!H57 -> 0.18 | M12: =Formulas!I57 -> 0.18 | N12: =Formulas!J57 -> 0.18 | ... P12: =Formulas!L57 -> 0.18
D13: Discount and Promotions | E13: % of total revenue | G13: =Formulas!C61 -> 0.12 | H13: =Formulas!D61 -> 0.11 | I13: =Formulas!E61 -> 0.1 | J13: =Formulas!F61 -> 0.09 | K13: =Formulas!G61 -> 0.09 | L13: =Formulas!H61 -> 0.08 | M13: =Formulas!I61 -> 0.08 | N13: =Formulas!J61 -> 0.07 | ... P13: =Formulas!L61 -> 0.07
D14: Salaries and Benefits | E14: =Profile!$F$10 -> USD | G14: =Formulas!C65 -> 50000 | H14: =Formulas!D65 -> 50000 | I14: =Formulas!E65 -> 50000 | J14: =Formulas!F65 -> 50000 | K14: =Formulas!G65 -> 50000 | L14: =Formulas!H65 -> 50000 | M14: =Formulas!I65 -> 50000 | N14: =Formulas!J65 -> 50000 | ... P14: =Formulas!L65 -> 50000
D15: Sales and Marketing | E15: % of total revenue | G15: =Formulas!C69 -> 0.04 | H15: =Formulas!D69 -> 0.04 | I15: =Formulas!E69 -> 0.035 | J15: =Formulas!F69 -> 0.035 | K15: =Formulas!G69 -> 0.035 | L15: =Formulas!H69 -> 0.035 | M15: =Formulas!I69 -> 0.03 | N15: =Formulas!J69 -> 0.03 | ... P15: =Formulas!L69 -> 0.03
D16: General and Administration | E16: =Profile!$F$10 -> USD | G16: =Formulas!C73 -> 35000 | H16: =Formulas!D73 -> 35000 | I16: =Formulas!E73 -> 35000 | J16: =Formulas!F73 -> 35000 | K16: =Formulas!G73 -> 35000 | L16: =Formulas!H73 -> 35000 | M16: =Formulas!I73 -> 35000 | N16: =Formulas!J73 -> 35000 | ... P16: =Formulas!L73 -> 35000
D17: Credit Card Fees | E17: % of total revenue | G17: =Formulas!C77 -> 0.008 | H17: =Formulas!D77 -> 0.008 | I17: =Formulas!E77 -> 0.008 | J17: =Formulas!F77 -> 0.008 | K17: =Formulas!G77 -> 0.008 | L17: =Formulas!H77 -> 0.008 | M17: =Formulas!I77 -> 0.008 | N17: =Formulas!J77 -> 0.008 | ... P17: =Formulas!L77 -> 0.008
D18: Depreciation and Amortization | E18: % of PP&E | G18: =Formulas!C81 -> 0.35 | H18: =Formulas!D81 -> 0.35 | I18: =Formulas!E81 -> 0.35 | J18: =Formulas!F81 -> 0.35 | K18: =Formulas!G81 -> 0.35 | L18: =Formulas!H81 -> 0.35 | M18: =Formulas!I81 -> 0.35 | N18: =Formulas!J81 -> 0.35 | ... P18: =Formulas!L81 -> 0.35
D19: Tax Rate | E19: % of EBT | G19: =Formulas!C85 -> 0.25 | H19: =Formulas!D85 -> 0.25 | I19: =Formulas!E85 -> 0.25 | J19: =Formulas!F85 -> 0.25 | K19: =Formulas!G85 -> 0.25 | L19: =Formulas!H85 -> 0.25 | M19: =Formulas!I85 -> 0.25 | N19: =Formulas!J85 -> 0.25 | ... P19: =Formulas!L85 -> 0.25
C21: Balance Sheet
D22: Accounts Receivable | E22: days | G22: =Formulas!C89 -> 40 | H22: =Formulas!D89 -> 40 | I22: =Formulas!E89 -> 40 | J22: =Formulas!F89 -> 40 | K22: =Formulas!G89 -> 40 | L22: =Formulas!H89 -> 35 | M22: =Formulas!I89 -> 35 | N22: =Formulas!J89 -> 35 | ... P22: =Formulas!L89 -> 35
D23: Inventory | E23: days | G23: =Formulas!C93 -> 65 | H23: =Formulas!D93 -> 65 | I23: =Formulas!E93 -> 65 | J23: =Formulas!F93 -> 70 | K23: =Formulas!G93 -> 70 | L23: =Formulas!H93 -> 70 | M23: =Formulas!I93 -> 75 | N23: =Formulas!J93 -> 75 | ... P23: =Formulas!L93 -> 80
D24: Property, Plant and Equipment | E24: USD (initial) | G24: =Formulas!C97 -> 13500
D25: Accounts Payable | E25: days | G25: =Formulas!C101 -> 50 | H25: =Formulas!D101 -> 50 | I25: =Formulas!E101 -> 50 | J25: =Formulas!F101 -> 50 | K25: =Formulas!G101 -> 50 | L25: =Formulas!H101 -> 45 | M25: =Formulas!I101 -> 45 | N25: =Formulas!J101 -> 45 | ... P25: =Formulas!L101 -> 45
D26: Accrued Expenses and Other | E26: % of total revenue | G26: =Formulas!C105 -> 0.045 | H26: =Formulas!D105 -> 0.045 | I26: =Formulas!E105 -> 0.045 | J26: =Formulas!F105 -> 0.045 | K26: =Formulas!G105 -> 0.045 | L26: =Formulas!H105 -> 0.045 | M26: =Formulas!I105 -> 0.045 | N26: =Formulas!J105 -> 0.045 | ... P26: =Formulas!L105 -> 0.045
D27: Capital Expenditures | E27: =Profile!$F$10 -> USD | G27: =Formulas!C109 -> 8000 | H27: =Formulas!D109 -> 10000 | I27: =Formulas!E109 -> 12000 | J27: =Formulas!F109 -> 12000 | K27: =Formulas!G109 -> 15000 | L27: =Formulas!H109 -> 18000 | M27: =Formulas!I109 -> 15000 | N27: =Formulas!J109 -> 12000 | ... P27: =Formulas!L109 -> 8000
C29: Financing
D30: Interest Rate (% of Debt) | E30: % | G30: =Formulas!C113 -> 0.055 | H30: =Formulas!D113 -> 0.055 | I30: =Formulas!E113 -> 0.055 | J30: =Formulas!F113 -> 0.055 | K30: =Formulas!G113 -> 0.055 | L30: =Formulas!H113 -> 0.055 | M30: =Formulas!I113 -> 0.055 | N30: =Formulas!J113 -> 0.055 | ... P30: =Formulas!L113 -> 0.055
D31: Long-Term Debt | E31: USD (Initial) | G31: =Formulas!C117 -> 60000
D32: Equity Capital | E32: USD | G32: =Formulas!C121 -> 110000 | H32: =Formulas!D121 -> 110000 | I32: =Formulas!E121 -> 110000 | J32: =Formulas!F121 -> 110000 | K32: =Formulas!G121 -> 110000 | L32: =Formulas!H121 -> 110000 | M32: =Formulas!I121 -> 110000 | N32: =Formulas!J121 -> 110000 | ... P32: =Formulas!L121 -> 110000
D33: Debt Issued/(Repaid) | E33: =Profile!$F$10 -> USD | G33: =Formulas!C125 -> -5000 | H33: =Formulas!D125 -> -5000 | I33: =Formulas!E125 -> -5000 | J33: =Formulas!F125 -> -5000 | K33: =Formulas!G125 -> -5000 | L33: =Formulas!H125 -> -5000 | M33: =Formulas!I125 -> -5000 | N33: =Formulas!J125 -> -5000 | ... P33: =Formulas!L125 -> -5000
D34: Equity Issued/(Repaid) | E34: =Profile!$F$10 -> USD | G34: =Formulas!C129 -> 0 | H34: =Formulas!D129 -> 0 | I34: =Formulas!E129 -> 0 | J34: =Formulas!F129 -> 0 | K34: =Formulas!G129 -> 0 | L34: =Formulas!H129 -> 0 | M34: =Formulas!I129 -> 0 | N34: =Formulas!J129 -> 0 | ... P34: =Formulas!L129 -> 0
D35: Dividends | E35: % of net income | G35: =Formulas!C133 -> 0.15 | H35: =Formulas!D133 -> 0.15 | I35: =Formulas!E133 -> 0.15 | J35: =Formulas!F133 -> 0.15 | K35: =Formulas!G133 -> 0.15 | L35: =Formulas!H133 -> 0.15 | M35: =Formulas!I133 -> 0.15 | N35: =Formulas!J133 -> 0.15 | ... P35: =Formulas!L133 -> 0.15
C37: Base Case Scenario
C38: Income Statement
D39: Revenue Growth | E39: % change | H39: 0.06 | I39: 0.05 | J39: 0.04 | K39: 0.03 | L39: 0.03 | M39: 0.02 | N39: 0.02 | O39: 0.02 | P39: 0.02
D40: Service Cost | E40: % of service revenue | H40: 0.25 | I40: 0.25 | J40: 0.24 | K40: 0.24 | L40: 0.23 | M40: 0.23 | N40: 0.22 | O40: 0.22 | P40: 0.21
D41: Product Cost | E41: % of product revenue | H41: 0.4 | I41: 0.38 | J41: 0.37 | K41: 0.36 | L41: 0.35 | M41: 0.35 | N41: 0.34 | O41: 0.34 | P41: 0.34
D42: Direct Labor Cost | E42: % of total revenue | G42: 0.18 | H42: 0.18 | I42: 0.18 | J42: 0.18 | K42: 0.18 | L42: 0.18 | M42: 0.18 | N42: 0.18 | O42: 0.18 | P42: 0.18
D43: Discount and Promotions | E43: % of total revenue | G43: 0.12 | H43: 0.11 | I43: 0.1 | J43: 0.09 | K43: 0.09 | L43: 0.08 | M43: 0.08 | N43: 0.07 | O43: 0.07 | P43: 0.07
D44: Salaries and Benefits | E44: =Profile!$F$10 -> USD | G44: 50000 | H44: 50000 | I44: 50000 | J44: 50000 | K44: 50000 | L44: 50000 | M44: 50000 | N44: 50000 | O44: 50000 | P44: 50000
...

Sheet Actual FS
A1: © Person0811. All rights reserved.
A2: MENU | B2: =Profile!F6 -> Person0811
C4: 12 Month Actual Financial Statement
C5: =Formulas!A3 -> Amounts in USD
H6: =Profile!F8 -> 2025
C7: Income Statement | H7: =Formulas!C41 -> January | I7: =Formulas!D41 -> February | J7: =Formulas!E41 -> March | K7: =Formulas!F41 -> April | L7: =Formulas!G41 -> May | M7: =Formulas!H41 -> June | N7: =Formulas!I41 -> July | O7: =Formulas!J41 -> August | ... S7: =Formulas!N41 -> December | T7: FY
D8: Service Sales | H8: 35000 | I8: 35000 | J8: 35000 | K8: 35000 | L8: 35000 | M8: 35000 | N8: 35000 | O8: 35000 | P8: 35000 | Q8: 35000 | R8: 35000 | S8: 35000 | T8: =SUM(H8:S8) -> 420000
D9: Product Sales | H9: 10000 | I9: 10000 | J9: 10000 | K9: 10000 | L9: 10000 | M9: 10000 | N9: 10000 | O9: 10000 | P9: 10000 | Q9: 10000 | R9: 10000 | S9: 10000 | T9: =SUM(H9:S9) -> 120000
C10: Total Sales | H10: =SUM(H8:H9) -> 45000 | I10: =SUM(I8:I9) -> 45000 | J10: =SUM(J8:J9) -> 45000 | K10: =SUM(K8:K9) -> 45000 | L10: =SUM(L8:L9) -> 45000 | M10: =SUM(M8:M9) -> 45000 | N10: =SUM(N8:N9) -> 45000 | O10: =SUM(O8:O9) -> 45000 | ... T10: =SUM(T8:T9) -> 540000
D12: Service Cost | H12: 7000 | I12: 7000 | J12: 7000 | K12: 7000 | L12: 7000 | M12: 7000 | N12: 7000 | O12: 7000 | P12: 7000 | Q12: 7000 | R12: 7000 | S12: 7000 | T12: =SUM(H12:S12) -> 84000
D13: Product Cost | H13: 5000 | I13: 5000 | J13: 5000 | K13: 5000 | L13: 5000 | M13: 5000 | N13: 5000 | O13: 5000 | P13: 5000 | Q13: 5000 | R13: 5000 | S13: 5000 | T13: =SUM(H13:S13) -> 60000
D14: Direct Labor Cost | H14: 9000 | I14: 9000 | J14: 9000 | K14: 9000 | L14: 9000 | M14: 9000 | N14: 9000 | O14: 9000 | P14: 9000 | Q14: 9000 | R14: 9000 | S14: 9000 | T14: =SUM(H14:S14) -> 108000
D15: Discounts and Promotions | H15: 7000 | I15: 7000 | J15: 7000 | K15: 7000 | L15: 7000 | M15: 7000 | N15: 7000 | O15: 7000 | P15: 7000 | Q15: 7000 | R15: 7000 | S15: 7000 | T15: =SUM(H15:S15) -> 84000
C16: Total Cost of Sales | H16: =SUM(H12:H15) -> 28000 | I16: =SUM(I12:I15) -> 28000 | J16: =SUM(J12:J15) -> 28000 | K16: =SUM(K12:K15) -> 28000 | L16: =SUM(L12:L15) -> 28000 | M16: =SUM(M12:M15) -> 28000 | N16: =SUM(N12:N15) -> 28000 | O16: =SUM(O12:O15) -> 28000 | ... T16: =SUM(T12:T15) -> 336000
C18: Gross Profit | H18: =H10-H16 -> 17000 | I18: =I10-I16 -> 17000 | J18: =J10-J16 -> 17000 | K18: =K10-K16 -> 17000 | L18: =L10-L16 -> 17000 | M18: =M10-M16 -> 17000 | N18: =N10-N16 -> 17000 | O18: =O10-O16 -> 17000 | ... T18: =T10-T16 -> 204000
C19: Gross Margin % | H19: =IFERROR(H18/H10,0) -> 0.37777778 | I19: =IFERROR(I18/I10,0) -> 0.37777778 | J19: =IFERROR(J18/J10,0) -> 0.37777778 | K19: =IFERROR(K18/K10,0) -> 0.37777778 | L19: =IFERROR(L18/L10,0) -> 0.37777778 | M19: =IFERROR(M18/M10,0) -> 0.37777778 | N19: =IFERROR(N18/N10,0) -> 0.37777778 | O19: =IFERROR(O18/O10,0) -> 0.37777778 | ... T19: =IFERROR(T18/T10,0) -> 0.37777778
D21: Salaries and Benefits | H21: 4000 | I21: 4000 | J21: 4000 | K21: 4000 | L21: 4000 | M21: 4000 | N21: 4000 | O21: 4000 | P21: 4000 | Q21: 4000 | R21: 4000 | S21: 4000 | T21: =SUM(H21:S21) -> 48000
D22: Sales and Marketing | H22: 2500 | I22: 2500 | J22: 2500 | K22: 2500 | L22: 2500 | M22: 2500 | N22: 2500 | O22: 2500 | P22: 2500 | Q22: 2500 | R22: 2500 | S22: 2500 | T22: =SUM(H22:S22) -> 30000
D23: General and Administration | H23: 3500 | I23: 3500 | J23: 3500 | K23: 3500 | L23: 3500 | M23: 3500 | N23: 3500 | O23: 3500 | P23: 3500 | Q23: 3500 | R23: 3500 | S23: 3500 | T23: =SUM(H23:S23) -> 42000
D24: Credit Card Fees | H24: 450 | I24: 450 | J24: 450 | K24: 450 | L24: 450 | M24: 450 | N24: 450 | O24: 450 | P24: 450 | Q24: 450 | R24: 450 | S24: 450 | T24: =SUM(H24:S24) -> 5400
D25: Depreciation and Amortization | H25: 800 | I25: 800 | J25: 800 | K25: 800 | L25: 800 | M25: 800 | N25: 800 | O25: 800 | P25: 800 | Q25: 800 | R25: 800 | S25: 800 | T25: =SUM(H25:S25) -> 9600
C26: Total Operating Expenses | H26: =SUM(H21:H25) -> 11250 | I26: =SUM(I21:I25) -> 11250 | J26: =SUM(J21:J25) -> 11250 | K26: =SUM(K21:K25) -> 11250 | L26: =SUM(L21:L25) -> 11250 | M26: =SUM(M21:M25) -> 11250 | N26: =SUM(N21:N25) -> 11250 | O26: =SUM(O21:O25) -> 11250 | ... T26: =SUM(T21:T25) -> 135000
C28: Operating Profit (EBIT) | H28: =H18-H26 -> 5750 | I28: =I18-I26 -> 5750 | J28: =J18-J26 -> 5750 | K28: =K18-K26 -> 5750 | L28: =L18-L26 -> 5750 | M28: =M18-M26 -> 5750 | N28: =N18-N26 -> 5750 | O28: =O18-O26 -> 5750 | ... T28: =T18-T26 -> 69000
C29: Operating Margin % | H29: =IFERROR(H28/H10,0) -> 0.12777778 | I29: =IFERROR(I28/I10,0) -> 0.12777778 | J29: =IFERROR(J28/J10,0) -> 0.12777778 | K29: =IFERROR(K28/K10,0) -> 0.12777778 | L29: =IFERROR(L28/L10,0) -> 0.12777778 | M29: =IFERROR(M28/M10,0) -> 0.12777778 | N29: =IFERROR(N28/N10,0) -> 0.12777778 | O29: =IFERROR(O28/O10,0) -> 0.12777778 | ... T29: =IFERROR(T28/T10,0) -> 0.12777778
D31: Interest | H31: 450 | I31: 450 | J31: 450 | K31: 450 | L31: 450 | M31: 450 | N31: 450 | O31: 450 | P31: 450 | Q31: 450 | R31: 450 | S31: 450 | T31: =SUM(H31:S31) -> 5400
C32: Earnings Before Taxes (EBT) | H32: =H28-H31 -> 5300 | I32: =I28-I31 -> 5300 | J32: =J28-J31 -> 5300 | K32: =K28-K31 -> 5300 | L32: =L28-L31 -> 5300 | M32: =M28-M31 -> 5300 | N32: =N28-N31 -> 5300 | O32: =O28-O31 -> 5300 | ... T32: =T28-T31 -> 63600
D34: Income Taxes | H34: 1700 | I34: 1700 | J34: 1700 | K34: 1700 | L34: 1700 | M34: 1700 | N34: 1700 | O34: 1700 | P34: 1700 | Q34: 1700 | R34: 1700 | S34: 1700 | T34: =SUM(H34:S34) -> 20400
C35: Net Income | H35: =H32-H34 -> 3600 | I35: =I32-I34 -> 3600 | J35: =J32-J34 -> 3600 | K35: =K32-K34 -> 3600 | L35: =L32-L34 -> 3600 | M35: =M32-M34 -> 3600 | N35: =N32-N34 -> 3600 | O35: =O32-O34 -> 3600 | ... T35: =T32-T34 -> 43200
C36: Net Profit Margin % | H36: =IFERROR(H35/H10,0) -> 0.08 | I36: =IFERROR(I35/I10,0) -> 0.08 | J36: =IFERROR(J35/J10,0) -> 0.08 | K36: =IFERROR(K35/K10,0) -> 0.08 | L36: =IFERROR(L35/L10,0) -> 0.08 | M36: =IFERROR(M35/M10,0) -> 0.08 | N36: =IFERROR(N35/N10,0) -> 0.08 | O36: =IFERROR(O35/O10,0) -> 0.08 | ... T36: =IFERROR(T35/T10,0) -> 0.08
C38: Balance Sheet
C39: Current Assets
D40: Cash and Cash Equivalents | H40: =H91 -> 188000 | I40: =I91 -> 186000 | J40: =J91 -> 184000 | K40: =K91 -> 182000 | L40: =L91 -> 180000 | M40: =M91 -> 178000 | N40: =N91 -> 176000 | O40: =O91 -> 174000 | ... S40: =S91 -> 166000 | T40: =S40 -> 166000
D41: Accounts Receivable | H41: 5500 | I41: 11000 | J41: 16500 | K41: 22000 | L41: 27500 | M41: 33000 | N41: 38500 | O41: 44000 | P41: 49500 | Q41: 55000 | R41: 60500 | S41: 66000 | T41: =S41 -> 66000
D42: Inventory | H42: 5300 | I42: 10600 | J42: 15900 | K42: 21200 | L42: 26500 | M42: 31800 | N42: 37100 | O42: 42400 | P42: 47700 | Q42: 53000 | R42: 58300 | S42: 63600 | T42: =S42 -> 63600
D43: Total Current Assets | H43: =SUM(H40:H42) -> 198800 | I43: =SUM(I40:I42) -> 207600 | J43: =SUM(J40:J42) -> 216400 | K43: =SUM(K40:K42) -> 225200 | L43: =SUM(L40:L42) -> 234000 | M43: =SUM(M40:M42) -> 242800 | N43: =SUM(N40:N42) -> 251600 | O43: =SUM(O40:O42) -> 260400 | ... T43: =SUM(T40:T42) -> 295600
C45: Non-Current Assets
D46: Property, Plant and Equipment | H46: 1500 | I46: 3000 | J46: 4500 | K46: 6000 | L46: 7500 | M46: 9000 | N46: 10500 | O46: 12000 | P46: 13500 | Q46: 15000 | R46: 16500 | S46: 18000 | T46: =S46 -> 18000
D47: Total Non-Current Assets | H47: =SUM(H46) -> 1500 | I47: =SUM(I46) -> 3000 | J47: =SUM(J46) -> 4500 | K47: =SUM(K46) -> 6000 | L47: =SUM(L46) -> 7500 | M47: =SUM(M46) -> 9000 | N47: =SUM(N46) -> 10500 | O47: =SUM(O46) -> 12000 | ... T47: =SUM(T46) -> 18000
C48: Total Assets | H48: =H43+H47 -> 200300 | I48: =I43+I47 -> 210600 | J48: =J43+J47 -> 220900 | K48: =K43+K47 -> 231200 | L48: =L43+L47 -> 241500 | M48: =M43+M47 -> 251800 | N48: =N43+N47 -> 262100 | O48: =O43+O47 -> 272400 | ... T48: =T43+T47 -> 313600
C50: Current Liabilities
...

Sheet 12-Month Projection
A1: © Person0811. All rights reserved.
A2: MENU | B2: =Profile!F6 -> Person0811
C4: 12 Month Financial Projection
C5: =Formulas!A3 -> Amounts in USD
E6: Case Scenario | F6: =Scenario!E6 -> Base Case
E7: Days in Period | F7: 365 | H7: =Profile!F8 -> 2025
C8: Income Statement | H8: =Formulas!C41 -> January | I8: =Formulas!D41 -> February | J8: =Formulas!E41 -> March | K8: =Formulas!F41 -> April | L8: =Formulas!G41 -> May | M8: =Formulas!H41 -> June | N8: =Formulas!I41 -> July | O8: =Formulas!J41 -> August | ... S8: =Formulas!N41 -> December | T8: FY
D9: Service Sales | H9: =Revenue!G20 -> 17850 | I9: =Revenue!H20 -> 18025 | J9: =Revenue!I20 -> 18200 | K9: =Revenue!J20 -> 18375 | L9: =Revenue!K20 -> 19250 | M9: =Revenue!L20 -> 19600 | N9: =Revenue!M20 -> 18900 | O9: =Revenue!N20 -> 18375 | ... S9: =Revenue!R20 -> 19600 | T9: =SUM(H9:S9) -> 222250
D10: Product Sales | H10: =Revenue!G32 -> 17850 | I10: =Revenue!H32 -> 18025 | J10: =Revenue!I32 -> 18200 | K10: =Revenue!J32 -> 18375 | L10: =Revenue!K32 -> 19250 | M10: =Revenue!L32 -> 19600 | N10: =Revenue!M32 -> 18900 | O10: =Revenue!N32 -> 18375 | ... S10: =Revenue!R32 -> 19600 | T10: =SUM(H10:S10) -> 222250
C11: Total Sales | H11: =SUM(H9:H10) -> 35700 | I11: =SUM(I9:I10) -> 36050 | J11: =SUM(J9:J10) -> 36400 | K11: =SUM(K9:K10) -> 36750 | L11: =SUM(L9:L10) -> 38500 | M11: =SUM(M9:M10) -> 39200 | N11: =SUM(N9:N10) -> 37800 | O11: =SUM(O9:O10) -> 36750 | ... T11: =SUM(T9:T10) -> 444500
D13: Service Cost | H13: =Revenue!G49 -> 2677.5 | I13: =Revenue!H49 -> 2703.75 | J13: =Revenue!I49 -> 2730 | K13: =Revenue!J49 -> 2756.25 | L13: =Revenue!K49 -> 2887.5 | M13: =Revenue!L49 -> 2940 | N13: =Revenue!M49 -> 2835 | O13: =Revenue!N49 -> 2756.25 | ... S13: =Revenue!R49 -> 2940 | T13: =SUM(H13:S13) -> 33337.5
D14: Product Cost | H14: =Revenue!G61 -> 5355 | I14: =Revenue!H61 -> 5407.5 | J14: =Revenue!I61 -> 5460 | K14: =Revenue!J61 -> 5512.5 | L14: =Revenue!K61 -> 5775 | M14: =Revenue!L61 -> 5880 | N14: =Revenue!M61 -> 5670 | O14: =Revenue!N61 -> 5512.5 | ... S14: =Revenue!R61 -> 5880 | T14: =SUM(H14:S14) -> 66675
D15: Direct Labor Cost | H15: =Scenario!$G$12*H11 -> 6426 | I15: =Scenario!$G$12*I11 -> 6489 | J15: =Scenario!$G$12*J11 -> 6552 | K15: =Scenario!$G$12*K11 -> 6615 | L15: =Scenario!$G$12*L11 -> 6930 | M15: =Scenario!$G$12*M11 -> 7056 | N15: =Scenario!$G$12*N11 -> 6804 | O15: =Scenario!$G$12*O11 -> 6615 | ... S15: =Scenario!$G$12*S11 -> 7056 | T15: =SUM(H15:S15) -> 80010
D16: Discounts and Promotions | H16: =Scenario!$G$13*H11 -> 4284 | I16: =Scenario!$G$13*I11 -> 4326 | J16: =Scenario!$G$13*J11 -> 4368 | K16: =Scenario!$G$13*K11 -> 4410 | L16: =Scenario!$G$13*L11 -> 4620 | M16: =Scenario!$G$13*M11 -> 4704 | N16: =Scenario!$G$13*N11 -> 4536 | O16: =Scenario!$G$13*O11 -> 4410 | ... S16: =Scenario!$G$13*S11 -> 4704 | T16: =SUM(H16:S16) -> 53340
C17: Total Cost of Sales | H17: =SUM(H13:H16) -> 18742.5 | I17: =SUM(I13:I16) -> 18926.25 | J17: =SUM(J13:J16) -> 19110 | K17: =SUM(K13:K16) -> 19293.75 | L17: =SUM(L13:L16) -> 20212.5 | M17: =SUM(M13:M16) -> 20580 | N17: =SUM(N13:N16) -> 19845 | O17: =SUM(O13:O16) -> 19293.75 | ... T17: =SUM(T13:T16) -> 233362.5
C19: Gross Profit | H19: =H11-H17 -> 16957.5 | I19: =I11-I17 -> 17123.75 | J19: =J11-J17 -> 17290 | K19: =K11-K17 -> 17456.25 | L19: =L11-L17 -> 18287.5 | M19: =M11-M17 -> 18620 | N19: =N11-N17 -> 17955 | O19: =O11-O17 -> 17456.25 | ... T19: =T11-T17 -> 211137.5
C20: Gross Margin % | H20: =IFERROR(H19/H11,0) -> 0.475 | I20: =IFERROR(I19/I11,0) -> 0.475 | J20: =IFERROR(J19/J11,0) -> 0.475 | K20: =IFERROR(K19/K11,0) -> 0.475 | L20: =IFERROR(L19/L11,0) -> 0.475 | M20: =IFERROR(M19/M11,0) -> 0.475 | N20: =IFERROR(N19/N11,0) -> 0.475 | O20: =IFERROR(O19/O11,0) -> 0.475 | ... T20: =IFERROR(T19/T11,0) -> 0.475
D22: Salaries and Benefits | H22: =Scenario!$G$14/12 -> 4166.6667 | I22: =Scenario!$G$14/12 -> 4166.6667 | J22: =Scenario!$G$14/12 -> 4166.6667 | K22: =Scenario!$G$14/12 -> 4166.6667 | L22: =Scenario!$G$14/12 -> 4166.6667 | M22: =Scenario!$G$14/12 -> 4166.6667 | N22: =Scenario!$G$14/12 -> 4166.6667 | O22: =Scenario!$G$14/12 -> 4166.6667 | ... S22: =Scenario!$G$14/12 -> 4166.6667 | T22: =SUM(H22:S22) -> 50000
D23: Sales and Marketing | H23: =Scenario!$G$15*H11 -> 1428 | I23: =Scenario!$G$15*I11 -> 1442 | J23: =Scenario!$G$15*J11 -> 1456 | K23: =Scenario!$G$15*K11 -> 1470 | L23: =Scenario!$G$15*L11 -> 1540 | M23: =Scenario!$G$15*M11 -> 1568 | N23: =Scenario!$G$15*N11 -> 1512 | O23: =Scenario!$G$15*O11 -> 1470 | ... S23: =Scenario!$G$15*S11 -> 1568 | T23: =SUM(H23:S23) -> 17780
D24: General and Administration | H24: =Scenario!$G$16/12 -> 2916.6667 | I24: =Scenario!$G$16/12 -> 2916.6667 | J24: =Scenario!$G$16/12 -> 2916.6667 | K24: =Scenario!$G$16/12 -> 2916.6667 | L24: =Scenario!$G$16/12 -> 2916.6667 | M24: =Scenario!$G$16/12 -> 2916.6667 | N24: =Scenario!$G$16/12 -> 2916.6667 | O24: =Scenario!$G$16/12 -> 2916.6667 | ... S24: =Scenario!$G$16/12 -> 2916.6667 | T24: =SUM(H24:S24) -> 35000
D25: Credit Card Fees | H25: =Scenario!$G$17*H11 -> 285.6 | I25: =Scenario!$G$17*I11 -> 288.4 | J25: =Scenario!$G$17*J11 -> 291.2 | K25: =Scenario!$G$17*K11 -> 294 | L25: =Scenario!$G$17*L11 -> 308 | M25: =Scenario!$G$17*M11 -> 313.6 | N25: =Scenario!$G$17*N11 -> 302.4 | O25: =Scenario!$G$17*O11 -> 294 | ... S25: =Scenario!$G$17*S11 -> 313.6 | T25: =SUM(H25:S25) -> 3556
D26: Depreciation and Amortization | H26: =Scenario!$G$18*((Scenario!$G$24+Scenario!$G$27)/12) -> 627.08333 | I26: =H26 -> 627.08333 | J26: =I26 -> 627.08333 | K26: =J26 -> 627.08333 | L26: =K26 -> 627.08333 | M26: =L26 -> 627.08333 | N26: =M26 -> 627.08333 | O26: =N26 -> 627.08333 | P26: =O26 -> 627.08333 | ... S26: =R26 -> 627.08333 | T26: =SUM(H26:S26) -> 7525
C27: Total Operating Expenses | H27: =SUM(H22:H26) -> 9424.0167 | I27: =SUM(I22:I26) -> 9440.8167 | J27: =SUM(J22:J26) -> 9457.6167 | K27: =SUM(K22:K26) -> 9474.4167 | L27: =SUM(L22:L26) -> 9558.4167 | M27: =SUM(M22:M26) -> 9592.0167 | N27: =SUM(N22:N26) -> 9524.8167 | O27: =SUM(O22:O26) -> 9474.4167 | ... T27: =SUM(T22:T26) -> 113861
C29: Operating Profit (EBIT) | H29: =H19-H27 -> 7533.4833 | I29: =I19-I27 -> 7682.9333 | J29: =J19-J27 -> 7832.3833 | K29: =K19-K27 -> 7981.8333 | L29: =L19-L27 -> 8729.0833 | M29: =M19-M27 -> 9027.9833 | N29: =N19-N27 -> 8430.1833 | O29: =O19-O27 -> 7981.8333 | ... T29: =T19-T27 -> 97276.5
C30: Operating Margin % | H30: =IFERROR(H29/H11,0) -> 0.21102194 | I30: =IFERROR(I29/I11,0) -> 0.21311882 | J30: =IFERROR(J29/J11,0) -> 0.21517537 | K30: =IFERROR(K29/K11,0) -> 0.21719274 | L30: =IFERROR(L29/L11,0) -> 0.22672944 | M30: =IFERROR(M29/M11,0) -> 0.2303057 | N30: =IFERROR(N29/N11,0) -> 0.22302072 | O30: =IFERROR(O29/O11,0) -> 0.21719274 | ... T30: =IFERROR(T29/T11,0) -> 0.21884477
D32: Interest | H32: =Scenario!$G$30*((Scenario!$G$30*((Scenario!$G$31)/12)+H57)/12) -> 274.35069 | I32: =Scenario!$G$30*((H32+I57)/12) -> 272.438 | J32: =Scenario!$G$30*((I32+J57)/12) -> 270.51951 | K32: =Scenario!$G$30*((J32+K57)/12) -> 268.60099 | L32: =Scenario!$G$30*((K32+L57)/12) -> 266.68248 | M32: =Scenario!$G$30*((L32+M57)/12) -> 264.76396 | N32: =Scenario!$G$30*((M32+N57)/12) -> 262.84545 | O32: =Scenario!$G$30*((N32+O57)/12) -> 260.92693 | P32: =Scenario!$G$30*((O32+P57)/12) -> 259.00842 | ... S32: =Scenario!$G$30*((R32+S57)/12) -> 253.25287 | T32: =SUM(H32:S32) -> 3165.6506
C33: Earnings Before Taxes (EBT) | H33: =H29-H32 -> 7259.1326 | I33: =I29-I32 -> 7410.4953 | J33: =J29-J32 -> 7561.8638 | K33: =K29-K32 -> 7713.2323 | L33: =L29-L32 -> 8462.4009 | M33: =M29-M32 -> 8763.2194 | N33: =N29-N32 -> 8167.3379 | O33: =O29-O32 -> 7720.9064 | ... T33: =T29-T32 -> 94110.849
D35: Income Taxes | H35: =IF(H33>0,Scenario!$G$19*H33,0) -> 1814.7832 | I35: =IF(I33>0,Scenario!$G$19*I33,0) -> 1852.6238 | J35: =IF(J33>0,Scenario!$G$19*J33,0) -> 1890.466 | K35: =IF(K33>0,Scenario!$G$19*K33,0) -> 1928.3081 | L35: =IF(L33>0,Scenario!$G$19*L33,0) -> 2115.6002 | M35: =IF(M33>0,Scenario!$G$19*M33,0) -> 2190.8048 | N35: =IF(N33>0,Scenario!$G$19*N33,0) -> 2041.8345 | O35: =IF(O33>0,Scenario!$G$19*O33,0) -> 1930.2266 | ... T35: =IF(T33>0,Scenario!$G$19*T33,0) -> 23527.712
C36: Net Income | H36: =H33-H35 -> 5444.3495 | I36: =I33-I35 -> 5557.8715 | J36: =J33-J35 -> 5671.3979 | K36: =K33-K35 -> 5784.9243 | L36: =L33-L35 -> 6346.8006 | M36: =M33-M35 -> 6572.4145 | N36: =N33-N35 -> 6125.5034 | O36: =O33-O35 -> 5790.6798 | ... T36: =T33-T35 -> 70583.137
C37: Net Profit Margin % | H37: =IFERROR(H36/H11,0) -> 0.15250279 | I37: =IFERROR(I36/I11,0) -> 0.15417119 | J37: =IFERROR(J36/J11,0) -> 0.15580763 | K37: =IFERROR(K36/K11,0) -> 0.1574129 | L37: =IFERROR(L36/L11,0) -> 0.16485196 | M37: =IFERROR(M36/M11,0) -> 0.16766364 | N37: =IFERROR(N36/N11,0) -> 0.16205035 | O37: =IFERROR(O36/O11,0) -> 0.15756952 | ... T37: =IFERROR(T36/T11,0) -> 0.15879221
C39: Balance Sheet
C40: Current Assets
D41: Cash and Cash Equivalents | H41: =H92 -> 157595.38 | I41: =I92 -> 158757.09 | J41: =J92 -> 159985.15 | K41: =K92 -> 161279.54 | L41: =L92 -> 162900.74 | M41: =M92 -> 164653.4 | N41: =N92 -> 166146.82 | O41: =O92 -> 167446.1 | ... S41: =S92 -> 172720.6 | T41: =S41 -> 172720.6
D42: Accounts Receivable | H42: =Scenario!$G$22*H11/$F$7 -> 3912.3288 | I42: =Scenario!$G$22*I11/$F$7+H42 -> 7863.0137 | J42: =Scenario!$G$22*J11/$F$7+I42 -> 11852.055 | K42: =Scenario!$G$22*K11/$F$7+J42 -> 15879.452 | L42: =Scenario!$G$22*L11/$F$7+K42 -> 20098.63 | M42: =Scenario!$G$22*M11/$F$7+L42 -> 24394.521 | N42: =Scenario!$G$22*N11/$F$7+M42 -> 28536.986 | O42: =Scenario!$G$22*O11/$F$7+N42 -> 32564.384 | P42: =Scenario!$G$22*P11/$F$7+O42 -> 36323.288 | ... S42: =Scenario!$G$22*S11/$F$7+R42 -> 48712.329 | T42: =S42 -> 48712.329
D43: Inventory | H43: =Scenario!$G$23*H17/$F$7 -> 3337.7055 | I43: =Scenario!$G$23*I17/$F$7+H43 -> 6708.1336 | J43: =Scenario!$G$23*J17/$F$7+I43 -> 10111.284 | K43: =Scenario!$G$23*K17/$F$7+J43 -> 13547.158 | L43: =Scenario!$G$23*L17/$F$7+K43 -> 17146.644 | M43: =Scenario!$G$23*M17/$F$7+L43 -> 20811.575 | N43: =Scenario!$G$23*N17/$F$7+M43 -> 24345.616 | O43: =Scenario!$G$23*O17/$F$7+N43 -> 27781.49 | P43: =Scenario!$G$23*P17/$F$7+O43 -> 30988.305 | ... S43: =Scenario!$G$23*S17/$F$7+R43 -> 41557.705 | T43: =S43 -> 41557.705
D44: Total Current Assets | H44: =SUM(H41:H43) -> 164845.41 | I44: =SUM(I41:I43) -> 173328.24 | J44: =SUM(J41:J43) -> 181948.49 | K44: =SUM(K41:K43) -> 190706.15 | L44: =SUM(L41:L43) -> 200146.02 | M44: =SUM(M41:M43) -> 209859.5 | N44: =SUM(N41:N43) -> 219029.42 | O44: =SUM(O41:O43) -> 227791.98 | ... T44: =SUM(T41:T43) -> 262990.63
C46: Non-Current Assets
D47: Property, Plant and Equipment | H47: =(Scenario!$G$24+(Scenario!$G$27/12))-H26 -> 13539.583 | I47: =(Scenario!$G$27)/12-I26+H47 -> 13579.167 | J47: =(Scenario!$G$27)/12-J26+I47 -> 13618.75 | K47: =(Scenario!$G$27)/12-K26+J47 -> 13658.333 | L47: =(Scenario!$G$27)/12-L26+K47 -> 13697.917 | M47: =(Scenario!$G$27)/12-M26+L47 -> 13737.5 | N47: =(Scenario!$G$27)/12-N26+M47 -> 13777.083 | O47: =(Scenario!$G$27)/12-O26+N47 -> 13816.667 | P47: =(Scenario!$G$27)/12-P26+O47 -> 13856.25 | ... S47: =(Scenario!$G$27)/12-S26+R47 -> 13975 | T47: =S47 -> 13975
D48: Total Non-Current Assets | H48: =SUM(H47) -> 13539.583 | I48: =SUM(I47) -> 13579.167 | J48: =SUM(J47) -> 13618.75 | K48: =SUM(K47) -> 13658.333 | L48: =SUM(L47) -> 13697.917 | M48: =SUM(M47) -> 13737.5 | N48: =SUM(N47) -> 13777.083 | O48: =SUM(O47) -> 13816.667 | ... T48: =SUM(T47) -> 13975
C49: Total Assets | H49: =H44+H48 -> 178385 | I49: =I44+I48 -> 186907.41 | J49: =J44+J48 -> 195567.24 | K49: =K44+K48 -> 204364.49 | L49: =L44+L48 -> 213843.93 | M49: =M44+M48 -> 223597 | N49: =N44+N48 -> 232806.5 | O49: =O44+O48 -> 241608.64 | ... T49: =T44+T48 -> 276965.63
...

Sheet Variance
A1: © Person0811. All rights reserved.
A2: MENU | B2: =Profile!F6 -> Person0811
C4: Variance Analysis
C5: =Formulas!A3 -> Amounts in USD
F6: Year to Date | L6: Current Month | M6: February
C7: Income Statement | F7: Actual | G7: Budget | H7: ∆PL | I7: ∆PL (%) | K7: Actual | L7: Budget | M7: ∆PL | N7: ∆PL (%)
D8: Service Sales | F8: =Formulas!$O145 -> 70000 | G8: =Formulas!$O164 -> 35875 | H8: =F8-G8 -> 34125 | I8: =H8/G8 -> 0.95121951 | K8: =Formulas!$P145 -> 35000 | L8: =Formulas!$P164 -> 18025 | M8: =K8-L8 -> 16975 | N8: =M8/L8 -> 0.94174757
D9: Product Sales | F9: =Formulas!$O146 -> 20000 | G9: =Formulas!$O165 -> 35875 | H9: =F9-G9 -> -15875 | I9: =H9/G9 -> -0.44250871 | K9: =Formulas!$P146 -> 10000 | L9: =Formulas!$P165 -> 18025 | M9: =K9-L9 -> -8025 | N9: =M9/L9 -> -0.44521498
C10: Revenue | F10: =SUM(F8:F9) -> 90000 | G10: =SUM(G8:G9) -> 71750 | H10: =F10-G10 -> 18250 | I10: =H10/G10 -> 0.2543554 | K10: =SUM(K8:K9) -> 45000 | L10: =SUM(L8:L9) -> 36050 | M10: =K10-L10 -> 8950 | N10: =M10/L10 -> 0.2482663
D11: Cost of Sales | F11: =Formulas!$O147 -> 56000 | G11: =Formulas!$O166 -> 37668.75 | H11: =F11-G11 -> 18331.25 | I11: =H11/G11 -> 0.48664344 | K11: =Formulas!$P147 -> 28000 | L11: =Formulas!$P166 -> 18926.25 | M11: =K11-L11 -> 9073.75 | N11: =M11/L11 -> 0.47942672
C12: Gross Profit | F12: =F10-F11 -> 34000 | G12: =G10-G11 -> 34081.25 | H12: =F12-G12 -> -81.25 | I12: =H12/G12 -> -0.0023840088 | K12: =SUM(K8:K9)-K11 -> 17000 | L12: =L10-L11 -> 17123.75 | M12: =K12-L12 -> -123.75 | N12: =M12/L12 -> -0.0072268049
C13: Gross Margin % | F13: =IFERROR(F12/SUM($F$8:$F$9),"") -> 0.37777778 | G13: =IFERROR(G12/SUM($G$8:$G$9),"") -> 0.475 | K13: =IFERROR(K12/SUM($K$8:$K$9),"") -> 0.37777778 | L13: =IFERROR(L12/SUM($L$8:$L$9),"") -> 0.475
D15: Salaries and Benefits | F15: =Formulas!$O148 -> 8000 | G15: =Formulas!$O167 -> 8333.3333 | H15: =F15-G15 -> -333.33333 | I15: =H15/G15 -> -0.04 | K15: =Formulas!$P148 -> 4000 | L15: =Formulas!$P167 -> 4166.6667 | M15: =K15-L15 -> -166.66667 | N15: =M15/L15 -> -0.04
D16: Sales and Marketing | F16: =Formulas!$O149 -> 5000 | G16: =Formulas!$O168 -> 2870 | H16: =F16-G16 -> 2130 | I16: =H16/G16 -> 0.74216028 | K16: =Formulas!$P149 -> 2500 | L16: =Formulas!$P168 -> 1442 | M16: =K16-L16 -> 1058 | N16: =M16/L16 -> 0.73370319
D17: General and Administration | F17: =Formulas!$O150 -> 7000 | G17: =Formulas!$O169 -> 5833.3333 | H17: =F17-G17 -> 1166.6667 | I17: =H17/G17 -> 0.2 | K17: =Formulas!$P150 -> 3500 | L17: =Formulas!$P169 -> 2916.6667 | M17: =K17-L17 -> 583.33333 | N17: =M17/L17 -> 0.2
D18: Credit Card Fees | F18: =Formulas!$O151 -> 900 | G18: =Formulas!$O170 -> 574 | H18: =F18-G18 -> 326 | I18: =H18/G18 -> 0.56794425 | K18: =Formulas!$P151 -> 450 | L18: =Formulas!$P170 -> 288.4 | M18: =K18-L18 -> 161.6 | N18: =M18/L18 -> 0.56033287
D19: Depreciation and Amortization | F19: =Formulas!$O152 -> 1600 | G19: =Formulas!$O171 -> 1254.1667 | H19: =F19-G19 -> 345.83333 | I19: =H19/G19 -> 0.27574751 | K19: =Formulas!$P152 -> 800 | L19: =Formulas!P171 -> 627.08333 | M19: =K19-L19 -> 172.91667 | N19: =M19/L19 -> 0.27574751
