Workbook
Name IQ_CH: 110000
Name IQ_CQ: 5000
Name IQ_CY: 10000
Name IQ_DAILY: 500000
Name IQ_FH: 100000
Name IQ_FQ: 500
Name IQ_FY: 1000
Name IQ_LTM: 2000
Name IQ_MONTH: 15000
Name IQ_NTM: 6000
Name IQ_WEEK: 50000
Name IQ_YTD: 3000

Sheet GL-Summary
B2: General Ledger Summary
B4: Account | C4: Description | D4: Total Debits | E4: Total Credits | F4: Net Balance
B5: 9804018 | C5: FCOSIEGE FRAIS GENERAUX Impôts et t | D5: =SUMIFS('GL-Transactions'!C:C,'GL-Transactions'!G:G,"Total",'GL-Transactions'!E:E,B5) -> 1664283 | E5: =SUMIFS('GL-Transactions'!B:B,'GL-Transactions'!G:G,"Total",'GL-Transactions'!E:E,B5) -> 0 | F5: =D5-E5 -> 1664283
B6: 9804017 | C6: FCOSIEGE FRAIS GENERAUX Amort & pro | D6: =SUMIFS('GL-Transactions'!C:C,'GL-Transactions'!G:G,"Total",'GL-Transactions'!E:E,B6) -> 39103689 | E6: =SUMIFS('GL-Transactions'!B:B,'GL-Transactions'!G:G,"Total",'GL-Transactions'!E:E,B6) -> 0 | F6: =D6-E6 -> 39103689
B7: 9804016 | C7: FCOSIEGE FRAIS GENERAUX Intétrêts e | D7: =SUMIFS('GL-Transactions'!C:C,'GL-Transactions'!G:G,"Total",'GL-Transactions'!E:E,B7) -> 11741512 | E7: =SUMIFS('GL-Transactions'!B:B,'GL-Transactions'!G:G,"Total",'GL-Transactions'!E:E,B7) -> 23200 | F7: =D7-E7 -> 11718312
B8: 9804015 | C8: FCOSIEGE FRAIS GENERAUX Frais gx et | D8: =SUMIFS('GL-Transactions'!C:C,'GL-Transactions'!G:G,"Total",'GL-Transactions'!E:E,B8) -> 846756 | E8: =SUMIFS('GL-Transactions'!B:B,'GL-Transactions'!G:G,"Total",'GL-Transactions'!E:E,B8) -> 0 | F8: =D8-E8 -> 846756
B9: 9804011 | C9: FCOSIEGE FRAIS GENERAUX Autres frai | D9: =SUMIFS('GL-Transactions'!C:C,'GL-Transactions'!G:G,"Total",'GL-Transactions'!E:E,B9) -> 594395 | E9: =SUMIFS('GL-Transactions'!B:B,'GL-Transactions'!G:G,"Total",'GL-Transactions'!E:E,B9) -> 0 | F9: =D9-E9 -> 594395
B10: 9804009 | C10: FCOSIEGE FRAIS GENERAUX Frais télép | D10: =SUMIFS('GL-Transactions'!C:C,'GL-Transactions'!G:G,"Total",'GL-Transactions'!E:E,B10) -> 937920 | E10: =SUMIFS('GL-Transactions'!B:B,'GL-Transactions'!G:G,"Total",'GL-Transactions'!E:E,B10) -> 0 | F10: =D10-E10 -> 937920
B11: 9804007 | C11: FCOSIEGE FRAIS GENERAUX Loyers et l | D11: =SUMIFS('GL-Transactions'!C:C,'GL-Transactions'!G:G,"Total",'GL-Transactions'!E:E,B11) -> 11159715 | E11: =SUMIFS('GL-Transactions'!B:B,'GL-Transactions'!G:G,"Total",'GL-Transactions'!E:E,B11) -> 0 | F11: =D11-E11 -> 11159715
B12: 9801010 | C12: FCOSIEGE PERS ADM Salaires & chges | D12: =SUMIFS('GL-Transactions'!C:C,'GL-Transactions'!G:G,"Total",'GL-Transactions'!E:E,B12) -> 22835205 | E12: =SUMIFS('GL-Transactions'!B:B,'GL-Transactions'!G:G,"Total",'GL-Transactions'!E:E,B12) -> 39470824 | F12: =D12-E12 -> -16635619
B13: 9706016 | C13: QUALDEV Frais opérat ind impu Intét | D13: =SUMIFS('GL-Transactions'!C:C,'GL-Transactions'!G:G,"Total",'GL-Transactions'!E:E,B13) -> 84353 | E13: =SUMIFS('GL-Transactions'!B:B,'GL-Transactions'!G:G,"Total",'GL-Transactions'!E:E,B13) -> 0 | F13: =D13-E13 -> 84353
B14: 9706005 | C14: QUALDEV Frais opérat ind impu Honor | D14: =SUMIFS('GL-Transactions'!C:C,'GL-Transactions'!G:G,"Total",'GL-Transactions'!E:E,B14) -> 327750 | E14: =SUMIFS('GL-Transactions'!B:B,'GL-Transactions'!G:G,"Total",'GL-Transactions'!E:E,B14) -> 0 | F14: =D14-E14 -> 327750
B15: 9706003 | C15: QUALDEV Frais opérat ind impu Redev | D15: =SUMIFS('GL-Transactions'!C:C,'GL-Transactions'!G:G,"Total",'GL-Transactions'!E:E,B15) -> 11366472 | E15: =SUMIFS('GL-Transactions'!B:B,'GL-Transactions'!G:G,"Total",'GL-Transactions'!E:E,B15) -> 0 | F15: =D15-E15 -> 11366472
B16: 9705308 | C16: QUALDEV FR VHC S3 Frais roulement V | D16: =SUMIFS('GL-Transactions'!C:C,'GL-Transactions'!G:G,"Total",'GL-Transactions'!E:E,B16) -> 398232 | E16: =SUMIFS('GL-Transactions'!B:B,'GL-Transactions'!G:G,"Total",'GL-Transactions'!E:E,B16) -> 0 | F16: =D16-E16 -> 398232
... B574: 11 | C574: QUALITY CERT | D574: =SUMIFS('GL-Transactions'!C:C,'GL-Transactions'!G:G,"Total",'GL-Transactions'!E:E,B574) -> 48760000 | E574: =SUMIFS('GL-Transactions'!B:B,'GL-Transactions'!G:G,"Total",'GL-Transactions'!E:E,B574) -> 156386981 | F574: =D574-E574 -> -107626981
B575: GRAND TOTAL | D575: =SUM(D5:D574) -> 1712749956 | E575: =SUM(E5:E574) -> 1844657779 | F575: =D575-E575 -> -131907823

Sheet GL-Transactions
A1: Balance | B1: Credits | C1: Debits | D1: Ref# | E1: Type | F1: Description | G1: Date
A2: =C2-B2 -> 0
A3: =C3-B3 -> 0 | D3: Company1063 Company0081 Frais Missions | G3: 1110101
A4: =C4-B4 -> 0 | F4: PERDIEM AUDITS | G4: 63841000
A5: =C5-B5 -> 95881 | C5: 95881 | D5: 151 | E5: ACH | F5: PERDIEMS AUDITEUR MISSION Company1057 /Company0725 | G5: 44712
A6: =C6-B6 -> 95881 | C6: 95881
A7: =C7-B7 -> 95881 | C7: 95881 | E7: 1110101 | F7: Company1063 Company0081 Frais Missions | G7: Total
A8: =C8-B8 -> 0 | D8: Company0081 Honoraires | G8: 1110105
A9: =C9-B9 -> 0 | F9: HONORAIRE | G9: 63240000
A10: =C10-B10 -> 215625 | C10: 215625 | D10: 256 | E10: ACH | F10: FA N°01 HONORAIRES Person0864 Person0726 | G10: 44778
A11: =C11-B11 -> 215625 | C11: 215625
A12: =C12-B12 -> 215625 | C12: 215625 | E12: 1110105 | F12: Company0081 Honoraires | G12: Total
A13: =C13-B13 -> 0 | D13: Company0081 Chiffre d'affaires | G13: 1110121
A14: =C14-B14 -> 0 | F14: SERVICES VENDUS NON TAXABLES | G14: 70612000
A15: =C15-B15 -> -1589177 | B15: 1589177 | D15: 15 | E15: VTE | F15: AUDIT Company1063 ET QC FA 025 Company0081 | G15: 44600
A16: =C16-B16 -> -1589177 | B16: 1589177
A17: =C17-B17 -> -1589177 | B17: 1589177 | E17: 1110121 | F17: Company0081 Chiffre d'affaires | G17: Total
A18: =C18-B18 -> 0 | D18: Company1063 DOSSIER Company0294 Frais Missions | G18: 1110301
A19: =C19-B19 -> 0 | F19: PERDIEM AUDITS | G19: 63841000
A20: =C20-B20 -> 34500 | C20: 34500 | D20: 29 | E20: BQ 1 | F20: CHQ N°2280895 RGLT PERDIEM Person1005 Person0010 MISSION Company0294 | G20: 44631
A21: =C21-B21 -> 139495 | C21: 139495 | D21: 128 | E21: ACH | F21: PERDIEMS AUDITEUR MISSION Company0294/Company0725 | G21: 44692
A22: =C22-B22 -> 173995 | C22: 173995
A23: =C23-B23 -> 173995 | C23: 173995 | E23: 1110301 | F23: Company1063 DOSSIER Company0294 Frais Missions | G23: Total
A24: =C24-B24 -> 0 | D24: Company1063 DOSSIER Company0294 Dép.&Transp. | G24: 1110302
A25: =C25-B25 -> 0 | F25: Frais voyages et dépl. audits | G25: 61811000
A26: =C26-B26 -> 32200 | C26: 32200 | D26: 301 | E26: ACH | F26: FA N°0003471 Company2325 BILLET Person1005 Person0010 MISSION Product0082 DOR Company0551 NFG | G26: 44830
A27: =C27-B27 -> 32200 | C27: 32200
A28: =C28-B28 -> 32200 | C28: 32200 | E28: 1110302 | F28: Company1063 DOSSIER Company0294 Dép.&Transp. | G28: Total
A29: =C29-B29 -> 0 | D29: Company1063 DOSSIER Company0294 Autres frais d | G29: 1110304
A30: =C30-B30 -> 0 | F30: FRAIS DE RECEPTION | G30: 63833
A31: =C31-B31 -> 84180 | C31: 84180 | D31: 52 | E31: ACH | F31: FA N°0026 Company0831 CI FRAIS DE RESTAURAT° MISSION Company0294 | G31: 44635
A32: =C32-B32 -> 84180 | C32: 84180
A33: =C33-B33 -> 84180 | C33: 84180 | E33: 1110304 | F33: Company1063 DOSSIER Company0294 Autres frais d | G33: Total
A34: =C34-B34 -> 0 | D34: Company2372 Frais Missions | G34: 1110501
A35: =C35-B35 -> 0 | F35: PERDIEM AUDITS | G35: 63841000
A36: =C36-B36 -> 69805 | C36: 69805 | D36: 50 | E36: OD | F36: PERDIEMS AUDITEUR MISSION Company2372 | G36: 44763
A37: =C37-B37 -> 69805 | C37: 69805 | D37: 78 | E37: OD | F37: PERDIEMS AUDITEUR MISSION Company2372 | G37: 44774
A38: =C38-B38 -> 139610 | C38: 139610
A39: =C39-B39 -> 139610 | C39: 139610 | E39: 1110501 | F39: Company2372 Frais Missions | G39: Total
A40: =C40-B40 -> 0 | D40: Company2372 Honoraires | G40: 1110505
...

Sheet Sheet1
F3: Debits | G3: Credits
D4: 1114701 | E4: DOSSIER AFRICA FOOD Frais Missions | F4: 103500 | G4: 0
D5: 1331302 | E5: RFA Person0018 Person0559 Dép.&Transp. | F5: 0 | G5: 0
D6: 1335801 | E6: RFA Company2197 Frais Missions | F6: 2875 | G6: 0
D7: 1116321 | E7: Company1063 Company0304 Chiffre d'affaires | F7: 1980108 | G7: 2300670
D8: 9702010 | E8: QUALDEV PERS PROF. Salaires & chges | F8: 5980000 | G8: 0
D9: 1115202 | E9: Company1063 Company1989 FRUITS Dép.&Transp. | F9: 0 | G9: 0
D10: 1114721 | E10: AFRICA FOOD Chiffre d'affaires | F10: 69748 | G10: 3515410
D11: 4170321 | E11: Company0888 Company0561 CAFE -Company0422 Chiffre | F11: 2277460 | G11: 64398168
D12: 1115805 | E12: Company0720- Company0951 Honoraires | F12: 87228 | G12: 0
D13: 1115801 | E13: Company0721 Frais Missions | F13: 883200 | G13: 0
D14: 1115502 | E14: Company1063 RPG SENEGAL Dép.&Transp. | F14: 69805 | G14: 0
D15: 1115402 | E15: Company1063 DOSSIER Product0356 Dép.&Transp. | F15: 345000 | G15: 0
... D48: 1115605 | E48: Company0048 Honoraires | F48: 139495 | G48: 0
