Workbook
Name calendar: #REF!
Name Ccy: Inputs!$C$21
Name circ: Inputs!$C$24
Name CoName: Inputs!$C$19
Name Ticker0005_Share_Price: #REF!
Name IQ_CH: 110000
Name IQ_CQ: 5000
Name IQ_CY: 10000
Name IQ_DAILY: 500000
Name IQ_FH: 100000
Name IQ_FQ: 500
Name IQ_FY: 1000
Name IQ_LTM: 2000
Name IQ_MONTH: 15000
Name IQ_NTM: 6000
Name IQ_WEEK: 50000
Name IQ_YTD: 3000
Name refin: #REF!
Name roll: #REF!
Name Units: Inputs!$C$22

Sheet Inputs
A1: Financial Forecasting and Modeling
A2: Fully integrated financial model
A4: Special features
B6: Detailed revenue forecast
B7: Cash sweep with revolver (including mandated repayments)
B8: Positive presentation income statement
B9: Non-threaded assumptions
B10: OWC accounts forecast on days
B11: Cash and revolver
B12: Ratios
A17: Model information
B19: Company name | C19: Company1825
B20: Latest BS date | C20: 43100
B21: Currency | C21: USD
B22: Units | C22: m
B23: Analyst name | C23: Analyst name
B24: Circular switch | C24: 1

Sheet Assumptions
A1: =CoName | C1: Hist. | D1: Hist. | E1: Hist. | F1: Proj. | G1: Proj. | H1: Proj. | I1: Proj. | J1: Proj.
A2: Assumptions | C2: =DATE(YEAR(D2)-1,MONTH(D2),DAY(D2)) | D2: =DATE(YEAR(E2)-1,MONTH(E2),DAY(E2)) | E2: =Inputs!C20 | F2: =DATE(YEAR(E2)+1,MONTH(E2),DAY(E2)) | G2: =DATE(YEAR(F2)+1,MONTH(F2),DAY(F2)) | H2: =DATE(YEAR(G2)+1,MONTH(G2),DAY(G2)) | I2: =DATE(YEAR(H2)+1,MONTH(H2),DAY(H2)) | J2: =DATE(YEAR(I2)+1,MONTH(I2),DAY(I2))
A4: Income statement
B5: COGS % of sales | C5: =+IS!C5/IS!C4 | D5: =+IS!D5/IS!D4 | E5: =+IS!E5/IS!E4 | F5: 0.61 | G5: 0.61 | H5: 0.61 | I5: 0.61 | J5: 0.61
B6: SG&A % of sales | C6: =+IS!C8/IS!C4 | D6: =+IS!D8/IS!D4 | E6: =+IS!E8/IS!E4 | F6: 0.215 | G6: 0.215 | H6: 0.215 | I6: 0.215 | J6: 0.215
B7: Amortization amount | C7: =+IS!C12 | D7: =+IS!D12 | E7: =+IS!E12 | F7: 175 | G7: 175 | H7: 175 | I7: 85 | J7: 85
B8: Non-recurring income / (expense) amount | C8: =+IS!C17 | D8: =+IS!D17 | E8: =+IS!E17 | F8: 0 | G8: 0 | H8: 0 | I8: 0 | J8: 0
B9: Effective tax rate | C9: =(593-(6822-6600))/(7884-6822) | D9: =129/1454 | E9: =688/3121 | F9: 0.22 | G9: 0.22 | H9: 0.22 | I9: 0.22 | J9: 0.22
B10: Marginal tax rate | C10: =35%+-0.1% | D10: =35%+0.8% | E10: =35%+0.8% | F10: =21%+1% | G10: =21%+1% | H10: =21%+1% | I10: =21%+1% | J10: =21%+1%
B11: Basic WASO | C11: =+IS!C29 | D11: =+IS!D29 | E11: =+IS!E29 | F11: 1487.3285 | G11: =F11 | H11: =G11 | I11: =H11 | J11: =I11
B12: Diluted WASO | C12: =+IS!C30 | D12: =+IS!D30 | E12: =+IS!E30 | F12: =+E12/E11*F11 | G12: =+F12/F11*G11 | H12: =+G12/G11*H11 | I12: =+H12/H11*I11 | J12: =+I12/I11*J11
B13: Dividend per share growth rate | D13: =+IS!D33/IS!C33-1 | E13: =+IS!E33/IS!D33-1 | F13: 0.1 | G13: 0.05 | H13: 0.05 | I13: 0.05 | J13: 0.05
A14: Balance sheet
B15: Receivables days | D15: =+BS!D5/IS!D4*365 | E15: =+BS!E5/IS!E4*365 | F15: 49.5 | G15: 49.5 | H15: 49.5 | I15: 49.5 | J15: 49.5
B16: Inventory days | D16: =+BS!D6/IS!D5*365 | E16: =+BS!E6/IS!E5*365 | F16: 58 | G16: 58 | H16: 58 | I16: 58 | J16: 58
B17: Other current assets % of sales | D17: =+BS!D7/IS!D4 | E17: =+BS!E7/IS!E4 | F17: 0.027 | G17: 0.027 | H17: 0.027 | I17: 0.027 | J17: 0.027
B18: Goodwill amount | D18: =+BS!D11 | E18: =+BS!E11 | F18: =E18 | G18: =F18 | H18: =G18 | I18: =H18 | J18: =I18
B19: Other long-term assets % of sales | D19: =BS!D14/IS!D4 | E19: =BS!E14/IS!E4 | F19: 0.033 | G19: 0.033 | H19: 0.033 | I19: 0.033 | J19: 0.033
B20: Equity method investments $ amount | D20: =BS!D13 | E20: =BS!E13 | F20: 6450 | G20: 6500 | H20: 6550 | I20: 6600 | J20: 6650
B21: Payable days | D21: =+BS!D20/IS!D5*365 | E21: =+BS!E20/IS!E5*365 | F21: 130 | G21: 130 | H21: 130 | I21: 130 | J21: 130
B22: Accrued marketing % of sales | D22: =+BS!D21/IS!D4 | E22: =+BS!E21/IS!E4 | F22: 0.067 | G22: 0.067 | H22: 0.067 | I22: 0.067 | J22: 0.067
B23: Accrued employment costs % of sales | D23: =+BS!D22/IS!D4 | E23: =+BS!E22/IS!E4 | F23: 0.028 | G23: 0.028 | H23: 0.028 | I23: 0.028 | J23: 0.028
B24: Other current liabilities % of sales | D24: =BS!D23/IS!D4 | E24: =BS!E23/IS!E4 | F24: 0.11 | G24: 0.11 | H24: 0.11 | I24: 0.11 | J24: 0.11
B25: Deferred taxes % of sales | D25: =+BS!D27/IS!D4 | E25: =+BS!E27/IS!E4 | F25: 0.14 | G25: 0.13 | H25: 0.12 | I25: 0.11 | J25: 0.09
B26: Other long-term liabilities % of sales | D26: =+BS!D28/IS!D4 | E26: =+BS!E28/IS!E4 | F26: 0.16 | G26: 0.15 | H26: 0.14 | I26: 0.12 | J26: 0.11
A27: PP&E
B28: Capital expenditure % of sales | C28: =+Calcs!C6/IS!C4 | D28: =+Calcs!D6/IS!D4 | E28: =+Calcs!E6/IS!E4 | F28: 0.039 | G28: 0.039 | H28: 0.039 | I28: 0.039 | J28: 0.039
B29: Depreciation % of beginning PP&E | E29: =+IS!E11/BS!D10 | F29: 0.078 | G29: 0.078 | H29: 0.078 | I29: 0.078 | J29: 0.078
A30: Equity
B31: Share issuance / (repurchases) | F31: 0 | G31: 0 | H31: 0 | I31: 0 | J31: 0
A32: Cash available for debt repayment
B33: Minimum cash % of sales | F33: 0.005 | G33: 0.005 | H33: 0.005 | I33: 0.005 | J33: 0.005
A34: Interest rates
B35: =Debt!B12 | F35: 0.018 | G35: 0.018 | H35: 0.018 | I35: 0.018 | J35: 0.018
B36: =Debt!B21 | F36: 0.03414 | G36: 0.03414 | H36: 0.03414 | I36: 0.03414 | J36: 0.03414
B37: =Debt!B30 | F37: 0.0193 | G37: 0.0193 | H37: 0.0193 | I37: 0.0193 | J37: 0.0193
B38: =Debt!B39 | F38: 0.015 | G38: 0.015 | H38: 0.015 | I38: 0.015 | J38: 0.015
B39: Interest income on cash | F39: 0.01 | G39: 0.01 | H39: 0.01 | I39: 0.01 | J39: 0.01

Sheet Revenues
A1: =CoName | C1: Hist. | D1: Hist. | E1: Hist. | F1: Proj. | G1: Proj. | H1: Proj. | I1: Proj. | J1: Proj.
A2: Revenues | C2: =DATE(YEAR(D2)-1,MONTH(D2),DAY(D2)) | D2: =DATE(YEAR(E2)-1,MONTH(E2),DAY(E2)) | E2: =Inputs!C20 | F2: =DATE(YEAR(E2)+1,MONTH(E2),DAY(E2)) | G2: =DATE(YEAR(F2)+1,MONTH(F2),DAY(F2)) | H2: =DATE(YEAR(G2)+1,MONTH(G2),DAY(G2)) | I2: =DATE(YEAR(H2)+1,MONTH(H2),DAY(H2)) | J2: =DATE(YEAR(I2)+1,MONTH(I2),DAY(I2))
A4: North America
B5: CPI increase / (decrease) % | F5: 0.016043686 | G5: 0.018081827 | H5: 0.019847766 | I5: 0.01982264 | J5: 0.020617745
B6: Price growth over / (under) CPI % | F6: 0.01 | G6: 0.01 | H6: 0.005 | I6: 0.005 | J6: 0
B7: Price growth % (additive) | F7: =SUM(F5:F6) | G7: =SUM(G5:G6) | H7: =SUM(H5:H6) | I7: =SUM(I5:I6) | J7: =SUM(J5:J6)
B8: Population growth increase | F8: 0.008 | G8: 0.008 | H8: 0.008 | I8: 0.008 | J8: 0.008
B9: Market share growth / (decline) | F9: 0 | G9: -0.01 | H9: -0.01 | I9: 0.005 | J9: 0
B10: Volume growth | F10: =(1+F8)*(1+F9)-1 | G10: =(1+G8)*(1+G9)-1 | H10: =(1+H8)*(1+H9)-1 | I10: =(1+I8)*(1+I9)-1 | J10: =(1+J8)*(1+J9)-1
B11: Sales growth | D11: =D12/C12-1 | E11: =E12/D12-1 | F11: =(1+F7)*(1+F10)-1 | G11: =(1+G7)*(1+G10)-1 | H11: =(1+H7)*(1+H10)-1 | I11: =(1+I7)*(1+I10)-1 | J11: =(1+J7)*(1+J10)-1
B12: =A4&" Sales" | C12: 6974 | D12: 6960 | E12: 6797 | F12: =(1+F11)*E12 | G12: =(1+G11)*F12 | H12: =(1+H11)*G12 | I12: =(1+I11)*H12 | J12: =(1+J11)*I12
A13: Europe
B14: CPI increase / (decrease) % | F14: 0.007 | G14: 0.007 | H14: 0.01 | I14: 0.015 | J14: 0.015
B15: Price growth over / (under) CPI % | F15: 0.01 | G15: 0.01 | H15: 0.005 | I15: 0.005 | J15: 0
B16: Price growth % (additive) | F16: =SUM(F14:F15) | G16: =SUM(G14:G15) | H16: =SUM(H14:H15) | I16: =SUM(I14:I15) | J16: =SUM(J14:J15)
B17: Population growth increase | F17: 0.008 | G17: 0.008 | H17: 0.008 | I17: 0.008 | J17: 0.008
B18: Market share growth / (decline) | F18: 0 | G18: -0.01 | H18: -0.01 | I18: 0.005 | J18: 0
B19: Volume growth | F19: =(1+F17)*(1+F18)-1 | G19: =(1+G17)*(1+G18)-1 | H19: =(1+H17)*(1+H18)-1 | I19: =(1+I17)*(1+I18)-1 | J19: =(1+J17)*(1+J18)-1
B20: Sales growth | D20: =D21/C21-1 | E20: =E21/D21-1 | F20: =(1+F16)*(1+F19)-1 | G20: =(1+G16)*(1+G19)-1 | H20: =(1+H16)*(1+H19)-1 | I20: =(1+I16)*(1+I19)-1 | J20: =(1+J16)*(1+J19)-1
B21: =A13&" Sales" | C21: 11672 | D21: 9755 | E21: 9794 | F21: =(1+F20)*E21 | G21: =(1+G20)*F21 | H21: =(1+H20)*G21 | I21: =(1+I20)*H21 | J21: =(1+J20)*I21
A22: Latin America
B23: CPI increase / (decrease) % | F23: 0.045 | G23: 0.04 | H23: 0.04 | I23: 0.035 | J23: 0.035
B24: Price growth over / (under) CPI % | F24: 0.01 | G24: 0.01 | H24: 0.005 | I24: 0.005 | J24: 0
B25: Price growth % (additive) | F25: =SUM(F23:F24) | G25: =SUM(G23:G24) | H25: =SUM(H23:H24) | I25: =SUM(I23:I24) | J25: =SUM(J23:J24)
B26: Population growth increase | F26: 0.007 | G26: 0.007 | H26: 0.007 | I26: 0.007 | J26: 0.007
B27: Market share growth / (decline) | F27: 0.005 | G27: -0.01 | H27: 0 | I27: 0.005 | J27: 0
B28: Volume growth | F28: =(1+F26)*(1+F27)-1 | G28: =(1+G26)*(1+G27)-1 | H28: =(1+H26)*(1+H27)-1 | I28: =(1+I26)*(1+I27)-1 | J28: =(1+J26)*(1+J27)-1
B29: Sales growth | D29: =D30/C30-1 | E29: =E30/D30-1 | F29: =(1+F25)*(1+F28)-1 | G29: =(1+G25)*(1+G28)-1 | H29: =(1+H25)*(1+H28)-1 | I29: =(1+I25)*(1+I28)-1 | J29: =(1+J25)*(1+J28)-1
B30: =A22&" Sales" | C30: 4988 | D30: 3392 | E30: 3566 | F30: =(1+F29)*E30 | G30: =(1+G29)*F30 | H30: =(1+H29)*G30 | I30: =(1+I29)*H30 | J30: =(1+J29)*I30
A31: Other
B32: CPI increase / (decrease) % | F32: 0.025 | G32: 0.025 | H32: 0.02 | I32: 0.02 | J32: 0.02
B33: Price growth over / (under) CPI % | F33: 0.01 | G33: 0.01 | H33: 0.005 | I33: 0.005 | J33: 0
B34: Price growth % (additive) | F34: =SUM(F32:F33) | G34: =SUM(G32:G33) | H34: =SUM(H32:H33) | I34: =SUM(I32:I33) | J34: =SUM(J32:J33)
B35: Population growth increase | F35: 0.01 | G35: 0.01 | H35: 0.01 | I35: 0.01 | J35: 0.01
B36: Market share growth / (decline) | F36: 0.008 | G36: -0.005 | H36: 0 | I36: 0.005 | J36: 0
B37: Volume growth | F37: =(1+F35)*(1+F36)-1 | G37: =(1+G35)*(1+G36)-1 | H37: =(1+H35)*(1+H36)-1 | I37: =(1+I35)*(1+I36)-1 | J37: =(1+J35)*(1+J36)-1
B38: Sales growth | D38: =D39/C39-1 | E38: =E39/D39-1 | F38: =(1+F34)*(1+F37)-1 | G38: =(1+G34)*(1+G37)-1 | H38: =(1+H34)*(1+H37)-1 | I38: =(1+I34)*(1+I37)-1 | J38: =(1+J34)*(1+J37)-1
B39: =A31&" Sales" | C39: 6002 | D39: 5816 | E39: 5739 | F39: =(1+F38)*E39 | G39: =(1+G38)*F39 | H39: =(1+H38)*G39 | I39: =(1+I38)*H39 | J39: =(1+J38)*I39
A41: Sales summary
B42: Total sales | C42: =SUM(C12,C21,C39,C30) | D42: =SUM(D12,D21,D39,D30) | E42: =SUM(E12,E21,E39,E30) | F42: =SUM(F12,F21,F39,F30) | G42: =SUM(G12,G21,G39,G30) | H42: =SUM(H12,H21,H39,H30) | I42: =SUM(I12,I21,I39,I30) | J42: =SUM(J12,J21,J39,J30)
...

Sheet Calcs
A1: =CoName | C1: Hist. | D1: Hist. | E1: Hist. | F1: Proj. | G1: Proj. | H1: Proj. | I1: Proj. | J1: Proj.
A2: Calcs | C2: =DATE(YEAR(D2)-1,MONTH(D2),DAY(D2)) | D2: =DATE(YEAR(E2)-1,MONTH(E2),DAY(E2)) | E2: =Inputs!C20 | F2: =DATE(YEAR(E2)+1,MONTH(E2),DAY(E2)) | G2: =DATE(YEAR(F2)+1,MONTH(F2),DAY(F2)) | H2: =DATE(YEAR(G2)+1,MONTH(G2),DAY(G2)) | I2: =DATE(YEAR(H2)+1,MONTH(H2),DAY(H2)) | J2: =DATE(YEAR(I2)+1,MONTH(I2),DAY(I2))
A4: PP&E
B5: Beginning balance | F5: =E8 | G5: =F8 | H5: =G8 | I5: =H8 | J5: =I8
B6: Capital expenditure | C6: 1514 | D6: 1224 | E6: 1014 | F6: =Assumptions!F28*IS!F4 | G6: =Assumptions!G28*IS!G4 | H6: =Assumptions!H28*IS!H4 | I6: =Assumptions!I28*IS!I4 | J6: =Assumptions!J28*IS!J4
B7: Depreciation | F7: =Assumptions!F29*Calcs!F5 | G7: =Assumptions!G29*Calcs!G5 | H7: =Assumptions!H29*Calcs!H5 | I7: =Assumptions!I29*Calcs!I5 | J7: =Assumptions!J29*Calcs!J5
B8: Ending balance | E8: =BS!E10 | F8: =F5+F6-F7 | G8: =G5+G6-G7 | H8: =H5+H6-H7 | I8: =I5+I6-I7 | J8: =J5+J6-J7
A10: Equity
B11: Beginning balance | F11: =E15 | G11: =F15 | H11: =G15 | I11: =H15 | J11: =I15
B12: Net income | F12: =IS!F21 | G12: =IS!G21 | H12: =IS!H21 | I12: =IS!I21 | J12: =IS!J21
B13: Dividends | F13: =IS!F26 | G13: =IS!G26 | H13: =IS!H26 | I13: =IS!I26 | J13: =IS!J26
B14: Share issuance / (repurchases) | F14: =Assumptions!F31 | G14: =Assumptions!G31 | H14: =Assumptions!H31 | I14: =Assumptions!I31 | J14: =Assumptions!J31
B15: Ending balance | E15: =BS!E31 | F15: =F11+F12-F13+F14 | G15: =G11+G12-G13+G14 | H15: =H11+H12-H13+H14 | I15: =I11+I12-I13+I14 | J15: =J11+J12-J13+J14
A17: OWC
B18: =+BS!B5 | E18: =BS!E5 | F18: =BS!F5 | G18: =BS!G5 | H18: =BS!H5 | I18: =BS!I5 | J18: =BS!J5
B19: =+BS!B6 | E19: =BS!E6 | F19: =BS!F6 | G19: =BS!G6 | H19: =BS!H6 | I19: =BS!I6 | J19: =BS!J6
B20: =+BS!B7 | E20: =BS!E7 | F20: =BS!F7 | G20: =BS!G7 | H20: =BS!H7 | I20: =BS!I7 | J20: =BS!J7
B21: Total operating current assets | E21: =SUM(E18:E20) | F21: =SUM(F18:F20) | G21: =SUM(G18:G20) | H21: =SUM(H18:H20) | I21: =SUM(I18:I20) | J21: =SUM(J18:J20)
B22: =+BS!B20 | E22: =BS!E20 | F22: =BS!F20 | G22: =BS!G20 | H22: =BS!H20 | I22: =BS!I20 | J22: =BS!J20
B23: =+BS!B21 | E23: =BS!E21 | F23: =BS!F21 | G23: =BS!G21 | H23: =BS!H21 | I23: =BS!I21 | J23: =BS!J21
B24: =+BS!B22 | E24: =BS!E22 | F24: =BS!F22 | G24: =BS!G22 | H24: =BS!H22 | I24: =BS!I22 | J24: =BS!J22
B25: =+BS!B23 | E25: =BS!E23 | F25: =BS!F23 | G25: =BS!G23 | H25: =BS!H23 | I25: =BS!I23 | J25: =BS!J23
B26: Total operating current liabilities | E26: =SUM(E22:E25) | F26: =SUM(F22:F25) | G26: =SUM(G22:G25) | H26: =SUM(H22:H25) | I26: =SUM(I22:I25) | J26: =SUM(J22:J25)
B27: OWC | E27: =E21-E26 | F27: =F21-F26 | G27: =G21-G26 | H27: =H21-H26 | I27: =I21-I26 | J27: =J21-J26

Sheet Debt
A1: =CoName | C1: Hist. | D1: Hist. | E1: Hist. | F1: Proj. | G1: Proj. | H1: Proj. | I1: Proj. | J1: Proj.
A2: Debt | C2: =DATE(YEAR(D2)-1,MONTH(D2),DAY(D2)) | D2: =DATE(YEAR(E2)-1,MONTH(E2),DAY(E2)) | E2: =Inputs!C20 | F2: =DATE(YEAR(E2)+1,MONTH(E2),DAY(E2)) | G2: =DATE(YEAR(F2)+1,MONTH(F2),DAY(F2)) | H2: =DATE(YEAR(G2)+1,MONTH(G2),DAY(G2)) | I2: =DATE(YEAR(H2)+1,MONTH(H2),DAY(H2)) | J2: =DATE(YEAR(I2)+1,MONTH(I2),DAY(I2))
A4: =Assumptions!A32
B5: =Assumptions!B33 | F5: =Assumptions!F33 | G5: =Assumptions!G33 | H5: =Assumptions!H33 | I5: =Assumptions!I33 | J5: =Assumptions!J33
B7: Beginning cash | F7: =BS!E4 | G7: =BS!F4 | H7: =BS!G4 | I7: =BS!H4 | J7: =BS!I4
B8: Minimum cash | F8: =-IS!F4*Debt!F5 | G8: =-IS!G4*Debt!G5 | H8: =-IS!H4*Debt!H5 | I8: =-IS!I4*Debt!I5 | J8: =-IS!J4*Debt!J5
B9: Cash flow available for debt repayment | F9: =CFS!F11+CFS!F15+CFS!F17+CFS!F18 | G9: =CFS!G11+CFS!G15+CFS!G17+CFS!G18 | H9: =CFS!H11+CFS!H15+CFS!H17+CFS!H18 | I9: =CFS!I11+CFS!I15+CFS!I17+CFS!I18 | J9: =CFS!J11+CFS!J15+CFS!J17+CFS!J18
B10: Cash available for debt repayment | F10: =SUM(F7:F9) | G10: =SUM(G7:G9) | H10: =SUM(H7:H9) | I10: =SUM(I7:I9) | J10: =SUM(J7:J9)
B12: Short-term debt / revolver
B13: Beginning balance | F13: =E15 | G13: =F15 | H13: =G15 | I13: =H15 | J13: =I15
B14: Issuance / (repayment) | F14: =-MIN(F13,F10) | G14: =-MIN(G13,G10) | H14: =-MIN(H13,H10) | I14: =-MIN(I13,I10) | J14: =-MIN(J13,J10)
B15: Ending balance | E15: 3517 | F15: =SUM(F13:F14) | G15: =SUM(G13:G14) | H15: =SUM(H13:H14) | I15: =SUM(I13:I14) | J15: =SUM(J13:J14)
B16: Interest rate | F16: =Assumptions!F$35 | G16: =Assumptions!G$35 | H16: =Assumptions!H$35 | I16: =Assumptions!I$35 | J16: =Assumptions!J$35
B17: Interest expense | F17: =AVERAGE(E15:F15)*F16 | G17: =AVERAGE(F15:G15)*G16 | H17: =AVERAGE(G15:H15)*H16 | I17: =AVERAGE(H15:I15)*I16 | J17: =AVERAGE(I15:J15)*J16
B19: Cash available after servicing the revolver | F19: =F14+F10 | G19: =G14+G10 | H19: =H14+H10 | I19: =I14+I10 | J19: =J14+J10
B21: U.S. dollar notes
B22: Beginning balance | F22: =E24 | G22: =F24 | H22: =G24 | I22: =H24 | J22: =I24
B23: Accelerated repayment | F23: =-MIN(F22,F19) | G23: =-MIN(G22,G19) | H23: =-MIN(H22,H19) | I23: =-MIN(I22,I19) | J23: =-MIN(J22,J19)
B24: Ending balance | E24: 8327 | F24: =SUM(F22:F23) | G24: =SUM(G22:G23) | H24: =SUM(H22:H23) | I24: =SUM(I22:I23) | J24: =SUM(J22:J23)
B25: Interest rate | F25: =Assumptions!F$36 | G25: =Assumptions!G$36 | H25: =Assumptions!H$36 | I25: =Assumptions!I$36 | J25: =Assumptions!J$36
B26: Interest expense | F26: =AVERAGE(E24:F24)*F25 | G26: =AVERAGE(F24:G24)*G25 | H26: =AVERAGE(G24:H24)*H25 | I26: =AVERAGE(H24:I24)*I25 | J26: =AVERAGE(I24:J24)*J25
B28: Cash available for acceleration of debt 2 | F28: =F23+F19 | G28: =G23+G19 | H28: =H23+H19 | I28: =I23+I19 | J28: =J23+J19
B30: Euro notes
B31: Beginning balance | F31: =E33 | G31: =F33 | H31: =G33 | I31: =H33 | J31: =I33
B32: Accelerated repayment | F32: =-MIN(F31,F28) | G32: =-MIN(G31,G28) | H32: =-MIN(H31,H28) | I32: =-MIN(I31,I28) | J32: =-MIN(J31,J28)
B33: Ending balance | E33: 3653 | F33: =SUM(F31:F32) | G33: =SUM(G31:G32) | H33: =SUM(H31:H32) | I33: =SUM(I31:I32) | J33: =SUM(J31:J32)
B34: Interest rate | F34: =Assumptions!F$37 | G34: =Assumptions!G$37 | H34: =Assumptions!H$37 | I34: =Assumptions!I$37 | J34: =Assumptions!J$37
B35: Interest expense | F35: =AVERAGE(E33:F33)*F34 | G35: =AVERAGE(F33:G33)*G34 | H35: =AVERAGE(G33:H33)*H34 | I35: =AVERAGE(H33:I33)*I34 | J35: =AVERAGE(I33:J33)*J34
B37: Cash available for acceleration of debt 3 | F37: =F28+F32 | G37: =G28+G32 | H37: =H28+H32 | I37: =I28+I32 | J37: =J28+J32
B39: Other debt
B40: Beginning balance | F40: =E42 | G40: =F42 | H40: =G42 | I40: =H42 | J40: =I42
B41: Accelerated repayment | F41: =-MIN(F40,F37) | G41: =-MIN(G40,G37) | H41: =-MIN(H40,H37) | I41: =-MIN(I40,I37) | J41: =-MIN(J40,J37)
B42: Ending balance | E42: =(12972+1163)-SUM(E24,E33) | F42: =SUM(F40:F41) | G42: =SUM(G40:G41) | H42: =SUM(H40:H41) | I42: =SUM(I40:I41) | J42: =SUM(J40:J41)
B43: Interest rate | F43: =Assumptions!F$38 | G43: =Assumptions!G$38 | H43: =Assumptions!H$38 | I43: =Assumptions!I$38 | J43: =Assumptions!J$38
B44: Interest expense | F44: =AVERAGE(E42:F42)*F43 | G44: =AVERAGE(F42:G42)*G43 | H44: =AVERAGE(G42:H42)*H43 | I44: =AVERAGE(H42:I42)*I43 | J44: =AVERAGE(I42:J42)*J43
A46: Long-term debt summary
B47: =+B21 | E47: =+E24 | F47: =+F24 | G47: =+G24 | H47: =+H24 | I47: =+I24 | J47: =+J24
B48: =+B30 | E48: =+E33 | F48: =+F33 | G48: =+G33 | H48: =+H33 | I48: =+I33 | J48: =+J33
B49: =+B39 | E49: =+E42 | F49: =+F42 | G49: =+G42 | H49: =+H42 | I49: =+I42 | J49: =+J42
B50: Total long-term debt | E50: =SUM(E47:E49) | F50: =SUM(F47:F49) | G50: =SUM(G47:G49) | H50: =SUM(H47:H49) | I50: =SUM(I47:I49) | J50: =SUM(J47:J49)
...

Sheet IS
A1: =CoName | C1: Hist. | D1: Hist. | E1: Hist. | F1: Proj. | G1: Proj. | H1: Proj. | I1: Proj. | J1: Proj.
A2: Income Statement | C2: =DATE(YEAR(D2)-1,MONTH(D2),DAY(D2)) | D2: =DATE(YEAR(E2)-1,MONTH(E2),DAY(E2)) | E2: =Inputs!C20 | F2: =DATE(YEAR(E2)+1,MONTH(E2),DAY(E2)) | G2: =DATE(YEAR(F2)+1,MONTH(F2),DAY(F2)) | H2: =DATE(YEAR(G2)+1,MONTH(G2),DAY(G2)) | I2: =DATE(YEAR(H2)+1,MONTH(H2),DAY(H2)) | J2: =DATE(YEAR(I2)+1,MONTH(I2),DAY(I2))
B4: Sales | C4: =Revenues!C42 | D4: =Revenues!D42 | E4: =Revenues!E42 | F4: =Revenues!F42 | G4: =Revenues!G42 | H4: =Revenues!H42 | I4: =Revenues!I42 | J4: =Revenues!J42
B5: COGS | C5: 18124 | D5: 15795 | E5: 15831 | F5: =Assumptions!F5*IS!F4 | G5: =Assumptions!G5*IS!G4 | H5: =Assumptions!H5*IS!H4 | I5: =Assumptions!I5*IS!I4 | J5: =Assumptions!J5*IS!J4
B6: Gross profit | C6: =C4-C5 | D6: =D4-D5 | E6: =E4-E5 | F6: =F4-F5 | G6: =G4-G5 | H6: =H4-H5 | I6: =I4-I5 | J6: =J4-J5
B8: SG&A | C8: =7577+C12-291 | D8: =6540+D12-372 | E8: =5911+E12-257+153+46+4 | F8: =Assumptions!F6*IS!F4 | G8: =Assumptions!G6*IS!G4 | H8: =Assumptions!H6*IS!H4 | I8: =Assumptions!I6*IS!I4 | J8: =Assumptions!J6*IS!J4
B9: EBIT | C9: =C6-C8 | D9: =D6-D8 | E9: =E6-E8 | F9: =F6-F8 | G9: =G6-G8 | H9: =H6-H8 | I9: =I6-I8 | J9: =J6-J8
B11: Depreciation | C11: =713 | D11: 647 | E11: 638 | F11: =Calcs!F7 | G11: =Calcs!G7 | H11: =Calcs!H7 | I11: =Calcs!I7 | J11: =Calcs!J7
B12: Amortization | C12: 181 | D12: 176 | E12: 178 | F12: =Assumptions!F7 | G12: =Assumptions!G7 | H12: =Assumptions!H7 | I12: =Assumptions!I7 | J12: =Assumptions!J7
B13: EBITDA | C13: =C9+SUM(C11:C12) | D13: =D9+SUM(D11:D12) | E13: =E9+SUM(E11:E12) | F13: =F9+SUM(F11:F12) | G13: =G9+SUM(G11:G12) | H13: =H9+SUM(H11:H12) | I13: =I9+SUM(I11:I12) | J13: =J9+SUM(J11:J12)
B15: Interest income | C15: 0 | D15: 0 | E15: 0 | F15: =IF(circ=1,Debt!F62,0) | G15: =IF(circ=1,Debt!G62,0) | H15: =IF(circ=1,Debt!H62,0) | I15: =IF(circ=1,Debt!I62,0) | J15: =IF(circ=1,Debt!J62,0)
B16: Interest expense | C16: 609 | D16: 515 | E16: 396 | F16: =IF(circ=1,Debt!F57,0) | G16: =IF(circ=1,Debt!G57,0) | H16: =IF(circ=1,Debt!H57,0) | I16: =IF(circ=1,Debt!I57,0) | J16: =IF(circ=1,Debt!J57,0)
B17: Non-recurring income / (expense) | C17: =-901+6822-778-291-(1013-C16) | D17: =-852+9-372-(1115-515)+43+301 | E17: =-656+186-257+(153+46+4)+(-11+25)+40+460 | F17: =Assumptions!F8 | G17: =Assumptions!G8 | H17: =Assumptions!H8 | I17: =Assumptions!I8 | J17: =Assumptions!J8
B18: Profit before tax | C18: =C9+C15-C16+C17 | D18: =D9+D15-D16+D17 | E18: =E9+E15-E16+E17 | F18: =F9+F15-F16+F17 | G18: =G9+G15-G16+G17 | H18: =H9+H15-H16+H17 | I18: =I9+I15-I16+I17 | J18: =J9+J15-J16+J17
B20: Tax | C20: 593 | D20: 129 | E20: 688 | F20: =F18*Assumptions!F9 | G20: =G18*Assumptions!G9 | H20: =H18*Assumptions!H9 | I20: =I18*Assumptions!I9 | J20: =J18*Assumptions!J9
B21: Net income | C21: =C18-C20 | D21: =D18-D20 | E21: =E18-E20 | F21: =F18-F20 | G21: =G18-G20 | H21: =H18-H20 | I21: =I18-I20 | J21: =J18-J20
B23: Post-tax non-recurring (income) / expense | C23: =-6600-(C17-6822)*(1-Assumptions!C10) | D23: =-(D17-43-301)*(1-Assumptions!D10)-(43+301) | E23: =-(E17-40-460)*(1-Assumptions!E10)-(40+460) | F23: =-(1-Assumptions!F10)*IS!F17 | G23: =-(1-Assumptions!G10)*IS!G17 | H23: =-(1-Assumptions!H10)*IS!H17 | I23: =-(1-Assumptions!I10)*IS!I17 | J23: =-(1-Assumptions!J10)*IS!J17
B24: Recurring net income | C24: =C21+C23 | D24: =D21+D23 | E24: =E21+E23 | F24: =F21+F23 | G24: =G21+G23 | H24: =H21+H23 | I24: =I21+I23 | J24: =J21+J23
B26: Dividends | C26: 1008 | D26: 1094 | E26: 1198 | F26: =F29*F33 | G26: =G29*G33 | H26: =H29*H33 | I26: =I29*I33 | J26: =J29*J33
A28: Shareholder information
B29: Basic WASO | C29: 1618 | D29: 1556 | E29: 1513 | F29: =Assumptions!F11 | G29: =Assumptions!G11 | H29: =Assumptions!H11 | I29: =Assumptions!I11 | J29: =Assumptions!J11
B30: Diluted WASO | C30: 1637 | D30: 1573 | E30: 1531 | F30: =Assumptions!F12 | G30: =Assumptions!G12 | H30: =Assumptions!H12 | I30: =Assumptions!I12 | J30: =Assumptions!J12
B31: Basic EPS | C31: =+C24/C29 | D31: =+D24/D29 | E31: =+E24/E29 | F31: =+F24/F29 | G31: =+G24/G29 | H31: =+H24/H29 | I31: =+I24/I29 | J31: =+J24/J29
B32: Diluted EPS | C32: =+C24/C30 | D32: =+D24/D30 | E32: =+E24/E30 | F32: =+F24/F30 | G32: =+G24/G30 | H32: =+H24/H30 | I32: =+I24/I30 | J32: =+J24/J30
B33: Dividend per share | C33: =+C26/C29 | D33: =+D26/D29 | E33: =+E26/E29 | F33: =(1+Assumptions!F13)*IS!E33 | G33: =(1+Assumptions!G13)*IS!F33 | H33: =(1+Assumptions!H13)*IS!G33 | I33: =(1+Assumptions!I13)*IS!H33 | J33: =(1+Assumptions!J13)*IS!I33

Sheet BS
A1: =CoName | C1: Hist. | D1: Hist. | E1: Hist. | F1: Proj. | G1: Proj. | H1: Proj. | I1: Proj. | J1: Proj.
A2: Balance Sheet | C2: =DATE(YEAR(D2)-1,MONTH(D2),DAY(D2)) | D2: =DATE(YEAR(E2)-1,MONTH(E2),DAY(E2)) | E2: =Inputs!C20 | F2: =DATE(YEAR(E2)+1,MONTH(E2),DAY(E2)) | G2: =DATE(YEAR(F2)+1,MONTH(F2),DAY(F2)) | H2: =DATE(YEAR(G2)+1,MONTH(G2),DAY(G2)) | I2: =DATE(YEAR(H2)+1,MONTH(H2),DAY(H2)) | J2: =DATE(YEAR(I2)+1,MONTH(I2),DAY(I2))
B4: Cash and cash equivalents | D4: =1741 | E4: 761 | F4: =CFS!F25 | G4: =CFS!G25 | H4: =CFS!H25 | I4: =CFS!I25 | J4: =CFS!J25
B5: Receivables | D5: =2611+859 | E5: =2691+835 | F5: =Assumptions!F15*IS!F4/365 | G5: =Assumptions!G15*IS!G4/365 | H5: =Assumptions!H15*IS!H4/365 | I5: =Assumptions!I15*IS!I4/365 | J5: =Assumptions!J15*IS!J4/365
B6: Inventories, net | D6: 2469 | E6: 2557 | F6: =Assumptions!F16*IS!F5/365 | G6: =Assumptions!G16*IS!G5/365 | H6: =Assumptions!H16*IS!H5/365 | I6: =Assumptions!I16*IS!I5/365 | J6: =Assumptions!J16*IS!J5/365
B7: Other current assets | D7: 800 | E7: 676 | F7: =Assumptions!F17*IS!F4 | G7: =Assumptions!G17*IS!G4 | H7: =Assumptions!H17*IS!H4 | I7: =Assumptions!I17*IS!I4 | J7: =Assumptions!J17*IS!J4
B8: Total current assets | D8: =SUM(D4:D7) | E8: =SUM(E4:E7) | F8: =SUM(F4:F7) | G8: =SUM(G4:G7) | H8: =SUM(H4:H7) | I8: =SUM(I4:I7) | J8: =SUM(J4:J7)
B10: Property, plant and equipment, net | D10: =8229 | E10: 8677 | F10: =Calcs!F8 | G10: =Calcs!G8 | H10: =Calcs!H8 | I10: =Calcs!I8 | J10: =Calcs!J8
B11: Goodwill | D11: =20276 | E11: 21085 | F11: =Assumptions!F18 | G11: =Assumptions!G18 | H11: =Assumptions!H18 | I11: =Assumptions!I18 | J11: =Assumptions!J18
B12: Intangible assets, net | D12: =18101 | E12: 18639 | F12: =-IS!F12+BS!E12 | G12: =-IS!G12+BS!F12 | H12: =-IS!H12+BS!G12 | I12: =-IS!I12+BS!H12 | J12: =-IS!J12+BS!I12
B13: Equity method investments | D13: 5585 | E13: 6345 | F13: =Assumptions!F20 | G13: =Assumptions!G20 | H13: =Assumptions!H20 | I13: =Assumptions!I20 | J13: =Assumptions!J20
B14: Other long-term assets | D14: =350+358+159 | E14: =366+319+158 | F14: =Assumptions!F19*IS!F4 | G14: =Assumptions!G19*IS!G4 | H14: =Assumptions!H19*IS!H4 | I14: =Assumptions!I19*IS!I4 | J14: =Assumptions!J19*IS!J4
B15: Total other non-current assets | D15: =SUM(D10:D14) | E15: =SUM(E10:E14) | F15: =SUM(F10:F14) | G15: =SUM(G10:G14) | H15: =SUM(H10:H14) | I15: =SUM(I10:I14) | J15: =SUM(J10:J14)
B17: TOTAL ASSETS | D17: =D15+D8 | E17: =E15+E8 | F17: =F15+F8 | G17: =G15+G8 | H17: =H15+H8 | I17: =I15+I8 | J17: =J15+J8
B19: Short-term debt / revolver | D19: 2531 | E19: =+Debt!E15 | F19: =+Debt!F15 | G19: =+Debt!G15 | H19: =+Debt!H15 | I19: =+Debt!I15 | J19: =+Debt!J15
B20: Accounts payable | D20: 5318 | E20: 5705 | F20: =Assumptions!F21*IS!F5/365 | G20: =Assumptions!G21*IS!G5/365 | H20: =Assumptions!H21*IS!H5/365 | I20: =Assumptions!I21*IS!I5/365 | J20: =Assumptions!J21*IS!J5/365
B21: Accrued marketing | D21: 1745 | E21: 1728 | F21: =Assumptions!F22*IS!F$4 | G21: =Assumptions!G22*IS!G$4 | H21: =Assumptions!H22*IS!H$4 | I21: =Assumptions!I22*IS!I$4 | J21: =Assumptions!J22*IS!J$4
B22: Accrued employment costs | D22: 736 | E22: 721 | F22: =Assumptions!F23*IS!F$4 | G22: =Assumptions!G23*IS!G$4 | H22: =Assumptions!H23*IS!H$4 | I22: =Assumptions!I23*IS!I$4 | J22: =Assumptions!J23*IS!J$4
B23: Other current liabilities | D23: 2636 | E23: 2959 | F23: =Assumptions!F24*IS!F$4 | G23: =Assumptions!G24*IS!G$4 | H23: =Assumptions!H24*IS!H$4 | I23: =Assumptions!I24*IS!I$4 | J23: =Assumptions!J24*IS!J$4
B24: Total current liabilities | D24: =SUM(D19:D23) | E24: =SUM(E19:E23) | F24: =SUM(F19:F23) | G24: =SUM(G19:G23) | H24: =SUM(H19:H23) | I24: =SUM(I19:I23) | J24: =SUM(J19:J23)
B26: Long-term debt | D26: 14668 | E26: =Debt!E50 | F26: =Debt!F50 | G26: =Debt!G50 | H26: =Debt!H50 | I26: =Debt!I50 | J26: =Debt!J50
B27: Deferred income taxes | D27: 4721 | E27: 3376 | F27: =Assumptions!F25*IS!F$4 | G27: =Assumptions!G25*IS!G$4 | H27: =Assumptions!H25*IS!H$4 | I27: =Assumptions!I25*IS!I$4 | J27: =Assumptions!J25*IS!J$4
B28: Other long-term liabilities | D28: 3968 | E28: =1669+419+2689 | F28: =Assumptions!F26*IS!F$4 | G28: =Assumptions!G26*IS!G$4 | H28: =Assumptions!H26*IS!H$4 | I28: =Assumptions!I26*IS!I$4 | J28: =Assumptions!J26*IS!J$4
B29: Total non-current liabilities | D29: =SUM(D26:D28) | E29: =SUM(E26:E28) | F29: =SUM(F26:F28) | G29: =SUM(G26:G28) | H29: =SUM(H26:H28) | I29: =SUM(I26:I28) | J29: =SUM(J26:J28)
B31: Equity | D31: 25215 | E31: 26191 | F31: =Calcs!F15 | G31: =Calcs!G15 | H31: =Calcs!H15 | I31: =Calcs!I15 | J31: =Calcs!J15
B32: TOTAL LIABILITIES & EQUITY | D32: =D24+D29+D31 | E32: =E24+E29+E31 | F32: =F24+F29+F31 | G32: =G24+G29+G31 | H32: =H24+H29+H31 | I32: =I24+I29+I31 | J32: =J24+J29+J31
B34: Balance check | D34: =IF(D32=D17,"OK",D32-D17) | E34: =IF(E32=E17,"OK",E32-E17) | F34: =IF(F32=F17,"OK",F32-F17) | G34: =IF(G32=G17,"OK",G32-G17) | H34: =IF(H32=H17,"OK",H32-H17) | I34: =IF(I32=I17,"OK",I32-I17) | J34: =IF(J32=J17,"OK",J32-J17)

Sheet CFS
A1: =CoName | C1: Hist. | D1: Hist. | E1: Hist. | F1: Proj. | G1: Proj. | H1: Proj. | I1: Proj. | J1: Proj.
A2: Cash Flow Statement | C2: =DATE(YEAR(D2)-1,MONTH(D2),DAY(D2)) | D2: =DATE(YEAR(E2)-1,MONTH(E2),DAY(E2)) | E2: =Inputs!C20 | F2: =DATE(YEAR(E2)+1,MONTH(E2),DAY(E2)) | G2: =DATE(YEAR(F2)+1,MONTH(F2),DAY(F2)) | H2: =DATE(YEAR(G2)+1,MONTH(G2),DAY(G2)) | I2: =DATE(YEAR(H2)+1,MONTH(H2),DAY(H2)) | J2: =DATE(YEAR(I2)+1,MONTH(I2),DAY(I2))
B4: Net income | F4: =IS!F21 | G4: =IS!G21 | H4: =IS!H21 | I4: =IS!I21 | J4: =IS!J21
B5: Depreciation | F5: =IS!F11 | G5: =IS!G11 | H5: =IS!H11 | I5: =IS!I11 | J5: =IS!J11
B6: Amortization | F6: =IS!F12 | G6: =IS!G12 | H6: =IS!H12 | I6: =IS!I12 | J6: =IS!J12
B7: (inc) dec in OWC | F7: =Calcs!E27-Calcs!F27 | G7: =Calcs!F27-Calcs!G27 | H7: =Calcs!G27-Calcs!H27 | I7: =Calcs!H27-Calcs!I27 | J7: =Calcs!I27-Calcs!J27
B8: (inc) dec in other long-term assets | F8: =BS!E14-BS!F14 | G8: =BS!F14-BS!G14 | H8: =BS!G14-BS!H14 | I8: =BS!H14-BS!I14 | J8: =BS!I14-BS!J14
B9: inc (dec) in deferred income tax liability | F9: =BS!F27-BS!E27 | G9: =BS!G27-BS!F27 | H9: =BS!H27-BS!G27 | I9: =BS!I27-BS!H27 | J9: =BS!J27-BS!I27
B10: inc (dec) in other liabilities | F10: =BS!F28-BS!E28 | G10: =BS!G28-BS!F28 | H10: =BS!H28-BS!G28 | I10: =BS!I28-BS!H28 | J10: =BS!J28-BS!I28
B11: Operating cash flow | F11: =SUM(F4:F10) | G11: =SUM(G4:G10) | H11: =SUM(H4:H10) | I11: =SUM(I4:I10) | J11: =SUM(J4:J10)
B13: Capital expenditure | F13: =-Calcs!F6 | G13: =-Calcs!G6 | H13: =-Calcs!H6 | I13: =-Calcs!I6 | J13: =-Calcs!J6
B14: (inc) dec in equity method investments | F14: =BS!E13-BS!F13 | G14: =BS!F13-BS!G13 | H14: =BS!G13-BS!H13 | I14: =BS!H13-BS!I13 | J14: =BS!I13-BS!J13
B15: Investing cash flow | F15: =SUM(F13:F14) | G15: =SUM(G13:G14) | H15: =SUM(H13:H14) | I15: =SUM(I13:I14) | J15: =SUM(J13:J14)
B17: Dividends | F17: =-Calcs!F13 | G17: =-Calcs!G13 | H17: =-Calcs!H13 | I17: =-Calcs!I13 | J17: =-Calcs!J13
B18: Share issuance / (repurchases) | F18: =Calcs!F14 | G18: =Calcs!G14 | H18: =Calcs!H14 | I18: =Calcs!I14 | J18: =Calcs!J14
B19: Issuance / (repayment) of short-term debt / revolver | F19: =BS!F19-BS!E19 | G19: =BS!G19-BS!F19 | H19: =BS!H19-BS!G19 | I19: =BS!I19-BS!H19 | J19: =BS!J19-BS!I19
B20: Issuance / (repayment) of long-term debt | F20: =BS!F26-BS!E26 | G20: =BS!G26-BS!F26 | H20: =BS!H26-BS!G26 | I20: =BS!I26-BS!H26 | J20: =BS!J26-BS!I26
B21: Financing cash flow | F21: =SUM(F17:F20) | G21: =SUM(G17:G20) | H21: =SUM(H17:H20) | I21: =SUM(I17:I20) | J21: =SUM(J17:J20)
B23: NET CASH FLOW | F23: =F21+F15+F11 | G23: =G21+G15+G11 | H23: =H21+H15+H11 | I23: =I21+I15+I11 | J23: =J21+J15+J11
B25: Cash balance | E25: =BS!E4 | F25: =E25+F23 | G25: =F25+G23 | H25: =G25+H23 | I25: =H25+I23 | J25: =I25+J23

Sheet Ratios
A1: =CoName | C1: Hist. | D1: Hist. | E1: Hist. | F1: Proj. | G1: Proj. | H1: Proj. | I1: Proj. | J1: Proj.
A2: Ratios | C2: =DATE(YEAR(D2)-1,MONTH(D2),DAY(D2)) | D2: =DATE(YEAR(E2)-1,MONTH(E2),DAY(E2)) | E2: =Inputs!C20 | F2: =DATE(YEAR(E2)+1,MONTH(E2),DAY(E2)) | G2: =DATE(YEAR(F2)+1,MONTH(F2),DAY(F2)) | H2: =DATE(YEAR(G2)+1,MONTH(G2),DAY(G2)) | I2: =DATE(YEAR(H2)+1,MONTH(H2),DAY(H2)) | J2: =DATE(YEAR(I2)+1,MONTH(I2),DAY(I2))
A4: Growth
B5: Sales | D5: =IS!D4/IS!C4-1 | E5: =IS!E4/IS!D4-1 | F5: =IS!F4/IS!E4-1 | G5: =IS!G4/IS!F4-1 | H5: =IS!H4/IS!G4-1 | I5: =IS!I4/IS!H4-1 | J5: =IS!J4/IS!I4-1
B6: EBITDA | D6: =IS!D13/IS!C13-1 | E6: =IS!E13/IS!D13-1 | F6: =IS!F13/IS!E13-1 | G6: =IS!G13/IS!F13-1 | H6: =IS!H13/IS!G13-1 | I6: =IS!I13/IS!H13-1 | J6: =IS!J13/IS!I13-1
B7: CFO | G7: =CFS!G11/CFS!F11-1 | H7: =CFS!H11/CFS!G11-1 | I7: =CFS!I11/CFS!H11-1 | J7: =CFS!J11/CFS!I11-1
B8: Net income | D8: =IS!D24/IS!C24-1 | E8: =IS!E24/IS!D24-1 | F8: =IS!F24/IS!E24-1 | G8: =IS!G24/IS!F24-1 | H8: =IS!H24/IS!G24-1 | I8: =IS!I24/IS!H24-1 | J8: =IS!J24/IS!I24-1
A10: Profitability
B11: EBIT margin | C11: =IS!C9/IS!C4 | D11: =IS!D9/IS!D4 | E11: =IS!E9/IS!E4 | F11: =IS!F9/IS!F4 | G11: =IS!G9/IS!G4 | H11: =IS!H9/IS!H4 | I11: =IS!I9/IS!I4 | J11: =IS!J9/IS!J4
B12: EBITDA margin | C12: =IS!C13/IS!C4 | D12: =IS!D13/IS!D4 | E12: =IS!E13/IS!E4 | F12: =IS!F13/IS!F4 | G12: =IS!G13/IS!G4 | H12: =IS!H13/IS!H4 | I12: =IS!I13/IS!I4 | J12: =IS!J13/IS!J4
B13: Net income margin | C13: =IS!C24/IS!C4 | D13: =IS!D24/IS!D4 | E13: =IS!E24/IS!E4 | F13: =IS!F24/IS!F4 | G13: =IS!G24/IS!G4 | H13: =IS!H24/IS!H4 | I13: =IS!I24/IS!I4 | J13: =IS!J24/IS!J4
A15: Credit
B16: Total debt | D16: =BS!D26+BS!D19 | E16: =BS!E26+BS!E19 | F16: =BS!F26+BS!F19 | G16: =BS!G26+BS!G19 | H16: =BS!H26+BS!H19 | I16: =BS!I26+BS!I19 | J16: =BS!J26+BS!J19
B17: Net debt | D17: =BS!D26+BS!D19-BS!D4 | E17: =BS!E26+BS!E19-BS!E4 | F17: =BS!F26+BS!F19-BS!F4 | G17: =BS!G26+BS!G19-BS!G4 | H17: =BS!H26+BS!H19-BS!H4 | I17: =BS!I26+BS!I19-BS!I4 | J17: =BS!J26+BS!J19-BS!J4
B18: Equity | D18: =BS!D31 | E18: =BS!E31 | F18: =BS!F31 | G18: =BS!G31 | H18: =BS!H31 | I18: =BS!I31 | J18: =BS!J31
B19: Net debt / equity | D19: =D17/D18 | E19: =E17/E18 | F19: =F17/F18 | G19: =G17/G18 | H19: =H17/H18 | I19: =I17/I18 | J19: =J17/J18
B20: Net debt / EBITDA | D20: =D17/IS!D13 | E20: =E17/IS!E13 | F20: =F17/IS!F13 | G20: =G17/IS!G13 | H20: =H17/IS!H13 | I20: =I17/IS!I13 | J20: =J17/IS!J13
B21: EBITDA / interest expense | C21: =IS!C13/IS!C16 | D21: =IS!D13/IS!D16 | E21: =IS!E13/IS!E16 | F21: =IS!F13/IS!F16 | G21: =IS!G13/IS!G16 | H21: =IS!H13/IS!H16 | I21: =IS!I13/IS!I16 | J21: =IS!J13/IS!J16
B22: Dividend payout ratio | C22: =IS!C26/IS!C24 | D22: =IS!D26/IS!D24 | E22: =IS!E26/IS!E24 | F22: =IS!F26/IS!F24 | G22: =IS!G26/IS!G24 | H22: =IS!H26/IS!H24 | I22: =IS!I26/IS!I24 | J22: =IS!J26/IS!J24
A24: Asset turnover
B25: OWC to sales | D25: =Calcs!D27/IS!D4 | E25: =Calcs!E27/IS!E4 | F25: =Calcs!F27/IS!F4 | G25: =Calcs!G27/IS!G4 | H25: =Calcs!H27/IS!H4 | I25: =Calcs!I27/IS!I4 | J25: =Calcs!J27/IS!J4
B26: Net PPE to sales | D26: =BS!D10/IS!D4 | E26: =BS!E10/IS!E4 | F26: =BS!F10/IS!F4 | G26: =BS!G10/IS!G4 | H26: =BS!H10/IS!H4 | I26: =BS!I10/IS!I4 | J26: =BS!J10/IS!J4
B27: Invested capital | D27: =SUM(D17:D18) | E27: =SUM(E17:E18) | F27: =SUM(F17:F18) | G27: =SUM(G17:G18) | H27: =SUM(H17:H18) | I27: =SUM(I17:I18) | J27: =SUM(J17:J18)
B28: Invested capital to sales | D28: =D27/IS!D4 | E28: =E27/IS!E4 | F28: =F27/IS!F4 | G28: =G27/IS!G4 | H28: =H27/IS!H4 | I28: =I27/IS!I4 | J28: =J27/IS!J4
A30: Returns
B31: Net operating profit after tax (NOPAT) | D31: =IS!D9*(1-Assumptions!D9) | E31: =IS!E9*(1-Assumptions!E9) | F31: =IS!F9*(1-Assumptions!F9) | G31: =IS!G9*(1-Assumptions!G9) | H31: =IS!H9*(1-Assumptions!H9) | I31: =IS!I9*(1-Assumptions!I9) | J31: =IS!J9*(1-Assumptions!J9)
B32: Return on invested capital | E32: =E31/D27 | F32: =F31/E27 | G32: =G31/F27 | H32: =H31/G27 | I32: =I31/H27 | J32: =J31/I27
B33: Return on equity | E33: =IS!E24/Ratios!D18 | F33: =IS!F24/Ratios!E18 | G33: =IS!G24/Ratios!F18 | H33: =IS!H24/Ratios!G18 | I33: =IS!I24/Ratios!H18 | J33: =IS!J24/Ratios!I18
