Workbook

Sheet Company1153 Assumptions
B2: COMPANY1153 (Company0080) - OPERATING MODEL ASSUMPTIONS
B3: 3-Year Historical (2021-2023) | 5-Year Projections (2024-2028)
B5: SCENARIO SELECTION
B6: Selected Scenario: | D6: Base
B8: Historical | G8: Projections
D9: 2021 | E9: 2022 | F9: 2023 | G9: 2024 | H9: 2025 | I9: 2026 | J9: 2027 | K9: 2028
B11: 1. REVENUE ASSUMPTIONS
B13: Revenue Growth Rates (%)
C14: Scenario | D14: 2021 | E14: 2022 | F14: 2023 | G14: 2024 | H14: 2025 | I14: 2026 | J14: 2027 | K14: 2028
B15: Company1153 Search | C15: Base | G15: 0.085 | H15: 0.075 | I15: 0.065 | J15: 0.055 | K15: 0.05
C16: Bull | G16: 0.105 | H16: 0.095 | I16: 0.085 | J16: 0.075 | K16: 0.07
C17: Bear | G17: 0.06 | H17: 0.05 | I17: 0.04 | J17: 0.035 | K17: 0.03
B19: Product0476 Ads | C19: Base | G19: 0.15 | H19: 0.13 | I19: 0.11 | J19: 0.1 | K19: 0.09
C20: Bull | G20: 0.18 | H20: 0.16 | I20: 0.14 | J20: 0.12 | K20: 0.11
C21: Bear | G21: 0.12 | H21: 0.1 | I21: 0.08 | J21: 0.07 | K21: 0.06
B23: Company1153 Cloud | C23: Base | G23: 0.28 | H23: 0.25 | I23: 0.22 | J23: 0.2 | K23: 0.18
C24: Bull | G24: 0.32 | H24: 0.3 | I24: 0.27 | J24: 0.24 | K24: 0.22
C25: Bear | G25: 0.24 | H25: 0.2 | I25: 0.17 | J25: 0.15 | K25: 0.14
B27: Other Revenues | C27: Base | G27: 0.05 | H27: 0.045 | I27: 0.04 | J27: 0.035 | K27: 0.03
C28: Bull | G28: 0.07 | H28: 0.06 | I28: 0.055 | J28: 0.05 | K28: 0.045
C29: Bear | G29: 0.03 | H29: 0.025 | I29: 0.02 | J29: 0.015 | K29: 0.01
B31: 2. OPERATING EXPENSE ASSUMPTIONS
B33: Operating Expenses (% of Revenue)
B35: Research & Development | C35: Base | D35: 0.151 | E35: 0.148 | F35: 0.145 | G35: 0.143 | H35: 0.14 | I35: 0.138 | J35: 0.135 | K35: 0.133
C36: Bull | D36: 0.151 | E36: 0.148 | F36: 0.145 | G36: 0.138 | H36: 0.135 | I36: 0.132 | J36: 0.13 | K36: 0.128
C37: Bear | D37: 0.151 | E37: 0.148 | F37: 0.145 | G37: 0.148 | H37: 0.145 | I37: 0.143 | J37: 0.14 | K37: 0.138
B39: Sales & Marketing | C39: Base | D39: 0.115 | E39: 0.112 | F39: 0.108 | G39: 0.105 | H39: 0.103 | I39: 0.1 | J39: 0.098 | K39: 0.095
C40: Bull | D40: 0.115 | E40: 0.112 | F40: 0.108 | G40: 0.102 | H40: 0.1 | I40: 0.097 | J40: 0.095 | K40: 0.092
C41: Bear | D41: 0.115 | E41: 0.112 | F41: 0.108 | G41: 0.108 | H41: 0.106 | I41: 0.103 | J41: 0.101 | K41: 0.098
B43: General & Administrative | C43: Base | D43: 0.068 | E43: 0.065 | F43: 0.063 | G43: 0.062 | H43: 0.06 | I43: 0.058 | J43: 0.057 | K43: 0.055
C44: Bull | D44: 0.068 | E44: 0.065 | F44: 0.063 | G44: 0.06 | H44: 0.058 | I44: 0.056 | J44: 0.055 | K44: 0.053
C45: Bear | D45: 0.068 | E45: 0.065 | F45: 0.063 | G45: 0.064 | H45: 0.062 | I45: 0.06 | J45: 0.059 | K45: 0.057
B47: Stock-Based Compensation | C47: Base | D47: 0.092 | E47: 0.095 | F47: 0.098 | G47: 0.095 | H47: 0.093 | I47: 0.09 | J47: 0.088 | K47: 0.085
C48: Bull | D48: 0.092 | E48: 0.095 | F48: 0.098 | G48: 0.092 | H48: 0.09 | I48: 0.087 | J48: 0.085 | K48: 0.082
C49: Bear | D49: 0.092 | E49: 0.095 | F49: 0.098 | G49: 0.098 | H49: 0.096 | I49: 0.093 | J49: 0.091 | K49: 0.088
B51: 3. BALANCE SHEET & CASH FLOW ASSUMPTIONS
B53: Working Capital Metrics
B55: Days Sales Outstanding (DSO) | C55: Base | D55: 48 | E55: 47 | F55: 46 | G55: 46 | H55: 45 | I55: 45 | J55: 44 | K55: 44
C56: Bull | D56: 48 | E56: 47 | F56: 46 | G56: 45 | H56: 44 | I56: 43 | J56: 42 | K56: 42
C57: Bear | D57: 48 | E57: 47 | F57: 46 | G57: 47 | H57: 47 | I57: 46 | J57: 46 | K57: 45
...

Sheet Company1808 Assumptions
B2: COMPANY1809 - OPERATING MODEL ASSUMPTIONS
B3: 3-Year Historical (2021-2023) | 5-Year Projections (2024-2028)
B5: SCENARIO SELECTION
B6: Selected Scenario: | D6: ='Company1153 Assumptions'!$D$6
B8: Historical | G8: Projections
D9: 2021 | E9: 2022 | F9: 2023 | G9: 2024 | H9: 2025 | I9: 2026 | J9: 2027 | K9: 2028
B11: 1. REVENUE ASSUMPTIONS
B13: Revenue Growth Rates (%)
C14: Scenario | D14: 2021 | E14: 2022 | F14: 2023 | G14: 2024 | H14: 2025 | I14: 2026 | J14: 2027 | K14: 2028
B15: Family of Apps (FoA) | C15: Base | G15: 0.12 | H15: 0.1 | I15: 0.085 | J15: 0.075 | K15: 0.07
C16: Bull | G16: 0.14 | H16: 0.12 | I16: 0.105 | J16: 0.095 | K16: 0.09
C17: Bear | G17: 0.1 | H17: 0.08 | I17: 0.065 | J17: 0.055 | K17: 0.05
B19: Product0338 | C19: Base | G19: 0.014 | H19: =G$19+(($K$19-$G$19)/COUNT($H$14:$K$14)) | I19: =H$19+(($K$19-$G$19)/COUNT($H$14:$K$14)) | J19: =I$19+(($K$19-$G$19)/COUNT($H$14:$K$14)) | K19: 0.05
B20: % of total revenue | C20: Bull | G20: =G19+$M$20 | H20: =H19+$M$20 | I20: =I19+$M$20 | J20: =J19+$M$20 | K20: =K19+$M$20 | M20: 0.005
C21: Bear | G21: =G19-$M$21 | H21: =H19-$M$21 | I21: =I19-$M$21 | J21: =J19-$M$21 | K21: =K19-$M$21 | M21: 0.005
B24: User Growth Metrics
B26: DAU Growth (%) | C26: Base | G26: 0.03 | H26: 0.025 | I26: 0.02 | J26: 0.015 | K26: 0.01
C27: Bull | G27: 0.04 | H27: 0.035 | I27: 0.03 | J27: 0.025 | K27: 0.02
C28: Bear | G28: 0.02 | H28: 0.015 | I28: 0.01 | J28: 0.005 | K28: 0
B30: ARPU Growth (%) | C30: Base | G30: 0.085 | H30: 0.07 | I30: 0.06 | J30: 0.055 | K30: 0.05
C31: Bull | G31: 0.1 | H31: 0.085 | I31: 0.075 | J31: 0.07 | K31: 0.065
C32: Bear | G32: 0.07 | H32: 0.055 | I32: 0.045 | J32: 0.04 | K32: 0.035
B34: 2. OPERATING EXPENSE ASSUMPTIONS
B36: Operating Expenses (% of Revenue)
B38: Research & Development | C38: Base | D38: 0.255 | E38: 0.27 | F38: 0.29 | G38: 0.285 | H38: 0.28 | I38: 0.275 | J38: 0.27 | K38: 0.265
C39: Bull | D39: 0.255 | E39: 0.27 | F39: 0.29 | G39: 0.28 | H39: 0.275 | I39: 0.27 | J39: 0.265 | K39: 0.26
C40: Bear | D40: 0.255 | E40: 0.27 | F40: 0.29 | G40: 0.29 | H40: 0.285 | I40: 0.28 | J40: 0.275 | K40: 0.27
B42: Sales & Marketing | C42: Base | D42: 0.118 | E42: 0.125 | F42: 0.13 | G42: 0.125 | H42: 0.12 | I42: 0.115 | J42: 0.11 | K42: 0.105
C43: Bull | D43: 0.118 | E43: 0.125 | F43: 0.13 | G43: 0.12 | H43: 0.115 | I43: 0.11 | J43: 0.105 | K43: 0.1
C44: Bear | D44: 0.118 | E44: 0.125 | F44: 0.13 | G44: 0.13 | H44: 0.125 | I44: 0.12 | J44: 0.115 | K44: 0.11
B46: General & Administrative | C46: Base | D46: 0.102 | E46: 0.108 | F46: 0.115 | G46: 0.11 | H46: 0.105 | I46: 0.1 | J46: 0.095 | K46: 0.09
C47: Bull | D47: 0.102 | E47: 0.108 | F47: 0.115 | G47: 0.105 | H47: 0.1 | I47: 0.095 | J47: 0.09 | K47: 0.085
C48: Bear | D48: 0.102 | E48: 0.108 | F48: 0.115 | G48: 0.115 | H48: 0.11 | I48: 0.105 | J48: 0.1 | K48: 0.095
B50: Stock-Based Compensation | C50: Base | D50: 0.085 | E50: 0.102 | F50: 0.118 | G50: 0.11 | H50: 0.105 | I50: 0.1 | J50: 0.095 | K50: 0.09
C51: Bull | D51: 0.085 | E51: 0.102 | F51: 0.118 | G51: 0.105 | H51: 0.1 | I51: 0.095 | J51: 0.09 | K51: 0.085
C52: Bear | D52: 0.085 | E52: 0.102 | F52: 0.118 | G52: 0.115 | H52: 0.11 | I52: 0.105 | J52: 0.1 | K52: 0.095
B54: Product0338 Operating Margin
B56: Operating Margin (%) | C56: Base | D56: -3.5 | E56: -3 | F56: -2.5 | G56: -2 | H56: -1.5 | I56: -1 | J56: -0.75 | K56: -0.5
C57: Bull | D57: -3.5 | E57: -3 | F57: -2.5 | G57: -1.75 | H57: -1.25 | I57: -0.75 | J57: -0.5 | K57: -0.25
C58: Bear | D58: -3.5 | E58: -3 | F58: -2.5 | G58: -2.25 | H58: -1.75 | I58: -1.25 | J58: -1 | K58: -0.75
...

Sheet Company1153 3-Statement
B2: COMPANY1153 (Company0080) - INCOME STATEMENT
B3: $ in millions
B5: Selected Scenario: | D5: ='Company1153 Assumptions'!$D$6
B7: Historical | F7: Projections
C8: 2021 | D8: 2022 | E8: 2023 | F8: 2024 | G8: 2025 | H8: 2026 | I8: 2027 | J8: 2028
B10: INCOME STATEMENT
B12: Company1153 Search | C12: 148951 | D12: 162450 | E12: 175033 | F12: =E12*(1+INDEX('Company1153 Assumptions'!G$15:G$17,MATCH($D$5,'Company1153 Assumptions'!$C$15:$C$17,0))) | G12: =F12*(1+INDEX('Company1153 Assumptions'!H$15:H$17,MATCH($D$5,'Company1153 Assumptions'!$C$15:$C$17,0))) | H12: =G12*(1+INDEX('Company1153 Assumptions'!I$15:I$17,MATCH($D$5,'Company1153 Assumptions'!$C$15:$C$17,0))) | I12: =H12*(1+INDEX('Company1153 Assumptions'!J$15:J$17,MATCH($D$5,'Company1153 Assumptions'!$C$15:$C$17,0))) | J12: =I12*(1+INDEX('Company1153 Assumptions'!K$15:K$17,MATCH($D$5,'Company1153 Assumptions'!$C$15:$C$17,0)))
B13: Product0476 Ads | C13: 28845 | D13: 29243 | E13: 31865 | F13: =E13*(1+INDEX('Company1153 Assumptions'!G$19:G$21,MATCH($D$5,'Company1153 Assumptions'!$C$19:$C$21,0))) | G13: =F13*(1+INDEX('Company1153 Assumptions'!H$19:H$21,MATCH($D$5,'Company1153 Assumptions'!$C$19:$C$21,0))) | H13: =G13*(1+INDEX('Company1153 Assumptions'!I$19:I$21,MATCH($D$5,'Company1153 Assumptions'!$C$19:$C$21,0))) | I13: =H13*(1+INDEX('Company1153 Assumptions'!J$19:J$21,MATCH($D$5,'Company1153 Assumptions'!$C$19:$C$21,0))) | J13: =I13*(1+INDEX('Company1153 Assumptions'!K$19:K$21,MATCH($D$5,'Company1153 Assumptions'!$C$19:$C$21,0)))
B14: Company1153 Cloud | C14: 13059 | D14: 19206 | E14: 26280 | F14: =E14*(1+INDEX('Company1153 Assumptions'!G$23:G$25,MATCH($D$5,'Company1153 Assumptions'!$C$23:$C$25,0))) | G14: =F14*(1+INDEX('Company1153 Assumptions'!H$23:H$25,MATCH($D$5,'Company1153 Assumptions'!$C$23:$C$25,0))) | H14: =G14*(1+INDEX('Company1153 Assumptions'!I$23:I$25,MATCH($D$5,'Company1153 Assumptions'!$C$23:$C$25,0))) | I14: =H14*(1+INDEX('Company1153 Assumptions'!J$23:J$25,MATCH($D$5,'Company1153 Assumptions'!$C$23:$C$25,0))) | J14: =I14*(1+INDEX('Company1153 Assumptions'!K$23:K$25,MATCH($D$5,'Company1153 Assumptions'!$C$23:$C$25,0)))
B15: Other Revenues | C15: 28032 | D15: 29071 | E15: 30300 | F15: =E15*(1+INDEX('Company1153 Assumptions'!G$27:G$29,MATCH($D$5,'Company1153 Assumptions'!$C$27:$C$29,0))) | G15: =F15*(1+INDEX('Company1153 Assumptions'!H$27:H$29,MATCH($D$5,'Company1153 Assumptions'!$C$27:$C$29,0))) | H15: =G15*(1+INDEX('Company1153 Assumptions'!I$27:I$29,MATCH($D$5,'Company1153 Assumptions'!$C$27:$C$29,0))) | I15: =H15*(1+INDEX('Company1153 Assumptions'!J$27:J$29,MATCH($D$5,'Company1153 Assumptions'!$C$27:$C$29,0))) | J15: =I15*(1+INDEX('Company1153 Assumptions'!K$27:K$29,MATCH($D$5,'Company1153 Assumptions'!$C$27:$C$29,0)))
B16: Total Revenue | C16: =SUM(C12:C15) | D16: =SUM(D12:D15) | E16: =SUM(E12:E15) | F16: =SUM(F12:F15) | G16: =SUM(G12:G15) | H16: =SUM(H12:H15) | I16: =SUM(I12:I15) | J16: =SUM(J12:J15)
B17: YoY Growth % | D17: =D16/C16-1 | E17: =E16/D16-1 | F17: =F16/E16-1 | G17: =G16/F16-1 | H17: =H16/G16-1 | I17: =I16/H16-1 | J17: =J16/I16-1
B19: Quarterly Seasonality
B20: Seasonality Factors (% of Annual)
B21: Q1 Factor | F21: 0.22
B22: Q2 Factor | F22: =F21+(($F$24-$F$21)/3)
B23: Q3 Factor | F23: =F22+(($F$24-$F$21)/3)
B24: Q4 Factor | F24: 0.28
B25: 2024 Quarterly Revenue ($mm)
B26: Q1 2024 | F26: =$F$16*F21
B27: Q2 2024 | F27: =$F$16*F22
B28: Q3 2024 | F28: =$F$16*F23
B29: Q4 2024 | F29: =$F$16*F24
B30: Total Check | F30: =SUM(F26:F29)
B32: Cost of Revenue | C32: =C16*(1-C34) | D32: =D16*(1-D34) | E32: =E16*(1-E34) | F32: =F16*(1-F34) | G32: =G16*(1-G34) | H32: =H16*(1-H34) | I32: =I16*(1-I34) | J32: =J16*(1-J34)
B33: Gross Profit | C33: =C16-C32 | D33: =D16-D32 | E33: =E16-E32 | F33: =F16-F32 | G33: =G16-G32 | H33: =H16-H32 | I33: =I16-I32 | J33: =J16-J32
B34: Gross Margin % | C34: 0.545 | D34: 0.548 | E34: 0.55 | F34: 0.552 | G34: 0.554 | H34: 0.556 | I34: 0.558 | J34: 0.56
B36: Research & Development | C36: =C16*INDEX('Company1153 Assumptions'!D$35:D$37,MATCH($D$5,'Company1153 Assumptions'!$C$35:$C$37,0)) | D36: =D16*INDEX('Company1153 Assumptions'!E$35:E$37,MATCH($D$5,'Company1153 Assumptions'!$C$35:$C$37,0)) | E36: =E16*INDEX('Company1153 Assumptions'!F$35:F$37,MATCH($D$5,'Company1153 Assumptions'!$C$35:$C$37,0)) | F36: =F16*INDEX('Company1153 Assumptions'!G$35:G$37,MATCH($D$5,'Company1153 Assumptions'!$C$35:$C$37,0)) | G36: =G16*INDEX('Company1153 Assumptions'!H$35:H$37,MATCH($D$5,'Company1153 Assumptions'!$C$35:$C$37,0)) | H36: =H16*INDEX('Company1153 Assumptions'!I$35:I$37,MATCH($D$5,'Company1153 Assumptions'!$C$35:$C$37,0)) | I36: =I16*INDEX('Company1153 Assumptions'!J$35:J$37,MATCH($D$5,'Company1153 Assumptions'!$C$35:$C$37,0)) | J36: =J16*INDEX('Company1153 Assumptions'!K$35:K$37,MATCH($D$5,'Company1153 Assumptions'!$C$35:$C$37,0))
B37: Sales & Marketing | C37: =C16*INDEX('Company1153 Assumptions'!D$39:D$41,MATCH($D$5,'Company1153 Assumptions'!$C$39:$C$41,0)) | D37: =D16*INDEX('Company1153 Assumptions'!E$39:E$41,MATCH($D$5,'Company1153 Assumptions'!$C$39:$C$41,0)) | E37: =E16*INDEX('Company1153 Assumptions'!F$39:F$41,MATCH($D$5,'Company1153 Assumptions'!$C$39:$C$41,0)) | F37: =F16*INDEX('Company1153 Assumptions'!G$39:G$41,MATCH($D$5,'Company1153 Assumptions'!$C$39:$C$41,0)) | G37: =G16*INDEX('Company1153 Assumptions'!H$39:H$41,MATCH($D$5,'Company1153 Assumptions'!$C$39:$C$41,0)) | H37: =H16*INDEX('Company1153 Assumptions'!I$39:I$41,MATCH($D$5,'Company1153 Assumptions'!$C$39:$C$41,0)) | I37: =I16*INDEX('Company1153 Assumptions'!J$39:J$41,MATCH($D$5,'Company1153 Assumptions'!$C$39:$C$41,0)) | J37: =J16*INDEX('Company1153 Assumptions'!K$39:K$41,MATCH($D$5,'Company1153 Assumptions'!$C$39:$C$41,0))
B38: General & Administrative | C38: =C16*INDEX('Company1153 Assumptions'!D$43:D$45,MATCH($D$5,'Company1153 Assumptions'!$C$43:$C$45,0)) | D38: =D16*INDEX('Company1153 Assumptions'!E$43:E$45,MATCH($D$5,'Company1153 Assumptions'!$C$43:$C$45,0)) | E38: =E16*INDEX('Company1153 Assumptions'!F$43:F$45,MATCH($D$5,'Company1153 Assumptions'!$C$43:$C$45,0)) | F38: =F16*INDEX('Company1153 Assumptions'!G$43:G$45,MATCH($D$5,'Company1153 Assumptions'!$C$43:$C$45,0)) | G38: =G16*INDEX('Company1153 Assumptions'!H$43:H$45,MATCH($D$5,'Company1153 Assumptions'!$C$43:$C$45,0)) | H38: =H16*INDEX('Company1153 Assumptions'!I$43:I$45,MATCH($D$5,'Company1153 Assumptions'!$C$43:$C$45,0)) | I38: =I16*INDEX('Company1153 Assumptions'!J$43:J$45,MATCH($D$5,'Company1153 Assumptions'!$C$43:$C$45,0)) | J38: =J16*INDEX('Company1153 Assumptions'!K$43:K$45,MATCH($D$5,'Company1153 Assumptions'!$C$43:$C$45,0))
B39: Stock-Based Compensation | C39: =C16*INDEX('Company1153 Assumptions'!D$47:D$49,MATCH($D$5,'Company1153 Assumptions'!$C$47:$C$49,0)) | D39: =D16*INDEX('Company1153 Assumptions'!E$47:E$49,MATCH($D$5,'Company1153 Assumptions'!$C$47:$C$49,0)) | E39: =E16*INDEX('Company1153 Assumptions'!F$47:F$49,MATCH($D$5,'Company1153 Assumptions'!$C$47:$C$49,0)) | F39: =F16*INDEX('Company1153 Assumptions'!G$47:G$49,MATCH($D$5,'Company1153 Assumptions'!$C$47:$C$49,0)) | G39: =G16*INDEX('Company1153 Assumptions'!H$47:H$49,MATCH($D$5,'Company1153 Assumptions'!$C$47:$C$49,0)) | H39: =H16*INDEX('Company1153 Assumptions'!I$47:I$49,MATCH($D$5,'Company1153 Assumptions'!$C$47:$C$49,0)) | I39: =I16*INDEX('Company1153 Assumptions'!J$47:J$49,MATCH($D$5,'Company1153 Assumptions'!$C$47:$C$49,0)) | J39: =J16*INDEX('Company1153 Assumptions'!K$47:K$49,MATCH($D$5,'Company1153 Assumptions'!$C$47:$C$49,0))
B40: Total Operating Expenses | C40: =SUM(C36:C39) | D40: =SUM(D36:D39) | E40: =SUM(E36:E39) | F40: =SUM(F36:F39) | G40: =SUM(G36:G39) | H40: =SUM(H36:H39) | I40: =SUM(I36:I39) | J40: =SUM(J36:J39)
B42: Operating Income (EBIT) | C42: =C33-C40 | D42: =D33-D40 | E42: =E33-E40 | F42: =F33-F40 | G42: =G33-G40 | H42: =H33-H40 | I42: =I33-I40 | J42: =J33-J40
B43: Operating Margin % | C43: =C42/C16 | D43: =D42/D16 | E43: =E42/E16 | F43: =F42/F16 | G43: =G42/G16 | H43: =H42/H16 | I43: =I42/I16 | J43: =J42/J16
B45: Interest (Expense) / Income | C45: =(C$64*INDEX('Company1153 Assumptions'!$D$88:$D$90,MATCH($D$5,'Company1153 Assumptions'!$C$88:$C$90,0)))-(C86*INDEX('Company1153 Assumptions'!$D$92:$D$94,MATCH($D$5,'Company1153 Assumptions'!$C$92:$C$94,0))) | D45: =(D$64*INDEX('Company1153 Assumptions'!$D$88:$D$90,MATCH($D$5,'Company1153 Assumptions'!$C$88:$C$90,0)))-(D86*INDEX('Company1153 Assumptions'!$D$92:$D$94,MATCH($D$5,'Company1153 Assumptions'!$C$92:$C$94,0))) | E45: =(E$64*INDEX('Company1153 Assumptions'!$D$88:$D$90,MATCH($D$5,'Company1153 Assumptions'!$C$88:$C$90,0)))-(E86*INDEX('Company1153 Assumptions'!$D$92:$D$94,MATCH($D$5,'Company1153 Assumptions'!$C$92:$C$94,0))) | F45: =(F$64*INDEX('Company1153 Assumptions'!$D$88:$D$90,MATCH($D$5,'Company1153 Assumptions'!$C$88:$C$90,0)))-(F86*INDEX('Company1153 Assumptions'!$D$92:$D$94,MATCH($D$5,'Company1153 Assumptions'!$C$92:$C$94,0))) | G45: =(G$64*INDEX('Company1153 Assumptions'!$D$88:$D$90,MATCH($D$5,'Company1153 Assumptions'!$C$88:$C$90,0)))-(G86*INDEX('Company1153 Assumptions'!$D$92:$D$94,MATCH($D$5,'Company1153 Assumptions'!$C$92:$C$94,0))) | H45: =(H$64*INDEX('Company1153 Assumptions'!$D$88:$D$90,MATCH($D$5,'Company1153 Assumptions'!$C$88:$C$90,0)))-(H86*INDEX('Company1153 Assumptions'!$D$92:$D$94,MATCH($D$5,'Company1153 Assumptions'!$C$92:$C$94,0))) | I45: =(I$64*INDEX('Company1153 Assumptions'!$D$88:$D$90,MATCH($D$5,'Company1153 Assumptions'!$C$88:$C$90,0)))-(I86*INDEX('Company1153 Assumptions'!$D$92:$D$94,MATCH($D$5,'Company1153 Assumptions'!$C$92:$C$94,0))) | J45: =(J$64*INDEX('Company1153 Assumptions'!$D$88:$D$90,MATCH($D$5,'Company1153 Assumptions'!$C$88:$C$90,0)))-(J86*INDEX('Company1153 Assumptions'!$D$92:$D$94,MATCH($D$5,'Company1153 Assumptions'!$C$92:$C$94,0)))
B47: Income Before Tax | C47: =C42+C45 | D47: =D42+D45 | E47: =E42+E45 | F47: =F42+F45 | G47: =G42+G45 | H47: =H42+H45 | I47: =I42+I45 | J47: =J42+J45
B48: Tax Provision | C48: =C47*INDEX('Company1153 Assumptions'!D$81:D$83,MATCH($D$5,'Company1153 Assumptions'!$C$81:$C$83,0)) | D48: =D47*INDEX('Company1153 Assumptions'!E$81:E$83,MATCH($D$5,'Company1153 Assumptions'!$C$81:$C$83,0)) | E48: =E47*INDEX('Company1153 Assumptions'!F$81:F$83,MATCH($D$5,'Company1153 Assumptions'!$C$81:$C$83,0)) | F48: =F47*INDEX('Company1153 Assumptions'!G$81:G$83,MATCH($D$5,'Company1153 Assumptions'!$C$81:$C$83,0)) | G48: =G47*INDEX('Company1153 Assumptions'!H$81:H$83,MATCH($D$5,'Company1153 Assumptions'!$C$81:$C$83,0)) | H48: =H47*INDEX('Company1153 Assumptions'!I$81:I$83,MATCH($D$5,'Company1153 Assumptions'!$C$81:$C$83,0)) | I48: =I47*INDEX('Company1153 Assumptions'!J$81:J$83,MATCH($D$5,'Company1153 Assumptions'!$C$81:$C$83,0)) | J48: =J47*INDEX('Company1153 Assumptions'!K$81:K$83,MATCH($D$5,'Company1153 Assumptions'!$C$81:$C$83,0))
B50: NET INCOME | C50: =C47-C48 | D50: =D47-D48 | E50: =E47-E48 | F50: =F47-F48 | G50: =G47-G48 | H50: =H47-H48 | I50: =I47-I48 | J50: =J47-J48
B51: Net Margin % | C51: =C50/C16 | D51: =D50/D16 | E51: =E50/E16 | F51: =F50/F16 | G51: =G50/G16 | H51: =H50/H16 | I51: =I50/I16 | J51: =J50/J16
B53: EARNINGS PER SHARE
...

Sheet Company1808 3-Statement
B2: COMPANY1809 - INCOME STATEMENT
B3: $ in millions
B5: Selected Scenario: | D5: ='Company1153 Assumptions'!$D$6
B7: Historical | F7: Projections
C8: 2021 | D8: 2022 | E8: 2023 | F8: 2024 | G8: 2025 | H8: 2026 | I8: 2027 | J8: 2028
B10: INCOME STATEMENT
B12: Family of Apps | C12: 115655 | D12: 114450 | E12: 133008 | F12: =E12*(1+INDEX('Company1808 Assumptions'!G$15:G$17,MATCH($D$5,'Company1808 Assumptions'!$C$15:$C$17,0))) | G12: =F12*(1+INDEX('Company1808 Assumptions'!H$15:H$17,MATCH($D$5,'Company1808 Assumptions'!$C$15:$C$17,0))) | H12: =G12*(1+INDEX('Company1808 Assumptions'!I$15:I$17,MATCH($D$5,'Company1808 Assumptions'!$C$15:$C$17,0))) | I12: =H12*(1+INDEX('Company1808 Assumptions'!J$15:J$17,MATCH($D$5,'Company1808 Assumptions'!$C$15:$C$17,0))) | J12: =I12*(1+INDEX('Company1808 Assumptions'!K$15:K$17,MATCH($D$5,'Company1808 Assumptions'!$C$15:$C$17,0)))
B13: Product0338 | C13: 2274 | D13: 2159 | E13: 1896 | F13: =F14-F12 | G13: =G14-G12 | H13: =H14-H12 | I13: =I14-I12 | J13: =J14-J12
B14: Total Revenue | C14: =SUM(C12:C13) | D14: =SUM(D12:D13) | E14: =SUM(E12:E13) | F14: =F12/(1-(INDEX('Company1808 Assumptions'!G$19:G$21,MATCH('Company1808 3-Statement'!$D$5,'Company1808 Assumptions'!$D$6,0)))) | G14: =G12/(1-(INDEX('Company1808 Assumptions'!H$19:H$21,MATCH('Company1808 3-Statement'!$D$5,'Company1808 Assumptions'!$D$6,0)))) | H14: =H12/(1-(INDEX('Company1808 Assumptions'!I$19:I$21,MATCH('Company1808 3-Statement'!$D$5,'Company1808 Assumptions'!$D$6,0)))) | I14: =I12/(1-(INDEX('Company1808 Assumptions'!J$19:J$21,MATCH('Company1808 3-Statement'!$D$5,'Company1808 Assumptions'!$D$6,0)))) | J14: =J12/(1-(INDEX('Company1808 Assumptions'!K$19:K$21,MATCH('Company1808 3-Statement'!$D$5,'Company1808 Assumptions'!$D$6,0))))
B15: YoY Growth % | D15: =D14/C14-1 | E15: =E14/D14-1 | F15: =F14/E14-1 | G15: =G14/F14-1 | H15: =H14/G14-1 | I15: =I14/H14-1 | J15: =J14/I14-1
B17: Cost of Revenue | C17: =C14*(1-C19) | D17: =D14*(1-D19) | E17: =E14*(1-E19) | F17: =F14*(1-F19) | G17: =G14*(1-G19) | H17: =H14*(1-H19) | I17: =I14*(1-I19) | J17: =J14*(1-J19)
B18: Gross Profit | C18: =C14-C17 | D18: =D14-D17 | E18: =E14-E17 | F18: =F14-F17 | G18: =G14-G17 | H18: =H14-H17 | I18: =I14-I17 | J18: =J14-J17
B19: Gross Margin % | C19: 0.802 | D19: 0.798 | E19: 0.795 | F19: 0.797 | G19: 0.799 | H19: 0.801 | I19: 0.803 | J19: 0.805
B21: Research & Development | C21: =C14*INDEX('Company1808 Assumptions'!D$38:D$40,MATCH($D$5,'Company1808 Assumptions'!$C$38:$C$40,0)) | D21: =D14*INDEX('Company1808 Assumptions'!E$38:E$40,MATCH($D$5,'Company1808 Assumptions'!$C$38:$C$40,0)) | E21: =E14*INDEX('Company1808 Assumptions'!F$38:F$40,MATCH($D$5,'Company1808 Assumptions'!$C$38:$C$40,0)) | F21: =F14*INDEX('Company1808 Assumptions'!G$38:G$40,MATCH($D$5,'Company1808 Assumptions'!$C$38:$C$40,0)) | G21: =G14*INDEX('Company1808 Assumptions'!H$38:H$40,MATCH($D$5,'Company1808 Assumptions'!$C$38:$C$40,0)) | H21: =H14*INDEX('Company1808 Assumptions'!I$38:I$40,MATCH($D$5,'Company1808 Assumptions'!$C$38:$C$40,0)) | I21: =I14*INDEX('Company1808 Assumptions'!J$38:J$40,MATCH($D$5,'Company1808 Assumptions'!$C$38:$C$40,0)) | J21: =J14*INDEX('Company1808 Assumptions'!K$38:K$40,MATCH($D$5,'Company1808 Assumptions'!$C$38:$C$40,0))
B22: Sales & Marketing | C22: =C14*INDEX('Company1808 Assumptions'!D$42:D$44,MATCH($D$5,'Company1808 Assumptions'!$C$42:$C$44,0)) | D22: =D14*INDEX('Company1808 Assumptions'!E$42:E$44,MATCH($D$5,'Company1808 Assumptions'!$C$42:$C$44,0)) | E22: =E14*INDEX('Company1808 Assumptions'!F$42:F$44,MATCH($D$5,'Company1808 Assumptions'!$C$42:$C$44,0)) | F22: =F14*INDEX('Company1808 Assumptions'!G$42:G$44,MATCH($D$5,'Company1808 Assumptions'!$C$42:$C$44,0)) | G22: =G14*INDEX('Company1808 Assumptions'!H$42:H$44,MATCH($D$5,'Company1808 Assumptions'!$C$42:$C$44,0)) | H22: =H14*INDEX('Company1808 Assumptions'!I$42:I$44,MATCH($D$5,'Company1808 Assumptions'!$C$42:$C$44,0)) | I22: =I14*INDEX('Company1808 Assumptions'!J$42:J$44,MATCH($D$5,'Company1808 Assumptions'!$C$42:$C$44,0)) | J22: =J14*INDEX('Company1808 Assumptions'!K$42:K$44,MATCH($D$5,'Company1808 Assumptions'!$C$42:$C$44,0))
B23: General & Administrative | C23: =C14*INDEX('Company1808 Assumptions'!D$46:D$48,MATCH($D$5,'Company1808 Assumptions'!$C$46:$C$48,0)) | D23: =D14*INDEX('Company1808 Assumptions'!E$46:E$48,MATCH($D$5,'Company1808 Assumptions'!$C$46:$C$48,0)) | E23: =E14*INDEX('Company1808 Assumptions'!F$46:F$48,MATCH($D$5,'Company1808 Assumptions'!$C$46:$C$48,0)) | F23: =F14*INDEX('Company1808 Assumptions'!G$46:G$48,MATCH($D$5,'Company1808 Assumptions'!$C$46:$C$48,0)) | G23: =G14*INDEX('Company1808 Assumptions'!H$46:H$48,MATCH($D$5,'Company1808 Assumptions'!$C$46:$C$48,0)) | H23: =H14*INDEX('Company1808 Assumptions'!I$46:I$48,MATCH($D$5,'Company1808 Assumptions'!$C$46:$C$48,0)) | I23: =I14*INDEX('Company1808 Assumptions'!J$46:J$48,MATCH($D$5,'Company1808 Assumptions'!$C$46:$C$48,0)) | J23: =J14*INDEX('Company1808 Assumptions'!K$46:K$48,MATCH($D$5,'Company1808 Assumptions'!$C$46:$C$48,0))
B24: Stock-Based Compensation | C24: =C14*INDEX('Company1808 Assumptions'!D$50:D$52,MATCH($D$5,'Company1808 Assumptions'!$C$50:$C$52,0)) | D24: =D14*INDEX('Company1808 Assumptions'!E$50:E$52,MATCH($D$5,'Company1808 Assumptions'!$C$50:$C$52,0)) | E24: =E14*INDEX('Company1808 Assumptions'!F$50:F$52,MATCH($D$5,'Company1808 Assumptions'!$C$50:$C$52,0)) | F24: =F14*INDEX('Company1808 Assumptions'!G$50:G$52,MATCH($D$5,'Company1808 Assumptions'!$C$50:$C$52,0)) | G24: =G14*INDEX('Company1808 Assumptions'!H$50:H$52,MATCH($D$5,'Company1808 Assumptions'!$C$50:$C$52,0)) | H24: =H14*INDEX('Company1808 Assumptions'!I$50:I$52,MATCH($D$5,'Company1808 Assumptions'!$C$50:$C$52,0)) | I24: =I14*INDEX('Company1808 Assumptions'!J$50:J$52,MATCH($D$5,'Company1808 Assumptions'!$C$50:$C$52,0)) | J24: =J14*INDEX('Company1808 Assumptions'!K$50:K$52,MATCH($D$5,'Company1808 Assumptions'!$C$50:$C$52,0))
B25: Total Operating Expenses | C25: =SUM(C21:C24) | D25: =SUM(D21:D24) | E25: =SUM(E21:E24) | F25: =SUM(F21:F24) | G25: =SUM(G21:G24) | H25: =SUM(H21:H24) | I25: =SUM(I21:I24) | J25: =SUM(J21:J24)
B27: Operating Income (EBIT) | C27: =C18-C25 | D27: =D18-D25 | E27: =E18-E25 | F27: =F18-F25 | G27: =G18-G25 | H27: =H18-H25 | I27: =I18-I25 | J27: =J18-J25
B28: Operating Margin % | C28: =C27/C14 | D28: =D27/D14 | E28: =E27/E14 | F28: =F27/F14 | G28: =G27/G14 | H28: =H27/H14 | I28: =I27/I14 | J28: =J27/J14
B30: Interest (Expense) / Income | C30: =(C$49*INDEX('Company1808 Assumptions'!$D$99:$D$101,MATCH($D$5,'Company1808 Assumptions'!$C$99:$C$101,0)))-(C71*INDEX('Company1808 Assumptions'!$D$103:$D$105,MATCH($D$5,'Company1808 Assumptions'!$C$103:$C$105,0))) | D30: =(D$49*INDEX('Company1808 Assumptions'!$D$99:$D$101,MATCH($D$5,'Company1808 Assumptions'!$C$99:$C$101,0)))-(D71*INDEX('Company1808 Assumptions'!$D$103:$D$105,MATCH($D$5,'Company1808 Assumptions'!$C$103:$C$105,0))) | E30: =(E$49*INDEX('Company1808 Assumptions'!$D$99:$D$101,MATCH($D$5,'Company1808 Assumptions'!$C$99:$C$101,0)))-(E71*INDEX('Company1808 Assumptions'!$D$103:$D$105,MATCH($D$5,'Company1808 Assumptions'!$C$103:$C$105,0))) | F30: =(F$49*INDEX('Company1808 Assumptions'!$D$99:$D$101,MATCH($D$5,'Company1808 Assumptions'!$C$99:$C$101,0)))-(F71*INDEX('Company1808 Assumptions'!$D$103:$D$105,MATCH($D$5,'Company1808 Assumptions'!$C$103:$C$105,0))) | G30: =(G$49*INDEX('Company1808 Assumptions'!$D$99:$D$101,MATCH($D$5,'Company1808 Assumptions'!$C$99:$C$101,0)))-(G71*INDEX('Company1808 Assumptions'!$D$103:$D$105,MATCH($D$5,'Company1808 Assumptions'!$C$103:$C$105,0))) | H30: =(H$49*INDEX('Company1808 Assumptions'!$D$99:$D$101,MATCH($D$5,'Company1808 Assumptions'!$C$99:$C$101,0)))-(H71*INDEX('Company1808 Assumptions'!$D$103:$D$105,MATCH($D$5,'Company1808 Assumptions'!$C$103:$C$105,0))) | I30: =(I$49*INDEX('Company1808 Assumptions'!$D$99:$D$101,MATCH($D$5,'Company1808 Assumptions'!$C$99:$C$101,0)))-(I71*INDEX('Company1808 Assumptions'!$D$103:$D$105,MATCH($D$5,'Company1808 Assumptions'!$C$103:$C$105,0))) | J30: =(J$49*INDEX('Company1808 Assumptions'!$D$99:$D$101,MATCH($D$5,'Company1808 Assumptions'!$C$99:$C$101,0)))-(J71*INDEX('Company1808 Assumptions'!$D$103:$D$105,MATCH($D$5,'Company1808 Assumptions'!$C$103:$C$105,0)))
B32: Income Before Tax | C32: =C27+C30 | D32: =D27+D30 | E32: =E27+E30 | F32: =F27+F30 | G32: =G27+G30 | H32: =H27+H30 | I32: =I27+I30 | J32: =J27+J30
B33: Tax Provision | C33: =C32*INDEX('Company1808 Assumptions'!D$92:D$94,MATCH($D$5,'Company1808 Assumptions'!$C$92:$C$94,0)) | D33: =D32*INDEX('Company1808 Assumptions'!E$92:E$94,MATCH($D$5,'Company1808 Assumptions'!$C$92:$C$94,0)) | E33: =E32*INDEX('Company1808 Assumptions'!F$92:F$94,MATCH($D$5,'Company1808 Assumptions'!$C$92:$C$94,0)) | F33: =F32*INDEX('Company1808 Assumptions'!G$92:G$94,MATCH($D$5,'Company1808 Assumptions'!$C$92:$C$94,0)) | G33: =G32*INDEX('Company1808 Assumptions'!H$92:H$94,MATCH($D$5,'Company1808 Assumptions'!$C$92:$C$94,0)) | H33: =H32*INDEX('Company1808 Assumptions'!I$92:I$94,MATCH($D$5,'Company1808 Assumptions'!$C$92:$C$94,0)) | I33: =I32*INDEX('Company1808 Assumptions'!J$92:J$94,MATCH($D$5,'Company1808 Assumptions'!$C$92:$C$94,0)) | J33: =J32*INDEX('Company1808 Assumptions'!K$92:K$94,MATCH($D$5,'Company1808 Assumptions'!$C$92:$C$94,0))
B35: NET INCOME | C35: =C32-C33 | D35: =D32-D33 | E35: =E32-E33 | F35: =F32-F33 | G35: =G32-G33 | H35: =H32-H33 | I35: =I32-I33 | J35: =J32-J33
B36: Net Margin % | C36: =C35/C14 | D36: =D35/D14 | E36: =E35/E14 | F36: =F35/F14 | G36: =G35/G14 | H36: =H35/H14 | I36: =I35/I14 | J36: =J35/J14
B38: EARNINGS PER SHARE
B40: Basic Shares Outstanding | C40: 2800 | D40: 2750 | E40: 2700 | F40: 2650 | G40: 2600 | H40: 2550 | I40: 2500 | J40: 2450
B41: Basic EPS | C41: =C35/C40 | D41: =D35/D40 | E41: =E35/E40 | F41: =F35/F40 | G41: =G35/G40 | H41: =H35/H40 | I41: =I35/I40 | J41: =J35/J40
B44: BALANCE SHEET
B46: ASSETS
B48: Current Assets
B49: Cash & Cash Equivalents | C49: 35000 | D49: =D$106 | E49: =E$106 | F49: =F$106 | G49: =G$106 | H49: =H$106 | I49: =I$106 | J49: =J$106
B50: Accounts Receivable | C50: =C$14*INDEX('Company1808 Assumptions'!D$64:D$66,MATCH($D$5,'Company1808 Assumptions'!$C$64:$C$66,0))/365 | D50: =D$14*INDEX('Company1808 Assumptions'!E$64:E$66,MATCH($D$5,'Company1808 Assumptions'!$C$64:$C$66,0))/365 | E50: =E$14*INDEX('Company1808 Assumptions'!F$64:F$66,MATCH($D$5,'Company1808 Assumptions'!$C$64:$C$66,0))/365 | F50: =F$14*INDEX('Company1808 Assumptions'!G$64:G$66,MATCH($D$5,'Company1808 Assumptions'!$C$64:$C$66,0))/365 | G50: =G$14*INDEX('Company1808 Assumptions'!H$64:H$66,MATCH($D$5,'Company1808 Assumptions'!$C$64:$C$66,0))/365 | H50: =H$14*INDEX('Company1808 Assumptions'!I$64:I$66,MATCH($D$5,'Company1808 Assumptions'!$C$64:$C$66,0))/365 | I50: =I$14*INDEX('Company1808 Assumptions'!J$64:J$66,MATCH($D$5,'Company1808 Assumptions'!$C$64:$C$66,0))/365 | J50: =J$14*INDEX('Company1808 Assumptions'!K$64:K$66,MATCH($D$5,'Company1808 Assumptions'!$C$64:$C$66,0))/365
B51: Other Current Assets | C51: 5000 | D51: =C51*(1+'Company1808 Assumptions'!E$72) | E51: =D51*(1+'Company1808 Assumptions'!F$72) | F51: =E51*(1+'Company1808 Assumptions'!G$72) | G51: =F51*(1+'Company1808 Assumptions'!H$72) | H51: =G51*(1+'Company1808 Assumptions'!I$72) | I51: =H51*(1+'Company1808 Assumptions'!J$72) | J51: =I51*(1+'Company1808 Assumptions'!K$72)
B52: Total Current Assets | C52: =SUM(C49:C51) | D52: =SUM(D49:D51) | E52: =SUM(E49:E51) | F52: =SUM(F49:F51) | G52: =SUM(G49:G51) | H52: =SUM(H49:H51) | I52: =SUM(I49:I51) | J52: =SUM(J49:J51)
B54: Non-Current Assets
B55: Property, Plant & Equipment (Gross) | C55: 60000 | D55: =C55+D95 | E55: =D55+E95 | F55: =E55+F95 | G55: =F55+G95 | H55: =G55+H95 | I55: =H55+I95 | J55: =I55+J95
B56: Less: Accumulated Depreciation | C56: 15000 | D56: =C56+D87 | E56: =D56+E87 | F56: =E56+F87 | G56: =F56+G87 | H56: =G56+H87 | I56: =H56+I87 | J56: =I56+J87
B57: Net PP&E | C57: =C55-C56 | D57: =D55-D56 | E57: =E55-E56 | F57: =F55-F56 | G57: =G55-G56 | H57: =H55-H56 | I57: =I55-I56 | J57: =J55-J56
B59: Other Long-term Assets | C59: 25000 | D59: =C59*(1+'Company1808 Assumptions'!E$73) | E59: =D59*(1+'Company1808 Assumptions'!F$73) | F59: =E59*(1+'Company1808 Assumptions'!G$73) | G59: =F59*(1+'Company1808 Assumptions'!H$73) | H59: =G59*(1+'Company1808 Assumptions'!I$73) | I59: =H59*(1+'Company1808 Assumptions'!J$73) | J59: =I59*(1+'Company1808 Assumptions'!K$73)
...

Sheet Combination Assumptions
B2: M&A TRANSACTION ASSUMPTIONS - COMPANY1153 / COMPANY1808 COMBINATION
B3: Pro Forma Merger Model Assumptions
B5: 1. TRANSACTION OVERVIEW
B7: Transaction Structure
B8: Acquirer | D8: Company1153 (Company0215)
B9: Target | D9: Company1809
B10: Transaction Type | D10: Stock & Cash Combination
B11: Announcement Date | D11: Q4 2023
B12: Expected Close | D12: Q1 2024
B14: 2. PURCHASE PRICE CALCULATION
B16: Stock Prices & Premium
B17: Company1808 Current Stock Price | D17: 520
B18: Premium Offered | D18: 0.3
B19: Offer Price per Share | D19: =D17*(1+D18)
B20: Company1808 Shares Outstanding (mm) | D20: 2700
B21: Total Purchase Price ($mm) | D21: =D19*D20
B23: Consideration Mix
B24: % Cash Consideration | D24: 0.5
B25: % Stock Consideration | D25: 0.5
B26: Cash Required ($mm) | D26: =$D$21*D24
B27: Stock Value Required ($mm) | D27: =$D$21*D25
B28: Company1153 Stock Price | D28: 175
B29: New Company1153 Shares Issued (mm) | D29: =D27/D28
B31: 3. SOURCES & USES OF FUNDS
B33: Sources of Funds ($mm) | F33: Uses of Funds ($mm)
B34: Stock Issued | D34: =$D$27 | F34: Purchase Price | H34: {=D21}
B35: New Term Loan | D35: 400000 | F35: Transaction Fees | H35: =$D$21*$I$35 | I35: 0.02
B36: Bridge Loan | D36: 100000 | F36: Financing Fees | H36: =(D35+D36)*$I$36 | I36: 0.025
B37: Cash on Hand | D37: =H38-D26-D35-D36 | F37: Integration Costs | H37: 5000
B38: Total Sources | D38: =SUM(D34:D37) | F38: Total Uses | H38: =SUM(H34:H37)
B40: 4. SYNERGY ASSUMPTIONS
B42: Revenue Synergies ($mm)
D43: Year 1 | E43: Year 2 | F43: Year 3 | G43: Year 4 | H43: Year 5
B44: Cross-Platform Advertising | D44: 2000 | E44: 4000 | F44: 6000 | G44: 7000 | H44: 8000
B45: Data & AI Integration | D45: 1000 | E45: 2500 | F45: 4000 | G45: 5000 | H45: 6000
B46: Market Expansion | D46: 500 | E46: 1500 | F46: 2500 | G46: 3000 | H46: 3500
B47: Total Revenue Synergies | D47: =SUM(D44:D46) | E47: =SUM(E44:E46) | F47: =SUM(F44:F46) | G47: =SUM(G44:G46) | H47: =SUM(H44:H46)
B49: Cost Synergies ($mm)
B50: Infrastructure & Cloud | D50: 3000 | E50: 5000 | F50: 7000 | G50: 8000 | H50: 8500
B51: R&D Efficiency | D51: 2000 | E51: 3500 | F51: 4500 | G51: 5000 | H51: 5500
...

Sheet PF Combination
B2: PRO FORMA COMBINED ENTITY - COMPANY1153 / COMPANY1808
B3: $ in millions
B5: TRANSACTION SUMMARY
B7: Purchase Price ($mm): | D7: ='Combination Assumptions'!$D$21
B8: Cash Consideration: | D8: ='Combination Assumptions'!$D$26
B9: Stock Consideration: | D9: ='Combination Assumptions'!$D$27
B10: Total Debt Raised: | D10: ='Combination Assumptions'!$D$35+'Combination Assumptions'!$D$36
B11: Goodwill Created: | D11: ='Combination Assumptions'!$D$75
B13: PRO FORMA INCOME STATEMENT
B15: For the Year Ending | D15: 2024 | E15: 2025 | F15: 2026 | G15: 2027 | H15: 2028
B17: COMBINED REVENUE
B18: Company1153 Revenue | D18: ='Company1153 3-Statement'!F$16 | E18: ='Company1153 3-Statement'!G$16 | F18: ='Company1153 3-Statement'!H$16 | G18: ='Company1153 3-Statement'!I$16 | H18: ='Company1153 3-Statement'!J$16
B19: Company1808 Revenue | D19: ='Company1808 3-Statement'!F$14 | E19: ='Company1808 3-Statement'!G$14 | F19: ='Company1808 3-Statement'!H$14 | G19: ='Company1808 3-Statement'!I$14 | H19: ='Company1808 3-Statement'!J$14
B20: Revenue Synergies | D20: ='Combination Assumptions'!D$47 | E20: ='Combination Assumptions'!E$47 | F20: ='Combination Assumptions'!F$47 | G20: ='Combination Assumptions'!G$47 | H20: ='Combination Assumptions'!H$47
B21: Total Combined Revenue | D21: =SUM(D18:D20) | E21: =SUM(E18:E20) | F21: =SUM(F18:F20) | G21: =SUM(G18:G20) | H21: =SUM(H18:H20)
B23: OPERATING EXPENSES
B24: Cost of Revenue (Combined) | D24: ='Company1153 3-Statement'!F$32+'Company1808 3-Statement'!F$17 | E24: ='Company1153 3-Statement'!G$32+'Company1808 3-Statement'!G$17 | F24: ='Company1153 3-Statement'!H$32+'Company1808 3-Statement'!H$17 | G24: ='Company1153 3-Statement'!I$32+'Company1808 3-Statement'!I$17 | H24: ='Company1153 3-Statement'!J$32+'Company1808 3-Statement'!J$17
B25: Infrastructure Synergy | D25: =-'Combination Assumptions'!D$50 | E25: =-'Combination Assumptions'!E$50 | F25: =-'Combination Assumptions'!F$50 | G25: =-'Combination Assumptions'!G$50 | H25: =-'Combination Assumptions'!H$50
B26: Gross Profit | D26: =D21-D24-D25 | E26: =E21-E24-E25 | F26: =F21-F24-F25 | G26: =G21-G24-G25 | H26: =H21-H24-H25
B28: R&D (Combined) | D28: ='Company1153 3-Statement'!F$36+'Company1808 3-Statement'!F$21 | E28: ='Company1153 3-Statement'!G$36+'Company1808 3-Statement'!G$21 | F28: ='Company1153 3-Statement'!H$36+'Company1808 3-Statement'!H$21 | G28: ='Company1153 3-Statement'!I$36+'Company1808 3-Statement'!I$21 | H28: ='Company1153 3-Statement'!J$36+'Company1808 3-Statement'!J$21
B29: R&D Synergy | D29: =-'Combination Assumptions'!D$51 | E29: =-'Combination Assumptions'!E$51 | F29: =-'Combination Assumptions'!F$51 | G29: =-'Combination Assumptions'!G$51 | H29: =-'Combination Assumptions'!H$51
B30: S&M (Combined) | D30: ='Company1153 3-Statement'!F$37+'Company1808 3-Statement'!F$22 | E30: ='Company1153 3-Statement'!G$37+'Company1808 3-Statement'!G$22 | F30: ='Company1153 3-Statement'!H$37+'Company1808 3-Statement'!H$22 | G30: ='Company1153 3-Statement'!I$37+'Company1808 3-Statement'!I$22 | H30: ='Company1153 3-Statement'!J$37+'Company1808 3-Statement'!J$22
B31: S&M Synergy | D31: =-'Combination Assumptions'!D$53 | E31: =-'Combination Assumptions'!E$53 | F31: =-'Combination Assumptions'!F$53 | G31: =-'Combination Assumptions'!G$53 | H31: =-'Combination Assumptions'!H$53
B32: G&A (Combined) | D32: ='Company1153 3-Statement'!F$38+'Company1808 3-Statement'!F$23 | E32: ='Company1153 3-Statement'!G$38+'Company1808 3-Statement'!G$23 | F32: ='Company1153 3-Statement'!H$38+'Company1808 3-Statement'!H$23 | G32: ='Company1153 3-Statement'!I$38+'Company1808 3-Statement'!I$23 | H32: ='Company1153 3-Statement'!J$38+'Company1808 3-Statement'!J$23
B33: G&A Synergy | D33: =-'Combination Assumptions'!D$52 | E33: =-'Combination Assumptions'!E$52 | F33: =-'Combination Assumptions'!F$52 | G33: =-'Combination Assumptions'!G$52 | H33: =-'Combination Assumptions'!H$52
B34: Stock-Based Compensation (Combined) | D34: ='Company1153 3-Statement'!F$39+'Company1808 3-Statement'!F$24 | E34: ='Company1153 3-Statement'!G$39+'Company1808 3-Statement'!G$24 | F34: ='Company1153 3-Statement'!H$39+'Company1808 3-Statement'!H$24 | G34: ='Company1153 3-Statement'!I$39+'Company1808 3-Statement'!I$24 | H34: ='Company1153 3-Statement'!J$39+'Company1808 3-Statement'!J$24
B35: Dis-synergies & Integration | D35: =-'Combination Assumptions'!D$60 | E35: =-'Combination Assumptions'!E$60 | F35: =-'Combination Assumptions'!F$60 | G35: =-'Combination Assumptions'!G$60 | H35: =-'Combination Assumptions'!H$60
B36: Amortization of new intangibles | D36: ='Combination Assumptions'!$D$91 | E36: ='Combination Assumptions'!$D$91 | F36: ='Combination Assumptions'!$D$91 | G36: ='Combination Assumptions'!$D$91 | H36: ='Combination Assumptions'!$D$91
B38: EBIT | D38: =D26-SUM(D28:D36) | E38: =E26-SUM(E28:E36) | F38: =F26-SUM(F28:F36) | G38: =G26-SUM(G28:G36) | H38: =H26-SUM(H28:H36)
B40: Existing interest expense / (income) | D40: =-('Company1153 3-Statement'!F$45+'Company1808 3-Statement'!F$30) | E40: =-('Company1153 3-Statement'!G$45+'Company1808 3-Statement'!G$30) | F40: =-('Company1153 3-Statement'!H$45+'Company1808 3-Statement'!H$30) | G40: =-('Company1153 3-Statement'!I$45+'Company1808 3-Statement'!I$30) | H40: =-('Company1153 3-Statement'!J$45+'Company1808 3-Statement'!J$30)
B41: New interest expense | D41: =(('Combination Assumptions'!$D$80*((1-'Combination Assumptions'!$D$84)^(D$15-$D$15)))*'Combination Assumptions'!$D$81)+(('Combination Assumptions'!$D$82*((1-'Combination Assumptions'!$D$84)^(D$15-$D$15)))*'Combination Assumptions'!$D$83) | E41: =(('Combination Assumptions'!$D$80*((1-'Combination Assumptions'!$D$84)^(E$15-$D$15)))*'Combination Assumptions'!$D$81)+(('Combination Assumptions'!$D$82*((1-'Combination Assumptions'!$D$84)^(E$15-$D$15)))*'Combination Assumptions'!$D$83) | F41: =(('Combination Assumptions'!$D$80*((1-'Combination Assumptions'!$D$84)^(F$15-$D$15)))*'Combination Assumptions'!$D$81)+(('Combination Assumptions'!$D$82*((1-'Combination Assumptions'!$D$84)^(F$15-$D$15)))*'Combination Assumptions'!$D$83) | G41: =(('Combination Assumptions'!$D$80*((1-'Combination Assumptions'!$D$84)^(G$15-$D$15)))*'Combination Assumptions'!$D$81)+(('Combination Assumptions'!$D$82*((1-'Combination Assumptions'!$D$84)^(G$15-$D$15)))*'Combination Assumptions'!$D$83) | H41: =(('Combination Assumptions'!$D$80*((1-'Combination Assumptions'!$D$84)^(H$15-$D$15)))*'Combination Assumptions'!$D$81)+(('Combination Assumptions'!$D$82*((1-'Combination Assumptions'!$D$84)^(H$15-$D$15)))*'Combination Assumptions'!$D$83)
B42: EBT | D42: =D38-D40-D41 | E42: =E38-E40-E41 | F42: =F38-F40-F41 | G42: =G38-G40-G41 | H42: =H38-H40-H41
B43: Taxes | D43: =D42*'Combination Assumptions'!$D$95 | E43: =E42*'Combination Assumptions'!$D$95 | F43: =F42*'Combination Assumptions'!$D$95 | G43: =G42*'Combination Assumptions'!$D$95 | H43: =H42*'Combination Assumptions'!$D$95
B45: NET INCOME | D45: =D42-D43 | E45: =E42-E43 | F45: =F42-F43 | G45: =G42-G43 | H45: =H42-H43
B47: ACCRETION / DILUTION ANALYSIS
B49: Pro Forma Shares (mm) | D49: ='Company1153 3-Statement'!F$55+'Combination Assumptions'!$D$29 | E49: ='Company1153 3-Statement'!G$55+'Combination Assumptions'!$D$29 | F49: ='Company1153 3-Statement'!H$55+'Combination Assumptions'!$D$29 | G49: ='Company1153 3-Statement'!I$55+'Combination Assumptions'!$D$29 | H49: ='Company1153 3-Statement'!J$55+'Combination Assumptions'!$D$29
B50: Pro Forma EPS | D50: =D45/D49 | E50: =E45/E49 | F50: =F45/F49 | G50: =G45/G49 | H50: =H45/H49
B51: % Accretion (Dilution) | D51: =D50/'Company1153 3-Statement'!F$56-1 | E51: =E50/'Company1153 3-Statement'!G$56-1 | F51: =F50/'Company1153 3-Statement'!H$56-1 | G51: =G50/'Company1153 3-Statement'!I$56-1 | H51: =H50/'Company1153 3-Statement'!J$56-1

Sheet Synergy Analysis
B2: SYNERGY ANALYSIS - COMPANY1153 / COMPANY1808 COMBINATION
B3: Detailed Cost and Revenue Synergy Modeling
B5: SYNERGY ASSUMPTIONS
B7: 1. Infrastructure Cost Savings
B8: % of Combined CapEx Savings | D8: Conservative | E8: Base | F8: Aggressive
D9: 0.15 | E9: 0.2 | F9: 0.25
B10: Selected Scenario: | D10: ='Company1153 Assumptions'!$D$6
B12: 2. R&D Efficiency Gains
B13: % Reduction in Combined R&D | D13: Conservative | E13: Base | F13: Aggressive
D14: 0.1 | E14: 0.15 | F14: 0.2
B15: Selected Scenario: | D15: ='Company1153 Assumptions'!$D$6
B17: 3. Revenue Synergies - Cross-Platform Advertising
B18: % Revenue Uplift | D18: Conservative | E18: Base | F18: Aggressive
D19: 0.02 | E19: 0.035 | F19: 0.05
B20: Selected Scenario: | D20: ='Company1153 Assumptions'!$D$6
B22: SYNERGY CALCULATIONS
B24: $ in millions | D24: 2024 | E24: 2025 | F24: 2026 | G24: 2027 | H24: 2028
B26: Infrastructure Cost Savings
B27: Company1153 CapEx | D27: ='Company1153 3-Statement'!F$110 | E27: ='Company1153 3-Statement'!G$110 | F27: ='Company1153 3-Statement'!H$110 | G27: ='Company1153 3-Statement'!I$110 | H27: ='Company1153 3-Statement'!J$110
B28: Company1808 CapEx | D28: ='Company1808 3-Statement'!F$95 | E28: ='Company1808 3-Statement'!G$95 | F28: ='Company1808 3-Statement'!H$95 | G28: ='Company1808 3-Statement'!I$95 | H28: ='Company1808 3-Statement'!J$95
B29: Combined CapEx | D29: =D27+D28 | E29: =E27+E28 | F29: =F27+F28 | G29: =G27+G28 | H29: =H27+H28
B30: Savings % | D30: {=INDEX($D$9:$F$9,MATCH($D$10,$D$8:$F$8,0))} | E30: {=INDEX($D$9:$F$9,MATCH($D$10,$D$8:$F$8,0))} | F30: {=INDEX($D$9:$F$9,MATCH($D$10,$D$8:$F$8,0))} | G30: {=INDEX($D$9:$F$9,MATCH($D$10,$D$8:$F$8,0))} | H30: {=INDEX($D$9:$F$9,MATCH($D$10,$D$8:$F$8,0))}
B31: Infrastructure Synergy | D31: =D29*D30 | E31: =E29*E30 | F31: =F29*F30 | G31: =G29*G30 | H31: =H29*H30
B33: R&D Efficiency Gains
B34: Company1153 R&D Expense | D34: ='Company1153 3-Statement'!F$38 | E34: ='Company1153 3-Statement'!G$38 | F34: ='Company1153 3-Statement'!H$38 | G34: ='Company1153 3-Statement'!I$38 | H34: ='Company1153 3-Statement'!J$38
B35: Company1808 R&D Expense | D35: ='Company1808 3-Statement'!F$23 | E35: ='Company1808 3-Statement'!G$23 | F35: ='Company1808 3-Statement'!H$23 | G35: ='Company1808 3-Statement'!I$23 | H35: ='Company1808 3-Statement'!J$23
B36: Combined R&D | D36: =D34+D35 | E36: =E34+E35 | F36: =F34+F35 | G36: =G34+G35 | H36: =H34+H35
B37: Efficiency % | D37: {=INDEX($D$14:$F$14,MATCH($D$15,$D$13:$F$13,0))} | E37: {=INDEX($D$14:$F$14,MATCH($D$15,$D$13:$F$13,0))} | F37: {=INDEX($D$14:$F$14,MATCH($D$15,$D$13:$F$13,0))} | G37: {=INDEX($D$14:$F$14,MATCH($D$15,$D$13:$F$13,0))} | H37: {=INDEX($D$14:$F$14,MATCH($D$15,$D$13:$F$13,0))}
B38: R&D Synergy | D38: =D36*D37 | E38: =E36*E37 | F38: =F36*F37 | G38: =G36*G37 | H38: =H36*H37
B40: Revenue Synergies
B41: Company1153 Revenue | D41: ='Company1153 3-Statement'!F$16 | E41: ='Company1153 3-Statement'!G$16 | F41: ='Company1153 3-Statement'!H$16 | G41: ='Company1153 3-Statement'!I$16 | H41: ='Company1153 3-Statement'!J$16
B42: Company1808 Revenue | D42: ='Company1808 3-Statement'!F$14 | E42: ='Company1808 3-Statement'!G$14 | F42: ='Company1808 3-Statement'!H$14 | G42: ='Company1808 3-Statement'!I$14 | H42: ='Company1808 3-Statement'!J$14
B43: Combined Revenue | D43: =D41+D42 | E43: =E41+E42 | F43: =F41+F42 | G43: =G41+G42 | H43: =H41+H42
B44: Revenue Uplift % | D44: {=INDEX($D$19:$F$19,MATCH($D$20,$D$18:$F$18,0))} | E44: {=INDEX($D$19:$F$19,MATCH($D$20,$D$18:$F$18,0))} | F44: {=INDEX($D$19:$F$19,MATCH($D$20,$D$18:$F$18,0))} | G44: {=INDEX($D$19:$F$19,MATCH($D$20,$D$18:$F$18,0))} | H44: {=INDEX($D$19:$F$19,MATCH($D$20,$D$18:$F$18,0))}
B45: Revenue Synergy | D45: =D43*D44 | E45: =E43*E44 | F45: =F43*F44 | G45: =G43*G44 | H45: =H43*H44
B47: Phase-in Schedule
B48: Year 1 Realization % | D48: 0 | E48: 0.3 | F48: 0.6 | G48: 0.85 | H48: 0.95
B50: TOTAL SYNERGIES SUMMARY
B52: Gross Synergies
B53: Infrastructure Savings | D53: {=D31} | E53: {=E31} | F53: {=F31} | G53: {=G31} | H53: {=H31}
...
