Workbook

Sheet Liability Summary
A1: Liability Summary
B2: Year | C2: Actual Property For Review | E2: Amount Remediated (C) | G2: Amount Unresolved (U) | M2: Unclaimed Property for Extrapolation Base | N2: Revenue | O2: Percentage Unclaimed
C3: =SUM(C5:C19) | E3: =SUM(E5:E19) | G3: =SUM(G5:G19) | M3: =SUM(M5:M19) | N3: =SUM(N5:N7) | O3: =M3/N3
B5: 2021 | C5: =GETPIVOTDATA("For Review",Pivot!$C$3,"Year","2021") | E5: =GETPIVOTDATA("For Review",Pivot!$C$9,"Year","2021","Remediation Status","Clear") | G5: =GETPIVOTDATA("For Review",Pivot!$C$9,"Year","2021","Remediation Status",) | M5: =G5 | N5: 610380066
B6: 2020 | C6: =GETPIVOTDATA("For Review",Pivot!$C$3,"Year","2020") | E6: =GETPIVOTDATA("For Review",Pivot!$C$9,"Year","2020","Remediation Status","Clear") | G6: =GETPIVOTDATA("For Review",Pivot!$C$9,"Year","2020","Remediation Status",) | M6: =G6 | N6: 610380066
B7: 2019 | C7: =GETPIVOTDATA("For Review",Pivot!$C$3,"Year","2019") | E7: =GETPIVOTDATA("For Review",Pivot!$C$9,"Year","2019","Remediation Status","Clear") | G7: =GETPIVOTDATA("For Review",Pivot!$C$9,"Year","2019","Remediation Status",) | M7: =G7 | N7: 936367274
B8: 2018 | N8: 871902720 | O8: 0.00033093425
B9: 2017 | N9: 945981332 | O9: 0.00033093425
B10: 2016 | N10: 650068873 | O10: 0.00033093425
B11: 2015 | N11: 671539905 | O11: 0.00033093425
B12: 2014 | N12: 652603477 | O12: 0.00033093425
B13: 2013 | N13: 629959474 | O13: 0.00033093425
B14: 2012 | N14: 634480785 | O14: 0.00033093425
B15: 2011 | N15: 531122462 | O15: 0.00033093425
B16: 2010 | N16: 3.4206417e+08 | O16: 0.00033093425
B17: 2009 | N17: 239892122 | O17: 0.00033093425
B18: 2008 | N18: 266770483 | O18: 0.00033093425
B19: 2007 | N19: 219892366 | O19: 0.00033093425
B21: Year | C21: Extrapolated Unclaimed | G21: Net Extrapolated Unclaimed Property | I21: Actual Unclaimed Property Due to DE | K21: Total Actual and Extrapolated Unclaimed Property Due to DE | M21: Current Due Unclaimed Property - DE (2007-2019) | N21: Future Due Unclaimed Property - DE (2020-2021)
C22: =SUM(C24:C39) | G22: =SUM(G24:G38) | I22: =SUM(I24:I26) | K22: =SUM(K24:K39) | M22: =SUM(M24:M38) | N22: =SUM(N24:N38)
B24: 2021 | I24: =GETPIVOTDATA("Unresolved Amount",Pivot!$C$17,"Year","2021","Due to State","DE") | K24: =SUM(G24,I24) | N24: =K24
B25: 2020 | I25: =GETPIVOTDATA("Unresolved Amount",Pivot!$C$17,"Year","2020","Due to State","DE") | K25: =SUM(G25,I25) | N25: =K25
B26: 2019 | I26: =GETPIVOTDATA("Unresolved Amount",Pivot!$C$17,"Year","2019","Due to State","DE") | K26: =SUM(G26,I26) | M26: =K26
B27: 2018 | C27: =IF(O8="","",O8*N8) | G27: =IF(C27="","",C27-IF(E27="",0,E27)) | K27: =SUM(G27,I27) | M27: =K27
B28: 2017 | C28: =IF(O9="","",O9*N9) | G28: =IF(C28="","",C28-IF(E28="",0,E28)) | K28: =SUM(G28,I28) | M28: =K28
B29: 2016 | C29: =IF(O10="","",O10*N10) | G29: =IF(C29="","",C29-IF(E29="",0,E29)) | K29: =SUM(G29,I29) | M29: =K29
B30: 2015 | C30: =IF(O11="","",O11*N11) | G30: =IF(C30="","",C30-IF(E30="",0,E30)) | K30: =SUM(G30,I30) | M30: =K30
B31: 2014 | C31: =IF(O12="","",O12*N12) | G31: =IF(C31="","",C31-IF(E31="",0,E31)) | K31: =SUM(G31,I31) | M31: =K31
B32: 2013 | C32: =IF(O13="","",O13*N13) | G32: =IF(C32="","",C32-IF(E32="",0,E32)) | K32: =SUM(G32,I32) | M32: =K32
B33: 2012 | C33: =IF(O14="","",O14*N14) | G33: =IF(C33="","",C33-IF(E33="",0,E33)) | K33: =SUM(G33,I33) | M33: =K33
B34: 2011 | C34: =IF(O15="","",O15*N15) | G34: =IF(C34="","",C34-IF(E34="",0,E34)) | K34: =SUM(G34,I34) | M34: =K34
B35: 2010 | C35: =IF(O16="","",O16*N16) | G35: =IF(C35="","",C35-IF(E35="",0,E35)) | K35: =SUM(G35,I35) | M35: =K35
B36: 2009 | C36: =IF(O17="","",O17*N17) | G36: =IF(C36="","",C36-IF(E36="",0,E36)) | K36: =SUM(G36,I36) | M36: =K36
B37: 2008 | C37: =IF(O18="","",O18*N18) | G37: =IF(C37="","",C37-IF(E37="",0,E37)) | K37: =SUM(G37,I37) | M37: =K37
B38: 2007 | C38: =IF(O19="","",O19*N19) | G38: =IF(C38="","",C38-IF(E38="",0,E38)) | K38: =SUM(G38,I38) | M38: =K38

Sheet Data File
A1: Data File
Z3: Remediation Legend
Z4: U = Unresolved | AA4: =COUNTIF(AA11:AA370,"U")
Z5: F = Filed | AA5: =COUNTIF(AA11:AA370,"F")
Z6: R = Returned | AA6: =COUNTIF(AA11:AA370,"R")
Z7: C = Clear | AA7: =COUNTIF(AA11:AA370,"C")
Z8: Total | AA8: =SUM(AA4:AA7)
A10: Property ID | B10: Item Number | C10: Date | D10: Amount | E10: Name | F10: Address 1 | G10: Address 2 | H10: City | I10: State | J10: Zip Code | K10: Year | L10: Claim State | M10: Sample Item | N10: Reconciliation Date | O10: Blank | P10: Customer ID | Q10: Description | R10: Stratum | S10: Address Property Status | T10: Address Status Code | U10: Exam Team Comments | V10: Estimation Property Status | W10: Due to State | X10: For Review | Y10: Remediation Status | Z10: Unresolved Amount | AA10: Remediation Code | AB10: Holder Comments | AC10: Documentation Provided | AD10: Company0197 Comments | AE10: Company1850 Code
A11: 000004 | B11: 10004 | C11: 43525 | D11: 29.28 | E11: Name 4 | K11: 2019 | W11: NY | X11: 29.28 | Y11: Clear | Z11: =IF(Y11="Clear",0,X11) | AA11: C | AE11: MS09
A12: 000005 | B12: 10005 | C12: 43697 | D12: 7668.89 | E12: Name 5 | K12: 2019 | W12: NY | X12: 7668.89 | Y12: Clear | Z12: =IF(Y12="Clear",0,X12) | AA12: C | AE12: MS09
A13: 000006 | B13: 10006 | C13: 43686 | D13: 2093.05 | E13: Name 6 | K13: 2019 | W13: NY | X13: 2093.05 | Z13: =IF(Y13="Clear",0,X13) | AA13: U | AE13: MS09
A14: 000007 | B14: 10007 | C14: 43542 | D14: 205.11 | E14: Name 7 | K14: 2019 | W14: PA | X14: 205.11 | Z14: =IF(Y14="Clear",0,X14) | AA14: U | AE14: MS09
A15: 000008 | B15: 10008 | C15: 43482 | D15: 262.98 | E15: Name 8 | K15: 2019 | W15: PA | X15: 262.98 | Z15: =IF(Y15="Clear",0,X15) | AA15: U | AE15: MS09
A16: 000009 | B16: 10009 | C16: 43588 | D16: 461.74 | E16: Name 9 | K16: 2019 | W16: PA | X16: 461.74 | Z16: =IF(Y16="Clear",0,X16) | AA16: U | AE16: MS09
A17: 000010 | B17: 10010 | C17: 43769 | D17: 263.44 | E17: Name 10 | K17: 2019 | W17: PA | X17: 263.44 | Z17: =IF(Y17="Clear",0,X17) | AA17: U | AE17: MS09
A18: 000011 | B18: 10011 | C18: 43731 | D18: 784.4 | E18: Name 11 | K18: 2019 | W18: PA | X18: 784.4 | Z18: =IF(Y18="Clear",0,X18) | AA18: U | AE18: MS09
A19: 000012 | B19: 10012 | C19: 43669 | D19: 110 | E19: Name 12 | K19: 2019 | W19: PA | X19: 110 | Z19: =IF(Y19="Clear",0,X19) | AA19: U | AE19: MS09
A20: 000013 | B20: 10013 | C20: 43626 | D20: 30.97 | E20: Name 13 | K20: 2019 | W20: PA | X20: 30.97 | Z20: =IF(Y20="Clear",0,X20) | AA20: U | AE20: MS09
A21: 000014 | B21: 10014 | C21: 43626 | D21: 26.39 | E21: Name 14 | K21: 2019 | W21: PA | X21: 26.39 | Z21: =IF(Y21="Clear",0,X21) | AA21: U | AE21: MS09
A22: 000015 | B22: 10015 | C22: 43602 | D22: 61.25 | E22: Name 15 | K22: 2019 | W22: PA | X22: 61.25 | Z22: =IF(Y22="Clear",0,X22) | AA22: U | AE22: MS09
A23: 000016 | B23: 10016 | C23: 43892 | D23: 2285.13 | E23: Name 16 | K23: 2020 | W23: PA | X23: 2285.13 | Y23: Clear | Z23: =IF(Y23="Clear",0,X23) | AA23: C | AE23: MS09
A24: 000020 | B24: 10020 | C24: 44006 | D24: 2504.86 | E24: Name 20 | K24: 2020 | W24: NC | X24: 2504.86 | Z24: =IF(Y24="Clear",0,X24) | AA24: U | AE24: MS09
A25: 000021 | B25: 10021 | C25: 43812 | D25: 3751.53 | E25: Name 21 | K25: 2019 | W25: GA | X25: 3751.53 | Z25: =IF(Y25="Clear",0,X25) | AA25: U | AE25: MS09
A26: 000022 | B26: 10022 | C26: 43625 | D26: 20.18 | E26: Name 22 | K26: 2019 | W26: GA | X26: 20.18 | Z26: =IF(Y26="Clear",0,X26) | AA26: U | AE26: MS09
A27: 000023 | B27: 10023 | C27: 43557 | D27: 44 | E27: Name 23 | K27: 2019 | W27: GA | X27: 44 | Z27: =IF(Y27="Clear",0,X27) | AA27: U | AE27: MS09
A28: 000024 | B28: 10024 | C28: 43872 | D28: 427.02 | E28: Name 24 | K28: 2020 | W28: GA | X28: 427.02 | Z28: =IF(Y28="Clear",0,X28) | AA28: U | AE28: MS09
A29: 000025 | B29: 10025 | C29: 43762 | D29: 456.42 | E29: Name 25 | K29: 2019 | W29: GA | X29: 456.42 | Z29: =IF(Y29="Clear",0,X29) | AA29: U | AE29: MS09
A30: 000026 | B30: 10026 | C30: 43616 | D30: 50.52 | E30: Name 26 | K30: 2019 | W30: GA | X30: 50.52 | Z30: =IF(Y30="Clear",0,X30) | AA30: U | AE30: MS09
A31: 000027 | B31: 10027 | C31: 43798 | D31: 6065.27 | E31: Name 27 | K31: 2019 | W31: FL | X31: 6065.27 | Z31: =IF(Y31="Clear",0,X31) | AA31: U | AE31: MS09
A32: 000028 | B32: 10028 | C32: 43669 | D32: 468.99 | E32: Name 28 | K32: 2019 | W32: FL | X32: 468.99 | Z32: =IF(Y32="Clear",0,X32) | AA32: U | AE32: MS09
A33: 000029 | B33: 10029 | C33: 43665 | D33: 101.06 | E33: Name 29 | K33: 2019 | W33: FL | X33: 101.06 | Z33: =IF(Y33="Clear",0,X33) | AA33: U | AE33: MS09
A34: 000030 | B34: 10030 | C34: 43649 | D34: 109.25 | E34: Name 30 | K34: 2019 | W34: FL | X34: 109.25 | Z34: =IF(Y34="Clear",0,X34) | AA34: U | AE34: MS09
A35: 000031 | B35: 10031 | C35: 43468 | D35: 1610.39 | E35: Name 31 | K35: 2019 | W35: FL | X35: 1610.39 | Z35: =IF(Y35="Clear",0,X35) | AA35: U | AE35: MS09
... A37: 000033 | B37: 10033 | C37: 44453 | D37: 152.89 | E37: Name 33 | K37: 2021 | W37: FL | X37: 152.89 | Z37: =IF(Y37="Clear",0,X37) | AA37: U | AE37: MS09
A38: 000034 | B38: 10034 | C38: 43640 | D38: 8977.92 | E38: Name 34 | K38: 2019 | W38: FL | X38: 8977.92 | Y38: Clear | Z38: =IF(Y38="Clear",0,X38) | AA38: C | AE38: MS09
A39: 000035 | B39: 10035 | C39: 43628 | D39: 8977.92 | E39: Name 35 | K39: 2019 | W39: FL | X39: 8977.92 | Z39: =IF(Y39="Clear",0,X39) | AA39: U | AE39: MS09
A40: 000036 | B40: 10036 | C40: 44378 | D40: 2426.33 | E40: Name 36 | K40: 2021 | W40: FL | X40: 2426.33 | Z40: =IF(Y40="Clear",0,X40) | AA40: U | AE40: MS09
A41: 000037 | B41: 10037 | C41: 43546 | D41: 130.67 | E41: Name 37 | K41: 2019 | W41: AL | X41: 130.67 | Z41: =IF(Y41="Clear",0,X41) | AA41: U | AE41: MS09
A42: 000038 | B42: 10038 | C42: 43683 | D42: 129.9 | E42: Name 38 | K42: 2019 | W42: TN | X42: 129.9 | Z42: =IF(Y42="Clear",0,X42) | AA42: U | AE42: MS09
A43: 000039 | B43: 10039 | C43: 44134 | D43: 2299.09 | E43: Name 39 | K43: 2020 | W43: TN | X43: 2299.09 | Z43: =IF(Y43="Clear",0,X43) | AA43: U | AE43: MS09
...

Sheet Pivot
C2: Actual Property For Review
D3: Column Labels
D4: 2019 | E4: 2020 | F4: 2021 | G4: Grand Total
C5: Sum of For Review | D5: 473375.3 | E5: 159249.45 | F5: 1738748.7 | G5: 2371373.4
C8: Amount Remediated
C9: Sum of For Review | D9: Column Labels
C10: Row Labels | D10: 2019 | E10: 2020 | F10: 2021 | G10: Grand Total
C11: Clear | D11: 111894.73 | E11: 51308.3 | F11: 1494303.1 | G11: 1657506.1
C12: (blank) | D12: 361480.57 | E12: 107941.15 | F12: 244445.62 | G12: 713867.34
C13: Grand Total | D13: 473375.3 | E13: 159249.45 | F13: 1738748.7 | G13: 2371373.5
C16: Actual Unclaimed Property Due to DE
C17: Sum of Unresolved Amount | D17: Column Labels
C18: Row Labels | D18: 2019 | E18: 2020 | F18: 2021 | G18: Grand Total
C19: AL | D19: 130.67 | G19: 130.67
C20: AZ | E20: 1149.11 | G20: 1149.11
C21: CA | D21: 36931.99 | E21: 1188.57 | G21: 38120.56
C22: DE | D22: 55544.02 | E22: 77116.22 | F22: 199976.29 | G22: 332636.53
C23: FL | D23: 17810.36 | E23: 176.29 | F23: 2579.22 | G23: 20565.87
C24: GA | D24: 6278.83 | E24: 427.02 | G24: 6705.85
C25: IL | D25: 125131.1 | E25: 1074.65 | F25: 177.83 | G25: 126383.58
C26: MN | D26: 500.09 | G26: 500.09
C27: MO | D27: 1821.85 | E27: 436.55 | F27: 20729.06 | G27: 22987.46
C28: NC | E28: 2504.86 | G28: 2504.86
C29: NJ | D29: 44695.22 | G29: 44695.22
C30: NY | D30: 2093.05 | G30: 2093.05
C31: OH | E31: 4114.37 | G31: 4114.37
C32: OR | D32: 882.04 | G32: 882.04
C33: PA | D33: 68212.64 | E33: 2739.7 | G33: 70952.34
C34: TN | D34: 1163.13 | E34: 13358.97 | F34: 20.38 | G34: 14542.48
C35: TX | D35: 285.58 | E35: 3654.84 | F35: 20962.84 | G35: 24903.26
C36: Grand Total | D36: 361480.57 | E36: 107941.15 | F36: 244445.62 | G36: 713867.34
